
# Created by Ruins mod version 15.4.1 Ingame Parser
# authoring Player: SunsOfOld

weight=100
embed_into_distance=4
acceptable_target_blocks=
unacceptable_target_blocks=flowing_water,water,flowing_lava,lava
dimensions=10,17,14
allowable_overhang=0
max_leveling=4
leveling_buffer=0
preserve_water=0
preserve_lava=0
uniqueMinDistance=5000
preventRotation=1

rule1=0,100,preserveBlock
rule2=0,100,UndergroundBiomes:metamorphicCobblestone-1
rule3=0,100,minecraft:gravel-0
rule4=0,100,chisel:mossy_cobblestone-1
rule5=0,100,minecraft:iron_bars-0
rule6=0,100,IInventory;minecraft:chest;minecraft:iron_pickaxe#1#0#0+minecraft:bucket#1#0#1+minecraft:flint_and_steel#1#0#2+minecraft:lead#3#0#6+minecraft:chainmail_helmet#1#0#7+minecraft:bow#1#0#8+minecraft:iron_pickaxe#1#0#9+minecraft:iron_chestplate#1#0#10+minecraft:compass#1#0#11+minecraft:anvil#1#0#13+minecraft:iron_shovel#1#0#15+minecraft:chainmail_chestplate#1#0#16+minecraft:arrow#64#0#17+minecraft:iron_sword#1#0#18+minecraft:bucket#1#0#19+minecraft:clock#1#0#20+minecraft:ladder#12#0#24+minecraft:chainmail_leggings#1#0#25+minecraft:chainmail_boots#1#0#26-3
rule7=0,100,chisel:mossy_cobblestone-12
rule8=2,100,minecraft:torch-1
rule9=0,100,minecraft:stonebrick-1
rule10=2,100,minecraft:torch-3
rule11=0,100,chisel:mossy_cobblestone-4
rule12=0,100,GardenStuff:moss_brick-4
rule13=0,100,UndergroundBiomes:metamorphicStoneHalfSlab-1
rule14=0,100,minecraft:stonebrick-2
rule15=0,100,minecraft:cobblestone_wall-1
rule16=0,100,GardenStuff:bloomery_furnace-3
rule17=0,100,minecraft:anvil-6
rule18=0,100,minecraft:furnace-3
rule19=0,100,minecraft:cobblestone_wall-0

layer
1,1,1,1,1,1,1,1,1,1,1,1,1,1
1,1,1,1,1,1,1,1,1,1,1,1,1,1
1,1,1,1,1,1,1,1,1,1,1,1,1,1
1,1,1,1,1,1,1,1,1,1,1,1,1,1
1,1,1,1,2,2,2,2,2,2,2,1,1,1
1,1,1,1,2,2,2,2,2,2,2,1,1,1
1,1,1,1,2,2,2,2,2,2,2,1,1,1
1,1,1,1,2,2,2,2,2,2,2,1,1,1
1,1,1,1,2,2,2,2,2,2,2,1,1,1
1,1,1,1,2,2,2,2,2,2,2,1,1,1
1,1,1,1,2,2,2,2,2,2,2,1,1,1
1,1,1,1,2,2,2,2,2,2,2,1,1,1
1,1,1,1,2,2,2,2,2,2,2,1,1,1
1,1,1,1,2,2,2,2,2,2,2,1,1,1
1,1,1,1,1,1,1,1,1,1,1,1,1,1
1,1,1,1,1,1,1,1,1,1,1,1,1,1
1,1,1,1,1,1,1,1,1,1,1,1,1,1
endlayer

layer
1,1,1,1,1,1,1,1,1,1,1,1,1,1
1,1,1,1,1,1,1,1,1,1,1,1,1,1
1,1,1,1,1,1,1,1,1,1,1,1,1,1
1,1,1,1,1,1,1,1,1,1,1,1,1,1
1,1,1,1,2,2,2,2,2,2,2,1,1,1
1,1,1,1,2,0,0,0,0,0,2,1,1,1
1,1,1,1,3,0,0,3,0,3,2,1,1,1
1,1,1,1,3,2,0,0,0,4,2,1,1,1
1,1,1,1,2,3,2,0,3,3,2,1,1,1
1,1,1,1,3,2,0,3,3,3,2,1,1,1
1,1,1,1,2,2,3,5,5,5,2,1,1,1
1,1,1,1,2,3,3,5,0,0,2,1,1,1
1,1,1,1,2,3,3,3,0,6,2,1,1,1
1,1,1,1,2,2,2,2,2,2,2,1,1,1
1,1,1,1,1,1,1,1,1,1,1,1,1,1
1,1,1,1,1,1,1,1,1,1,1,1,1,1
1,1,1,1,1,1,1,1,1,1,1,1,1,1
endlayer

layer
1,1,1,1,1,1,1,1,1,1,1,1,1,1
1,1,1,1,1,1,1,1,1,1,1,1,1,1
1,1,1,1,1,1,1,1,1,1,1,1,1,1
1,1,1,1,1,1,1,1,1,1,1,1,1,1
1,1,1,1,2,2,2,2,2,2,2,1,1,1
1,1,1,1,2,0,0,0,0,0,2,1,1,1
1,1,1,1,3,0,0,0,0,0,2,1,1,1
1,1,1,1,0,0,0,0,0,3,2,1,1,1
1,1,1,1,2,0,2,0,3,0,2,1,1,1
1,1,1,1,3,3,0,3,3,3,2,1,1,1
1,1,1,1,2,3,0,5,5,5,2,1,1,1
1,1,1,1,2,3,0,5,0,0,2,1,1,1
1,1,1,1,2,3,3,3,0,0,2,1,1,1
1,1,1,1,2,2,2,2,2,2,2,1,1,1
1,1,1,1,1,1,1,1,1,1,1,1,1,1
1,1,1,1,1,1,1,1,1,1,1,1,1,1
1,1,1,1,1,1,1,1,1,1,1,1,1,1
endlayer

layer
1,1,1,1,1,1,7,1,1,1,1,1,1,1
1,1,1,1,1,1,1,1,1,1,1,1,1,1
1,1,1,1,1,3,7,1,3,1,1,1,1,1
1,1,1,1,1,3,1,1,1,1,1,1,1,1
1,1,3,1,2,2,2,2,2,2,2,3,1,1
1,1,1,9,3,0,0,8,0,0,2,1,1,1
1,1,1,7,3,0,0,0,0,10,2,1,1,1
1,1,11,4,0,0,0,0,0,3,2,1,1,1
1,1,1,1,0,0,0,0,0,0,2,1,7,1
1,1,1,3,3,2,0,3,0,3,2,1,1,1
1,1,1,1,3,0,0,5,5,5,2,1,3,1
1,1,1,1,3,0,0,5,0,0,2,1,1,3
1,1,3,1,3,3,0,5,0,0,2,1,1,1
1,1,1,1,2,2,2,2,2,2,2,1,1,1
1,1,1,1,1,12,1,1,1,1,1,1,1,1
1,1,1,1,1,1,11,3,1,1,1,1,1,1
1,1,1,3,1,1,1,1,4,1,1,1,1,1
endlayer

layer
0,0,0,0,0,0,0,0,3,0,0,0,0,0
0,0,0,0,0,0,13,0,13,0,0,0,0,0
0,0,0,0,0,0,0,3,7,3,0,0,0,0
0,7,0,0,0,0,12,0,3,13,0,0,0,0
0,0,0,9,7,7,7,7,7,7,7,0,0,0
0,0,11,2,3,12,14,11,12,11,9,0,0,0
0,4,13,0,3,11,9,12,14,9,4,13,0,7
0,0,0,0,7,14,12,12,11,0,12,7,3,0
0,0,0,0,9,12,14,4,14,12,9,3,0,13
0,0,0,0,7,9,11,12,9,14,2,7,0,0
0,0,0,0,0,12,14,9,12,11,11,0,0,0
0,0,12,0,0,4,9,11,12,4,9,0,0,0
0,0,0,0,9,11,11,9,4,9,12,0,0,0
0,0,0,0,7,9,11,12,14,12,7,0,0,0
0,0,3,0,3,0,3,4,0,0,0,0,0,0
0,0,0,0,11,3,0,0,0,12,0,0,0,0
0,0,0,0,0,0,3,0,0,0,0,0,0,0
endlayer

layer
0,0,0,0,0,0,0,0,0,0,0,0,0,0
0,0,0,0,0,0,0,0,0,0,0,0,0,0
0,0,0,0,0,0,0,0,0,0,0,0,0,0
0,0,0,0,0,0,0,0,0,0,0,0,0,0
0,0,0,13,7,9,14,0,12,11,7,0,0,0
0,0,0,0,0,2,0,2,0,2,11,0,0,0
0,0,0,0,2,0,2,3,2,0,4,0,0,0
0,0,0,0,7,0,2,0,2,0,13,0,0,0
0,0,0,0,0,0,2,3,2,3,12,0,0,0
0,0,0,0,15,0,0,2,3,2,11,0,0,0
0,0,0,0,0,0,0,16,7,7,12,0,0,0
0,0,0,0,0,0,0,0,14,0,4,0,0,0
0,0,0,0,0,0,17,0,0,0,11,0,0,0
0,0,0,0,15,3,0,3,0,0,7,0,0,0
0,0,0,0,0,0,0,0,0,0,0,0,0,0
0,0,0,0,0,0,0,0,0,0,0,0,0,0
0,0,0,0,0,0,0,0,0,0,0,0,0,0
endlayer

layer
0,0,0,0,0,0,0,0,0,0,0,0,0,0
0,0,0,0,0,0,0,0,0,0,0,0,0,0
0,0,0,0,0,0,0,0,0,0,0,0,0,0
0,0,0,0,0,0,0,0,0,0,0,0,0,0
0,0,0,0,7,11,12,0,5,4,7,0,0,0
0,0,0,0,5,0,0,0,0,0,4,0,0,0
0,0,0,0,0,0,0,0,0,0,5,0,0,0
0,0,0,0,7,0,0,0,0,0,0,0,0,0
0,0,0,0,0,0,3,0,0,0,5,0,0,0
0,0,0,0,15,0,0,0,2,3,4,0,0,0
0,0,0,0,0,0,0,18,12,4,9,0,0,0
0,0,0,0,0,0,0,0,0,0,5,0,0,0
0,0,0,0,0,0,0,0,0,0,5,0,0,0
0,0,0,0,19,0,0,0,5,5,7,0,0,0
0,0,0,0,0,0,0,0,0,0,0,0,0,0
0,0,0,0,0,0,0,0,0,0,0,0,0,0
0,0,0,0,0,0,0,0,0,0,0,0,0,0
endlayer

layer
0,0,0,0,0,0,0,0,0,0,0,0,0,0
0,0,0,0,0,0,0,0,0,0,0,0,0,0
0,0,0,0,0,0,0,0,0,0,0,0,0,0
0,0,0,0,0,0,0,0,0,0,0,0,0,0
0,0,0,0,7,14,0,0,0,12,7,0,0,0
0,0,0,0,0,0,0,0,0,0,0,0,0,0
0,0,0,0,0,0,0,0,0,0,0,0,0,0
0,0,0,0,7,0,0,0,0,0,0,0,0,0
0,0,0,0,0,0,0,0,0,0,0,0,0,0
0,0,0,0,19,0,0,0,0,0,12,0,0,0
0,0,0,0,0,0,0,18,0,11,14,0,0,0
0,0,0,0,0,0,0,0,2,2,11,0,0,0
0,0,0,0,0,0,0,10,2,2,12,0,0,0
0,0,0,0,15,0,0,0,12,11,7,0,0,0
0,0,0,0,0,0,0,0,0,0,0,0,0,0
0,0,0,0,0,0,0,0,0,0,0,0,0,0
0,0,0,0,0,0,0,0,0,0,0,0,0,0
endlayer

layer
0,0,0,0,0,0,0,0,0,0,0,0,0,0
0,0,0,0,0,0,0,0,0,0,0,0,0,0
0,0,0,0,0,0,0,0,0,0,0,0,0,0
0,0,0,0,0,0,0,0,0,0,0,0,0,0
0,0,0,0,7,7,7,0,0,0,7,0,0,0
0,0,0,0,0,0,0,0,0,0,7,0,0,0
0,0,0,0,7,0,0,0,0,0,0,0,0,0
0,0,0,0,7,2,0,0,0,0,0,0,0,0
0,0,0,0,7,2,0,0,0,0,0,0,0,0
0,0,0,0,7,2,2,0,0,0,0,0,0,0
0,0,0,0,7,2,2,2,2,2,7,0,0,0
0,0,0,0,7,2,2,2,2,2,7,0,0,0
0,0,0,0,7,2,2,2,2,2,7,0,0,0
0,0,0,0,7,7,7,7,7,7,7,0,0,0
0,0,0,0,0,0,0,0,0,0,0,0,0,0
0,0,0,0,0,0,0,0,0,0,0,0,0,0
0,0,0,0,0,0,0,0,0,0,0,0,0,0
endlayer

layer
0,0,0,0,0,0,0,0,0,0,0,0,0,0
0,0,0,0,0,0,0,0,0,0,0,0,0,0
0,0,0,0,0,0,0,0,0,0,0,0,0,0
0,0,0,0,0,0,0,0,0,0,0,0,0,0
0,0,0,0,13,13,13,0,0,0,13,0,0,0
0,0,0,0,0,0,0,0,0,0,13,0,0,0
0,0,0,0,0,0,0,0,0,0,0,0,0,0
0,0,0,0,13,0,0,0,0,0,0,0,0,0
0,0,0,0,13,0,0,0,0,0,0,0,0,0
0,0,0,0,13,0,0,0,0,0,13,0,0,0
0,0,0,0,13,0,0,0,0,0,13,0,0,0
0,0,0,0,13,0,0,0,0,0,13,0,0,0
0,0,0,0,13,0,0,0,0,0,13,0,0,0
0,0,0,0,13,13,13,13,13,13,13,0,0,0
0,0,0,0,0,0,0,0,0,0,0,0,0,0
0,0,0,0,0,0,0,0,0,0,0,0,0,0
0,0,0,0,0,0,0,0,0,0,0,0,0,0
endlayer

