
# Created by Ruins mod version 14.9 Ingame Parser
# authoring Player: SunsOfOld

weight=100
embed_into_distance=2
acceptable_target_blocks=
unacceptable_target_blocks=flowing_water,water,flowing_lava,lava
dimensions=9,8,8
allowable_overhang=0
max_leveling=3
leveling_buffer=0
preserve_water=0
preserve_lava=0
uniqueMinDistance=1000000
preventRotation=1

rule1=0,100,preserveBlock
rule2=0,100,BiomesOPlenty:newBopDirt-0
rule3=0,100,BiomesOPlenty:mud-0
rule4=0,100,BiomesOPlenty:newBopDirt-1
rule5=0,100,dendrology:leaves2-15
rule6=0,100,BiomesOPlenty:foliage-11
rule7=0,100,plantmegapack:wetlandsCattails-0
rule8=0,100,dendrology:logs2-3
rule9=0,100,GardenStuff:moss_brick-4
rule10=0,100,GardenStuff:moss_brick-5
rule11=0,100,dendrology:logs2-7
rule12=0,100,plantmegapack:wetlandsClubrush-0
rule13=0,100,BiomesOPlenty:colorizedLeaves2-12
rule14=0,100,plantmegapack:wetlandsFloweringRush-0
rule15=0,100,GardenStuff:moss_brick-3
rule16=0,100,dendrology:logs2-11
rule17=0,100,BiomesOPlenty:colorizedLeaves2-4
rule18=0,100,GardenStuff:moss_brick-6
rule19=0,100,plantmegapack:wetlandsCommonRush-0
rule20=0,100,GardenTrees:thin_log-0
rule21=0,100,dendrology:sslab0-13
rule22=0,100,dendrology:dslab0-5
rule23=0,100,GardenStuff:lattice-3
rule24=0,100,GardenStuff:lantern-12

layer
2,1,3,2,1,2,1,1
1,2,1,1,1,1,1,1
3,1,1,1,1,1,1,1
1,1,1,1,1,1,2,1
1,1,1,1,1,4,1,2
1,1,1,1,1,1,1,1
1,1,1,1,2,1,1,1
1,1,3,1,1,4,1,2
endlayer

layer
6,8,0,7,3,6,5,2
0,6,1,10,4,5,9,1
0,11,3,1,5,5,5,2
1,11,2,13,4,1,12,0
2,11,13,13,13,14,2,6
16,11,1,9,1,13,15,2
0,11,1,17,7,1,4,0
0,11,0,0,1,6,0,6
endlayer

layer
0,0,0,0,0,0,0,6
0,0,0,18,14,0,10,2
0,0,0,2,0,5,0,19
0,0,6,0,19,2,0,0
6,0,0,13,0,0,6,0
0,8,1,10,0,0,18,19
0,0,0,0,0,0,2,0
0,0,0,0,0,0,0,0
endlayer

layer
0,0,0,0,0,0,0,0
0,0,0,9,20,20,9,6
0,0,0,12,5,5,5,0
0,0,0,0,13,5,0,0
0,0,0,0,13,0,0,0
0,8,0,18,20,20,9,0
0,0,0,0,0,0,6,0
0,0,0,0,0,0,0,0
endlayer

layer
0,0,0,0,21,0,0,0
0,0,0,10,22,22,18,0
0,0,0,0,21,21,0,0
0,0,0,0,21,21,0,0
0,0,0,0,21,21,0,0
0,0,0,15,22,22,15,0
0,0,0,0,21,21,0,0
0,0,0,0,0,21,0,0
endlayer

layer
0,0,0,23,0,0,0,0
0,0,0,23,0,0,23,0
0,0,0,23,0,0,23,0
0,0,0,23,0,0,23,0
0,0,0,23,0,0,23,0
0,0,0,23,0,0,23,0
0,0,0,0,0,0,23,0
0,0,0,0,0,0,23,0
endlayer

layer
0,0,0,23,0,0,23,0
0,0,0,0,0,0,23,0
0,0,0,23,0,0,23,0
0,0,0,23,0,0,23,0
0,0,0,23,0,0,23,0
0,0,0,23,0,0,23,0
0,0,0,0,0,0,23,0
0,0,0,0,0,0,0,0
endlayer

layer
0,0,0,0,0,0,0,0
0,0,0,0,0,0,0,0
0,0,0,0,0,0,0,0
0,0,24,23,0,0,23,24
0,0,0,0,0,0,0,0
0,0,0,0,0,0,0,0
0,0,0,0,0,0,0,0
0,0,0,0,0,0,0,0
endlayer

layer
0,0,0,0,0,0,0,0
0,0,0,0,0,0,0,0
0,0,0,0,0,0,0,0
0,0,23,23,0,0,23,23
0,0,0,0,0,0,0,0
0,0,0,0,0,0,0,0
0,0,0,0,0,0,0,0
0,0,0,0,0,0,0,0
endlayer

