
# Created by Ruins mod version 15.0 Ingame Parser
# authoring Player: SunsOfOld

weight=100
embed_into_distance=1
acceptable_target_blocks=
unacceptable_target_blocks=flowing_water,water,flowing_lava,lava,sand
dimensions=4,14,8
allowable_overhang=0
max_leveling=4
leveling_buffer=0
preserve_water=0
preserve_lava=0
uniqueMinDistance=1000000
preventRotation=1

rule1=0,100,preserveBlock
rule2=0,100,BiomesOPlenty:planks-3
rule3=0,100,minecraft:grass-0
rule4=0,100,minecraft:monster_egg-0
rule5=0,100,minecraft:stone-0
rule6=0,100,minecraft:cobblestone-0
rule7=0,100,minecraft:rail-1
rule8=0,100,ExtrabiomesXL:flower3-11
rule9=0,100,minecraft:double_plant-2
rule10=0,100,minecraft:tallgrass-1
rule11=0,100,BiomesOPlenty:foliage-4
rule12=0,100,minecraft:dirt-0
rule13=0,100,minecraft:rail-7
rule14=0,100,minecraft:rail-0
rule15=0,100,minecraft:rail-9
rule16=0,100,ExtrabiomesXL:flower2-8
rule17=0,100,GardenTrees:thin_log-0
rule18=0,100,minecraft:double_plant-8
rule19=0,100,chisel:torch6-5

layer
1,1,1,1,1,2,1,1
1,1,1,1,4,2,3,1
3,5,1,1,3,2,1,3
1,1,1,1,3,2,1,1
3,1,1,1,1,2,3,1
3,1,1,2,2,2,1,1
1,1,1,2,1,3,1,1
3,1,1,2,3,3,1,3
1,1,1,2,6,1,1,3
1,3,2,2,3,1,5,1
1,1,2,1,1,3,5,5
1,1,2,3,5,5,1,3
1,3,2,1,3,1,1,1
1,1,2,1,5,1,1,5
endlayer

layer
0,0,0,0,0,7,0,0
0,3,3,4,0,7,8,0
10,5,5,4,10,7,0,9
0,5,5,4,11,0,0,0
10,4,12,4,4,0,10,0
16,3,5,15,14,13,0,0
0,3,4,7,0,10,0,0
0,4,4,7,10,10,0,10
0,4,4,0,17,0,0,10
0,0,15,13,10,0,0,0
0,0,7,0,0,10,0,0
0,0,7,10,0,0,5,9
0,10,0,0,9,5,5,5
0,0,7,0,0,5,3,0
endlayer

layer
0,0,0,0,0,0,0,0
0,10,9,0,0,0,0,0
0,0,4,0,0,0,0,18
0,4,4,4,0,0,0,0
0,0,3,0,0,0,0,0
0,10,4,0,0,0,0,0
0,10,0,0,0,0,0,0
0,0,0,0,0,0,0,0
0,0,0,0,19,0,0,0
0,0,0,0,0,0,0,0
0,0,0,0,0,0,0,0
0,0,0,0,0,0,0,18
0,0,0,0,18,5,5,0
0,0,0,0,0,0,10,0
endlayer

layer
0,0,0,0,0,0,0,0
0,0,18,0,0,0,0,0
0,0,0,0,0,0,0,0
0,0,4,0,0,0,0,0
0,0,10,0,0,0,0,0
0,0,0,0,0,0,0,0
0,0,0,0,0,0,0,0
0,0,0,0,0,0,0,0
0,0,0,0,0,0,0,0
0,0,0,0,0,0,0,0
0,0,0,0,0,0,0,0
0,0,0,0,0,0,0,0
0,0,0,0,0,0,5,0
0,0,0,0,0,0,0,0
endlayer

