
# Created by Ruins mod version 15.0 Ingame Parser
# authoring Player: SunsOfOld

weight=100
embed_into_distance=5
acceptable_target_blocks=
unacceptable_target_blocks=flowing_water,water,flowing_lava,lava,sand
dimensions=7,12,14
allowable_overhang=0
max_leveling=4
leveling_buffer=0
preserve_water=0
preserve_lava=0
uniqueMinDistance=1000000
preventRotation=1

rule1=0,100,preserveBlock
rule2=0,100,minecraft:dirt-0
rule3=0,100,BiomesOPlenty:bopGrass-1
rule4=0,100,BiomesOPlenty:hardDirt-0
rule5=0,100,minecraft:grass-0
rule6=0,100,minecraft:stone-0
rule7=0,100,BiomesOPlenty:planks-11
rule8=0,100,minecraft:monster_egg-0
rule9=0,100,minecraft:tallgrass-1
rule10=0,100,minecraft:double_plant-2
rule11=0,100,GardenTrees:thin_log-0
rule12=0,100,minecraft:rail-0
rule13=0,100,minecraft:rail-2
rule14=0,100,ExtrabiomesXL:flower3-11
rule15=0,100,minecraft:double_plant-8
rule16=0,100,chisel:torch6-5

layer
1,1,1,1,1,1,1,1,1,1,1,1,1,1
1,1,1,1,1,1,1,1,1,1,1,1,1,1
1,1,1,1,1,1,1,1,1,1,1,1,1,1
1,1,1,1,1,1,1,1,1,1,1,1,1,1
1,1,2,2,2,2,2,2,2,1,1,1,1,1
1,1,1,2,2,2,2,2,2,1,1,1,1,1
1,1,1,2,2,2,2,2,2,1,1,1,1,1
1,1,1,2,2,2,2,2,2,1,1,1,1,1
1,1,1,2,2,2,2,2,1,1,1,1,1,1
1,1,1,1,1,1,1,1,1,1,1,1,1,1
1,1,1,1,1,1,1,1,1,1,1,1,1,1
1,1,1,1,1,1,1,1,1,1,1,1,1,1
endlayer

layer
1,1,1,1,1,1,1,1,1,1,1,1,1,1
1,1,1,1,1,1,1,1,1,1,1,1,1,1
1,1,1,1,1,1,1,1,1,2,1,1,1,1
1,1,2,2,2,2,2,2,2,2,1,1,1,1
1,1,2,2,2,2,2,2,2,2,1,1,1,1
1,1,2,2,2,2,2,2,2,2,1,1,1,1
1,1,2,2,2,2,2,2,2,2,1,1,1,1
1,1,2,2,2,2,2,2,2,2,1,1,1,1
1,1,2,2,2,2,2,2,2,2,1,1,1,1
1,1,1,1,1,1,1,1,1,1,1,1,1,1
1,1,1,1,1,1,1,1,1,1,1,1,1,1
1,1,1,1,1,1,1,1,1,1,1,1,1,1
endlayer

layer
1,1,1,1,1,1,1,1,1,1,1,1,1,1
1,1,1,1,1,1,1,1,1,2,1,1,1,1
1,1,1,1,1,1,1,0,1,0,2,1,1,1
1,1,2,2,4,4,3,0,2,0,2,1,1,1
1,1,2,2,2,3,0,0,0,0,2,1,1,1
1,2,2,2,4,0,0,0,0,3,2,1,1,1
1,2,2,2,2,2,2,0,3,2,2,1,1,1
1,2,2,2,2,2,2,2,2,2,1,1,1,1
1,1,2,2,2,2,2,2,2,2,1,1,1,1
1,1,1,1,1,1,1,1,1,1,1,1,1,1
1,1,1,1,1,1,1,1,1,1,1,1,1,1
1,1,1,1,1,1,1,1,1,1,1,1,1,1
endlayer

layer
1,1,1,1,1,1,1,1,1,1,1,1,1,1
1,2,2,2,4,4,4,4,4,4,4,2,2,1
1,2,2,4,4,0,0,0,0,0,0,2,2,1
1,2,2,4,0,0,0,0,0,0,0,4,2,1
1,2,2,4,4,0,0,0,0,0,0,4,2,1
1,2,2,2,0,0,0,0,0,0,0,2,2,1
1,2,2,4,4,0,0,0,0,0,4,2,2,1
1,2,2,2,4,4,4,0,0,4,2,2,2,1
1,2,2,2,2,2,4,2,4,2,2,2,2,1
1,2,2,2,2,2,2,2,2,2,2,2,2,1
1,2,2,2,2,2,2,2,2,2,2,2,2,1
1,1,1,1,1,1,1,1,1,1,1,1,1,1
endlayer

layer
1,1,1,1,1,1,1,0,0,1,1,1,1,1
1,5,1,1,0,0,0,0,0,0,3,3,1,5
1,1,5,0,0,0,0,0,0,0,0,3,1,6
5,1,1,0,0,0,0,0,0,0,0,0,2,1
1,6,1,0,0,0,0,0,0,0,0,0,1,1
7,7,7,7,0,0,0,0,0,0,0,7,7,7
1,1,1,0,0,0,0,0,0,0,0,1,5,1
1,5,1,8,0,0,0,0,0,0,3,8,1,1
1,1,5,1,1,3,0,1,0,8,6,1,1,1
1,5,1,5,1,5,1,1,1,8,1,5,1,1
1,1,5,5,1,1,1,1,1,1,5,1,5,1
1,1,1,1,1,1,1,1,1,1,1,1,1,1
endlayer

layer
0,0,0,0,0,0,0,0,0,0,0,0,0,0
0,10,0,0,0,0,0,0,0,0,0,0,0,9
0,0,9,0,0,0,0,0,0,0,0,0,0,0
0,0,0,0,0,0,0,0,0,0,0,0,0,0
0,11,0,0,0,0,0,0,0,0,0,0,0,0
12,12,12,12,0,0,0,0,0,0,0,12,12,12
0,0,0,0,0,0,0,0,0,0,0,0,9,0
0,9,0,0,0,0,0,0,0,0,0,0,0,0
0,0,0,0,0,0,0,0,0,0,8,0,0,0
0,9,0,9,0,9,13,0,0,0,0,9,0,0
0,0,9,14,0,0,7,0,0,0,0,0,10,0
0,0,0,0,0,0,0,0,0,0,0,0,0,0
endlayer

layer
0,0,0,0,0,0,0,0,0,0,0,0,0,0
0,15,0,0,0,0,0,0,0,0,0,0,0,0
0,0,0,0,0,0,0,0,0,0,0,0,0,0
0,0,0,0,0,0,0,0,0,0,0,0,0,0
0,16,0,0,0,0,0,0,0,0,0,0,0,0
0,0,0,0,0,0,0,0,0,0,0,0,0,0
0,0,0,0,0,0,0,0,0,0,0,0,0,0
0,0,0,0,0,0,0,0,0,0,0,0,0,0
0,0,0,0,0,0,0,0,0,0,0,0,0,0
0,0,0,0,0,0,0,0,0,0,0,0,0,0
0,0,0,0,0,0,0,0,0,0,0,0,15,0
0,0,0,0,0,0,0,0,0,0,0,0,0,0
endlayer

