
# Created by Ruins mod version 15.0 Ingame Parser
# authoring Player: SunsOfOld

weight=100
embed_into_distance=1
acceptable_target_blocks=
unacceptable_target_blocks=flowing_water,water,flowing_lava,lava,sand
dimensions=7,26,13
allowable_overhang=0
max_leveling=5
leveling_buffer=0
preserve_water=0
preserve_lava=0
uniqueMinDistance=1000000
preventRotation=1

rule1=0,100,preserveBlock
rule2=0,100,minecraft:cobblestone-0
rule3=0,100,BiomesOPlenty:planks-11
rule4=0,100,minecraft:grass-0
rule5=0,100,BiomesOPlenty:stoneSingleSlab-8
rule6=0,100,minecraft:brick_block-0
rule7=0,100,BiomesOPlenty:hardDirt-0
rule8=0,100,chisel:nether_brick-5
rule9=0,100,minecraft:stone-0
rule10=0,100,minecraft:stonebrick-0
rule11=0,100,GardenTrees:thin_log-0
rule12=0,100,minecraft:rail-1
rule13=0,100,minecraft:tallgrass-1
rule14=0,100,minecraft:double_plant-2
rule15=0,100,ExtrabiomesXL:flower2-5
rule16=0,100,minecraft:crafting_table-0
rule17=0,100,IInventory;minecraft:furnace;minecraft:coal#16#1#1-5
rule18=0,100,IInventory;minecraft:chest;minecraft:iron_ore#48#0#0+minecraft:iron_ore#9#0#1+minecraft:iron_ore#1#0#2+minecraft:iron_ore#1#0#3+minecraft:iron_ore#1#0#4+minecraft:iron_ore#1#0#5+minecraft:iron_ore#1#0#6+minecraft:iron_ore#1#0#7+minecraft:iron_ore#1#0#8+minecraft:coal#4#1#18+minecraft:coal#4#1#19+minecraft:coal#4#1#20+minecraft:coal#4#1#21-5
rule19=0,100,CarpentersBlocks:blockCarpentersBarrier-0
rule20=0,100,GardenStuff:lattice-1
rule21=0,100,minecraft:rail-0
rule22=0,100,IInventory;minecraft:chest;minecraft:furnace_minecart#1#0#0+minecraft:furnace_minecart#1#0#1-2
rule23=0,100,minecraft:anvil-5
rule24=0,100,minecraft:anvil-7
rule25=0,100,IInventory;minecraft:furnace;minecraft:coal#8#1#1-2
rule26=0,100,minecraft:lever-5
rule27=0,100,IInventory;minecraft:chest;minecraft:furnace_minecart#1#0#0+minecraft:furnace_minecart#1#0#1+minecraft:redstone_torch#16#0#16+minecraft:rail#32#0#18+minecraft:golden_rail#32#0#19-2
rule28=0,100,IInventory;minecraft:furnace;minecraft:coal#16#1#1-2
rule29=0,100,IInventory;minecraft:chest;minecraft:coal#64#1#0+minecraft:coal#64#1#1+minecraft:coal#64#1#2+minecraft:coal#64#1#3+minecraft:coal#64#1#4+minecraft:coal#64#1#5+minecraft:coal#44#1#6+minecraft:coal#1#1#7+minecraft:coal#1#1#8+minecraft:coal#1#1#9+minecraft:coal#1#1#10+minecraft:coal#1#1#11+minecraft:coal#1#1#12+minecraft:coal#1#1#13+minecraft:coal#1#1#14+minecraft:coal#1#1#15+minecraft:coal#1#1#16+minecraft:coal#1#1#17+minecraft:coal#1#1#18+minecraft:coal#1#1#19+minecraft:coal#1#1#20+minecraft:coal#1#1#21+minecraft:coal#1#1#22+minecraft:coal#1#1#23+minecraft:coal#1#1#24+minecraft:coal#1#1#25+minecraft:coal#1#1#26-3
rule30=2,100,WallSign:null:Fuel:null:null-3
rule31=2,100,WallSign:null:Lunchbox:null:null-4
rule32=2,100,WallSign:No Smelting!!!:For food :cooking only!:This means you.-4
rule33=0,100,IInventory;minecraft:chest;harvestcraft:chiliItem#4#0#0+harvestcraft:chiliItem#4#0#1+harvestcraft:beanburritoItem#4#0#2+harvestcraft:meatystewItem#4#0#3+harvestcraft:coffeeconlecheItem#16#0#4+harvestcraft:blueberrypieItem#4#0#5-4
rule34=0,100,IInventory;minecraft:furnace;minecraft:coal#8#1#1-4
rule35=0,100,minecraft:anvil-6
rule36=0,100,harvestcraft:sink-3
rule37=0,100,minecraft:rail-7
rule38=0,100,chisel:torch6-5
rule39=0,100,minecraft:double_plant-8
rule40=0,100,chisel:torch6-2
rule41=0,100,chisel:torch6-4
rule42=0,100,minecraft:brick_stairs-3
rule43=0,100,minecraft:brick_stairs-2
rule44=0,100,minecraft:brick_stairs-1
rule45=0,100,minecraft:brick_stairs-0
rule46=0,100,minecraft:brick_stairs-5
rule47=0,100,GardenStuff:lantern-15
rule48=0,100,minecraft:brick_stairs-4
rule49=0,100,GardenStuff:heavy_chain-4
rule50=0,100,minecraft:brick_stairs-7
rule51=0,100,minecraft:stone_slab-12
rule52=0,100,minecraft:brick_stairs-6
rule53=0,100,minecraft:double_stone_slab-4
rule54=0,100,chisel:glass-15

layer
1,1,1,1,1,1,1,1,1,1,3,2,1
4,1,1,4,1,1,1,1,1,4,3,1,1
4,1,1,1,4,1,1,1,1,4,3,1,1
1,1,1,1,1,1,4,4,4,5,3,1,1
4,1,6,6,6,6,6,6,6,5,3,4,1
4,1,7,7,7,7,7,7,6,5,3,4,1
1,1,7,5,5,5,5,5,5,5,3,1,4
1,1,7,5,8,8,8,8,3,3,3,4,1
1,1,7,5,5,5,5,5,5,5,3,1,4
1,1,7,7,7,7,7,7,6,5,3,4,1
4,1,7,7,7,7,7,7,6,5,3,4,1
4,1,7,5,5,5,5,5,5,5,3,1,4
1,1,7,5,8,8,8,8,3,3,3,9,4
4,1,7,5,5,5,5,5,5,5,3,1,1
1,1,7,7,7,7,7,7,6,5,3,4,1
4,1,7,7,7,7,7,7,6,5,3,1,4
4,1,7,5,5,5,5,5,5,5,3,1,1
1,1,7,5,8,8,8,8,3,3,3,9,1
4,1,7,5,5,5,5,5,5,5,3,4,1
1,1,7,7,7,7,7,7,6,5,3,1,1
4,1,1,6,6,6,6,6,6,5,3,4,1
1,4,1,1,4,1,5,5,5,5,3,1,4
1,4,1,4,1,4,5,5,1,5,3,1,1
10,1,1,1,1,1,5,5,5,5,3,4,1
3,3,3,3,3,3,3,3,3,3,3,1,4
1,1,4,1,1,4,4,1,1,1,4,1,1
endlayer

layer
0,0,0,0,0,0,0,0,0,0,12,11,0
13,0,0,13,0,0,0,0,0,0,12,0,0
13,0,0,0,13,0,0,0,0,0,12,0,0
0,0,0,0,0,0,14,13,0,0,12,0,0
15,6,6,6,6,6,6,6,6,0,0,0,0
13,6,6,18,17,16,0,6,6,0,12,13,0
0,6,0,19,0,0,0,0,0,0,12,0,13
0,6,22,19,21,21,21,21,21,20,12,13,0
0,6,0,19,0,0,0,0,0,0,12,0,13
0,6,24,0,0,0,0,23,6,0,12,13,0
0,6,25,0,0,0,0,16,6,0,12,13,0
14,6,0,19,0,0,0,0,0,0,0,0,13
0,6,27,19,21,21,21,21,0,20,12,26,13
0,6,0,19,0,0,0,0,0,0,12,0,0
0,6,28,0,0,0,0,6,6,0,12,13,0
13,6,24,0,0,0,30,29,6,0,12,0,13
14,6,0,19,0,0,0,0,0,0,12,0,0
0,6,22,19,21,21,21,21,21,20,0,26,0
0,6,0,19,0,32,31,0,0,0,12,13,0
0,6,6,0,35,34,33,6,6,0,12,0,0
13,6,6,6,6,6,6,6,6,0,12,13,0
0,13,0,0,14,0,0,0,0,0,0,0,13
0,13,0,13,0,13,0,0,36,0,12,0,0
11,0,0,0,0,0,0,0,0,0,12,14,0
21,21,0,0,0,0,21,21,21,0,37,0,13
0,0,13,0,0,13,13,0,0,0,0,0,0
endlayer

layer
0,0,0,0,0,0,0,0,0,0,0,38,0
0,0,0,0,0,0,0,0,0,0,0,0,0
0,0,0,0,0,0,0,0,0,0,0,0,0
0,40,0,0,0,0,39,0,0,0,0,0,0
0,6,43,20,20,20,20,42,6,41,0,0,0
0,44,38,0,0,0,0,38,44,0,0,0,0
0,20,0,0,0,0,0,0,0,0,0,0,0
0,20,0,0,0,0,0,0,0,0,0,0,0
0,20,0,0,0,0,0,0,0,0,0,0,0
0,6,41,0,0,0,0,0,45,0,0,0,0
0,6,0,0,0,0,0,0,44,0,0,0,0
39,20,0,0,0,0,0,0,0,0,0,0,0
0,20,0,0,0,0,0,0,0,0,0,0,0
0,20,0,0,0,0,0,0,0,0,0,0,0
0,6,0,0,0,0,0,38,45,0,0,0,0
0,6,41,0,0,0,0,0,44,0,0,0,0
39,20,0,0,0,0,0,0,0,0,0,0,0
0,20,0,0,0,0,0,0,0,0,0,0,0
0,20,0,0,0,0,0,0,0,0,0,0,0
0,45,38,0,0,0,0,38,45,0,0,0,0
0,6,43,20,20,20,20,42,6,41,0,0,0
0,0,0,0,39,0,0,0,0,0,0,0,0
0,0,0,0,0,0,0,0,0,0,0,0,0
38,0,0,0,0,0,0,0,0,0,0,39,0
0,0,0,0,0,0,0,0,0,0,0,0,0
0,0,0,0,0,0,0,0,0,0,0,0,0
endlayer

layer
0,0,0,0,0,0,0,0,0,0,0,0,0
0,0,0,0,0,0,0,0,0,0,0,0,0
0,0,0,0,0,0,0,0,0,0,0,0,0
0,0,0,0,0,0,0,0,0,0,0,0,0
0,6,20,20,20,20,20,20,6,0,0,0,0
0,20,0,0,0,0,0,0,46,0,0,0,0
0,20,0,0,0,0,0,0,0,0,0,0,0
0,20,0,0,0,0,0,0,47,0,0,0,0
0,20,0,0,0,0,0,0,0,0,0,0,0
0,6,0,0,0,0,0,0,48,0,0,0,0
0,6,0,0,0,49,0,0,46,0,0,0,0
0,20,0,0,0,0,0,0,0,0,0,0,0
0,20,0,0,0,0,0,0,47,0,0,0,0
0,20,0,0,0,0,0,0,0,0,0,0,0
0,6,0,0,0,0,0,0,48,0,0,0,0
0,6,0,0,0,49,0,0,46,0,0,0,0
0,20,0,0,0,0,0,0,0,0,0,0,0
0,20,0,0,0,0,0,0,47,0,0,0,0
0,20,0,0,0,0,0,0,0,0,0,0,0
0,20,0,0,0,0,0,0,48,0,0,0,0
0,6,20,20,20,20,20,20,6,0,0,0,0
0,0,0,0,0,0,0,0,0,0,0,0,0
0,0,0,0,0,0,0,0,0,0,0,0,0
0,0,0,0,0,0,0,0,0,0,0,0,0
0,0,0,0,0,0,0,0,0,0,0,0,0
0,0,0,0,0,0,0,0,0,0,0,0,0
endlayer

layer
0,0,0,0,0,0,0,0,0,0,0,0,0
0,0,0,0,0,0,0,0,0,0,0,0,0
0,0,0,0,0,0,0,0,0,0,0,0,0
0,0,0,0,0,0,0,0,0,0,0,0,0
0,6,52,51,51,51,51,50,6,0,0,0,0
0,46,0,0,0,0,0,0,6,0,0,0,0
0,51,0,0,0,0,0,0,46,0,0,0,0
0,51,0,0,0,0,0,0,51,0,0,0,0
0,51,0,0,0,0,0,0,48,0,0,0,0
0,53,0,0,0,0,0,0,6,0,0,0,0
0,53,20,20,20,20,20,20,6,0,0,0,0
0,51,0,0,0,0,0,0,46,0,0,0,0
0,51,0,0,0,0,0,0,51,0,0,0,0
0,51,0,0,0,0,0,0,48,0,0,0,0
0,53,0,0,0,0,0,0,6,0,0,0,0
0,53,20,20,20,20,20,20,6,0,0,0,0
0,51,0,0,0,0,0,0,46,0,0,0,0
0,51,0,0,0,0,0,0,51,0,0,0,0
0,51,0,0,0,0,0,0,48,0,0,0,0
0,48,0,0,0,0,0,0,6,0,0,0,0
0,6,52,51,51,51,51,50,6,0,0,0,0
0,0,0,0,0,0,0,0,0,0,0,0,0
0,0,0,0,0,0,0,0,0,0,0,0,0
0,0,0,0,0,0,0,0,0,0,0,0,0
0,0,0,0,0,0,0,0,0,0,0,0,0
0,0,0,0,0,0,0,0,0,0,0,0,0
endlayer

layer
0,0,0,0,0,0,0,0,0,0,0,0,0
0,0,0,0,0,0,0,0,0,0,0,0,0
0,0,0,0,0,0,0,0,0,0,0,0,0
0,0,0,0,0,0,0,0,0,0,0,0,0
0,10,10,10,10,10,10,10,10,0,0,0,0
0,10,54,54,54,54,54,54,10,0,0,0,0
0,10,54,0,54,54,54,54,10,0,0,0,0
0,10,54,54,54,0,0,54,10,0,0,0,0
0,10,54,54,54,0,54,54,10,0,0,0,0
0,10,54,54,54,54,54,54,10,0,0,0,0
0,10,54,54,54,54,54,54,10,0,0,0,0
0,10,54,54,54,54,54,54,10,0,0,0,0
0,10,54,54,54,0,54,54,10,0,0,0,0
0,10,54,54,54,54,54,54,10,0,0,0,0
0,10,54,54,54,54,54,54,10,0,0,0,0
0,10,54,54,54,54,54,54,10,0,0,0,0
0,10,54,54,54,0,54,54,10,0,0,0,0
0,10,54,54,54,54,54,54,10,0,0,0,0
0,10,54,0,54,54,54,54,10,0,0,0,0
0,10,54,54,54,54,54,54,10,0,0,0,0
0,10,10,10,10,10,10,10,10,0,0,0,0
0,0,0,0,0,0,0,0,0,0,0,0,0
0,0,0,0,0,0,0,0,0,0,0,0,0
0,0,0,0,0,0,0,0,0,0,0,0,0
0,0,0,0,0,0,0,0,0,0,0,0,0
0,0,0,0,0,0,0,0,0,0,0,0,0
endlayer

layer
0,0,0,0,0,0,0,0,0,0,0,0,0
0,0,0,0,0,0,0,0,0,0,0,0,0
0,0,0,0,0,0,0,0,0,0,0,0,0
0,0,0,0,0,0,0,0,0,0,0,0,0
0,38,0,0,0,0,0,0,38,0,0,0,0
0,0,0,0,0,0,0,0,0,0,0,0,0
0,0,0,0,0,0,0,0,0,0,0,0,0
0,0,0,0,0,0,0,0,0,0,0,0,0
0,0,0,0,0,0,0,0,0,0,0,0,0
0,38,0,0,0,0,0,0,38,0,0,0,0
0,0,0,0,0,0,0,0,0,0,0,0,0
0,0,0,0,0,0,0,0,0,0,0,0,0
0,0,0,0,0,0,0,0,0,0,0,0,0
0,0,0,0,0,0,0,0,0,0,0,0,0
0,0,0,0,0,0,0,0,0,0,0,0,0
0,38,0,0,0,0,0,0,38,0,0,0,0
0,0,0,0,0,0,0,0,0,0,0,0,0
0,0,0,0,0,0,0,0,0,0,0,0,0
0,0,0,0,0,0,0,0,0,0,0,0,0
0,0,0,0,0,0,0,0,0,0,0,0,0
0,38,0,0,0,0,0,0,38,0,0,0,0
0,0,0,0,0,0,0,0,0,0,0,0,0
0,0,0,0,0,0,0,0,0,0,0,0,0
0,0,0,0,0,0,0,0,0,0,0,0,0
0,0,0,0,0,0,0,0,0,0,0,0,0
0,0,0,0,0,0,0,0,0,0,0,0,0
endlayer

