
# Created by Ruins mod version 15.0 Ingame Parser
# authoring Player: SunsOfOld

weight=85
embed_into_distance=1
acceptable_target_blocks=
unacceptable_target_blocks=flowing_water,water,flowing_lava,lava,sand
dimensions=18,22,16
allowable_overhang=0
max_leveling=5
leveling_buffer=0
preserve_water=0
preserve_lava=0
uniqueMinDistance=1000000
preventRotation=1

rule1=0,100,preserveBlock
rule2=0,100,minecraft:monster_egg-0
rule3=0,100,BiomesOPlenty:planks-11
rule4=0,100,minecraft:grass-0
rule5=0,100,minecraft:stone-0
rule6=0,100,minecraft:dirt-0
rule7=0,100,BiomesOPlenty:planks-3
rule8=0,100,BiomesOPlenty:stoneSingleSlab-8
rule9=0,100,minecraft:cobblestone-0
rule10=0,100,GardenTrees:thin_log-0
rule11=0,100,minecraft:rail-1
rule12=0,100,minecraft:yellow_flower-0
rule13=0,100,minecraft:tallgrass-1
rule14=0,100,BiomesOPlenty:foliage-4
rule15=0,100,minecraft:double_plant-2
rule16=0,100,BiomesOPlenty:logs4-0
rule17=0,100,ExtrabiomesXL:flower2-3
rule18=0,100,minecraft:log-0
rule19=0,100,minecraft:rail-6
rule20=0,100,minecraft:rail-0
rule21=0,100,ExtrabiomesXL:flower2-9
rule22=0,100,minecraft:rail-7
rule23=0,100,CarpentersBlocks:blockCarpentersBarrier-0
rule24=0,100,minecraft:lever-6
rule25=0,100,BiblioCraft:BiblioSeats-0
rule26=0,100,minecraft:stonebrick-2
rule27=0,100,CarpentersBlocks:blockCarpentersDoor-0
rule28=0,100,ExtrabiomesXL:flower3-5
rule29=0,100,minecraft:wooden_pressure_plate-0
rule30=0,100,minecraft:anvil-6
rule31=0,100,minecraft:furnace-3
rule32=0,100,harvestcraft:sink-0
rule33=0,100,IInventory;minecraft:chest;harvestcraft:skilletItem#1#0#0+harvestcraft:potItem#1#0#1+harvestcraft:mixingbowlItem#1#0#2+harvestcraft:mortarandpestleItem#1#0#3+minecraft:water_bucket#1#0#4+harvestcraft:flourItem#64#0#5+harvestcraft:freshwaterItem#64#0#6+harvestcraft:hotchocolateItem#16#0#18+harvestcraft:fishtacoItem#4#0#20+harvestcraft:potroastItem#4#0#21+harvestcraft:butteredpotatoItem#6#0#22+harvestcraft:vegetablesoupItem#4#0#23+harvestcraft:applepieItem#3#0#24+harvestcraft:grilledcheeseItem#2#0#25+harvestcraft:cornonthecobItem#3#0#26-3
rule34=0,100,minecraft:crafting_table-0
rule35=0,100,BiblioCraft:BiblioTable-0
rule36=0,100,chisel:torch6-5
rule37=0,100,minecraft:double_plant-8
rule38=0,100,chisel:torch6-2
rule39=0,100,chisel:glass-1
rule40=0,100,CarpentersBlocks:blockCarpentersDoor-14
rule41=0,100,chisel:glass-15
rule42=0,100,chisel:glass2-0
rule43=0,100,chisel:torch6-4
rule44=0,100,chisel:torch6-3
rule45=0,100,minecraft:ladder-4
rule46=0,100,chisel:torch6-1
rule47=0,100,minecraft:log-8
rule48=0,100,minecraft:log-4
rule49=0,100,BiomesOPlenty:woodenSingleSlab2-10
rule50=0,100,BiomesOPlenty:woodenSingleSlab2-2
rule51=0,100,BiomesOPlenty:woodenDoubleSlab2-2
rule52=0,100,minecraft:bed-9
rule53=0,100,minecraft:bed-1
rule54=0,100,ChestGenHook:dungeonChest:5-3
rule55=0,100,minecraft:leaves-0
rule56=0,100,BiomesOPlenty:colorizedLeaves2-1

layer
1,1,1,1,4,1,1,1,1,4,4,1,1,3,2,1
1,1,4,5,1,5,2,1,4,1,1,4,4,3,1,4
1,4,4,5,1,1,2,5,1,4,1,1,1,3,4,1
1,1,6,5,1,1,2,2,4,1,1,4,1,3,1,4
1,4,1,4,1,5,1,5,1,1,4,1,1,3,4,1
1,1,4,1,4,4,1,4,1,4,4,4,5,3,1,4
7,7,7,7,7,7,7,1,4,4,6,4,4,3,1,1
1,1,4,1,1,4,7,1,4,4,4,4,1,3,1,4
1,1,4,1,4,1,7,1,4,4,4,1,1,3,1,1
4,1,1,1,8,8,7,4,4,1,1,4,1,3,1,1
1,4,8,8,8,9,9,9,1,2,3,3,3,3,4,1
4,8,8,8,8,8,8,8,8,5,4,1,1,4,4,4
4,9,9,9,9,9,8,8,8,5,3,3,3,3,3,4
4,9,9,9,9,9,4,8,8,2,8,3,1,1,3,4
1,9,9,9,9,9,8,8,8,8,8,3,1,1,3,1
4,9,9,9,9,9,8,5,8,8,4,5,1,1,3,4
4,9,9,9,9,9,9,9,9,9,1,1,4,1,3,1
4,9,9,9,9,9,9,9,9,9,4,1,1,4,3,4
4,9,9,9,9,9,9,9,9,9,1,4,1,1,3,1
1,9,9,9,9,9,9,9,9,9,4,4,6,1,3,2
1,9,9,9,9,9,9,9,9,9,4,1,1,4,3,9
1,1,4,1,1,4,4,4,1,4,1,1,1,1,3,1
endlayer

layer
0,0,0,0,13,0,0,0,0,13,12,0,0,11,10,0
0,0,13,2,5,4,0,2,14,0,0,0,14,11,0,13
0,13,15,0,5,2,0,0,0,13,0,0,0,11,13,0
0,0,16,0,4,2,0,0,0,0,0,13,0,11,0,13
0,13,0,15,0,10,0,0,0,0,13,0,0,11,13,0
0,0,15,0,13,17,0,13,0,13,15,15,10,11,0,14
20,20,20,20,20,20,19,0,13,13,18,13,13,11,0,0
0,0,13,0,0,13,11,0,13,14,15,13,0,11,0,13
0,0,0,0,13,0,11,0,0,13,21,0,0,11,0,0
13,0,0,0,0,0,11,0,0,0,0,13,0,11,0,0
0,0,0,0,0,23,23,23,0,23,20,20,20,22,13,0
13,0,0,0,0,0,0,0,0,23,0,24,0,13,13,13
13,26,3,27,3,26,0,0,25,23,20,19,20,20,19,13
0,3,0,29,0,3,15,0,0,23,0,11,0,0,11,28
0,3,0,0,0,3,0,0,0,0,0,11,0,0,11,0
15,3,0,0,0,3,0,30,0,0,0,23,0,0,11,13
13,26,0,0,0,26,3,3,3,26,0,0,13,0,11,0
0,3,0,0,0,0,32,0,31,3,15,0,0,13,11,13
13,3,25,0,0,0,0,0,33,3,0,13,0,0,11,0
0,3,35,25,0,0,0,0,34,3,13,13,16,0,11,0
0,26,3,3,3,26,3,3,3,26,13,0,0,13,11,10
0,0,0,0,0,0,0,0,0,0,0,0,0,0,11,0
endlayer

layer
0,0,0,0,0,0,0,0,0,0,0,0,0,0,36,0
0,0,0,0,2,15,0,0,0,0,0,0,0,0,0,0
0,0,37,0,5,2,0,0,0,0,0,0,0,0,0,0
0,0,16,0,13,0,0,0,0,0,0,0,0,0,0,0
0,0,0,37,0,36,0,0,0,0,0,0,0,0,0,0
0,0,37,0,0,0,0,0,0,0,37,37,36,0,0,0
0,0,0,0,0,0,0,0,0,0,18,0,0,0,0,0
0,0,0,0,0,0,0,0,0,0,37,0,0,0,0,0
0,0,0,0,0,0,0,0,0,0,0,0,0,0,0,0
0,0,0,0,0,0,0,0,0,0,0,0,0,0,0,0
0,0,0,0,0,0,0,0,0,36,0,0,0,0,0,0
0,38,0,0,0,38,0,0,0,0,0,0,0,0,0,0
0,26,39,40,39,26,0,0,0,0,0,0,0,0,0,0
0,42,0,0,0,41,37,0,0,0,0,0,0,0,0,0
0,42,0,0,0,41,0,0,0,0,0,0,0,0,0,0
37,42,0,0,0,41,0,0,0,0,0,0,0,0,0,0
0,26,43,0,44,26,41,41,41,26,43,0,0,0,0,0
0,41,0,0,0,0,0,0,0,41,37,0,0,0,0,0
0,41,0,0,0,0,0,0,0,41,0,0,0,0,0,0
0,41,0,0,0,45,0,0,0,41,0,0,16,0,0,0
0,26,41,41,41,26,41,41,41,26,43,0,0,0,0,36
0,46,0,0,0,46,0,0,0,0,0,0,0,0,0,0
endlayer

layer
0,0,0,0,0,0,0,0,0,0,0,0,0,0,0,0
0,0,0,0,0,37,0,0,0,0,0,0,0,0,0,0
0,0,0,0,2,0,0,0,0,0,0,0,0,0,0,0
0,0,16,0,0,0,0,0,0,0,0,0,0,0,0,0
0,0,0,0,0,0,0,0,0,0,0,0,0,0,0,0
0,0,0,0,0,0,0,0,0,0,0,0,0,0,0,0
0,0,0,0,0,0,0,0,0,0,18,0,0,0,0,0
0,0,0,0,0,0,0,0,0,0,0,0,0,0,0,0
0,0,0,0,0,0,0,0,0,0,0,0,0,0,0,0
0,0,0,0,0,0,0,0,0,0,0,0,0,0,0,0
0,0,0,0,0,0,0,0,0,0,0,0,0,0,0,0
0,0,0,0,0,0,0,0,0,0,0,0,0,0,0,0
0,26,47,47,47,26,0,0,0,0,0,0,0,0,0,0
0,48,0,46,0,48,0,0,0,0,0,0,0,0,0,0
0,48,0,0,0,48,0,0,0,0,0,0,0,0,0,0
0,48,0,0,0,48,0,0,0,0,0,0,0,0,0,0
0,26,0,0,0,26,47,47,47,26,0,0,0,0,0,0
0,48,0,0,0,50,50,50,49,48,0,0,0,0,0,0
0,48,0,0,0,0,50,50,49,48,0,0,0,0,0,0
0,48,0,0,0,45,50,50,51,48,0,0,16,0,0,0
0,26,47,47,47,26,47,47,47,26,0,0,0,0,0,0
0,0,0,0,0,0,0,0,0,0,0,0,0,0,0,0
endlayer

layer
0,0,0,0,0,0,0,0,0,0,0,0,0,0,0,0
0,0,0,0,0,0,0,0,0,0,0,0,0,0,0,0
0,0,0,0,0,0,0,0,0,0,0,0,0,0,0,0
0,0,16,0,0,0,0,0,0,0,0,0,0,0,0,0
0,0,0,0,0,0,0,0,0,0,0,0,0,0,0,0
0,0,0,0,0,0,0,0,0,0,0,0,0,0,0,0
0,0,0,0,0,0,0,0,0,0,18,0,0,0,0,0
0,0,0,0,0,0,0,0,0,0,0,0,0,0,0,0
0,0,0,0,0,0,0,0,0,0,0,0,0,0,0,0
0,0,0,0,0,0,0,0,0,0,0,0,0,0,0,0
0,0,0,0,0,0,0,0,0,0,0,0,0,0,0,0
0,0,0,0,0,0,0,0,0,0,0,0,0,0,0,0
0,26,10,10,10,26,0,0,0,0,0,0,0,0,0,0
0,10,0,0,0,10,0,0,0,0,0,0,0,0,0,0
0,10,0,0,0,10,0,0,0,0,0,0,0,0,0,0
0,10,0,0,0,10,0,0,0,0,0,0,0,0,0,0
0,26,0,0,0,26,10,10,10,26,0,0,0,0,0,0
0,10,0,0,0,46,0,0,52,10,0,0,0,0,0,0
0,10,0,0,0,0,0,0,53,10,0,0,0,0,0,0
0,10,0,0,0,0,0,0,54,10,0,0,16,0,0,0
0,26,10,10,10,26,10,10,10,26,0,0,0,0,0,0
0,0,0,0,0,0,0,0,0,0,0,0,0,0,0,0
endlayer

layer
0,0,0,0,0,0,0,0,0,0,0,0,0,0,0,0
0,0,0,0,0,0,0,0,0,0,0,0,0,0,0,0
0,0,0,0,0,0,0,0,0,0,0,0,0,0,0,0
0,0,16,0,0,0,0,0,0,0,0,0,0,0,0,0
0,0,0,0,0,0,0,0,0,0,0,55,0,0,0,0
56,0,0,0,0,0,0,0,0,0,55,48,55,0,0,0
0,0,0,0,0,0,0,0,0,0,18,55,0,0,0,0
0,0,0,0,0,0,0,0,0,48,55,48,55,0,0,0
0,0,0,0,0,0,0,0,0,48,0,55,0,0,0,0
0,0,0,0,0,0,0,0,0,0,0,0,0,0,0,0
0,0,0,0,0,0,0,0,0,0,0,0,0,0,0,0
0,0,0,0,0,0,0,0,0,0,0,0,0,0,0,0
0,50,50,50,50,50,0,0,0,0,0,0,0,0,0,0
0,50,49,49,49,50,0,0,0,0,0,0,0,0,0,0
0,50,49,0,49,50,0,0,0,0,0,0,0,0,0,0
0,50,49,0,49,50,0,0,0,0,0,0,0,0,0,0
0,50,49,0,49,50,50,50,50,50,0,0,0,0,0,0
0,50,49,0,49,49,49,49,49,50,0,0,0,0,0,0
0,50,49,0,0,0,0,0,49,50,0,0,0,0,0,0
0,50,49,49,49,49,49,49,49,50,0,0,16,0,0,0
0,50,50,50,50,50,50,50,50,50,0,0,0,0,0,0
0,0,0,0,0,0,0,0,0,0,0,0,0,0,0,0
endlayer

layer
0,0,0,0,0,0,0,0,0,0,0,0,0,0,0,0
0,0,0,0,56,0,0,0,0,0,0,0,0,0,0,0
0,0,0,0,0,0,0,0,0,0,0,0,0,0,0,0
0,0,16,0,0,0,0,0,0,0,55,55,55,0,0,0
56,0,0,0,0,0,0,0,0,55,55,55,48,55,0,0
0,56,0,0,0,0,0,0,0,55,55,48,55,55,0,0
0,0,0,0,0,0,0,0,0,55,18,55,55,55,0,0
0,0,0,0,0,0,0,0,55,48,55,55,55,55,0,0
0,0,0,0,0,0,0,55,48,48,55,55,55,55,0,0
0,0,0,0,0,0,0,55,48,55,55,55,55,0,0,0
0,0,0,0,0,0,0,0,55,0,0,0,0,0,0,0
0,0,0,0,0,0,0,0,0,0,0,0,0,0,0,0
0,0,0,0,0,0,0,0,0,0,0,0,0,0,0,0
0,0,0,0,0,0,0,0,0,0,0,0,0,0,0,0
0,0,0,51,0,0,0,0,0,0,0,0,0,0,0,0
0,0,0,50,0,0,0,0,0,0,0,0,0,0,0,0
0,0,0,50,0,0,0,0,0,0,0,0,0,0,0,0
0,0,0,50,0,0,0,0,0,0,0,0,0,0,0,0
0,0,0,51,50,50,50,51,0,0,0,0,0,0,0,0
0,0,0,0,0,0,0,0,0,0,0,0,16,0,0,0
0,0,0,0,0,0,0,0,0,0,0,0,0,0,0,0
0,0,0,0,0,0,0,0,0,0,0,0,0,0,0,0
endlayer

layer
0,0,0,0,0,0,0,0,0,0,0,0,0,0,0,0
56,0,0,56,0,0,0,0,0,0,0,0,0,0,0,0
0,56,56,56,56,0,0,0,0,0,0,0,0,55,0,0
0,56,16,56,0,0,0,0,0,0,55,55,55,48,55,0
0,56,56,56,0,0,0,0,0,55,55,55,55,55,0,0
0,0,0,0,0,0,0,0,47,48,55,55,55,55,0,0
0,0,0,0,0,0,0,55,55,55,18,55,55,55,0,0
0,0,0,0,0,0,55,55,55,55,55,55,55,55,0,0
0,0,0,0,0,0,55,55,55,55,55,55,55,55,0,0
0,0,0,0,0,0,55,55,48,55,55,55,55,0,0,0
0,0,0,0,0,0,55,55,48,55,55,0,0,0,0,0
0,0,0,0,0,0,0,55,55,55,0,0,0,0,0,0
0,0,0,0,0,0,0,0,0,0,0,0,0,0,0,0
0,0,0,0,0,0,0,0,0,0,0,0,0,0,0,0
0,0,0,10,0,0,0,0,0,0,0,0,0,0,0,0
0,0,0,0,0,0,0,0,0,0,0,0,0,0,0,0
0,0,0,0,0,0,0,0,0,0,0,0,0,0,0,0
0,0,0,0,0,0,0,0,0,0,0,0,0,0,0,0
0,0,0,10,0,0,0,10,0,0,0,0,0,0,0,0
0,0,0,0,0,0,0,0,0,0,0,0,16,0,0,0
0,0,0,0,0,0,0,0,0,0,0,0,0,0,0,0
0,0,0,0,0,0,0,0,0,0,56,0,0,0,0,0
endlayer

layer
0,0,0,0,0,0,0,0,0,0,0,0,0,0,0,0
0,56,0,0,0,0,0,0,0,0,0,0,55,55,55,0
56,0,0,0,0,0,0,0,0,0,0,55,55,55,55,55
0,0,16,0,0,0,0,55,0,0,0,55,55,55,55,55
0,0,0,0,0,0,55,47,55,0,55,48,55,55,55,55
0,0,0,0,0,0,0,55,0,0,48,55,55,55,55,0
0,0,0,0,0,0,0,55,55,55,18,55,0,0,0,0
0,0,0,0,0,0,55,55,55,48,55,55,55,0,0,0
0,0,0,0,0,0,55,55,48,55,55,55,0,0,0,0
0,0,0,0,0,0,55,55,55,55,55,0,0,0,0,0
0,0,0,0,0,0,55,55,55,55,55,0,0,0,0,0
0,0,0,0,0,0,55,55,55,55,55,0,0,0,0,0
0,0,0,0,0,0,0,55,55,55,0,0,0,0,0,0
0,0,0,0,0,0,0,0,0,0,0,0,0,0,0,0
0,0,0,36,0,0,0,0,0,0,0,0,0,0,0,0
0,0,0,0,0,0,0,0,0,0,0,0,0,0,0,0
0,0,0,0,0,0,0,0,0,0,0,0,0,0,0,0
0,0,0,0,0,0,0,0,0,0,0,0,0,0,56,0
0,0,0,36,0,0,0,36,0,0,0,0,0,0,0,0
0,0,0,0,0,0,0,0,0,0,0,0,16,0,0,0
0,0,0,0,0,0,0,0,0,0,56,0,0,0,0,0
0,0,0,0,0,0,0,0,0,0,0,56,0,0,0,0
endlayer

layer
0,0,0,0,0,0,0,0,0,0,0,0,0,0,0,0
0,0,0,0,0,0,0,0,0,0,0,0,55,55,55,0
0,56,56,56,0,0,55,55,55,0,55,55,55,55,55,55
0,56,16,56,0,55,55,55,55,55,55,55,55,55,55,55
0,56,56,56,56,55,55,55,55,55,55,55,55,55,55,55
0,0,0,56,56,55,55,55,55,55,55,55,55,55,55,0
0,0,0,0,0,0,55,55,55,0,18,55,55,0,0,0
0,0,0,0,0,0,0,0,55,0,55,48,55,0,0,0
0,0,0,0,0,0,0,55,55,55,0,55,0,0,0,0
0,0,0,0,0,0,55,55,48,55,55,0,0,0,0,0
0,0,0,0,0,0,55,48,55,55,55,0,0,0,0,0
0,0,0,0,0,0,55,55,55,55,55,0,0,0,0,0
0,0,0,0,0,0,0,55,55,55,0,0,0,0,0,0
0,0,0,0,0,0,0,0,0,0,0,0,0,0,0,0
0,0,0,0,0,0,0,0,0,0,0,0,0,0,0,0
0,0,0,0,0,0,0,0,0,0,0,0,0,0,0,0
0,0,0,0,0,0,0,0,0,0,0,0,0,0,0,0
0,0,0,0,0,0,0,0,0,0,0,0,0,56,0,0
0,0,0,0,0,0,0,0,0,0,0,56,56,56,56,0
0,0,0,0,0,0,0,0,0,0,0,56,16,56,0,0
0,0,0,0,0,0,0,0,0,0,0,56,56,56,0,0
0,0,0,0,0,0,0,0,0,0,0,0,0,0,0,0
endlayer

layer
0,0,0,0,0,0,0,0,0,0,0,0,0,0,0,0
0,0,0,0,56,0,0,0,0,0,0,0,0,0,0,0
0,0,0,0,0,0,55,55,55,0,55,55,55,55,0,0
0,0,16,0,0,55,55,55,55,55,55,55,55,55,55,0
0,0,0,0,0,55,55,55,55,55,55,55,55,55,0,0
56,0,0,0,0,55,55,55,55,55,55,48,55,55,0,0
0,0,0,0,0,0,55,55,55,55,18,55,55,55,0,0
0,0,0,0,0,0,0,0,0,48,48,48,55,55,0,0
0,0,0,0,0,0,55,55,55,48,55,48,55,55,0,0
0,0,0,0,0,55,55,55,55,55,55,55,55,0,0,0
0,0,0,0,0,55,55,55,55,55,0,0,0,0,0,0
0,0,0,0,0,55,55,55,55,55,0,0,0,0,0,0
0,0,0,0,0,0,55,55,55,0,0,0,0,0,0,0
0,0,0,0,0,0,0,0,0,0,0,0,0,0,0,0
0,0,0,0,0,0,0,0,0,0,0,0,0,0,0,0
0,0,0,0,0,0,0,0,0,0,0,0,0,0,0,0
0,0,0,0,0,0,0,0,0,0,0,0,0,0,0,0
0,0,0,0,0,0,0,0,0,0,0,0,0,0,0,0
0,0,0,0,0,0,0,0,0,0,0,0,0,0,0,0
0,0,0,0,0,0,0,0,0,0,0,0,16,0,0,0
0,0,0,0,0,0,0,0,0,0,0,0,0,0,0,0
0,0,0,0,0,0,0,0,0,0,0,0,0,0,0,0
endlayer

layer
0,0,0,0,0,0,0,0,0,0,0,0,0,0,0,0
0,0,0,56,0,0,0,0,0,0,0,0,0,0,0,0
0,56,56,56,56,0,0,0,0,0,0,0,0,0,0,0
0,56,16,56,0,0,0,55,0,0,0,55,55,0,0,0
56,56,56,56,0,0,55,55,55,0,55,55,48,55,0,0
0,56,0,0,0,0,0,55,0,0,55,55,55,0,0,0
0,0,0,0,0,0,0,0,0,55,18,55,55,55,0,0
0,0,0,0,0,0,0,0,0,55,55,55,55,55,0,0
0,0,0,0,0,0,55,55,55,55,55,55,55,55,0,0
0,0,0,0,0,55,55,55,48,55,55,55,55,55,0,0
0,0,0,0,0,55,55,55,55,55,55,55,55,0,0,0
0,0,0,0,0,0,55,55,55,55,0,0,0,0,0,0
0,0,0,0,0,0,0,55,55,0,0,0,0,0,0,0
0,0,0,0,0,0,0,0,0,0,0,0,0,0,0,0
0,0,0,0,0,0,0,0,0,0,0,0,0,0,0,0
0,0,0,0,0,0,0,0,0,0,0,0,0,0,0,0
0,0,0,0,0,0,0,0,0,0,0,0,0,0,0,0
0,0,0,0,0,0,0,0,0,0,56,56,0,0,0,0
0,0,0,0,0,0,0,0,0,0,56,56,56,56,0,0
0,0,0,0,0,0,0,0,0,0,0,56,16,56,0,0
0,0,0,0,0,0,0,0,0,0,0,56,56,56,56,0
0,0,0,0,0,0,0,0,0,0,0,0,0,56,56,0
endlayer

layer
0,0,0,0,0,0,0,0,0,0,0,0,0,0,0,0
56,56,0,0,0,0,0,0,0,0,0,0,0,0,0,0
56,0,0,0,0,0,0,0,0,0,0,55,55,55,0,0
0,0,16,0,0,0,0,0,0,0,55,55,55,55,55,0
0,0,0,0,56,0,0,0,0,0,55,55,55,55,55,0
0,0,0,56,56,0,0,0,0,0,55,55,55,55,55,0
0,0,0,0,0,0,0,0,0,55,18,55,55,55,0,0
0,0,0,0,0,0,0,55,55,55,55,55,55,55,0,0
0,0,0,0,0,0,55,55,55,55,55,55,55,55,0,0
0,0,0,0,0,0,55,55,55,55,55,55,55,55,0,0
0,0,0,0,0,0,55,55,55,55,55,55,55,0,0,0
0,0,0,0,0,0,0,55,55,55,0,0,0,0,0,0
0,0,0,0,0,0,0,0,0,0,0,0,0,0,0,0
0,0,0,0,0,0,0,0,0,0,0,0,0,0,0,0
0,0,0,0,0,0,0,0,0,0,0,0,0,0,0,0
0,0,0,0,0,0,0,0,0,0,0,0,0,0,0,0
0,0,0,0,0,0,0,0,0,0,0,0,0,0,0,0
0,0,0,0,0,0,0,0,0,0,0,0,0,0,0,0
0,0,0,0,0,0,0,0,0,0,0,0,0,0,0,0
0,0,0,0,0,0,0,0,0,0,0,0,16,0,0,0
0,0,0,0,0,0,0,0,0,0,0,0,0,0,0,0
0,0,0,0,0,0,0,0,0,0,0,0,0,0,0,0
endlayer

layer
0,0,0,0,0,0,0,0,0,0,0,0,0,0,0,0
0,0,0,0,0,0,0,0,0,0,0,0,0,0,0,0
0,56,56,56,0,0,0,0,0,0,0,55,55,55,0,0
0,56,16,56,0,0,0,0,0,0,55,55,55,55,55,0
0,56,56,56,0,0,0,0,0,55,55,55,55,55,55,0
0,0,0,0,0,0,0,0,55,55,55,55,55,55,55,0
0,0,0,0,0,0,0,0,55,55,55,55,55,55,0,0
0,0,0,0,0,0,0,55,55,55,55,55,55,0,0,0
0,0,0,0,0,0,55,55,55,55,55,55,55,0,0,0
0,0,0,0,0,0,55,55,55,55,55,55,0,0,0,0
0,0,0,0,0,0,55,55,55,55,55,0,0,0,0,0
0,0,0,0,0,0,0,55,55,55,0,0,0,0,0,0
0,0,0,0,0,0,0,0,0,0,0,0,0,0,0,0
0,0,0,0,0,0,0,0,0,0,0,0,0,0,0,0
0,0,0,0,0,0,0,0,0,0,0,0,0,0,0,0
0,0,0,0,0,0,0,0,0,0,0,0,0,0,0,0
0,0,0,0,0,0,0,0,0,0,0,0,0,0,0,0
0,0,0,0,0,0,0,0,0,0,0,0,0,0,0,0
0,0,0,0,0,0,0,0,0,0,0,56,56,56,0,0
0,0,0,0,0,0,0,0,0,0,0,56,16,56,0,0
0,0,0,0,0,0,0,0,0,0,0,56,56,56,0,0
0,0,0,0,0,0,0,0,0,0,0,0,0,0,0,0
endlayer

layer
0,0,0,0,0,0,0,0,0,0,0,0,0,0,0,0
0,0,0,0,0,0,0,0,0,0,0,0,0,0,0,0
0,0,0,0,0,0,0,0,0,0,0,0,0,0,0,0
0,0,16,0,0,0,0,0,0,0,0,0,55,0,0,0
0,0,0,0,0,0,0,0,0,55,55,55,55,55,0,0
0,0,0,0,0,0,0,0,55,55,55,55,55,0,0,0
0,0,0,0,0,0,0,0,55,55,55,55,55,0,0,0
0,0,0,0,0,0,0,0,55,55,55,55,55,0,0,0
0,0,0,0,0,0,0,0,55,55,55,55,0,0,0,0
0,0,0,0,0,0,0,55,55,55,0,0,0,0,0,0
0,0,0,0,0,0,0,0,55,0,0,0,0,0,0,0
0,0,0,0,0,0,0,0,0,0,0,0,0,0,0,0
0,0,0,0,0,0,0,0,0,0,0,0,0,0,0,0
0,0,0,0,0,0,0,0,0,0,0,0,0,0,0,0
0,0,0,0,0,0,0,0,0,0,0,0,0,0,0,0
0,0,0,0,0,0,0,0,0,0,0,0,0,0,0,0
0,0,0,0,0,0,0,0,0,0,0,0,0,0,0,0
0,0,0,0,0,0,0,0,0,0,0,0,0,0,0,0
0,0,0,0,0,0,0,0,0,0,0,0,56,0,0,0
0,0,0,0,0,0,0,0,0,0,0,56,0,56,0,0
0,0,0,0,0,0,0,0,0,0,0,0,56,0,0,0
0,0,0,0,0,0,0,0,0,0,0,0,0,0,0,0
endlayer

layer
0,0,0,0,0,0,0,0,0,0,0,0,0,0,0,0
0,0,0,0,0,0,0,0,0,0,0,0,0,0,0,0
0,56,56,56,0,0,0,0,0,0,0,0,0,0,0,0
0,56,16,56,0,0,0,0,0,0,0,0,0,0,0,0
0,56,56,56,0,0,0,0,0,0,0,0,0,0,0,0
0,0,0,0,0,0,0,0,0,0,55,0,0,0,0,0
0,0,0,0,0,0,0,0,0,55,55,55,0,0,0,0
0,0,0,0,0,0,0,0,0,0,55,0,0,0,0,0
0,0,0,0,0,0,0,0,0,0,0,0,0,0,0,0
0,0,0,0,0,0,0,0,0,0,0,0,0,0,0,0
0,0,0,0,0,0,0,0,0,0,0,0,0,0,0,0
0,0,0,0,0,0,0,0,0,0,0,0,0,0,0,0
0,0,0,0,0,0,0,0,0,0,0,0,0,0,0,0
0,0,0,0,0,0,0,0,0,0,0,0,0,0,0,0
0,0,0,0,0,0,0,0,0,0,0,0,0,0,0,0
0,0,0,0,0,0,0,0,0,0,0,0,0,0,0,0
0,0,0,0,0,0,0,0,0,0,0,0,0,0,0,0
0,0,0,0,0,0,0,0,0,0,0,0,0,0,0,0
0,0,0,0,0,0,0,0,0,0,0,0,0,0,0,0
0,0,0,0,0,0,0,0,0,0,0,0,56,0,0,0
0,0,0,0,0,0,0,0,0,0,0,0,0,0,0,0
0,0,0,0,0,0,0,0,0,0,0,0,0,0,0,0
endlayer

layer
0,0,0,0,0,0,0,0,0,0,0,0,0,0,0,0
0,0,0,0,0,0,0,0,0,0,0,0,0,0,0,0
0,0,56,0,0,0,0,0,0,0,0,0,0,0,0,0
0,56,0,56,0,0,0,0,0,0,0,0,0,0,0,0
0,0,56,0,0,0,0,0,0,0,0,0,0,0,0,0
0,0,0,0,0,0,0,0,0,0,0,0,0,0,0,0
0,0,0,0,0,0,0,0,0,0,0,0,0,0,0,0
0,0,0,0,0,0,0,0,0,0,0,0,0,0,0,0
0,0,0,0,0,0,0,0,0,0,0,0,0,0,0,0
0,0,0,0,0,0,0,0,0,0,0,0,0,0,0,0
0,0,0,0,0,0,0,0,0,0,0,0,0,0,0,0
0,0,0,0,0,0,0,0,0,0,0,0,0,0,0,0
0,0,0,0,0,0,0,0,0,0,0,0,0,0,0,0
0,0,0,0,0,0,0,0,0,0,0,0,0,0,0,0
0,0,0,0,0,0,0,0,0,0,0,0,0,0,0,0
0,0,0,0,0,0,0,0,0,0,0,0,0,0,0,0
0,0,0,0,0,0,0,0,0,0,0,0,0,0,0,0
0,0,0,0,0,0,0,0,0,0,0,0,0,0,0,0
0,0,0,0,0,0,0,0,0,0,0,0,0,0,0,0
0,0,0,0,0,0,0,0,0,0,0,0,0,0,0,0
0,0,0,0,0,0,0,0,0,0,0,0,0,0,0,0
0,0,0,0,0,0,0,0,0,0,0,0,0,0,0,0
endlayer

layer
0,0,0,0,0,0,0,0,0,0,0,0,0,0,0,0
0,0,0,0,0,0,0,0,0,0,0,0,0,0,0,0
0,0,0,0,0,0,0,0,0,0,0,0,0,0,0,0
0,0,56,0,0,0,0,0,0,0,0,0,0,0,0,0
0,0,0,0,0,0,0,0,0,0,0,0,0,0,0,0
0,0,0,0,0,0,0,0,0,0,0,0,0,0,0,0
0,0,0,0,0,0,0,0,0,0,0,0,0,0,0,0
0,0,0,0,0,0,0,0,0,0,0,0,0,0,0,0
0,0,0,0,0,0,0,0,0,0,0,0,0,0,0,0
0,0,0,0,0,0,0,0,0,0,0,0,0,0,0,0
0,0,0,0,0,0,0,0,0,0,0,0,0,0,0,0
0,0,0,0,0,0,0,0,0,0,0,0,0,0,0,0
0,0,0,0,0,0,0,0,0,0,0,0,0,0,0,0
0,0,0,0,0,0,0,0,0,0,0,0,0,0,0,0
0,0,0,0,0,0,0,0,0,0,0,0,0,0,0,0
0,0,0,0,0,0,0,0,0,0,0,0,0,0,0,0
0,0,0,0,0,0,0,0,0,0,0,0,0,0,0,0
0,0,0,0,0,0,0,0,0,0,0,0,0,0,0,0
0,0,0,0,0,0,0,0,0,0,0,0,0,0,0,0
0,0,0,0,0,0,0,0,0,0,0,0,0,0,0,0
0,0,0,0,0,0,0,0,0,0,0,0,0,0,0,0
0,0,0,0,0,0,0,0,0,0,0,0,0,0,0,0
endlayer

