
# Created by Ruins mod version 15.0 Ingame Parser
# authoring Player: SunsOfOld

weight=100
embed_into_distance=1
acceptable_target_blocks=
unacceptable_target_blocks=flowing_water,water,flowing_lava,lava,sand
dimensions=18,14,14
allowable_overhang=0
max_leveling=4
leveling_buffer=0
preserve_water=0
preserve_lava=0
uniqueMinDistance=1000000
preventRotation=1

rule1=0,100,preserveBlock
rule2=0,100,minecraft:grass-0
rule3=0,100,BiomesOPlenty:planks-3
rule4=0,100,minecraft:dirt-0
rule5=0,100,minecraft:stone-0
rule6=0,100,minecraft:cobblestone-0
rule7=0,100,minecraft:tallgrass-1
rule8=0,100,minecraft:rail-1
rule9=0,100,minecraft:double_plant-2
rule10=0,100,BiomesOPlenty:logs4-4
rule11=0,100,BiomesOPlenty:logs4-0
rule12=0,100,BiomesOPlenty:foliage-4
rule13=0,100,minecraft:yellow_flower-0
rule14=0,100,GardenTrees:thin_log-0
rule15=0,100,minecraft:red_flower-0
rule16=0,100,BiomesOPlenty:logs1-3
rule17=0,100,ExtrabiomesXL:flower2-14
rule18=0,100,ExtrabiomesXL:flower3-6
rule19=0,100,minecraft:double_plant-8
rule20=0,100,minecraft:monster_egg-0
rule21=0,100,chisel:torch6-5
rule22=0,100,BiomesOPlenty:leaves2-1
rule23=0,100,BiomesOPlenty:fruitBop-4
rule24=0,100,BiomesOPlenty:colorizedLeaves2-1

layer
1,1,1,1,1,1,1,1,3,1,2,1,1,1
2,1,2,1,1,1,2,2,3,1,2,1,1,1
1,1,1,1,2,2,1,1,3,1,1,1,2,1
5,1,5,2,1,1,1,2,3,1,4,2,1,1
5,1,2,1,2,1,1,1,3,1,2,1,2,1
2,1,1,1,1,2,1,1,3,1,1,2,1,1
1,2,1,2,1,1,1,1,3,6,1,2,1,1
1,1,2,1,1,1,1,2,3,1,1,2,2,1
1,1,1,2,2,2,2,1,3,1,2,1,2,1
1,1,1,2,4,2,1,1,3,1,1,1,1,1
1,1,2,1,2,1,2,1,3,5,1,1,2,1
2,2,2,1,1,2,2,1,3,1,1,1,1,1
2,1,1,1,2,1,1,2,3,1,1,1,1,1
2,2,1,1,1,2,2,1,3,1,1,1,2,1
endlayer

layer
0,0,0,0,0,0,0,0,8,0,7,0,0,0
7,5,7,0,0,0,7,9,8,0,7,0,0,0
5,2,5,0,7,7,10,0,8,0,0,0,7,0
5,5,0,7,0,0,10,12,0,0,11,9,0,0
0,5,7,0,13,0,10,0,8,0,7,0,7,0
9,0,0,0,0,7,10,0,8,0,0,7,0,0
0,9,0,7,0,0,10,0,8,14,0,7,0,0
0,0,7,0,0,0,0,7,8,0,0,9,9,0
0,0,0,7,15,12,7,0,8,0,7,0,7,0
0,0,0,7,16,7,0,0,8,0,5,2,0,0
0,0,17,0,7,0,7,0,8,0,5,5,0,0
7,7,7,0,0,0,18,0,8,0,5,5,5,0
9,0,0,0,7,0,0,7,8,0,0,5,0,0
13,7,0,0,0,7,9,0,8,0,0,0,0,0
endlayer

layer
0,0,0,0,0,0,0,0,0,0,0,0,0,0
0,0,0,0,0,0,0,19,0,0,0,0,0,0
20,7,0,0,0,0,0,0,0,0,0,0,0,0
0,0,0,0,0,0,0,0,0,0,11,19,0,0
0,0,0,0,0,0,0,0,0,0,0,0,0,0
19,0,0,0,0,0,0,0,0,0,0,0,0,0
0,19,0,0,0,0,0,0,0,21,0,0,0,0
0,0,0,0,0,0,0,0,0,0,0,19,19,0
0,0,0,0,0,0,0,0,0,0,0,0,0,0
0,0,0,0,16,0,0,0,0,0,0,9,0,0
0,0,0,0,0,0,0,0,0,0,0,0,0,0
0,0,0,0,0,0,0,0,0,0,0,5,0,0
19,0,0,0,0,0,0,0,0,0,0,0,0,0
0,0,0,0,0,0,19,0,0,0,0,0,0,0
endlayer

layer
0,0,0,0,0,0,0,0,0,0,0,0,0,0
0,0,0,0,0,0,0,0,0,0,0,0,0,0
0,0,0,0,0,0,0,0,0,0,0,0,0,0
0,0,0,0,0,0,0,0,0,0,11,0,0,0
0,0,0,0,0,0,0,0,0,0,0,0,0,0
0,0,0,0,0,0,0,0,0,0,0,0,0,0
0,0,0,0,0,0,0,0,0,0,0,0,0,0
0,0,0,22,22,22,0,0,0,0,0,0,0,0
0,0,22,22,22,22,22,0,0,0,0,0,0,0
0,0,22,22,16,22,22,0,0,0,0,19,0,0
0,0,22,22,22,22,22,0,0,0,0,0,0,0
0,0,0,22,22,22,0,0,0,0,0,0,0,0
0,0,0,0,0,0,0,0,0,0,0,0,0,0
0,0,0,0,0,0,0,0,0,0,0,0,0,0
endlayer

layer
0,0,0,0,0,0,0,0,0,0,0,0,0,0
0,0,0,0,0,0,0,0,0,0,0,0,0,0
0,0,0,0,0,0,0,0,0,0,0,0,0,0
0,0,0,0,0,0,0,0,0,0,11,0,0,0
0,0,0,0,0,0,0,0,0,0,0,0,0,0
0,0,0,0,0,0,0,0,0,0,0,0,0,0
0,0,0,0,0,0,0,0,0,0,0,0,0,0
0,0,0,0,0,0,0,0,0,0,0,0,0,0
0,0,0,0,22,23,0,0,0,0,0,0,0,0
0,0,0,22,16,22,0,0,0,0,0,0,0,0
0,0,0,0,22,0,0,0,0,0,0,0,0,0
0,0,0,0,0,0,0,0,0,0,0,0,0,0
0,0,0,0,0,0,0,0,0,0,0,0,0,0
0,0,0,0,0,0,0,0,0,0,0,0,0,0
endlayer

layer
0,0,0,0,0,0,0,0,0,0,0,0,0,0
0,0,0,0,0,0,0,0,0,0,0,0,24,0
0,0,0,0,0,0,0,0,0,0,0,0,0,0
0,0,0,0,0,0,0,0,0,0,11,0,0,0
0,0,0,0,0,0,0,0,0,0,0,0,0,0
0,0,0,0,0,0,0,0,0,0,0,0,0,0
0,0,0,22,22,22,0,0,0,0,0,0,0,0
0,0,22,22,22,22,22,0,0,0,0,0,0,0
0,22,22,22,22,22,22,22,0,0,0,0,0,0
0,22,22,22,16,22,22,22,0,0,0,0,0,0
0,22,22,22,22,22,22,22,0,0,0,0,0,0
0,22,22,22,22,22,22,22,0,0,0,0,0,0
0,0,22,22,22,22,22,0,0,0,0,0,0,0
0,0,0,0,0,0,0,0,0,0,0,0,0,0
endlayer

layer
0,0,0,0,0,0,0,0,0,0,0,0,0,0
0,0,0,0,0,0,0,0,0,0,0,24,0,0
0,0,0,0,0,0,0,0,0,0,0,0,24,0
0,0,0,0,0,0,0,0,0,0,11,0,0,0
0,0,0,0,0,0,0,0,0,0,0,0,0,0
0,0,0,0,0,0,0,0,0,0,0,0,0,0
0,0,0,0,0,0,0,0,0,0,0,0,0,0
0,0,0,22,22,22,0,0,0,0,0,0,0,0
0,0,22,22,22,22,22,0,0,0,0,0,0,0
0,0,22,22,16,22,22,0,0,0,0,0,0,0
0,0,22,22,22,22,22,0,0,0,0,0,0,0
0,0,0,22,22,22,0,0,0,0,0,0,0,0
0,0,0,0,0,0,0,0,0,0,0,0,0,0
0,0,0,0,0,0,0,0,0,0,0,0,0,0
endlayer

layer
0,0,0,0,0,0,0,0,0,0,0,0,0,0
0,0,0,0,0,0,0,0,0,0,0,0,0,0
0,0,0,0,0,0,0,0,0,24,24,24,0,0
0,0,0,0,0,0,0,0,0,24,11,24,0,0
0,0,0,0,0,0,0,0,24,24,24,24,0,0
0,0,0,0,0,0,0,0,24,24,0,0,24,0
0,0,0,0,0,0,0,0,0,0,0,0,0,0
0,0,0,0,0,0,0,0,0,0,0,0,0,0
0,0,0,0,22,0,0,0,0,0,0,0,0,0
0,0,0,22,16,22,0,0,0,0,0,0,0,0
0,0,0,0,22,0,0,0,0,0,0,0,0,0
0,0,0,0,0,0,0,0,0,0,0,0,0,0
0,0,0,0,0,0,0,0,0,0,0,0,0,0
0,0,0,0,0,0,0,0,0,0,0,0,0,0
endlayer

layer
0,0,0,0,0,0,0,0,0,0,0,0,0,0
0,0,0,0,0,0,0,0,24,24,0,0,0,0
0,0,0,0,0,0,0,0,24,0,0,0,0,0
0,0,0,0,0,0,0,0,0,0,11,0,0,0
0,0,0,0,0,0,0,0,0,0,0,0,24,0
0,0,0,0,0,0,0,0,0,0,0,24,0,0
0,0,22,22,22,22,22,0,0,0,0,0,0,0
0,22,22,22,22,22,22,22,0,0,0,0,0,0
0,22,22,22,22,22,22,22,0,0,0,0,0,0
0,22,22,22,16,22,22,22,0,0,0,0,0,0
0,22,22,22,22,22,22,22,0,0,0,0,0,0
0,22,22,22,22,22,22,22,0,0,0,0,0,0
0,0,22,22,22,22,22,0,0,0,0,0,0,0
0,0,0,0,0,0,0,0,0,0,0,0,0,0
endlayer

layer
0,0,0,0,0,0,0,0,0,0,0,0,0,0
0,0,0,0,0,0,0,0,0,0,0,0,24,0
0,0,0,0,0,0,0,0,0,24,24,24,0,0
0,0,0,0,0,0,0,0,0,24,11,24,0,0
0,0,0,0,0,0,0,0,0,24,24,24,0,0
0,0,0,0,0,0,0,0,24,0,0,0,0,0
0,0,0,0,0,0,0,0,0,0,0,0,0,0
0,0,0,22,22,22,0,0,0,0,0,0,0,0
0,0,22,22,22,22,22,0,0,0,0,0,0,0
0,0,22,22,16,22,22,0,0,0,0,0,0,0
0,0,22,22,22,22,22,0,0,0,0,0,0,0
0,0,0,22,22,22,0,0,0,0,0,0,0,0
0,0,0,0,0,0,0,0,0,0,0,0,0,0
0,0,0,0,0,0,0,0,0,0,0,0,0,0
endlayer

layer
0,0,0,0,0,0,0,0,0,0,0,0,0,0
0,0,0,0,0,0,0,0,0,0,0,24,0,0
0,0,0,0,0,0,0,0,0,0,0,0,24,0
0,0,0,0,0,0,0,0,0,0,11,0,0,0
0,0,0,0,0,0,0,0,24,0,0,0,0,0
0,0,0,0,0,0,0,0,0,24,0,0,0,0
0,0,0,0,0,0,0,0,0,0,0,0,0,0
0,0,0,0,0,0,0,0,0,0,0,0,0,0
0,0,0,0,22,0,0,0,0,0,0,0,0,0
0,0,0,22,16,22,0,0,0,0,0,0,0,0
0,0,0,0,22,0,0,0,0,0,0,0,0,0
0,0,0,0,0,0,0,0,0,0,0,0,0,0
0,0,0,0,0,0,0,0,0,0,0,0,0,0
0,0,0,0,0,0,0,0,0,0,0,0,0,0
endlayer

layer
0,0,0,0,0,0,0,0,0,0,0,0,0,0
0,0,0,0,0,0,0,0,0,0,0,0,0,0
0,0,0,0,0,0,0,0,0,24,24,24,0,0
0,0,0,0,0,0,0,0,0,24,11,24,0,0
0,0,0,0,0,0,0,0,0,24,24,24,0,0
0,0,0,0,0,0,0,0,0,0,0,0,24,0
0,0,22,22,22,22,22,0,0,0,0,0,0,0
0,22,22,22,22,22,22,22,0,0,0,0,0,0
0,22,22,22,22,22,22,22,0,0,0,0,0,0
0,22,22,22,16,22,22,22,0,0,0,0,0,0
0,22,22,22,22,22,22,22,0,0,0,0,0,0
0,22,22,22,22,22,22,22,0,0,0,0,0,0
0,0,22,22,22,22,22,0,0,0,0,0,0,0
0,0,0,0,0,0,0,0,0,0,0,0,0,0
endlayer

layer
0,0,0,0,0,0,0,0,0,0,0,0,0,0
0,0,0,0,0,0,0,0,24,24,0,0,0,0
0,0,0,0,0,0,0,0,24,0,0,0,0,0
0,0,0,0,0,0,0,0,0,0,11,0,0,0
0,0,0,0,0,0,0,0,0,0,0,0,24,0
0,0,0,0,0,0,0,0,0,0,0,24,0,0
0,0,0,0,0,0,0,0,0,0,0,0,0,0
0,0,0,22,22,22,0,0,0,0,0,0,0,0
0,0,22,22,22,22,22,0,0,0,0,0,0,0
0,0,22,22,16,22,22,0,0,0,0,0,0,0
0,0,22,22,22,22,22,0,0,0,0,0,0,0
0,0,0,22,22,22,0,0,0,0,0,0,0,0
0,0,0,0,0,0,0,0,0,0,0,0,0,0
0,0,0,0,0,0,0,0,0,0,0,0,0,0
endlayer

layer
0,0,0,0,0,0,0,0,0,0,0,0,0,0
0,0,0,0,0,0,0,0,0,0,0,0,0,0
0,0,0,0,0,0,0,0,0,24,24,24,0,0
0,0,0,0,0,0,0,0,0,24,11,24,0,0
0,0,0,0,0,0,0,0,0,24,24,24,0,0
0,0,0,0,0,0,0,0,0,0,0,0,0,0
0,0,0,0,0,0,0,0,0,0,0,0,0,0
0,0,0,0,0,0,0,0,0,0,0,0,0,0
0,0,0,0,22,0,0,0,0,0,0,0,0,0
0,0,0,22,16,22,0,0,0,0,0,0,0,0
0,0,0,0,22,0,0,0,0,0,0,0,0,0
0,0,0,0,0,0,0,0,0,0,0,0,0,0
0,0,0,0,0,0,0,0,0,0,0,0,0,0
0,0,0,0,0,0,0,0,0,0,0,0,0,0
endlayer

layer
0,0,0,0,0,0,0,0,0,0,0,0,0,0
0,0,0,0,0,0,0,0,0,0,0,0,0,0
0,0,0,0,0,0,0,0,0,0,0,0,0,0
0,0,0,0,0,0,0,0,0,0,11,0,0,0
0,0,0,0,0,0,0,0,0,0,0,0,0,0
0,0,0,0,0,0,0,0,0,0,0,0,0,0
0,0,0,0,0,0,0,0,0,0,0,0,0,0
0,0,0,22,22,22,0,0,0,0,0,0,0,0
0,0,22,22,22,22,22,0,0,0,0,0,0,0
0,0,22,22,16,22,22,0,0,0,0,0,0,0
0,0,22,22,22,22,22,0,0,0,0,0,0,0
0,0,0,22,22,22,0,0,0,0,0,0,0,0
0,0,0,0,0,0,0,0,0,0,0,0,0,0
0,0,0,0,0,0,0,0,0,0,0,0,0,0
endlayer

layer
0,0,0,0,0,0,0,0,0,0,0,0,0,0
0,0,0,0,0,0,0,0,0,0,0,0,0,0
0,0,0,0,0,0,0,0,0,24,24,24,0,0
0,0,0,0,0,0,0,0,0,24,11,24,0,0
0,0,0,0,0,0,0,0,0,24,24,24,0,0
0,0,0,0,0,0,0,0,0,0,0,0,0,0
0,0,0,0,0,0,0,0,0,0,0,0,0,0
0,0,0,0,0,0,0,0,0,0,0,0,0,0
0,0,0,0,22,0,0,0,0,0,0,0,0,0
0,0,0,22,16,22,0,0,0,0,0,0,0,0
0,0,0,0,22,0,0,0,0,0,0,0,0,0
0,0,0,0,0,0,0,0,0,0,0,0,0,0
0,0,0,0,0,0,0,0,0,0,0,0,0,0
0,0,0,0,0,0,0,0,0,0,0,0,0,0
endlayer

layer
0,0,0,0,0,0,0,0,0,0,0,0,0,0
0,0,0,0,0,0,0,0,0,0,0,0,0,0
0,0,0,0,0,0,0,0,0,0,24,0,0,0
0,0,0,0,0,0,0,0,0,24,0,24,0,0
0,0,0,0,0,0,0,0,0,0,24,0,0,0
0,0,0,0,0,0,0,0,0,0,0,0,0,0
0,0,0,0,0,0,0,0,0,0,0,0,0,0
0,0,0,0,0,0,0,0,0,0,0,0,0,0
0,0,0,0,0,0,0,0,0,0,0,0,0,0
0,0,0,0,22,0,0,0,0,0,0,0,0,0
0,0,0,0,0,0,0,0,0,0,0,0,0,0
0,0,0,0,0,0,0,0,0,0,0,0,0,0
0,0,0,0,0,0,0,0,0,0,0,0,0,0
0,0,0,0,0,0,0,0,0,0,0,0,0,0
endlayer

layer
0,0,0,0,0,0,0,0,0,0,0,0,0,0
0,0,0,0,0,0,0,0,0,0,0,0,0,0
0,0,0,0,0,0,0,0,0,0,0,0,0,0
0,0,0,0,0,0,0,0,0,0,24,0,0,0
0,0,0,0,0,0,0,0,0,0,0,0,0,0
0,0,0,0,0,0,0,0,0,0,0,0,0,0
0,0,0,0,0,0,0,0,0,0,0,0,0,0
0,0,0,0,0,0,0,0,0,0,0,0,0,0
0,0,0,0,22,0,0,0,0,0,0,0,0,0
0,0,0,22,22,22,0,0,0,0,0,0,0,0
0,0,0,0,22,0,0,0,0,0,0,0,0,0
0,0,0,0,0,0,0,0,0,0,0,0,0,0
0,0,0,0,0,0,0,0,0,0,0,0,0,0
0,0,0,0,0,0,0,0,0,0,0,0,0,0
endlayer

