
# Created by Ruins mod version 15.0 Ingame Parser
# authoring Player: SunsOfOld

weight=100
embed_into_distance=1
acceptable_target_blocks=
unacceptable_target_blocks=flowing_water,water,flowing_lava,lava,sand
dimensions=15,12,16
allowable_overhang=0
max_leveling=4
leveling_buffer=0
preserve_water=0
preserve_lava=0
uniqueMinDistance=1000000
preventRotation=1

rule1=0,100,minecraft:grass-0
rule2=0,100,preserveBlock
rule3=0,100,BiomesOPlenty:planks-3
rule4=0,100,minecraft:dirt-0
rule5=0,100,minecraft:cobblestone-0
rule6=0,100,minecraft:tallgrass-1
rule7=0,100,minecraft:rail-1
rule8=0,100,minecraft:double_plant-2
rule9=0,100,minecraft:yellow_flower-0
rule10=0,100,BiomesOPlenty:logs4-0
rule11=0,100,ExtrabiomesXL:flower3-1
rule12=0,100,minecraft:red_flower-0
rule13=0,100,GardenTrees:thin_log-0
rule14=0,100,BiomesOPlenty:logs1-3
rule15=0,100,ExtrabiomesXL:flower1-7
rule16=0,100,minecraft:rail-0
rule17=0,100,minecraft:rail-8
rule18=0,100,minecraft:double_plant-8
rule19=0,100,chisel:torch6-5
rule20=0,100,BiomesOPlenty:leaves2-1
rule21=0,100,BiomesOPlenty:colorizedLeaves2-1
rule22=0,100,BiomesOPlenty:fruitBop-4

layer
1,2,3,2,1,2,2,2,2,2,1,2,2,2,2,1
2,2,3,1,2,2,1,1,2,2,2,1,2,2,2,2
2,1,3,2,2,1,2,4,2,1,2,1,1,4,2,2
2,2,3,2,1,2,4,1,1,2,2,1,1,1,1,1
1,2,3,2,2,2,1,2,2,1,1,2,2,2,2,1
2,5,3,2,2,1,2,1,2,2,1,2,2,1,2,1
2,2,3,2,1,4,1,2,1,2,2,2,1,2,2,1
2,2,3,2,1,1,2,2,2,2,1,2,2,1,2,2
1,2,3,2,2,2,2,1,1,2,2,1,2,5,1,1
1,2,3,3,3,3,3,3,3,3,3,3,3,3,3,3
2,2,2,1,1,2,2,2,2,1,1,1,2,2,2,2
2,2,2,2,2,2,2,1,2,2,2,2,2,1,2,2
endlayer

layer
8,0,7,0,6,0,0,0,0,0,0,0,0,0,0,6
0,0,7,6,0,0,0,6,0,0,0,9,0,0,0,0
0,9,7,0,0,11,1,1,0,6,0,0,6,10,0,0
0,0,7,0,0,1,1,8,6,0,0,6,8,6,6,6
6,0,7,0,0,0,12,0,0,6,6,0,0,0,0,8
0,13,7,0,0,6,0,6,0,0,6,0,0,8,0,6
0,0,7,0,6,14,0,0,6,0,0,0,6,0,0,6
0,0,7,0,0,6,0,0,0,0,8,0,0,6,0,0
6,0,7,0,0,0,0,15,6,0,0,6,0,13,0,0
6,0,17,16,16,16,16,16,16,16,16,16,16,16,16,16
0,0,0,6,6,0,0,0,0,6,6,6,0,0,0,0
0,0,0,0,0,0,0,8,0,0,0,0,0,6,0,0
endlayer

layer
18,0,0,0,0,0,0,0,0,0,0,0,0,0,0,0
0,0,0,0,0,0,0,0,0,0,0,0,0,0,0,0
0,0,0,0,0,0,6,6,0,0,0,0,0,10,0,0
0,0,0,0,0,6,0,18,0,0,0,0,18,0,0,0
0,0,0,0,0,0,0,0,0,0,0,0,0,0,0,18
0,19,0,0,0,0,0,0,0,0,0,0,0,18,0,0
0,0,0,0,0,14,0,0,0,0,0,0,0,0,0,0
0,0,0,0,0,0,0,0,0,0,18,0,0,0,0,0
0,0,0,0,0,0,0,0,0,0,0,0,0,19,0,0
0,0,0,0,0,0,0,0,0,0,0,0,0,0,0,0
0,0,0,0,0,0,0,0,0,0,0,0,0,0,0,0
0,0,0,0,0,0,0,18,0,0,0,0,0,0,0,0
endlayer

layer
0,0,0,0,0,0,0,0,0,0,0,0,0,0,0,0
0,0,0,0,0,0,0,0,0,0,0,0,0,0,0,0
0,0,0,0,0,0,0,0,0,0,0,0,0,10,0,0
0,0,0,0,0,0,0,0,0,0,0,0,0,0,0,0
0,0,0,0,0,0,0,0,0,0,0,0,0,0,0,0
0,0,0,0,0,20,0,0,0,0,0,0,0,0,0,0
0,0,0,0,20,14,20,0,0,0,0,0,0,0,0,0
0,0,0,0,0,20,0,0,0,0,0,0,0,0,0,0
0,0,0,0,0,0,0,0,0,0,0,0,0,0,0,0
0,0,0,0,0,0,0,0,0,0,0,0,0,0,0,0
0,0,0,0,0,0,0,0,0,0,0,0,0,0,0,0
0,0,0,0,0,0,0,0,0,0,0,0,0,0,0,0
endlayer

layer
0,0,0,0,0,0,0,0,0,0,0,0,0,0,0,0
0,0,0,0,0,0,0,0,0,0,0,0,0,0,0,0
0,0,0,0,0,0,0,0,0,0,0,0,0,10,0,0
0,0,0,20,20,20,20,20,0,0,0,0,0,0,0,0
0,0,20,20,20,20,20,20,20,0,0,0,0,0,0,0
0,0,20,20,20,20,20,20,20,0,0,0,0,0,0,0
0,0,20,20,20,14,20,20,20,0,0,0,0,0,0,0
0,0,20,20,20,20,20,20,20,0,0,0,0,0,0,0
0,0,20,20,20,20,20,20,20,0,0,0,0,0,0,0
0,0,0,20,20,20,20,20,0,0,0,0,0,0,0,0
0,0,0,0,0,0,0,0,0,0,0,0,0,0,0,0
0,0,0,0,0,0,0,0,0,0,0,0,0,0,0,0
endlayer

layer
0,0,0,0,0,0,0,0,0,0,0,0,0,0,21,21
0,0,0,0,0,0,0,0,0,0,0,0,0,0,0,21
0,0,0,0,0,0,0,0,0,0,0,0,0,10,0,0
0,0,0,0,0,0,0,0,0,0,0,0,0,0,0,0
0,0,0,0,20,20,20,0,0,0,0,21,0,0,0,0
0,0,0,20,20,20,20,20,0,0,0,0,0,0,0,0
0,0,0,20,20,14,20,20,0,0,0,0,0,0,0,0
0,0,0,20,20,20,20,20,0,0,0,0,0,0,0,0
0,0,0,0,20,20,20,0,0,0,0,0,0,0,0,0
0,0,0,0,0,0,0,0,0,0,0,0,0,0,0,0
0,0,0,0,0,0,0,0,0,0,0,0,0,0,0,0
0,0,0,0,0,0,0,0,0,0,0,0,0,0,0,0
endlayer

layer
0,0,0,0,0,0,0,0,0,0,0,0,0,0,0,0
0,0,0,0,0,0,0,0,0,0,0,0,21,21,21,0
0,0,0,0,0,0,0,0,0,0,0,0,21,10,21,0
0,0,0,0,0,0,0,0,0,0,0,21,21,21,21,0
0,0,0,0,0,0,0,0,0,0,0,0,21,0,0,0
0,0,0,0,0,20,0,0,0,0,0,0,0,0,0,0
0,0,0,0,20,14,20,0,0,0,0,0,0,0,0,0
0,0,0,0,0,20,0,22,0,0,0,0,0,0,0,0
0,0,0,0,0,0,0,0,0,0,0,0,0,0,0,0
0,0,0,0,0,0,0,0,0,0,0,0,0,0,0,0
0,0,0,0,0,0,0,0,0,0,0,0,0,0,0,0
0,0,0,0,0,0,0,0,0,0,0,0,0,0,0,0
endlayer

layer
0,0,0,0,0,0,0,0,0,0,0,0,0,0,0,0
0,0,0,0,0,0,0,0,0,0,0,0,0,0,0,0
0,0,0,0,0,0,0,0,0,0,0,0,0,10,0,0
0,0,0,20,20,20,20,20,0,0,0,0,0,0,0,0
0,0,20,20,20,20,20,20,20,0,0,0,0,0,0,0
0,0,20,20,20,20,20,20,20,0,0,0,0,0,0,0
0,0,20,20,20,14,20,20,20,0,0,0,0,0,0,0
0,0,20,20,20,20,20,20,20,0,0,0,0,0,0,0
0,0,20,20,20,20,20,20,20,0,0,0,0,0,0,0
0,0,0,20,20,20,20,20,0,0,0,0,0,0,0,0
0,0,0,0,0,0,0,0,0,0,0,0,0,0,0,0
0,0,0,0,0,0,0,0,0,0,0,0,0,0,0,0
endlayer

layer
0,0,0,0,0,0,0,0,0,0,0,21,21,0,0,0
0,0,0,0,0,0,0,0,0,0,0,21,21,21,21,0
0,0,0,0,0,0,0,0,0,0,0,0,21,10,21,0
0,0,0,0,0,0,0,0,0,0,0,0,21,21,21,21
0,0,0,0,20,20,20,0,0,0,0,0,0,0,21,21
0,0,0,20,20,20,20,20,0,0,0,0,0,0,0,0
0,0,0,20,20,14,20,20,0,0,0,0,0,0,0,0
0,0,0,20,20,20,20,20,0,0,0,0,0,0,0,0
0,0,0,0,20,20,20,0,0,0,0,0,0,0,0,0
0,0,0,0,0,0,0,0,0,0,0,0,0,0,0,0
0,0,0,0,0,0,0,0,0,0,0,0,0,0,0,0
0,0,0,0,0,0,0,0,0,0,0,0,0,0,0,0
endlayer

layer
0,0,0,0,0,0,0,0,0,0,0,0,0,0,0,0
0,0,0,0,0,0,0,0,0,0,0,0,0,0,0,0
0,0,0,0,0,0,0,0,0,0,0,0,0,10,0,0
0,0,0,0,0,0,0,0,0,0,0,0,0,0,0,0
0,0,0,0,0,0,0,0,0,0,0,0,0,0,0,0
0,0,0,0,0,20,0,0,0,0,0,0,0,0,0,0
0,0,0,0,20,14,20,0,0,0,0,0,0,0,0,0
0,0,0,0,0,20,0,0,0,0,0,0,0,0,0,0
0,0,0,0,0,0,0,0,0,0,0,0,0,0,0,0
0,0,0,0,0,0,0,0,0,0,0,0,0,0,0,0
0,0,0,0,0,0,0,0,0,0,0,0,0,0,0,0
0,0,0,0,0,0,0,0,0,0,0,0,0,0,0,0
endlayer

layer
0,0,0,0,0,0,0,0,0,0,0,0,0,0,0,0
0,0,0,0,0,0,0,0,0,0,0,0,21,21,21,0
0,0,0,0,0,0,0,0,0,0,0,0,21,10,21,0
0,0,0,0,0,0,0,0,0,0,0,0,21,21,21,0
0,0,0,0,20,20,20,0,0,0,0,0,0,0,0,0
0,0,0,20,20,20,20,20,0,0,0,0,0,0,0,0
0,0,0,20,20,14,20,20,0,0,0,0,0,0,0,0
0,0,0,20,20,20,20,20,0,0,0,0,0,0,0,0
0,0,0,0,20,20,20,0,0,0,0,0,0,0,0,0
0,0,0,0,0,0,0,0,0,0,0,0,0,0,0,0
0,0,0,0,0,0,0,0,0,0,0,0,0,0,0,0
0,0,0,0,0,0,0,0,0,0,0,0,0,0,0,0
endlayer

layer
0,0,0,0,0,0,0,0,0,0,0,0,0,0,0,0
0,0,0,0,0,0,0,0,0,0,0,0,0,21,0,0
0,0,0,0,0,0,0,0,0,0,0,0,21,0,21,0
0,0,0,0,0,0,0,0,0,0,0,0,0,21,0,0
0,0,0,0,0,0,0,0,0,0,0,0,0,0,0,0
0,0,0,0,0,20,0,0,0,0,0,0,0,0,0,0
0,0,0,0,20,14,20,0,0,0,0,0,0,0,0,0
0,0,0,0,0,20,0,0,0,0,0,0,0,0,0,0
0,0,0,0,0,0,0,0,0,0,0,0,0,0,0,0
0,0,0,0,0,0,0,0,0,0,0,0,0,0,0,0
0,0,0,0,0,0,0,0,0,0,0,0,0,0,0,0
0,0,0,0,0,0,0,0,0,0,0,0,0,0,0,0
endlayer

layer
0,0,0,0,0,0,0,0,0,0,0,0,0,0,0,0
0,0,0,0,0,0,0,0,0,0,0,0,0,0,0,0
0,0,0,0,0,0,0,0,0,0,0,0,0,21,0,0
0,0,0,0,0,0,0,0,0,0,0,0,0,0,0,0
0,0,0,0,0,0,0,0,0,0,0,0,0,0,0,0
0,0,0,0,0,0,0,0,0,0,0,0,0,0,0,0
0,0,0,0,0,14,0,0,0,0,0,0,0,0,0,0
0,0,0,0,0,0,0,0,0,0,0,0,0,0,0,0
0,0,0,0,0,0,0,0,0,0,0,0,0,0,0,0
0,0,0,0,0,0,0,0,0,0,0,0,0,0,0,0
0,0,0,0,0,0,0,0,0,0,0,0,0,0,0,0
0,0,0,0,0,0,0,0,0,0,0,0,0,0,0,0
endlayer

layer
0,0,0,0,0,0,0,0,0,0,0,0,0,0,0,0
0,0,0,0,0,0,0,0,0,0,0,0,0,0,0,0
0,0,0,0,0,0,0,0,0,0,0,0,0,0,0,0
0,0,0,0,0,0,0,0,0,0,0,0,0,0,0,0
0,0,0,0,0,0,0,0,0,0,0,0,0,0,0,0
0,0,0,0,0,20,0,0,0,0,0,0,0,0,0,0
0,0,0,0,20,14,20,0,0,0,0,0,0,0,0,0
0,0,0,0,0,20,0,0,0,0,0,0,0,0,0,0
0,0,0,0,0,0,0,0,0,0,0,0,0,0,0,0
0,0,0,0,0,0,0,0,0,0,0,0,0,0,0,0
0,0,0,0,0,0,0,0,0,0,0,0,0,0,0,0
0,0,0,0,0,0,0,0,0,0,0,0,0,0,0,0
endlayer

layer
0,0,0,0,0,0,0,0,0,0,0,0,0,0,0,0
0,0,0,0,0,0,0,0,0,0,0,0,0,0,0,0
0,0,0,0,0,0,0,0,0,0,0,0,0,0,0,0
0,0,0,0,0,0,0,0,0,0,0,0,0,0,0,0
0,0,0,0,0,0,0,0,0,0,0,0,0,0,0,0
0,0,0,0,0,0,0,0,0,0,0,0,0,0,0,0
0,0,0,0,0,20,0,0,0,0,0,0,0,0,0,0
0,0,0,0,0,0,0,0,0,0,0,0,0,0,0,0
0,0,0,0,0,0,0,0,0,0,0,0,0,0,0,0
0,0,0,0,0,0,0,0,0,0,0,0,0,0,0,0
0,0,0,0,0,0,0,0,0,0,0,0,0,0,0,0
0,0,0,0,0,0,0,0,0,0,0,0,0,0,0,0
endlayer

