
# Created by Ruins mod version 15.0 Ingame Parser
# authoring Player: SunsOfOld

weight=100
embed_into_distance=24
acceptable_target_blocks=
unacceptable_target_blocks=flowing_water,water,flowing_lava,lava
dimensions=25,5,5
allowable_overhang=0
max_leveling=2
leveling_buffer=0
preserve_water=0
preserve_lava=0
uniqueMinDistance=1000000
preventRotation=1

rule1=0,100,preserveBlock
rule2=0,100,UndergroundBiomes:igneousStone-9
rule3=0,100,IInventory;minecraft:hopper;VeganOption:sufferingProof#1#0#0+BiomesOPlenty:misc#1#3#1+UndergroundBiomes:fossilPiece#{RepairCost:2,ench:[0:{id:34s,lvl:3s,},1:{id:17s,lvl:5s,},],display:{Name:"Breath of the Undying",},}#2#2+minecraft:skull#1#1#3+minecraft:clock#1#0#4-0
rule4=0,100,UndergroundBiomes:igneousStoneBrick-1
rule5=0,100,UndergroundBiomes:igneousCobblestone-1
rule6=0,100,Skull:0:7-1
rule7=0,100,BiomesOPlenty:stoneFormations-0
rule8=0,100,BiomesOPlenty:stoneFormations-1
rule9=0,100,minecraft:web-0
rule10=0,100,minecraft:trapdoor-11
rule11=2,100,minecraft:redstone_torch-1
rule12=0,100,BiomesOPlenty:leaves1-7

layer
1,1,1,1,1
1,2,2,2,1
1,2,3,2,1
1,2,2,2,1
1,1,1,1,1
endlayer

layer
4,5,5,5,4
5,7,0,6,5
5,0,0,0,5
5,0,0,0,5
4,5,5,5,4
endlayer

layer
4,5,5,5,4
5,0,0,0,5
5,0,0,0,5
5,0,0,0,5
4,5,5,5,4
endlayer

layer
4,5,5,5,4
5,9,0,8,5
5,0,0,0,5
5,8,0,0,5
4,5,5,5,4
endlayer

layer
4,2,2,2,4
2,2,2,2,2
2,2,10,2,2
2,2,2,2,2
4,2,2,2,4
endlayer

layer
1,1,1,1,1
1,1,2,1,1
1,2,0,2,1
1,1,2,1,1
1,1,1,1,1
endlayer

layer
1,1,1,1,1
1,1,2,1,1
1,2,11,2,1
1,1,2,1,1
1,1,1,1,1
endlayer

layer
1,1,1,1,1
1,1,2,1,1
1,2,0,2,1
1,1,2,1,1
1,1,1,1,1
endlayer

layer
1,1,1,1,1
1,1,2,1,1
1,2,0,2,1
1,1,2,1,1
1,1,1,1,1
endlayer

layer
1,1,1,1,1
1,1,2,1,1
1,2,0,2,1
1,1,2,1,1
1,1,1,1,1
endlayer

layer
1,1,1,1,1
1,1,2,1,1
1,2,0,2,1
1,1,2,1,1
1,1,1,1,1
endlayer

layer
1,1,1,1,1
1,1,2,1,1
1,2,0,2,1
1,1,2,1,1
1,1,1,1,1
endlayer

layer
1,1,1,1,1
1,1,2,1,1
1,2,0,2,1
1,1,2,1,1
1,1,1,1,1
endlayer

layer
1,1,1,1,1
1,1,2,1,1
1,2,0,2,1
1,1,2,1,1
1,1,1,1,1
endlayer

layer
1,1,1,1,1
1,1,2,1,1
1,2,0,2,1
1,1,2,1,1
1,1,1,1,1
endlayer

layer
1,1,1,1,1
1,1,2,1,1
1,2,0,2,1
1,1,2,1,1
1,1,1,1,1
endlayer

layer
1,1,1,1,1
1,1,2,1,1
1,2,0,2,1
1,1,2,1,1
1,1,1,1,1
endlayer

layer
1,1,1,1,1
1,1,2,1,1
1,2,0,2,1
1,1,2,1,1
1,1,1,1,1
endlayer

layer
1,1,1,1,1
1,1,2,1,1
1,2,0,2,1
1,1,2,1,1
1,1,1,1,1
endlayer

layer
1,1,1,1,1
1,1,2,1,1
1,2,0,2,1
1,1,2,1,1
1,1,1,1,1
endlayer

layer
1,1,1,1,1
1,1,2,1,1
1,2,0,2,1
1,1,2,1,1
1,1,1,1,1
endlayer

layer
1,1,1,1,1
1,1,2,1,1
1,2,12,2,1
1,1,2,1,1
1,1,1,1,1
endlayer

layer
1,1,1,1,1
1,1,2,1,1
1,2,0,2,1
1,1,2,1,1
1,1,1,1,1
endlayer

layer
1,1,1,1,1
1,1,2,1,1
1,2,0,2,1
1,1,2,1,1
1,1,1,1,1
endlayer

layer
1,1,1,1,1
1,1,1,1,1
1,1,0,1,1
1,1,1,1,1
1,1,1,1,1
endlayer

