
# Created by Ruins mod version 15.0 Ingame Parser
# authoring Player: SunsOfOld

weight=100
embed_into_distance=1
acceptable_target_blocks=
unacceptable_target_blocks=flowing_water,water,flowing_lava,lava
dimensions=6,8,8
allowable_overhang=0
max_leveling=2
leveling_buffer=0
preserve_water=0
preserve_lava=0
uniqueMinDistance=1000000
preventRotation=1

rule1=0,100,minecraft:grass-0
rule2=0,100,minecraft:dirt-0
rule3=0,100,minecraft:log2-1
rule4=0,100,BiomesOPlenty:leaves1-7
rule5=0,100,BiomesOPlenty:leaves1-15
rule6=0,100,minecraft:fence-0

layer
1,2,1,1,1,1,2,1
1,1,1,1,1,1,1,1
1,1,1,1,1,1,1,1
1,1,1,1,1,1,1,1
1,1,1,1,1,1,1,1
1,1,1,1,1,1,1,1
1,2,1,1,1,1,2,1
1,1,1,1,1,1,1,1
endlayer

layer
0,3,0,0,0,0,3,0
0,5,0,0,0,0,4,0
0,5,0,0,0,0,4,0
0,5,0,0,0,0,4,0
0,5,0,0,0,0,4,0
0,5,0,0,0,0,4,0
0,3,0,0,0,0,3,0
0,0,0,0,0,0,4,0
endlayer

layer
0,3,0,0,0,0,3,0
0,6,0,0,0,0,6,0
0,6,0,0,0,0,6,0
0,6,0,0,0,0,6,0
0,6,0,0,0,0,6,0
0,6,0,0,0,0,6,0
0,3,0,0,0,0,3,0
0,0,0,0,0,0,4,0
endlayer

layer
5,3,0,0,0,0,3,0
0,6,0,0,0,0,6,0
0,0,0,0,0,0,0,0
0,6,0,0,0,0,6,4
0,5,0,0,0,0,0,0
0,6,0,0,0,0,6,0
0,3,0,0,0,0,3,0
0,0,0,0,0,0,4,0
endlayer

layer
0,5,0,0,0,0,4,0
0,5,5,4,4,4,4,0
0,0,0,4,4,0,0,0
0,5,5,4,4,4,4,4
0,0,0,0,4,0,0,0
0,5,5,4,4,4,0,0
0,5,0,0,0,4,4,0
0,0,0,0,0,0,0,0
endlayer

layer
0,0,0,0,0,0,0,0
0,0,0,0,0,4,0,0
0,0,0,0,0,0,0,0
0,0,0,0,4,0,0,0
0,0,0,0,0,0,0,0
0,0,0,0,0,0,0,0
0,0,0,0,0,0,0,0
0,0,0,0,0,0,0,0
endlayer

