
# Created by Ruins mod version 14.9 Ingame Parser
# authoring Player: SunsOfOld

weight=100
embed_into_distance=1
acceptable_target_blocks=
unacceptable_target_blocks=flowing_water,water,flowing_lava,lava
dimensions=15,5,5
allowable_overhang=0
max_leveling=2
leveling_buffer=0
preserve_water=0
preserve_lava=0
uniqueMinDistance=1000000
preventRotation=1

rule1=0,100,minecraft:stone-0

layer
1,1,1,1,1
1,1,1,1,1
1,1,1,1,1
1,1,1,1,1
1,1,1,1,1
endlayer

layer
0,1,1,1,0
0,1,1,1,1
1,1,1,1,1
1,1,1,1,1
0,1,1,1,0
endlayer

layer
0,1,0,0,0
0,1,1,1,0
1,1,1,1,1
0,1,1,1,1
0,0,1,1,0
endlayer

layer
0,1,0,0,0
0,1,1,1,0
0,1,1,1,0
0,1,1,1,0
0,0,1,0,0
endlayer

layer
0,0,0,0,0
0,1,1,1,0
0,1,1,1,0
0,1,1,1,0
0,0,0,0,0
endlayer

layer
0,0,0,0,0
0,0,1,1,0
0,1,1,1,0
0,1,1,1,0
0,0,0,0,0
endlayer

layer
0,0,0,0,0
0,0,1,0,0
0,1,1,1,0
0,1,1,1,0
0,0,0,0,0
endlayer

layer
0,0,0,0,0
0,0,1,0,0
0,1,1,1,0
0,0,1,1,0
0,0,0,0,0
endlayer

layer
0,0,0,0,0
0,0,1,0,0
0,1,1,1,0
0,0,1,1,0
0,0,0,0,0
endlayer

layer
0,0,0,0,0
0,0,1,0,0
0,1,1,0,0
0,0,0,1,0
0,0,0,0,0
endlayer

layer
0,0,0,0,0
0,0,1,0,0
0,1,1,0,0
0,0,0,0,0
0,0,0,0,0
endlayer

layer
0,0,0,0,0
0,0,1,0,0
0,0,1,0,0
0,0,0,0,0
0,0,0,0,0
endlayer

layer
0,0,0,0,0
0,0,0,0,0
0,0,1,0,0
0,0,0,0,0
0,0,0,0,0
endlayer

layer
0,0,0,0,0
0,0,0,0,0
0,0,1,0,0
0,0,0,0,0
0,0,0,0,0
endlayer

layer
0,0,0,0,0
0,0,0,0,0
0,0,1,0,0
0,0,0,0,0
0,0,0,0,0
endlayer

