
# Created by Ruins mod version 15.0 Ingame Parser
# authoring Player: SunsOfOld

weight=100
embed_into_distance=0
acceptable_target_blocks=
unacceptable_target_blocks=flowing_water,water,flowing_lava,lava
dimensions=13,14,13
allowable_overhang=0
max_leveling=4
leveling_buffer=0
preserve_water=0
preserve_lava=0
uniqueMinDistance=1000000
preventRotation=1

rule1=0,100,UndergroundBiomes:metamorphicCobblestone-2
rule2=0,100,BiomesOPlenty:leaves4-13
rule3=0,100,minecraft:log-0
rule4=0,100,chisel:packedice-4
rule5=0,100,chisel:packedice_stairs.5-0
rule6=0,100,plantmegapack:vineSpanishMoss-11
rule7=0,100,chisel:marble-1
rule8=0,100,chisel:packedice-2
rule9=0,100,chisel:packedice-3
rule10=0,100,minecraft:snow-0
rule11=0,100,chisel:marble-10
rule12=0,100,chisel:packedice_stairs.1-3
rule13=0,100,ExtrabiomesXL:planks-3
rule14=0,100,ExtrabiomesXL:planks-7
rule15=0,100,ExtrabiomesXL:stairs.baldcypress-2
rule16=0,100,chisel:packedice_stairs.5-3
rule17=0,100,GardenTrees:thin_log-0
rule18=0,100,plantmegapack:vineSpanishMoss-2
rule19=0,100,plantmegapack:vineSpanishMoss-3
rule20=0,100,chisel:packedice-12
rule21=0,100,chisel:packedice_stairs.1-8
rule22=0,100,chisel:packedice_stairs.1-0
rule23=0,100,plantmegapack:vineSpanishMoss-1
rule24=0,100,chisel:packedice_stairs.5-1
rule25=2,100,WallSign:null:null:null:null-3
rule26=2,100,WallSign:null:null:null:null-5
rule27=0,100,ExtrabiomesXL:door_cypress-1
rule28=0,100,chisel:stained_glass_pane_white-2
rule29=0,100,chisel:stained_glass_pane_white-3
rule30=0,100,chisel:packedice_stairs.2-1
rule31=0,100,chisel:packedice_stairs.1-13
rule32=0,100,ExtrabiomesXL:door_cypress-8
rule33=0,100,chisel:packedice_stairs.1-1
rule34=0,100,GardenTrees:thin_log_fence-0
rule35=0,100,chisel:packedice_stairs.1-5
rule36=0,100,chisel:packedice_stairs.5-7
rule37=0,100,chisel:packedice_stairs.1-7
rule38=0,100,chisel:packedice_stairs.3-0
rule39=0,100,ExtrabiomesXL:stairs.baldcypress-4
rule40=0,100,ExtrabiomesXL:stairs.baldcypress-7
rule41=0,100,chisel:packedice_stairs.3-3
rule42=0,100,chisel:packedice_stairs.3-2
rule43=0,100,chisel:glowstone-4
rule44=0,100,ExtrabiomesXL:stairs.baldcypress-6
rule45=0,100,chisel:packedice_stairs.3-1
rule46=0,100,minecraft:log-8
rule47=0,100,ExtrabiomesXL:stairs.baldcypress-0
rule48=0,100,IInventory;minecraft:chest;harvestcraft:extremechiliItem#1#0#6+harvestcraft:caramelicecreamItem#1#0#11+harvestcraft:strawberrysmoothieItem#1#0#21+harvestcraft:pistachioicecreamItem#1#0#26-5
rule49=0,100,minecraft:bookshelf-0
rule50=0,100,minecraft:bed-9
rule51=0,100,IInventory;minecraft:chest;minecraft:cooked_beef#6#0#7+ExtrabiomesXL:saplings_1#1#7#13+minecraft:slime_ball#1#0#19-5
rule52=0,100,minecraft:bed-1
rule53=0,100,chisel:carpet-0
rule54=0,100,chisel:carpet-3
rule55=2,100,WallSign:null:null:null:null-2
rule56=0,100,ExtrabiomesXL:door_cypress-3
rule57=2,100,WallSign:null:null:null:null-4
rule58=0,100,chisel:stained_glass_pane_white-1
rule59=0,100,minecraft:flower_pot-1
rule60=0,100,ExtrabiomesXL:door_cypress-9
rule61=0,100,chisel:packedice_stairs.6-4
rule62=0,100,chisel:packedice_stairs.6-6
rule63=0,100,chisel:packedice_stairs.6-7
rule64=0,100,chisel:packedice_stairs.6-5
rule65=0,100,chisel:packedice_stairs.7-2
rule66=0,100,chisel:packedice_stairs.7-1
rule67=0,100,chisel:packedice_stairs.7-3
rule68=0,100,chisel:packedice_stairs.7-0
rule69=0,100,ExtrabiomesXL:log1-10
rule70=0,100,IInventory;minecraft:chest;minecraft:name_tag#1#0#0+antiqueatlas:emptyAntiqueAtlas#1#0#5+minecraft:chest#1#0#16+minecraft:enchanted_book#{StoredEnchantments:[0:{id:61s,lvl:3s,},],}#0#17+minecraft:string#2#0#19+minecraft:diamond_hoe#1#0#21-5
rule71=0,100,chisel:packedice_stairs.1-4
rule72=0,100,chisel:packedice_stairs.5-2
rule73=0,100,chisel:marble-0
rule74=0,100,chisel:packedice_stairs.5-5
rule75=0,100,chisel:packedice_stairs.5-4

layer
0,0,0,0,0,0,0,0,0,0,0,0,0
3,2,2,2,2,0,0,0,1,0,0,0,0
10,7,9,9,9,9,8,7,6,5,5,4,0
0,12,11,11,11,11,11,9,10,9,9,10,0
0,8,11,14,13,13,11,9,10,9,9,10,0
0,8,15,13,13,13,11,9,10,10,10,10,0
16,7,8,14,13,13,11,9,10,10,10,10,0
8,7,11,15,13,14,11,9,10,0,8,0,0
0,9,11,8,13,13,11,9,2,0,0,0,0
0,1,11,14,13,1,11,9,2,0,0,0,0
0,1,14,14,1,11,11,9,2,0,0,0,0
10,7,9,9,9,9,9,7,2,0,0,0,0
17,10,10,0,0,0,2,2,2,0,0,0,0
10,10,19,18,18,0,0,0,0,0,0,0,0
endlayer

layer
0,0,0,0,0,0,0,0,0,0,0,0,0
3,0,0,0,0,0,0,0,17,0,0,0,0
0,7,20,20,22,21,20,7,19,0,0,3,0
0,20,0,0,25,24,16,8,23,5,5,4,0
0,8,0,0,0,0,16,8,23,9,9,0,0
0,8,0,0,0,0,26,20,10,9,9,0,0
0,0,0,0,0,0,0,20,10,0,10,0,0
0,27,0,0,0,0,0,20,0,0,8,0,0
0,15,0,0,0,0,0,20,0,0,0,0,0
0,8,0,0,0,0,0,20,0,0,0,0,0
0,20,0,0,0,0,0,20,2,0,0,0,0
0,7,20,20,20,20,20,7,2,0,0,0,0
17,10,0,0,0,0,0,2,2,0,0,0,0
0,0,18,18,18,0,0,0,0,0,0,0,0
endlayer

layer
0,0,0,0,0,0,0,0,0,0,0,0,0
17,0,0,0,0,0,0,0,17,0,0,0,0
0,1,29,28,28,0,28,7,19,0,0,17,0
0,28,0,0,0,0,0,28,23,0,0,3,0
0,21,0,0,0,0,0,28,23,5,5,0,0
0,30,0,0,0,0,0,28,0,9,9,0,0
0,0,0,0,0,0,0,28,0,9,31,0,0
0,32,0,0,0,0,0,28,0,0,31,0,0
0,20,0,0,0,0,0,29,0,0,0,0,0
0,0,0,0,0,0,0,14,0,0,0,0,0
0,33,0,0,0,0,0,28,0,0,0,0,0
0,1,28,28,28,28,28,17,0,0,0,0,0
17,0,0,0,0,0,0,0,17,0,0,0,0
0,0,18,18,18,0,0,0,0,0,0,0,0
endlayer

layer
0,0,0,0,0,0,0,0,0,0,0,0,0
3,0,0,0,0,0,0,0,17,0,0,0,0
0,1,28,28,28,28,0,7,19,0,0,0,0
0,28,0,0,0,0,0,28,23,0,0,34,0
0,0,0,0,0,0,0,28,23,0,0,0,0
0,35,0,0,0,0,0,28,0,21,22,4,0
0,8,0,0,0,0,0,28,0,9,9,0,0
0,36,0,0,0,0,0,28,0,9,8,0,0
0,20,0,0,0,0,0,28,0,0,0,0,0
0,28,0,0,0,0,0,28,0,0,0,0,0
0,28,0,0,0,0,0,28,0,0,0,0,0
0,37,28,28,29,29,28,3,0,0,0,0,0
17,8,0,0,0,0,0,0,17,0,0,0,0
0,0,18,18,18,0,0,0,0,0,0,0,0
endlayer

layer
0,0,0,0,0,0,0,0,0,0,0,0,0
7,38,0,0,0,0,0,8,7,0,0,0,0
41,1,13,13,40,13,39,13,19,0,0,0,0
41,13,13,13,13,13,13,13,23,0,0,0,0
17,13,13,13,13,13,13,1,23,0,0,34,0
17,13,13,13,13,13,13,13,42,0,0,34,0
41,13,13,13,43,13,13,13,4,5,5,4,0
41,13,13,13,43,13,13,13,4,33,4,44,0
41,13,13,13,13,13,13,13,4,44,4,4,0
41,13,13,13,13,13,13,13,42,0,0,0,0
0,8,13,13,13,13,13,13,42,0,0,0,0
0,17,13,13,13,13,13,13,42,0,0,0,0
8,45,45,46,46,46,46,45,7,0,0,0,0
0,0,18,18,18,0,0,0,0,0,0,0,0
endlayer

layer
0,0,0,0,0,0,0,0,0,0,0,0,0
17,0,0,0,0,0,0,0,17,0,0,0,0
0,1,47,20,22,20,20,7,23,0,0,0,0
0,20,51,49,50,49,48,20,23,0,0,0,0
0,17,0,0,52,0,0,20,23,0,0,0,0
0,17,0,54,54,54,53,20,0,0,0,34,0
0,8,53,54,54,54,0,1,55,0,0,34,0
0,0,0,54,54,54,0,56,55,0,0,34,0
0,1,0,0,0,54,0,4,0,0,34,34,0
0,20,54,0,0,0,0,4,0,0,0,0,0
0,20,0,0,0,0,0,20,0,0,0,0,0
0,7,20,20,20,20,20,7,0,0,0,0,0
17,0,0,0,0,34,0,0,17,0,0,0,0
0,0,18,18,0,0,0,0,0,0,0,0,0
endlayer

layer
0,0,0,0,0,0,0,0,0,0,0,0,0
3,57,0,0,0,0,0,0,17,0,0,0,0
25,1,28,0,29,58,28,7,23,0,0,0,0
25,28,0,0,0,59,0,29,0,0,0,0,0
0,28,0,0,0,0,0,28,0,0,0,0,0
0,29,0,0,0,0,0,7,0,0,0,0,0
0,29,0,0,0,0,0,37,55,0,0,0,0
0,0,0,0,0,0,0,60,55,0,0,0,0
25,8,0,0,0,0,0,7,55,0,0,0,0
25,28,0,0,0,0,0,29,0,0,0,0,0
0,29,0,0,0,0,0,28,0,0,0,0,0
0,7,29,58,29,29,29,7,0,0,0,0,0
17,0,0,0,0,17,0,0,17,0,0,0,0
0,0,18,18,0,0,0,0,0,0,0,0,0
endlayer

layer
0,0,0,0,0,0,0,0,0,0,0,0,0
17,61,61,61,8,0,61,61,7,0,0,0,0
0,7,13,13,13,13,13,7,62,0,0,0,0
22,13,0,0,0,0,0,13,62,0,0,0,0
63,13,0,0,0,34,0,13,62,0,0,0,0
12,13,0,0,0,0,0,13,62,0,0,0,0
0,13,0,0,0,0,0,13,62,0,0,0,0
0,57,0,0,0,0,0,13,62,0,0,0,0
63,13,0,0,0,0,0,13,62,0,0,0,0
63,13,0,0,0,0,0,13,62,0,0,0,0
63,13,0,0,0,0,0,13,62,0,0,0,0
63,7,13,13,13,13,13,7,0,0,0,0,0
7,64,64,64,64,17,64,64,3,0,0,0,0
0,0,18,18,0,0,0,0,0,0,0,0,0
endlayer

layer
0,0,0,0,0,0,17,17,17,17,0,0,0
17,38,38,38,38,38,38,38,65,17,0,0,0
0,7,42,45,45,45,41,7,42,0,0,0,0
0,45,45,9,9,9,45,41,42,0,0,0,0
17,42,9,66,66,34,9,41,17,0,0,0,0
41,42,9,65,20,67,9,41,17,0,0,0,0
17,42,9,65,43,67,9,41,17,0,0,0,0
41,42,9,65,43,67,9,41,17,0,0,0,0
41,42,9,65,20,67,9,41,17,0,0,0,0
17,42,9,68,68,67,9,41,42,0,0,0,0
41,38,42,9,9,9,41,38,42,0,0,0,0
41,7,42,38,38,38,41,7,42,0,0,0,0
67,45,8,45,45,45,45,45,66,0,0,0,0
0,0,18,18,0,0,0,0,0,0,0,0,0
endlayer

layer
0,0,0,0,0,0,0,5,5,0,0,0,0
47,69,0,0,69,0,0,69,69,17,0,0,0
17,0,0,0,0,0,22,0,7,0,0,0,0
7,0,0,0,0,0,0,0,7,17,0,0,0
7,0,0,0,0,34,0,0,7,0,0,0,0
17,69,0,69,12,69,69,69,69,17,0,0,0
3,0,0,0,70,0,0,0,24,0,0,0,0
5,0,0,0,0,0,0,0,8,0,0,0,0
17,69,69,69,69,69,69,69,69,0,0,0,0
34,0,0,0,0,0,0,0,7,0,0,0,0
7,0,0,0,0,0,0,0,17,0,0,0,0
7,0,0,0,0,0,0,8,7,0,0,0,0
69,69,69,69,69,69,69,17,46,0,0,0,0
24,0,18,18,24,24,24,0,0,0,0,0,0
endlayer

layer
0,0,0,0,0,0,0,0,0,0,0,0,0
0,0,0,0,0,0,0,0,0,34,0,0,0
0,57,0,0,5,5,22,5,5,5,0,0,0
34,71,0,0,37,69,69,69,69,0,0,0,0
7,0,0,0,71,34,0,0,7,5,0,0,0
73,72,24,24,24,24,24,16,8,0,0,0,0
74,0,0,0,0,0,0,0,74,0,0,0,0
75,0,0,0,0,0,0,0,75,0,0,0,0
73,72,5,5,5,5,5,16,73,9,0,0,0
34,7,7,7,7,7,7,7,7,0,0,0,0
69,69,69,69,69,69,69,69,69,0,0,0,0
17,17,24,24,24,24,24,0,0,0,0,0,0
0,0,0,0,0,0,0,0,0,0,0,0,0
0,0,0,0,0,0,0,0,0,0,0,0,0
endlayer

layer
0,0,0,0,0,0,0,0,0,0,0,0,0
0,0,0,0,0,0,0,0,0,0,0,0,0
0,0,0,0,0,0,0,0,0,0,0,0,0
0,0,0,0,0,0,0,0,0,0,0,0,0
34,0,0,0,0,0,0,0,0,0,0,0,0
5,5,5,5,5,5,5,5,0,0,0,0,0
69,69,69,69,69,69,69,69,47,17,0,0,0
69,0,69,69,69,69,17,69,69,17,0,0,0
24,24,24,24,24,24,0,0,8,0,0,0,0
34,34,34,0,34,0,0,0,34,0,0,0,0
0,0,0,0,0,0,0,0,0,0,0,0,0
0,0,0,0,0,0,0,0,0,0,0,0,0
0,0,0,0,0,0,0,0,0,0,0,0,0
0,0,0,0,0,0,0,0,0,0,0,0,0
endlayer

layer
0,0,0,0,0,0,0,0,0,0,0,0,0
0,0,0,0,0,0,0,0,0,0,0,0,0
0,0,0,0,0,0,0,0,0,0,0,0,0
0,0,0,0,0,0,0,0,0,0,0,0,0
0,0,0,0,0,0,0,0,0,0,0,0,0
0,0,0,0,0,0,0,0,0,0,0,0,0
0,0,5,5,0,0,5,5,0,0,0,0,0
0,0,0,24,24,24,0,0,24,0,0,0,0
0,0,0,0,0,0,0,0,0,0,0,0,0
0,0,0,0,0,0,0,0,0,0,0,0,0
0,0,0,0,0,0,0,0,0,0,0,0,0
0,0,0,0,0,0,0,0,0,0,0,0,0
0,0,0,0,0,0,0,0,0,0,0,0,0
0,0,0,0,0,0,0,0,0,0,0,0,0
endlayer

