
# Created by Ruins mod version 15.0 Ingame Parser
# authoring Player: SunsOfOld

weight=20
embed_into_distance=5
acceptable_target_blocks=
unacceptable_target_blocks=flowing_water,water,flowing_lava,lava
dimensions=25,14,21
allowable_overhang=0
max_leveling=2
leveling_buffer=0
preserve_water=0
preserve_lava=0
uniqueMinDistance=1000000
preventRotation=1

rule1=0,100,preserveBlock
rule2=0,100,minecraft:planks-5
rule3=0,100,minecraft:planks-0
rule4=0,100,minecraft:dark_oak_stairs-2
rule5=0,100,minecraft:dark_oak_stairs-3
rule6=0,100,dendrology:wood0-6
rule7=0,100,minecraft:bed-9
rule8=0,100,IInventory;minecraft:chest;minecraft:arrow#1#0#0+minecraft:arrow#1#0#2+minecraft:arrow#1#0#4+minecraft:arrow#1#0#6+minecraft:arrow#1#0#8+minecraft:arrow#1#0#9+minecraft:arrow#1#0#11+minecraft:arrow#1#0#13+minecraft:arrow#1#0#15+minecraft:arrow#1#0#17+minecraft:arrow#1#0#18+minecraft:arrow#1#0#20+minecraft:arrow#1#0#22+minecraft:arrow#1#0#24+minecraft:arrow#1#0#26-2
rule9=0,100,minecraft:bed-1
rule10=0,100,minecraft:trapdoor-6
rule11=0,100,dendrology:stairs12-2
rule12=0,100,minecraft:trapdoor-7
rule13=0,100,dendrology:stairs12-3
rule14=0,100,minecraft:double_wooden_slab-5
rule15=2,100,minecraft:torch-1
rule16=0,100,IInventory;minecraft:chest;minecraft:enchanted_book#{StoredEnchantments:[0:{id:2s,lvl:4s,},],}#0#0+minecraft:bow#{RepairCost:2,ench:[0:{id:48s,lvl:5s,},],}#0#21+minecraft:chainmail_chestplate#1#0#24-2
rule17=0,100,IInventory;minecraft:chest;minecraft:chainmail_boots#1#0#6+minecraft:name_tag#1#0#11+minecraft:iron_sword#1#0#26-2
rule18=0,100,minecraft:fence-0
rule19=0,100,BiomesOPlenty:colorizedLeaves1-4
rule20=0,100,BiomesOPlenty:leaves3-6
rule21=0,100,BiomesOPlenty:flowerVine-8
rule22=0,100,ExtrabiomesXL:leaves_1-4
rule23=0,100,chisel:glass_pane-14
rule24=0,100,minecraft:web-0
rule25=0,100,minecraft:carpet-13
rule26=0,100,minecraft:lever-13
rule27=0,100,minecraft:lit_redstone_lamp-0
rule28=0,100,minecraft:dark_oak_stairs-1
rule29=0,100,minecraft:wooden_slab-13
rule30=0,100,minecraft:cobblestone-0
rule31=0,100,GardenTrees:ivy-4
rule32=0,100,minecraft:furnace-5
rule33=0,100,GardenTrees:thin_log_fence-5
rule34=0,100,IInventory;minecraft:chest;minecraft:bookshelf#1#0#0+minecraft:clock#1#0#2+minecraft:paper#3#0#6+minecraft:paper#3#0#17-5
rule35=0,100,minecraft:bookshelf-0
rule36=0,100,minecraft:crafting_table-0
rule37=0,100,minecraft:piston-1
rule38=2,100,WallSign:null:null:null:null-4
rule39=0,100,minecraft:wooden_slab-5
rule40=0,100,minecraft:enchanting_table-0
rule41=0,100,minecraft:cauldron-3
rule42=0,100,minecraft:sticky_piston-1
rule43=2,100,WallSign:null:null:null:null-5
rule44=2,100,WallSign:null:null:null:null-2
rule45=0,100,minecraft:dark_oak_stairs-0
rule46=2,100,WallSign:null:null:null:null-3
rule47=0,100,minecraft:carpet-12
rule48=1,100,minecraft:torch-5
rule49=0,100,ExtrabiomesXL:fence-4
rule50=0,100,ExtrabiomesXL:door_fir-0
rule51=0,100,minecraft:trapdoor-11
rule52=0,100,GardenTrees:ivy-8
rule53=0,100,GardenTrees:ivy-1
rule54=0,100,minecraft:stone-0
rule55=0,100,minecraft:stonebrick-2
rule56=0,100,minecraft:stone_slab-8
rule57=0,100,minecraft:lever-11
rule58=0,100,minecraft:wooden_pressure_plate-0
rule59=0,100,IInventory;minecraft:chest;minecraft:item_frame#1#0#1+minecraft:potion#1#8194#3+minecraft:redstone_lamp#2#0#8+minecraft:potion#1#16417#25-2
rule60=0,100,GardenStuff:lattice-0
rule61=0,100,IInventory;minecraft:chest;harvestcraft:pamgrapefruitSapling#1#0#0+plantmegapack:foodBellPepperYellow#1#0#2+plantmegapack:foodEggplant#1#0#4+plantmegapack:berriesSnow#1#0#6+plantmegapack:foodTomato#1#0#8+harvestcraft:rhubarbseedItem#1#0#9+harvestcraft:spinachseedItem#1#0#10+harvestcraft:zucchiniItem#1#0#11+plantmegapack:berriesHuckle#1#0#17+harvestcraft:beanseedItem#1#0#22+harvestcraft:blackberryItem#1#0#23+harvestcraft:cucumberseedItem#1#0#25-3
rule62=0,100,ExtrabiomesXL:door_fir-8
rule63=0,100,minecraft:trapdoor-4
rule64=0,100,minecraft:dirt-0
rule65=0,100,minecraft:trapdoor-5
rule66=0,100,BiomesOPlenty:flowerVine-13
rule67=0,100,minecraft:cobblestone_wall-0
rule68=0,100,minecraft:trapdoor-8
rule69=0,100,minecraft:trapdoor-9
rule70=0,100,plantmegapack:flowerLupine-9
rule71=0,100,plantmegapack:flowerNemesia-5
rule72=0,100,plantmegapack:flowerViolet-0
rule73=0,100,minecraft:lever-2
rule74=2,100,minecraft:torch-4
rule75=2,100,minecraft:torch-2
rule76=0,100,GardenTrees:ivy-9
rule77=0,100,BiomesOPlenty:flowerVine-12
rule78=0,100,ExtrabiomesXL:door_fir-2
rule79=0,100,ChestGenHook:dungeonChest:5-5
rule80=0,100,minecraft:ladder-5
rule81=0,100,harvestcraft:pamcinnamonSapling-0
rule82=0,100,plantmegapack:flowerDottedBlazingstar-0
rule83=0,100,minecraft:trapdoor-14
rule84=0,100,dendrology:stairs8-0
rule85=0,100,minecraft:trapdoor-12
rule86=0,100,plantmegapack:flowerNemesia-8
rule87=2,100,minecraft:torch-3
rule88=0,100,ExtrabiomesXL:saplings_1-13
rule89=0,100,minecraft:tripwire_hook-2
rule90=0,100,VeganOption:bedStraw-3
rule91=0,100,VeganOption:bedStraw-11
rule92=0,100,GardenTrees:ivy-2
rule93=0,100,plantmegapack:bambooTimorBlackSlab-0
rule94=0,100,chisel:cloud-0

layer
1,1,1,1,1,1,1,1,1,1,1,1,1,1,1,1,1,1,1,1,1
1,1,1,1,1,1,1,1,1,1,1,1,1,1,1,1,1,1,1,1,1
1,1,1,1,1,1,1,1,1,1,1,1,1,1,1,1,1,1,1,1,1
1,1,1,1,1,1,1,1,1,1,1,1,1,1,1,1,1,1,1,1,1
1,1,1,1,1,1,1,1,1,1,1,1,1,1,1,1,1,1,1,1,1
1,1,1,1,1,1,1,1,1,1,1,1,1,1,1,1,1,1,1,1,1
1,1,1,1,1,1,1,1,1,1,1,1,1,1,1,1,1,1,1,1,1
1,1,1,1,1,1,1,1,1,1,1,1,1,1,1,1,1,1,1,1,1
1,1,1,1,1,1,1,1,1,1,1,1,1,1,1,1,1,1,1,1,1
1,1,1,1,1,1,1,1,1,1,1,1,1,1,1,1,1,1,1,1,1
1,1,1,1,1,1,1,1,1,1,1,1,1,1,1,1,1,1,1,1,1
1,1,1,1,1,1,1,1,1,1,1,1,1,1,1,1,1,1,1,1,1
1,1,1,1,1,1,1,1,1,1,1,1,1,1,1,1,1,1,1,1,1
1,1,1,1,1,1,1,1,1,1,1,1,1,1,1,1,1,1,1,1,1
endlayer

layer
1,1,1,1,1,1,1,1,1,1,1,1,1,1,1,1,1,1,1,1,1
1,1,1,1,1,1,1,1,1,1,1,1,1,1,1,1,1,1,1,1,1
1,1,1,1,1,1,1,1,2,2,2,2,2,1,1,1,1,1,1,1,1
1,1,1,1,1,1,1,1,2,2,2,2,2,1,1,1,1,1,1,1,1
1,1,1,1,1,1,1,1,2,2,2,2,2,1,1,1,1,1,1,1,1
1,1,1,1,1,1,1,1,2,2,2,2,2,1,1,1,1,1,1,1,1
1,1,1,1,1,1,1,1,2,2,2,2,2,1,1,1,1,1,1,1,1
1,1,1,1,1,1,1,1,2,2,2,2,2,1,1,1,1,1,1,1,1
1,1,1,1,1,1,1,1,2,2,2,2,2,1,1,1,1,1,1,1,1
1,1,1,1,1,1,1,1,2,2,2,2,2,1,1,1,1,1,1,1,1
1,1,1,1,1,1,1,1,2,2,2,2,2,1,1,1,1,1,1,1,1
1,1,1,1,1,1,1,1,2,2,2,2,2,1,1,1,1,1,1,1,1
1,1,1,1,1,1,1,1,1,1,1,1,1,1,1,1,1,1,1,1,1
1,1,1,1,1,1,1,1,1,1,1,1,1,1,1,1,1,1,1,1,1
endlayer

layer
1,1,1,1,1,1,1,1,1,1,1,1,1,1,1,1,1,1,1,1,1
1,1,1,1,1,1,1,1,1,1,1,1,1,1,1,1,1,1,1,1,1
1,1,1,1,1,1,2,2,2,3,3,3,2,2,2,1,1,1,1,1,1
1,1,1,1,1,1,2,2,2,4,0,0,2,2,2,1,1,1,1,1,1
1,1,1,1,1,1,2,2,2,4,0,0,2,2,2,1,1,1,1,1,1
1,1,1,1,1,1,2,2,2,4,0,0,2,2,2,1,1,1,1,1,1
1,1,1,1,1,1,2,2,2,4,0,0,5,2,2,1,1,1,1,1,1
1,1,1,1,1,1,2,2,2,4,0,0,5,2,2,1,1,1,1,1,1
1,1,1,1,1,1,2,2,2,4,0,0,2,2,2,1,1,1,1,1,1
1,1,1,1,1,1,2,2,2,4,0,0,2,2,2,1,1,1,1,1,1
1,1,1,1,1,1,2,2,2,0,0,0,2,2,2,1,1,1,1,1,1
1,1,1,1,1,1,2,2,2,3,3,3,2,2,2,1,1,1,1,1,1
1,1,1,1,1,1,1,1,1,1,1,1,1,1,1,1,1,1,1,1,1
1,1,1,1,1,1,1,1,1,1,1,1,1,1,1,1,1,1,1,1,1
endlayer

layer
1,1,1,1,1,1,1,1,1,1,1,1,1,1,1,1,1,1,1,1,1
1,1,1,1,1,1,1,1,1,1,1,1,1,1,1,1,1,1,1,1,1
1,1,1,1,1,2,2,3,3,6,6,6,3,3,2,2,1,1,1,1,1
1,1,1,1,1,2,2,8,0,0,0,0,0,7,2,2,1,1,1,1,1
1,1,1,1,1,2,2,10,0,0,0,0,0,9,2,2,1,1,1,1,1
1,1,1,1,1,2,2,11,0,0,0,0,0,0,2,2,1,1,1,1,1
1,1,1,1,1,2,2,11,0,0,0,0,0,0,2,2,1,1,1,1,1
1,1,1,1,1,2,2,12,0,0,0,0,0,0,2,2,1,1,1,1,1
1,1,1,1,1,2,2,4,0,0,0,0,0,10,2,2,1,1,1,1,1
1,1,1,1,1,2,2,4,0,0,0,0,0,13,2,2,1,1,1,1,1
1,1,1,1,1,2,2,14,2,0,0,0,0,12,2,2,1,1,1,1,1
1,1,1,1,1,2,2,3,3,6,6,6,3,3,2,2,1,1,1,1,1
1,1,1,1,1,1,1,1,1,1,1,1,1,1,1,1,1,1,1,1,1
1,1,1,1,1,1,1,1,1,1,1,1,1,1,1,1,1,1,1,1,1
endlayer

layer
1,1,1,1,1,1,1,1,1,1,1,1,1,1,1,1,1,1,1,1,1
1,1,1,1,1,1,1,1,1,1,1,1,1,1,1,1,1,1,1,1,1
1,1,1,1,2,2,3,6,6,3,3,3,6,6,3,2,2,1,1,1,1
1,1,1,1,2,0,7,0,15,0,0,0,15,0,0,2,2,1,1,1,1
1,1,1,1,2,0,9,0,0,0,0,0,0,0,0,2,2,1,1,1,1
1,1,1,1,2,0,0,0,0,0,0,0,0,0,0,2,2,1,1,1,1
1,1,1,1,2,16,0,0,0,0,0,0,0,0,0,2,2,1,1,1,1
1,1,1,1,2,17,0,0,0,0,0,0,0,0,0,2,2,1,1,1,1
1,1,1,1,2,0,0,0,0,0,0,0,0,0,0,2,2,1,1,1,1
1,1,1,1,2,0,0,0,0,0,0,0,0,0,0,2,2,1,1,1,1
1,1,1,1,2,0,5,2,2,0,0,0,0,0,18,2,2,1,1,1,1
1,1,1,1,2,2,3,6,6,3,3,3,3,6,3,2,2,1,1,1,1
1,1,1,1,1,1,1,1,1,1,1,1,1,1,1,1,1,1,1,1,1
1,1,1,1,1,1,1,1,1,1,1,1,1,1,1,1,1,1,1,1,1
endlayer

layer
0,0,0,0,0,0,0,0,0,0,0,0,0,0,0,0,0,0,0,0,0
0,0,22,0,0,0,19,19,21,21,0,0,0,20,0,19,19,19,0,0,0
0,0,22,2,2,3,6,3,3,23,23,23,3,3,6,3,2,2,19,0,0
0,0,22,2,2,0,0,0,0,0,0,24,0,0,24,2,2,2,0,0,0
0,0,0,2,2,24,0,0,0,0,0,0,0,0,0,2,2,2,0,0,0
0,0,22,2,2,0,0,0,0,0,0,0,0,0,0,2,2,2,22,0,0
0,0,0,2,2,25,0,0,0,0,0,0,0,0,0,2,2,2,0,0,0
0,0,0,2,2,25,0,0,0,0,0,0,0,0,0,2,2,2,22,0,0
0,0,20,2,2,0,0,0,0,0,0,0,0,0,0,2,2,2,0,0,0
0,0,0,2,2,0,0,0,0,0,0,0,0,0,0,2,2,2,19,0,0
0,20,20,2,2,0,0,5,2,24,0,0,0,0,27,26,2,2,19,0,0
0,0,19,2,2,3,6,3,3,6,6,6,3,3,6,3,2,2,0,0,0
0,0,0,19,0,0,0,0,0,0,6,0,19,20,20,20,0,0,0,0,0
0,0,0,0,0,0,0,0,0,18,28,18,0,0,0,0,0,0,0,0,0
endlayer

layer
0,0,0,0,0,0,0,0,0,0,0,0,0,0,0,0,0,0,0,0,0
0,0,0,0,0,0,19,21,21,21,0,0,0,20,0,0,0,19,0,0,0
0,0,0,2,3,6,3,6,6,3,3,3,6,6,3,6,3,2,0,0,0
0,0,22,2,2,2,2,2,2,2,2,2,2,2,2,2,2,2,0,0,0
0,0,0,2,2,2,2,2,2,2,2,2,2,2,2,2,2,2,0,0,0
0,0,0,2,2,2,2,2,2,2,2,2,2,2,2,2,2,2,0,0,0
0,0,0,2,2,2,2,2,2,2,2,2,2,2,2,2,2,2,0,0,0
0,0,0,2,2,2,2,2,2,2,2,2,2,2,2,2,2,2,0,0,0
0,0,0,2,2,14,14,14,14,2,2,2,2,2,2,2,2,2,0,0,0
0,0,0,2,2,2,2,2,29,2,2,2,2,2,2,2,2,2,22,0,0
0,0,0,2,2,0,0,0,5,2,2,2,2,2,2,2,2,2,22,0,0
0,0,19,2,3,6,3,6,6,3,3,3,6,6,3,6,3,2,0,0,0
0,0,0,0,0,0,0,0,0,0,28,0,19,0,0,0,0,0,0,0,0
0,0,0,0,0,0,0,0,0,18,0,18,0,0,0,0,0,0,0,0,0
endlayer

layer
0,0,0,0,0,0,0,0,0,0,0,0,0,0,0,0,0,0,0,0,0
0,0,0,0,0,0,0,21,21,0,0,0,0,19,20,30,0,0,0,0,0
0,31,2,2,3,6,3,6,3,6,6,6,3,6,3,30,3,2,2,0,0
0,31,2,2,35,35,0,34,4,28,28,5,0,33,33,32,32,2,2,0,0
0,31,2,36,0,0,0,0,0,0,0,0,0,0,0,0,0,2,2,0,0
0,31,2,2,0,40,0,0,0,39,39,0,38,0,37,37,0,2,2,0,0
0,0,2,35,0,0,0,0,0,0,0,0,5,0,37,42,0,41,2,0,0
0,0,2,2,0,25,47,25,0,46,45,44,43,0,37,37,0,2,2,0,0
0,0,2,2,0,47,25,47,0,0,0,0,0,0,0,0,0,2,2,0,0
0,0,2,2,49,49,49,49,49,0,48,0,0,0,0,0,2,2,2,0,0
0,0,2,2,49,0,0,0,0,0,0,0,0,0,5,2,2,2,2,0,0
0,0,2,2,3,6,3,6,3,6,50,6,3,6,3,6,3,2,2,0,0
0,0,19,0,0,0,51,51,0,0,0,0,19,51,51,0,0,0,0,0,0
0,0,0,0,0,0,0,0,0,18,0,18,0,0,0,0,0,0,0,0,0
endlayer

layer
0,0,0,0,0,0,0,0,0,0,0,0,0,0,0,52,0,0,0,0,0
0,0,0,0,0,0,52,52,21,52,52,52,52,0,20,54,53,0,0,0,0
0,31,2,3,6,3,6,3,6,3,3,3,6,3,6,55,6,3,2,0,0
0,31,2,57,27,48,0,0,0,0,0,0,0,33,33,56,56,0,2,0,0
0,31,2,35,0,0,0,0,0,0,0,0,0,0,0,0,0,58,2,0,0
0,31,2,59,0,0,0,0,0,0,0,0,0,0,0,0,0,0,2,0,0
0,0,2,35,0,0,0,0,0,0,0,0,0,0,0,0,0,60,2,0,0
0,0,2,0,0,0,0,0,0,0,0,0,0,0,0,0,0,58,2,0,0
0,0,2,0,0,0,0,0,0,0,0,0,0,0,0,0,0,61,2,0,0
0,0,2,0,0,0,0,0,0,0,0,0,0,0,0,0,2,2,2,0,0
0,0,2,0,0,0,0,0,0,0,0,0,0,0,0,5,2,2,2,0,0
0,0,2,3,6,3,6,3,6,3,62,3,6,3,6,3,6,3,2,0,0
0,0,19,0,0,65,64,64,63,0,0,19,65,64,64,63,0,0,0,0,0
0,0,0,0,0,0,12,12,0,18,0,18,0,12,12,0,0,0,0,0,0
endlayer

layer
0,0,0,0,0,0,0,0,0,0,0,0,0,0,0,52,0,0,0,0,0
0,0,0,0,0,0,52,52,21,52,52,0,0,0,66,30,53,52,0,0,0
0,0,2,3,6,3,6,3,6,3,3,3,6,3,6,55,6,3,2,0,0
0,31,2,0,25,0,0,0,0,0,0,0,0,33,33,67,0,0,2,0,0
0,0,2,0,0,0,0,0,0,0,0,0,0,0,0,0,0,0,2,0,0
0,69,2,0,0,0,0,0,0,0,0,0,0,0,0,0,0,0,2,68,0
0,0,2,0,0,0,0,0,0,0,0,0,0,0,0,0,0,0,2,0,0
0,0,2,0,0,0,0,0,0,0,0,0,0,0,0,0,0,0,2,0,0
0,69,2,0,0,0,0,0,0,0,0,0,0,0,0,0,0,0,2,68,0
0,0,2,0,0,0,0,0,0,0,0,0,0,0,0,0,28,2,2,0,0
0,0,2,0,0,0,0,0,0,0,0,0,0,0,0,0,0,2,2,0,0
0,0,2,3,23,3,23,23,6,3,3,3,6,23,23,3,23,3,2,0,0
0,0,0,0,0,0,72,71,0,39,39,39,19,0,70,0,0,0,0,0,0
0,0,0,0,0,0,0,0,0,39,39,39,0,0,0,0,0,0,0,0,0
endlayer

layer
0,0,0,0,0,0,0,73,73,73,73,73,73,73,0,21,0,0,0,0,0
0,0,52,0,0,0,52,2,2,2,2,2,2,2,66,30,52,52,0,0,0
0,31,2,3,6,3,6,3,6,3,3,3,6,3,6,3,6,3,2,0,0
0,31,2,2,2,2,2,2,2,2,2,2,2,2,2,2,2,2,2,0,0
0,10,2,2,2,2,2,2,2,2,2,2,2,2,2,2,2,2,2,10,0
65,64,2,2,2,2,2,2,2,2,2,2,2,2,2,2,2,2,2,64,63
0,12,2,2,2,2,2,2,2,2,2,2,2,2,2,2,2,2,2,12,0
0,10,2,2,0,0,0,0,0,2,2,2,2,2,2,2,2,2,2,10,0
65,64,2,2,74,0,0,0,0,2,2,2,2,2,2,2,28,2,2,64,63
0,12,2,2,0,0,0,0,0,0,0,0,0,0,0,0,0,2,2,12,0
0,0,2,2,0,0,0,0,75,0,0,0,75,0,0,0,0,2,2,0,0
0,0,2,3,23,3,23,23,6,3,3,3,6,23,23,3,23,3,2,0,0
0,0,0,0,0,0,0,0,0,0,0,19,0,0,0,0,0,0,0,0,0
0,0,0,0,0,0,0,0,0,0,0,0,0,0,0,0,0,0,0,0,0
endlayer

layer
0,0,0,0,0,0,0,18,18,18,18,18,18,18,0,21,0,0,0,0,0
0,0,0,0,0,0,52,18,0,0,0,0,21,18,77,54,76,52,52,0,0
0,31,2,2,3,6,3,6,78,6,6,6,78,6,3,6,3,2,2,0,0
0,31,2,2,28,63,7,79,0,18,80,18,0,79,7,0,10,2,2,0,0
0,0,2,2,0,0,9,0,0,0,0,0,0,0,9,0,5,2,2,0,0
0,82,23,0,0,0,0,0,0,0,0,0,0,0,0,0,12,0,23,81,0
0,0,2,2,18,18,18,18,18,18,83,0,0,0,0,0,0,2,2,0,0
0,0,2,2,0,0,0,0,0,18,35,85,65,84,63,0,0,2,2,0,0
0,71,23,0,0,0,0,0,0,18,18,18,18,18,18,18,0,0,23,86,0
0,0,2,2,0,0,0,0,0,0,0,0,0,0,0,0,0,2,2,0,0
0,0,2,2,0,0,0,0,0,0,0,0,0,0,0,0,0,2,2,0,0
0,0,2,2,3,6,3,6,3,6,6,6,3,6,3,6,3,2,2,0,0
0,0,0,0,0,0,0,51,0,0,19,0,0,51,0,0,0,0,0,0,0
0,0,0,0,0,0,0,0,0,0,0,0,0,0,0,0,0,0,0,0,0
endlayer

layer
0,0,0,0,0,0,0,0,0,0,0,0,0,0,0,21,0,0,0,0,0
0,0,0,52,0,0,52,0,0,0,0,0,21,21,77,54,53,52,0,0,0
0,0,31,2,3,6,3,6,62,3,3,3,62,6,3,6,3,2,0,0,0
0,0,31,2,0,0,0,0,0,18,80,18,0,0,0,0,0,2,0,0,0
0,0,31,2,0,0,0,0,0,0,0,0,0,0,0,0,0,2,0,0,0
0,0,5,2,0,0,0,0,0,0,0,0,0,0,0,0,0,2,4,0,0
0,0,0,2,0,0,0,0,0,0,0,0,0,0,0,0,0,2,0,0,0
0,0,0,2,0,0,0,0,0,0,35,0,0,0,0,0,0,2,0,0,0
0,0,5,2,0,0,0,0,0,0,0,0,0,0,0,0,0,2,4,0,0
0,0,0,2,0,0,0,0,0,0,0,0,0,0,0,0,0,2,0,0,0
0,0,19,2,0,0,0,0,0,0,0,0,0,0,0,0,0,2,0,0,0
0,0,0,2,3,6,3,6,6,3,3,3,6,6,3,6,3,2,0,0,0
0,0,0,0,0,0,65,64,63,0,0,19,65,64,63,0,0,0,0,0,0
0,0,0,0,0,0,0,12,0,0,0,0,0,12,0,0,0,0,0,0,0
endlayer

layer
0,0,0,0,0,0,0,0,0,0,0,0,0,0,0,21,0,0,0,0,0
0,0,0,52,0,0,0,0,0,0,0,0,21,21,77,55,76,52,0,0,0
0,0,31,2,2,3,6,3,3,6,6,6,3,3,6,3,2,2,53,0,0
0,0,31,2,2,0,0,0,0,18,80,18,0,0,0,0,2,2,0,0,0
0,0,31,2,2,0,0,0,0,0,0,0,0,0,0,0,2,2,0,0,0
0,0,0,5,2,74,0,0,0,0,0,0,0,0,0,87,2,4,0,0,0
0,0,0,2,2,0,0,0,0,0,0,0,0,0,0,0,2,2,0,0,0
0,0,0,2,2,0,0,0,0,0,35,0,0,0,0,0,2,2,0,0,0
0,0,0,5,2,74,0,0,0,0,0,0,0,0,0,87,2,4,0,0,0
0,0,0,2,2,0,0,0,0,0,0,0,0,0,0,0,2,2,0,0,0
0,0,19,2,2,0,0,0,0,75,0,75,0,0,0,0,2,2,0,0,0
0,0,0,2,2,3,6,23,3,6,6,6,3,23,6,3,2,2,0,0,0
0,0,0,0,0,0,0,88,0,0,19,0,0,72,0,0,0,0,0,0,0
0,0,0,0,0,0,0,0,0,0,0,0,0,0,0,0,0,0,0,0,0
endlayer

layer
0,0,0,0,0,0,0,0,0,0,0,0,0,0,0,21,0,0,0,0,0
0,0,0,0,0,0,0,0,0,0,0,0,21,21,77,55,53,0,0,0,0
0,0,0,0,2,2,3,6,6,3,3,3,6,6,3,2,2,0,0,0,0
0,0,0,0,2,2,2,2,2,2,80,2,89,0,0,2,2,0,0,0,0
0,0,0,0,2,2,2,2,2,2,2,2,0,0,0,2,2,0,0,0,0
0,0,0,0,2,2,2,2,2,2,2,2,0,0,0,2,2,0,0,0,0
0,0,0,0,2,2,2,2,2,2,2,2,0,0,0,2,2,0,0,0,0
0,0,0,0,2,2,2,2,2,2,2,2,89,0,0,2,2,0,0,0,0
0,0,0,0,2,2,2,2,2,2,2,2,0,0,0,2,2,0,0,0,0
0,0,0,19,2,2,2,2,2,2,2,2,0,0,0,2,2,0,0,0,0
0,0,0,19,2,2,2,2,2,2,2,2,0,0,0,2,2,0,0,0,0
0,0,0,0,2,2,3,6,6,3,3,3,6,6,3,2,2,0,0,0,0
0,0,0,0,0,0,0,0,0,0,0,22,0,0,0,0,0,0,0,0,0
0,0,0,0,0,0,0,0,0,0,0,0,0,0,0,0,0,0,0,0,0
endlayer

layer
0,0,0,0,0,0,0,0,0,0,0,0,0,0,0,21,0,0,0,0,0
0,0,0,0,0,0,0,0,0,0,0,0,21,21,77,55,53,0,0,0,0
0,0,0,0,0,2,2,3,3,6,6,6,3,3,2,2,0,0,0,0,0
0,0,0,0,0,2,2,0,24,0,80,2,0,0,2,2,0,0,0,0,0
0,0,0,0,19,2,2,0,0,0,0,2,0,0,2,2,0,0,0,0,0
0,0,0,0,20,2,2,0,0,0,0,2,0,0,2,2,19,0,0,0,0
0,0,0,0,0,2,2,0,0,0,0,2,0,0,2,2,19,0,0,0,0
0,0,0,0,0,2,2,0,0,0,0,2,0,0,2,2,0,0,0,0,0
0,0,0,0,0,2,2,0,0,90,0,2,0,0,2,2,0,0,0,0,0
0,0,0,0,0,2,2,0,0,91,24,2,0,0,2,2,0,0,0,0,0
0,0,0,0,0,2,2,0,0,0,0,2,0,0,2,2,0,0,0,0,0
0,0,0,0,0,2,2,3,3,6,6,6,3,3,2,2,0,0,0,0,0
0,0,0,0,0,0,0,0,0,0,22,22,0,0,0,0,0,0,0,0,0
0,0,0,0,0,0,0,0,0,0,0,0,0,0,0,0,0,0,0,0,0
endlayer

layer
0,0,0,0,0,0,0,0,0,0,0,0,0,0,0,52,0,0,0,0,0
0,0,0,0,0,0,0,0,0,0,0,0,21,21,21,55,53,0,0,0,0
0,0,0,0,0,0,2,2,2,23,3,23,2,2,2,92,0,0,0,0,0
0,0,0,0,0,0,2,2,2,24,80,0,2,2,2,19,0,0,0,0,0
0,0,0,0,0,20,2,2,2,0,0,0,2,2,2,19,0,0,0,0,0
0,0,0,0,0,20,2,2,2,0,0,24,2,2,2,19,19,0,0,0,0
0,0,0,0,0,20,2,2,2,0,0,0,2,2,2,0,0,0,0,0,0
0,0,0,0,0,0,2,2,2,0,0,0,2,2,2,0,0,0,0,0,0
0,0,0,0,0,0,2,2,2,0,0,0,2,2,2,0,0,0,0,0,0
0,0,0,0,0,20,2,2,2,0,0,35,2,2,2,0,0,0,0,0,0
0,0,0,0,0,0,2,2,2,0,0,35,2,2,2,0,0,0,0,0,0
0,0,0,0,0,0,2,2,2,3,3,3,2,2,2,0,0,0,0,0,0
0,0,0,0,0,0,0,0,0,0,0,0,0,0,0,0,0,0,0,0,0
0,0,0,0,0,0,0,0,0,0,0,0,0,0,0,0,0,0,0,0,0
endlayer

layer
0,0,0,0,0,0,0,0,0,0,0,0,0,0,0,52,0,0,0,0,0
0,0,0,0,0,0,0,0,0,0,0,0,0,55,55,55,53,0,0,0,0
0,0,0,0,0,0,0,0,2,2,2,2,2,19,0,92,0,0,0,0,0
0,0,0,0,0,0,0,0,2,2,2,2,2,0,0,0,0,0,0,0,0
0,0,0,0,0,0,0,0,2,2,2,2,2,0,0,0,0,0,0,0,0
0,0,0,0,0,0,0,0,2,2,2,2,2,0,0,0,0,0,0,0,0
0,0,0,0,0,0,0,0,2,2,2,2,2,0,0,0,0,0,0,0,0
0,0,0,0,0,0,0,0,2,2,2,2,2,0,0,0,0,0,0,0,0
0,0,0,0,0,0,0,0,2,2,2,2,2,0,0,0,0,0,0,0,0
0,0,0,0,0,0,22,22,2,2,2,2,2,0,0,0,0,0,0,0,0
0,0,0,0,0,0,0,0,2,2,2,2,2,0,0,0,0,0,0,0,0
0,0,0,0,0,0,0,0,2,2,2,2,2,0,0,0,0,0,0,0,0
0,0,0,0,0,0,0,0,0,0,0,0,0,0,0,0,0,0,0,0,0
0,0,0,0,0,0,0,0,0,0,0,0,0,0,0,0,0,0,0,0,0
endlayer

layer
0,0,0,0,0,0,0,0,0,0,0,0,0,0,0,0,0,0,0,0,0
0,0,0,0,0,0,0,0,0,0,0,0,0,55,19,0,0,0,0,0,0
0,0,0,0,0,0,0,0,0,0,0,0,0,0,0,0,0,0,0,0,0
0,0,0,0,0,0,0,0,0,0,0,0,0,0,0,0,0,0,0,0,0
0,0,0,0,0,0,0,0,0,0,0,0,0,0,0,0,0,0,0,0,0
0,0,0,0,0,0,0,0,0,0,0,0,0,0,0,0,0,0,0,0,0
0,0,0,0,0,0,0,0,0,0,0,0,0,0,0,0,0,0,0,0,0
0,0,0,0,0,0,0,0,0,0,0,0,0,0,0,0,0,0,0,0,0
0,0,0,0,0,0,0,0,0,0,0,0,0,0,0,0,0,0,0,0,0
0,0,0,0,0,0,0,0,0,0,0,0,0,0,0,0,0,0,0,0,0
0,0,0,0,0,0,0,0,0,0,0,0,0,0,0,0,0,0,0,0,0
0,0,0,0,0,0,0,0,0,0,0,0,0,0,0,0,0,0,0,0,0
0,0,0,0,0,0,0,0,0,0,0,0,0,0,0,0,0,0,0,0,0
0,0,0,0,0,0,0,0,0,0,0,0,0,0,0,0,0,0,0,0,0
endlayer

layer
0,0,0,0,0,0,0,0,0,0,0,0,0,0,0,0,0,0,0,0,0
0,0,0,0,0,0,0,0,0,0,0,0,0,55,0,0,0,0,0,0,0
0,0,0,0,0,0,0,0,0,0,0,0,0,0,0,0,0,0,0,0,0
0,0,0,0,0,0,0,0,0,0,0,0,0,0,0,0,0,0,0,0,0
0,0,0,0,0,0,0,0,0,0,0,0,0,0,0,0,0,0,0,0,0
0,0,0,0,0,0,0,0,0,0,0,0,0,0,0,0,0,0,0,0,0
0,0,0,0,0,0,0,0,0,0,0,0,0,0,0,0,0,0,0,0,0
0,0,0,0,0,0,0,0,0,0,0,0,0,0,0,0,0,0,0,0,0
0,0,0,0,0,0,0,0,0,0,0,0,0,0,0,0,0,0,0,0,0
0,0,0,0,0,0,0,0,0,0,0,0,0,0,0,0,0,0,0,0,0
0,0,0,0,0,0,0,0,0,0,0,0,0,0,0,0,0,0,0,0,0
0,0,0,0,0,0,0,0,0,0,0,0,0,0,0,0,0,0,0,0,0
0,0,0,0,0,0,0,0,0,0,0,0,0,0,0,0,0,0,0,0,0
0,0,0,0,0,0,0,0,0,0,0,0,0,0,0,0,0,0,0,0,0
endlayer

layer
0,0,0,0,0,0,0,0,0,0,0,0,0,0,0,0,0,0,0,0,0
0,0,0,0,0,0,0,0,0,0,0,0,0,93,0,0,0,0,0,0,0
0,0,0,0,0,0,0,0,0,0,0,0,0,0,0,0,0,0,0,0,0
0,0,0,0,0,0,0,0,0,0,0,0,0,0,0,0,0,0,0,0,0
0,0,0,0,0,0,0,0,0,0,0,0,0,0,0,0,0,0,0,0,0
0,0,0,0,0,0,0,0,0,0,0,0,0,0,0,0,0,0,0,0,0
0,0,0,0,0,0,0,0,0,0,0,0,0,0,0,0,0,0,0,0,0
0,0,0,0,0,0,0,0,0,0,0,0,0,0,0,0,0,0,0,0,0
0,0,0,0,0,0,0,0,0,0,0,0,0,0,0,0,0,0,0,0,0
0,0,0,0,0,0,0,0,0,0,0,0,0,0,0,0,0,0,0,0,0
0,0,0,0,0,0,0,0,0,0,0,0,0,0,0,0,0,0,0,0,0
0,0,0,0,0,0,0,0,0,0,0,0,0,0,0,0,0,0,0,0,0
0,0,0,0,0,0,0,0,0,0,0,0,0,0,0,0,0,0,0,0,0
0,0,0,0,0,0,0,0,0,0,0,0,0,0,0,0,0,0,0,0,0
endlayer

layer
0,0,0,0,0,0,0,0,0,0,0,0,0,0,0,0,0,0,0,0,0
0,0,0,0,0,0,0,0,0,0,0,0,0,94,0,0,0,0,0,0,0
0,0,0,0,0,0,0,0,0,0,0,0,0,0,0,0,0,0,0,0,0
0,0,0,0,0,0,0,0,0,0,0,0,0,0,0,0,0,0,0,0,0
0,0,0,0,0,0,0,0,0,0,0,0,0,0,0,0,0,0,0,0,0
0,0,0,0,0,0,0,0,0,0,0,0,0,0,0,0,0,0,0,0,0
0,0,0,0,0,0,0,0,0,0,0,0,0,0,0,0,0,0,0,0,0
0,0,0,0,0,0,0,0,0,0,0,0,0,0,0,0,0,0,0,0,0
0,0,0,0,0,0,0,0,0,0,0,0,0,0,0,0,0,0,0,0,0
0,0,0,0,0,0,0,0,0,0,0,0,0,0,0,0,0,0,0,0,0
0,0,0,0,0,0,0,0,0,0,0,0,0,0,0,0,0,0,0,0,0
0,0,0,0,0,0,0,0,0,0,0,0,0,0,0,0,0,0,0,0,0
0,0,0,0,0,0,0,0,0,0,0,0,0,0,0,0,0,0,0,0,0
0,0,0,0,0,0,0,0,0,0,0,0,0,0,0,0,0,0,0,0,0
endlayer

layer
0,0,0,0,0,0,0,0,0,0,0,0,0,0,0,0,0,0,0,0,0
0,0,0,0,0,0,0,0,0,0,0,0,0,0,0,0,0,0,0,0,0
0,0,0,0,0,0,0,0,0,0,0,0,0,0,0,0,0,0,0,0,0
0,0,0,0,0,0,0,0,0,0,0,0,0,0,0,0,0,0,0,0,0
0,0,0,0,0,0,0,0,0,0,0,0,0,0,0,0,0,0,0,0,0
0,0,0,0,0,0,0,0,0,0,0,0,0,0,0,0,0,0,0,0,0
0,0,0,0,0,0,0,0,0,0,0,0,0,0,0,0,0,0,0,0,0
0,0,0,0,0,0,0,0,0,0,0,0,0,0,0,0,0,0,0,0,0
0,0,0,0,0,0,0,0,0,0,0,0,0,0,0,0,0,0,0,0,0
0,0,0,0,0,0,0,0,0,0,0,0,0,0,0,0,0,0,0,0,0
0,0,0,0,0,0,0,0,0,0,0,0,0,0,0,0,0,0,0,0,0
0,0,0,0,0,0,0,0,0,0,0,0,0,0,0,0,0,0,0,0,0
0,0,0,0,0,0,0,0,0,0,0,0,0,0,0,0,0,0,0,0,0
0,0,0,0,0,0,0,0,0,0,0,0,0,0,0,0,0,0,0,0,0
endlayer

layer
0,0,0,0,0,0,0,0,0,0,0,0,0,0,0,0,0,0,0,0,0
0,0,0,0,0,0,0,0,0,0,0,0,94,0,0,0,0,0,0,0,0
0,0,0,0,0,0,0,0,0,0,0,0,0,0,0,0,0,0,0,0,0
0,0,0,0,0,0,0,0,0,0,0,0,0,0,0,0,0,0,0,0,0
0,0,0,0,0,0,0,0,0,0,0,0,0,0,0,0,0,0,0,0,0
0,0,0,0,0,0,0,0,0,0,0,0,0,0,0,0,0,0,0,0,0
0,0,0,0,0,0,0,0,0,0,0,0,0,0,0,0,0,0,0,0,0
0,0,0,0,0,0,0,0,0,0,0,0,0,0,0,0,0,0,0,0,0
0,0,0,0,0,0,0,0,0,0,0,0,0,0,0,0,0,0,0,0,0
0,0,0,0,0,0,0,0,0,0,0,0,0,0,0,0,0,0,0,0,0
0,0,0,0,0,0,0,0,0,0,0,0,0,0,0,0,0,0,0,0,0
0,0,0,0,0,0,0,0,0,0,0,0,0,0,0,0,0,0,0,0,0
0,0,0,0,0,0,0,0,0,0,0,0,0,0,0,0,0,0,0,0,0
0,0,0,0,0,0,0,0,0,0,0,0,0,0,0,0,0,0,0,0,0
endlayer

layer
0,0,0,0,0,0,0,0,0,0,0,0,0,0,0,0,0,0,0,0,0
0,0,0,0,0,0,0,0,0,0,0,0,0,0,0,0,0,0,0,0,0
0,0,0,0,0,0,0,0,94,0,0,94,0,0,0,0,0,0,0,0,0
0,0,0,0,0,0,0,0,0,0,0,0,0,0,0,0,0,0,0,0,0
0,0,0,0,0,0,0,94,0,0,0,0,0,0,0,0,0,0,0,0,0
0,0,0,0,0,0,0,0,0,0,0,0,0,0,0,0,0,0,0,0,0
0,0,0,0,0,0,0,0,0,0,0,0,0,0,0,0,0,0,0,0,0
0,0,0,0,0,0,0,0,0,0,0,0,0,0,0,0,0,0,0,0,0
0,0,0,0,0,0,0,0,0,0,0,0,0,0,0,0,0,0,0,0,0
0,0,0,0,0,0,0,0,0,0,0,0,0,0,0,0,0,0,0,0,0
0,0,0,0,0,0,0,0,0,0,0,0,0,0,0,0,0,0,0,0,0
0,0,0,0,0,0,0,0,0,0,0,0,0,0,0,0,0,0,0,0,0
0,0,0,0,0,0,0,0,0,0,0,0,0,0,0,0,0,0,0,0,0
0,0,0,0,0,0,0,0,0,0,0,0,0,0,0,0,0,0,0,0,0
endlayer

