
# Created by Ruins mod version 15.1 Ingame Parser
# authoring Player: SunsOfOld

weight=100
embed_into_distance=0
acceptable_target_blocks=
unacceptable_target_blocks=flowing_water,water,flowing_lava,lava
dimensions=10,13,7
allowable_overhang=0
max_leveling=2
leveling_buffer=0
preserve_water=0
preserve_lava=0
uniqueMinDistance=1000000
preventRotation=1

rule1=0,100,chisel:marble-14
rule2=0,100,chisel:marble_slab-15
rule3=0,100,chisel:marble_slab-14
rule4=0,100,chisel:marble-4
rule5=0,100,chisel:marble-5
rule6=0,100,minecraft:grass-0
rule7=0,100,ExtrabiomesXL:log1-6
rule8=0,100,ExtrabiomesXL:log1-10
rule9=0,100,ExtrabiomesXL:log1-2
rule10=0,100,preserveBlock
rule11=0,100,dendrology:leaves0-14
rule12=0,100,minecraft:tallgrass-1
rule13=0,100,minecraft:double_plant-2
rule14=0,100,minecraft:double_plant-8
rule15=0,100,dendrology:leaves0-6

layer
2,1,2,2,0,1,0
0,2,3,2,3,0,3
0,3,2,3,2,3,2
3,0,3,2,3,2,0
0,2,2,2,2,0,0
4,5,5,5,5,5,4
5,6,7,6,6,6,5
5,6,6,9,6,8,5
5,10,10,9,8,6,5
5,6,6,9,6,6,5
5,6,7,6,6,6,5
4,5,5,5,5,5,4
0,2,2,2,2,0,2
endlayer

layer
0,11,0,0,0,11,0
0,0,0,0,0,0,0
0,0,0,0,0,0,0
0,0,0,0,0,0,0
0,0,0,0,0,0,0
4,0,0,0,0,0,4
0,12,0,12,13,12,0
0,12,13,9,12,0,0
0,9,9,9,0,12,0
0,12,13,9,13,12,0
0,12,0,12,12,12,0
4,0,0,0,0,0,4
0,0,0,0,0,0,0
endlayer

layer
0,11,0,0,0,0,0
0,0,0,0,0,0,0
0,0,0,0,0,0,0
0,0,0,0,0,0,0
0,0,0,0,0,0,0
0,0,0,0,0,0,0
0,0,0,0,14,0,0
0,0,14,0,0,0,0
0,0,9,9,0,0,0
0,0,14,0,14,0,0
0,0,0,0,0,0,0
0,0,0,0,0,0,0
0,0,0,0,0,0,0
endlayer

layer
0,0,0,0,0,0,0
0,0,0,0,0,0,0
0,0,0,0,0,0,0
0,0,0,0,0,0,0
0,0,0,0,0,0,0
0,0,0,0,0,0,0
0,0,0,0,0,0,0
0,0,0,0,0,0,0
0,0,0,9,0,0,0
0,0,0,0,0,0,0
0,0,0,0,0,0,0
0,0,0,0,0,0,0
0,0,0,0,0,0,0
endlayer

layer
0,0,0,0,0,0,0
0,0,0,0,0,0,0
0,0,0,0,0,0,0
0,0,0,0,11,0,0
0,0,11,11,11,0,0
0,0,11,11,11,11,0
0,0,11,7,11,0,0
0,11,0,7,0,0,0
0,0,0,9,11,0,0
0,11,0,11,0,0,0
0,0,0,0,11,0,0
0,0,0,0,0,0,0
0,0,0,0,0,0,0
endlayer

layer
0,0,0,0,0,0,0
0,0,0,0,0,0,0
0,0,0,0,0,0,0
0,0,0,11,0,0,0
0,0,11,11,11,11,0
0,11,11,7,11,0,0
0,0,11,11,11,11,0
0,11,11,11,11,11,0
11,11,8,9,11,11,11
0,11,11,11,11,11,0
0,0,11,11,11,11,0
0,0,0,11,0,0,0
0,0,0,0,0,0,0
endlayer

layer
0,0,0,0,0,0,0
0,0,0,0,0,0,0
0,0,0,0,0,0,0
0,0,11,11,11,0,0
0,0,11,11,15,0,0
0,11,11,11,15,11,0
15,11,15,15,15,11,0
0,15,15,15,15,11,11
11,8,15,9,8,11,11
11,11,15,15,15,11,15
0,11,15,15,15,11,11
0,0,15,15,15,15,0
0,0,0,15,0,0,0
endlayer

layer
0,0,0,0,0,0,0
0,0,0,0,0,0,0
0,0,0,0,0,0,0
0,0,0,11,0,0,0
0,0,0,11,15,0,0
0,0,11,11,15,0,0
0,11,11,11,15,15,0
0,15,15,15,15,15,15
15,15,15,9,15,8,11
15,15,15,15,15,11,11
0,15,15,15,15,11,11
0,0,15,15,15,15,0
0,0,0,0,15,0,0
endlayer

layer
0,0,0,0,0,0,0
0,0,0,0,0,0,0
0,0,0,0,0,0,0
0,0,0,0,0,0,0
0,0,0,0,0,0,0
0,0,0,11,0,0,0
0,0,11,11,15,0,0
0,11,11,11,15,15,0
0,15,15,15,15,15,15
0,0,15,15,15,15,0
0,0,15,15,15,15,0
0,0,0,15,15,0,0
0,0,0,0,0,0,0
endlayer

layer
0,0,0,0,0,0,0
0,0,0,0,0,0,0
0,0,0,0,0,0,0
0,0,0,0,0,0,0
0,0,0,0,0,0,0
0,0,0,0,0,0,0
0,0,0,0,0,0,0
0,0,0,11,15,0,0
0,0,15,15,15,15,0
0,0,0,15,15,15,0
0,0,0,0,15,0,0
0,0,0,0,0,0,0
0,0,0,0,0,0,0
endlayer

