
# Created by Ruins mod version 15.0 Ingame Parser
# authoring Player: SunsOfOld

weight=100
embed_into_distance=1
acceptable_target_blocks=
unacceptable_target_blocks=flowing_water,water,flowing_lava,lava,sand
dimensions=24,10,35
allowable_overhang=0
max_leveling=6
leveling_buffer=0
preserve_water=0
preserve_lava=0
uniqueMinDistance=1000000
preventRotation=1

rule1=0,100,preserveBlock
rule2=0,100,minecraft:grass-0
rule3=0,100,minecraft:dirt-0
rule4=0,100,minecraft:stone-0
rule5=0,100,minecraft:cobblestone-0
rule6=0,100,BiomesOPlenty:planks-11
rule7=0,100,minecraft:tallgrass-1
rule8=0,100,minecraft:double_plant-2
rule9=0,100,minecraft:yellow_flower-0
rule10=0,100,BiomesOPlenty:logs4-0
rule11=0,100,ExtrabiomesXL:flower2-0
rule12=0,100,GardenTrees:thin_log-0
rule13=0,100,minecraft:rail-0
rule14=0,100,ExtrabiomesXL:flower1-4
rule15=0,100,minecraft:double_plant-8
rule16=0,100,chisel:torch6-5
rule17=0,100,BiomesOPlenty:colorizedLeaves2-1

layer
1,1,1,1,1,1,1,2,1,1,1,1,2,2,1,1,1,1,1,2,1,2,1,1,1,2,2,1,2,1,1,1,2,1,1
2,2,1,1,2,1,2,1,1,2,2,1,1,1,1,2,2,1,1,2,1,1,1,1,1,1,1,1,1,1,1,2,1,1,1
2,1,2,1,2,4,4,1,2,3,1,1,1,1,2,3,2,1,2,1,1,2,2,2,4,4,1,2,3,1,1,1,2,2,1
1,1,1,1,1,4,4,4,5,1,2,1,1,1,2,2,2,1,1,1,1,1,3,2,1,4,1,1,2,5,1,2,3,2,1
6,6,6,6,6,6,6,6,6,6,6,6,6,6,6,6,6,6,6,6,6,6,6,6,6,6,6,6,6,6,6,6,6,6,6
1,1,1,2,2,2,1,2,2,1,2,1,1,1,1,2,1,1,5,2,1,2,2,4,1,1,1,1,1,1,1,4,4,1,1
1,2,1,2,3,2,1,1,1,2,1,1,1,2,1,1,1,1,2,4,4,1,2,1,3,2,2,1,2,1,2,4,4,1,2
1,1,1,2,2,2,1,1,2,1,1,2,1,3,2,1,1,2,1,4,1,1,1,2,1,2,1,1,1,3,1,4,1,2,1
1,2,1,1,2,1,1,1,2,1,2,1,1,1,1,1,2,1,2,1,2,1,2,1,1,1,2,1,1,1,1,2,2,1,1
1,1,1,2,1,2,2,1,1,1,1,1,2,2,1,1,1,1,2,1,2,2,1,1,1,1,1,1,2,1,1,1,1,1,2
endlayer

layer
0,0,0,0,0,0,0,7,0,0,0,0,7,8,0,0,0,0,0,7,0,9,0,0,0,7,8,0,7,0,0,0,7,0,0
7,7,0,0,7,0,7,0,0,7,8,0,0,0,0,8,7,0,0,8,0,0,0,0,0,0,0,0,0,0,0,7,0,0,0
11,0,7,0,9,0,4,0,8,10,0,0,0,0,7,10,8,0,7,0,0,7,8,7,0,4,0,7,10,0,0,0,8,7,0
0,0,0,0,0,0,4,0,12,0,7,0,0,0,8,7,7,0,0,0,0,0,10,7,0,0,0,0,7,12,0,7,10,7,0
0,0,13,13,0,13,0,0,13,0,13,13,13,0,13,13,13,13,0,13,13,13,13,0,0,13,13,13,13,0,13,13,13,13,13
0,0,0,7,7,7,0,7,0,0,7,0,0,0,0,7,0,0,12,7,0,14,7,0,0,0,0,0,0,0,0,0,0,0,0
0,7,0,8,10,7,0,0,0,7,0,0,0,7,0,0,0,0,7,0,0,0,7,0,10,8,7,0,7,0,8,4,0,0,7
0,0,0,7,7,7,0,0,7,0,0,7,0,10,9,0,0,7,0,4,0,0,0,8,0,7,0,0,0,10,0,4,0,7,0
0,8,0,0,7,0,0,0,7,0,7,0,0,0,0,0,0,0,7,0,7,0,8,0,0,0,7,0,0,0,0,7,8,0,0
0,0,0,7,0,7,7,0,0,0,0,0,7,7,0,0,0,0,7,0,7,7,0,0,0,0,0,0,7,0,0,0,0,0,8
endlayer

layer
0,0,0,0,0,0,0,0,0,0,0,0,0,15,0,0,0,0,0,0,0,0,0,0,0,0,15,0,0,0,0,0,0,0,0
0,0,0,0,0,0,0,0,0,0,15,0,0,0,0,15,0,0,0,15,0,0,0,0,0,0,0,0,0,0,0,0,0,0,0
0,0,0,0,0,0,4,0,15,10,0,0,0,0,0,10,15,0,0,0,0,0,15,0,0,0,0,0,10,0,0,0,15,0,0
0,0,0,0,0,0,0,0,16,0,0,0,0,0,15,0,0,0,0,0,0,0,10,0,0,0,0,0,0,16,0,0,10,0,0
0,0,0,0,0,0,0,0,0,0,0,0,0,0,0,0,0,0,0,0,0,0,0,0,0,0,0,0,0,0,0,0,0,0,0
0,0,0,0,0,0,0,0,0,0,0,0,0,0,0,0,0,0,16,0,0,0,0,0,0,0,0,0,0,0,0,0,0,0,0
0,0,0,15,10,0,0,0,0,0,0,0,0,0,0,0,0,0,0,0,0,0,0,0,10,15,0,0,0,0,15,0,0,0,0
0,0,0,0,0,0,0,0,0,0,0,0,0,10,0,0,0,0,0,0,0,0,0,15,0,0,0,0,0,10,0,4,0,0,0
0,15,0,0,0,0,0,0,0,0,0,0,0,0,0,0,0,0,0,0,0,0,15,0,0,0,0,0,0,0,0,0,15,0,0
0,0,0,0,0,0,0,0,0,0,0,0,0,0,0,0,0,0,0,0,0,0,0,0,0,0,0,0,0,0,0,0,0,0,15
endlayer

layer
0,0,0,0,0,0,0,0,0,0,0,0,0,0,0,0,0,0,0,0,0,0,0,0,0,0,0,0,0,0,0,0,0,0,0
0,0,0,0,0,0,0,0,0,0,0,0,0,0,0,0,0,0,0,0,0,0,0,0,0,0,0,0,0,0,0,0,0,0,0
0,0,0,0,0,0,0,0,0,10,0,0,0,0,0,10,0,0,0,0,0,0,0,0,0,0,0,0,10,0,0,0,0,0,0
0,0,0,0,0,0,0,0,0,0,0,0,0,0,0,0,0,0,0,0,0,0,10,0,0,0,0,0,0,0,0,0,10,0,0
0,0,0,0,0,0,0,0,0,0,0,0,0,0,0,0,0,0,0,0,0,0,0,0,0,0,0,0,0,0,0,0,0,0,0
0,0,0,0,0,0,0,0,0,0,0,0,0,0,0,0,0,0,0,0,0,0,0,0,0,0,0,0,0,0,0,0,0,0,0
0,0,0,0,10,0,0,0,0,0,0,0,0,0,0,0,0,0,0,0,0,0,0,0,10,0,0,0,0,0,0,0,0,0,0
0,0,0,0,0,0,0,0,0,0,0,0,0,10,0,0,0,0,0,0,0,0,0,0,0,0,0,0,0,10,0,0,0,0,0
0,0,0,0,0,0,0,0,0,0,0,0,0,0,0,0,0,0,0,0,0,0,0,0,0,0,0,0,0,0,0,0,0,0,0
0,0,0,0,0,0,0,0,0,0,0,0,0,0,0,0,0,0,0,0,0,0,0,0,0,0,0,0,0,0,0,0,0,0,0
endlayer

layer
0,0,0,0,0,0,0,0,0,0,0,0,0,0,0,0,0,0,0,0,0,0,0,0,0,0,0,0,0,0,0,0,0,0,0
0,0,0,0,0,0,0,0,0,0,0,0,0,0,0,0,0,0,0,0,0,0,0,0,0,0,0,0,0,0,0,0,0,0,17
0,0,0,0,0,0,0,0,0,10,0,0,0,0,0,10,0,0,0,0,0,0,0,0,0,0,0,0,10,0,0,0,0,0,0
0,0,0,0,0,0,0,0,0,0,0,0,0,0,0,0,0,0,0,0,0,0,10,0,0,0,0,0,0,0,0,0,10,0,0
0,0,0,0,0,0,0,0,0,0,0,0,0,0,0,0,0,0,0,0,0,0,0,0,0,0,0,0,0,0,0,0,0,0,0
0,0,0,0,0,0,0,0,0,0,0,0,0,0,0,0,0,0,0,0,0,0,0,0,0,0,0,0,0,0,0,0,0,0,0
0,0,0,0,10,0,0,0,0,0,0,0,0,0,0,0,0,0,0,0,0,0,0,0,10,0,0,0,0,0,0,0,0,0,0
0,0,0,0,0,0,0,0,0,0,0,0,0,10,0,0,0,0,0,0,0,0,0,0,0,0,0,0,0,10,0,0,0,0,0
0,0,0,0,0,0,0,0,0,0,0,0,0,0,0,0,0,0,0,0,0,0,0,0,0,0,0,0,0,0,0,0,0,0,0
0,0,0,0,0,0,0,0,0,0,0,0,0,0,0,0,0,0,0,0,0,0,0,0,0,0,0,0,0,0,0,0,0,0,0
endlayer

layer
0,0,0,0,0,0,0,0,0,0,0,0,0,0,0,0,0,0,0,0,0,0,0,0,0,0,0,0,0,0,0,0,0,0,0
0,0,0,0,0,0,0,0,0,0,0,0,0,0,0,0,0,0,0,0,0,0,0,0,0,0,0,0,0,0,0,0,0,17,0
0,0,0,0,0,0,0,0,0,10,0,0,0,0,0,10,0,0,0,0,0,0,0,0,0,0,0,0,10,0,0,0,0,0,17
0,0,0,0,0,0,0,0,0,0,0,0,0,0,0,0,0,0,0,0,0,0,10,0,0,0,0,0,0,0,0,0,10,0,0
0,0,0,0,0,0,0,0,0,0,0,0,0,0,0,0,0,0,0,0,0,0,0,0,0,0,0,0,0,0,17,0,0,0,0
0,0,0,0,0,0,0,0,0,0,0,0,0,0,0,0,0,0,0,0,0,0,0,0,0,0,0,0,0,0,17,17,0,0,0
0,0,0,0,10,0,0,0,0,0,0,0,0,0,0,0,0,0,0,0,0,0,0,0,10,0,0,0,0,0,0,0,0,0,0
0,0,0,0,0,0,0,0,0,0,0,0,0,10,0,0,0,0,0,0,0,0,0,0,0,0,0,0,0,10,0,0,0,0,0
0,0,0,0,0,0,0,0,0,0,0,0,0,0,0,0,0,0,0,0,0,0,0,0,0,0,0,0,0,0,0,0,0,0,0
0,0,0,0,0,0,0,0,0,0,0,0,0,0,0,0,0,0,0,0,0,0,0,0,0,0,0,0,0,0,0,0,0,0,0
endlayer

layer
0,0,0,0,0,0,0,0,0,0,0,0,0,0,0,0,0,17,0,0,0,0,0,0,0,0,0,0,0,0,0,0,0,0,0
0,0,0,0,0,0,0,0,0,0,0,0,0,0,0,0,0,0,0,0,0,0,0,0,0,0,0,0,0,0,0,0,0,0,0
0,0,0,0,0,0,0,0,0,10,0,0,0,0,0,10,0,0,0,0,0,0,0,0,0,0,0,0,10,0,0,17,17,17,0
0,0,0,0,0,0,0,0,0,0,0,0,0,0,0,0,0,0,0,0,0,0,10,0,0,0,0,0,0,0,0,17,10,17,0
0,0,0,0,0,0,0,0,0,0,0,0,0,0,0,0,0,0,0,0,17,0,0,0,0,0,0,0,0,0,0,17,17,17,0
0,0,0,0,0,0,0,0,0,0,0,0,0,0,0,0,0,0,0,0,17,17,0,0,0,0,0,0,0,0,0,0,0,0,0
0,0,0,0,10,0,0,0,0,0,0,0,0,0,0,0,0,0,0,0,0,0,0,0,10,0,0,0,0,0,0,0,0,0,0
0,0,0,0,0,0,0,0,0,0,0,0,0,10,0,0,0,0,0,0,0,0,0,0,0,0,0,0,0,10,0,0,0,0,0
0,0,0,0,0,0,0,0,0,0,0,0,0,0,0,0,0,0,0,0,0,0,0,0,0,0,0,0,0,0,0,0,0,0,0
0,0,0,0,0,0,0,0,0,0,0,0,0,0,0,0,0,0,0,0,0,0,0,0,0,0,0,0,0,0,0,0,0,0,0
endlayer

layer
0,0,0,0,0,0,0,0,0,0,0,0,0,0,0,0,17,0,0,0,0,0,0,0,0,0,0,0,0,0,0,0,0,0,0
0,0,0,0,0,0,0,0,0,0,0,0,0,0,17,17,17,17,0,0,17,0,0,17,17,0,0,0,0,0,17,17,0,0,0
0,0,0,0,0,0,0,0,0,10,0,0,0,0,17,10,17,0,0,0,0,17,17,17,17,0,0,0,10,0,17,0,0,0,0
0,0,0,0,0,0,0,0,0,0,0,0,0,17,17,17,17,0,0,0,0,17,10,17,0,0,0,0,0,0,0,0,10,0,0
0,0,0,0,0,0,0,0,0,0,0,0,0,17,17,0,0,0,0,0,0,17,17,17,0,17,17,0,0,0,0,0,0,0,0
0,0,0,0,0,0,0,0,0,0,0,0,0,0,0,0,0,0,0,0,0,0,0,0,0,0,17,0,0,0,0,0,0,0,0
0,0,0,0,10,0,0,0,0,0,0,0,0,0,0,0,0,0,0,0,0,0,0,0,10,0,0,0,0,0,0,0,0,0,0
0,0,0,0,0,0,0,0,0,0,0,0,0,10,0,0,0,0,0,0,0,0,17,0,0,0,0,0,0,10,0,0,0,0,0
0,0,0,0,0,0,0,0,0,0,0,0,0,0,0,0,0,0,0,0,0,0,17,17,0,0,0,0,0,0,0,0,0,0,0
0,0,0,0,0,0,0,0,0,0,0,0,0,0,0,0,0,0,0,0,0,0,0,0,0,0,0,0,0,0,0,0,0,0,0
endlayer

layer
0,0,0,0,0,0,0,0,0,0,0,0,0,0,0,0,0,0,0,0,0,0,0,0,0,0,0,0,0,0,17,0,0,0,0
0,0,0,0,0,0,0,0,0,0,0,0,0,0,0,0,0,0,0,0,0,17,0,0,0,0,0,0,0,0,0,0,0,0,0
0,0,0,0,0,0,0,0,0,10,0,0,0,0,0,10,0,0,0,0,17,0,0,0,0,0,0,0,10,0,0,17,17,17,0
0,0,0,0,0,0,0,0,0,0,0,0,0,0,0,0,0,0,0,0,0,0,10,0,0,0,0,0,0,0,0,17,10,17,0
0,0,0,0,0,0,0,0,0,0,0,0,0,0,0,0,0,0,0,0,0,0,0,0,17,0,17,0,0,0,0,17,17,17,17
0,0,0,0,0,0,0,0,0,0,0,0,0,0,0,17,0,0,0,0,0,0,0,17,17,17,0,17,0,0,17,17,0,17,17
0,0,0,0,10,0,0,0,0,0,0,0,0,0,0,0,0,0,0,0,0,0,0,17,10,17,0,0,17,17,17,17,0,0,0
0,0,0,0,0,0,0,0,0,0,0,0,0,10,0,0,0,0,0,0,0,0,0,17,17,17,0,0,17,10,17,0,0,0,0
0,0,0,0,0,0,0,0,0,0,0,0,0,0,0,0,0,0,0,0,0,0,0,0,0,0,17,17,17,17,17,0,0,0,0
0,0,0,0,0,0,0,0,0,0,0,0,0,0,0,0,0,0,0,0,0,0,0,0,0,0,0,17,17,0,0,0,0,0,0
endlayer

layer
0,0,0,0,0,0,0,0,0,0,0,0,0,17,17,0,0,0,0,0,0,0,0,0,0,0,0,0,0,17,0,0,0,0,0
0,0,0,0,0,0,0,0,0,0,0,0,0,17,17,17,17,0,0,0,0,0,0,0,0,0,0,0,0,0,17,0,0,0,17
0,0,0,0,0,0,0,0,0,10,0,0,0,0,17,10,17,0,0,0,0,17,17,17,0,0,0,0,10,0,0,0,0,0,0
0,0,0,0,0,0,0,0,0,0,0,0,0,0,17,17,17,17,0,0,0,17,10,17,0,0,17,0,0,0,0,0,10,0,0
0,0,0,0,0,17,17,0,0,0,0,0,0,0,0,0,17,17,0,0,0,17,17,17,0,0,0,17,0,0,17,0,0,0,0
0,0,0,0,0,0,17,0,0,0,0,0,0,0,17,0,0,0,0,0,0,0,0,0,0,0,0,0,17,0,0,17,0,0,0
0,0,0,0,10,0,0,0,0,0,0,0,17,17,17,17,0,0,0,0,0,0,0,0,10,0,0,17,0,0,0,0,0,0,0
0,0,0,0,0,0,0,0,0,0,0,0,17,10,17,0,0,0,0,0,0,0,0,0,0,0,17,0,0,10,0,0,0,0,0
0,0,17,0,0,0,0,0,0,0,0,17,17,17,17,0,0,0,0,0,0,0,0,0,0,17,0,0,0,0,0,0,0,0,0
0,0,0,0,0,0,0,0,0,0,0,17,17,0,0,0,0,0,0,0,0,0,0,0,0,0,0,0,0,0,0,0,0,0,0
endlayer

layer
0,0,0,0,0,0,0,0,0,0,0,0,0,0,0,0,0,17,0,0,0,0,0,0,0,0,0,0,0,0,0,0,0,0,0
0,0,0,0,0,0,0,0,0,0,0,0,0,0,0,0,0,0,0,0,0,0,0,0,0,0,0,17,17,17,17,0,0,17,0
0,0,0,0,0,0,0,0,0,10,0,0,0,0,0,10,0,0,0,0,0,0,0,0,0,0,0,17,10,17,0,17,17,17,17
0,0,0,0,0,0,0,0,0,0,0,0,0,17,0,0,0,0,0,0,0,0,10,0,0,0,0,17,17,17,0,17,10,17,0
0,0,0,0,0,0,0,17,0,0,0,0,0,17,17,0,0,0,0,0,0,0,17,17,0,0,0,0,0,0,17,17,17,17,0
0,0,0,17,17,17,0,0,0,0,0,17,17,0,0,0,0,0,0,0,0,0,17,17,17,17,0,0,0,0,0,0,0,0,17
0,0,0,17,10,17,0,0,0,0,0,17,0,0,0,0,0,0,0,0,0,0,0,17,10,17,0,0,17,17,17,0,0,0,0
0,0,17,17,17,17,0,0,0,0,0,0,0,10,0,0,0,0,0,0,0,0,0,17,17,17,0,0,17,10,17,0,0,0,0
0,0,0,17,0,0,0,0,0,0,0,0,0,0,0,0,0,0,0,0,0,0,0,0,0,0,0,0,17,17,17,17,0,0,0
0,0,0,0,0,0,0,0,0,0,0,0,0,0,0,0,0,0,0,0,0,0,0,0,0,0,0,0,0,0,17,17,0,0,0
endlayer

layer
0,0,0,0,0,0,0,0,0,0,17,17,0,0,0,0,17,0,0,0,0,0,0,0,0,0,17,17,0,0,0,0,0,0,0
0,0,0,0,0,0,0,0,17,17,17,17,0,0,17,17,17,17,0,0,0,0,0,0,0,0,17,0,0,0,0,17,0,0,0
0,0,0,0,0,0,0,0,17,10,17,0,0,0,17,10,17,0,0,0,0,17,17,17,0,0,0,0,10,0,17,0,0,0,0
0,0,0,0,0,0,0,17,17,17,17,0,0,0,17,17,17,0,0,0,0,17,10,17,0,0,0,0,0,0,17,0,10,0,0
0,0,0,0,0,0,0,0,17,0,0,17,0,0,0,0,0,0,0,0,0,17,17,17,0,0,0,0,0,17,0,0,0,0,17
0,0,0,0,0,0,0,0,0,0,0,0,0,0,0,0,0,0,0,0,0,0,0,0,0,0,0,0,0,0,0,0,0,17,0
0,0,0,0,10,0,0,0,0,0,0,0,17,17,17,0,0,0,0,0,0,0,0,0,10,0,0,0,0,0,0,0,0,0,0
0,0,0,0,0,0,17,0,0,0,0,0,17,10,17,0,0,0,0,0,0,0,0,0,0,0,0,0,0,10,0,0,0,0,0
0,0,0,0,0,17,17,0,0,0,0,0,17,17,17,17,0,0,0,0,0,0,0,0,0,0,0,0,0,0,0,0,0,0,0
0,0,0,0,0,0,0,0,0,0,0,17,0,0,17,17,0,0,0,0,0,0,0,0,0,0,0,17,0,0,0,0,0,0,0
endlayer

layer
0,0,0,0,0,0,0,0,0,0,0,0,0,17,17,0,0,0,0,0,0,0,0,0,0,0,0,0,0,0,0,0,0,0,0
0,0,0,0,0,0,0,0,0,0,0,0,0,17,0,0,0,0,0,0,0,0,0,0,0,0,0,17,17,17,0,0,0,0,0
0,0,0,0,0,0,0,0,0,10,0,0,0,0,0,10,0,0,0,0,0,0,17,0,0,0,0,17,10,17,0,17,17,17,0
0,0,0,0,0,0,0,0,0,0,0,17,0,0,0,0,0,17,0,0,0,17,0,17,0,0,0,17,17,17,0,17,10,17,0
0,0,17,17,0,0,0,0,0,0,17,0,0,0,0,0,17,17,0,0,0,0,17,0,0,17,17,0,0,0,0,17,17,17,0
0,0,17,17,17,17,0,0,0,0,0,0,0,0,17,17,0,0,0,0,0,0,0,17,17,17,17,0,0,0,17,17,0,0,0
0,0,0,17,10,17,0,0,0,0,0,0,0,0,0,17,0,0,0,0,0,0,0,17,10,17,0,0,17,17,17,17,0,0,0
0,0,0,17,17,17,0,0,0,0,0,0,0,10,0,0,0,0,0,0,0,0,17,17,17,17,0,0,17,10,17,0,0,0,0
0,0,0,0,0,0,0,0,0,0,0,17,0,0,0,0,0,0,0,0,0,0,17,17,0,0,0,17,17,17,17,0,0,0,0
0,0,0,0,0,0,0,0,0,0,0,0,17,0,0,0,0,0,0,0,0,0,0,0,0,0,0,0,17,0,0,0,0,0,0
endlayer

layer
0,0,0,0,0,0,0,17,17,0,0,0,0,0,0,0,0,0,0,0,0,0,0,0,0,0,0,0,0,0,17,0,0,0,0
0,0,0,0,0,0,0,17,17,17,17,0,0,0,17,17,17,0,0,0,0,0,0,0,0,0,0,0,0,0,0,0,0,0,0
0,0,0,0,0,0,0,0,17,10,17,0,0,0,17,10,17,0,0,0,0,0,0,0,0,0,0,0,10,0,0,0,0,0,0
0,0,0,0,0,0,0,0,17,17,17,0,0,0,17,17,17,0,0,0,0,0,17,0,0,0,0,0,0,0,0,0,10,0,0
0,0,0,0,0,0,0,0,0,0,0,0,0,0,0,0,0,0,0,0,0,0,0,17,0,0,0,0,0,0,0,0,0,0,0
0,0,0,0,0,0,0,0,0,0,0,17,0,0,0,0,0,0,0,0,0,0,17,0,0,0,0,0,0,0,0,0,0,0,0
0,0,0,0,10,0,0,0,0,0,0,0,17,17,17,0,0,0,0,0,0,0,0,0,10,0,0,0,0,0,0,0,0,0,0
0,0,0,0,0,0,0,0,0,0,0,0,17,10,17,0,0,0,0,0,0,0,0,0,0,0,0,0,0,10,0,0,0,0,0
0,0,0,0,0,0,0,0,0,0,0,0,17,17,17,0,0,0,0,0,0,0,0,0,0,0,0,0,0,0,0,0,0,0,0
0,0,0,0,0,0,0,0,0,0,0,0,0,0,0,0,0,0,0,0,0,0,0,0,0,0,0,0,0,0,0,0,0,0,0
endlayer

layer
0,0,0,0,0,0,0,0,0,0,17,17,0,0,0,0,0,0,0,0,0,0,0,0,0,0,0,0,0,17,0,0,0,0,0
0,0,0,0,0,0,0,0,0,0,0,17,0,0,0,0,0,0,0,0,0,0,0,0,0,0,0,17,17,17,17,0,0,0,0
0,0,0,0,0,0,0,0,0,10,0,0,0,0,0,10,0,0,0,0,0,0,0,0,0,0,0,17,10,17,0,17,17,17,0
0,0,0,0,0,0,0,17,0,0,0,0,0,0,0,0,0,0,0,0,0,0,0,0,0,0,17,17,17,17,0,17,10,17,0
0,0,0,0,0,17,17,17,17,0,0,0,0,0,0,0,0,0,0,0,0,0,0,0,0,0,17,17,0,0,0,17,17,17,0
0,0,0,17,17,17,17,0,0,0,0,0,17,0,0,0,0,0,0,0,0,0,0,17,17,17,0,17,17,0,0,17,0,0,0
0,0,0,17,10,17,0,0,0,0,0,17,0,0,0,0,0,0,0,0,0,0,0,17,10,17,0,17,17,17,17,0,0,0,0
0,0,17,17,17,17,0,0,0,0,0,0,0,10,0,0,0,0,0,0,0,0,0,17,17,17,17,0,17,10,17,0,0,0,0
0,0,17,17,0,0,0,0,0,0,0,0,0,0,0,0,0,0,0,0,0,0,0,0,0,17,17,0,17,17,17,17,0,0,0
0,0,0,0,0,0,0,0,0,0,0,0,0,0,0,0,0,0,0,0,0,0,0,0,0,0,0,0,0,0,17,17,0,0,0
endlayer

layer
0,0,0,0,0,0,0,17,0,0,0,0,0,0,0,0,17,17,0,0,0,0,0,0,0,0,0,0,0,0,0,0,0,0,0
0,0,0,0,0,0,0,0,17,17,17,0,0,0,17,17,17,17,0,0,0,0,0,0,0,0,0,0,0,0,0,0,0,0,0
0,0,0,0,0,0,0,0,17,10,17,0,0,0,17,10,17,0,0,0,0,0,0,0,0,0,0,0,10,0,0,0,17,0,0
0,0,0,0,0,0,0,0,17,17,17,0,0,17,17,17,17,0,0,0,0,0,0,0,0,0,0,0,0,0,0,17,0,17,0
0,0,0,0,0,0,0,0,0,0,0,0,0,17,17,0,0,0,0,0,0,0,0,0,0,0,0,0,0,0,0,0,17,0,0
0,0,0,0,0,0,0,0,0,0,0,0,0,0,0,0,0,0,0,0,0,0,0,0,0,0,0,0,0,0,17,0,0,0,0
0,0,0,0,10,0,0,0,0,0,0,0,17,17,17,0,0,0,0,0,0,0,0,0,10,0,0,0,0,0,0,17,0,0,0
0,0,0,0,0,0,0,0,0,0,0,0,17,10,17,0,0,0,0,0,0,0,0,0,0,0,0,0,0,10,0,0,0,0,0
0,0,0,0,0,0,0,0,0,0,0,0,17,17,17,17,0,0,0,0,0,0,0,0,0,0,0,0,0,0,0,0,0,0,0
0,0,0,0,0,0,0,0,0,0,0,0,0,0,17,17,0,0,0,0,0,0,0,0,0,0,0,0,0,0,0,0,0,0,0
endlayer

layer
0,0,0,0,0,0,0,0,17,0,0,0,0,0,0,0,0,0,0,0,0,0,0,0,0,0,0,0,0,0,0,0,0,0,0
0,0,0,0,0,0,0,17,0,0,0,0,0,0,0,0,0,0,0,0,0,0,0,0,0,0,0,17,17,17,0,0,0,0,0
0,0,0,0,0,0,0,0,0,10,0,0,0,0,0,10,0,0,0,0,0,0,0,0,0,0,0,17,10,17,0,0,0,0,0
0,0,0,0,0,0,0,0,0,0,0,0,0,0,0,0,0,0,0,0,0,0,0,0,0,0,0,17,17,17,0,0,17,0,0
0,0,0,0,0,0,0,0,0,0,0,0,0,0,0,0,0,0,0,0,0,0,0,0,0,0,0,0,0,0,0,0,0,0,0
0,0,0,17,17,17,0,0,0,0,0,0,0,0,0,0,0,0,0,0,0,0,0,17,17,17,0,0,0,0,0,0,0,0,0
0,0,0,17,10,17,0,0,0,0,0,0,0,0,0,0,0,0,0,0,0,0,0,17,10,17,0,0,17,17,17,0,0,0,0
0,0,0,17,17,17,0,0,0,0,0,0,0,10,0,0,0,0,0,0,0,0,0,17,17,17,0,0,17,10,17,0,0,0,0
0,0,0,0,0,0,0,0,0,0,0,0,0,0,0,0,0,0,0,0,0,0,0,0,0,0,0,17,17,17,17,0,0,0,0
0,0,0,0,0,0,0,0,0,0,0,0,0,0,0,0,0,0,0,0,0,0,0,0,0,0,0,17,17,0,0,0,0,0,0
endlayer

layer
0,0,0,0,0,0,0,0,0,0,0,0,0,0,0,0,0,0,0,0,0,0,0,0,0,0,0,0,0,0,0,0,0,0,0
0,0,0,0,0,0,0,0,17,17,17,0,0,0,17,17,17,0,0,0,0,0,0,0,0,0,0,0,17,0,0,0,0,0,0
0,0,0,0,0,0,0,0,17,10,17,0,0,0,17,10,17,0,0,0,0,0,0,0,0,0,0,17,0,17,0,0,0,0,0
0,0,0,0,0,0,0,0,17,17,17,17,0,0,17,17,17,0,0,0,0,0,0,0,0,0,0,0,17,0,0,0,0,0,0
0,0,0,0,0,0,0,0,0,0,17,17,0,0,0,0,0,0,0,0,0,0,0,0,0,0,0,0,0,0,0,0,0,0,0
0,0,0,0,17,0,0,0,0,0,0,0,0,0,0,0,0,0,0,0,0,0,0,0,17,0,0,0,0,0,0,0,0,0,0
0,0,0,17,0,17,0,0,0,0,0,0,17,17,17,0,0,0,0,0,0,0,0,17,0,17,0,0,0,0,0,0,0,0,0
0,0,0,0,17,0,0,0,0,0,0,0,17,10,17,0,0,0,0,0,0,0,0,0,17,0,0,0,0,10,0,0,0,0,0
0,0,0,0,0,0,0,0,0,0,0,0,17,17,17,0,0,0,0,0,0,0,0,0,0,0,0,0,0,0,0,0,0,0,0
0,0,0,0,0,0,0,0,0,0,0,0,0,0,0,0,0,0,0,0,0,0,0,0,0,0,0,0,0,0,0,0,0,0,0
endlayer

layer
0,0,0,0,0,0,0,0,0,0,17,17,0,0,0,0,0,0,0,0,0,0,0,0,0,0,0,0,0,0,0,0,0,0,0
0,0,0,0,0,0,0,0,0,0,0,17,0,0,0,17,0,0,0,0,0,0,0,0,0,0,0,0,0,0,0,0,0,0,0
0,0,0,0,0,0,0,0,0,10,0,0,0,0,17,0,17,0,0,0,0,0,0,0,0,0,0,0,17,0,0,0,0,0,0
0,0,0,0,0,0,0,0,0,0,0,0,0,0,0,17,0,0,0,0,0,0,0,0,0,0,0,0,0,0,0,0,0,0,0
0,0,0,0,0,0,0,0,0,0,0,0,0,0,0,0,0,0,0,0,0,0,0,0,0,0,0,0,0,0,0,0,0,0,0
0,0,0,0,0,0,0,0,0,0,0,0,0,0,0,0,0,0,0,0,0,0,0,0,0,0,0,0,0,0,0,0,0,0,0
0,0,0,0,17,0,0,0,0,0,0,0,0,17,0,0,0,0,0,0,0,0,0,0,17,0,0,0,17,17,17,0,0,0,0
0,0,0,0,0,0,0,0,0,0,0,0,17,0,17,0,0,0,0,0,0,0,0,0,0,0,0,0,17,10,17,0,0,0,0
0,0,0,0,0,0,0,0,0,0,0,0,0,17,0,0,0,0,0,0,0,0,0,0,0,0,0,0,17,17,17,0,0,0,0
0,0,0,0,0,0,0,0,0,0,0,0,0,0,0,0,0,0,0,0,0,0,0,0,0,0,0,0,0,0,0,0,0,0,0
endlayer

layer
0,0,0,0,0,0,0,0,0,0,0,0,0,0,0,0,0,0,0,0,0,0,0,0,0,0,0,0,0,0,0,0,0,0,0
0,0,0,0,0,0,0,0,17,17,17,0,0,0,0,0,0,0,0,0,0,0,0,0,0,0,0,0,0,0,0,0,0,0,0
0,0,0,0,0,0,0,0,17,10,17,0,0,0,0,17,0,0,0,0,0,0,0,0,0,0,0,0,0,0,0,0,0,0,0
0,0,0,0,0,0,0,17,17,17,17,0,0,0,0,0,0,0,0,0,0,0,0,0,0,0,0,0,0,0,0,0,0,0,0
0,0,0,0,0,0,0,17,17,0,0,0,0,0,0,0,0,0,0,0,0,0,0,0,0,0,0,0,0,0,0,0,0,0,0
0,0,0,0,0,0,0,0,0,0,0,0,0,0,0,0,0,0,0,0,0,0,0,0,0,0,0,0,0,0,0,0,0,0,0
0,0,0,0,0,0,0,0,0,0,0,0,0,0,0,0,0,0,0,0,0,0,0,0,0,0,0,0,0,17,0,0,0,0,0
0,0,0,0,0,0,0,0,0,0,0,0,0,17,0,0,0,0,0,0,0,0,0,0,0,0,0,0,17,0,17,0,0,0,0
0,0,0,0,0,0,0,0,0,0,0,0,0,0,0,0,0,0,0,0,0,0,0,0,0,0,0,0,0,17,0,0,0,0,0
0,0,0,0,0,0,0,0,0,0,0,0,0,0,0,0,0,0,0,0,0,0,0,0,0,0,0,0,0,0,0,0,0,0,0
endlayer

layer
0,0,0,0,0,0,0,0,0,0,0,0,0,0,0,0,0,0,0,0,0,0,0,0,0,0,0,0,0,0,0,0,0,0,0
0,0,0,0,0,0,0,0,0,0,0,0,0,0,0,0,0,0,0,0,0,0,0,0,0,0,0,0,0,0,0,0,0,0,0
0,0,0,0,0,0,0,0,0,10,0,0,0,0,0,0,0,0,0,0,0,0,0,0,0,0,0,0,0,0,0,0,0,0,0
0,0,0,0,0,0,0,0,0,0,0,0,0,0,0,0,0,0,0,0,0,0,0,0,0,0,0,0,0,0,0,0,0,0,0
0,0,0,0,0,0,0,0,0,0,0,0,0,0,0,0,0,0,0,0,0,0,0,0,0,0,0,0,0,0,0,0,0,0,0
0,0,0,0,0,0,0,0,0,0,0,0,0,0,0,0,0,0,0,0,0,0,0,0,0,0,0,0,0,0,0,0,0,0,0
0,0,0,0,0,0,0,0,0,0,0,0,0,0,0,0,0,0,0,0,0,0,0,0,0,0,0,0,0,0,0,0,0,0,0
0,0,0,0,0,0,0,0,0,0,0,0,0,0,0,0,0,0,0,0,0,0,0,0,0,0,0,0,0,17,0,0,0,0,0
0,0,0,0,0,0,0,0,0,0,0,0,0,0,0,0,0,0,0,0,0,0,0,0,0,0,0,0,0,0,0,0,0,0,0
0,0,0,0,0,0,0,0,0,0,0,0,0,0,0,0,0,0,0,0,0,0,0,0,0,0,0,0,0,0,0,0,0,0,0
endlayer

layer
0,0,0,0,0,0,0,0,0,0,0,0,0,0,0,0,0,0,0,0,0,0,0,0,0,0,0,0,0,0,0,0,0,0,0
0,0,0,0,0,0,0,0,17,17,17,0,0,0,0,0,0,0,0,0,0,0,0,0,0,0,0,0,0,0,0,0,0,0,0
0,0,0,0,0,0,0,0,17,10,17,0,0,0,0,0,0,0,0,0,0,0,0,0,0,0,0,0,0,0,0,0,0,0,0
0,0,0,0,0,0,0,0,17,17,17,0,0,0,0,0,0,0,0,0,0,0,0,0,0,0,0,0,0,0,0,0,0,0,0
0,0,0,0,0,0,0,0,0,0,0,0,0,0,0,0,0,0,0,0,0,0,0,0,0,0,0,0,0,0,0,0,0,0,0
0,0,0,0,0,0,0,0,0,0,0,0,0,0,0,0,0,0,0,0,0,0,0,0,0,0,0,0,0,0,0,0,0,0,0
0,0,0,0,0,0,0,0,0,0,0,0,0,0,0,0,0,0,0,0,0,0,0,0,0,0,0,0,0,0,0,0,0,0,0
0,0,0,0,0,0,0,0,0,0,0,0,0,0,0,0,0,0,0,0,0,0,0,0,0,0,0,0,0,0,0,0,0,0,0
0,0,0,0,0,0,0,0,0,0,0,0,0,0,0,0,0,0,0,0,0,0,0,0,0,0,0,0,0,0,0,0,0,0,0
0,0,0,0,0,0,0,0,0,0,0,0,0,0,0,0,0,0,0,0,0,0,0,0,0,0,0,0,0,0,0,0,0,0,0
endlayer

layer
0,0,0,0,0,0,0,0,0,0,0,0,0,0,0,0,0,0,0,0,0,0,0,0,0,0,0,0,0,0,0,0,0,0,0
0,0,0,0,0,0,0,0,0,17,0,0,0,0,0,0,0,0,0,0,0,0,0,0,0,0,0,0,0,0,0,0,0,0,0
0,0,0,0,0,0,0,0,17,0,17,0,0,0,0,0,0,0,0,0,0,0,0,0,0,0,0,0,0,0,0,0,0,0,0
0,0,0,0,0,0,0,0,0,17,0,0,0,0,0,0,0,0,0,0,0,0,0,0,0,0,0,0,0,0,0,0,0,0,0
0,0,0,0,0,0,0,0,0,0,0,0,0,0,0,0,0,0,0,0,0,0,0,0,0,0,0,0,0,0,0,0,0,0,0
0,0,0,0,0,0,0,0,0,0,0,0,0,0,0,0,0,0,0,0,0,0,0,0,0,0,0,0,0,0,0,0,0,0,0
0,0,0,0,0,0,0,0,0,0,0,0,0,0,0,0,0,0,0,0,0,0,0,0,0,0,0,0,0,0,0,0,0,0,0
0,0,0,0,0,0,0,0,0,0,0,0,0,0,0,0,0,0,0,0,0,0,0,0,0,0,0,0,0,0,0,0,0,0,0
0,0,0,0,0,0,0,0,0,0,0,0,0,0,0,0,0,0,0,0,0,0,0,0,0,0,0,0,0,0,0,0,0,0,0
0,0,0,0,0,0,0,0,0,0,0,0,0,0,0,0,0,0,0,0,0,0,0,0,0,0,0,0,0,0,0,0,0,0,0
endlayer

layer
0,0,0,0,0,0,0,0,0,0,0,0,0,0,0,0,0,0,0,0,0,0,0,0,0,0,0,0,0,0,0,0,0,0,0
0,0,0,0,0,0,0,0,0,0,0,0,0,0,0,0,0,0,0,0,0,0,0,0,0,0,0,0,0,0,0,0,0,0,0
0,0,0,0,0,0,0,0,0,17,0,0,0,0,0,0,0,0,0,0,0,0,0,0,0,0,0,0,0,0,0,0,0,0,0
0,0,0,0,0,0,0,0,0,0,0,0,0,0,0,0,0,0,0,0,0,0,0,0,0,0,0,0,0,0,0,0,0,0,0
0,0,0,0,0,0,0,0,0,0,0,0,0,0,0,0,0,0,0,0,0,0,0,0,0,0,0,0,0,0,0,0,0,0,0
0,0,0,0,0,0,0,0,0,0,0,0,0,0,0,0,0,0,0,0,0,0,0,0,0,0,0,0,0,0,0,0,0,0,0
0,0,0,0,0,0,0,0,0,0,0,0,0,0,0,0,0,0,0,0,0,0,0,0,0,0,0,0,0,0,0,0,0,0,0
0,0,0,0,0,0,0,0,0,0,0,0,0,0,0,0,0,0,0,0,0,0,0,0,0,0,0,0,0,0,0,0,0,0,0
0,0,0,0,0,0,0,0,0,0,0,0,0,0,0,0,0,0,0,0,0,0,0,0,0,0,0,0,0,0,0,0,0,0,0
0,0,0,0,0,0,0,0,0,0,0,0,0,0,0,0,0,0,0,0,0,0,0,0,0,0,0,0,0,0,0,0,0,0,0
endlayer

