
# Created by Ruins mod version 15.1 Ingame Parser
# authoring Player: VikingWarlock

weight=100
embed_into_distance=1
acceptable_target_blocks=
unacceptable_target_blocks=flowing_water,water,flowing_lava,lava
dimensions=9,11,14
allowable_overhang=0
max_leveling=2
leveling_buffer=0
preserve_water=0
preserve_lava=0
uniqueMinDistance=1000000
preventRotation=1

rule1=0,100,BiomesOPlenty:newBopGrass-0
rule2=0,100,BiomesOPlenty:newBopDirt-0
rule3=0,100,minecraft:tallgrass-1
rule4=0,100,BiomesOPlenty:leaves1-14
rule5=0,100,minecraft:double_plant-2
rule6=0,100,plantmegapack:flowerDelphinium-0
rule7=0,100,plantmegapack:flowerAzalea-7
rule8=0,100,BiomesOPlenty:logs2-1
rule9=0,100,plantmegapack:flowerRose-7
rule10=0,100,ExtrabiomesXL:log_elbow_rainbow_eucalyptus-2
rule11=0,100,BiomesOPlenty:magicStairs-2
rule12=0,100,ExtrabiomesXL:cornerlog_rainboweucalyptus-9
rule13=0,100,GardenStuff:lattice-2
rule14=0,100,ExtrabiomesXL:log_elbow_rainbow_eucalyptus-3
rule15=0,100,BiomesOPlenty:leaves1-6
rule16=0,100,ExtrabiomesXL:log2-0
rule17=0,100,minecraft:double_plant-8
rule18=0,100,ExtrabiomesXL:log2-8
rule19=0,100,ExtrabiomesXL:log2-4
rule20=0,100,ExtrabiomesXL:cornerlog_rainboweucalyptus-0
rule21=0,100,ExtrabiomesXL:cornerlog_rainboweucalyptus-6
rule22=0,100,ExtrabiomesXL:cornerlog_rainboweucalyptus-3
rule23=0,100,ExtrabiomesXL:cornerlog_rainboweucalyptus-11
rule24=0,100,ExtrabiomesXL:cornerlog_rainboweucalyptus-2
rule25=0,100,ExtrabiomesXL:cornerlog_rainboweucalyptus-1
rule26=0,100,ExtrabiomesXL:cornerlog_rainboweucalyptus-10
rule27=0,100,ExtrabiomesXL:cornerlog_rainboweucalyptus-7
rule28=0,100,chisel:woolen_clay-3
rule29=0,100,chisel:woolen_clay-15
rule30=0,100,IInventory;minecraft:chest;minecraft:grass#1#0#3+harvestcraft:saltItem#3#0#10+minecraft:brown_mushroom#2#0#24-2
rule31=0,100,ExtrabiomesXL:door_rainboweucalyptus-1
rule32=0,100,minecraft:bed-3
rule33=0,100,minecraft:bed-11
rule34=0,100,IInventory;minecraft:chest;harvestcraft:rainbowcurryItem#1#0#11+ExtrabiomesXL:saplings_2#1#3#13+minecraft:diamond_axe#1#0#26-2
rule35=0,100,chisel:stained_glass_pane_red-11
rule36=0,100,harvestcraft:pamcandleDeco4-3
rule37=0,100,harvestcraft:pamcandleDeco4-4
rule38=0,100,ExtrabiomesXL:door_rainboweucalyptus-9
rule39=0,100,ExtrabiomesXL:door_rainboweucalyptus-8
rule40=0,100,BiomesOPlenty:magicStairs-3
rule41=0,100,ExtrabiomesXL:woodslab-13
rule42=0,100,ExtrabiomesXL:log_elbow_rainbow_eucalyptus-1
rule43=0,100,ExtrabiomesXL:log_elbow_rainbow_eucalyptus-0
rule44=0,100,ExtrabiomesXL:stairs.rainboweucalyptus-0
rule45=0,100,BiomesOPlenty:magicStairs-0
rule46=0,100,ExtrabiomesXL:stairs.rainboweucalyptus-2
rule47=0,100,BiomesOPlenty:planks-5
rule48=0,100,ExtrabiomesXL:stairs.rainboweucalyptus-3
rule49=0,100,BiomesOPlenty:magicStairs-1
rule50=0,100,ExtrabiomesXL:stairs.rainboweucalyptus-1

layer
1,1,1,1,1,1,1,1,1,1,1,1,1,1
1,1,1,2,1,1,1,1,2,1,1,1,1,1
1,1,1,1,1,1,1,1,1,1,1,2,1,1
1,1,1,1,1,1,1,1,1,1,1,2,1,1
1,1,1,1,1,1,1,1,1,1,1,2,1,1
1,1,1,1,1,1,1,1,1,1,1,2,1,1
1,1,1,2,1,1,1,1,2,1,1,1,1,1
1,1,1,1,1,1,1,1,1,1,1,1,1,1
1,1,1,1,1,1,1,1,1,1,1,1,1,1
1,1,1,1,1,1,1,1,1,1,1,1,2,1
1,1,1,1,1,1,1,1,1,1,1,1,1,1
endlayer

layer
3,3,3,6,3,0,5,0,4,4,0,3,3,3
3,3,9,8,0,5,0,0,8,4,4,7,3,3
3,3,3,3,3,3,3,0,0,4,4,10,3,3
3,3,3,3,0,3,3,3,0,7,13,12,11,3
3,3,3,0,0,3,3,3,0,0,13,12,11,3
3,3,3,4,15,0,0,3,0,4,4,14,3,0
3,0,4,8,15,3,3,0,8,4,4,3,3,3
3,0,4,4,15,4,3,3,4,4,7,3,3,3
3,3,3,0,15,9,3,3,3,3,0,3,3,3
3,3,3,0,0,0,3,3,3,3,3,3,16,0
3,0,3,3,3,3,3,3,3,0,3,0,0,0
endlayer

layer
0,0,0,0,0,0,17,0,0,0,0,0,0,0
0,0,0,8,0,17,0,0,8,4,0,0,0,0
0,0,0,0,0,0,0,0,0,4,10,13,0,0
0,0,0,0,0,0,0,0,0,13,12,11,0,0
0,0,0,0,0,0,0,0,0,13,12,11,0,0
0,0,0,4,0,0,0,0,0,4,14,13,0,0
0,0,15,8,0,0,0,0,8,4,0,0,0,0
0,0,0,4,4,0,0,0,0,0,0,0,0,0
0,0,0,0,0,0,0,0,0,0,0,0,0,0
0,0,0,0,0,0,0,0,0,0,0,0,16,0
0,0,0,0,0,0,0,0,0,0,0,0,0,0
endlayer

layer
0,0,0,0,0,0,0,0,0,0,0,0,0,0
0,0,0,8,18,18,18,18,8,0,0,0,0,0
0,0,0,19,22,21,21,20,19,10,13,13,0,0
0,0,0,19,26,25,24,23,19,12,11,0,0,0
0,0,0,19,26,20,22,23,19,12,11,0,0,0
0,0,0,19,24,27,27,25,19,14,13,13,0,0
0,0,0,8,18,18,18,18,8,0,0,0,0,0
0,0,0,0,0,0,0,0,0,0,0,0,0,0
0,0,0,0,0,0,0,0,0,0,0,0,4,0
0,0,0,0,0,0,0,0,0,0,0,0,16,4
0,0,0,0,0,0,0,0,0,0,0,0,4,0
endlayer

layer
0,0,0,0,0,0,0,0,0,0,0,0,0,0
0,0,0,8,28,29,29,28,8,0,0,0,0,0
0,0,0,28,30,0,0,0,29,13,13,0,0,0
0,0,0,29,32,0,0,0,31,0,0,0,0,0
0,0,0,29,33,0,0,0,31,0,0,0,0,0
0,0,0,28,34,0,0,0,29,13,13,0,0,0
0,0,0,8,28,29,29,28,8,0,0,0,0,0
0,0,0,0,0,0,0,0,0,0,0,0,0,0
0,0,0,0,0,0,0,0,0,0,0,4,4,4
0,0,0,0,0,0,0,0,0,0,0,4,16,4
0,0,0,0,0,0,0,0,0,0,0,4,4,4
endlayer

layer
0,0,0,0,0,0,0,0,0,0,0,0,0,0
0,0,0,8,29,35,35,29,8,0,0,0,0,0
0,0,0,29,37,0,0,36,29,0,0,0,0,0
0,0,0,35,0,0,0,0,38,0,0,0,0,0
0,0,0,35,0,0,0,0,39,0,0,0,0,0
0,0,0,29,37,0,0,36,29,0,0,0,0,0
0,0,0,8,29,35,35,29,8,0,0,0,0,0
0,0,0,0,0,0,0,0,0,0,0,0,0,0
0,0,0,0,0,0,0,0,0,0,0,0,0,0
0,0,0,0,0,0,0,0,0,0,0,0,4,0
0,0,0,0,0,0,0,0,0,0,0,0,0,0
endlayer

layer
0,40,18,13,13,13,13,13,13,18,11,0,0,0
0,41,13,42,18,18,18,18,10,13,41,0,0,0
0,41,13,19,0,0,0,0,19,13,41,0,0,0
0,41,13,19,0,0,0,0,19,13,41,0,0,0
0,41,13,19,0,0,0,0,19,13,41,0,0,0
0,41,13,19,0,0,0,0,19,13,41,0,0,0
0,41,13,43,18,18,18,18,14,13,41,0,0,0
0,40,18,13,13,13,13,13,13,18,11,0,0,0
0,0,0,0,0,0,0,0,0,0,0,0,0,0
0,0,0,0,0,0,0,0,0,0,0,0,0,0
0,0,0,0,0,0,0,0,0,0,0,0,0,0
endlayer

layer
0,0,45,44,45,44,44,45,44,11,0,0,0,0
0,0,48,47,47,47,47,47,47,46,0,0,0,0
0,0,40,47,18,18,18,18,47,11,0,0,0,0
0,0,48,47,19,22,20,19,47,46,0,0,0,0
0,0,48,47,19,24,25,19,47,46,0,0,0,0
0,0,40,47,18,18,18,18,47,11,0,0,0,0
0,0,48,47,47,47,47,47,47,46,0,0,0,0
0,0,40,50,49,50,50,49,50,49,0,0,0,0
0,0,0,0,0,0,0,0,0,0,0,0,0,0
0,0,0,0,0,0,0,0,0,0,0,0,0,0
0,0,0,0,0,0,0,0,0,0,0,0,0,0
endlayer

layer
0,0,0,0,0,0,0,0,0,0,0,0,0,0
0,0,0,13,13,13,13,13,13,0,0,0,0,0
0,0,0,13,0,0,0,0,13,0,0,0,0,0
0,0,0,13,0,0,0,0,13,0,0,0,0,0
0,0,0,13,0,0,0,0,13,0,0,0,0,0
0,0,0,13,0,0,0,0,13,0,0,0,0,0
0,0,0,13,13,13,13,13,13,0,0,0,0,0
0,0,0,0,0,0,0,0,0,0,0,0,0,0
0,0,0,0,0,0,0,0,0,0,0,0,0,0
0,0,0,0,0,0,0,0,0,0,0,0,0,0
0,0,0,0,0,0,0,0,0,0,0,0,0,0
endlayer

