
# Created by Ruins mod version 15.1 Ingame Parser
# authoring Player: VikingWarlock

weight=100
embed_into_distance=1
acceptable_target_blocks=
unacceptable_target_blocks=flowing_water,water,flowing_lava,lava
dimensions=7,11,9
allowable_overhang=0
max_leveling=2
leveling_buffer=0
preserve_water=0
preserve_lava=0
uniqueMinDistance=1000000
preventRotation=1

rule1=0,100,minecraft:grass-0
rule2=0,100,minecraft:dirt-0
rule3=0,100,minecraft:coal_block-0
rule4=0,100,minecraft:lapis_block-0
rule5=0,100,BiomesOPlenty:magicStairs-2
rule6=0,100,BiomesOPlenty:planks-5
rule7=0,100,BiomesOPlenty:magicStairs-3
rule8=0,100,BiomesOPlenty:magicStairs-1
rule9=0,100,ExtrabiomesXL:log2-0
rule10=0,100,chisel:waterstone-1
rule11=0,100,minecraft:bookshelf-0
rule12=0,100,minecraft:bed-9
rule13=0,100,minecraft:wooden_slab-8
rule14=0,100,minecraft:bed-1
rule15=0,100,IInventory;minecraft:chest;ExtrabiomesXL:saplings_2#1#3#2+ExtrabiomesXL:log2#2#0#4+ExtrabiomesXL:saplings_2#1#3#7+ExtrabiomesXL:log2#1#0#10+ExtrabiomesXL:log2#4#0#12+ExtrabiomesXL:saplings_2#1#3#14+ExtrabiomesXL:log2#3#0#19+ExtrabiomesXL:saplings_2#1#3#21+ExtrabiomesXL:log2#3#0#24+ExtrabiomesXL:log2#3#0#26-3
rule16=0,100,minecraft:ender_chest-3
rule17=0,100,minecraft:wooden_door-2
rule18=0,100,GardenStuff:lattice-2
rule19=0,100,minecraft:stained_glass_pane-11
rule20=0,100,minecraft:flower_pot-1
rule21=0,100,minecraft:wooden_door-8
rule22=0,100,BiblioCraft:BiblioIronLantern-11
rule23=0,100,BiomesOPlenty:magicStairs-0
rule24=0,100,ExtrabiomesXL:cornerlog_rainboweucalyptus-6
rule25=0,100,ExtrabiomesXL:cornerlog_rainboweucalyptus-11
rule26=0,100,ExtrabiomesXL:cornerlog_rainboweucalyptus-10
rule27=0,100,ExtrabiomesXL:cornerlog_rainboweucalyptus-7

layer
1,1,1,1,1,1,1,1,1
1,2,2,2,2,2,2,2,1
1,2,2,2,2,2,2,2,1
1,2,2,2,2,2,2,2,1
1,2,2,2,2,2,2,2,1
1,2,2,2,2,2,2,2,1
1,2,2,2,2,2,2,2,1
1,2,2,2,2,2,2,2,1
1,1,1,2,2,2,1,1,1
1,1,1,2,2,2,1,1,1
1,1,1,1,1,1,1,1,1
endlayer

layer
0,0,0,0,0,0,0,0,0
0,3,3,3,3,3,3,3,0
0,3,4,3,4,3,4,3,0
0,3,3,4,3,4,3,3,0
0,3,4,3,4,3,4,3,0
0,3,3,4,3,4,3,3,0
0,3,4,3,4,3,4,3,0
0,3,3,3,3,3,3,3,0
0,0,7,6,6,6,5,0,0
0,0,7,6,6,6,5,0,0
0,0,8,8,8,8,5,0,0
endlayer

layer
0,0,0,0,0,0,0,0,0
0,9,10,10,10,10,10,9,0
0,10,12,0,0,0,11,10,0
0,10,14,0,0,0,13,10,0
0,10,0,0,0,0,11,10,0
0,10,0,0,0,0,15,10,0
0,10,0,0,0,0,16,10,0
0,9,10,10,17,10,10,9,0
0,0,0,18,0,18,0,0,0
0,0,0,18,0,18,0,0,0
0,0,0,0,0,0,0,0,0
endlayer

layer
0,0,0,0,0,0,0,0,0
0,9,10,19,19,19,10,9,0
0,10,0,0,0,0,20,10,0
0,19,0,0,0,0,0,19,0
0,19,0,0,0,0,20,19,0
0,19,0,0,0,0,0,19,0
0,10,0,0,0,0,0,10,0
0,9,10,10,21,10,10,9,0
0,0,0,18,0,18,0,0,0
0,0,0,0,0,0,0,0,0
0,0,0,0,0,0,0,0,0
endlayer

layer
0,0,0,0,0,0,0,0,0
0,9,10,10,10,10,10,9,0
0,10,22,0,0,0,22,10,0
0,10,0,0,0,0,0,10,0
0,10,0,0,0,0,0,10,0
0,10,0,0,0,0,0,10,0
0,10,22,0,0,0,22,10,0
0,9,10,10,10,10,10,9,0
0,0,0,0,0,0,0,0,0
0,0,0,0,0,0,0,0,0
0,0,0,0,0,0,0,0,0
endlayer

layer
23,23,23,23,23,23,23,23,23
7,9,10,10,10,10,10,9,5
7,10,24,26,24,25,24,10,5
7,10,27,26,27,25,24,10,5
7,10,24,26,24,25,24,10,5
7,10,24,26,27,25,24,10,5
7,10,24,26,24,25,24,10,5
7,9,10,10,10,10,10,9,5
8,8,8,8,8,8,8,8,5
0,0,0,0,0,0,0,0,0
0,0,0,0,0,0,0,0,0
endlayer

layer
0,0,0,0,0,0,0,0,0
0,23,23,23,23,23,23,5,0
0,7,6,6,6,6,6,5,0
0,7,6,6,6,6,6,5,0
0,7,6,6,6,6,6,5,0
0,7,6,6,6,6,6,5,0
0,7,6,6,6,6,6,5,0
0,8,8,8,8,8,8,8,0
0,0,0,0,0,0,0,0,0
0,0,0,0,0,0,0,0,0
0,0,0,0,0,0,0,0,0
endlayer

