
# Created by Ruins mod version 15.0 Ingame Parser
# authoring Player: SunsOfOld

weight=50
embed_into_distance=8
acceptable_target_blocks=
unacceptable_target_blocks=flowing_water,water,flowing_lava,lava
dimensions=24,14,19
allowable_overhang=0
max_leveling=5
leveling_buffer=0
preserve_water=0
preserve_lava=0
uniqueMinDistance=1000000
preventRotation=1

rule1=0,100,preserveBlock
rule2=0,100,UndergroundBiomes:metamorphicCobblestone-1
rule3=0,100,minecraft:diamond_ore-0
rule4=0,100,IInventory;minecraft:chest;minecraft:lead#1#0#13+minecraft:diamond_horse_armor#1#0#22-3
rule5=0,100,IInventory;minecraft:chest;minecraft:water_bucket#1#0#4-3
rule6=0,100,minecraft:crafting_table-0
rule7=0,100,minecraft:brown_mushroom-0
rule8=0,100,minecraft:red_mushroom-0
rule9=0,100,IInventory;minecraft:chest;minecraft:sign#1#0#22-3
rule10=0,100,IInventory;minecraft:chest;minecraft:clock#1#0#13-3
rule11=0,100,minecraft:ladder-2
rule12=0,100,minecraft:stonebrick-1
rule13=0,100,minecraft:stonebrick-2
rule14=0,100,minecraft:dirt-0
rule15=0,100,minecraft:vine-4
rule16=0,100,minecraft:vine-8
rule17=0,100,minecraft:vine-1
rule18=0,100,minecraft:gravel-0
rule19=0,100,minecraft:stone_slab-5
rule20=0,100,minecraft:stonebrick-0
rule21=0,100,minecraft:monster_egg-3
rule22=0,100,minecraft:log-0
rule23=0,100,minecraft:vine-2
rule24=0,100,minecraft:vine-12
rule25=0,100,minecraft:monster_egg-4
rule26=0,100,minecraft:vine-5
rule27=0,100,minecraft:vine-9
rule28=0,100,minecraft:trapdoor-0
rule29=0,100,minecraft:leaves-0
rule30=0,100,minecraft:iron_bars-0
rule31=0,100,minecraft:vine-6
rule32=0,100,MobSpawner:Silverfish
rule33=0,100,minecraft:leaves-4
rule34=0,100,minecraft:log-4
rule35=0,100,minecraft:log-8
rule36=0,100,Skull:1:12-1

layer
1,1,1,1,1,1,1,1,1,1,1,1,1,1,1,1,1,1,1
1,1,1,1,1,1,1,1,1,1,1,1,1,1,1,1,1,1,1
1,1,1,1,1,1,1,1,1,1,1,1,1,1,1,1,1,1,1
1,1,1,1,1,1,1,1,1,1,1,1,1,1,1,1,1,1,1
1,1,1,2,2,2,2,2,2,2,2,2,1,1,1,1,1,1,1
1,1,1,2,2,2,2,2,2,2,2,2,1,1,1,1,1,1,1
1,1,1,2,2,2,2,2,2,2,2,2,1,1,1,1,1,1,1
1,1,1,2,2,2,2,2,2,2,2,2,1,1,1,1,1,1,1
1,1,1,2,2,2,2,2,2,2,2,2,1,1,1,1,1,1,1
1,1,1,1,1,1,1,1,1,1,1,1,1,1,1,1,1,1,1
1,1,1,1,1,1,1,1,1,1,1,1,1,1,1,1,1,1,1
1,1,1,1,1,1,1,1,1,1,1,1,1,1,1,1,1,1,1
1,1,1,1,1,1,1,1,1,1,1,1,1,1,1,1,1,1,1
1,1,1,1,1,1,1,1,1,1,1,1,1,1,1,1,1,1,1
endlayer

layer
1,1,1,1,1,1,1,1,1,1,1,1,1,1,1,1,1,1,1
1,1,1,1,1,1,1,1,1,1,1,1,1,1,1,1,1,1,1
1,1,1,1,1,1,1,1,1,1,1,1,1,1,1,1,1,1,1
1,1,1,1,1,1,1,1,1,1,1,1,1,1,1,1,1,1,1
1,1,1,2,2,2,2,2,2,2,2,2,1,1,1,1,1,1,1
1,1,1,2,2,3,2,0,0,0,0,2,1,1,1,1,1,1,1
1,1,1,3,2,3,0,0,0,0,0,3,1,1,1,1,1,1,1
1,1,1,3,2,0,0,0,0,0,0,2,1,1,1,1,1,1,1
1,1,1,2,2,2,3,2,3,2,2,2,1,1,1,1,1,1,1
1,1,1,1,1,1,1,1,1,1,1,1,1,1,1,1,1,1,1
1,1,1,1,1,1,1,1,1,1,1,1,1,1,1,1,1,1,1
1,1,1,1,1,1,1,1,1,1,1,1,1,1,1,1,1,1,1
1,1,1,1,1,1,1,1,1,1,1,1,1,1,1,1,1,1,1
1,1,1,1,1,1,1,1,1,1,1,1,1,1,1,1,1,1,1
endlayer

layer
1,1,1,1,1,1,1,1,1,1,1,1,1,1,1,1,1,1,1
1,1,1,1,1,1,1,1,1,1,1,1,1,1,1,1,1,1,1
1,1,1,1,1,1,1,1,1,1,1,1,1,1,1,1,1,1,1
1,1,1,1,1,1,1,1,1,1,1,1,1,1,1,1,1,1,1
1,1,1,2,2,2,2,2,2,2,2,2,1,1,1,1,1,1,1
1,1,1,2,2,3,0,0,0,0,0,3,1,1,1,1,1,1,1
1,1,1,2,2,0,0,0,0,0,0,2,1,1,1,1,1,1,1
1,1,1,2,0,0,0,0,0,0,0,2,1,1,1,1,1,1,1
1,1,1,2,3,2,2,3,3,2,2,2,1,1,1,1,1,1,1
1,1,1,1,1,1,1,1,1,1,1,1,1,1,1,1,1,1,1
1,1,1,1,1,1,1,1,1,1,1,1,1,1,1,1,1,1,1
1,1,1,1,1,1,1,1,1,1,1,1,1,1,1,1,1,1,1
1,1,1,1,1,1,1,1,1,1,1,1,1,1,1,1,1,1,1
1,1,1,1,1,1,1,1,1,1,1,1,1,1,1,1,1,1,1
endlayer

layer
1,1,1,1,1,1,1,1,1,1,1,1,1,1,1,1,1,1,1
1,1,1,1,1,1,1,1,1,1,1,1,1,1,1,1,1,1,1
1,1,1,1,1,1,1,1,1,1,1,1,1,1,1,1,1,1,1
1,1,1,1,1,1,1,1,1,1,1,1,1,1,1,1,1,1,1
1,1,1,2,2,3,2,2,2,3,2,2,1,1,1,1,1,1,1
1,1,1,3,0,0,0,0,0,0,0,2,1,1,1,1,1,1,1
1,1,1,2,0,0,0,0,0,0,0,2,1,1,1,1,1,1,1
1,1,1,2,0,0,0,0,0,0,0,3,1,1,1,1,1,1,1
1,1,1,2,3,2,2,3,2,2,3,2,1,1,1,1,1,1,1
1,1,1,1,1,1,1,1,1,1,1,1,1,1,1,1,1,1,1
1,1,1,1,1,1,1,1,1,1,1,1,1,1,1,1,1,1,1
1,1,1,1,1,1,1,1,1,1,1,1,1,1,1,1,1,1,1
1,1,1,1,1,1,1,1,1,1,1,1,1,1,1,1,1,1,1
1,1,1,1,1,1,1,1,1,1,1,1,1,1,1,1,1,1,1
endlayer

layer
1,1,1,1,1,1,1,1,1,1,1,1,1,1,1,1,1,1,1
1,1,1,1,1,1,1,1,1,1,1,1,1,1,1,1,1,1,1
1,1,1,1,1,1,1,1,1,1,1,1,1,1,1,1,1,1,1
1,1,1,1,1,1,1,1,1,1,1,1,1,1,1,1,1,1,1
1,1,1,2,2,2,2,2,2,2,2,2,1,1,1,1,1,1,1
1,1,1,2,2,2,2,2,2,2,2,2,1,1,1,1,1,1,1
1,1,1,2,2,2,2,2,2,2,4,2,1,1,1,1,1,1,1
1,1,1,2,2,2,2,2,2,2,5,2,1,1,1,1,1,1,1
1,1,1,2,2,2,2,2,2,2,2,2,1,1,1,1,1,1,1
1,1,1,1,1,1,1,1,1,1,1,1,1,1,1,1,1,1,1
1,1,1,1,1,1,1,1,1,1,1,1,1,1,1,1,1,1,1
1,1,1,1,1,1,1,1,1,1,1,1,1,1,1,1,1,1,1
1,1,1,1,1,1,1,1,1,1,1,1,1,1,1,1,1,1,1
1,1,1,1,1,1,1,1,1,1,1,1,1,1,1,1,1,1,1
endlayer

layer
1,1,1,1,1,1,1,1,1,1,1,1,1,1,1,1,1,1,1
1,1,1,1,1,1,1,1,1,1,1,1,1,1,1,1,1,1,1
1,1,1,1,1,1,1,1,1,1,1,1,1,1,1,1,1,1,1
1,1,1,1,1,1,1,1,1,1,1,1,1,1,1,1,1,1,1
1,1,1,2,2,2,2,2,2,2,2,2,1,1,1,1,1,1,1
1,1,1,2,0,0,7,8,0,7,6,2,1,1,1,1,1,1,1
1,1,1,2,8,7,0,8,8,8,9,2,1,1,1,1,1,1,1
1,1,1,2,8,7,0,0,7,8,10,2,1,1,1,1,1,1,1
1,1,1,2,2,2,2,2,2,2,2,2,1,1,1,1,1,1,1
1,1,1,1,1,1,1,1,1,1,1,1,1,1,1,1,1,1,1
1,1,1,1,1,1,1,1,1,1,1,1,1,1,1,1,1,1,1
1,1,1,1,1,1,1,1,1,1,1,1,1,1,1,1,1,1,1
1,1,1,1,1,1,1,1,1,1,1,1,1,1,1,1,1,1,1
1,1,1,1,1,1,1,1,1,1,1,1,1,1,1,1,1,1,1
endlayer

layer
1,1,1,1,1,1,1,1,1,1,1,1,1,1,1,1,1,1,1
1,1,1,1,1,1,1,1,1,1,1,1,1,1,1,1,1,1,1
1,1,1,1,1,1,1,1,1,1,1,1,1,1,1,1,1,1,1
1,1,1,1,1,1,1,1,1,1,1,1,1,1,1,1,1,1,1
1,1,1,2,2,2,2,2,2,2,2,2,1,1,1,1,1,1,1
1,1,1,2,0,0,0,0,0,0,0,2,1,1,1,1,1,1,1
1,1,1,2,11,0,0,0,0,0,0,2,1,1,1,1,1,1,1
1,1,1,2,0,0,0,0,0,0,0,2,1,1,1,1,1,1,1
1,1,1,2,2,2,2,2,2,2,2,2,1,1,1,1,1,1,1
1,1,1,1,1,1,1,1,1,1,1,1,1,1,1,1,1,1,1
1,1,1,1,1,1,1,1,1,1,1,1,1,1,1,1,1,1,1
1,1,1,1,1,1,1,1,1,1,1,1,1,1,1,1,1,1,1
1,1,1,1,1,1,1,1,1,1,1,1,1,1,1,1,1,1,1
1,1,1,1,1,1,1,1,1,1,1,1,1,1,1,1,1,1,1
endlayer

layer
1,1,1,1,1,1,1,1,1,1,1,1,1,1,1,1,1,1,1
1,1,1,12,1,1,1,1,1,1,1,1,1,1,1,1,1,1,1
1,14,1,12,12,14,1,12,1,1,1,1,13,12,1,1,1,1,1
1,13,1,1,1,1,14,1,14,1,1,13,1,14,1,1,1,1,1
1,1,1,1,2,2,2,2,2,2,2,1,1,1,1,1,1,1,1
1,1,1,2,0,0,0,0,0,0,0,2,14,13,1,1,1,1,1
1,1,14,2,11,0,0,0,0,0,0,2,1,1,1,1,1,1,1
1,1,14,2,0,0,0,0,0,0,0,2,1,14,1,1,1,1,1
13,1,1,1,2,2,2,2,2,2,2,1,1,1,1,1,1,1,1
1,1,1,1,1,1,1,1,1,1,1,1,1,1,1,1,1,1,1
1,1,1,1,1,1,14,1,1,1,1,1,1,1,1,1,1,1,1
1,1,1,14,1,1,1,1,1,14,1,1,1,1,1,1,1,1,1
1,1,1,1,1,1,1,1,1,1,1,1,1,1,1,1,1,1,1
1,1,1,1,1,1,1,1,1,1,1,1,1,1,1,1,1,1,1
endlayer

layer
0,0,15,0,0,0,0,0,0,0,0,0,0,0,0,0,0,0,0
20,0,0,0,0,0,19,0,0,18,0,15,12,17,16,12,0,0,0
0,15,13,0,0,22,0,0,17,19,18,0,16,0,13,19,0,21,0
0,0,24,19,18,19,0,18,0,18,18,16,13,16,23,17,21,0,0
13,16,12,13,20,20,12,13,13,13,12,12,19,0,19,0,21,16,0
15,12,15,12,2,2,2,2,2,2,2,25,17,0,16,16,0,0,25
0,0,15,20,11,21,2,2,2,2,2,2,19,0,18,0,0,17,0
0,19,18,20,2,2,2,2,2,2,2,13,0,22,0,0,0,0,0
0,16,0,18,12,20,20,13,20,13,20,17,18,15,0,0,25,0,0
0,0,0,0,23,23,0,18,0,23,23,23,0,15,0,0,0,0,0
0,0,0,0,0,0,22,0,0,0,0,0,15,0,23,0,23,0,0
15,0,0,22,0,0,0,0,0,22,0,0,15,0,0,23,0,17,0
15,0,0,0,0,0,26,0,0,0,0,0,0,23,0,17,23,0,0
15,0,0,0,0,0,0,0,0,0,0,0,0,0,0,0,0,0,0
endlayer

layer
0,0,15,0,0,0,0,0,0,0,0,0,0,0,0,0,0,0,0
0,0,0,0,0,0,0,0,0,0,0,0,0,0,0,0,0,0,0
0,0,15,0,0,22,0,0,17,0,0,0,0,0,0,0,0,0,0
0,0,15,0,0,0,0,16,0,16,18,16,0,16,0,17,0,0,0
0,0,15,0,0,20,12,20,12,13,12,18,16,0,0,0,27,16,0
0,0,0,16,13,19,13,23,21,23,19,13,17,0,16,16,0,0,0
0,0,15,20,28,0,21,21,12,19,0,27,16,0,0,0,0,17,0
0,0,15,20,21,21,15,16,16,0,16,20,0,22,0,0,0,0,0
0,16,0,15,12,20,12,12,20,12,20,17,17,15,0,0,0,0,0
0,0,0,0,0,23,0,23,29,23,23,23,0,15,0,0,0,0,0
0,0,0,0,0,0,22,29,29,29,29,29,15,0,23,0,23,0,0
15,0,0,22,0,0,0,29,29,22,29,29,15,0,0,23,0,17,0
15,0,0,0,0,0,26,29,29,29,29,29,0,23,0,17,23,0,0
15,0,0,0,0,0,0,0,29,29,29,29,0,0,0,0,0,0,0
endlayer

layer
0,0,15,0,0,0,0,0,0,0,0,0,0,0,0,0,0,0,0
0,0,0,0,0,0,0,0,0,0,0,0,0,0,0,0,0,0,0
0,0,15,0,0,22,0,0,17,0,0,0,0,0,0,0,0,0,0
0,0,15,0,0,0,0,16,0,16,16,16,0,16,0,17,0,0,0
0,0,15,0,0,12,30,20,20,30,12,18,16,0,0,0,27,16,0
0,0,0,16,21,31,15,23,23,0,0,17,0,0,16,16,0,0,0
0,0,15,20,21,0,21,0,21,0,0,27,16,0,0,0,0,17,0
0,0,15,13,17,16,15,16,0,0,16,20,0,22,0,0,0,0,0
0,16,0,15,20,20,20,20,13,30,20,17,17,15,0,0,0,0,0
0,0,0,0,29,23,0,23,29,23,23,23,0,15,0,0,0,0,0
0,0,0,29,29,29,22,29,29,29,29,29,15,0,23,0,23,0,0
15,0,0,22,29,0,0,29,29,22,29,29,15,0,0,23,0,17,0
15,0,0,0,0,0,26,29,29,29,29,29,0,23,0,17,23,0,0
15,0,0,0,0,0,0,0,29,29,29,0,0,0,0,0,0,0,0
endlayer

layer
0,0,15,29,29,29,29,29,0,0,0,0,0,0,0,0,0,0,0
0,0,0,29,29,29,29,29,0,0,0,0,0,0,0,0,0,0,0
0,0,15,29,29,22,29,29,17,0,0,0,0,0,0,0,0,0,0
0,0,15,29,29,29,29,16,0,16,0,16,0,16,0,17,0,0,0
0,0,15,29,0,29,30,20,13,30,27,0,16,0,0,0,27,16,0
0,0,0,16,21,15,15,23,23,0,0,17,0,0,16,16,0,0,0
0,0,15,30,0,0,26,0,0,0,0,27,16,0,0,0,0,17,0
0,0,15,20,17,16,15,16,0,0,16,20,0,22,0,0,0,0,0
0,16,0,15,13,30,12,20,20,30,13,17,17,15,0,0,0,0,0
0,29,29,29,29,23,29,23,0,23,23,23,0,15,0,0,0,0,0
0,29,29,29,29,29,22,29,29,29,0,0,15,0,23,0,23,0,0
15,29,29,22,29,29,29,0,29,22,29,0,15,0,0,23,0,17,0
15,29,29,29,29,29,17,0,0,29,0,0,0,23,0,17,23,0,0
15,29,29,29,29,29,0,0,0,0,0,0,0,0,0,0,0,0,0
endlayer

layer
0,0,0,0,29,29,29,29,0,0,0,0,0,0,0,0,0,0,0
0,0,0,29,29,29,29,29,0,0,0,0,0,0,0,0,0,0,0
0,0,15,29,29,22,29,29,0,0,0,0,0,0,0,0,0,0,0
0,0,15,29,29,29,29,16,0,16,0,16,0,16,0,17,0,0,0
0,0,0,0,29,29,15,20,20,20,27,0,16,0,0,0,27,16,0
0,0,0,16,16,15,15,13,20,12,12,17,0,0,16,16,0,0,0
0,0,15,20,21,0,15,21,0,13,20,27,16,0,0,0,0,17,0
0,0,15,20,17,16,15,13,0,12,13,20,0,22,0,29,0,0,0
0,0,0,15,20,20,20,12,20,13,20,20,17,15,29,29,29,0,0
0,29,29,29,29,23,29,23,29,23,23,23,0,15,29,29,29,0,0
0,29,29,29,29,29,22,29,29,29,0,0,15,0,23,29,23,0,0
15,29,29,22,29,29,29,29,29,29,29,0,15,0,0,23,0,17,0
15,29,29,29,29,29,29,29,0,29,0,0,0,23,0,17,23,0,0
0,0,29,29,29,0,0,0,0,0,0,0,0,0,0,0,0,0,0
endlayer

layer
0,0,0,0,0,0,0,0,0,0,0,0,0,0,0,0,0,0,0
0,0,0,0,0,29,0,0,0,0,0,0,0,0,0,0,0,0,0
0,0,0,0,29,22,29,0,0,0,0,0,0,0,0,0,0,0,0
0,0,0,0,29,29,29,16,0,16,0,16,0,16,0,17,0,0,0
0,0,0,0,0,0,15,15,20,13,17,0,16,0,0,0,27,16,0
0,0,0,0,16,15,20,12,33,32,18,0,0,0,16,16,0,0,0
0,0,0,0,12,20,0,20,33,33,33,16,16,33,29,29,29,17,0
0,0,0,0,20,12,20,12,0,0,17,12,0,22,29,29,29,29,0
0,0,0,0,23,23,23,12,12,20,20,18,0,34,34,29,29,29,0
0,0,0,0,29,29,29,23,29,23,23,0,0,34,29,29,29,29,0
0,0,0,29,29,29,29,29,29,0,0,0,15,29,29,29,29,29,0
0,0,29,22,29,29,29,29,29,0,0,0,15,0,29,29,29,17,0
0,0,0,29,0,29,29,29,0,0,0,0,0,23,0,17,23,0,0
0,0,0,0,0,0,0,0,0,0,0,0,0,0,0,0,0,0,0
endlayer

layer
0,0,0,0,0,0,0,0,0,0,0,0,0,0,0,0,0,0,0
0,0,0,0,0,29,0,0,0,0,0,0,0,0,0,0,0,0,0
0,0,0,0,29,29,29,0,0,0,0,0,0,0,0,0,0,0,0
0,0,0,0,0,29,0,16,0,16,0,16,0,16,0,17,0,0,0
0,0,0,0,0,0,15,15,13,30,17,0,16,0,0,0,27,16,0
0,0,0,0,0,0,0,13,33,0,33,0,33,33,16,16,0,0,0
0,0,0,0,0,0,0,0,33,33,0,16,16,29,29,29,29,17,0
0,0,0,0,0,0,15,20,0,0,17,13,29,22,29,29,29,29,0
0,0,0,0,0,0,0,15,13,30,20,23,29,29,29,29,29,29,0
0,0,0,0,0,0,29,23,0,23,0,0,29,29,29,29,29,29,0
0,0,0,29,0,29,29,29,0,0,0,0,15,29,34,29,29,29,0
0,0,29,29,29,0,29,0,0,0,0,0,15,29,34,29,29,17,0
0,0,0,29,0,0,0,0,0,0,0,0,0,23,29,17,23,0,0
0,0,0,0,0,0,0,0,0,0,0,0,0,0,0,0,0,0,0
endlayer

layer
0,0,0,0,0,0,0,0,0,0,0,0,0,0,0,0,0,0,0
0,0,0,0,0,0,0,0,0,0,0,0,0,0,0,0,0,0,0
0,0,0,0,0,0,0,0,0,0,0,0,0,0,0,0,0,0,0
0,0,0,0,0,0,0,16,0,16,0,16,0,16,0,17,0,0,0
0,0,0,0,0,0,15,15,20,0,17,0,16,0,0,0,27,16,0
0,0,0,0,0,0,0,13,33,0,17,33,0,0,16,16,0,0,0
0,0,0,0,0,0,0,0,0,0,0,16,16,29,29,29,0,0,0
0,0,0,0,0,0,15,20,0,0,17,20,29,22,29,29,29,0,0
0,0,0,0,0,0,0,15,12,30,12,23,34,34,29,29,29,0,0
0,0,0,0,0,0,0,23,0,23,0,29,34,29,34,29,29,0,0
0,0,0,0,0,0,0,0,0,0,0,0,29,29,29,29,29,0,0
0,0,0,0,0,0,0,0,0,0,0,0,29,29,29,29,29,0,0
0,0,0,0,0,0,0,0,0,0,0,0,29,29,29,29,29,0,0
0,0,0,0,0,0,0,0,0,0,0,0,0,29,29,29,0,0,0
endlayer

layer
0,0,0,0,0,0,0,0,0,0,0,0,0,0,0,0,0,0,0
0,0,0,0,0,0,0,0,0,0,0,0,0,0,0,0,0,0,0
0,0,0,0,0,0,0,0,0,0,0,0,0,0,0,0,0,0,0
0,0,0,0,0,0,0,16,0,16,0,16,0,16,0,17,0,0,0
0,0,0,0,0,0,15,15,20,13,17,33,16,29,0,0,27,16,0
0,0,0,0,0,0,0,12,0,0,17,33,29,34,29,0,0,0,0
0,0,0,0,0,0,0,12,0,0,0,0,0,34,0,0,0,0,0
0,0,0,0,0,0,15,13,33,0,17,18,29,22,35,35,0,0,0
0,0,0,0,0,0,0,15,20,20,12,29,29,29,29,29,0,0,0
0,0,0,0,0,0,0,23,0,23,29,29,29,29,29,29,0,0,0
0,0,0,0,0,0,0,0,0,0,29,29,29,29,34,29,29,0,0
0,0,0,0,0,0,0,0,0,0,0,29,29,29,29,29,29,0,0
0,0,0,0,0,0,0,0,0,0,0,0,29,29,29,29,29,0,0
0,0,0,0,0,0,0,0,0,0,0,0,0,29,29,29,0,0,0
endlayer

layer
0,0,0,0,0,0,0,0,0,0,0,0,0,0,0,0,0,0,0
0,0,0,0,0,0,0,0,0,0,0,0,0,0,0,0,0,0,0
0,0,0,0,0,0,0,0,0,0,0,0,0,0,0,0,0,0,0
0,0,0,0,0,0,0,16,0,16,0,16,29,29,29,17,0,0,0
0,0,0,0,0,0,15,20,20,13,0,29,29,29,29,29,27,16,0
0,0,0,0,0,0,0,20,20,12,17,29,29,29,29,29,0,0,0
0,0,0,0,0,0,0,20,20,13,0,29,29,29,29,29,29,0,0
0,0,0,0,0,0,15,12,33,20,17,35,35,22,29,29,35,29,0
0,0,0,0,0,0,0,12,13,12,17,29,29,29,34,35,29,0,0
0,0,0,0,0,0,0,23,0,23,29,29,29,29,29,29,29,0,0
0,0,0,0,0,0,0,0,0,0,29,29,29,29,29,29,29,0,0
0,0,0,0,0,0,0,0,0,0,0,29,29,29,29,29,29,0,0
0,0,0,0,0,0,0,0,0,0,0,0,0,29,29,29,0,0,0
0,0,0,0,0,0,0,0,0,0,0,0,0,0,0,0,0,0,0
endlayer

layer
0,0,0,0,0,0,0,0,0,0,0,0,0,0,0,0,0,0,0
0,0,0,0,0,0,0,0,0,0,0,0,0,0,0,0,0,0,0
0,0,0,0,0,0,0,0,0,0,0,0,0,0,0,0,0,0,0
0,0,0,0,0,0,0,0,0,16,0,16,29,29,29,17,0,0,0
0,0,0,0,0,0,0,16,15,20,33,29,29,29,29,29,27,16,0
0,0,0,0,0,0,0,20,0,0,0,29,34,29,29,29,29,29,0
0,0,0,0,0,0,0,12,36,29,0,29,34,29,34,29,29,29,29
0,0,0,0,0,0,15,20,29,35,35,0,29,22,29,29,29,29,29
0,0,0,0,0,0,0,0,15,13,17,0,29,29,29,29,29,29,29
0,0,0,0,0,0,0,0,0,23,0,29,29,29,29,29,29,29,0
0,0,0,0,0,0,0,0,0,0,0,0,29,29,29,29,29,0,0
0,0,0,0,0,0,0,0,0,0,0,0,29,29,29,29,29,0,0
0,0,0,0,0,0,0,0,0,0,0,0,0,29,29,29,0,0,0
0,0,0,0,0,0,0,0,0,0,0,0,0,0,0,0,0,0,0
endlayer

layer
0,0,0,0,0,0,0,0,0,0,0,0,0,0,0,0,0,0,0
0,0,0,0,0,0,0,0,0,0,0,0,0,0,0,0,0,0,0
0,0,0,0,0,0,0,0,0,0,0,0,0,0,0,0,0,0,0
0,0,0,0,0,0,0,0,0,0,0,29,0,0,0,0,0,0,0
0,0,0,0,0,0,0,0,0,0,29,34,29,29,29,29,16,16,0
0,0,0,0,0,0,0,16,29,29,29,29,29,29,29,34,29,29,0
0,0,0,0,0,0,0,13,29,29,29,29,29,29,29,29,29,29,29
0,0,0,0,0,0,0,29,29,29,29,29,29,22,29,29,29,29,29
0,0,0,0,0,0,0,29,15,13,17,29,0,29,29,29,29,29,29
0,0,0,0,0,0,0,0,29,23,29,0,0,29,29,29,29,29,0
0,0,0,0,0,0,0,0,0,0,0,0,0,29,29,29,29,0,0
0,0,0,0,0,0,0,0,0,0,0,0,0,0,29,0,0,0,0
0,0,0,0,0,0,0,0,0,0,0,0,0,0,0,0,0,0,0
0,0,0,0,0,0,0,0,0,0,0,0,0,0,0,0,0,0,0
endlayer

layer
0,0,0,0,0,0,0,0,0,0,0,0,0,0,0,0,0,0,0
0,0,0,0,0,0,0,0,0,0,0,0,0,0,0,0,0,0,0
0,0,0,0,0,0,0,0,0,0,29,29,29,0,0,0,0,0,0
0,0,0,0,0,0,0,0,0,29,29,29,29,29,29,29,29,0,0
0,0,0,0,0,0,0,0,0,29,29,29,29,29,29,29,29,29,0
0,0,0,0,0,0,0,0,29,29,29,29,29,29,29,29,29,29,0
0,0,0,0,0,0,0,29,29,29,29,29,29,29,29,29,29,29,0
0,0,0,0,0,0,0,29,29,29,29,29,29,22,29,29,29,29,0
0,0,0,0,0,0,0,29,29,29,29,29,0,29,29,29,29,0,0
0,0,0,0,0,0,0,0,29,29,29,0,0,0,0,29,0,0,0
0,0,0,0,0,0,0,0,0,0,0,0,0,0,0,0,0,0,0
0,0,0,0,0,0,0,0,0,0,0,0,0,0,0,0,0,0,0
0,0,0,0,0,0,0,0,0,0,0,0,0,0,0,0,0,0,0
0,0,0,0,0,0,0,0,0,0,0,0,0,0,0,0,0,0,0
endlayer

layer
0,0,0,0,0,0,0,0,0,0,0,0,0,0,0,0,0,0,0
0,0,0,0,0,0,0,0,0,0,0,0,0,0,0,0,0,0,0
0,0,0,0,0,0,0,0,0,0,29,29,29,0,0,0,0,0,0
0,0,0,0,0,0,0,0,0,29,29,29,29,29,29,29,29,0,0
0,0,0,0,0,0,0,0,0,29,29,29,29,29,29,29,29,29,0
0,0,0,0,0,0,0,0,0,29,29,29,29,29,29,29,29,29,0
0,0,0,0,0,0,0,0,0,29,29,29,29,29,29,29,29,29,0
0,0,0,0,0,0,0,0,29,29,29,29,29,29,29,29,29,0,0
0,0,0,0,0,0,0,0,0,29,0,29,29,29,29,29,0,0,0
0,0,0,0,0,0,0,0,0,0,0,0,29,29,29,0,0,0,0
0,0,0,0,0,0,0,0,0,0,0,0,0,0,0,0,0,0,0
0,0,0,0,0,0,0,0,0,0,0,0,0,0,0,0,0,0,0
0,0,0,0,0,0,0,0,0,0,0,0,0,0,0,0,0,0,0
0,0,0,0,0,0,0,0,0,0,0,0,0,0,0,0,0,0,0
endlayer

layer
0,0,0,0,0,0,0,0,0,0,0,0,0,0,0,0,0,0,0
0,0,0,0,0,0,0,0,0,0,0,0,0,0,0,0,0,0,0
0,0,0,0,0,0,0,0,0,0,0,0,0,0,0,0,0,0,0
0,0,0,0,0,0,0,0,0,0,0,29,0,0,0,0,0,0,0
0,0,0,0,0,0,0,0,0,0,29,29,29,0,0,29,0,0,0
0,0,0,0,0,0,0,0,0,0,0,29,29,29,29,29,29,0,0
0,0,0,0,0,0,0,0,0,0,0,29,29,29,29,29,0,0,0
0,0,0,0,0,0,0,0,0,0,0,29,29,29,29,29,0,0,0
0,0,0,0,0,0,0,0,0,0,0,29,29,29,29,29,0,0,0
0,0,0,0,0,0,0,0,0,0,0,0,29,29,29,0,0,0,0
0,0,0,0,0,0,0,0,0,0,0,0,0,0,0,0,0,0,0
0,0,0,0,0,0,0,0,0,0,0,0,0,0,0,0,0,0,0
0,0,0,0,0,0,0,0,0,0,0,0,0,0,0,0,0,0,0
0,0,0,0,0,0,0,0,0,0,0,0,0,0,0,0,0,0,0
endlayer

layer
0,0,0,0,0,0,0,0,0,0,0,0,0,0,0,0,0,0,0
0,0,0,0,0,0,0,0,0,0,0,0,0,0,0,0,0,0,0
0,0,0,0,0,0,0,0,0,0,0,0,0,0,0,0,0,0,0
0,0,0,0,0,0,0,0,0,0,0,0,0,0,0,0,0,0,0
0,0,0,0,0,0,0,0,0,0,0,0,0,0,0,0,0,0,0
0,0,0,0,0,0,0,0,0,0,0,0,0,0,0,0,0,0,0
0,0,0,0,0,0,0,0,0,0,0,0,0,29,0,0,0,0,0
0,0,0,0,0,0,0,0,0,0,0,0,29,29,29,0,0,0,0
0,0,0,0,0,0,0,0,0,0,0,0,0,29,0,0,0,0,0
0,0,0,0,0,0,0,0,0,0,0,0,0,0,0,0,0,0,0
0,0,0,0,0,0,0,0,0,0,0,0,0,0,0,0,0,0,0
0,0,0,0,0,0,0,0,0,0,0,0,0,0,0,0,0,0,0
0,0,0,0,0,0,0,0,0,0,0,0,0,0,0,0,0,0,0
0,0,0,0,0,0,0,0,0,0,0,0,0,0,0,0,0,0,0
endlayer

