
# Created by Ruins mod version 15.0 Ingame Parser
# authoring Player: SunsOfOld

weight=100
embed_into_distance=7
acceptable_target_blocks=
unacceptable_target_blocks=flowing_water,water,flowing_lava,lava
dimensions=13,56,27
allowable_overhang=0
max_leveling=5
leveling_buffer=0
preserve_water=0
preserve_lava=0
uniqueMinDistance=1000000
preventRotation=1

rule1=0,100,preserveBlock
rule2=0,100,UndergroundBiomes:metamorphicStone-1
rule3=0,100,chisel:andesite-0
rule4=0,100,UndergroundBiomes:metamorphicStone-6
rule5=0,100,UndergroundBiomes:metamorphic_oreCoal-1
rule6=0,100,UndergroundBiomes:metamorphic_oreCoal-6
rule7=0,100,chisel:limestone-0
rule8=0,100,chisel:diorite-0
rule9=0,100,minecraft:stone-0
rule10=0,100,minecraft:grass-0
rule11=0,100,harvestcraft:salt-0
rule12=0,100,chisel:granite-0
rule13=0,100,dendrology:logs0-1
rule14=0,100,minecraft:gravel-0
rule15=0,100,minecraft:tallgrass-1
rule16=0,100,MobSpawner:Piranha
rule17=0,100,BiomesOPlenty:coral2-8
rule18=0,100,BiomesOPlenty:coral1-11
rule19=0,100,BiomesOPlenty:coral1-12
rule20=0,100,BiomesOPlenty:coral1-13
rule21=0,100,BiomesOPlenty:coral1-14
rule22=0,100,BiomesOPlenty:coral1-15
rule23=0,100,minecraft:water-0
rule24=0,100,BiomesOPlenty:coral1-8
rule25=0,100,minecraft:water-8
rule26=0,100,BiomesOPlenty:coral1-10
rule27=0,100,minecraft:vine-2
rule28=0,100,minecraft:vine-1
rule29=0,100,plantmegapack:vineFlowersPurple-0
rule30=0,100,minecraft:double_plant-2
rule31=0,100,ExtrabiomesXL:flower1-7
rule32=0,100,ExtrabiomesXL:flower3-6
rule33=0,100,minecraft:vine-8
rule34=0,100,minecraft:vine-9
rule35=0,100,BiomesOPlenty:foliage-10
rule36=0,100,BiomesOPlenty:foliage-11
rule37=0,100,ExtrabiomesXL:flower1-4
rule38=0,100,ExtrabiomesXL:flower3-5
rule39=0,100,dendrology:dslab0-1
rule40=0,100,minecraft:double_plant-8
rule41=0,100,ExtrabiomesXL:flower2-5
rule42=0,100,minecraft:vine-4
rule43=0,100,GardenTrees:thin_log-1
rule44=0,100,ExtrabiomesXL:flower3-0
rule45=0,100,ExtrabiomesXL:flower2-8
rule46=0,100,ExtrabiomesXL:flower3-2
rule47=0,100,ExtrabiomesXL:flower1-3
rule48=0,100,ExtrabiomesXL:flower3-12
rule49=0,100,ExtrabiomesXL:flower2-13
rule50=0,100,ExtrabiomesXL:flower2-3
rule51=0,100,ExtrabiomesXL:flower3-4
rule52=0,100,BiomesOPlenty:foliage-2
rule53=0,100,ExtrabiomesXL:flower3-8
rule54=0,100,minecraft:yellow_flower-0
rule55=0,100,GardenTrees:thin_log_fence-1
rule56=0,100,minecraft:red_flower-0
rule57=0,100,ExtrabiomesXL:flower3-7
rule58=0,100,ExtrabiomesXL:flower3-10
rule59=0,100,ExtrabiomesXL:flower3-3
rule60=0,100,minecraft:log-0
rule61=0,100,GardenStuff:heavy_chain-0
rule62=0,100,ExtrabiomesXL:flower3-9
rule63=0,100,ExtrabiomesXL:flower2-0
rule64=0,100,ExtrabiomesXL:flower2-12
rule65=0,100,ExtrabiomesXL:flower2-6
rule66=0,100,ExtrabiomesXL:flower2-7
rule67=0,100,BiomesOPlenty:foliage-14
rule68=0,100,ExtrabiomesXL:flower1-2
rule69=0,100,ExtrabiomesXL:flower2-15
rule70=0,100,plantmegapack:savannaButterflyWeed-1
rule71=0,100,plantmegapack:savannaButterflyWeed-0
rule72=0,100,minecraft:leaves-0
rule73=0,100,minecraft:leaves-4
rule74=0,100,dendrology:logs0-9
rule75=0,100,minecraft:vine-6

layer
1,1,1,1,1,1,1,1,1,1,1,1,1,1,1,1,1,1,1,1,1,1,1,1,1,1,1
1,1,4,4,4,4,2,2,2,2,2,3,3,3,3,2,2,2,2,2,2,2,2,2,2,1,1
1,1,4,4,4,2,2,2,2,2,5,5,5,2,2,2,2,2,2,2,2,2,2,2,2,4,1
1,4,4,4,4,2,2,2,2,2,5,5,5,2,2,2,5,5,2,2,2,2,2,2,2,4,1
1,6,6,4,4,4,2,2,2,2,2,5,5,2,2,2,5,5,4,4,4,4,2,2,2,2,1
1,6,6,4,4,4,4,4,4,2,2,2,2,2,2,2,2,2,4,4,4,3,3,4,4,4,1
1,4,4,4,4,4,4,4,4,2,2,2,2,2,2,2,2,2,4,4,4,3,3,3,4,4,1
1,4,4,4,4,4,4,4,4,2,2,2,2,2,2,4,4,4,4,4,4,3,3,4,4,4,1
1,4,4,4,4,4,4,4,4,2,2,2,2,4,4,4,4,4,4,4,4,4,4,4,4,4,1
1,4,4,4,4,4,4,4,4,4,4,4,4,4,1,1,4,4,4,4,4,4,4,4,4,4,1
1,4,4,4,4,4,4,4,4,4,4,4,4,4,4,1,1,1,4,4,4,4,4,4,1,1,1
1,4,4,4,4,4,4,4,4,4,4,4,4,4,4,1,1,1,1,4,4,1,1,1,1,1,1
1,4,4,4,4,4,4,4,4,4,4,4,4,4,4,1,1,1,1,1,1,1,1,1,1,1,1
1,4,4,4,4,4,4,7,7,4,4,4,4,4,4,4,1,1,1,1,1,1,0,1,1,1,1
1,4,4,4,4,4,4,7,7,4,4,4,4,1,1,1,1,1,1,1,1,1,1,1,1,1,1
1,4,4,3,4,4,4,4,7,4,4,4,1,1,1,1,1,1,1,1,1,1,1,1,1,1,1
1,4,8,8,8,3,3,4,4,4,1,1,1,1,1,1,1,1,1,1,1,1,1,1,1,1,1
1,8,8,8,8,3,3,4,1,1,1,1,1,1,1,1,1,1,1,1,1,1,1,1,1,1,1
1,8,8,8,8,3,1,1,1,9,9,9,1,1,1,1,1,9,9,1,1,1,1,1,1,1,1
1,8,8,8,1,1,1,1,9,9,9,9,9,9,9,9,9,9,9,1,1,1,1,1,1,1,1
1,8,8,1,1,1,1,9,9,9,9,9,9,9,9,9,9,9,9,1,1,1,1,1,1,1,1
1,1,1,1,1,1,1,1,1,1,1,1,1,1,1,1,1,1,1,1,1,1,1,1,1,1,1
1,1,1,1,1,1,1,1,1,1,1,1,1,1,1,1,1,1,1,1,1,1,1,1,1,1,1
1,1,1,1,1,1,1,1,1,1,1,1,1,1,1,1,1,1,1,1,1,1,1,1,1,1,1
1,1,1,1,1,1,1,1,1,1,1,1,1,1,1,1,1,1,1,1,1,1,1,1,1,1,1
1,1,1,1,1,1,1,1,1,1,1,1,1,1,1,1,1,1,1,1,1,1,1,1,1,1,1
1,1,1,1,1,1,1,1,1,1,1,1,1,1,1,1,1,1,1,1,1,1,1,1,1,1,1
1,1,1,1,1,1,1,1,1,1,1,1,1,1,1,1,1,1,1,1,1,1,1,1,1,1,1
1,1,1,1,1,1,1,1,1,1,1,1,1,1,1,1,1,1,1,1,1,1,1,1,1,1,1
1,1,1,1,1,1,1,1,1,1,1,1,1,1,1,1,1,1,1,1,1,1,1,1,1,1,1
1,1,1,1,1,1,1,1,1,1,1,1,1,1,1,1,1,1,1,1,1,1,1,1,1,1,1
1,1,1,1,1,1,1,1,1,1,1,1,1,1,1,1,1,1,1,1,1,1,1,1,1,1,1
1,1,1,1,1,1,1,1,1,1,1,1,1,1,1,1,1,1,1,1,1,1,1,1,1,9,1
1,1,1,1,1,1,1,1,1,1,1,1,1,1,1,1,1,1,1,1,1,1,1,1,1,1,1
1,1,1,1,1,1,1,1,1,1,1,1,1,1,1,1,1,1,1,1,1,1,1,1,1,1,1
1,1,1,1,1,1,1,1,1,1,1,1,1,1,1,1,1,1,1,1,1,1,1,1,1,1,1
1,1,1,1,1,1,1,1,1,1,1,1,1,1,1,1,1,1,1,1,1,1,4,1,4,4,1
1,1,1,1,1,1,1,1,1,1,1,1,1,1,1,1,1,1,1,1,1,4,1,4,4,4,1
1,1,1,1,1,1,1,1,1,1,1,1,1,1,1,1,1,1,1,1,4,4,4,4,4,4,1
1,1,1,1,1,1,1,1,1,1,1,1,1,1,1,1,1,1,1,9,4,4,4,4,4,4,1
1,1,1,1,1,1,1,1,1,1,1,1,1,1,1,1,1,1,1,9,9,4,4,4,4,4,1
1,1,1,1,1,1,1,1,1,1,1,1,1,1,1,1,1,1,1,1,9,4,4,4,4,4,1
1,1,1,1,1,1,1,1,1,1,1,1,1,1,1,1,1,1,1,9,9,9,4,4,4,4,1
1,1,1,1,1,1,1,1,1,1,1,1,1,1,1,4,4,4,9,9,9,9,9,4,4,4,1
1,1,1,1,1,1,1,1,1,1,4,4,4,4,4,4,4,4,4,9,9,9,9,4,4,4,1
1,1,1,1,1,1,1,10,1,4,4,4,4,4,4,4,4,4,4,4,9,9,4,4,4,4,1
1,1,1,1,1,1,1,1,4,4,4,4,4,4,4,4,4,4,4,4,4,4,4,4,4,4,1
1,1,1,1,1,1,1,1,4,4,4,4,4,4,4,4,4,4,4,4,4,4,4,4,4,4,1
1,1,1,1,1,1,1,1,4,4,4,4,4,4,4,4,4,4,4,4,11,4,4,4,4,4,1
1,1,1,1,1,1,1,1,4,4,4,4,4,4,4,4,4,4,4,4,11,4,4,4,4,4,1
1,1,1,1,1,1,1,1,4,4,4,4,4,4,4,4,4,4,12,12,12,12,12,12,12,4,1
1,1,1,1,1,1,1,1,1,4,4,4,4,4,4,4,4,12,12,12,12,12,9,9,12,12,1
1,1,1,1,1,1,1,1,1,4,4,4,4,4,4,4,4,4,12,12,12,12,9,9,9,12,1
1,1,1,1,1,1,1,1,1,1,4,4,4,4,4,4,4,4,12,12,12,12,9,9,9,9,1
1,1,1,1,1,1,1,1,1,1,8,4,4,4,4,4,4,4,4,4,4,4,9,9,9,9,1
1,1,1,1,1,1,1,1,1,1,1,1,1,1,1,1,1,1,1,1,1,1,1,1,1,1,1
endlayer

layer
1,1,1,1,1,1,1,1,1,1,1,1,1,1,1,1,1,1,1,1,1,1,1,1,1,1,1
1,1,4,4,4,4,2,2,2,2,3,3,3,3,3,3,2,2,2,2,2,2,2,2,2,1,1
1,1,4,4,4,2,2,2,2,2,3,3,3,3,3,2,2,2,2,2,2,2,2,2,2,1,1
1,1,6,4,4,2,2,2,2,3,3,5,5,2,2,2,2,2,2,2,2,2,2,2,2,4,1
1,1,6,6,6,4,2,2,2,2,2,2,5,2,2,2,2,2,4,4,4,4,2,2,2,2,1
1,1,6,6,4,4,4,4,4,2,2,2,2,2,2,2,2,2,4,4,4,4,4,4,4,4,1
1,1,4,4,4,4,4,4,4,2,2,2,2,2,2,2,2,2,4,4,4,4,4,4,4,4,1
1,1,4,4,4,4,4,4,4,2,2,2,2,2,2,4,4,4,4,4,4,4,4,4,4,4,1
1,1,4,4,4,4,4,4,4,2,2,2,2,1,1,1,4,4,4,4,4,4,4,4,4,4,1
1,1,4,4,4,4,4,4,4,4,4,4,4,1,1,1,1,1,4,4,4,4,4,4,4,4,1
1,1,4,4,4,4,7,4,4,4,1,1,13,1,1,1,1,1,1,4,4,4,1,1,1,1,1
1,1,4,4,4,4,1,1,1,4,1,1,13,10,10,13,1,1,1,1,1,1,1,1,10,1,1
1,1,4,4,4,4,1,1,1,1,1,1,10,10,1,10,10,10,1,1,10,10,1,1,1,1,1
1,1,4,4,4,4,1,1,1,10,1,10,10,10,10,10,10,10,10,1,10,10,1,1,1,1,1
1,1,4,4,8,8,1,1,10,10,10,10,10,10,10,10,10,10,10,1,1,1,1,1,1,1,1
1,1,4,8,8,8,1,10,10,10,10,10,10,10,10,14,10,14,14,14,14,1,1,1,1,1,1
1,1,8,8,8,8,1,10,10,10,10,10,10,14,14,14,14,14,14,14,14,1,1,1,1,1,1
1,1,8,8,8,8,10,10,10,1,10,10,14,14,14,14,14,14,14,14,14,1,1,1,1,1,1
1,1,8,8,1,1,10,10,14,14,14,14,14,14,14,14,14,14,14,14,14,1,1,1,1,1,1
1,1,1,1,1,1,10,10,14,14,14,14,14,14,14,14,14,14,14,14,14,1,1,1,1,1,1
1,1,1,1,1,14,14,14,14,14,14,14,14,14,14,14,14,14,14,14,14,1,1,1,1,1,1
1,1,1,1,14,14,14,14,14,14,14,14,14,14,14,14,14,14,14,14,14,1,1,1,1,1,1
1,1,1,14,14,14,14,14,14,14,14,14,14,14,14,14,14,14,14,14,14,1,1,1,1,1,1
1,1,1,14,14,14,14,14,14,14,14,14,14,14,14,14,14,14,14,14,14,1,1,1,1,1,1
1,1,1,14,14,14,14,14,14,14,14,14,14,14,14,14,14,14,14,14,14,1,1,1,1,1,1
1,1,1,14,14,14,14,14,14,14,14,10,10,10,14,14,14,14,14,14,14,1,1,1,1,1,1
1,1,1,14,14,14,14,14,14,14,14,14,10,10,14,14,14,14,14,14,14,1,1,1,1,1,1
1,1,1,14,14,14,14,14,14,14,14,14,10,10,14,14,14,14,14,14,14,1,1,1,1,1,1
1,1,1,14,14,14,14,14,14,14,14,14,14,10,14,14,14,14,14,14,14,1,0,1,1,1,1
1,1,1,14,14,14,14,14,14,14,14,14,14,14,14,14,14,14,14,14,14,10,1,1,1,1,1
1,1,1,14,14,14,14,14,14,14,14,14,14,14,14,14,14,14,14,14,14,10,1,1,1,1,1
1,1,1,14,14,14,14,14,14,14,14,14,14,14,14,14,14,14,14,14,14,10,1,1,1,1,1
1,1,1,14,14,14,14,14,14,14,14,14,14,14,14,14,14,14,14,14,14,10,1,1,1,9,1
1,1,1,14,14,14,14,14,14,14,14,14,14,14,14,14,14,14,14,14,14,10,1,1,1,14,1
1,1,1,14,14,14,14,14,14,14,14,14,14,14,14,14,14,14,14,14,14,10,1,1,1,1,1
1,1,1,14,14,14,14,14,14,14,14,14,14,14,14,14,14,14,14,14,14,10,1,10,1,1,1
1,1,1,14,14,14,14,14,14,14,14,14,14,14,14,14,14,14,14,14,14,10,1,1,4,4,1
1,1,1,14,14,14,14,14,14,14,14,14,14,14,14,14,14,14,10,10,10,10,1,1,1,4,1
1,1,1,14,14,14,14,14,14,14,14,14,14,14,14,14,14,10,10,10,1,1,4,4,4,4,1
1,1,1,14,14,14,14,14,14,14,14,14,14,14,14,14,14,10,10,10,1,1,4,4,4,4,1
1,1,1,14,14,14,14,14,14,14,14,14,14,14,14,14,14,10,10,10,1,1,4,4,4,4,1
1,1,1,14,14,14,14,14,14,14,14,14,14,14,14,14,14,14,10,10,1,1,4,4,4,4,1
1,1,1,14,14,14,14,14,14,14,1,1,1,10,10,1,14,14,1,9,9,9,4,4,4,4,1
1,1,1,14,14,14,14,14,14,14,1,1,13,4,4,4,4,4,9,9,9,9,4,4,4,4,1
1,1,1,14,14,14,14,14,14,14,1,4,4,4,4,4,4,4,4,9,9,9,9,4,4,4,1
1,1,1,1,1,1,1,0,1,1,1,4,4,4,4,4,4,4,4,4,9,9,4,4,4,4,1
1,1,1,1,1,1,1,1,1,1,1,4,4,4,4,4,4,4,4,4,4,4,4,4,4,4,1
1,1,1,1,1,1,1,1,1,1,1,4,4,11,4,4,4,4,4,4,4,4,4,4,4,4,1
1,1,1,1,1,1,1,1,1,1,4,4,4,4,4,4,4,4,4,4,4,4,4,4,4,4,1
1,1,1,1,1,1,1,1,1,1,4,4,4,4,4,4,4,4,4,4,4,4,4,4,4,4,1
1,1,1,1,1,1,1,1,1,1,4,4,4,4,4,4,4,4,12,12,12,4,12,4,4,6,1
1,1,1,1,1,1,1,1,1,4,4,4,4,4,4,4,4,12,12,12,12,12,12,12,12,6,1
1,1,1,1,1,1,1,1,1,4,4,4,4,4,4,4,4,4,12,12,12,11,12,12,12,6,1
1,1,1,1,1,1,1,1,1,1,4,4,4,4,4,4,4,4,4,12,4,4,12,9,4,4,1
1,1,1,1,1,1,1,1,1,1,8,4,4,4,4,4,4,4,4,4,4,4,4,0,9,4,1
1,1,1,1,1,1,1,1,1,1,1,1,1,1,1,1,1,1,1,1,1,1,1,1,1,1,1
endlayer

layer
1,1,1,1,1,1,1,1,1,1,1,1,1,1,1,1,1,1,1,1,1,1,1,1,1,1,1
1,1,4,4,11,4,2,2,2,3,3,3,3,3,3,3,2,2,2,2,2,2,1,1,1,1,1
1,4,4,11,4,2,2,2,2,3,3,3,3,3,3,2,2,2,2,2,2,2,2,2,2,1,1
1,4,4,4,4,2,2,2,2,3,3,3,3,3,2,2,2,2,2,2,2,2,2,2,2,1,1
1,6,6,6,6,4,2,2,2,3,3,2,2,2,2,2,2,2,4,4,4,4,2,2,2,2,1
1,6,6,3,3,4,4,4,4,2,2,2,2,2,2,2,2,2,4,4,4,4,4,4,4,1,1
1,4,3,3,3,4,4,4,4,2,2,2,2,2,2,2,2,2,4,4,4,4,4,4,4,1,1
1,4,4,4,4,4,4,4,4,2,1,1,1,2,2,4,4,4,4,4,4,4,4,4,4,1,1
1,4,4,4,4,4,4,4,4,2,1,1,1,1,1,1,4,4,4,4,4,4,4,4,4,4,1
1,4,4,4,4,4,4,4,4,4,1,1,1,1,1,1,1,1,4,4,4,4,1,1,1,1,1
1,4,4,4,4,4,7,7,4,1,1,1,13,1,1,13,1,1,1,1,1,1,1,1,1,1,1
1,4,4,4,4,1,1,1,1,1,1,1,13,16,16,13,1,1,1,1,1,1,1,1,15,0,1
1,4,4,4,4,1,1,1,1,10,1,1,17,17,1,17,17,17,1,1,17,17,1,1,1,1,1
1,4,4,4,4,1,1,1,10,18,10,17,17,17,17,17,17,17,17,1,17,17,1,1,0,1,1
1,4,4,4,8,1,10,10,20,17,17,17,20,19,17,20,17,19,17,1,1,1,1,1,1,1,1
1,4,4,8,8,1,10,17,17,17,19,17,19,17,17,21,17,17,17,19,1,1,1,1,1,1,1
1,4,8,8,8,1,10,17,21,17,17,17,22,17,17,23,17,17,22,20,17,1,1,1,1,1,1
1,8,8,1,1,1,17,17,17,17,17,17,17,19,17,22,17,17,19,23,17,10,1,1,1,1,1
1,1,1,1,1,1,17,22,17,17,20,23,22,17,17,20,17,17,17,17,17,23,1,1,1,1,1
1,1,1,1,1,1,17,17,18,21,23,17,17,17,23,17,17,19,23,21,23,23,1,1,1,1,1
1,1,1,1,14,1,10,17,17,18,17,22,17,17,20,17,21,23,17,20,17,23,1,1,1,1,1
1,1,1,14,1,1,10,10,10,20,23,18,19,17,19,17,23,17,17,23,23,17,1,1,1,1,1
1,1,14,14,1,1,1,10,17,17,19,17,17,18,22,17,17,23,19,23,23,10,1,1,1,1,1
1,1,1,1,1,1,1,10,17,17,17,17,21,19,17,17,17,22,23,21,10,1,1,1,1,1,1
1,1,1,1,1,1,1,10,17,17,20,17,17,17,17,17,17,23,17,17,10,1,1,1,1,1,1
1,1,1,1,1,1,1,10,17,19,20,23,23,23,17,18,17,20,23,10,1,1,1,1,1,1,1
1,1,1,1,1,1,1,17,17,17,18,22,23,23,17,23,18,23,19,10,1,1,1,1,1,1,1
1,1,1,1,1,1,17,23,17,20,18,17,23,23,21,17,23,19,17,17,1,1,1,1,1,1,1
1,1,1,1,1,1,23,22,18,17,19,23,17,23,18,23,19,18,17,19,1,1,1,1,1,1,1
1,1,1,1,1,1,23,17,17,19,21,23,20,19,23,20,18,18,19,10,10,17,1,1,1,1,1
1,1,1,1,1,1,17,22,23,17,17,17,17,23,17,22,18,19,10,1,17,17,1,1,1,1,1
1,1,1,1,1,1,17,17,19,17,19,17,23,21,18,18,18,17,10,17,17,17,1,1,1,1,1
1,1,1,1,1,1,17,17,19,17,17,23,22,17,17,20,23,17,21,17,17,17,1,1,1,1,1
1,1,1,1,1,1,17,17,17,19,17,20,17,17,17,17,22,17,17,22,23,17,1,1,1,14,1
1,1,1,1,1,1,17,17,20,21,17,17,17,22,17,17,23,19,18,17,17,17,1,1,1,1,1
1,1,1,1,1,1,1,10,22,17,17,17,17,17,18,21,17,24,18,20,21,17,1,0,1,1,1
1,1,1,1,1,1,1,1,10,10,17,17,22,18,20,17,17,18,22,17,17,17,1,1,1,1,1
1,1,1,1,1,1,1,1,1,1,17,18,19,17,17,17,20,18,17,17,19,17,1,1,1,4,1
1,1,1,1,1,1,1,1,10,1,17,17,21,20,19,23,17,17,22,19,10,10,1,1,1,1,1
1,1,1,1,1,1,1,1,17,10,17,17,19,23,21,22,19,17,17,17,10,1,1,4,4,1,1
1,1,1,1,1,1,1,10,20,22,23,19,23,21,17,18,17,20,17,19,1,1,1,4,4,1,1
1,1,1,1,1,1,1,17,17,17,17,10,20,10,10,18,18,17,17,17,1,1,1,4,1,4,1
1,1,1,1,1,1,1,1,1,1,1,1,1,16,16,1,1,1,1,1,1,1,4,4,4,4,1
1,1,1,1,1,1,1,1,1,1,1,1,13,1,1,4,4,4,9,9,9,4,1,4,4,1,1
1,1,1,1,1,1,1,1,1,1,1,1,13,4,4,4,4,4,4,4,1,1,4,1,4,1,1
1,1,1,1,1,1,1,1,1,1,1,1,4,4,4,4,4,1,1,4,4,1,4,1,1,4,1
1,1,1,1,1,1,1,1,1,1,1,4,4,11,4,4,4,4,1,4,1,1,1,1,1,4,1
1,0,1,1,1,1,1,1,1,1,4,4,4,11,4,4,4,4,4,4,4,4,4,1,1,4,1
1,1,0,1,1,1,1,1,1,1,4,4,4,4,4,4,4,4,4,4,1,4,1,1,1,1,1
1,1,1,1,1,1,1,1,1,1,4,4,4,4,4,4,4,4,4,1,4,4,4,1,1,1,1
1,1,1,1,1,1,1,1,1,1,4,4,4,4,4,4,4,4,4,1,1,1,1,1,1,6,1
1,1,1,1,1,1,1,1,4,4,4,4,4,4,4,4,4,4,1,12,1,1,11,4,4,6,1
1,1,1,1,1,1,1,1,1,4,4,4,4,4,4,4,4,4,4,4,1,1,4,4,4,1,1
1,1,1,1,1,1,1,1,1,4,4,4,1,4,4,4,4,4,4,4,4,4,1,1,4,1,1
1,1,1,1,1,1,1,1,1,8,1,1,4,4,1,1,4,4,4,4,4,1,1,4,4,4,1
1,1,1,1,1,1,1,1,1,1,1,1,1,1,1,1,1,1,1,1,1,1,1,1,1,1,1
endlayer

layer
1,1,1,1,1,1,1,1,1,1,1,1,1,1,1,1,1,1,1,1,1,1,1,1,1,1,1
1,1,1,1,1,1,1,1,1,1,1,1,1,1,3,1,2,2,2,2,2,1,1,1,1,1,1
1,1,1,1,1,1,1,1,1,1,1,1,1,1,3,2,1,2,2,2,2,2,1,1,1,1,1
1,1,1,1,1,1,1,1,1,1,1,1,1,1,1,2,2,2,2,2,2,2,2,1,1,1,1
1,1,1,1,1,1,1,1,1,1,1,1,2,2,1,2,2,2,4,4,4,4,2,2,1,1,1
1,1,1,1,1,1,1,1,1,1,1,1,1,1,1,2,1,2,4,4,4,4,4,4,4,1,1
1,1,1,1,1,1,1,1,1,1,1,1,1,1,1,2,1,2,4,4,4,4,1,1,1,1,1
1,1,1,1,1,1,1,1,1,1,1,1,1,1,2,4,4,4,4,1,1,1,1,1,1,1,1
1,1,1,1,1,1,1,1,1,1,1,1,1,1,1,1,1,1,1,4,1,1,1,1,1,1,1
1,1,1,1,1,1,1,1,1,1,1,1,1,1,1,1,1,1,1,1,1,1,1,1,1,1,1
1,1,1,1,1,1,1,1,1,1,1,1,13,1,1,13,1,1,1,1,1,1,1,1,1,1,1
1,1,1,1,1,1,1,1,1,1,1,1,13,1,1,13,1,1,1,1,1,1,1,1,1,1,1
1,1,1,1,1,1,10,10,1,23,10,1,10,10,10,23,10,23,10,1,1,1,1,1,1,1,1
1,1,1,1,1,1,10,10,23,23,23,23,23,23,23,23,23,23,23,10,10,10,1,1,1,1,1
1,1,1,1,1,1,23,23,23,23,23,23,23,23,23,23,23,23,25,10,1,1,1,1,1,1,1
1,1,1,1,1,1,23,23,23,23,23,23,23,23,23,23,23,23,23,23,10,1,1,1,1,1,1
1,1,1,1,1,1,23,23,23,23,23,23,23,23,23,23,23,23,23,23,23,10,1,1,1,1,1
1,1,1,1,1,1,23,23,23,23,23,23,23,23,23,23,23,23,23,23,23,23,1,1,1,1,1
1,1,1,1,1,1,23,23,23,23,23,23,23,23,23,23,23,23,23,23,23,23,1,1,1,1,1
1,1,1,1,1,1,23,23,23,23,23,23,23,23,23,23,23,23,23,23,23,23,1,1,1,1,1
1,1,1,1,1,1,23,23,23,23,23,23,23,23,23,23,23,23,23,23,23,23,1,1,1,1,1
1,1,1,1,1,1,23,23,23,23,23,23,23,23,23,23,23,23,23,23,23,23,1,1,1,1,1
1,1,14,1,1,1,10,23,23,23,23,23,23,23,23,23,23,23,23,23,23,23,1,1,1,1,1
1,1,1,1,1,1,10,23,23,23,23,23,23,23,23,23,23,23,23,23,23,1,1,1,1,1,1
1,1,1,1,1,1,1,23,23,23,23,23,23,23,23,23,23,23,23,23,23,1,1,1,1,1,1
1,1,1,1,1,1,10,23,23,23,23,23,23,23,23,23,23,23,23,23,1,23,1,1,1,1,1
1,1,1,1,1,1,10,23,23,23,23,23,23,23,23,23,23,23,23,23,1,23,1,1,1,1,1
1,1,1,1,1,1,23,23,23,23,23,23,23,23,23,23,23,23,23,23,10,23,1,1,1,1,1
1,1,1,1,1,1,23,23,23,23,23,23,23,23,23,23,23,23,23,23,10,1,1,1,1,1,1
1,1,1,1,1,1,23,23,23,23,23,23,23,23,23,23,23,23,23,23,23,1,1,1,0,1,1
1,1,1,1,1,1,23,23,23,23,23,23,23,23,23,23,23,23,23,10,23,10,1,1,1,1,1
1,1,1,1,1,1,23,23,23,23,23,23,23,23,23,23,23,23,23,23,23,10,1,1,1,1,1
1,1,1,1,1,1,23,23,23,23,23,23,23,23,23,23,23,23,23,23,23,10,1,1,1,1,1
1,1,1,1,1,1,23,23,23,23,23,23,23,23,23,23,23,23,23,23,23,23,1,1,1,14,1
1,1,1,1,1,1,23,23,23,23,23,23,23,23,23,23,23,23,23,23,23,23,10,1,1,14,1
1,1,1,1,1,1,10,23,23,23,23,23,23,23,23,23,23,26,23,23,23,23,1,1,1,1,1
1,1,1,1,1,1,1,10,23,23,23,23,23,23,23,23,23,23,23,23,23,23,1,1,1,1,1
1,1,1,1,1,1,1,1,10,10,23,23,23,23,23,23,23,23,23,23,23,23,1,1,1,1,1
1,1,1,1,1,1,1,10,23,10,23,23,23,23,23,23,23,23,23,23,23,23,1,1,1,1,1
1,1,1,1,1,1,10,10,23,23,23,23,23,23,23,23,23,23,23,23,23,10,1,1,1,1,1
1,1,1,1,1,1,10,23,23,23,23,23,23,23,23,23,23,23,23,23,10,10,1,1,1,1,1
1,1,1,1,1,1,1,10,1,10,23,23,23,23,23,23,23,23,23,23,10,1,1,1,1,1,1
1,1,1,1,1,1,1,1,1,1,1,1,1,1,1,10,1,1,1,1,1,1,1,1,1,1,1
1,1,1,1,1,1,1,1,1,1,1,1,13,1,1,13,1,1,1,1,1,1,1,1,1,1,1
1,1,1,1,1,1,1,1,1,1,1,1,13,1,1,13,1,1,1,1,1,1,1,1,1,1,1
1,1,1,1,1,1,1,1,1,1,1,1,1,1,1,1,1,1,1,1,1,1,1,1,1,1,1
1,1,1,1,1,1,1,1,1,1,1,1,1,1,1,1,1,1,1,1,1,1,1,1,1,1,1
1,1,1,1,1,1,1,1,1,1,1,1,1,1,1,1,1,1,1,1,1,1,1,1,1,1,1
1,1,1,1,1,1,1,1,1,1,1,1,1,4,4,1,1,1,1,1,1,1,1,1,1,1,1
1,1,1,1,1,1,1,1,1,1,1,1,1,1,1,1,1,1,1,1,1,1,1,1,1,1,1
1,1,1,1,1,1,1,1,1,1,1,1,1,1,1,1,1,1,1,1,1,1,1,1,1,1,1
1,1,1,1,1,1,1,1,1,1,1,1,1,1,1,1,1,1,1,1,1,1,1,1,1,1,1
1,1,1,1,1,1,1,1,1,1,1,1,1,1,1,1,1,1,1,1,1,1,1,1,1,1,1
1,1,1,1,1,1,1,1,1,1,1,1,1,1,1,1,1,1,1,1,1,1,1,1,1,1,1
1,1,1,1,1,1,1,1,1,1,1,1,1,1,1,1,1,10,1,1,1,1,1,1,1,1,1
1,1,1,1,1,1,1,1,1,1,1,1,1,1,1,1,1,1,1,1,1,1,1,1,1,1,1
endlayer

layer
1,1,1,1,1,1,1,1,1,1,1,1,1,1,1,1,1,1,1,1,1,1,1,1,1,1,1
1,1,1,1,1,1,1,1,1,1,1,1,1,1,1,1,1,1,1,1,1,1,1,1,1,1,1
1,1,1,1,1,1,1,1,1,1,1,1,1,1,1,1,1,1,1,1,1,1,1,1,1,1,1
1,1,1,1,1,1,1,1,1,1,1,1,1,1,1,1,1,1,1,1,1,1,1,1,1,1,1
1,1,1,1,1,1,1,1,1,1,1,1,1,1,1,1,1,1,1,1,1,1,1,1,1,1,1
1,1,1,1,1,1,1,1,1,1,1,1,1,1,1,1,1,1,1,1,1,1,1,1,1,1,1
1,1,1,1,1,1,1,1,1,1,1,1,1,1,1,1,1,1,1,1,1,1,1,1,1,1,1
1,1,1,1,1,1,1,1,1,1,1,1,1,1,1,1,1,1,1,1,1,1,1,1,1,1,1
1,1,1,1,1,1,1,1,1,1,1,1,1,1,1,1,1,1,1,1,1,1,1,1,1,1,1
1,1,1,1,1,1,1,1,1,1,1,1,1,0,1,1,1,1,1,1,1,1,1,1,1,1,1
1,1,1,1,10,10,10,10,10,10,10,10,13,10,10,13,10,10,10,10,10,10,10,10,1,1,1
1,1,1,1,10,10,23,10,10,10,10,10,13,23,23,13,23,23,10,10,10,10,10,10,1,1,1
1,1,1,1,10,10,23,23,10,23,23,10,23,23,23,23,23,23,23,10,10,10,10,10,1,1,1
1,1,1,1,10,10,23,23,23,23,23,23,23,23,23,23,23,23,23,23,23,23,23,10,1,1,1
1,1,1,1,10,23,23,23,23,23,23,23,23,23,23,23,23,23,23,23,10,10,10,10,1,1,1
1,1,1,1,10,10,23,23,23,23,23,23,23,23,23,23,23,23,23,23,23,10,10,10,1,1,1
1,1,1,1,10,23,23,23,23,23,23,23,23,23,23,23,23,23,23,23,23,23,23,10,1,1,1
1,1,1,1,10,23,23,23,23,23,23,23,23,23,23,23,23,23,23,23,23,23,23,10,1,1,1
1,1,1,1,10,23,23,23,23,23,23,23,23,23,23,23,23,23,23,23,23,23,23,10,1,1,1
1,1,1,1,10,23,23,23,23,23,23,23,23,23,23,23,23,23,23,23,23,23,23,10,1,1,1
1,1,1,14,10,23,23,23,23,23,23,23,23,23,23,23,23,23,23,23,23,23,23,10,1,1,1
1,1,1,1,10,10,23,23,23,23,23,23,23,23,23,23,23,23,23,23,23,23,23,10,1,1,1
1,1,1,1,10,10,23,23,23,23,23,23,23,23,23,23,23,23,23,23,23,23,23,10,1,1,1
1,1,1,1,10,10,23,23,23,23,23,23,23,23,23,23,23,23,23,23,23,10,10,10,1,1,1
1,1,1,1,10,10,10,23,23,23,23,23,23,23,23,23,23,23,23,23,23,10,10,10,1,1,1
1,1,1,1,10,10,23,23,23,23,23,23,23,23,23,23,23,23,23,23,10,1,10,10,1,1,1
1,1,1,1,10,10,23,23,23,23,23,23,23,23,23,23,23,23,23,23,10,10,10,10,1,1,1
1,1,1,1,10,23,23,23,23,23,23,23,23,23,23,23,23,23,23,23,23,10,10,10,1,1,1
1,1,1,1,10,23,23,23,23,23,23,23,23,23,23,23,23,23,23,23,23,10,10,10,1,1,1
1,1,1,1,10,23,23,23,23,23,23,23,23,23,23,23,23,23,23,23,23,10,10,10,1,1,1
1,1,1,1,10,10,23,23,23,23,23,23,23,23,23,23,23,23,23,23,23,23,10,10,1,1,1
1,1,1,1,10,10,23,23,23,23,23,23,23,23,23,23,23,23,23,23,23,23,23,10,1,1,1
1,1,1,1,10,23,23,23,23,23,23,23,23,23,23,23,23,23,23,23,23,23,23,10,1,1,1
1,1,1,1,10,23,23,23,23,23,23,23,23,23,23,23,23,23,23,23,23,23,23,10,1,1,1
1,1,1,1,10,23,23,23,23,23,23,23,23,23,23,23,23,23,23,23,23,23,23,10,1,14,1
1,1,1,1,10,10,23,23,23,23,23,23,23,23,23,23,23,23,23,23,23,23,23,10,1,14,1
1,1,1,1,10,10,10,23,23,23,23,23,23,23,23,23,23,23,23,23,23,23,23,10,1,14,1
1,1,1,1,10,10,10,10,23,23,23,23,23,23,23,23,23,23,23,23,23,23,23,10,1,14,1
1,1,1,1,10,10,10,23,23,23,23,23,23,23,23,23,23,23,23,23,23,23,23,10,1,1,1
1,1,1,1,10,10,23,23,23,23,23,23,23,23,23,23,23,23,23,23,23,23,23,10,1,1,1
1,1,1,1,10,10,23,23,23,23,23,23,23,23,23,23,23,23,23,23,23,23,23,10,1,1,1
1,1,1,1,10,10,10,23,10,23,23,23,23,23,23,23,23,23,23,23,23,10,10,10,1,1,1
1,1,1,1,10,10,10,10,10,10,10,10,10,10,10,23,23,23,23,23,10,10,10,10,1,1,1
1,1,1,1,1,1,1,1,1,1,1,1,13,10,10,13,10,10,10,10,10,10,1,10,1,1,1
1,1,1,1,1,1,1,1,1,1,1,1,13,1,1,13,1,1,1,1,1,1,1,1,1,1,1
1,1,1,1,1,1,1,1,1,1,1,1,1,1,1,1,1,1,1,1,1,1,1,1,1,1,1
1,1,1,1,1,1,1,1,1,1,1,1,1,1,1,1,1,1,1,1,1,1,1,1,1,1,1
1,1,1,1,1,1,1,1,1,1,1,14,14,1,1,1,1,1,1,1,1,1,1,1,1,1,1
1,1,1,1,1,1,1,1,1,1,1,1,1,1,1,1,1,1,1,1,1,1,1,1,1,1,1
1,1,1,1,1,1,1,1,1,1,1,1,1,1,1,1,1,1,1,1,1,1,1,1,1,1,1
1,1,1,1,1,1,1,1,1,1,1,1,1,1,1,1,1,1,1,1,1,1,1,1,1,1,1
1,1,1,1,1,1,1,1,1,1,1,1,1,1,1,1,1,1,1,1,1,1,1,1,1,1,1
1,1,1,1,1,1,1,1,1,1,1,1,1,1,1,1,1,1,1,1,1,1,1,1,1,1,1
1,1,1,1,1,1,1,1,1,1,1,1,1,1,1,1,1,1,1,1,1,1,1,1,1,1,1
1,1,1,1,1,1,1,1,1,1,1,1,1,1,1,1,1,0,1,1,1,1,1,1,1,1,1
1,1,1,1,1,1,1,1,1,1,1,1,1,1,1,1,1,1,1,1,1,1,1,1,1,1,1
endlayer

layer
1,1,1,1,1,1,1,1,1,1,1,1,1,1,1,1,1,1,1,1,1,1,1,1,10,10,10
1,1,1,1,1,1,1,1,1,1,1,1,1,1,1,1,1,1,1,1,1,1,10,10,10,10,10
1,1,1,1,1,1,1,1,1,1,1,1,1,1,1,1,10,1,1,1,1,1,10,10,10,10,10
1,1,1,1,1,1,1,1,1,1,1,1,1,1,1,1,1,1,1,1,1,1,1,10,10,10,10
1,1,1,1,1,1,1,1,1,1,1,1,1,1,1,1,1,1,1,1,1,1,1,1,1,10,10
1,1,1,1,1,1,1,1,1,1,1,1,1,1,1,1,1,1,1,1,1,1,1,1,1,10,10
1,1,1,1,1,1,1,1,1,1,1,1,1,1,1,1,1,1,1,1,1,1,1,1,1,10,10
1,1,1,1,1,1,1,1,1,1,1,1,1,1,1,1,1,1,1,1,1,1,1,1,1,10,10
1,1,1,1,1,1,1,1,1,1,1,1,1,1,1,1,1,1,1,1,1,1,1,1,1,1,10
1,1,1,10,10,10,10,10,10,10,10,10,1,1,1,1,1,10,10,10,10,10,10,10,10,10,10
1,1,1,10,15,15,15,31,10,30,15,10,13,29,29,13,28,27,0,0,0,15,0,0,10,10,10
1,1,1,10,15,0,0,0,10,10,10,10,13,0,29,13,28,0,27,27,27,27,0,15,10,10,10
1,1,1,10,0,0,0,0,0,0,0,0,27,0,0,0,0,0,0,0,0,0,0,0,10,10,10
1,1,1,10,0,0,0,0,0,0,0,0,0,0,29,0,0,0,0,0,0,0,0,0,10,10,10
1,1,1,10,0,0,0,0,0,0,0,0,0,0,29,0,0,0,0,0,0,0,0,0,10,10,10
1,1,1,10,0,0,0,0,0,0,0,0,0,0,0,0,0,0,0,0,0,0,0,0,10,10,10
1,1,1,10,0,0,0,0,0,0,0,0,0,0,0,0,0,0,0,0,0,0,0,0,10,10,10
1,1,1,10,0,0,0,0,0,0,0,0,0,0,0,0,0,0,0,0,0,0,0,0,10,10,10
1,1,1,10,0,0,0,0,0,0,0,0,0,0,0,0,0,0,0,0,0,0,0,0,10,10,10
1,1,1,10,0,0,0,0,0,0,0,0,0,0,0,0,0,0,0,0,0,0,0,15,10,10,10
1,14,1,10,0,0,0,0,0,0,0,0,0,0,0,0,0,0,0,0,0,0,0,0,10,10,10
1,1,1,10,0,0,0,0,0,0,0,0,0,0,0,0,0,0,0,0,0,0,0,0,10,10,10
1,1,1,10,0,0,0,0,0,0,0,0,0,0,0,0,0,0,0,0,0,0,0,0,10,10,10
1,1,1,10,0,0,0,0,0,0,0,0,0,0,0,0,0,0,0,0,0,0,0,15,10,10,10
1,1,1,10,0,0,0,0,0,0,0,0,0,0,0,0,0,0,0,0,0,0,0,0,10,10,10
1,1,1,10,0,0,0,0,0,0,0,0,0,0,0,0,0,0,0,0,0,10,0,0,10,10,10
1,1,1,10,0,0,0,0,0,0,0,0,0,0,0,0,0,0,0,0,0,0,0,15,10,10,10
1,1,1,10,0,0,0,0,0,0,0,0,0,0,0,0,0,0,0,0,0,0,0,15,10,10,10
1,1,1,10,0,0,0,0,0,0,0,0,0,0,0,0,0,0,0,0,0,0,0,0,10,10,10
1,1,1,10,0,0,0,0,0,0,0,0,0,0,0,0,0,0,0,0,0,0,0,0,10,10,10
1,1,1,10,10,0,0,0,0,0,0,0,0,0,0,0,0,0,0,0,0,0,0,0,10,10,10
1,1,1,10,10,0,0,0,0,0,0,0,0,0,0,0,0,0,0,0,0,0,0,15,10,10,10
1,1,1,10,0,0,0,0,0,0,0,0,0,0,0,0,0,0,0,0,0,0,0,0,10,10,10
1,1,1,10,0,0,0,0,0,0,0,0,0,0,0,0,0,0,0,0,0,0,0,0,10,10,10
1,1,1,10,0,0,0,0,0,0,0,0,0,0,0,0,0,0,0,0,0,0,0,0,10,10,10
1,1,1,10,0,0,0,0,0,0,0,0,0,0,0,0,0,0,0,0,0,0,0,0,10,10,10
1,1,1,10,0,0,0,0,0,0,0,0,0,0,0,0,0,0,0,0,0,0,0,0,10,10,10
1,1,1,10,0,0,0,0,0,0,0,0,0,0,0,0,0,0,0,0,0,0,0,0,10,10,10
1,1,1,10,0,0,0,0,0,0,0,0,0,0,0,0,0,0,0,0,0,0,0,0,10,10,10
1,1,1,10,10,0,0,0,0,0,0,0,0,0,0,0,0,0,0,0,0,0,0,32,10,10,10
1,1,1,10,0,0,0,0,0,0,0,0,0,0,0,0,0,0,0,0,0,0,0,0,10,10,10
1,1,1,10,10,0,0,0,0,0,0,0,0,0,0,0,0,0,0,0,0,0,0,0,10,10,10
1,1,1,10,10,10,33,33,33,33,33,33,0,0,0,33,0,0,0,0,0,0,0,0,10,10,10
1,1,1,1,1,1,1,1,1,1,1,1,13,0,0,13,34,33,33,33,33,33,10,0,10,10,10
1,1,1,1,1,1,1,1,1,1,1,1,13,1,1,13,10,10,10,10,10,10,10,10,10,10,10
1,1,1,1,1,1,1,1,1,1,1,1,1,1,1,1,1,1,1,1,1,1,1,1,1,1,1
1,1,1,1,1,1,1,1,1,1,1,1,1,14,1,1,1,1,1,1,1,1,1,1,1,1,1
1,1,1,1,1,1,1,1,1,1,1,1,1,14,1,1,1,1,1,1,1,1,1,1,1,1,1
1,1,1,1,1,1,1,1,1,1,1,1,1,1,1,1,1,1,1,1,1,1,1,1,1,1,1
1,1,1,1,1,1,1,1,1,1,1,1,1,1,1,1,1,1,1,1,1,1,1,1,1,1,1
1,1,1,1,1,1,1,1,1,1,1,1,1,1,1,1,1,1,1,1,1,1,1,1,1,1,1
1,1,1,1,1,1,1,1,1,1,1,1,1,1,1,1,1,1,1,1,1,1,1,1,1,1,1
1,1,1,1,1,1,1,1,1,1,1,1,1,1,1,1,1,1,1,1,1,1,1,1,1,1,1
1,1,1,1,1,1,1,1,1,1,1,1,1,1,1,1,1,1,1,1,1,1,1,1,1,1,1
1,1,1,1,1,1,1,1,1,1,1,1,1,1,1,1,1,1,1,1,1,1,1,1,1,1,1
1,1,1,1,1,1,1,1,1,1,1,1,1,1,1,1,1,1,1,1,1,1,1,1,1,1,1
endlayer

layer
10,10,10,10,10,10,10,10,10,10,10,10,10,10,10,10,10,10,10,10,10,10,10,10,0,0,0
10,10,10,10,10,10,10,10,10,10,10,10,10,10,10,10,10,10,10,10,10,10,35,15,0,0,0
10,10,10,10,10,10,10,10,10,10,10,10,10,10,10,10,0,10,10,10,10,10,15,35,15,0,0
10,10,10,10,10,10,10,10,10,10,10,10,10,10,10,10,10,10,10,10,10,10,10,15,0,15,0
10,10,10,10,10,10,10,10,10,10,10,10,10,10,10,10,10,10,10,10,10,10,10,10,10,15,0
10,10,10,10,10,10,10,10,10,10,10,10,10,14,14,10,10,10,10,10,10,10,10,10,10,35,0
10,10,10,10,10,10,10,10,10,10,10,10,10,14,14,10,10,10,10,10,10,10,10,10,10,0,0
10,10,10,10,10,10,10,10,10,10,10,10,10,14,14,10,10,10,10,10,10,10,10,10,10,36,0
10,10,10,10,10,10,10,10,10,10,10,10,10,14,14,10,10,10,10,1,10,10,10,10,10,10,0
10,10,10,15,15,15,0,15,0,38,0,0,10,14,14,10,10,0,0,0,0,0,28,37,15,36,0
10,10,10,15,0,0,0,0,0,40,0,10,13,39,39,13,28,27,0,0,0,0,28,0,0,15,0
10,10,10,15,0,0,0,0,0,0,0,42,13,39,39,13,28,0,27,27,27,27,0,0,15,41,15
10,10,10,0,0,0,0,0,0,0,0,0,43,39,0,43,0,0,0,0,0,0,0,0,15,15,15
10,10,10,0,0,0,0,0,0,0,0,0,43,0,39,43,0,0,0,0,0,0,0,0,15,15,15
10,10,10,15,0,0,0,0,0,0,0,0,43,39,39,43,0,0,0,0,0,0,0,0,15,15,15
10,10,10,15,0,0,0,0,0,0,0,0,43,0,39,43,0,0,0,0,0,0,0,0,15,0,44
10,10,10,45,0,0,0,0,0,0,0,0,43,39,39,43,0,0,0,0,0,0,0,0,0,30,0
10,10,10,15,0,0,0,0,0,0,0,0,43,39,39,43,0,0,0,0,0,0,0,0,0,0,46
10,10,10,15,0,0,0,0,0,0,0,0,43,39,0,43,0,0,0,0,0,0,0,0,15,15,15
10,10,10,0,0,0,0,0,0,0,0,0,43,39,0,43,0,0,0,0,0,0,0,0,15,15,15
10,10,10,0,0,0,0,0,0,0,0,0,43,39,0,43,0,0,0,0,0,0,0,0,15,15,15
10,10,10,0,0,0,0,0,0,0,0,0,43,39,39,43,0,0,0,0,0,0,0,0,0,44,15
10,10,10,0,0,0,0,0,0,0,0,0,43,39,0,43,0,0,0,0,0,0,0,0,15,15,15
10,10,10,0,0,0,0,0,0,0,0,0,43,39,39,43,0,0,0,0,0,0,0,0,15,15,0
10,10,10,0,0,0,0,0,0,0,0,0,43,39,0,43,0,0,0,0,0,0,0,0,47,15,0
10,10,10,0,0,0,0,0,0,0,0,0,43,39,39,43,0,0,0,0,0,0,0,0,15,46,15
10,10,10,0,0,0,0,0,0,0,0,0,43,39,39,43,0,0,0,0,0,0,0,0,38,15,15
10,10,10,0,0,0,0,0,0,0,0,0,43,39,39,43,0,0,0,0,0,0,0,0,15,48,46
10,10,10,0,0,0,0,0,0,0,0,0,43,0,39,43,0,0,0,0,0,0,0,0,49,15,15
10,10,10,15,0,0,0,0,0,0,0,0,43,39,39,43,0,0,0,0,0,0,0,0,0,15,0
10,10,10,15,0,0,0,0,0,0,0,0,43,39,39,43,0,0,0,0,0,0,0,0,15,15,15
10,10,10,0,0,0,0,0,0,0,0,0,43,39,39,43,0,0,0,0,0,0,0,0,15,15,0
10,10,10,0,0,0,0,0,0,0,0,0,43,0,39,43,0,0,0,0,0,0,0,0,15,30,15
10,10,10,0,0,0,0,0,0,0,0,0,0,39,39,43,0,0,0,0,0,0,0,0,0,30,0
10,10,10,15,0,0,0,0,0,0,0,0,43,39,39,43,0,0,0,0,0,0,0,0,50,0,15
10,10,10,0,0,0,0,0,0,0,0,0,43,39,39,43,0,0,0,0,0,0,0,0,15,47,15
10,10,10,15,0,0,0,0,0,0,0,0,43,39,39,43,0,0,0,0,0,0,0,0,15,15,15
10,10,10,0,0,0,0,0,0,0,0,0,43,39,39,43,0,0,0,0,0,0,0,0,15,15,15
10,10,10,0,0,0,0,0,0,0,0,0,43,39,39,43,0,0,0,0,0,0,0,0,15,51,0
10,10,10,15,0,0,0,0,0,0,0,0,43,39,39,43,0,0,0,0,0,0,0,0,15,15,15
10,10,10,0,0,0,0,0,0,0,0,0,43,39,0,43,0,0,0,0,0,0,0,0,15,15,15
10,10,10,15,0,0,0,0,0,0,0,0,43,39,39,43,0,0,0,0,0,0,0,0,15,15,15
10,10,10,0,10,33,33,33,33,33,33,33,43,39,39,43,0,0,0,0,0,0,0,0,0,0,0
10,10,10,10,10,10,10,10,10,10,10,10,13,39,39,13,28,0,0,0,0,0,0,0,0,15,0
10,10,10,10,10,10,10,10,10,10,10,10,13,39,39,13,28,0,0,0,0,0,0,0,0,0,15
10,10,10,10,10,10,10,1,10,10,10,10,10,14,14,10,10,10,10,10,10,10,10,10,10,10,10
10,10,10,10,10,10,10,10,10,10,10,10,10,14,14,10,10,10,10,10,10,10,10,10,10,10,10
10,10,10,10,10,10,10,10,10,10,10,10,10,14,14,10,10,10,10,10,10,10,10,10,10,10,10
10,10,10,10,10,10,10,10,10,10,10,10,10,14,14,10,10,10,10,10,10,10,10,10,10,10,10
10,10,10,10,10,10,10,10,10,10,10,10,10,14,14,10,10,10,10,10,10,10,10,10,10,10,10
10,10,10,10,10,10,10,10,10,10,10,10,10,14,14,10,10,10,10,10,10,10,10,10,10,10,10
10,10,10,10,10,10,10,10,10,10,10,10,10,10,10,10,10,10,10,10,10,10,10,10,10,10,10
10,10,10,10,10,10,10,10,10,10,10,10,10,10,10,10,10,10,10,10,10,10,10,10,10,10,10
10,10,10,10,10,10,10,10,10,10,10,10,10,10,10,10,10,10,10,10,10,10,10,10,10,10,10
10,10,10,10,10,10,10,10,10,10,10,10,10,10,10,10,10,10,10,10,10,10,10,10,10,10,10
10,10,10,10,10,10,10,10,10,10,10,10,10,10,10,10,10,10,10,10,10,10,10,10,10,10,10
endlayer

layer
0,0,0,0,0,0,0,0,0,0,0,0,0,0,0,0,0,0,0,0,0,0,0,0,0,0,0
0,0,15,15,15,15,15,15,15,15,52,15,52,15,15,35,52,52,15,15,15,52,0,0,0,0,0
0,52,52,15,52,15,35,15,15,52,52,15,15,15,0,0,0,15,52,0,52,15,0,0,0,0,0
0,15,15,52,15,52,15,15,15,15,15,15,15,53,0,0,15,15,15,15,15,15,36,0,0,0,0
0,15,15,52,35,52,15,52,15,0,15,15,15,0,0,0,15,15,15,52,15,15,15,15,36,0,0
0,52,15,15,15,15,52,15,15,15,15,0,55,0,0,55,15,15,54,33,15,33,15,0,0,0,0
0,15,15,15,15,0,52,52,15,15,15,0,55,0,0,0,15,15,0,15,15,15,15,15,0,0,0
0,15,15,52,15,15,15,15,15,58,15,0,0,0,0,0,15,0,0,44,15,57,15,0,56,0,0
0,15,15,52,0,15,0,0,49,15,0,0,0,0,0,55,42,0,0,60,0,15,59,0,15,0,0
0,52,30,0,0,0,0,0,0,0,0,0,55,0,0,0,42,0,0,0,0,0,28,0,0,0,0
0,15,15,0,0,0,0,0,0,0,0,0,55,0,0,55,0,27,0,0,0,0,28,0,0,0,0
0,15,15,0,0,0,0,0,0,0,0,42,13,0,0,13,28,0,27,27,27,27,0,0,0,0,0
0,0,15,0,0,0,0,0,0,0,0,0,61,0,0,61,0,0,0,0,0,0,0,0,0,0,0
0,15,15,0,0,0,0,0,0,0,0,0,0,0,0,0,0,0,0,0,0,0,0,0,0,0,0
0,62,15,0,0,0,0,0,0,0,0,0,61,0,0,0,0,0,0,0,0,0,0,0,0,0,0
0,37,15,0,0,0,0,0,0,0,0,0,0,0,0,0,0,0,0,0,0,0,0,0,0,0,0
0,15,0,0,0,0,0,0,0,0,0,0,61,0,0,61,0,0,0,0,0,0,0,0,0,40,0
0,0,15,0,0,0,0,0,0,0,0,0,0,0,0,0,0,0,0,0,0,0,0,0,0,0,0
0,0,51,0,0,0,0,0,0,0,0,0,61,0,0,61,0,0,0,0,0,0,0,0,0,0,0
0,0,0,0,0,0,0,0,0,0,0,0,0,0,0,0,0,0,0,0,0,0,0,0,0,0,0
0,63,0,0,0,0,0,0,0,0,0,0,61,0,0,0,0,0,0,0,0,0,0,0,0,0,0
0,15,15,0,0,0,0,0,0,0,0,0,0,0,0,0,0,0,0,0,0,0,0,0,0,0,0
0,15,15,0,0,0,0,0,0,0,0,0,61,0,0,61,0,0,0,0,0,0,0,0,0,0,0
15,15,15,0,0,0,0,0,0,0,0,0,0,0,0,0,0,0,0,0,0,0,0,0,0,0,0
0,38,0,0,0,0,0,0,0,0,0,0,61,0,0,61,0,0,0,0,0,0,0,0,0,0,0
0,0,0,0,0,0,0,0,0,0,0,0,0,0,0,0,0,0,0,0,0,0,0,0,0,0,0
0,0,0,0,0,0,0,0,0,0,0,0,0,0,0,61,0,0,0,0,0,0,0,0,0,0,0
0,0,0,0,0,0,0,0,0,0,0,0,0,0,0,0,0,0,0,0,0,0,0,0,0,0,0
0,0,15,0,0,0,0,0,0,0,0,0,0,0,0,61,0,0,0,0,0,0,0,0,0,0,0
0,15,15,0,0,0,0,0,0,0,0,0,0,0,0,0,0,0,0,0,0,0,0,0,0,0,0
0,15,15,0,0,0,0,0,0,0,0,0,0,0,0,61,0,0,0,0,0,0,0,0,0,0,0
0,15,0,0,0,0,0,0,0,0,0,0,0,0,0,0,0,0,0,0,0,0,0,0,0,0,0
0,15,0,0,0,0,0,0,0,0,0,0,0,0,0,61,0,0,0,0,0,0,0,0,0,40,0
0,15,15,0,0,0,0,0,0,0,0,0,0,0,0,0,0,0,0,0,0,0,0,0,0,40,0
0,15,15,0,0,0,0,0,0,0,0,0,61,0,0,61,0,0,0,0,0,0,0,0,0,0,0
0,15,15,0,0,0,0,0,0,0,0,0,0,0,0,0,0,0,0,0,0,0,0,0,0,0,0
0,15,15,0,0,0,0,0,0,0,0,0,61,0,0,61,0,0,0,0,0,0,0,0,0,0,0
0,15,15,0,0,0,0,0,0,0,0,0,0,0,0,0,0,0,0,0,0,0,0,0,0,0,0
0,0,31,0,0,0,0,0,0,0,0,0,61,0,0,0,0,0,0,0,0,0,0,0,0,0,0
0,15,15,0,0,0,0,0,0,0,0,0,0,0,0,0,0,0,0,0,0,0,0,0,0,0,0
0,15,15,0,0,0,0,0,0,0,0,0,61,0,0,61,0,0,0,0,0,0,0,0,0,0,0
0,0,15,0,0,0,0,0,0,0,0,0,0,0,0,0,0,0,0,0,0,0,0,0,0,0,0
0,0,15,0,0,0,33,33,33,33,0,0,61,0,0,61,0,0,0,0,0,0,0,0,0,0,0
0,0,30,64,0,33,0,0,0,0,28,42,13,0,0,13,28,0,0,0,0,0,0,0,0,0,0
0,0,15,0,15,0,0,0,0,0,28,0,55,0,0,55,0,0,0,0,0,0,0,0,0,0,0
0,15,15,15,15,15,15,60,0,66,15,56,0,0,0,55,15,0,65,15,15,15,0,30,15,15,0
0,15,15,15,15,15,54,15,15,15,15,15,55,0,0,0,0,15,0,15,54,15,15,15,15,36,15
0,15,15,15,15,15,15,0,0,0,28,15,0,0,0,0,0,0,67,15,54,15,0,15,15,15,0
0,15,15,15,31,27,27,27,27,63,0,15,55,0,0,0,68,0,15,52,0,15,0,36,15,67,15
0,0,0,0,0,0,0,15,15,15,49,0,55,0,0,55,15,0,67,15,15,15,0,15,15,15,0
15,49,0,69,54,0,15,15,15,15,15,15,55,0,0,55,15,0,36,15,15,15,15,36,67,15,0
0,15,15,15,15,0,0,15,15,65,15,15,15,15,0,0,0,59,0,15,54,15,15,36,15,15,0
0,15,15,30,15,15,15,15,15,0,0,15,36,15,70,52,67,52,70,15,15,15,15,15,15,15,0
0,15,15,15,15,0,15,15,0,15,0,15,15,52,15,36,54,54,15,67,52,15,67,15,15,0,0
0,0,15,0,0,15,15,15,0,0,0,15,36,15,15,36,71,0,52,15,35,15,15,15,0,15,0
0,0,0,0,0,15,15,15,0,0,0,0,0,0,0,0,0,0,0,0,0,0,0,0,0,0,0
endlayer

layer
0,0,0,0,0,0,0,0,0,0,0,0,0,0,0,0,0,0,0,0,0,0,0,0,0,0,0
0,0,0,0,0,0,0,0,0,0,0,0,0,0,0,0,0,0,0,0,0,0,0,0,0,0,0
0,0,0,0,0,0,0,0,0,0,0,0,0,0,0,0,0,0,0,0,0,0,0,0,0,0,0
0,0,0,0,0,0,0,0,0,0,0,0,0,0,0,0,0,0,0,0,0,0,0,0,0,0,0
0,0,0,0,0,0,0,0,0,0,0,0,0,0,0,0,0,0,0,0,0,0,0,0,0,0,0
0,0,0,0,0,0,0,0,0,0,0,0,0,0,0,0,0,33,33,33,33,33,0,0,0,0,0
0,0,0,0,0,0,0,0,0,0,0,0,0,0,0,0,42,0,0,0,0,0,28,0,0,0,0
0,0,0,0,0,0,0,0,0,0,0,0,0,0,0,0,42,0,0,0,0,0,28,0,0,0,0
0,0,0,0,0,0,0,0,0,0,0,0,0,0,0,0,42,0,0,60,0,0,28,0,0,0,0
0,0,40,0,0,0,0,0,0,0,0,0,0,0,0,0,42,0,0,0,0,0,28,0,0,0,0
0,0,0,0,0,0,0,0,0,0,0,0,33,33,0,33,0,27,0,0,0,0,28,0,0,0,0
0,0,0,0,0,0,0,0,0,0,0,42,13,0,0,13,28,0,27,27,27,27,0,0,0,0,0
0,0,0,0,0,0,0,0,0,0,0,0,61,0,27,61,0,0,0,0,0,0,0,0,0,0,0
0,0,0,0,0,0,0,0,0,0,0,0,0,0,0,0,0,0,0,0,0,0,0,0,0,0,0
0,0,0,0,0,0,0,0,0,0,0,0,61,0,0,0,0,0,0,0,0,0,0,0,0,0,0
0,0,0,0,0,0,0,0,0,0,0,0,0,0,0,0,0,0,0,0,0,0,0,0,0,0,0
0,0,0,0,0,0,0,0,0,0,0,0,61,0,0,61,0,0,0,0,0,0,0,0,0,0,0
0,0,0,0,0,0,0,0,0,0,0,0,0,0,0,0,0,0,0,0,0,0,0,0,0,0,0
0,0,0,0,0,0,0,0,0,0,0,0,61,0,0,61,0,0,0,0,0,0,0,0,0,0,0
0,0,0,0,0,0,0,0,0,0,0,0,0,0,0,0,0,0,0,0,0,0,0,0,0,0,0
0,0,0,0,0,0,0,0,0,0,0,0,43,0,0,43,0,0,0,0,0,0,0,0,0,0,0
0,0,0,0,0,0,0,0,0,0,0,0,43,0,0,43,0,0,0,0,0,0,0,0,0,0,0
0,0,0,0,0,0,0,0,0,0,0,0,43,0,0,43,0,0,0,0,0,0,0,0,0,0,0
0,0,0,0,0,0,0,0,0,0,0,0,43,0,0,43,0,0,0,0,0,0,0,0,0,0,0
0,0,0,0,0,0,0,0,0,0,0,0,43,0,0,43,0,0,0,0,0,0,0,0,0,0,0
0,0,0,0,0,0,0,0,0,0,0,0,43,0,0,43,0,0,0,0,0,0,0,0,0,0,0
0,0,0,0,0,0,0,0,0,0,0,0,0,0,0,43,0,0,0,0,0,0,0,0,0,0,0
0,0,0,0,0,0,0,0,0,0,0,0,0,0,0,43,0,0,0,0,0,0,0,0,0,0,0
0,0,0,0,0,0,0,0,0,0,0,0,0,0,0,0,0,0,0,0,0,0,0,0,0,0,0
0,0,0,0,0,0,0,0,0,0,0,0,0,0,0,43,0,0,0,0,0,0,0,0,0,0,0
0,0,0,0,0,0,0,0,0,0,0,0,0,0,0,43,0,0,0,0,0,0,0,0,0,0,0
0,0,0,0,0,0,0,0,0,0,0,0,0,0,0,43,0,0,0,0,0,0,0,0,0,0,0
0,0,0,0,0,0,0,0,0,0,0,0,0,0,0,43,0,0,0,0,0,0,0,0,0,0,0
0,0,0,0,0,0,0,0,0,0,0,0,43,0,0,43,0,0,0,0,0,0,0,0,0,0,0
0,0,0,0,0,0,0,0,0,0,0,0,43,0,0,43,0,0,0,0,0,0,0,0,0,0,0
0,0,0,0,0,0,0,0,0,0,0,0,0,0,0,0,0,0,0,0,0,0,0,0,0,0,0
0,0,0,0,0,0,0,0,0,0,0,0,61,0,0,61,0,0,0,0,0,0,0,0,0,0,0
0,0,0,0,0,0,0,0,0,0,0,0,0,0,0,0,0,0,0,0,0,0,0,0,0,0,0
0,0,0,0,0,0,0,0,0,0,0,0,61,0,0,0,0,0,0,0,0,0,0,0,0,0,0
0,0,0,0,0,0,0,0,0,0,0,0,0,0,0,0,0,0,0,0,0,0,0,0,0,0,0
0,0,0,0,0,0,0,0,0,0,0,0,61,0,0,61,0,0,0,0,0,0,0,0,0,0,0
0,0,0,0,0,0,0,0,0,0,0,0,0,0,0,0,0,0,0,0,0,0,0,0,0,0,0
0,0,0,0,0,0,33,33,33,33,0,0,61,0,0,61,0,0,0,0,0,0,0,0,0,0,0
0,0,40,0,0,33,0,0,0,0,28,42,13,0,0,13,28,0,0,0,0,0,0,0,0,0,0
0,0,0,0,42,0,0,0,0,0,28,0,27,27,27,27,0,0,0,0,0,0,0,0,0,0,0
0,0,0,0,42,0,0,60,0,0,28,0,0,0,0,0,0,0,0,0,0,0,0,40,0,0,0
0,0,0,0,42,0,0,0,0,0,28,0,0,0,0,0,0,0,0,0,0,0,0,0,0,0,0
0,0,0,0,42,0,0,0,0,0,28,0,0,0,0,0,0,0,0,0,0,0,0,0,0,0,0
0,0,0,0,0,27,27,27,27,27,0,0,0,0,0,0,0,0,0,0,0,0,0,0,0,0,0
0,0,0,0,0,0,0,0,0,0,0,0,0,0,0,0,0,0,0,0,0,0,0,0,0,0,0
0,0,0,0,0,0,0,0,0,0,0,0,0,0,0,0,0,0,0,0,0,0,0,0,0,0,0
0,0,0,0,0,0,0,0,0,0,0,0,0,0,0,0,0,0,0,0,0,0,0,0,0,0,0
0,0,0,40,0,0,0,0,0,0,0,0,0,0,0,0,0,0,0,0,0,0,0,0,0,0,0
0,0,0,0,0,0,0,0,0,0,0,0,0,0,0,0,0,0,0,0,0,0,0,0,0,0,0
0,0,0,0,0,0,0,0,0,0,0,0,0,0,0,0,0,0,0,0,0,0,0,0,0,0,0
0,0,0,0,0,0,0,0,0,0,0,0,0,0,0,0,0,0,0,0,0,0,0,0,0,0,0
endlayer

layer
0,0,0,0,0,0,0,0,0,0,0,0,0,0,0,0,0,0,0,0,0,0,0,0,0,0,0
0,0,0,0,0,0,0,0,0,0,0,0,0,0,0,0,0,0,0,0,0,0,0,0,0,0,0
0,0,0,0,0,0,0,0,0,0,0,0,0,0,0,0,0,0,0,0,0,0,0,0,0,0,0
0,0,0,0,0,0,0,0,0,0,0,0,0,0,0,0,0,0,0,0,0,0,0,0,0,0,0
0,0,0,0,0,0,0,0,0,0,0,0,0,0,0,0,0,0,0,0,0,0,0,0,0,0,0
0,0,0,0,0,0,0,0,0,0,0,0,0,0,0,0,0,33,33,33,33,33,0,0,0,0,0
0,0,0,0,0,0,0,0,0,0,0,0,0,0,0,0,42,72,72,72,72,72,28,0,0,0,0
0,0,0,0,0,0,0,0,0,0,0,0,0,0,0,0,42,72,72,72,72,72,28,0,0,0,0
0,0,0,0,0,0,0,0,0,0,0,0,0,0,0,0,42,72,72,60,72,72,28,0,0,0,0
0,0,0,0,0,0,0,0,0,0,0,0,0,0,0,0,42,72,72,72,72,72,28,0,0,0,0
0,0,0,0,0,0,0,0,0,0,0,0,33,33,33,33,0,27,72,72,72,72,28,0,0,0,0
0,0,0,0,0,0,0,0,0,0,0,42,13,0,0,13,28,0,27,27,27,27,0,0,0,0,0
0,0,0,0,0,0,0,0,0,0,0,0,61,0,27,61,0,0,0,0,0,0,0,0,0,0,0
0,0,0,0,0,0,0,0,0,0,0,0,0,0,0,0,0,0,0,0,0,0,0,0,0,0,0
0,0,0,0,0,0,0,0,0,0,0,0,61,0,0,61,0,0,0,0,0,0,0,0,0,0,0
0,0,0,0,0,0,0,0,0,0,0,0,0,0,0,0,0,0,0,0,0,0,0,0,0,0,0
0,0,0,0,0,0,0,0,0,0,0,0,61,0,0,61,0,0,0,0,0,0,0,0,0,0,0
0,0,0,0,0,0,0,0,0,0,0,0,0,0,0,0,0,0,0,0,0,0,0,0,0,0,0
0,0,0,0,0,0,0,0,0,0,0,0,43,0,0,43,0,0,0,0,0,0,0,0,0,0,0
0,0,0,0,0,0,0,0,0,0,0,0,43,0,0,43,0,0,0,0,0,0,0,0,0,0,0
0,0,0,0,0,0,0,0,0,0,0,0,43,0,0,43,0,0,0,0,0,0,0,0,0,0,0
0,0,0,0,0,0,0,0,0,0,0,0,0,0,0,0,0,0,0,0,0,0,0,0,0,0,0
0,0,0,0,0,0,0,0,0,0,0,0,0,0,0,0,0,0,0,0,0,0,0,0,0,0,0
0,0,0,0,0,0,0,0,0,0,0,0,0,0,0,0,0,0,0,0,0,0,0,0,0,0,0
0,0,0,0,0,0,0,0,0,0,0,0,0,0,0,0,0,0,0,0,0,0,0,0,0,0,0
0,0,0,0,0,0,0,0,0,0,0,0,0,0,0,0,0,0,0,0,0,0,0,0,0,0,0
0,0,0,0,0,0,0,0,0,0,0,0,0,0,0,0,0,0,0,0,0,0,0,0,0,0,0
0,0,0,0,0,0,0,0,0,0,0,0,0,0,0,0,0,0,0,0,0,0,0,0,0,0,0
0,0,0,0,0,0,0,0,0,0,0,0,0,0,0,0,0,0,0,0,0,0,0,0,0,0,0
0,0,0,0,0,0,0,0,0,0,0,0,0,0,0,0,0,0,0,0,0,0,0,0,0,0,0
0,0,0,0,0,0,0,0,0,0,0,0,0,0,0,0,0,0,0,0,0,0,0,0,0,0,0
0,0,0,0,0,0,0,0,0,0,0,0,0,0,0,0,0,0,0,0,0,0,0,0,0,0,0
0,0,0,0,0,0,0,0,0,0,0,0,0,0,0,0,0,0,0,0,0,0,0,0,0,0,0
0,0,0,0,0,0,0,0,0,0,0,0,0,0,0,0,0,0,0,0,0,0,0,0,0,0,0
0,0,0,0,0,0,0,0,0,0,0,0,43,0,0,43,0,0,0,0,0,0,0,0,0,0,0
0,0,0,0,0,0,0,0,0,0,0,0,43,0,0,43,0,0,0,0,0,0,0,0,0,0,0
0,0,0,0,0,0,0,0,0,0,0,0,43,0,0,43,0,0,0,0,0,0,0,0,0,0,0
0,0,0,0,0,0,0,0,0,0,0,0,0,0,0,0,0,0,0,0,0,0,0,0,0,0,0
0,0,0,0,0,0,0,0,0,0,0,0,61,0,0,61,0,0,0,0,0,0,0,0,0,0,0
0,0,0,0,0,0,0,0,0,0,0,0,0,0,0,0,0,0,0,0,0,0,0,0,0,0,0
0,0,0,0,0,0,0,0,0,0,0,0,61,0,0,61,0,0,0,0,0,0,0,0,0,0,0
0,0,0,0,0,0,0,0,0,0,0,0,0,0,0,0,0,0,0,0,0,0,0,0,0,0,0
0,0,0,0,0,0,33,33,33,33,0,0,61,0,33,61,0,0,0,0,0,0,0,0,0,0,0
0,0,0,0,0,33,73,72,72,72,28,42,13,0,0,13,28,0,0,0,0,0,0,0,0,0,0
0,0,0,0,42,72,72,72,72,72,28,0,27,27,27,27,0,0,0,0,0,0,0,0,0,0,0
0,0,0,0,42,72,72,60,72,72,28,0,0,0,0,0,0,0,0,0,0,0,0,0,0,0,0
0,0,0,0,42,72,72,72,72,72,28,0,0,0,0,0,0,0,0,0,0,0,0,0,0,0,0
0,0,0,0,42,72,72,72,72,72,28,0,0,0,0,0,0,0,0,0,0,0,0,0,0,0,0
0,0,0,0,0,27,27,27,27,27,0,0,0,0,0,0,0,0,0,0,0,0,0,0,0,0,0
0,0,0,0,0,0,0,0,0,0,0,0,0,0,0,0,0,0,0,0,0,0,0,0,0,0,0
0,0,0,0,0,0,0,0,0,0,0,0,0,0,0,0,0,0,0,0,0,0,0,0,0,0,0
0,0,0,0,0,0,0,0,0,0,0,0,0,0,0,0,0,0,0,0,0,0,0,0,0,0,0
0,0,0,0,0,0,0,0,0,0,0,0,0,0,0,0,0,0,0,0,0,0,0,0,0,0,0
0,0,0,0,0,0,0,0,0,0,0,0,0,0,0,0,0,0,0,0,0,0,0,0,0,0,0
0,0,0,0,0,0,0,0,0,0,0,0,0,0,0,0,0,0,0,0,0,0,0,0,0,0,0
0,0,0,0,0,0,0,0,0,0,0,0,0,0,0,0,0,0,0,0,0,0,0,0,0,0,0
endlayer

layer
0,0,0,0,0,0,0,0,0,0,0,0,0,0,0,0,0,0,0,0,0,0,0,0,0,0,0
0,0,0,0,0,0,0,0,0,0,0,0,0,0,0,0,0,0,0,0,0,0,0,0,0,0,0
0,0,0,0,0,0,0,0,0,0,0,0,0,0,0,0,0,0,0,0,0,0,0,0,0,0,0
0,0,0,0,0,0,0,0,0,0,0,0,0,0,0,0,0,0,0,0,0,0,0,0,0,0,0
0,0,0,0,0,0,0,0,0,0,0,0,0,0,0,0,0,0,0,0,0,0,0,0,0,0,0
0,0,0,0,0,0,0,0,0,0,0,0,0,0,0,0,0,33,33,33,33,0,0,0,0,0,0
0,0,0,0,0,0,0,0,0,0,0,0,0,0,0,0,42,72,72,72,72,33,0,0,0,0,0
0,0,0,0,0,0,0,0,0,0,0,0,0,0,0,0,42,72,72,72,72,72,28,0,0,0,0
0,0,0,0,0,0,0,0,0,0,0,0,0,0,0,0,42,72,72,60,72,72,28,0,0,0,0
0,0,0,0,0,0,0,0,0,0,0,0,0,0,0,0,42,72,72,72,72,72,28,0,0,0,0
0,0,0,0,0,0,0,0,0,0,0,0,33,33,33,33,0,27,72,72,72,72,28,0,0,0,0
0,0,0,0,0,0,0,0,0,0,0,42,13,0,0,13,28,0,27,27,27,27,0,0,0,0,0
0,0,0,0,0,0,0,0,0,0,0,0,61,27,27,61,0,0,0,0,0,0,0,0,0,0,0
0,0,0,0,0,0,0,0,0,0,0,0,0,0,0,0,0,0,0,0,0,0,0,0,0,0,0
0,0,0,0,0,0,0,0,0,0,0,0,61,0,0,61,0,0,0,0,0,0,0,0,0,0,0
0,0,0,0,0,0,0,0,0,0,0,0,0,0,0,0,0,0,0,0,0,0,0,0,0,0,0
0,0,0,0,0,0,0,0,0,0,0,0,61,0,0,61,0,0,0,0,0,0,0,0,0,0,0
0,0,0,0,0,0,0,0,0,0,0,0,0,0,0,0,0,0,0,0,0,0,0,0,0,0,0
0,0,0,0,0,0,0,0,0,0,0,0,43,0,0,43,0,0,0,0,0,0,0,0,0,0,0
0,0,0,0,0,0,0,0,0,0,0,0,0,0,0,0,0,0,0,0,0,0,0,0,0,0,0
0,0,0,0,0,0,0,0,0,0,0,0,0,0,0,0,0,0,0,0,0,0,0,0,0,0,0
0,0,0,0,0,0,0,0,0,0,0,0,0,0,0,0,0,0,0,0,0,0,0,0,0,0,0
0,0,0,0,0,0,0,0,0,0,0,0,0,0,0,0,0,0,0,0,0,0,0,0,0,0,0
0,0,0,0,0,0,0,0,0,0,0,0,0,0,0,0,0,0,0,0,0,0,0,0,0,0,0
0,0,0,0,0,0,0,0,0,0,0,0,0,0,0,0,0,0,0,0,0,0,0,0,0,0,0
0,0,0,0,0,0,0,0,0,0,0,0,0,0,0,0,0,0,0,0,0,0,0,0,0,0,0
0,0,0,0,0,0,0,0,0,0,0,0,0,0,0,0,0,0,0,0,0,0,0,0,0,0,0
0,0,0,0,0,0,0,0,0,0,0,0,0,0,0,0,0,0,0,0,0,0,0,0,0,0,0
0,0,0,0,0,0,0,0,0,0,0,0,0,0,0,0,0,0,0,0,0,0,0,0,0,0,0
0,0,0,0,0,0,0,0,0,0,0,0,0,0,0,0,0,0,0,0,0,0,0,0,0,0,0
0,0,0,0,0,0,0,0,0,0,0,0,0,0,0,0,0,0,0,0,0,0,0,0,0,0,0
0,0,0,0,0,0,0,0,0,0,0,0,0,0,0,0,0,0,0,0,0,0,0,0,0,0,0
0,0,0,0,0,0,0,0,0,0,0,0,0,0,0,0,0,0,0,0,0,0,0,0,0,0,0
0,0,0,0,0,0,0,0,0,0,0,0,0,0,0,0,0,0,0,0,0,0,0,0,0,0,0
0,0,0,0,0,0,0,0,0,0,0,0,0,0,0,0,0,0,0,0,0,0,0,0,0,0,0
0,0,0,0,0,0,0,0,0,0,0,0,0,0,0,0,0,0,0,0,0,0,0,0,0,0,0
0,0,0,0,0,0,0,0,0,0,0,0,43,0,0,43,0,0,0,0,0,0,0,0,0,0,0
0,0,0,0,0,0,0,0,0,0,0,0,0,0,0,0,0,0,0,0,0,0,0,0,0,0,0
0,0,0,0,0,0,0,0,0,0,0,0,61,0,0,61,0,0,0,0,0,0,0,0,0,0,0
0,0,0,0,0,0,0,0,0,0,0,0,0,0,0,0,0,0,0,0,0,0,0,0,0,0,0
0,0,0,0,0,0,0,0,0,0,0,0,61,0,0,61,0,0,0,0,0,0,0,0,0,0,0
0,0,0,0,0,0,0,0,0,0,0,0,0,0,0,0,0,0,0,0,0,0,0,0,0,0,0
0,0,0,0,0,0,33,33,33,33,0,0,61,0,33,61,0,0,0,0,0,0,0,0,0,0,0
0,0,0,0,0,33,72,72,72,72,28,42,13,0,0,13,28,0,0,0,0,0,0,0,0,0,0
0,0,0,0,42,72,72,72,72,72,28,0,27,27,27,27,0,0,0,0,0,0,0,0,0,0,0
0,0,0,0,42,72,72,60,72,72,28,0,0,0,0,0,0,0,0,0,0,0,0,0,0,0,0
0,0,0,0,42,72,72,72,72,72,28,0,0,0,0,0,0,0,0,0,0,0,0,0,0,0,0
0,0,0,0,42,72,72,72,72,72,28,0,0,0,0,0,0,0,0,0,0,0,0,0,0,0,0
0,0,0,0,0,27,27,27,27,27,0,0,0,0,0,0,0,0,0,0,0,0,0,0,0,0,0
0,0,0,0,0,0,0,0,0,0,0,0,0,0,0,0,0,0,0,0,0,0,0,0,0,0,0
0,0,0,0,0,0,0,0,0,0,0,0,0,0,0,0,0,0,0,0,0,0,0,0,0,0,0
0,0,0,0,0,0,0,0,0,0,0,0,0,0,0,0,0,0,0,0,0,0,0,0,0,0,0
0,0,0,0,0,0,0,0,0,0,0,0,0,0,0,0,0,0,0,0,0,0,0,0,0,0,0
0,0,0,0,0,0,0,0,0,0,0,0,0,0,0,0,0,0,0,0,0,0,0,0,0,0,0
0,0,0,0,0,0,0,0,0,0,0,0,0,0,0,0,0,0,0,0,0,0,0,0,0,0,0
0,0,0,0,0,0,0,0,0,0,0,0,0,0,0,0,0,0,0,0,0,0,0,0,0,0,0
endlayer

layer
0,0,0,0,0,0,0,0,0,0,0,0,0,0,0,0,0,0,0,0,0,0,0,0,0,0,0
0,0,0,0,0,0,0,0,0,0,0,0,0,0,0,0,0,0,0,0,0,0,0,0,0,0,0
0,0,0,0,0,0,0,0,0,0,0,0,0,0,0,0,0,0,0,0,0,0,0,0,0,0,0
0,0,0,0,0,0,0,0,0,0,0,0,0,0,0,0,0,0,0,0,0,0,0,0,0,0,0
0,0,0,0,0,0,0,0,0,0,0,0,0,0,0,0,0,0,0,0,0,0,0,0,0,0,0
0,0,0,0,0,0,0,0,0,0,0,0,0,0,0,0,0,0,0,0,0,0,0,0,0,0,0
0,0,0,0,0,0,0,0,0,0,0,0,0,0,0,0,0,0,0,33,0,0,0,0,0,0,0
0,0,0,0,0,0,0,0,0,0,0,0,0,0,0,0,0,0,33,72,0,0,0,0,0,0,0
0,0,0,0,0,0,0,0,0,0,0,0,0,0,0,0,0,42,72,60,72,0,0,0,0,0,0
0,0,0,0,0,0,0,0,0,0,0,0,0,0,0,0,0,0,42,72,0,0,0,0,0,0,0
0,0,0,0,0,0,0,0,0,0,0,0,33,33,33,33,0,0,0,27,0,0,0,0,0,0,0
0,0,0,0,0,0,0,0,0,0,0,42,13,74,74,13,28,0,0,0,0,0,0,0,0,0,0
0,0,0,0,0,0,0,0,0,0,0,0,43,27,27,43,0,0,0,0,0,0,0,0,0,0,0
0,0,0,0,0,0,0,0,0,0,0,0,43,0,0,43,0,0,0,0,0,0,0,0,0,0,0
0,0,0,0,0,0,0,0,0,0,0,0,43,0,0,43,0,0,0,0,0,0,0,0,0,0,0
0,0,0,0,0,0,0,0,0,0,0,0,43,0,0,43,0,0,0,0,0,0,0,0,0,0,0
0,0,0,0,0,0,0,0,0,0,0,0,43,0,0,43,0,0,0,0,0,0,0,0,0,0,0
0,0,0,0,0,0,0,0,0,0,0,0,43,0,0,43,0,0,0,0,0,0,0,0,0,0,0
0,0,0,0,0,0,0,0,0,0,0,0,43,43,43,43,0,0,0,0,0,0,0,0,0,0,0
0,0,0,0,0,0,0,0,0,0,0,0,0,0,0,0,0,0,0,0,0,0,0,0,0,0,0
0,0,0,0,0,0,0,0,0,0,0,0,0,0,0,0,0,0,0,0,0,0,0,0,0,0,0
0,0,0,0,0,0,0,0,0,0,0,0,0,0,0,0,0,0,0,0,0,0,0,0,0,0,0
0,0,0,0,0,0,0,0,0,0,0,0,0,0,0,0,0,0,0,0,0,0,0,0,0,0,0
0,0,0,0,0,0,0,0,0,0,0,0,0,0,0,0,0,0,0,0,0,0,0,0,0,0,0
0,0,0,0,0,0,0,0,0,0,0,0,0,0,0,0,0,0,0,0,0,0,0,0,0,0,0
0,0,0,0,0,0,0,0,0,0,0,0,0,0,0,0,0,0,0,0,0,0,0,0,0,0,0
0,0,0,0,0,0,0,0,0,0,0,0,0,0,0,0,0,0,0,0,0,0,0,0,0,0,0
0,0,0,0,0,0,0,0,0,0,0,0,0,0,0,0,0,0,0,0,0,0,0,0,0,0,0
0,0,0,0,0,0,0,0,0,0,0,0,0,0,0,0,0,0,0,0,0,0,0,0,0,0,0
0,0,0,0,0,0,0,0,0,0,0,0,0,0,0,0,0,0,0,0,0,0,0,0,0,0,0
0,0,0,0,0,0,0,0,0,0,0,0,0,0,0,0,0,0,0,0,0,0,0,0,0,0,0
0,0,0,0,0,0,0,0,0,0,0,0,0,0,0,0,0,0,0,0,0,0,0,0,0,0,0
0,0,0,0,0,0,0,0,0,0,0,0,0,0,0,0,0,0,0,0,0,0,0,0,0,0,0
0,0,0,0,0,0,0,0,0,0,0,0,0,0,0,0,0,0,0,0,0,0,0,0,0,0,0
0,0,0,0,0,0,0,0,0,0,0,0,0,0,0,0,0,0,0,0,0,0,0,0,0,0,0
0,0,0,0,0,0,0,0,0,0,0,0,0,0,0,0,0,0,0,0,0,0,0,0,0,0,0
0,0,0,0,0,0,0,0,0,0,0,0,43,0,0,43,0,0,0,0,0,0,0,0,0,0,0
0,0,0,0,0,0,0,0,0,0,0,0,43,0,0,43,0,0,0,0,0,0,0,0,0,0,0
0,0,0,0,0,0,0,0,0,0,0,0,43,0,0,43,0,0,0,0,0,0,0,0,0,0,0
0,0,0,0,0,0,0,0,0,0,0,0,43,0,0,43,0,0,0,0,0,0,0,0,0,0,0
0,0,0,0,0,0,0,0,0,0,0,0,43,0,0,43,0,0,0,0,0,0,0,0,0,0,0
0,0,0,0,0,0,0,0,0,0,0,0,43,0,0,43,0,0,0,0,0,0,0,0,0,0,0
0,0,0,0,0,0,0,0,0,0,0,0,43,33,33,43,0,0,0,0,0,0,0,0,0,0,0
0,0,0,0,0,0,0,33,0,0,0,42,13,74,74,13,28,0,0,0,0,0,0,0,0,0,0
0,0,0,0,0,0,33,72,0,0,0,0,27,27,27,27,0,0,0,0,0,0,0,0,0,0,0
0,0,0,0,0,42,72,60,72,0,0,0,0,0,0,0,0,0,0,0,0,0,0,0,0,0,0
0,0,0,0,0,0,75,72,27,0,0,0,0,0,0,0,0,0,0,0,0,0,0,0,0,0,0
0,0,0,0,0,0,0,27,0,0,0,0,0,0,0,0,0,0,0,0,0,0,0,0,0,0,0
0,0,0,0,0,0,0,0,0,0,0,0,0,0,0,0,0,0,0,0,0,0,0,0,0,0,0
0,0,0,0,0,0,0,0,0,0,0,0,0,0,0,0,0,0,0,0,0,0,0,0,0,0,0
0,0,0,0,0,0,0,0,0,0,0,0,0,0,0,0,0,0,0,0,0,0,0,0,0,0,0
0,0,0,0,0,0,0,0,0,0,0,0,0,0,0,0,0,0,0,0,0,0,0,0,0,0,0
0,0,0,0,0,0,0,0,0,0,0,0,0,0,0,0,0,0,0,0,0,0,0,0,0,0,0
0,0,0,0,0,0,0,0,0,0,0,0,0,0,0,0,0,0,0,0,0,0,0,0,0,0,0
0,0,0,0,0,0,0,0,0,0,0,0,0,0,0,0,0,0,0,0,0,0,0,0,0,0,0
0,0,0,0,0,0,0,0,0,0,0,0,0,0,0,0,0,0,0,0,0,0,0,0,0,0,0
endlayer

layer
0,0,0,0,0,0,0,0,0,0,0,0,0,0,0,0,0,0,0,0,0,0,0,0,0,0,0
0,0,0,0,0,0,0,0,0,0,0,0,0,0,0,0,0,0,0,0,0,0,0,0,0,0,0
0,0,0,0,0,0,0,0,0,0,0,0,0,0,0,0,0,0,0,0,0,0,0,0,0,0,0
0,0,0,0,0,0,0,0,0,0,0,0,0,0,0,0,0,0,0,0,0,0,0,0,0,0,0
0,0,0,0,0,0,0,0,0,0,0,0,0,0,0,0,0,0,0,0,0,0,0,0,0,0,0
0,0,0,0,0,0,0,0,0,0,0,0,0,0,0,0,0,0,0,0,0,0,0,0,0,0,0
0,0,0,0,0,0,0,0,0,0,0,0,0,0,0,0,0,0,0,33,0,0,0,0,0,0,0
0,0,0,0,0,0,0,0,0,0,0,0,0,0,0,0,0,0,33,72,0,0,0,0,0,0,0
0,0,0,0,0,0,0,0,0,0,0,0,0,0,0,0,0,42,72,72,72,0,0,0,0,0,0
0,0,0,0,0,0,0,0,0,0,0,0,0,0,0,0,0,0,42,72,0,0,0,0,0,0,0
0,0,0,0,0,0,0,0,0,0,0,0,33,0,0,33,0,0,0,27,0,0,0,0,0,0,0
0,0,0,0,0,0,0,0,0,0,0,42,13,28,42,13,28,0,0,0,0,0,0,0,0,0,0
0,0,0,0,0,0,0,0,0,0,0,0,27,0,0,27,0,0,0,0,0,0,0,0,0,0,0
0,0,0,0,0,0,0,0,0,0,0,0,0,0,0,0,0,0,0,0,0,0,0,0,0,0,0
0,0,0,0,0,0,0,0,0,0,0,0,0,0,0,0,0,0,0,0,0,0,0,0,0,0,0
0,0,0,0,0,0,0,0,0,0,0,0,0,0,0,0,0,0,0,0,0,0,0,0,0,0,0
0,0,0,0,0,0,0,0,0,0,0,0,0,0,0,0,0,0,0,0,0,0,0,0,0,0,0
0,0,0,0,0,0,0,0,0,0,0,0,0,0,0,0,0,0,0,0,0,0,0,0,0,0,0
0,0,0,0,0,0,0,0,0,0,0,0,0,0,0,0,0,0,0,0,0,0,0,0,0,0,0
0,0,0,0,0,0,0,0,0,0,0,0,0,0,0,0,0,0,0,0,0,0,0,0,0,0,0
0,0,0,0,0,0,0,0,0,0,0,0,0,0,0,0,0,0,0,0,0,0,0,0,0,0,0
0,0,0,0,0,0,0,0,0,0,0,0,0,0,0,0,0,0,0,0,0,0,0,0,0,0,0
0,0,0,0,0,0,0,0,0,0,0,0,0,0,0,0,0,0,0,0,0,0,0,0,0,0,0
0,0,0,0,0,0,0,0,0,0,0,0,0,0,0,0,0,0,0,0,0,0,0,0,0,0,0
0,0,0,0,0,0,0,0,0,0,0,0,0,0,0,0,0,0,0,0,0,0,0,0,0,0,0
0,0,0,0,0,0,0,0,0,0,0,0,0,0,0,0,0,0,0,0,0,0,0,0,0,0,0
0,0,0,0,0,0,0,0,0,0,0,0,0,0,0,0,0,0,0,0,0,0,0,0,0,0,0
0,0,0,0,0,0,0,0,0,0,0,0,0,0,0,0,0,0,0,0,0,0,0,0,0,0,0
0,0,0,0,0,0,0,0,0,0,0,0,0,0,0,0,0,0,0,0,0,0,0,0,0,0,0
0,0,0,0,0,0,0,0,0,0,0,0,0,0,0,0,0,0,0,0,0,0,0,0,0,0,0
0,0,0,0,0,0,0,0,0,0,0,0,0,0,0,0,0,0,0,0,0,0,0,0,0,0,0
0,0,0,0,0,0,0,0,0,0,0,0,0,0,0,0,0,0,0,0,0,0,0,0,0,0,0
0,0,0,0,0,0,0,0,0,0,0,0,0,0,0,0,0,0,0,0,0,0,0,0,0,0,0
0,0,0,0,0,0,0,0,0,0,0,0,0,0,0,0,0,0,0,0,0,0,0,0,0,0,0
0,0,0,0,0,0,0,0,0,0,0,0,0,0,0,0,0,0,0,0,0,0,0,0,0,0,0
0,0,0,0,0,0,0,0,0,0,0,0,0,0,0,0,0,0,0,0,0,0,0,0,0,0,0
0,0,0,0,0,0,0,0,0,0,0,0,0,0,0,0,0,0,0,0,0,0,0,0,0,0,0
0,0,0,0,0,0,0,0,0,0,0,0,0,0,0,0,0,0,0,0,0,0,0,0,0,0,0
0,0,0,0,0,0,0,0,0,0,0,0,0,0,0,0,0,0,0,0,0,0,0,0,0,0,0
0,0,0,0,0,0,0,0,0,0,0,0,0,0,0,0,0,0,0,0,0,0,0,0,0,0,0
0,0,0,0,0,0,0,0,0,0,0,0,0,0,0,0,0,0,0,0,0,0,0,0,0,0,0
0,0,0,0,0,0,0,0,0,0,0,0,0,0,0,0,0,0,0,0,0,0,0,0,0,0,0
0,0,0,0,0,0,0,0,0,0,0,0,33,0,0,33,0,0,0,0,0,0,0,0,0,0,0
0,0,0,0,0,0,0,33,0,0,0,42,13,28,42,13,28,0,0,0,0,0,0,0,0,0,0
0,0,0,0,0,0,33,72,0,0,0,0,27,0,0,27,0,0,0,0,0,0,0,0,0,0,0
0,0,0,0,0,42,72,72,72,0,0,0,0,0,0,0,0,0,0,0,0,0,0,0,0,0,0
0,0,0,0,0,0,42,72,27,0,0,0,0,0,0,0,0,0,0,0,0,0,0,0,0,0,0
0,0,0,0,0,0,0,27,0,0,0,0,0,0,0,0,0,0,0,0,0,0,0,0,0,0,0
0,0,0,0,0,0,0,0,0,0,0,0,0,0,0,0,0,0,0,0,0,0,0,0,0,0,0
0,0,0,0,0,0,0,0,0,0,0,0,0,0,0,0,0,0,0,0,0,0,0,0,0,0,0
0,0,0,0,0,0,0,0,0,0,0,0,0,0,0,0,0,0,0,0,0,0,0,0,0,0,0
0,0,0,0,0,0,0,0,0,0,0,0,0,0,0,0,0,0,0,0,0,0,0,0,0,0,0
0,0,0,0,0,0,0,0,0,0,0,0,0,0,0,0,0,0,0,0,0,0,0,0,0,0,0
0,0,0,0,0,0,0,0,0,0,0,0,0,0,0,0,0,0,0,0,0,0,0,0,0,0,0
0,0,0,0,0,0,0,0,0,0,0,0,0,0,0,0,0,0,0,0,0,0,0,0,0,0,0
0,0,0,0,0,0,0,0,0,0,0,0,0,0,0,0,0,0,0,0,0,0,0,0,0,0,0
endlayer

