
# Created by Ruins mod version 15.0 Ingame Parser
# authoring Player: SunsOfOld

weight=100
embed_into_distance=1
acceptable_target_blocks=
unacceptable_target_blocks=flowing_water,water,flowing_lava,lava
dimensions=9,11,14
allowable_overhang=0
max_leveling=4
leveling_buffer=0
preserve_water=0
preserve_lava=0
uniqueMinDistance=1000000
preventRotation=1

rule1=0,100,BiomesOPlenty:newBopDirt-0
rule2=0,100,preserveBlock
rule3=0,100,ExtrabiomesXL:terrain_blocks2-0
rule4=0,100,minecraft:dirt-0
rule5=0,100,IInventory;minecraft:furnace;VeganOption:sufferingFragment#1#0#0-3
rule6=0,100,BiomesOPlenty:logs1-10
rule7=0,100,BiomesOPlenty:logs1-6
rule8=0,100,IInventory;minecraft:furnace;UndergroundBiomes:fossilPiece#1#4#0-2
rule9=0,100,chisel:tyrian-13
rule10=0,100,IInventory;minecraft:furnace;BiomesOPlenty:misc#1#10#0-4
rule11=0,100,IInventory;minecraft:furnace;VeganOption:sufferingProof#1#0#0-2
rule12=0,100,ExtrabiomesXL:grass-3
rule13=0,100,ExtrabiomesXL:grass-4
rule14=0,100,BiomesOPlenty:plants-5
rule15=0,100,BiomesOPlenty:mushrooms-2
rule16=0,100,BiomesOPlenty:treeMoss-8
rule17=0,100,BiomesOPlenty:mushrooms-5
rule18=0,100,BiomesOPlenty:logs3-2
rule19=0,100,BiomesOPlenty:leaves1-15
rule20=0,100,minecraft:web-0
rule21=0,100,BiomesOPlenty:logs1-2
rule22=0,100,BiomesOPlenty:darkStairs-0
rule23=0,100,ExtrabiomesXL:fence-3
rule24=0,100,BiomesOPlenty:foliage-15
rule25=0,100,BiomesOPlenty:darkStairs-2
rule26=0,100,BiomesOPlenty:darkStairs-3
rule27=0,100,ExtrabiomesXL:door_cypress-3
rule28=0,100,BiblioWoodsBoP:BiblioWoodSeat-2
rule29=0,100,BiblioWoodsBoP:BiblioWoodtable-2
rule30=0,100,BiomesOPlenty:darkStairs-1
rule31=0,100,BiomesOPlenty:treeMoss-2
rule32=0,100,BiomesOPlenty:treeMoss-4
rule33=0,100,BiomesOPlenty:planks-2
rule34=0,100,chisel:stained_glass_pane_red-11
rule35=0,100,harvestcraft:pamcandleDeco16-5
rule36=0,100,BiomesOPlenty:darkStairs-6
rule37=0,100,BiomesOPlenty:darkStairs-7
rule38=0,100,ExtrabiomesXL:door_cypress-8
rule39=0,100,ExtrabiomesXL:door_cypress-9
rule40=0,100,BiomesOPlenty:treeMoss-1
rule41=0,100,BiomesOPlenty:logs3-10
rule42=0,100,UndergroundBiomes:sedimentaryStoneHalfSlab-12
rule43=0,100,BiomesOPlenty:darkStairs-5
rule44=0,100,BiomesOPlenty:darkStairs-4
rule45=0,100,BiomesOPlenty:logs3-6
rule46=0,100,UndergroundBiomes:sedimentaryStoneHalfSlab-4
rule47=0,100,UndergroundBiomes:sedimentaryStoneFullSlab-4
rule48=0,100,chisel:grimstone-12
rule49=0,100,BiomesOPlenty:woodenSingleSlab1-2

layer
2,1,1,1,3,1,1,2,1,1,2,3,2,1
1,3,1,1,1,1,2,1,3,1,4,1,1,2
1,1,1,1,4,1,1,1,1,1,1,2,4,1
1,1,1,1,1,1,1,1,1,3,1,4,1,3
1,1,8,7,6,5,1,1,1,1,1,1,1,1
3,1,7,6,7,6,9,9,1,9,1,9,3,9
4,1,6,7,6,7,9,1,9,1,1,1,9,1
1,1,11,6,7,10,1,1,1,1,1,4,1,3
1,1,1,1,1,1,1,1,1,1,4,1,1,2
3,1,1,1,1,1,4,1,2,3,1,1,3,1
1,2,1,3,1,1,1,3,1,1,2,3,1,2
endlayer

layer
0,14,13,12,0,12,13,0,13,12,0,0,0,12
13,0,12,12,13,12,16,12,0,12,15,12,13,0
19,19,20,19,15,19,13,19,12,13,12,18,17,13
12,21,22,22,22,22,21,19,12,0,12,15,12,0
19,26,0,0,0,0,25,12,0,12,13,24,23,14
19,26,0,28,0,0,27,0,14,0,12,0,0,0
15,26,0,29,0,0,27,12,0,24,13,12,0,13
19,26,0,0,0,0,25,20,12,23,12,15,12,0
19,21,30,30,30,30,21,19,13,12,17,12,12,0
31,19,20,19,19,19,17,19,0,0,12,13,0,12
14,0,12,0,12,14,12,0,12,12,0,0,13,0
endlayer

layer
0,0,0,0,0,0,0,0,0,0,0,0,0,0
0,0,0,0,0,16,16,0,0,0,0,0,0,0
0,0,19,0,32,0,19,19,0,0,0,18,0,0
19,21,33,34,34,33,21,20,0,0,0,0,0,0
19,37,0,0,0,0,36,0,0,0,0,0,35,0
0,37,0,0,0,0,38,0,0,0,0,0,0,0
0,37,0,35,0,0,39,0,0,0,0,0,0,0
20,37,0,0,0,0,36,0,0,35,0,0,0,0
19,21,33,34,34,33,21,40,0,0,0,0,0,0
31,31,19,0,0,0,19,40,0,0,0,0,0,0
0,0,0,0,0,0,31,0,0,0,0,0,0,0
endlayer

layer
0,0,0,0,0,0,0,0,0,0,0,0,0,0
0,0,0,0,0,16,0,0,0,0,0,0,0,0
0,0,0,0,32,19,0,0,0,0,0,18,41,0
19,21,30,30,30,30,21,0,0,0,0,0,0,0
32,33,0,0,0,0,43,42,0,0,0,0,0,0
0,34,0,0,0,0,36,0,0,0,0,0,0,0
0,34,0,0,0,0,36,0,0,0,0,0,0,0
19,33,0,0,0,0,44,42,0,0,0,0,0,0
32,21,22,22,22,22,21,40,0,0,0,0,0,0
0,31,19,0,0,0,31,0,0,0,0,0,0,0
0,0,0,0,0,0,0,0,0,0,0,0,0,0
endlayer

layer
0,0,0,0,0,0,0,0,0,0,0,0,0,0
0,0,0,0,0,16,0,0,0,0,0,0,0,41
0,42,0,0,32,19,42,0,0,0,0,18,0,0
42,21,43,43,43,43,21,42,0,0,0,45,0,0
32,33,0,0,0,0,37,0,0,0,0,45,0,0
0,36,0,0,0,0,37,46,0,0,0,0,0,0
19,36,0,0,0,0,37,46,0,0,0,0,0,0
19,33,0,0,0,0,37,0,0,0,0,0,0,0
42,21,44,44,44,44,21,42,0,0,0,0,0,0
0,42,0,19,0,0,42,0,0,0,0,0,0,0
0,0,0,0,0,0,0,0,0,0,0,0,0,0
endlayer

layer
0,0,0,0,0,0,0,0,0,0,0,0,0,0
0,0,0,0,0,0,0,0,0,0,0,45,0,0
0,0,46,46,46,46,0,0,0,0,0,18,0,0
0,21,47,47,47,47,21,0,0,0,0,0,0,0
46,47,19,48,48,19,47,46,0,0,0,0,0,0
46,47,48,0,0,48,47,46,0,0,0,45,0,0
46,47,48,0,0,48,47,46,0,0,0,0,0,0
46,47,19,48,48,19,47,46,0,0,0,0,0,0
0,21,47,47,47,47,21,0,0,0,0,0,0,0
0,0,46,46,46,46,0,0,0,0,0,0,0,0
0,0,0,0,0,0,0,0,0,0,0,0,0,0
endlayer

layer
0,0,0,0,0,0,0,0,0,0,0,45,0,0
0,0,0,0,0,0,0,0,0,0,0,0,0,0
0,0,0,0,0,0,0,0,0,0,41,18,0,0
0,49,0,0,0,0,49,0,0,0,0,0,0,0
0,0,0,46,46,0,0,0,0,0,0,0,0,0
0,0,46,19,19,46,0,0,0,0,0,0,0,0
0,0,46,19,19,46,0,0,0,0,0,0,0,0
0,0,0,46,46,0,0,0,0,0,0,0,0,0
0,49,0,0,0,0,49,0,0,0,0,0,0,0
0,0,0,0,0,0,0,0,0,0,0,0,0,0
0,0,0,0,0,0,0,0,0,0,0,0,0,0
endlayer

layer
0,0,0,0,0,0,0,0,0,0,0,0,0,0
0,0,0,0,0,0,0,0,0,0,0,0,0,0
0,0,0,0,0,0,0,0,0,41,0,18,41,0
0,0,0,0,0,0,0,0,0,0,0,0,0,0
0,0,0,0,0,0,0,0,0,0,0,0,0,0
0,0,0,0,0,0,0,0,0,0,0,0,0,0
0,0,0,0,0,0,0,0,0,0,0,0,0,0
0,0,0,0,0,0,0,0,0,0,0,0,0,0
0,0,0,0,0,0,0,0,0,0,0,0,0,0
0,0,0,0,0,0,0,0,0,0,0,0,0,0
0,0,0,0,0,0,0,0,0,0,0,0,0,0
endlayer

layer
0,0,0,0,0,0,0,0,0,0,0,0,0,0
0,0,0,0,0,0,0,0,0,0,0,0,0,0
0,0,0,0,0,0,0,0,0,0,0,18,0,0
0,0,0,0,0,0,0,0,0,0,0,0,0,0
0,0,0,0,0,0,0,0,0,0,0,0,0,0
0,0,0,0,0,0,0,0,0,0,0,0,0,0
0,0,0,0,0,0,0,0,0,0,0,0,0,0
0,0,0,0,0,0,0,0,0,0,0,0,0,0
0,0,0,0,0,0,0,0,0,0,0,0,0,0
0,0,0,0,0,0,0,0,0,0,0,0,0,0
0,0,0,0,0,0,0,0,0,0,0,0,0,0
endlayer

