
# Created by Ruins mod version 14.9 Ingame Parser
# authoring Player: SunsOfOld

weight=100
embed_into_distance=3
acceptable_target_blocks=
unacceptable_target_blocks=flowing_water,water,flowing_lava,lava
dimensions=12,17,23
allowable_overhang=0
max_leveling=5
leveling_buffer=0
preserve_water=0
preserve_lava=0
uniqueMinDistance=1000000
preventRotation=1

rule1=0,100,preserveBlock
rule2=0,100,UndergroundBiomes:igneousStone-10
rule3=0,100,UndergroundBiomes:sedimentaryStone-13
rule4=0,100,minecraft:dirt-0
rule5=0,100,minecraft:water-0
rule6=0,100,IInventory;minecraft:chest;BiomesOPlenty:coral1#1#14#11+BiomesOPlenty:flippers#1#0#13+minecraft:fishing_rod#{RepairCost:2,ench:[0:{id:34s,lvl:3s,},1:{id:62s,lvl:3s,},2:{id:61s,lvl:3s,},],display:{Name:"Lucky",},}#0#15-5
rule7=0,100,minecraft:water-1
rule8=0,100,minecraft:grass-0
rule9=0,100,minecraft:sand-0
rule10=0,100,BiomesOPlenty:newBopDirt-1
rule11=0,100,chisel:fantasyblock2-0
rule12=0,100,UndergroundBiomes:sedimentary_monsterStoneEgg-6
rule13=0,100,ExtrabiomesXL:flower3-0
rule14=0,100,minecraft:tallgrass-1
rule15=0,100,BiomesOPlenty:foliage-1
rule16=0,100,BiomesOPlenty:foliage-11
rule17=0,100,BiomesOPlenty:foliage-14
rule18=0,100,ExtrabiomesXL:leaves_2-14
rule19=0,100,ExtrabiomesXL:flower2-3
rule20=0,100,BiomesOPlenty:foliage-10
rule21=0,100,harvestcraft:presser-0
rule22=0,100,harvestcraft:sink-0
rule23=0,100,GardenTrees:thin_log-0
rule24=0,100,UndergroundBiomes:sedimentaryStoneHalfSlab-6
rule25=0,100,UndergroundBiomes:sedimentaryStoneHalfSlab-14
rule26=0,100,BiomesOPlenty:woodenSingleSlab1-6
rule27=0,100,minecraft:double_plant-2
rule28=0,100,UndergroundBiomes:sedimentaryStoneFullSlab-6
rule29=0,100,plantmegapack:groundcoverClover-0
rule30=0,100,minecraft:water-9
rule31=0,100,ExtrabiomesXL:leaves_2-6
rule32=0,100,ExtrabiomesXL:log1-3
rule33=0,100,dendrology:stairs9-2
rule34=0,100,dendrology:stairs9-0
rule35=0,100,dendrology:stairs9-3
rule36=0,100,dendrology:stairs9-1
rule37=0,100,dendrology:sslab1-1
rule38=0,100,minecraft:double_plant-8
rule39=0,100,chisel:paperwall-8
rule40=0,100,chisel:paperwall-3
rule41=0,100,ExtrabiomesXL:leaves_2-1
rule42=0,100,ExtrabiomesXL:leaves_2-13
rule43=0,100,ExtrabiomesXL:log1-7
rule44=0,100,ExtrabiomesXL:log1-11
rule45=0,100,chisel:torch4-1
rule46=0,100,chisel:torch4-2
rule47=0,100,IInventory;minecraft:chest;harvestcraft:sushiItem#8#0#1+harvestcraft:teaItem#5#0#7+harvestcraft:tealeafItem#9#0#9+dendrology:sapling0#1#2#10+harvestcraft:gingerItem#5#0#11+minecraft:diamond_hoe#{RepairCost:2,ench:[0:{id:34s,lvl:10s,},1:{id:21s,lvl:3s,},],display:{Name:"Bountiful Harvest",},}#0#13+harvestcraft:riceItem#8#0#15+ExtrabiomesXL:saplings_2#3#4#16+harvestcraft:seaweedItem#6#0#17+harvestcraft:cuttingboardItem#1#0#19+harvestcraft:soybeanItem#11#0#25-4
rule48=0,100,ExtrabiomesXL:leaves_2-5
rule49=0,100,dendrology:dslab1-1
rule50=0,100,dendrology:sslab1-9

layer
1,1,1,1,1,1,1,1,1,1,1,1,1,1,1,1,1,1,1,1,1,1,1
1,1,1,1,1,1,1,1,1,1,1,1,1,1,1,1,1,1,1,1,1,1,1
1,1,1,1,1,1,1,1,1,1,1,1,1,1,1,1,1,1,1,1,1,1,1
1,1,1,1,1,1,1,1,1,1,1,1,1,1,1,1,1,1,1,1,1,1,1
1,1,1,1,1,1,1,1,1,1,1,1,1,1,1,1,1,1,1,1,1,1,1
1,1,1,1,1,1,1,1,1,1,1,1,1,1,1,1,1,1,1,1,1,1,1
1,1,1,1,1,1,1,1,1,1,1,1,1,1,1,1,1,1,1,1,1,1,1
1,1,1,1,1,1,1,1,1,1,1,1,1,1,1,1,1,1,1,1,1,1,1
1,1,1,1,1,1,1,1,1,1,1,1,1,1,1,1,1,1,1,1,1,1,1
1,1,1,1,1,1,1,1,1,1,1,1,2,2,1,2,1,1,1,1,1,1,1
1,1,1,1,1,1,1,1,1,1,1,1,2,3,2,2,2,1,1,1,1,1,1
1,1,1,1,1,1,1,1,1,1,1,1,1,2,3,4,4,3,1,1,1,1,1
1,1,1,1,1,1,1,1,1,1,1,1,1,1,4,4,3,1,1,1,1,1,1
1,1,1,1,1,1,1,1,1,1,1,1,1,1,2,1,2,1,1,1,1,1,1
1,1,1,1,1,1,1,1,1,1,1,1,1,1,1,1,1,1,1,1,1,1,1
1,1,1,1,1,1,1,1,1,1,1,1,1,1,1,1,1,1,1,1,1,1,1
1,1,1,1,1,1,1,1,1,1,1,1,1,1,1,1,1,1,1,1,1,1,1
endlayer

layer
1,1,1,1,1,1,1,1,1,1,1,1,1,1,1,1,1,1,1,1,1,1,1
1,1,1,1,1,1,1,1,1,1,1,1,1,1,1,1,1,1,1,1,1,1,1
1,1,1,1,1,1,1,1,1,1,1,1,1,1,1,1,1,1,1,1,1,1,1
1,1,1,1,1,1,1,1,1,1,1,1,1,1,1,1,1,1,1,1,1,1,1
1,1,1,1,1,1,1,1,1,1,1,1,1,1,1,1,1,1,1,1,1,1,1
1,1,1,1,1,1,1,1,1,1,1,1,1,1,1,1,1,1,1,1,1,1,1
1,1,1,1,1,1,1,1,1,1,1,1,1,1,1,1,1,1,1,1,1,1,1
1,1,1,1,1,1,1,1,1,1,1,1,1,1,1,1,1,1,1,1,1,1,1
1,1,1,1,1,1,1,1,1,1,1,1,3,1,1,3,1,1,1,1,1,1,1
1,1,1,1,1,1,1,1,1,1,1,3,6,2,3,5,3,1,1,1,1,1,1
1,1,1,1,1,1,1,1,1,1,1,3,7,5,5,5,4,3,1,1,1,1,1
1,1,1,1,1,1,1,1,1,1,1,1,3,5,5,4,4,4,2,1,1,1,1
1,1,1,1,1,1,1,1,1,1,1,1,1,3,4,4,4,2,1,1,1,1,1
1,1,1,1,1,1,1,1,1,1,1,1,1,2,4,3,0,3,1,1,1,1,1
1,1,1,1,1,1,1,1,1,1,1,1,1,1,2,1,3,1,1,1,1,1,1
1,1,1,1,1,1,1,1,1,1,1,1,1,1,1,1,1,1,1,1,1,1,1
1,1,1,1,1,1,1,1,1,1,1,1,1,1,1,1,1,1,1,1,1,1,1
endlayer

layer
1,1,8,1,8,8,1,8,1,8,1,8,1,1,1,8,1,8,1,8,1,8,1
1,8,8,9,9,9,8,8,8,1,4,8,8,1,8,1,8,1,8,8,1,1,8
8,8,9,9,9,9,9,8,1,8,8,1,8,8,1,8,8,8,8,1,8,8,1
8,8,9,9,9,9,9,8,8,8,8,8,10,10,10,10,10,10,10,10,10,8,8
8,9,9,9,9,9,9,9,8,8,11,8,10,10,10,10,10,10,10,10,10,8,1
8,9,9,9,9,9,9,9,8,11,8,11,10,10,10,10,10,10,10,10,10,1,8
8,9,9,9,9,9,9,9,8,8,8,8,10,10,10,10,10,10,10,10,10,8,1
8,9,9,9,9,9,9,9,8,8,8,8,10,10,10,10,10,10,10,10,10,8,8
8,8,9,9,9,9,9,8,8,8,8,8,8,8,8,8,8,8,8,8,8,8,1
1,8,9,9,9,9,9,8,8,8,8,8,5,12,12,8,8,8,8,8,8,1,1
8,8,8,9,9,9,8,8,8,8,8,12,12,12,5,5,5,8,11,8,8,8,8
1,8,8,8,8,8,8,8,8,8,8,8,12,5,5,5,5,8,8,8,8,8,1
8,1,8,8,8,8,1,8,8,8,8,8,8,12,5,5,8,8,11,8,8,8,8
1,8,1,8,4,8,8,8,8,8,8,1,8,8,8,8,8,8,8,8,1,8,1
1,1,8,8,8,8,8,8,1,8,8,8,8,8,1,8,8,8,11,8,8,1,8
1,1,1,8,1,8,1,8,8,1,1,8,1,8,8,8,1,8,8,1,1,1,1
1,1,1,1,1,1,8,1,8,1,8,1,8,1,8,1,8,1,1,1,1,1,1
endlayer

layer
0,18,18,0,17,17,0,16,0,15,0,14,0,0,0,0,0,0,0,14,0,13,0
0,16,17,0,0,0,17,18,20,22,21,16,20,0,14,0,19,0,0,14,0,0,0
18,17,0,0,0,0,0,17,0,18,18,0,0,16,0,0,16,14,20,0,14,14,0
0,17,0,0,24,0,0,17,20,13,14,16,23,0,0,0,23,0,0,0,23,0,0
0,0,0,12,25,0,0,0,17,17,0,14,0,0,0,0,0,0,0,0,0,16,0
0,0,0,24,0,0,0,0,17,0,17,26,0,0,0,0,0,0,0,0,0,0,20
0,0,0,0,0,0,0,0,17,17,17,16,0,0,0,0,0,0,0,0,0,19,0
0,0,0,0,12,24,0,0,17,20,18,20,23,0,0,0,23,0,0,0,23,14,15
0,17,0,0,24,0,0,17,16,18,18,14,14,0,14,14,27,14,26,14,16,20,0
0,18,0,0,0,0,0,17,27,14,14,16,28,28,24,14,27,20,17,14,27,0,0
0,31,31,0,0,0,17,27,18,27,14,0,24,25,30,7,0,0,0,29,14,14,14
0,31,31,31,17,0,14,18,18,18,20,14,25,24,7,0,0,17,17,0,14,14,0
17,0,31,14,14,14,0,27,18,14,14,27,0,0,0,0,0,29,0,20,27,14,14
0,20,0,16,32,27,27,19,14,14,16,0,14,15,16,20,0,17,17,0,0,16,0
0,0,14,14,27,14,14,14,0,27,14,15,14,14,0,15,29,17,0,29,16,0,20
0,0,0,16,0,20,0,16,14,0,0,14,0,27,14,15,0,29,17,0,0,0,0
0,0,0,0,0,0,0,0,14,0,15,0,17,0,15,0,0,0,0,0,0,0,0
endlayer

layer
0,0,18,0,0,0,0,0,0,0,0,0,0,0,0,0,0,0,0,0,0,0,0
0,0,0,0,0,0,0,0,0,0,0,0,0,0,0,0,0,0,0,0,0,0,0
0,0,0,0,0,0,0,0,0,0,18,0,0,0,0,0,0,0,0,0,0,0,0
0,0,0,0,0,0,0,0,0,0,0,0,35,34,34,34,34,34,34,34,33,0,0
0,0,0,25,28,0,0,0,0,0,0,0,36,26,26,26,26,26,26,26,33,0,0
0,0,0,0,0,0,0,0,0,0,0,0,37,26,26,26,26,26,26,26,33,0,0
0,0,0,0,0,0,0,0,0,0,0,0,34,26,26,26,26,26,26,26,33,0,0
0,0,0,0,0,0,0,0,0,0,18,0,35,36,36,36,36,33,37,35,36,0,0
0,0,0,0,0,0,0,0,0,0,0,0,0,0,0,0,38,0,0,0,0,0,0
0,0,0,0,0,0,0,0,38,0,0,0,0,28,24,0,38,0,0,0,38,0,0
0,0,0,0,0,0,0,38,0,38,0,0,12,5,7,0,0,0,0,0,0,0,0
0,0,31,0,0,0,0,0,18,0,0,0,24,28,0,0,0,0,0,0,0,0,0
0,0,0,0,0,0,0,38,0,0,0,38,0,0,0,0,0,0,0,0,38,0,0
0,0,0,0,32,38,38,0,0,0,0,0,0,0,0,0,0,0,0,0,0,0,0
0,0,0,0,38,0,0,0,0,38,0,0,0,0,0,0,0,0,0,0,0,0,0
0,0,0,0,0,0,0,0,0,0,0,0,0,38,0,0,0,0,0,0,0,0,0
0,0,0,0,0,0,0,0,0,0,0,0,0,0,0,0,0,0,0,0,0,0,0
endlayer

layer
0,0,0,0,0,0,0,0,0,0,0,0,0,0,0,0,0,0,0,0,0,0,0
0,0,0,0,0,0,0,0,0,0,0,0,0,0,0,0,0,0,0,0,0,0,0
0,0,0,0,0,0,0,0,0,0,0,0,0,0,0,0,0,0,0,0,0,0,0
0,0,0,0,0,0,0,0,0,0,0,0,39,39,39,39,39,39,39,39,39,0,0
0,0,0,12,0,0,0,0,0,0,0,0,39,0,0,0,0,0,0,0,39,0,0
0,0,0,0,0,0,0,0,0,0,0,0,0,0,0,0,0,0,0,0,39,0,0
0,0,0,0,0,0,0,0,0,0,0,0,39,0,0,0,0,0,0,0,39,0,0
0,0,0,0,0,0,0,0,0,0,0,0,39,39,39,39,39,39,0,39,39,0,0
0,0,0,0,0,0,0,0,0,0,0,0,0,0,0,0,0,0,0,0,0,0,0
0,0,0,0,0,0,0,0,0,0,0,0,0,0,0,0,0,0,0,0,0,0,0
0,0,0,0,0,0,0,0,0,0,0,0,0,24,0,0,0,0,0,0,0,0,0
0,0,0,0,0,0,0,0,0,0,0,0,0,0,0,0,0,0,0,0,0,0,0
0,0,0,0,0,0,0,0,0,0,0,0,0,0,0,0,0,0,0,0,0,0,0
0,0,0,0,32,0,0,0,0,0,0,0,0,0,0,0,0,0,0,0,0,0,0
0,0,0,0,0,0,0,0,0,0,0,0,0,0,0,0,0,0,0,0,0,0,0
0,0,0,0,0,0,0,0,0,0,0,0,0,0,0,0,0,0,0,0,0,0,0
0,0,0,0,0,0,0,0,0,0,0,0,0,0,0,0,0,0,0,0,0,0,0
endlayer

layer
0,0,0,0,0,0,0,0,0,0,0,0,0,0,0,0,0,0,0,0,0,0,0
0,0,0,0,0,0,0,0,0,0,0,0,0,0,0,0,0,0,0,0,0,0,0
0,0,0,0,0,0,0,0,0,0,0,0,0,0,0,0,0,0,0,0,0,0,0
0,0,0,0,0,0,0,0,0,0,0,0,40,40,40,40,40,40,40,40,40,0,0
0,0,0,0,0,0,0,0,0,0,0,0,40,0,0,0,0,0,0,0,40,0,0
0,0,0,0,0,0,0,0,0,0,0,0,0,0,0,0,0,0,0,0,40,0,0
0,0,0,0,0,0,0,0,0,0,0,0,40,0,0,0,0,0,0,0,40,0,0
0,0,0,0,0,0,0,0,0,0,0,0,40,40,40,40,40,40,0,40,40,0,0
0,0,0,0,0,0,0,0,0,0,0,0,0,0,0,0,0,0,0,0,0,0,0
0,0,0,0,0,0,0,0,0,0,0,0,0,0,0,0,0,0,0,0,0,0,0
0,0,0,41,41,0,0,0,0,0,0,0,0,0,0,0,0,0,0,0,0,0,0
0,0,0,0,42,42,0,41,0,0,0,0,0,0,0,0,0,0,0,0,0,0,0
0,42,0,42,43,42,42,42,0,0,0,0,0,0,0,0,0,0,0,0,0,0,0
41,44,44,44,44,44,42,41,41,0,0,0,0,0,0,0,0,0,0,0,0,0,0
0,42,41,42,42,43,42,42,0,0,0,0,0,0,0,0,0,0,0,0,0,0,0
0,0,42,0,42,42,42,41,0,0,0,0,0,0,0,0,0,0,0,0,0,0,0
0,0,0,0,0,42,0,0,0,0,0,0,0,0,0,0,0,0,0,0,0,0,0
endlayer

layer
0,0,0,0,0,0,0,0,0,0,0,0,0,0,0,0,0,0,0,0,0,0,0
0,0,0,0,0,0,0,0,0,0,0,0,0,0,0,0,0,0,0,0,0,0,0
0,0,0,0,0,0,0,0,0,0,0,0,0,0,0,0,0,0,0,0,0,0,0
0,0,0,0,0,0,0,0,0,0,0,0,34,34,34,34,34,34,34,34,34,0,0
0,0,0,0,0,0,0,0,0,0,0,0,36,0,45,0,0,0,45,0,36,0,0
0,0,0,0,0,0,0,0,0,0,0,0,37,0,0,0,0,0,0,0,37,0,0
0,0,0,0,0,0,0,0,0,0,0,0,34,0,46,0,47,0,46,0,34,0,0
0,0,0,0,0,0,0,0,0,0,0,0,36,36,36,36,36,36,36,36,36,0,0
0,0,0,0,0,0,0,0,0,0,0,0,0,0,0,0,0,0,0,0,0,0,0
0,0,0,0,0,0,0,0,0,0,0,0,0,0,0,0,0,0,0,0,0,0,0
0,0,41,41,41,42,42,0,0,0,0,0,0,0,0,0,0,0,0,0,0,0,0
0,42,41,41,43,41,42,0,0,0,0,0,0,0,0,0,0,0,0,0,0,0,0
41,42,42,42,41,42,42,42,41,0,0,0,0,0,0,0,0,0,0,0,0,0,0
42,41,41,41,41,32,44,41,41,0,0,0,0,0,0,0,0,0,0,0,0,0,0
41,41,41,0,41,0,42,42,42,0,0,0,0,0,0,0,0,0,0,0,0,0,0
0,42,42,41,42,42,41,41,0,0,0,0,0,0,0,0,0,0,0,0,0,0,0
0,0,0,0,48,41,42,0,0,0,0,0,0,0,0,0,0,0,0,0,0,0,0
endlayer

layer
0,0,0,0,0,0,0,0,0,0,0,0,0,0,0,0,0,0,0,0,0,0,0
0,0,0,0,0,0,0,0,0,0,0,0,0,0,0,0,0,0,0,0,0,0,0
0,0,0,0,0,0,0,0,0,0,0,0,0,0,0,0,0,0,0,0,0,0,0
0,0,0,0,0,0,0,0,0,0,0,0,0,0,0,0,0,0,0,0,0,0,0
0,0,0,0,0,0,0,0,0,0,0,0,34,34,34,34,34,34,34,34,34,0,0
0,0,0,0,0,0,0,0,0,0,0,0,49,50,50,50,50,50,50,50,49,0,0
0,0,0,0,0,0,0,0,0,0,0,0,36,36,36,36,36,36,36,36,36,0,0
0,0,0,0,0,0,0,0,0,0,0,0,0,0,0,0,0,0,0,0,0,0,0
0,0,0,0,0,0,0,0,0,0,0,0,0,0,0,0,0,0,0,0,0,0,0
0,0,0,0,0,0,0,0,0,0,0,0,0,0,0,0,0,0,0,0,0,0,0
0,0,0,42,41,0,0,41,0,0,0,0,0,0,0,0,0,0,0,0,0,0,0
0,42,41,41,41,41,41,41,0,0,0,0,0,0,0,0,0,0,0,0,0,0,0
0,42,41,41,41,32,42,41,42,0,0,0,0,0,0,0,0,0,0,0,0,0,0
41,42,41,41,41,41,41,44,41,0,0,0,0,0,0,0,0,0,0,0,0,0,0
0,42,41,41,41,41,0,41,41,0,0,0,0,0,0,0,0,0,0,0,0,0,0
0,0,41,41,41,41,41,41,41,0,0,0,0,0,0,0,0,0,0,0,0,0,0
0,0,0,42,0,42,41,0,0,0,0,0,0,0,0,0,0,0,0,0,0,0,0
endlayer

layer
0,0,0,0,0,0,0,0,0,0,0,0,0,0,0,0,0,0,0,0,0,0,0
0,0,0,0,0,0,0,0,0,0,0,0,0,0,0,0,0,0,0,0,0,0,0
0,0,0,0,0,0,0,0,0,0,0,0,0,0,0,0,0,0,0,0,0,0,0
0,0,0,0,0,0,0,0,0,0,0,0,0,0,0,0,0,0,0,0,0,0,0
0,0,0,0,0,0,0,0,0,0,0,0,0,0,0,0,0,0,0,0,0,0,0
0,0,0,0,0,0,0,0,0,0,0,0,0,0,0,0,0,0,0,0,0,0,0
0,0,0,0,0,0,0,0,0,0,0,0,0,0,0,0,0,0,0,0,0,0,0
0,0,0,0,0,0,0,0,0,0,0,0,0,0,0,0,0,0,0,0,0,0,0
0,0,0,0,0,0,0,0,0,0,0,0,0,0,0,0,0,0,0,0,0,0,0
0,0,0,0,0,0,0,0,0,0,0,0,0,0,0,0,0,0,0,0,0,0,0
0,0,0,41,0,0,41,0,0,0,0,0,0,0,0,0,0,0,0,0,0,0,0
0,0,0,41,41,42,41,41,0,0,0,0,0,0,0,0,0,0,0,0,0,0,0
0,0,41,41,41,41,41,41,0,0,0,0,0,0,0,0,0,0,0,0,0,0,0
0,0,41,41,41,41,41,41,41,0,0,0,0,0,0,0,0,0,0,0,0,0,0
0,0,41,41,41,41,41,41,0,0,0,0,0,0,0,0,0,0,0,0,0,0,0
0,0,0,41,41,41,41,41,0,0,0,0,0,0,0,0,0,0,0,0,0,0,0
0,0,0,0,0,0,41,0,0,0,0,0,0,0,0,0,0,0,0,0,0,0,0
endlayer

layer
0,0,0,0,0,0,0,0,0,0,0,0,0,0,0,0,0,0,0,0,0,0,0
0,0,0,0,0,0,0,0,0,0,0,0,0,0,0,0,0,0,0,0,0,0,0
0,0,0,0,0,0,0,0,0,0,0,0,0,0,0,0,0,0,0,0,0,0,0
0,0,0,0,0,0,0,0,0,0,0,0,0,0,0,0,0,0,0,0,0,0,0
0,0,0,0,0,0,0,0,0,0,0,0,0,0,0,0,0,0,0,0,0,0,0
0,0,0,0,0,0,0,0,0,0,0,0,0,0,0,0,0,0,0,0,0,0,0
0,0,0,0,0,0,0,0,0,0,0,0,0,0,0,0,0,0,0,0,0,0,0
0,0,0,0,0,0,0,0,0,0,0,0,0,0,0,0,0,0,0,0,0,0,0
0,0,0,0,0,0,0,0,0,0,0,0,0,0,0,0,0,0,0,0,0,0,0
0,0,0,0,0,0,0,0,0,0,0,0,0,0,0,0,0,0,0,0,0,0,0
0,0,0,0,0,0,0,0,0,0,0,0,0,0,0,0,0,0,0,0,0,0,0
0,0,0,0,41,41,41,0,0,0,0,0,0,0,0,0,0,0,0,0,0,0,0
0,0,0,41,41,41,41,41,0,0,0,0,0,0,0,0,0,0,0,0,0,0,0
0,0,0,41,41,0,41,41,0,0,0,0,0,0,0,0,0,0,0,0,0,0,0
0,0,0,41,41,41,41,41,0,0,0,0,0,0,0,0,0,0,0,0,0,0,0
0,0,0,0,41,41,41,0,0,0,0,0,0,0,0,0,0,0,0,0,0,0,0
0,0,0,0,0,0,0,0,0,0,0,0,0,0,0,0,0,0,0,0,0,0,0
endlayer

layer
0,0,0,0,0,0,0,0,0,0,0,0,0,0,0,0,0,0,0,0,0,0,0
0,0,0,0,0,0,0,0,0,0,0,0,0,0,0,0,0,0,0,0,0,0,0
0,0,0,0,0,0,0,0,0,0,0,0,0,0,0,0,0,0,0,0,0,0,0
0,0,0,0,0,0,0,0,0,0,0,0,0,0,0,0,0,0,0,0,0,0,0
0,0,0,0,0,0,0,0,0,0,0,0,0,0,0,0,0,0,0,0,0,0,0
0,0,0,0,0,0,0,0,0,0,0,0,0,0,0,0,0,0,0,0,0,0,0
0,0,0,0,0,0,0,0,0,0,0,0,0,0,0,0,0,0,0,0,0,0,0
0,0,0,0,0,0,0,0,0,0,0,0,0,0,0,0,0,0,0,0,0,0,0
0,0,0,0,0,0,0,0,0,0,0,0,0,0,0,0,0,0,0,0,0,0,0
0,0,0,0,0,0,0,0,0,0,0,0,0,0,0,0,0,0,0,0,0,0,0
0,0,0,0,0,0,0,0,0,0,0,0,0,0,0,0,0,0,0,0,0,0,0
0,0,0,0,0,41,0,0,0,0,0,0,0,0,0,0,0,0,0,0,0,0,0
0,0,0,0,0,41,0,0,0,0,0,0,0,0,0,0,0,0,0,0,0,0,0
0,0,0,0,41,41,41,0,0,0,0,0,0,0,0,0,0,0,0,0,0,0,0
0,0,0,0,0,41,0,0,0,0,0,0,0,0,0,0,0,0,0,0,0,0,0
0,0,0,0,0,0,0,0,0,0,0,0,0,0,0,0,0,0,0,0,0,0,0
0,0,0,0,0,0,0,0,0,0,0,0,0,0,0,0,0,0,0,0,0,0,0
endlayer

