
# Created by Ruins mod version 15.0 Ingame Parser
# authoring Player: SunsOfOld

weight=100
embed_into_distance=0
acceptable_target_blocks=
unacceptable_target_blocks=flowing_water,water,flowing_lava,lava
dimensions=11,14,18
allowable_overhang=0
max_leveling=4
leveling_buffer=0
preserve_water=0
preserve_lava=0
uniqueMinDistance=1000000
preventRotation=1

rule1=0,100,minecraft:tallgrass-1
rule2=0,100,ExtrabiomesXL:flower1-1
rule3=0,100,ExtrabiomesXL:flower3-0
rule4=0,100,minecraft:red_flower-0
rule5=0,100,minecraft:yellow_flower-0
rule6=0,100,ExtrabiomesXL:flower3-9
rule7=0,100,ExtrabiomesXL:flower1-2
rule8=0,100,dendrology:sslab1-12
rule9=0,100,ExtrabiomesXL:flower1-3
rule10=0,100,dendrology:logs1-5
rule11=0,100,minecraft:dirt-0
rule12=0,100,ExtrabiomesXL:flower2-12
rule13=0,100,ExtrabiomesXL:flower3-2
rule14=0,100,ExtrabiomesXL:flower3-12
rule15=0,100,ExtrabiomesXL:flower2-1
rule16=0,100,GardenStuff:light_chain-4
rule17=0,100,dendrology:logs1-1
rule18=0,100,dendrology:logs1-9
rule19=0,100,dendrology:leaves1-1

layer
0,1,1,1,0,0,0,0,1,0,0,0,1,0,0,1,0,0
1,1,1,1,0,0,1,0,0,1,0,1,1,0,0,1,0,1
1,1,1,0,0,1,0,0,1,2,0,0,0,0,1,1,1,1
3,1,1,1,0,1,0,0,0,1,0,1,1,1,1,1,1,0
1,1,1,1,0,1,1,1,1,4,1,1,1,1,1,1,1,0
0,1,6,1,1,5,1,1,1,1,1,1,1,0,1,1,0,1
0,0,0,0,0,0,1,1,1,1,0,8,1,0,0,1,0,7
0,0,0,1,0,11,10,0,0,9,0,0,0,0,0,0,0,0
0,0,1,0,0,0,10,0,0,0,0,0,1,0,1,0,0,0
0,0,0,4,1,1,0,0,0,1,1,0,0,0,0,0,1,0
0,1,1,1,1,1,1,12,0,1,0,0,1,1,1,1,1,1
0,1,1,1,1,13,1,0,0,0,0,1,0,1,1,1,5,0
0,15,1,14,0,1,0,0,0,0,0,1,0,1,1,1,1,0
0,0,0,0,1,0,0,0,0,0,0,0,0,0,1,0,0,0
endlayer

layer
0,0,0,0,0,0,0,0,0,0,0,0,0,0,0,0,0,0
0,0,0,0,0,0,0,0,0,0,0,0,0,0,0,0,0,0
0,0,0,0,0,0,0,0,0,0,0,0,0,0,0,0,0,0
0,0,0,0,0,0,0,0,0,0,0,0,0,0,0,0,0,0
0,0,0,0,0,0,0,0,0,0,0,0,0,0,0,0,0,0
0,0,0,0,0,0,0,0,0,0,0,0,0,0,0,0,0,0
0,0,0,0,0,0,0,0,0,0,0,16,0,0,0,0,0,0
0,0,0,0,0,17,17,0,0,0,0,0,0,0,0,0,0,0
0,0,0,0,0,0,0,0,0,0,0,0,0,0,0,0,0,0
0,0,0,0,0,0,0,0,0,0,0,0,0,0,0,0,0,0
0,0,0,0,0,0,0,0,0,0,0,0,0,0,0,0,0,0
0,0,0,0,0,0,0,0,0,0,0,0,0,0,0,0,0,0
0,0,0,0,0,0,0,0,0,0,0,0,0,0,0,0,0,0
0,0,0,0,0,0,0,0,0,0,0,0,0,0,0,0,0,0
endlayer

layer
0,0,0,0,0,0,0,0,0,0,0,0,0,0,0,0,0,0
0,0,0,0,0,0,0,0,0,0,0,0,0,0,0,0,0,0
0,0,0,0,0,0,0,0,0,0,0,0,0,0,0,0,0,0
0,0,0,0,0,0,0,0,0,0,0,0,0,0,0,0,0,0
0,0,0,0,0,0,0,0,0,0,0,0,0,0,0,0,0,0
0,0,0,0,0,0,0,0,0,0,0,0,0,0,0,0,0,0
0,0,0,0,0,0,0,0,0,0,0,16,0,0,0,0,0,0
0,0,0,0,0,0,17,0,0,0,0,0,0,0,0,0,0,0
0,0,0,0,0,0,0,0,0,0,0,0,0,0,0,0,0,0
0,0,0,0,0,0,0,0,0,0,0,0,0,0,0,0,0,0
0,0,0,0,0,0,0,0,0,0,0,0,0,0,0,0,0,0
0,0,0,0,0,0,0,0,0,0,0,0,0,0,0,0,0,0
0,0,0,0,0,0,0,0,0,0,0,0,0,0,0,0,0,0
0,0,0,0,0,0,0,0,0,0,0,0,0,0,0,0,0,0
endlayer

layer
0,0,0,0,0,0,0,0,0,0,0,0,0,0,0,0,0,0
0,0,0,0,0,0,0,0,0,0,0,0,0,0,0,0,0,0
0,0,0,0,0,0,0,0,0,0,0,0,0,0,0,0,0,0
0,0,0,0,0,0,0,0,0,0,0,0,0,0,0,0,0,0
0,0,0,0,0,0,0,0,0,0,0,0,0,0,0,0,0,0
0,0,0,0,0,0,0,0,0,0,0,0,0,0,0,0,0,0
0,0,0,0,0,0,0,0,0,0,0,16,0,0,0,0,0,0
0,0,0,0,0,0,0,18,0,0,0,0,0,0,0,0,0,0
0,0,0,0,0,0,0,0,0,0,0,0,0,0,0,0,0,0
0,0,0,0,0,0,0,0,0,0,0,0,0,0,0,0,0,0
0,0,0,0,0,0,0,0,0,0,0,0,0,0,0,0,0,0
0,0,0,0,0,0,0,0,0,0,0,0,0,0,0,0,0,0
0,0,0,0,0,0,0,0,0,0,0,0,0,0,0,0,0,0
0,0,0,0,0,0,0,0,0,0,0,0,0,0,0,0,0,0
endlayer

layer
0,0,0,0,0,0,0,0,0,0,0,0,0,0,0,0,0,0
0,0,0,0,0,0,0,0,0,0,0,0,0,0,0,0,0,0
0,0,0,0,0,0,0,0,0,0,0,0,0,0,0,0,0,0
0,0,0,0,0,0,0,0,0,0,0,0,0,0,0,0,0,0
0,0,0,0,0,0,0,0,0,0,0,0,0,0,0,0,0,0
0,0,0,0,0,0,0,0,0,0,0,0,0,0,0,0,0,0
0,0,0,0,0,0,0,0,0,0,0,16,0,0,0,0,0,0
0,0,0,0,0,0,0,0,18,0,0,0,0,0,0,0,0,0
0,0,0,0,0,0,0,0,0,0,0,0,0,0,0,0,0,0
0,0,0,0,0,0,0,0,0,0,0,0,0,0,0,0,0,0
0,0,0,0,0,0,0,0,0,0,0,0,0,0,0,0,0,0
0,0,0,0,0,0,0,0,0,0,0,0,0,0,0,0,0,0
0,0,0,0,0,0,0,0,0,0,0,0,0,0,0,0,0,0
0,0,0,0,0,0,0,0,0,0,0,0,0,0,0,0,0,0
endlayer

layer
0,0,0,0,0,0,0,0,0,0,0,0,0,0,0,0,0,0
0,0,0,0,0,0,0,0,0,0,0,0,0,0,0,0,0,0
0,0,0,0,0,0,0,0,0,0,0,0,0,0,0,0,0,0
0,0,0,0,0,0,0,0,0,0,0,0,0,0,0,0,0,0
0,0,0,0,0,0,0,0,0,0,0,0,0,0,0,0,0,0
0,0,0,0,0,0,0,0,0,0,0,0,0,0,0,0,0,0
0,0,0,0,0,0,0,0,0,0,0,16,18,0,0,0,0,0
0,0,0,0,0,0,0,0,18,18,18,18,18,0,0,0,0,0
0,0,0,0,0,0,0,0,0,0,0,0,0,0,0,0,0,0
0,0,0,0,0,0,0,0,0,0,0,0,0,0,0,0,0,0
0,0,0,0,0,0,0,0,0,0,0,0,0,0,0,0,0,0
0,0,0,0,0,0,0,0,0,0,0,0,0,0,0,0,0,0
0,0,0,0,0,0,0,0,0,0,0,0,0,0,0,0,0,0
0,0,0,0,0,0,0,0,0,0,0,0,0,0,0,0,0,0
endlayer

layer
0,0,0,0,0,0,0,0,0,0,0,0,0,0,0,0,0,0
0,0,0,0,0,0,0,0,0,0,0,19,19,19,0,0,0,0
0,0,0,0,0,0,0,0,0,0,19,19,19,19,19,0,0,0
0,0,0,0,0,0,0,0,0,19,19,19,19,19,19,19,0,0
0,0,0,0,0,0,0,0,0,19,19,19,18,19,19,19,0,0
0,0,0,0,0,0,0,0,0,19,19,19,18,19,19,19,0,0
0,0,0,0,0,0,0,18,0,0,19,19,19,19,19,0,0,0
0,0,0,0,0,0,0,0,0,0,18,19,18,19,0,0,0,0
0,0,0,0,0,0,0,18,0,0,0,0,0,0,0,0,0,0
0,0,0,0,0,0,0,0,0,0,0,0,0,0,0,0,0,0
0,0,0,0,0,0,0,0,0,0,0,0,0,0,0,0,0,0
0,0,0,0,0,0,0,0,0,0,0,0,0,0,0,0,0,0
0,0,0,0,0,0,0,0,0,0,0,0,0,0,0,0,0,0
0,0,0,0,0,0,0,0,0,0,0,0,0,0,0,0,0,0
endlayer

layer
0,0,0,0,0,0,0,0,0,0,0,0,0,0,0,0,0,0
0,0,0,0,0,0,0,0,0,0,0,0,0,0,0,0,0,0
0,0,0,0,0,0,0,0,0,0,0,19,19,19,0,0,0,0
0,0,0,0,0,19,19,19,0,0,19,19,19,19,19,0,0,0
0,0,0,0,19,19,19,19,19,0,19,19,19,19,19,0,0,0
0,0,0,19,19,19,19,19,19,19,19,19,19,19,19,19,0,0
0,0,0,19,19,19,18,19,19,19,18,19,19,19,19,19,19,0
0,0,0,19,19,19,19,19,0,19,18,18,19,18,19,19,19,0
0,0,0,19,19,19,19,19,0,19,19,19,19,19,19,19,19,0
0,0,0,19,19,19,18,19,19,19,0,19,19,19,19,19,0,0
0,0,0,19,19,19,19,19,19,19,0,0,19,19,19,0,0,0
0,0,0,0,19,19,19,19,19,0,0,0,0,0,0,0,0,0
0,0,0,0,0,19,19,19,0,0,0,0,0,0,0,0,0,0
0,0,0,0,0,0,0,0,0,0,0,0,0,0,0,0,0,0
endlayer

layer
0,0,0,0,0,0,0,0,0,0,0,0,0,0,0,0,0,0
0,0,0,0,0,0,0,0,0,0,0,0,0,0,0,0,0,0
0,0,0,0,0,0,0,0,0,0,0,0,0,0,0,0,0,0
0,0,0,0,0,0,0,0,0,0,0,0,0,0,0,0,0,0
0,0,0,0,0,19,19,19,0,0,19,19,19,0,0,0,0,0
0,0,0,0,19,19,19,19,19,19,19,19,19,19,19,0,0,0
0,0,0,0,19,19,19,19,19,18,19,19,19,19,19,19,0,0
0,0,0,0,19,19,19,19,19,19,19,18,19,19,19,19,0,0
0,0,0,0,19,19,19,19,19,18,19,19,19,19,19,19,0,0
0,0,0,0,19,19,19,19,19,19,19,19,19,19,19,0,0,0
0,0,0,0,19,19,19,19,19,0,19,19,19,0,0,0,0,0
0,0,0,0,0,19,19,19,0,0,0,0,0,0,0,0,0,0
0,0,0,0,0,0,0,0,0,0,0,0,0,0,0,0,0,0
0,0,0,0,0,0,0,0,0,0,0,0,0,0,0,0,0,0
endlayer

layer
0,0,0,0,0,0,0,0,0,0,0,0,0,0,0,0,0,0
0,0,0,0,0,0,0,0,0,0,0,0,0,0,0,0,0,0
0,0,0,0,0,0,0,19,19,19,0,0,0,0,0,0,0,0
0,0,0,0,0,0,19,19,19,19,19,0,0,0,0,0,0,0
0,0,0,0,0,19,19,19,19,19,19,19,0,0,0,0,0,0
0,0,0,0,0,19,19,19,18,19,19,19,19,0,0,0,0,0
0,0,0,0,0,19,19,19,19,19,19,19,19,19,0,0,0,0
0,0,0,0,0,0,19,19,19,19,19,19,19,19,0,0,0,0
0,0,0,0,0,0,19,19,19,19,19,19,19,19,0,0,0,0
0,0,0,0,0,0,19,19,19,18,19,19,19,0,0,0,0,0
0,0,0,0,0,0,19,19,19,19,19,19,19,0,0,0,0,0
0,0,0,0,0,0,0,19,19,19,19,19,0,0,0,0,0,0
0,0,0,0,0,0,0,0,19,19,19,0,0,0,0,0,0,0
0,0,0,0,0,0,0,0,0,0,0,0,0,0,0,0,0,0
endlayer

layer
0,0,0,0,0,0,0,0,0,0,0,0,0,0,0,0,0,0
0,0,0,0,0,0,0,0,0,0,0,0,0,0,0,0,0,0
0,0,0,0,0,0,0,0,0,0,0,0,0,0,0,0,0,0
0,0,0,0,0,0,0,19,19,19,0,0,0,0,0,0,0,0
0,0,0,0,0,0,19,19,19,19,19,0,0,0,0,0,0,0
0,0,0,0,0,0,19,19,19,19,19,0,0,0,0,0,0,0
0,0,0,0,0,0,19,19,19,19,19,0,0,0,0,0,0,0
0,0,0,0,0,0,0,19,19,19,19,0,0,0,0,0,0,0
0,0,0,0,0,0,0,19,19,19,19,19,0,0,0,0,0,0
0,0,0,0,0,0,0,19,19,19,19,19,0,0,0,0,0,0
0,0,0,0,0,0,0,19,19,19,19,19,0,0,0,0,0,0
0,0,0,0,0,0,0,0,19,19,19,0,0,0,0,0,0,0
0,0,0,0,0,0,0,0,0,0,0,0,0,0,0,0,0,0
0,0,0,0,0,0,0,0,0,0,0,0,0,0,0,0,0,0
endlayer

