
# Created by Ruins mod version 15.0 Ingame Parser
# authoring Player: SunsOfOld

weight=100
embed_into_distance=1
acceptable_target_blocks=
unacceptable_target_blocks=flowing_water,water,flowing_lava,lava
dimensions=19,25,19
allowable_overhang=0
max_leveling=5
leveling_buffer=0
preserve_water=0
preserve_lava=0
uniqueMinDistance=1000000
preventRotation=1

rule1=0,100,minecraft:snow-0
rule2=0,100,minecraft:dirt-0
rule3=0,100,BiomesOPlenty:cherryStairs-0
rule4=0,100,dendrology:leaves0-14
rule5=0,100,BiomesOPlenty:cherryStairs-2
rule6=0,100,chisel:fantasyblock2-1
rule7=0,100,BiomesOPlenty:cherryStairs-3
rule8=0,100,chisel:carpet_block-10
rule9=0,100,dendrology:logs0-2
rule10=0,100,dendrology:leaves0-6
rule11=0,100,chisel:packedice-4
rule12=0,100,chisel:glowstone-4
rule13=0,100,ExtrabiomesXL:stairs.cypress-0
rule14=0,100,BiomesOPlenty:cherryStairs-1
rule15=0,100,chisel:packedice-12
rule16=0,100,ExtrabiomesXL:planks-3
rule17=0,100,minecraft:quartz_stairs-4
rule18=0,100,minecraft:furnace-3
rule19=0,100,ExtrabiomesXL:door_japanesemaple-1
rule20=0,100,ChestGenHook:dungeonChest:5-2
rule21=0,100,minecraft:quartz_stairs-6
rule22=0,100,minecraft:crafting_table-0
rule23=0,100,chisel:marble_stairs.0-7
rule24=0,100,chisel:marble-0
rule25=0,100,minecraft:quartz_block-0
rule26=0,100,minecraft:quartz_stairs-1
rule27=0,100,chisel:marble_stairs.0-5
rule28=0,100,ExtrabiomesXL:door_japanesemaple-2
rule29=0,100,chisel:carpet-10
rule30=0,100,minecraft:quartz_stairs-7
rule31=0,100,minecraft:quartz_stairs-5
rule32=0,100,chisel:stained_glass_pane_red-3
rule33=0,100,ExtrabiomesXL:door_japanesemaple-9
rule34=0,100,ExtrabiomesXL:door_japanesemaple-8
rule35=0,100,dendrology:leaves0-2
rule36=0,100,minecraft:lit_redstone_lamp-0
rule37=0,100,minecraft:redstone_block-0
rule38=0,100,chisel:marble_stairs.0-1
rule39=0,100,ExtrabiomesXL:log1-10
rule40=0,100,ExtrabiomesXL:log1-6
rule41=0,100,minecraft:stone_slab-15
rule42=0,100,minecraft:stone_slab-7
rule43=0,100,minecraft:double_stone_slab-7
rule44=0,100,BiomesOPlenty:planks-1
rule45=0,100,ExtrabiomesXL:door_japanesemaple-0
rule46=0,100,CarpentersBlocks:blockCarpentersLadder-4
rule47=0,100,minecraft:bookshelf-0
rule48=0,100,ChestGenHook:dungeonChest:5-5
rule49=0,100,minecraft:bed-10
rule50=0,100,minecraft:bed-2
rule51=0,100,ChestGenHook:dungeonChest:5-4
rule52=0,100,chisel:packedice_stairs.4-2
rule53=0,100,chisel:packedice_stairs.4-0
rule54=0,100,chisel:packedice_stairs.4-3
rule55=0,100,BiomesOPlenty:woodenSingleSlab1-9
rule56=0,100,chisel:packedice_stairs.4-1
rule57=0,100,minecraft:log-0
rule58=0,100,minecraft:log-3
rule59=0,100,harvestcraft:pamLime-1
rule60=0,100,harvestcraft:pamLime-0
rule61=0,100,harvestcraft:pamLime-2
rule62=0,100,minecraft:leaves-3
rule63=0,100,harvestcraft:pamCherry-1
rule64=0,100,harvestcraft:pamCherry-0
rule65=0,100,harvestcraft:pamCherry-2
rule66=0,100,harvestcraft:pamPapaya-1
rule67=0,100,harvestcraft:pamPapaya-0
rule68=0,100,harvestcraft:pamPapaya-2
rule69=0,100,harvestcraft:pamBanana-0
rule70=0,100,harvestcraft:pamBanana-2
rule71=0,100,harvestcraft:pamBanana-1
rule72=0,100,minecraft:leaves-0

layer
1,1,1,1,1,1,1,1,1,1,1,1,1,1,1,1,1,1,1
1,1,1,1,1,1,1,1,1,1,1,1,1,1,1,1,1,1,1
1,1,1,1,1,1,1,1,1,1,1,1,1,1,1,1,1,1,1
1,1,1,1,1,1,1,1,1,1,1,1,1,1,2,1,1,1,1
1,1,1,1,1,1,1,1,1,1,1,1,1,1,1,1,1,1,1
1,1,1,1,1,1,1,1,1,1,1,1,1,1,1,1,1,1,1
1,1,1,1,1,1,1,1,1,1,1,1,1,1,1,1,1,1,1
1,1,1,1,1,1,1,1,1,1,1,1,1,1,1,1,1,1,1
1,1,1,1,1,1,1,1,1,1,1,1,1,1,1,1,1,1,1
1,1,1,1,1,1,1,1,1,1,1,1,1,1,1,1,1,1,1
1,1,1,1,1,1,1,1,1,1,1,1,1,1,1,1,1,1,1
1,1,1,1,1,1,1,1,1,1,1,1,1,1,1,1,1,1,1
1,1,1,1,1,1,1,1,1,1,1,1,1,1,1,1,1,1,1
1,1,1,1,1,1,1,1,1,1,1,1,1,1,1,1,1,1,1
1,1,1,1,1,1,1,1,1,1,1,1,1,1,1,1,1,1,1
1,1,1,1,1,1,1,1,1,1,1,1,1,1,1,1,1,1,1
1,1,1,1,1,1,1,1,1,1,1,1,1,1,1,1,1,1,1
1,1,1,1,1,1,1,1,1,1,1,1,1,1,1,1,1,1,1
1,1,1,1,1,1,1,1,1,1,1,1,1,1,1,1,1,1,1
1,1,1,1,1,1,1,1,1,1,1,1,1,1,1,1,1,1,1
1,1,1,1,1,1,1,1,1,1,1,1,1,1,1,1,1,1,1
1,1,1,1,1,1,1,1,1,1,1,1,1,1,1,1,1,1,1
1,1,1,1,1,1,1,1,1,1,1,1,1,1,1,1,1,1,1
1,1,1,1,1,1,1,1,1,1,1,1,1,1,1,1,1,1,1
1,1,1,1,1,1,1,1,1,1,1,1,1,1,1,1,1,1,1
endlayer

layer
3,3,4,4,4,3,3,3,3,3,0,0,0,0,0,0,0,0,0
7,6,6,6,6,6,6,6,6,5,0,0,0,0,0,0,0,0,0
7,6,8,8,8,8,8,8,6,4,0,0,0,0,0,0,0,0,0
7,6,8,8,8,8,8,8,6,10,0,0,0,0,9,0,0,0,0
7,6,11,11,8,8,8,8,6,4,0,0,0,0,0,0,0,0,0
7,6,11,11,8,8,8,8,6,4,0,0,0,0,0,0,0,0,0
7,6,11,11,8,8,8,8,6,4,0,0,0,0,0,0,0,0,0
7,6,11,11,8,8,8,8,6,4,0,0,0,0,0,0,0,0,0
7,6,8,8,8,8,8,8,6,4,0,0,0,0,0,0,0,0,0
7,6,8,8,8,8,8,8,6,4,0,0,0,0,0,0,0,0,0
7,6,8,8,12,12,12,12,6,4,0,0,0,0,0,0,0,0,0
7,6,8,8,8,8,8,8,6,4,0,0,0,0,0,0,0,0,0
7,6,8,8,8,8,8,8,6,4,13,13,4,10,10,0,0,0,0
7,6,8,8,8,8,8,8,6,6,6,6,6,6,4,0,0,0,0
4,6,8,12,8,8,8,8,8,12,8,8,12,6,5,0,0,0,0
4,6,6,6,12,8,8,8,8,8,8,8,8,6,5,0,0,0,0
4,4,4,6,8,8,8,8,8,8,8,8,8,6,5,0,0,0,0
4,4,4,6,8,8,8,8,8,8,8,8,8,6,4,0,0,0,0
0,0,4,6,8,8,8,8,8,8,8,8,8,6,4,0,0,0,0
0,0,7,6,12,8,8,8,8,12,8,8,12,6,4,0,0,0,0
0,0,7,6,6,6,6,6,6,6,6,6,6,6,4,0,0,0,0
0,0,7,14,14,4,4,4,4,4,4,4,4,4,4,0,0,0,0
0,0,0,0,0,0,0,0,0,0,0,0,0,0,0,0,0,0,0
0,0,0,0,0,0,0,0,0,0,0,0,0,0,0,0,0,0,0
0,0,0,0,0,0,0,0,0,0,0,0,0,0,0,0,0,0,0
endlayer

layer
0,0,0,0,0,0,0,0,0,0,0,0,0,0,0,0,0,0,0
0,15,16,17,17,17,17,16,15,0,0,0,0,0,0,0,0,0,0
0,16,20,19,0,0,0,18,16,0,0,0,0,0,0,0,0,0,0
0,16,20,19,0,0,0,22,21,0,0,0,0,0,9,0,0,0,0
0,16,25,25,24,0,0,23,21,0,0,0,0,0,0,0,0,0,0
0,16,25,25,24,0,0,23,21,0,0,0,0,0,0,0,0,0,0
0,16,25,25,24,0,0,23,21,0,0,0,0,0,0,0,0,0,0
0,16,26,26,24,0,0,23,21,0,0,0,0,0,0,0,0,0,0
0,16,0,0,24,0,0,23,21,0,0,0,0,0,0,0,0,0,0
0,16,0,0,27,28,27,27,21,0,0,0,0,0,0,0,0,0,0
0,30,0,0,29,29,29,29,21,0,0,0,0,0,0,0,0,0,0
0,30,0,0,0,0,0,0,21,0,0,0,0,0,0,0,0,0,0
0,30,0,0,0,0,0,0,16,0,0,0,0,0,0,0,0,0,0
0,30,0,0,0,0,0,0,15,16,28,28,16,15,0,0,0,0,0
0,16,0,29,0,0,0,0,0,29,0,0,29,16,0,0,0,0,0
4,15,16,15,29,0,0,0,0,0,0,0,0,21,0,0,0,0,0
0,4,4,16,0,0,0,0,0,0,0,0,0,21,0,0,0,0,0
0,0,0,30,0,0,0,0,0,0,0,0,0,21,0,0,0,0,0
0,0,0,30,0,0,0,0,0,0,0,0,0,21,0,0,0,0,0
0,0,0,16,29,0,0,0,0,29,0,0,29,16,0,0,0,0,0
0,0,0,15,16,31,31,31,31,31,31,31,16,15,4,0,0,0,0
0,0,0,0,0,0,0,0,0,0,0,4,0,4,0,0,0,0,0
0,0,0,0,0,0,0,0,0,0,0,0,0,0,0,0,0,0,0
0,0,0,0,0,0,0,0,0,0,0,0,0,0,0,0,0,0,0
0,0,0,0,0,0,0,0,0,0,0,0,0,0,0,0,0,0,0
endlayer

layer
0,0,0,0,0,0,0,0,0,0,0,0,0,0,0,0,0,0,0
0,15,16,32,32,32,32,16,15,0,0,0,0,0,0,0,0,0,0
0,16,20,33,0,0,0,29,16,0,0,0,0,0,0,0,0,0,0
0,16,20,34,0,0,0,29,32,0,0,0,0,0,9,0,0,0,0
0,16,25,25,0,0,0,29,32,0,0,0,0,0,35,0,0,0,0
0,16,37,36,0,0,0,29,32,0,0,0,0,35,0,0,0,0,0
0,16,26,26,24,0,0,29,32,0,0,0,0,0,0,0,0,0,0
0,16,0,0,24,0,0,29,32,0,0,0,0,0,0,0,0,0,0
0,16,0,0,38,0,0,29,32,0,0,0,0,0,0,0,0,0,0
0,16,0,0,0,34,29,29,32,0,0,0,0,0,0,0,0,0,0
0,32,0,0,0,0,0,0,32,0,0,0,0,0,0,0,0,0,0
0,32,0,0,0,0,0,0,32,0,0,0,0,0,0,0,0,0,0
0,32,0,0,0,0,0,0,16,0,0,0,0,0,0,0,0,0,0
0,32,0,0,0,0,0,0,15,16,34,33,16,15,0,0,0,0,0
0,16,0,0,0,0,0,0,0,0,0,0,0,16,0,0,0,0,0
0,15,16,15,0,0,0,0,0,0,0,0,0,32,0,0,0,0,0
0,4,0,16,0,0,0,0,0,0,0,0,0,32,0,0,0,0,0
0,0,0,32,0,0,0,0,0,0,0,0,0,32,0,0,0,0,0
0,0,0,32,0,0,0,0,0,0,0,0,0,32,0,0,0,0,0
0,0,0,16,0,0,0,0,0,0,0,0,0,16,0,0,0,0,0
0,0,0,15,16,32,32,32,32,32,32,32,16,15,0,0,0,0,0
0,0,0,0,0,0,0,0,0,0,0,0,0,0,0,0,0,0,0
0,0,0,0,0,0,0,0,0,0,0,0,0,0,0,0,0,0,0
0,0,0,0,0,0,0,0,0,0,0,0,0,0,0,0,0,0,0
0,0,0,0,0,0,0,0,0,0,0,0,0,0,0,0,0,0,0
endlayer

layer
0,0,0,0,0,0,0,0,0,0,0,0,0,0,0,0,0,0,0
0,15,39,39,39,39,39,39,15,0,0,0,0,10,4,4,0,0,0
0,40,0,21,0,0,0,0,40,0,0,0,0,10,35,4,0,0,0
0,40,0,21,0,0,0,0,40,0,0,0,0,35,9,35,0,0,0
0,40,25,25,0,0,0,0,40,0,0,0,35,35,35,35,35,0,0
0,40,26,26,24,0,0,0,40,0,0,0,35,35,35,35,35,0,0
0,40,0,0,24,0,0,0,40,0,0,0,0,35,35,35,0,0,0
0,40,0,0,38,0,0,0,40,0,0,0,0,0,0,0,0,0,0
0,40,0,0,0,0,0,0,40,0,0,0,0,0,0,0,0,0,0
0,40,17,17,17,17,17,17,40,0,0,0,0,0,0,0,0,0,0
0,40,31,31,31,31,31,31,40,0,0,0,0,0,0,0,0,0,0
0,40,0,0,0,0,0,0,40,0,0,0,0,0,0,0,0,0,0
0,40,0,0,0,0,0,0,40,0,0,0,0,0,0,0,0,0,0
0,40,0,0,0,0,0,0,15,39,39,39,39,15,0,0,0,0,0
0,40,0,0,0,0,0,0,0,0,0,0,0,40,0,0,0,0,0
0,15,39,15,0,0,0,0,0,0,0,0,0,40,0,0,0,0,0
0,0,0,40,0,0,0,0,0,0,0,0,0,40,0,0,0,0,0
0,0,0,40,0,0,0,0,0,0,0,0,0,40,0,0,0,0,0
0,0,0,40,0,0,0,0,0,0,0,0,0,40,0,0,0,0,0
0,0,0,40,0,0,0,0,0,0,0,0,0,40,0,0,0,0,0
0,0,0,15,39,39,39,39,39,39,39,39,39,15,0,0,0,0,0
0,0,0,0,0,0,0,0,0,0,0,0,0,0,0,0,0,0,0
0,0,0,0,0,0,0,0,0,0,0,0,0,0,0,0,0,0,0
0,0,0,0,0,0,0,0,0,0,0,0,0,0,0,0,0,0,0
0,0,0,0,0,0,0,0,0,0,0,0,0,0,0,0,0,0,0
endlayer

layer
10,4,4,4,4,4,4,4,4,4,0,0,0,0,0,0,0,0,0
10,15,39,39,39,39,39,39,39,4,0,0,0,35,35,35,0,0,0
10,40,21,31,31,31,31,30,40,4,0,0,35,35,35,35,35,0,0
10,40,21,17,17,41,41,30,40,4,0,0,35,35,9,35,35,0,0
10,40,42,42,21,41,41,30,40,4,0,0,35,35,35,35,35,0,0
4,40,0,0,21,41,41,30,40,4,0,0,35,35,35,35,35,0,0
4,40,0,0,21,41,41,30,40,4,0,0,0,35,35,0,0,0,0
4,40,0,0,21,41,41,30,40,4,0,0,0,0,0,0,0,0,0
4,40,0,0,21,41,41,30,40,4,0,0,0,0,0,0,0,0,0
4,40,43,43,21,41,41,30,40,4,0,0,0,0,0,0,0,0,0
4,40,43,43,21,41,41,30,40,4,0,0,0,0,0,0,0,0,0
4,40,31,31,31,41,41,30,40,4,0,0,0,0,0,0,0,0,0
4,40,21,41,41,41,41,30,40,4,4,4,4,10,10,0,0,0,0
4,40,21,41,41,41,41,30,40,39,39,39,39,39,10,0,0,0,0
4,40,17,17,21,41,41,31,31,31,31,31,31,40,4,0,0,0,0
10,39,39,40,21,41,41,41,41,41,41,41,30,40,4,0,0,0,0
10,4,4,40,21,41,41,41,41,41,41,41,30,40,4,0,0,0,0
0,0,4,40,21,41,41,41,41,41,41,41,30,40,4,0,0,0,0
0,0,4,40,21,41,41,41,41,41,41,41,30,40,4,0,0,0,0
0,0,4,40,17,17,17,17,17,17,17,17,30,40,4,0,0,0,0
0,0,4,39,39,39,39,39,39,39,39,39,39,39,4,0,0,0,0
0,0,4,4,4,4,4,4,4,4,4,4,4,4,4,0,0,0,0
0,0,0,0,0,0,0,0,0,0,0,0,0,0,0,0,0,0,0
0,0,0,0,0,0,0,0,0,0,0,0,0,0,0,0,0,0,0
0,0,0,0,0,0,0,0,0,0,0,0,0,0,0,0,0,0,0
endlayer

layer
3,3,3,3,3,3,3,3,3,5,0,0,0,0,0,0,0,0,0
7,44,44,44,44,44,44,44,44,5,0,0,0,35,35,35,0,0,0
7,44,0,0,0,0,0,0,44,5,0,0,35,35,35,35,35,0,0
7,44,0,0,0,0,0,0,44,5,0,0,35,35,35,35,35,0,0
7,44,0,0,0,0,0,0,44,5,0,0,35,35,35,35,35,0,0
7,44,0,0,0,0,0,0,44,5,0,0,0,35,35,35,0,0,0
7,44,0,0,0,0,0,0,44,5,0,0,0,0,0,0,0,0,0
7,44,0,0,0,0,0,0,44,5,0,0,0,0,0,0,0,0,0
7,44,0,0,0,0,0,0,44,5,0,0,0,0,0,0,0,0,0
7,44,0,0,0,0,0,0,44,5,0,0,0,0,0,0,0,0,0
7,44,0,0,0,0,0,0,44,5,0,0,0,0,0,0,0,0,0
7,44,0,0,0,0,0,0,44,5,0,0,0,0,0,0,0,0,0
7,44,44,45,44,0,0,0,44,3,3,3,3,3,5,0,0,0,0
7,44,44,46,44,25,45,25,44,44,44,44,44,44,5,0,0,0,0
7,44,44,44,44,0,0,0,0,0,48,47,47,44,5,0,0,0,0
7,44,44,44,0,0,0,0,0,0,0,0,0,44,5,0,0,0,0
7,14,7,44,0,0,0,0,0,0,0,50,49,44,5,0,0,0,0
0,0,7,44,0,0,0,0,0,0,0,50,49,44,5,0,0,0,0
0,0,7,44,0,0,0,0,0,0,0,0,0,44,5,0,0,0,0
0,0,7,44,0,0,0,0,0,0,51,47,47,44,5,0,0,0,0
0,0,7,44,44,44,44,44,44,44,44,44,44,44,5,0,0,0,0
0,0,14,14,14,14,14,14,14,14,14,14,14,14,14,0,0,0,0
0,0,0,0,0,0,0,0,0,0,0,0,0,0,0,0,0,0,0
0,0,0,0,0,0,0,0,0,0,0,0,0,0,0,0,0,0,0
0,0,0,0,0,0,0,0,0,0,0,0,0,0,0,0,0,0,0
endlayer

layer
0,0,0,0,0,0,0,0,0,0,0,0,0,0,0,0,0,0,0
0,15,32,32,32,32,32,32,15,0,0,0,0,0,0,0,0,0,0
0,32,0,0,0,0,0,0,32,0,0,0,0,0,35,0,0,0,0
0,32,0,0,0,0,0,0,32,0,0,0,0,35,35,35,0,0,0
0,32,0,0,0,0,0,0,32,0,0,0,0,0,35,0,0,0,0
0,32,0,0,0,0,0,0,32,0,0,0,0,0,0,0,0,0,0
0,32,0,0,0,0,0,0,32,0,0,0,0,0,0,0,0,0,0
0,32,0,0,0,0,0,0,32,0,0,0,0,0,0,0,0,0,0
0,32,0,0,0,0,0,0,32,0,0,0,0,0,0,0,0,0,0
0,32,0,0,0,0,0,0,32,0,0,0,0,0,0,0,0,0,0
0,32,0,0,0,0,0,0,32,0,0,0,0,0,0,0,0,0,0
0,32,0,0,0,0,0,0,32,0,0,0,0,0,0,0,0,0,0
0,32,44,34,44,0,0,0,32,0,0,0,0,0,0,0,0,0,0
0,32,44,46,44,25,34,25,15,32,32,32,32,15,0,0,0,0,0
0,32,44,44,44,0,0,0,0,0,0,0,0,32,0,0,0,0,0
0,15,32,15,0,0,0,0,0,0,0,0,0,32,0,0,0,0,0
0,0,0,32,0,0,0,0,0,0,0,0,0,32,0,0,0,0,0
0,0,0,32,0,0,0,0,0,0,0,0,0,32,0,0,0,0,0
0,0,0,32,0,0,0,0,0,0,0,0,0,32,0,0,0,0,0
0,0,0,32,0,0,0,0,0,0,0,0,0,32,0,0,0,0,0
0,0,0,15,32,32,32,32,32,32,32,32,32,15,0,0,0,0,0
0,0,0,0,0,0,0,0,0,0,0,0,0,0,0,0,0,0,0
0,0,0,0,0,0,0,0,0,0,0,0,0,0,0,0,0,0,0
0,0,0,0,0,0,0,0,0,0,0,0,0,0,0,0,0,0,0
0,0,0,0,0,0,0,0,0,0,0,0,0,0,0,0,0,0,0
endlayer

layer
0,0,0,0,0,0,0,0,0,0,0,0,0,0,0,0,0,0,0
0,15,39,39,39,39,39,39,15,0,0,0,0,0,0,0,0,0,0
0,40,0,0,0,0,0,0,40,0,0,0,0,0,0,0,0,0,0
0,40,0,0,0,0,0,0,40,0,0,0,0,0,0,0,0,0,0
0,40,0,0,0,0,0,0,40,0,0,0,0,0,0,0,0,0,0
0,40,0,0,0,0,0,0,40,0,0,0,0,0,0,0,0,0,0
0,40,0,0,0,0,0,0,40,0,0,0,0,0,0,0,0,0,0
0,40,0,0,0,0,0,0,40,0,0,0,0,0,0,0,0,0,0
0,40,0,0,0,0,0,0,40,0,0,0,0,0,0,0,0,0,0
0,40,0,0,0,0,0,0,40,0,0,0,0,0,0,0,0,0,0
0,40,0,0,0,0,0,0,40,0,0,0,0,0,0,0,0,0,0
0,40,0,0,0,0,0,0,40,0,0,0,0,0,0,0,0,0,0
0,40,44,44,44,0,0,0,40,0,0,0,0,0,0,0,0,0,0
0,40,44,46,44,25,25,25,15,39,39,39,39,15,0,0,0,0,0
0,40,44,44,44,0,0,0,0,0,0,0,0,40,0,0,0,0,0
0,15,39,15,0,0,0,0,0,0,0,0,0,40,0,0,0,0,0
0,0,0,40,0,0,0,0,0,0,0,0,0,40,0,0,0,0,0
0,0,0,40,0,0,0,0,0,0,0,0,0,40,0,0,0,0,0
0,0,0,40,0,0,0,0,0,0,0,0,0,40,0,0,0,0,0
0,0,0,40,0,0,0,0,0,0,0,0,0,40,0,0,0,0,0
0,0,0,15,39,39,39,39,39,39,39,39,39,15,0,0,0,0,0
0,0,0,0,0,0,0,0,0,0,0,0,0,0,0,0,0,0,0
0,0,0,0,0,0,0,0,0,0,0,0,0,0,0,0,0,0,0
0,0,0,0,0,0,0,0,0,0,0,0,0,0,0,0,0,0,0
0,0,0,0,0,0,0,0,0,0,0,0,0,0,0,0,0,0,0
endlayer

layer
0,0,0,0,0,0,0,0,0,0,0,0,0,0,0,0,0,0,0
0,53,53,53,53,53,53,53,52,0,0,0,0,0,0,0,0,0,0
0,54,0,0,0,0,0,0,52,0,0,0,0,0,0,0,0,0,0
0,54,0,55,55,55,55,0,52,0,0,0,0,0,0,0,0,0,0
0,54,0,55,55,55,55,0,52,0,0,0,0,0,0,0,0,0,0
0,54,0,55,55,55,55,0,52,0,0,0,0,0,0,0,0,0,0
0,54,0,55,55,55,55,0,52,0,0,0,0,0,0,0,0,0,0
0,54,0,55,55,55,55,0,52,0,0,0,0,0,0,0,0,0,0
0,54,0,55,55,55,55,0,52,0,0,0,0,0,0,0,0,0,0
0,54,0,55,55,55,55,0,52,0,0,0,0,0,0,0,0,0,0
0,54,0,55,55,55,55,0,52,0,0,0,0,0,0,0,0,0,0
0,54,0,55,55,55,55,0,52,0,0,0,0,0,0,0,0,0,0
0,54,44,44,44,55,55,0,52,0,0,0,0,0,0,0,0,0,0
0,54,44,46,55,25,25,25,52,53,53,53,53,52,0,0,0,0,0
0,54,44,44,44,55,55,0,0,0,0,0,0,52,0,0,0,0,0
0,56,56,56,0,55,55,55,55,55,55,55,0,52,0,0,0,0,0
0,0,0,54,0,55,55,55,55,55,55,55,0,52,0,0,0,0,0
0,0,0,54,0,55,55,55,55,55,55,55,0,52,0,0,0,0,0
0,0,0,54,0,55,55,55,55,55,55,55,0,52,0,0,0,0,0
0,0,0,54,0,0,0,0,0,0,0,0,0,52,0,0,0,0,0
0,0,0,54,56,56,56,56,56,56,56,56,56,56,0,0,0,0,0
0,0,0,0,0,0,0,0,0,0,0,0,0,0,0,0,0,0,0
0,0,0,0,0,0,0,0,0,0,0,0,0,0,0,0,0,0,0
0,0,0,0,0,0,0,0,0,0,0,0,0,0,0,0,0,0,0
0,0,0,0,0,0,0,0,0,0,0,0,0,0,0,0,0,0,0
endlayer

layer
0,0,0,0,0,0,0,0,0,0,0,0,0,0,0,0,0,0,0
0,0,0,0,0,0,0,0,0,0,0,0,0,0,0,0,0,0,0
0,0,53,53,53,53,53,52,0,0,0,0,0,0,0,0,0,0,0
0,0,54,1,1,1,1,52,0,0,0,0,0,0,0,0,0,0,0
0,0,54,1,1,1,1,52,0,0,0,0,0,0,0,0,0,0,0
0,0,54,1,1,2,1,52,0,0,0,0,0,0,0,0,0,0,0
0,0,54,1,1,1,1,52,0,0,0,0,0,0,0,0,0,0,0
0,0,54,1,1,1,1,52,0,0,0,0,0,0,0,0,0,0,0
0,0,54,1,1,1,1,52,0,0,0,0,0,0,0,0,0,0,0
0,0,54,1,1,1,1,52,0,0,0,0,0,0,0,0,0,0,0
0,0,54,1,1,1,1,52,0,0,0,0,0,0,0,0,0,0,0
0,0,54,1,1,2,1,52,0,0,0,0,0,0,0,0,0,0,0
0,0,54,1,1,1,1,52,0,0,0,0,0,0,0,0,0,0,0
0,0,54,46,1,1,1,52,0,0,0,0,0,0,0,0,0,0,0
0,0,54,56,56,1,1,53,53,53,53,53,52,0,0,0,0,0,0
0,0,0,0,54,1,1,1,1,1,1,1,52,0,0,0,0,0,0
0,0,0,0,54,1,1,1,1,1,1,1,52,0,0,0,0,0,0
0,0,0,0,54,2,1,1,1,1,2,1,52,0,0,0,0,0,0
0,0,0,0,54,1,1,1,1,1,1,1,52,0,0,0,0,0,0
0,0,0,0,54,56,56,56,56,56,56,56,56,0,0,0,0,0,0
0,0,0,0,0,0,0,0,0,0,0,0,0,0,0,0,0,0,0
0,0,0,0,0,0,0,0,0,0,0,0,0,0,0,0,0,0,0
0,0,0,0,0,0,0,0,0,0,0,0,0,0,0,0,0,0,0
0,0,0,0,0,0,0,0,0,0,0,0,0,0,0,0,0,0,0
0,0,0,0,0,0,0,0,0,0,0,0,0,0,0,0,0,0,0
endlayer

layer
0,0,0,0,0,0,0,0,0,0,0,0,0,0,0,0,0,0,0
0,0,0,0,0,0,0,0,0,0,0,0,0,0,0,0,0,0,0
0,0,0,0,0,0,0,0,0,0,0,0,0,0,0,0,0,0,0
0,0,0,0,0,0,0,0,0,0,0,0,0,0,0,0,0,0,0
0,0,0,0,0,0,0,0,0,0,0,0,0,0,0,0,0,0,0
0,0,0,0,0,57,0,0,0,0,0,0,0,0,0,0,0,0,0
0,0,0,0,0,0,0,0,0,0,0,0,0,0,0,0,0,0,0
0,0,0,0,0,0,0,0,0,0,0,0,0,0,0,0,0,0,0
0,0,0,0,0,0,0,0,0,0,0,0,0,0,0,0,0,0,0
0,0,0,0,0,0,0,0,0,0,0,0,0,0,0,0,0,0,0
0,0,0,0,0,0,0,0,0,0,0,0,0,0,0,0,0,0,0
0,0,0,0,0,58,0,0,0,0,0,0,0,0,0,0,0,0,0
0,0,0,0,0,0,0,0,0,0,0,0,0,0,0,0,0,0,0
0,0,0,0,0,0,0,0,0,0,0,0,0,0,0,0,0,0,0
0,0,0,0,0,0,0,0,0,0,0,0,0,0,0,0,0,0,0
0,0,0,0,0,0,0,0,0,0,0,0,0,0,0,0,0,0,0
0,0,0,0,0,0,0,0,0,0,0,0,0,0,0,0,0,0,0
0,0,0,0,0,58,0,0,0,0,58,0,0,0,0,0,0,0,0
0,0,0,0,0,0,0,0,0,0,0,0,0,0,0,0,0,0,0
0,0,0,0,0,0,0,0,0,0,0,0,0,0,0,0,0,0,0
0,0,0,0,0,0,0,0,0,0,0,0,0,0,0,0,0,0,0
0,0,0,0,0,0,0,0,0,0,0,0,0,0,0,0,0,0,0
0,0,0,0,0,0,0,0,0,0,0,0,0,0,0,0,0,0,0
0,0,0,0,0,0,0,0,0,0,0,0,0,0,0,0,0,0,0
0,0,0,0,0,0,0,0,0,0,0,0,0,0,0,0,0,0,0
endlayer

layer
0,0,0,0,0,0,0,0,0,0,0,0,0,0,0,0,0,0,0
0,0,0,0,0,0,0,0,0,0,0,0,0,0,0,0,0,0,0
0,0,0,0,0,0,0,0,0,0,0,0,0,0,0,0,0,0,0
0,0,0,0,0,0,0,0,0,0,0,0,0,0,0,0,0,0,0
0,0,0,0,0,0,0,0,0,0,0,0,0,0,0,0,0,0,0
0,0,0,0,0,57,0,0,0,0,0,0,0,0,0,0,0,0,0
0,0,0,0,0,0,0,0,0,0,0,0,0,0,0,0,0,0,0
0,0,0,0,0,0,0,0,0,0,0,0,0,0,0,0,0,0,0
0,0,0,0,0,0,0,0,0,0,0,0,0,0,0,0,0,0,0
0,0,0,0,0,0,0,0,0,0,0,0,0,0,0,0,0,0,0
0,0,0,0,0,0,0,0,0,0,0,0,0,0,0,0,0,0,0
0,0,0,0,0,58,0,0,0,0,0,0,0,0,0,0,0,0,0
0,0,0,0,0,0,0,0,0,0,0,0,0,0,0,0,0,0,0
0,0,0,0,0,0,0,0,0,0,0,0,0,0,0,0,0,0,0
0,0,0,0,0,0,0,0,0,0,0,0,0,0,0,0,0,0,0
0,0,0,0,59,0,0,0,0,0,0,0,0,0,0,0,0,0,0
0,0,0,0,60,59,0,0,0,0,0,0,0,0,0,0,0,0,0
0,0,0,0,59,58,0,0,0,0,58,0,0,0,0,0,0,0,0
0,0,0,0,0,59,0,0,0,0,0,0,0,0,0,0,0,0,0
0,0,0,59,0,0,61,0,0,0,0,0,0,0,0,0,0,0,0
0,0,0,0,0,0,0,0,0,0,0,0,0,0,0,0,0,0,0
0,0,0,0,0,0,0,0,0,0,0,0,0,0,0,0,0,0,0
0,0,0,0,0,0,0,0,0,0,0,0,0,0,0,0,0,0,0
0,0,0,0,0,0,0,0,0,0,0,0,0,0,0,0,0,0,0
0,0,0,0,0,0,0,0,0,0,0,0,0,0,0,0,0,0,0
endlayer

layer
0,0,0,0,0,0,0,0,0,0,0,0,0,0,0,0,0,0,0
0,0,0,0,0,0,0,0,0,0,0,0,0,0,0,0,0,0,0
0,0,0,0,0,0,0,0,0,0,0,0,0,0,0,0,0,0,0
0,0,0,0,0,0,0,0,0,0,0,0,0,0,0,0,0,0,0
0,0,0,0,0,0,0,0,0,0,0,0,0,0,0,0,0,0,0
0,0,0,0,0,57,0,0,0,0,0,0,0,0,0,0,0,0,0
0,0,0,0,0,0,0,0,0,0,0,0,0,0,0,0,0,0,0
0,0,0,0,0,0,0,0,0,0,0,0,0,0,0,0,0,0,0
0,0,0,0,0,0,0,0,0,0,0,0,0,0,0,0,0,0,0
0,0,0,0,0,0,0,0,0,0,0,0,0,0,0,0,0,0,0
0,0,0,0,0,0,0,0,0,0,0,0,0,0,0,0,0,0,0
0,0,0,0,0,58,0,0,0,0,0,0,0,0,0,0,0,0,0
0,0,0,0,0,0,0,0,0,0,0,0,0,0,0,0,0,0,0
0,0,0,0,0,0,0,0,0,0,0,0,0,0,0,0,0,0,0
0,0,0,0,0,0,0,0,0,0,0,0,0,0,0,0,0,0,0
0,0,0,62,62,62,62,0,0,0,0,0,0,0,0,0,0,0,0
0,0,0,62,62,62,62,62,0,0,0,0,0,0,0,0,0,0,0
0,0,0,62,62,58,62,62,0,0,58,0,0,0,0,0,0,0,0
0,0,0,62,62,62,62,62,0,0,0,0,0,0,0,0,0,0,0
0,0,0,62,62,62,62,0,0,0,0,0,0,0,0,0,0,0,0
0,0,0,0,0,0,0,0,0,0,0,0,0,0,0,0,0,0,0
0,0,0,0,0,0,0,0,0,0,0,0,0,0,0,0,0,0,0
0,0,0,0,0,0,0,0,0,0,0,0,0,0,0,0,0,0,0
0,0,0,0,0,0,0,0,0,0,0,0,0,0,0,0,0,0,0
0,0,0,0,0,0,0,0,0,0,0,0,0,0,0,0,0,0,0
endlayer

layer
0,0,0,0,0,0,0,0,0,0,0,0,0,0,0,0,0,0,0
0,0,0,0,0,0,0,0,0,0,0,0,0,0,0,0,0,0,0
0,0,0,0,0,0,0,0,0,0,0,0,0,0,0,0,0,0,0
0,0,0,0,0,0,0,0,0,0,0,0,0,0,0,0,0,0,0
0,0,0,0,63,63,0,0,0,0,0,0,0,0,0,0,0,0,0
0,0,0,0,63,57,0,64,0,0,0,0,0,0,0,0,0,0,0
0,0,0,65,0,65,0,63,0,0,0,0,0,0,0,0,0,0,0
0,0,0,0,0,0,0,0,0,0,0,0,0,0,0,0,0,0,0
0,0,0,0,0,0,0,0,0,0,0,0,0,0,0,0,0,0,0
0,0,0,0,0,0,66,0,0,0,0,0,0,0,0,0,0,0,0
0,0,0,0,0,0,0,67,0,0,0,0,0,0,0,0,0,0,0
0,0,0,0,67,58,0,68,0,0,0,0,0,0,0,0,0,0,0
0,0,0,0,0,0,66,0,0,0,0,0,0,0,0,0,0,0,0
0,0,0,66,0,66,0,0,0,0,0,0,0,0,0,0,0,0,0
0,0,0,0,0,0,0,0,0,0,0,0,0,0,0,0,0,0,0
0,0,0,0,62,62,62,0,0,0,69,0,0,0,0,0,0,0,0
0,0,0,62,62,62,62,62,0,0,69,0,69,0,0,0,0,0,0
0,0,0,62,62,58,62,62,69,0,58,0,0,0,0,0,0,0,0
0,0,0,62,62,62,62,62,69,69,0,0,70,0,0,0,0,0,0
0,0,0,62,62,62,62,0,0,69,0,71,0,0,0,0,0,0,0
0,0,0,0,0,0,0,0,0,0,0,0,0,0,0,0,0,0,0
0,0,0,0,0,0,0,0,0,0,0,0,0,0,0,0,0,0,0
0,0,0,0,0,0,0,0,0,0,0,0,0,0,0,0,0,0,0
0,0,0,0,0,0,0,0,0,0,0,0,0,0,0,0,0,0,0
0,0,0,0,0,0,0,0,0,0,0,0,0,0,0,0,0,0,0
endlayer

layer
0,0,0,0,0,0,0,0,0,0,0,0,0,0,0,0,0,0,0
0,0,0,0,0,0,0,0,0,0,0,0,0,0,0,0,0,0,0
0,0,0,0,0,0,0,0,0,0,0,0,0,0,0,0,0,0,0
0,0,0,0,72,72,72,0,0,0,0,0,0,0,0,0,0,0,0
0,0,0,72,72,72,72,72,0,0,0,0,0,0,0,0,0,0,0
0,0,0,72,72,57,72,72,0,0,0,0,0,0,0,0,0,0,0
0,0,0,72,72,72,72,72,0,0,0,0,0,0,0,0,0,0,0
0,0,0,72,72,72,72,72,0,0,0,0,0,0,0,0,0,0,0
0,0,0,0,0,0,0,0,0,0,0,0,0,0,0,0,0,0,0
0,0,0,68,62,62,62,62,0,0,0,0,0,0,0,0,0,0,0
0,0,0,62,62,62,62,62,0,0,0,0,0,0,0,0,0,0,0
0,0,0,62,62,58,62,62,0,0,0,0,0,0,0,0,0,0,0
0,0,0,62,62,62,62,62,0,0,0,0,0,0,0,0,0,0,0
0,0,0,62,62,62,62,0,0,0,0,0,0,0,0,0,0,0,0
0,0,0,0,0,0,0,0,0,0,0,0,0,0,0,0,0,0,0
0,0,0,0,0,0,0,0,62,62,62,62,0,0,0,0,0,0,0
0,0,0,0,62,62,62,0,62,62,62,62,62,0,0,0,0,0,0
0,0,0,0,62,58,62,0,62,62,58,62,62,0,0,0,0,0,0
0,0,0,0,0,62,62,0,62,62,62,62,62,0,0,0,0,0,0
0,0,0,0,0,0,0,0,62,62,62,62,0,0,0,0,0,0,0
0,0,0,0,0,0,0,0,0,0,0,0,0,0,0,0,0,0,0
0,0,0,0,0,0,0,0,0,0,0,0,0,0,0,0,0,0,0
0,0,0,0,0,0,0,0,0,0,0,0,0,0,0,0,0,0,0
0,0,0,0,0,0,0,0,0,0,0,0,0,0,0,0,0,0,0
0,0,0,0,0,0,0,0,0,0,0,0,0,0,0,0,0,0,0
endlayer

layer
0,0,0,0,0,0,0,0,0,0,0,0,0,0,0,0,0,0,0
0,0,0,0,0,0,0,0,0,0,0,0,0,0,0,0,0,0,0
0,0,0,0,0,0,0,0,0,0,0,0,0,0,0,0,0,0,0
0,0,0,0,72,72,72,0,0,0,0,0,0,0,0,0,0,0,0
0,0,0,72,72,72,72,72,0,0,0,0,0,0,0,0,0,0,0
0,0,0,72,72,57,72,72,0,0,0,0,0,0,0,0,0,0,0
0,0,0,72,72,72,72,72,0,0,0,0,0,0,0,0,0,0,0
0,0,0,0,72,72,72,0,0,0,0,0,0,0,0,0,0,0,0
0,0,0,0,0,0,0,0,0,0,0,0,0,0,0,0,0,0,0
0,0,0,62,62,62,62,62,0,0,0,0,0,0,0,0,0,0,0
0,0,0,62,62,62,62,62,0,0,0,0,0,0,0,0,0,0,0
0,0,0,62,62,58,62,62,0,0,0,0,0,0,0,0,0,0,0
0,0,0,62,62,62,62,62,0,0,0,0,0,0,0,0,0,0,0
0,0,0,0,62,62,62,0,0,0,0,0,0,0,0,0,0,0,0
0,0,0,0,0,0,0,0,0,0,0,0,0,0,0,0,0,0,0
0,0,0,0,0,0,0,0,0,62,62,62,0,0,0,0,0,0,0
0,0,0,0,0,62,0,0,62,62,62,62,62,0,0,0,0,0,0
0,0,0,0,62,62,62,0,62,62,58,62,62,0,0,0,0,0,0
0,0,0,0,0,62,0,0,62,62,62,62,62,0,0,0,0,0,0
0,0,0,0,0,0,0,0,0,62,62,62,0,0,0,0,0,0,0
0,0,0,0,0,0,0,0,0,0,0,0,0,0,0,0,0,0,0
0,0,0,0,0,0,0,0,0,0,0,0,0,0,0,0,0,0,0
0,0,0,0,0,0,0,0,0,0,0,0,0,0,0,0,0,0,0
0,0,0,0,0,0,0,0,0,0,0,0,0,0,0,0,0,0,0
0,0,0,0,0,0,0,0,0,0,0,0,0,0,0,0,0,0,0
endlayer

layer
0,0,0,0,0,0,0,0,0,0,0,0,0,0,0,0,0,0,0
0,0,0,0,0,0,0,0,0,0,0,0,0,0,0,0,0,0,0
0,0,0,0,0,0,0,0,0,0,0,0,0,0,0,0,0,0,0
0,0,0,0,0,0,0,0,0,0,0,0,0,0,0,0,0,0,0
0,0,0,0,72,72,0,0,0,0,0,0,0,0,0,0,0,0,0
0,0,0,0,72,57,72,0,0,0,0,0,0,0,0,0,0,0,0
0,0,0,0,0,72,0,0,0,0,0,0,0,0,0,0,0,0,0
0,0,0,0,0,0,0,0,0,0,0,0,0,0,0,0,0,0,0
0,0,0,0,0,0,0,0,0,0,0,0,0,0,0,0,0,0,0
0,0,0,0,0,0,0,0,0,0,0,0,0,0,0,0,0,0,0
0,0,0,0,0,62,62,0,0,0,0,0,0,0,0,0,0,0,0
0,0,0,0,62,58,62,0,0,0,0,0,0,0,0,0,0,0,0
0,0,0,0,0,62,0,0,0,0,0,0,0,0,0,0,0,0,0
0,0,0,0,0,0,0,0,0,0,0,0,0,0,0,0,0,0,0
0,0,0,0,0,0,0,0,0,0,0,0,0,0,0,0,0,0,0
0,0,0,0,0,0,0,0,0,0,0,0,0,0,0,0,0,0,0
0,0,0,0,0,0,0,0,0,62,62,0,0,0,0,0,0,0,0
0,0,0,0,0,0,0,0,0,62,58,62,0,0,0,0,0,0,0
0,0,0,0,0,0,0,0,0,0,62,62,0,0,0,0,0,0,0
0,0,0,0,0,0,0,0,0,0,0,0,0,0,0,0,0,0,0
0,0,0,0,0,0,0,0,0,0,0,0,0,0,0,0,0,0,0
0,0,0,0,0,0,0,0,0,0,0,0,0,0,0,0,0,0,0
0,0,0,0,0,0,0,0,0,0,0,0,0,0,0,0,0,0,0
0,0,0,0,0,0,0,0,0,0,0,0,0,0,0,0,0,0,0
0,0,0,0,0,0,0,0,0,0,0,0,0,0,0,0,0,0,0
endlayer

layer
0,0,0,0,0,0,0,0,0,0,0,0,0,0,0,0,0,0,0
0,0,0,0,0,0,0,0,0,0,0,0,0,0,0,0,0,0,0
0,0,0,0,0,0,0,0,0,0,0,0,0,0,0,0,0,0,0
0,0,0,0,0,0,0,0,0,0,0,0,0,0,0,0,0,0,0
0,0,0,0,0,72,0,0,0,0,0,0,0,0,0,0,0,0,0
0,0,0,0,72,72,72,0,0,0,0,0,0,0,0,0,0,0,0
0,0,0,0,0,72,0,0,0,0,0,0,0,0,0,0,0,0,0
0,0,0,0,0,0,0,0,0,0,0,0,0,0,0,0,0,0,0
0,0,0,0,0,0,0,0,0,0,0,0,0,0,0,0,0,0,0
0,0,0,0,0,0,0,0,0,0,0,0,0,0,0,0,0,0,0
0,0,0,0,0,62,0,0,0,0,0,0,0,0,0,0,0,0,0
0,0,0,0,62,62,62,0,0,0,0,0,0,0,0,0,0,0,0
0,0,0,0,0,62,0,0,0,0,0,0,0,0,0,0,0,0,0
0,0,0,0,0,0,0,0,0,0,0,0,0,0,0,0,0,0,0
0,0,0,0,0,0,0,0,0,0,0,0,0,0,0,0,0,0,0
0,0,0,0,0,0,0,0,0,0,0,0,0,0,0,0,0,0,0
0,0,0,0,0,0,0,0,0,0,62,0,0,0,0,0,0,0,0
0,0,0,0,0,0,0,0,0,62,62,62,0,0,0,0,0,0,0
0,0,0,0,0,0,0,0,0,0,62,0,0,0,0,0,0,0,0
0,0,0,0,0,0,0,0,0,0,0,0,0,0,0,0,0,0,0
0,0,0,0,0,0,0,0,0,0,0,0,0,0,0,0,0,0,0
0,0,0,0,0,0,0,0,0,0,0,0,0,0,0,0,0,0,0
0,0,0,0,0,0,0,0,0,0,0,0,0,0,0,0,0,0,0
0,0,0,0,0,0,0,0,0,0,0,0,0,0,0,0,0,0,0
0,0,0,0,0,0,0,0,0,0,0,0,0,0,0,0,0,0,0
endlayer

