
# Created by Ruins mod version 15.0 Ingame Parser
# authoring Player: SunsOfOld

weight=100
embed_into_distance=2
acceptable_target_blocks=
unacceptable_target_blocks=flowing_water,water,flowing_lava,lava
dimensions=9,11,11
allowable_overhang=0
max_leveling=4
leveling_buffer=0
preserve_water=0
preserve_lava=0
uniqueMinDistance=1000000
preventRotation=1

rule1=0,100,preserveBlock
rule2=0,100,BiomesOPlenty:newBopDirt-3
rule3=0,100,chisel:fantasyblock2-14
rule4=0,100,minecraft:sand-0
rule5=0,100,BiomesOPlenty:newBopDirt-2
rule6=0,100,chisel:fantasyblock2-13
rule7=0,100,chisel:fantasyblock2-2
rule8=0,100,chisel:fantasyblock2-7
rule9=0,100,chisel:fantasyblock2-15
rule10=0,100,chisel:glowstone-4
rule11=0,100,IInventory;minecraft:dispenser;harvestcraft:freshwaterItem#8#0#1+harvestcraft:freshwaterItem#8#0#3+GardenStuff:iron_nugget#2#0#4+harvestcraft:freshwaterItem#8#0#5+harvestcraft:freshwaterItem#8#0#7-0
rule12=0,100,IInventory;minecraft:dispenser;harvestcraft:freshwaterItem#8#0#1+harvestcraft:freshwaterItem#8#0#3+GardenStuff:iron_nugget#6#0#4+harvestcraft:freshwaterItem#8#0#5+harvestcraft:freshwaterItem#8#0#7-0
rule13=0,100,IInventory;minecraft:dispenser;harvestcraft:freshwaterItem#8#0#1+harvestcraft:freshwaterItem#8#0#3+minecraft:emerald#1#0#4+harvestcraft:freshwaterItem#8#0#5+harvestcraft:freshwaterItem#8#0#7-0
rule14=0,100,IInventory;minecraft:dispenser;harvestcraft:freshwaterItem#8#0#1+harvestcraft:freshwaterItem#8#0#3+harvestcraft:bubblywaterItem#1#0#4+harvestcraft:freshwaterItem#8#0#5+harvestcraft:freshwaterItem#8#0#7-0
rule15=0,100,ExtrabiomesXL:grass-0
rule16=0,100,plantmegapack:grassPrairie-0
rule17=0,100,BiomesOPlenty:plants-3
rule18=0,100,plantmegapack:grassSeaOats-0
rule19=0,100,minecraft:water-1
rule20=0,100,minecraft:water-2
rule21=0,100,minecraft:water-0
rule22=0,100,minecraft:water-9
rule23=0,100,chisel:fantasyblock2-12
rule24=0,100,plantmegapack:flowerMediterraneanSeaHolly-0

layer
1,1,1,1,1,1,1,1,1,1,1
1,1,1,1,1,1,1,1,1,1,1
1,1,1,1,1,1,1,1,1,1,1
1,1,1,1,1,1,1,1,1,1,1
1,1,1,1,1,1,1,1,1,1,1
1,1,1,1,1,1,1,1,1,1,1
1,1,1,1,1,1,1,1,1,1,1
1,1,1,1,1,1,1,1,1,1,1
1,1,1,1,1,1,1,1,1,1,1
1,1,1,1,1,1,1,1,1,1,1
1,1,1,1,1,1,1,1,1,1,1
endlayer

layer
4,3,2,1,3,5,3,4,2,3,2
3,5,3,6,6,6,6,6,3,5,3
1,3,6,7,7,7,7,7,6,3,4
2,6,7,8,9,10,9,8,7,6,1
3,6,7,9,12,9,11,9,7,6,3
4,6,7,10,9,6,9,10,7,6,5
3,6,7,9,14,9,13,9,7,6,3
1,6,7,8,9,10,9,8,7,6,2
5,3,6,7,7,7,7,7,6,2,3
3,1,3,6,6,6,6,6,3,3,4
2,3,5,1,2,3,5,1,5,4,1
endlayer

layer
17,0,15,0,0,18,0,17,16,0,15
0,18,0,6,6,6,6,6,0,18,0
0,0,6,19,20,19,20,19,6,0,17
16,6,19,21,7,22,7,21,19,6,0
0,6,20,7,22,6,22,7,20,6,0
17,6,19,22,6,23,6,22,19,6,15
0,6,20,7,22,6,22,7,20,6,0
0,6,19,21,7,22,7,21,19,6,18
18,0,6,19,20,19,20,19,6,24,0
0,0,0,6,6,6,6,6,0,0,17
15,0,18,0,15,0,16,0,18,17,0
endlayer

layer
0,0,0,0,0,0,0,0,0,0,0
0,0,0,0,0,0,0,0,0,0,0
0,0,0,0,0,0,0,0,0,0,0
0,0,0,0,7,19,7,0,0,0,0
0,0,0,7,19,22,19,7,0,0,0
0,0,0,19,22,23,22,19,0,0,0
0,0,0,7,19,22,19,7,0,0,0
0,0,0,0,7,19,7,0,0,0,0
0,0,0,0,0,0,0,0,0,0,0
0,0,0,0,0,0,0,0,0,0,0
0,0,0,0,0,0,0,0,0,0,0
endlayer

layer
0,0,0,0,0,0,0,0,0,0,0
0,0,0,0,0,0,0,0,0,0,0
0,0,0,0,0,0,0,0,0,0,0
0,0,0,0,0,0,0,0,0,0,0
0,0,0,0,0,22,0,0,0,0,0
0,0,0,0,22,7,22,0,0,0,0
0,0,0,0,0,22,0,0,0,0,0
0,0,0,0,0,0,0,0,0,0,0
0,0,0,0,0,0,0,0,0,0,0
0,0,0,0,0,0,0,0,0,0,0
0,0,0,0,0,0,0,0,0,0,0
endlayer

layer
0,0,0,0,0,0,0,0,0,0,0
0,0,0,0,0,0,0,0,0,0,0
0,0,0,0,0,0,0,0,0,0,0
0,0,0,0,0,0,0,0,0,0,0
0,0,0,0,0,22,0,0,0,0,0
0,0,0,0,22,7,22,0,0,0,0
0,0,0,0,0,22,0,0,0,0,0
0,0,0,0,0,0,0,0,0,0,0
0,0,0,0,0,0,0,0,0,0,0
0,0,0,0,0,0,0,0,0,0,0
0,0,0,0,0,0,0,0,0,0,0
endlayer

layer
0,0,0,0,0,0,0,0,0,0,0
0,0,0,0,0,0,0,0,0,0,0
0,0,0,0,0,0,0,0,0,0,0
0,0,0,0,0,0,0,0,0,0,0
0,0,0,0,0,22,0,0,0,0,0
0,0,0,0,22,7,22,0,0,0,0
0,0,0,0,0,22,0,0,0,0,0
0,0,0,0,0,0,0,0,0,0,0
0,0,0,0,0,0,0,0,0,0,0
0,0,0,0,0,0,0,0,0,0,0
0,0,0,0,0,0,0,0,0,0,0
endlayer

layer
0,0,0,0,0,0,0,0,0,0,0
0,0,0,0,0,0,0,0,0,0,0
0,0,0,0,0,0,0,0,0,0,0
0,0,0,0,0,0,0,0,0,0,0
0,0,0,0,0,22,0,0,0,0,0
0,0,0,0,22,23,22,0,0,0,0
0,0,0,0,0,22,0,0,0,0,0
0,0,0,0,0,0,0,0,0,0,0
0,0,0,0,0,0,0,0,0,0,0
0,0,0,0,0,0,0,0,0,0,0
0,0,0,0,0,0,0,0,0,0,0
endlayer

layer
0,0,0,0,0,0,0,0,0,0,0
0,0,0,0,0,0,0,0,0,0,0
0,0,0,0,0,0,0,0,0,0,0
0,0,0,0,0,0,0,0,0,0,0
0,0,0,0,0,19,0,0,0,0,0
0,0,0,0,19,21,19,0,0,0,0
0,0,0,0,0,19,0,0,0,0,0
0,0,0,0,0,0,0,0,0,0,0
0,0,0,0,0,0,0,0,0,0,0
0,0,0,0,0,0,0,0,0,0,0
0,0,0,0,0,0,0,0,0,0,0
endlayer

