
# Created by Ruins mod version 15.0 Ingame Parser
# authoring Player: SunsOfOld

weight=100
embed_into_distance=1
acceptable_target_blocks=
unacceptable_target_blocks=flowing_water,water,flowing_lava,lava
dimensions=4,14,14
allowable_overhang=0
max_leveling=4
leveling_buffer=0
preserve_water=0
preserve_lava=0
uniqueMinDistance=1000000
preventRotation=1

rule1=0,100,preserveBlock
rule2=0,100,minecraft:netherrack-0
rule3=0,100,BiomesOPlenty:flesh-0
rule4=0,100,chisel:netherrack-3
rule5=0,100,chisel:netherrack-2
rule6=0,100,BiomesOPlenty:hell_blood-0
rule7=0,100,BiomesOPlenty:flowers-13
rule8=0,100,BiomesOPlenty:flowers-14

layer
1,1,1,1,2,1,1,1,1,1,1,1,1,1
1,1,1,1,2,1,1,2,1,1,1,1,1,1
1,1,1,2,2,1,1,2,2,1,1,2,2,2
1,1,2,2,2,2,1,2,2,2,2,2,1,1
2,2,1,2,2,2,2,2,2,2,2,2,1,1
1,2,2,2,2,2,2,2,2,2,2,2,2,1
1,1,1,2,2,2,2,2,2,2,2,2,2,1
1,1,2,2,2,2,2,3,2,2,2,2,2,1
1,1,2,2,2,2,2,2,2,2,2,2,2,1
1,1,1,2,2,2,2,2,2,2,2,2,2,2
1,2,2,2,2,2,2,2,2,2,2,2,2,2
1,1,1,2,2,2,2,2,2,2,2,2,2,2
1,1,2,2,1,2,2,1,2,1,2,2,1,2
1,1,1,2,1,2,2,1,1,1,1,1,1,2
endlayer

layer
0,0,0,0,0,0,0,0,0,0,0,0,0,0
0,0,0,0,0,0,0,0,0,0,0,0,0,0
0,0,0,0,0,0,0,0,0,0,0,0,0,0
0,0,0,0,0,0,0,0,0,0,0,0,0,0
0,0,0,0,5,5,4,5,5,5,4,0,0,0
0,0,0,0,4,3,3,3,3,3,5,0,0,0
0,0,0,0,4,3,3,3,3,3,4,0,0,0
0,0,0,0,4,3,3,6,3,3,4,0,0,0
0,0,0,0,4,3,3,3,3,3,4,0,0,0
0,0,0,0,4,3,3,3,3,3,5,0,0,0
0,0,0,0,4,5,5,4,5,5,4,0,0,0
0,0,0,0,0,0,0,0,0,0,0,0,0,0
0,0,0,0,0,0,0,0,0,0,0,0,0,0
0,0,0,0,0,0,0,0,0,0,0,0,0,0
endlayer

layer
0,0,0,0,0,0,0,0,0,0,0,0,0,0
0,0,0,0,0,0,0,0,0,0,0,0,0,0
0,0,0,0,0,0,0,0,0,0,0,0,0,0
0,0,0,0,0,0,0,0,0,0,0,0,0,0
0,0,0,0,0,0,0,0,0,0,0,0,0,0
0,0,0,0,0,7,7,7,7,7,0,0,0,0
0,0,0,0,0,7,7,7,7,0,0,0,0,0
0,0,0,0,0,7,7,0,7,7,0,0,0,0
0,0,0,0,0,7,7,7,7,7,0,0,0,0
0,0,0,0,0,7,7,7,7,7,0,0,0,0
0,0,0,0,0,0,0,0,0,0,0,0,0,0
0,0,0,0,0,0,0,0,0,0,0,0,0,0
0,0,0,0,0,0,0,0,0,0,0,0,0,0
0,0,0,0,0,0,0,0,0,0,0,0,0,0
endlayer

layer
0,0,0,0,0,0,0,0,0,0,0,0,0,0
0,0,0,0,0,0,0,0,0,0,0,0,0,0
0,0,0,0,0,0,0,0,0,0,0,0,0,0
0,0,0,0,0,0,0,0,0,0,0,0,0,0
0,0,0,0,0,0,0,0,0,0,0,0,0,0
0,0,0,0,0,8,8,8,8,8,0,0,0,0
0,0,0,0,0,8,8,8,8,0,0,0,0,0
0,0,0,0,0,8,8,0,8,8,0,0,0,0
0,0,0,0,0,8,8,8,8,8,0,0,0,0
0,0,0,0,0,8,8,8,8,8,0,0,0,0
0,0,0,0,0,0,0,0,0,0,0,0,0,0
0,0,0,0,0,0,0,0,0,0,0,0,0,0
0,0,0,0,0,0,0,0,0,0,0,0,0,0
0,0,0,0,0,0,0,0,0,0,0,0,0,0
endlayer

