
# Created by Ruins mod version 15.0 Ingame Parser
# authoring Player: ampinstein

weight=100
embed_into_distance=1
acceptable_target_blocks=
unacceptable_target_blocks=flowing_water,water,flowing_lava,lava
dimensions=30,9,9
allowable_overhang=0
max_leveling=2
leveling_buffer=0
preserve_water=0
preserve_lava=0
uniqueMinDistance=1000000
preventRotation=1

rule1=0,100,preserveBlock
rule2=0,100,chisel:mossy_cobblestone-13
rule3=0,100,chisel:mossy_cobblestone-12
rule4=0,100,plantmegapack:bambooTimorBlackDoor-7
rule5=0,100,chisel:mossy_cobblestone-3
rule6=0,100,BiomesOPlenty:ivy-1
rule7=0,100,chisel:mossy_cobblestone-11
rule8=0,100,BiomesOPlenty:ivy-12
rule9=0,100,plantmegapack:bambooTimorBlackDoor-8
rule10=0,100,plantmegapack:bambooAsperLadder-2
rule11=0,100,BiomesOPlenty:ivy-6
rule12=0,100,minecraft:cobblestone_wall-1
rule13=0,100,BiomesOPlenty:ivy-8
rule14=0,100,chisel:mossy_cobblestone-4
rule15=0,100,BiomesOPlenty:ivy-2
rule16=0,100,BiomesOPlenty:ivy-9
rule17=0,100,BiomesOPlenty:ivy-4
rule18=0,100,chisel:mossy_cobblestone-9
rule19=0,100,plantmegapack:bambooAsperLadder-3
rule20=0,100,GardenStuff:heavy_chain-5
rule21=0,100,ChestGenHook:dungeonChest:5-5
rule22=0,100,chisel:cobblestone-12
rule23=0,100,BiomesOPlenty:palmStairs-0
rule24=0,100,BiomesOPlenty:palmStairs-2
rule25=0,100,BiomesOPlenty:palmStairs-3
rule26=0,100,BiomesOPlenty:palmStairs-1
rule27=0,100,BiomesOPlenty:planks-7
rule28=0,100,BiomesOPlenty:ivy-3

layer
1,1,1,1,2,1,1,1,1
1,1,1,3,3,3,1,1,1
1,1,3,3,3,3,3,1,1
1,3,3,3,3,3,3,3,3
2,3,3,3,3,3,3,3,2
1,3,3,3,3,3,3,3,3
1,1,3,3,3,3,3,1,1
1,1,1,3,3,3,1,1,1
1,1,1,1,2,1,1,1,1
endlayer

layer
0,0,0,0,2,0,0,0,0
0,0,0,2,2,2,0,0,0
0,0,2,0,0,0,2,0,0
0,2,0,0,0,0,0,2,3
2,2,5,0,0,0,0,4,0
0,2,0,0,0,0,0,2,2
0,0,2,0,0,0,2,0,0
0,0,0,2,2,2,0,0,0
0,0,0,0,2,0,0,0,0
endlayer

layer
0,0,0,0,2,6,0,0,0
0,0,0,7,7,7,0,0,0
0,8,7,0,0,0,7,0,0
0,7,0,0,0,0,0,7,7
2,7,5,10,0,0,0,9,0
0,7,0,0,0,0,0,7,7
0,0,7,0,0,0,7,0,0
0,0,0,7,7,7,0,0,0
0,0,0,11,2,0,0,0,0
endlayer

layer
0,0,0,13,12,0,0,0,0
0,0,0,14,14,14,0,0,0
0,8,14,0,0,0,14,0,0
0,14,0,0,0,0,0,14,0
12,14,5,10,0,0,0,14,12
0,14,0,0,0,0,0,14,0
0,0,14,0,0,0,14,0,0
0,0,0,14,14,14,0,0,0
0,0,0,15,12,0,0,0,0
endlayer

layer
0,0,0,0,12,0,0,0,0
0,0,0,14,14,14,6,0,0
0,0,14,0,0,0,14,0,0
0,14,0,0,0,0,0,14,0
12,14,5,10,0,0,0,14,12
0,14,0,0,0,0,0,14,0
0,0,14,0,0,0,14,0,0
0,0,0,14,14,14,0,0,0
0,0,0,15,12,0,0,0,0
endlayer

layer
0,0,0,0,0,13,0,0,0
0,0,0,3,5,5,16,0,0
0,0,5,0,0,0,5,0,0
0,5,0,0,0,0,0,3,0
17,5,5,10,0,0,0,5,0
17,5,0,0,0,0,0,5,0
0,0,5,0,0,0,5,0,0
0,0,0,5,5,7,0,0,0
0,0,0,0,0,0,0,0,0
endlayer

layer
0,0,0,0,0,0,0,0,0
0,0,0,5,5,5,0,0,0
0,0,5,0,0,0,5,0,0
0,5,0,0,0,0,0,5,0
17,5,5,10,0,0,0,5,0
17,5,0,0,0,0,0,5,0
0,15,5,0,0,0,5,0,0
0,0,0,5,5,5,0,0,0
0,0,0,0,0,0,0,0,0
endlayer

layer
0,0,0,0,0,0,0,0,0
0,0,0,12,2,12,0,0,0
0,0,12,18,18,18,12,0,0
0,12,18,7,7,7,18,12,0
0,2,18,0,5,7,18,2,0
0,12,18,7,7,7,18,12,0
0,0,12,18,18,18,12,0,0
0,0,0,12,2,12,0,0,0
0,0,0,0,0,0,0,0,0
endlayer

layer
0,0,0,0,0,0,0,0,0
0,0,0,0,2,0,0,0,0
0,0,12,18,18,5,12,0,0
0,0,5,0,0,0,18,0,0
0,2,18,0,0,0,18,2,0
0,0,18,0,0,0,18,0,0
0,0,12,18,18,18,12,0,0
0,0,0,0,2,0,0,0,0
0,0,0,0,0,0,0,0,0
endlayer

layer
0,0,0,0,0,0,0,0,0
0,0,0,0,2,0,0,0,0
0,0,0,18,18,5,0,0,0
0,0,5,0,0,0,18,0,0
0,2,18,0,0,19,18,2,0
0,0,5,0,0,0,18,0,0
0,0,0,18,18,18,0,0,0
0,0,0,0,2,0,0,0,0
0,0,0,0,0,0,0,0,0
endlayer

layer
0,0,0,0,0,0,0,0,0
0,0,0,0,12,0,0,0,0
0,0,0,18,18,18,0,0,0
0,0,18,0,0,0,18,0,0
0,12,18,0,0,19,18,12,0
0,0,18,0,0,0,14,0,0
0,0,0,18,18,5,0,0,0
0,0,0,0,12,0,0,0,0
0,0,0,0,0,0,0,0,0
endlayer

layer
0,0,0,0,0,0,0,0,0
0,0,0,0,12,0,0,0,0
0,0,0,18,18,18,0,0,0
0,0,18,0,0,0,18,0,0
0,12,18,0,0,19,18,12,0
0,0,18,0,0,0,18,0,0
0,0,0,18,18,5,0,0,0
0,0,0,0,12,0,0,0,0
0,0,0,0,0,0,0,0,0
endlayer

layer
0,0,0,0,0,0,0,0,0
0,0,0,0,0,0,0,0,0
0,0,0,14,18,2,13,0,0
0,0,18,0,0,0,14,6,0
0,0,18,0,0,19,18,0,0
0,17,5,0,0,0,18,0,0
0,0,0,3,5,5,0,0,0
0,0,0,0,0,0,0,0,0
0,0,0,0,0,0,0,0,0
endlayer

layer
0,0,0,0,0,0,0,0,0
0,0,0,0,0,0,0,0,0
0,0,0,14,18,18,0,0,0
0,0,5,0,0,0,14,0,0
0,0,18,0,0,19,18,0,0
0,17,5,0,0,0,14,6,0
0,0,0,3,18,18,0,0,0
0,0,0,0,0,0,0,0,0
0,0,0,0,0,0,0,0,0
endlayer

layer
0,0,0,0,0,0,0,0,0
0,0,0,0,0,0,0,0,0
0,0,13,14,18,7,0,0,0
0,17,18,0,0,0,18,6,0
0,0,5,0,0,19,18,0,0
0,0,18,0,0,0,14,6,0
0,0,0,18,18,3,0,0,0
0,0,0,0,0,0,0,0,0
0,0,0,0,0,0,0,0,0
endlayer

layer
0,0,0,0,0,0,0,0,0
0,0,0,0,0,0,0,0,0
0,0,13,18,18,18,0,0,0
0,17,18,0,0,0,14,0,0
0,0,18,0,0,19,18,0,0
0,0,14,0,0,0,18,6,0
0,0,0,5,18,18,0,0,0
0,0,0,0,0,0,0,0,0
0,0,0,0,0,0,0,0,0
endlayer

layer
0,0,0,0,0,0,0,0,0
0,0,0,0,0,0,0,0,0
0,0,0,3,3,3,0,0,0
0,17,3,0,0,0,3,0,0
0,0,3,0,0,19,3,0,0
0,0,3,0,0,0,3,0,0
0,0,0,3,3,3,0,0,0
0,0,0,0,0,0,0,0,0
0,0,0,0,0,0,0,0,0
endlayer

layer
0,0,0,0,0,0,0,0,0
0,0,0,0,12,0,0,0,0
0,0,0,3,3,3,0,0,0
0,0,3,18,18,18,3,0,0
0,12,3,5,5,19,3,12,6
0,0,3,5,5,3,3,0,0
0,0,0,3,3,3,0,0,0
0,0,0,0,12,0,0,0,0
0,0,0,0,0,0,0,0,0
endlayer

layer
0,0,0,0,13,0,0,0,0
0,0,0,0,3,0,0,0,0
0,0,0,20,21,20,0,0,0
0,13,20,0,0,0,20,13,0
17,3,21,0,0,0,0,3,6
0,0,20,0,0,0,20,0,0
0,0,0,20,21,20,0,0,0
0,0,0,17,22,0,0,0,0
0,0,0,0,0,0,0,0,0
endlayer

layer
0,0,0,0,0,0,0,0,0
0,0,0,0,3,0,0,0,0
0,0,0,20,0,20,0,0,0
0,0,20,0,0,0,20,0,0
0,3,0,0,0,0,0,3,6
0,0,20,0,0,0,20,0,0
0,0,0,20,0,20,0,0,0
0,0,0,0,5,0,0,0,0
0,0,0,0,15,0,0,0,0
endlayer

layer
0,0,0,0,0,0,0,0,0
0,0,0,0,5,0,0,0,0
0,0,0,20,0,20,0,0,0
0,0,20,0,0,0,20,0,0
0,18,0,0,0,0,0,14,0
0,0,20,0,0,0,20,0,0
0,0,0,20,0,20,0,0,0
0,0,0,0,2,0,0,0,0
0,0,0,0,0,0,0,0,0
endlayer

layer
0,0,0,23,23,23,0,0,0
0,0,0,0,22,0,0,0,0
0,0,13,7,0,7,16,0,0
25,0,7,0,0,0,7,0,24
25,7,0,0,0,0,0,14,24
25,0,7,0,0,0,7,0,24
0,0,17,7,0,7,0,0,0
0,0,0,0,14,15,0,0,0
0,0,0,26,26,26,0,0,0
endlayer

layer
0,0,0,0,13,0,0,0,0
0,0,13,27,27,27,0,0,0
0,0,27,0,0,0,27,0,0
17,27,0,0,0,0,0,27,0
0,27,0,0,0,0,0,27,6
0,27,0,0,0,0,0,27,0
0,17,27,0,0,0,27,6,0
0,0,0,27,27,27,28,0,0
0,0,0,0,15,0,0,0,0
endlayer

layer
0,0,0,0,0,0,0,0,0
0,0,0,23,23,23,0,0,0
0,0,27,0,0,0,27,6,0
0,25,0,0,0,0,0,24,0
0,25,0,0,0,0,0,24,0
0,25,0,0,0,0,0,24,0
0,0,27,0,0,0,27,0,0
0,0,0,26,26,26,0,0,0
0,0,0,0,0,0,0,0,0
endlayer

layer
0,0,0,0,0,0,0,0,0
0,0,0,0,13,0,0,0,0
0,0,0,27,27,27,0,0,0
0,0,27,0,0,0,27,0,0
0,0,27,0,0,0,27,6,0
0,17,27,0,0,0,27,0,0
0,0,0,27,27,27,0,0,0
0,0,0,0,15,0,0,0,0
0,0,0,0,0,0,0,0,0
endlayer

layer
0,0,0,0,0,0,0,0,0
0,0,0,0,0,0,0,0,0
0,0,0,23,23,23,0,0,0
0,0,25,0,0,0,24,0,0
0,0,25,0,0,0,24,0,0
0,0,25,0,0,0,24,0,0
0,0,0,26,26,26,0,0,0
0,0,0,0,0,0,0,0,0
0,0,0,0,0,0,0,0,0
endlayer

layer
0,0,0,0,0,0,0,0,0
0,0,0,0,0,0,0,0,0
0,0,0,0,0,0,0,0,0
0,0,0,27,27,27,0,0,0
0,0,0,27,0,27,0,0,0
0,0,0,27,27,27,6,0,0
0,0,0,0,0,0,0,0,0
0,0,0,0,0,0,0,0,0
0,0,0,0,0,0,0,0,0
endlayer

layer
0,0,0,0,0,0,0,0,0
0,0,0,0,0,0,0,0,0
0,0,0,0,0,0,0,0,0
0,0,0,25,23,23,0,0,0
0,0,0,25,27,24,0,0,0
0,0,0,26,26,26,0,0,0
0,0,0,0,0,0,0,0,0
0,0,0,0,0,0,0,0,0
0,0,0,0,0,0,0,0,0
endlayer

layer
0,0,0,0,0,0,0,0,0
0,0,0,0,0,0,0,0,0
0,0,0,0,0,0,0,0,0
0,0,0,0,0,0,0,0,0
0,0,0,0,27,0,0,0,0
0,0,0,0,0,0,0,0,0
0,0,0,0,0,0,0,0,0
0,0,0,0,0,0,0,0,0
0,0,0,0,0,0,0,0,0
endlayer

layer
0,0,0,0,0,0,0,0,0
0,0,0,0,0,0,0,0,0
0,0,0,0,0,0,0,0,0
0,0,0,0,0,0,0,0,0
0,0,0,0,27,0,0,0,0
0,0,0,0,0,0,0,0,0
0,0,0,0,0,0,0,0,0
0,0,0,0,0,0,0,0,0
0,0,0,0,0,0,0,0,0
endlayer

