
# Created by Ruins mod version 15.0 Ingame Parser
# authoring Player: SunsOfOld

weight=100
embed_into_distance=1
acceptable_target_blocks=
unacceptable_target_blocks=flowing_water,water,flowing_lava,lava
dimensions=40,24,17
allowable_overhang=0
max_leveling=5
leveling_buffer=0
preserve_water=0
preserve_lava=0
uniqueMinDistance=1000000
preventRotation=1

rule1=0,100,preserveBlock
rule2=0,100,chisel:stonebricksmooth-3
rule3=0,100,minecraft:grass-0
rule4=0,100,minecraft:dirt-0
rule5=0,100,minecraft:netherrack-0
rule6=0,100,GardenStuff:moss_brick-3
rule7=0,100,chisel:marble-4
rule8=0,100,GardenStuff:lattice-2
rule9=0,100,chisel:marble-1
rule10=0,100,chisel:marble_stairs.0-9
rule11=0,100,chisel:glowstone-4
rule12=0,100,BiomesOPlenty:foliage-10
rule13=0,100,ExtrabiomesXL:door_cypress-0
rule14=0,100,chisel:leaves-10
rule15=0,100,minecraft:tallgrass-1
rule16=0,100,ExtrabiomesXL:fence-3
rule17=0,100,GardenStuff:fence-2
rule18=0,100,BiomesOPlenty:foliage-11
rule19=0,100,BiblioWoodsEBXL:BiblioWoodtable-3
rule20=0,100,minecraft:fire-15
rule21=0,100,ExtrabiomesXL:stairs.cypress-3
rule22=0,100,chisel:marble_slab-1
rule23=0,100,chisel:marble_stairs.0-10
rule24=0,100,ExtrabiomesXL:door_cypress-8
rule25=0,100,chisel:stained_glass_yellow-14
rule26=0,100,harvestcraft:pamcandleDeco16-5
rule27=0,100,chisel:glass-4
rule28=0,100,chisel:marble_stairs.0-8
rule29=0,100,chisel:marble_stairs.0-11
rule30=0,100,UndergroundBiomes:stairs-2
rule31=0,100,UndergroundBiomes:stairs-3
rule32=0,100,UndergroundBiomes:stairs-7
rule33=0,100,UndergroundBiomes:stairs-6
rule34=0,100,chisel:marble_stairs.0-12
rule35=0,100,UndergroundBiomes:stairs-5
rule36=0,100,UndergroundBiomes:metamorphicStoneHalfSlab-0
rule37=0,100,UndergroundBiomes:igneousStone-9
rule38=0,100,chisel:marble_slab_top-1
rule39=0,100,UndergroundBiomes:igneousStoneHalfSlab-9
rule40=0,100,UndergroundBiomes:igneousStoneFullSlab-1
rule41=0,100,IInventory;minecraft:chest;ExtrabiomesXL:saplings_1#4#1#12-3
rule42=0,100,chisel:stained_glass_lightgray-1
rule43=0,100,GardenStuff:fence-0
rule44=0,100,minecraft:carpet-7
rule45=0,100,UndergroundBiomes:igneousStoneHalfSlab-1
rule46=0,100,chisel:glowstone-10
rule47=0,100,minecraft:carpet-15

layer
1,1,1,1,1,1,1,1,1,1,1,1,1,1,1,1,1
1,1,1,1,1,1,1,1,1,1,1,1,1,1,1,1,1
1,1,1,1,1,1,1,1,1,1,1,1,1,1,1,1,1
1,1,1,1,1,1,2,2,2,2,2,1,1,1,1,1,1
1,1,1,1,2,2,2,2,2,2,2,2,2,1,1,1,1
1,1,1,2,2,2,2,2,2,2,2,2,2,1,1,1,1
1,1,1,2,2,2,2,2,2,2,2,2,2,2,1,1,1
1,1,1,2,2,2,2,2,2,2,2,2,2,2,1,1,1
3,1,1,2,2,2,2,2,2,2,2,2,2,2,1,1,1
1,1,1,2,2,2,2,2,2,2,2,2,2,2,1,1,1
1,3,1,2,2,2,2,2,2,2,2,2,2,2,1,1,1
1,1,1,1,2,2,2,2,2,2,2,2,2,1,1,1,1
1,1,3,1,2,2,2,2,2,2,2,2,2,1,1,1,1
1,1,1,1,1,1,2,2,2,2,2,1,1,1,3,1,1
1,3,1,3,3,1,1,1,2,1,1,1,3,1,1,1,1
1,1,1,1,3,1,2,2,2,2,2,1,3,3,1,1,1
1,1,3,1,4,1,2,2,2,2,2,1,3,1,1,1,1
1,3,1,1,4,5,2,2,2,2,2,1,3,1,3,1,1
1,1,1,1,4,5,2,2,2,2,2,1,3,1,1,1,1
1,1,3,1,3,1,2,2,2,2,2,1,3,3,1,1,1
1,3,1,3,3,1,2,2,2,2,2,1,3,1,1,1,1
1,1,1,1,3,1,1,1,2,1,1,1,3,3,1,1,1
1,1,1,3,1,3,3,3,6,3,3,3,1,1,1,1,1
1,1,1,1,1,1,3,1,1,3,1,1,3,1,1,1,1
endlayer

layer
0,0,0,0,0,0,0,0,0,0,0,0,0,0,0,0,0
0,0,0,0,0,0,0,0,0,0,0,0,0,0,0,0,0
0,0,0,0,0,0,7,7,7,7,7,0,0,0,0,0,0
0,0,0,8,9,9,0,0,0,0,0,9,9,8,0,0,0
0,0,0,9,0,0,0,0,0,0,0,0,0,9,0,0,0
0,0,0,9,0,0,0,0,0,0,0,0,0,9,0,0,0
0,0,7,0,0,0,0,0,0,0,0,0,0,0,7,0,0
0,0,7,0,0,0,0,0,0,0,0,0,0,0,7,0,0
0,0,7,0,0,0,0,0,11,10,0,0,0,0,7,0,0
0,0,7,0,0,0,0,0,0,0,0,0,0,0,7,0,0
0,0,7,0,0,0,0,0,0,0,0,0,0,0,7,0,0
0,0,0,9,0,0,0,0,0,0,0,0,0,9,0,0,0
0,0,0,9,0,0,0,0,0,0,0,0,0,9,0,0,0
0,0,0,8,9,9,0,0,0,0,0,9,9,8,0,0,0
0,0,0,0,14,9,7,7,13,7,7,9,12,0,0,0,0
0,0,0,0,14,9,0,0,0,0,16,9,0,15,0,0,0
0,0,0,0,9,9,17,0,0,0,0,9,0,0,0,0,0
0,0,0,0,9,20,17,0,0,0,19,9,12,0,18,0,0
0,0,0,0,9,20,17,0,0,0,21,9,0,0,0,0,0
0,0,0,0,12,9,17,0,0,0,0,9,18,0,0,0,0
0,0,0,0,12,9,0,0,0,0,16,9,14,0,0,0,0
0,0,0,0,12,9,9,9,13,9,9,9,14,0,0,0,0
0,0,0,0,0,12,18,15,0,18,12,18,0,0,0,0,0
0,0,0,0,0,0,0,0,0,0,0,0,0,0,0,0,0
endlayer

layer
0,0,0,0,0,0,0,0,0,0,0,0,0,0,0,0,0
0,0,0,0,0,0,0,0,0,0,0,0,0,0,0,0,0
0,0,0,0,0,0,7,7,7,7,7,0,0,0,0,0,0
0,0,0,8,9,9,0,0,0,0,0,9,9,8,0,0,0
0,0,0,9,0,0,0,0,0,0,0,0,0,9,0,0,0
0,0,0,9,0,0,0,0,0,0,0,0,0,9,0,0,0
0,0,7,0,0,0,0,0,0,0,0,0,0,0,7,0,0
0,0,7,0,0,0,0,0,23,22,0,0,0,0,7,0,0
0,0,7,0,0,0,0,0,11,0,0,0,0,0,7,0,0
0,0,7,0,0,0,0,0,0,0,0,0,0,0,7,0,0
0,0,7,0,0,0,0,0,0,0,0,0,0,0,7,0,0
0,0,0,9,0,0,0,0,0,0,0,0,0,9,0,0,0
0,0,0,9,0,0,0,0,0,0,0,0,0,9,0,0,0
0,0,0,8,9,9,0,0,0,0,0,9,9,8,0,0,0
0,0,0,0,14,9,7,7,24,7,7,9,0,0,0,0,0
0,0,0,0,0,9,0,0,0,0,14,9,0,0,0,0,0
0,0,0,0,9,9,0,0,0,0,0,25,0,0,0,0,0
0,0,0,0,9,0,0,0,0,0,26,9,0,0,0,0,0
0,0,0,0,9,0,0,0,0,0,0,9,0,0,0,0,0
0,0,0,0,0,9,0,0,0,0,0,25,0,0,0,0,0
0,0,0,0,0,9,0,0,0,0,14,9,0,0,0,0,0
0,0,0,0,0,9,9,9,24,9,9,9,0,0,0,0,0
0,0,0,0,0,0,0,0,0,0,0,0,0,0,0,0,0
0,0,0,0,0,0,0,0,0,0,0,0,0,0,0,0,0
endlayer

layer
0,0,0,0,0,0,0,0,0,0,0,0,0,0,0,0,0
0,0,0,0,0,0,0,0,0,0,0,0,0,0,0,0,0
0,0,0,0,0,0,7,7,27,7,7,0,0,0,0,0,0
0,0,0,8,9,9,0,0,0,0,0,9,9,8,0,0,0
0,0,0,9,0,0,0,0,0,0,0,0,0,9,0,0,0
0,0,0,9,0,0,0,0,0,0,0,0,0,9,0,0,0
0,0,7,0,0,0,0,0,0,0,0,0,0,0,7,0,0
0,0,7,0,0,0,0,22,0,0,0,0,0,0,7,0,0
0,0,27,0,0,0,0,28,11,0,0,0,0,0,27,0,0
0,0,7,0,0,0,0,0,0,0,0,0,0,0,7,0,0
0,0,7,0,0,0,0,0,0,0,0,0,0,0,7,0,0
0,0,0,9,0,0,0,0,0,0,0,0,0,9,0,0,0
0,0,0,9,0,0,0,0,0,0,0,0,0,9,0,0,0
0,0,0,8,9,9,0,0,0,0,0,9,9,8,0,0,0
0,0,0,0,0,9,7,7,7,7,7,9,0,0,0,0,0
0,0,0,0,0,9,0,0,0,0,14,9,0,0,0,0,0
0,0,0,0,9,9,0,0,0,0,0,25,0,0,0,0,0
0,0,0,0,9,0,0,0,0,0,0,9,0,0,0,0,0
0,0,0,0,9,0,0,0,0,0,0,9,0,0,0,0,0
0,0,0,0,0,9,0,0,0,0,0,25,0,0,0,0,0
0,0,0,0,0,9,0,0,0,0,14,9,0,0,0,0,0
0,0,0,0,0,9,9,9,9,9,9,9,0,0,0,0,0
0,0,0,0,0,0,0,0,0,0,0,0,0,0,0,0,0
0,0,0,0,0,0,0,0,0,0,0,0,0,0,0,0,0
endlayer

layer
0,0,0,0,0,0,0,0,0,0,0,0,0,0,0,0,0
0,0,0,0,0,0,0,0,0,0,0,0,0,0,0,0,0
0,0,0,0,0,0,7,7,27,7,7,0,0,0,0,0,0
0,0,0,8,9,9,0,0,0,0,0,9,9,8,0,0,0
0,0,0,9,0,0,0,0,0,0,0,0,0,9,0,0,0
0,0,0,9,0,0,0,0,0,0,0,0,0,9,0,0,0
0,0,7,0,0,0,0,0,0,0,0,0,0,0,7,0,0
0,0,7,0,0,0,0,0,0,0,0,0,0,0,7,0,0
0,0,27,0,0,0,0,0,11,0,0,0,0,0,27,0,0
0,0,7,0,0,0,0,22,29,0,0,0,0,0,7,0,0
0,0,7,0,0,0,0,0,0,0,0,0,0,0,7,0,0
0,0,0,9,0,0,0,0,0,0,0,0,0,9,0,0,0
0,0,0,9,0,0,0,0,0,0,0,0,0,9,0,0,0
0,0,0,8,9,9,0,0,0,0,0,9,9,8,0,0,0
0,0,0,0,31,9,7,7,7,7,7,9,30,0,0,0,0
0,0,0,0,31,9,0,0,0,0,0,9,30,0,0,0,0
0,0,0,0,9,9,0,0,0,0,0,9,30,0,0,0,0
0,0,0,0,9,0,0,0,0,0,0,9,30,0,0,0,0
0,0,0,0,9,0,0,0,0,0,0,9,30,0,0,0,0
0,0,0,0,31,9,0,0,0,0,0,9,30,0,0,0,0
0,0,0,0,31,9,0,0,0,0,0,9,30,0,0,0,0
0,0,0,0,31,9,9,9,25,9,9,9,30,0,0,0,0
0,0,0,0,31,33,0,0,0,0,0,32,30,0,0,0,0
0,0,0,0,0,0,0,0,0,0,0,0,0,0,0,0,0
endlayer

layer
0,0,0,0,0,0,0,0,0,0,0,0,0,0,0,0,0
0,0,0,0,0,0,0,0,0,0,0,0,0,0,0,0,0
0,0,0,0,0,0,7,7,7,7,7,0,0,0,0,0,0
0,0,0,8,9,9,0,0,0,0,0,9,9,8,0,0,0
0,0,0,9,0,0,0,0,0,0,0,0,0,9,0,0,0
0,0,0,9,0,0,0,0,0,0,0,0,0,9,0,0,0
0,0,7,0,0,0,0,0,0,0,0,0,0,0,7,0,0
0,0,7,0,0,0,0,0,0,0,0,0,0,0,7,0,0
0,0,7,0,0,0,0,0,11,10,0,0,0,0,7,0,0
0,0,7,0,0,0,0,0,0,22,0,0,0,0,7,0,0
0,0,7,0,0,0,0,0,0,0,0,0,0,0,7,0,0
0,0,0,9,0,0,0,0,0,0,0,0,0,9,0,0,0
0,0,0,9,0,0,0,0,0,0,0,0,0,9,0,0,0
0,0,0,8,9,9,0,0,0,0,0,9,9,8,0,0,0
0,0,0,0,0,31,7,7,7,7,7,30,0,0,0,0,0
0,0,0,0,0,31,0,0,0,0,0,30,0,0,0,0,0
0,0,0,0,29,9,0,0,0,0,0,30,0,0,0,0,0
0,0,0,0,9,0,0,0,0,0,0,30,0,0,0,0,0
0,0,0,0,9,34,0,0,0,0,0,30,0,0,0,0,0
0,0,0,0,0,31,0,0,0,0,0,30,0,0,0,0,0
0,0,0,0,0,31,0,0,0,0,0,30,0,0,0,0,0
0,0,0,0,0,31,9,9,25,9,9,30,0,0,0,0,0
0,0,0,0,0,31,33,0,0,0,32,30,0,0,0,0,0
0,0,0,0,0,0,0,0,0,0,0,0,0,0,0,0,0
endlayer

layer
0,0,0,0,0,0,0,0,0,0,0,0,0,0,0,0,0
0,0,0,0,0,0,0,0,0,0,0,0,0,0,0,0,0
0,0,0,0,0,0,7,7,7,7,7,0,0,0,0,0,0
0,0,0,8,9,9,0,0,0,0,0,9,9,8,0,0,0
0,0,0,9,0,0,0,0,0,0,0,0,0,9,0,0,0
0,0,0,9,0,0,0,0,0,0,0,0,0,9,0,0,0
0,0,7,0,0,0,0,0,0,0,0,0,0,0,7,0,0
0,0,7,0,0,0,0,0,23,22,0,0,0,0,7,0,0
0,0,7,0,0,0,0,0,11,0,0,0,0,0,7,0,0
0,0,7,0,0,0,0,0,0,0,0,0,0,0,7,0,0
0,0,7,0,0,0,0,0,0,0,0,0,0,0,7,0,0
0,0,0,9,0,0,0,0,0,0,0,0,0,9,0,0,0
0,0,0,9,0,0,0,0,0,0,0,0,0,9,0,0,0
0,0,0,8,9,9,0,0,0,0,0,9,9,8,0,0,0
0,0,0,0,0,0,7,7,7,7,7,0,0,0,0,0,0
0,0,0,0,0,0,31,0,0,0,30,0,0,0,0,0,0
0,0,0,0,0,9,31,0,0,0,30,0,0,0,0,0,0
0,0,0,0,9,0,31,0,0,0,30,0,0,0,0,0,0
0,0,0,0,0,9,31,0,0,0,30,0,0,0,0,0,0
0,0,0,0,0,0,31,0,0,0,30,0,0,0,0,0,0
0,0,0,0,0,0,31,0,0,0,30,0,0,0,0,0,0
0,0,0,0,0,0,31,9,9,9,30,0,0,0,0,0,0
0,0,0,0,0,0,31,33,0,32,30,0,0,0,0,0,0
0,0,0,0,0,0,0,0,0,0,0,0,0,0,0,0,0
endlayer

layer
0,0,0,0,0,0,0,0,0,0,0,0,0,0,0,0,0
0,0,0,0,0,0,0,0,0,0,0,0,0,0,0,0,0
0,0,0,0,0,0,7,7,7,7,7,0,0,0,0,0,0
0,0,0,8,9,9,0,0,0,0,0,9,9,8,0,0,0
0,0,0,9,0,0,0,0,0,0,0,0,0,9,0,0,0
0,0,0,9,0,0,0,0,0,0,0,0,0,9,0,0,0
0,0,7,0,0,0,0,0,0,0,0,0,0,0,7,0,0
0,0,7,0,0,0,0,22,0,0,0,0,0,0,7,0,0
0,0,7,0,0,0,0,28,11,0,0,0,0,0,7,0,0
0,0,7,0,0,0,0,0,0,0,0,0,0,0,7,0,0
0,0,7,0,0,0,0,0,0,0,0,0,0,0,7,0,0
0,0,0,9,0,0,0,0,0,0,0,0,0,9,0,0,0
0,0,0,9,0,0,0,0,0,0,0,0,0,9,0,0,0
0,0,0,8,9,9,0,0,0,0,0,9,9,8,0,0,0
0,0,0,0,0,0,7,7,7,7,7,0,0,0,0,0,0
0,0,0,0,0,0,0,31,0,30,0,0,0,0,0,0,0
0,0,0,0,0,9,0,31,0,30,0,0,0,0,0,0,0
0,0,0,0,9,0,9,31,0,30,0,0,0,0,0,0,0
0,0,0,0,0,9,0,31,0,30,0,0,0,0,0,0,0
0,0,0,0,0,0,0,31,0,30,0,0,0,0,0,0,0
0,0,0,0,0,0,0,31,0,30,0,0,0,0,0,0,0
0,0,0,0,0,0,0,31,9,30,0,0,0,0,0,0,0
0,0,0,0,0,0,0,31,35,30,0,0,0,0,0,0,0
0,0,0,0,0,0,0,0,0,0,0,0,0,0,0,0,0
endlayer

layer
0,0,0,0,0,0,0,0,0,0,0,0,0,0,0,0,0
0,0,0,0,0,0,0,0,0,0,0,0,0,0,0,0,0
0,0,0,0,0,0,7,7,27,7,7,0,0,0,0,0,0
0,0,0,8,9,9,0,0,0,0,0,9,9,8,0,0,0
0,0,0,9,0,0,0,0,0,0,0,0,0,9,0,0,0
0,0,0,9,0,0,0,0,0,0,0,0,0,9,0,0,0
0,0,7,0,0,0,0,0,0,0,0,0,0,0,7,0,0
0,0,7,0,0,0,0,0,0,0,0,0,0,0,7,0,0
0,0,27,0,0,0,0,0,11,0,0,0,0,0,27,0,0
0,0,7,0,0,0,0,22,29,0,0,0,0,0,7,0,0
0,0,7,0,0,0,0,0,0,0,0,0,0,0,7,0,0
0,0,0,9,0,0,0,0,0,0,0,0,0,9,0,0,0
0,0,0,9,0,0,0,0,0,0,0,0,0,9,0,0,0
0,0,0,8,9,9,0,0,0,0,0,9,9,8,0,0,0
0,0,0,0,0,0,7,7,7,7,7,0,0,0,0,0,0
0,0,0,0,0,0,0,0,36,0,0,0,0,0,0,0,0
0,0,0,0,0,9,0,0,36,0,0,0,0,0,0,0,0
0,0,0,0,9,0,9,0,36,0,0,0,0,0,0,0,0
0,0,0,0,0,9,0,0,36,0,0,0,0,0,0,0,0
0,0,0,0,0,0,0,0,36,0,0,0,0,0,0,0,0
0,0,0,0,0,0,0,0,36,0,0,0,0,0,0,0,0
0,0,0,0,0,0,0,0,36,0,0,0,0,0,0,0,0
0,0,0,0,0,0,0,0,36,0,0,0,0,0,0,0,0
0,0,0,0,0,0,0,0,0,0,0,0,0,0,0,0,0
endlayer

layer
0,0,0,0,0,0,0,0,0,0,0,0,0,0,0,0,0
0,0,0,0,0,0,0,0,0,0,0,0,0,0,0,0,0
0,0,0,0,0,0,7,7,7,7,7,0,0,0,0,0,0
0,0,0,8,9,9,0,0,0,0,0,9,9,8,0,0,0
0,0,0,9,0,0,0,0,0,0,0,0,0,9,0,0,0
0,0,0,9,0,0,0,0,0,0,0,0,0,9,0,0,0
0,0,7,0,0,0,0,0,0,0,0,0,0,0,7,0,0
0,0,7,0,0,0,0,0,0,0,0,0,0,0,7,0,0
0,0,7,0,0,0,0,0,11,10,0,0,0,0,7,0,0
0,0,7,0,0,0,0,0,0,22,0,0,0,0,7,0,0
0,0,7,0,0,0,0,0,0,0,0,0,0,0,7,0,0
0,0,0,9,0,0,0,0,0,0,0,0,0,9,0,0,0
0,0,0,9,0,0,0,0,0,0,0,0,0,9,0,0,0
0,0,0,8,9,9,0,0,0,0,0,9,9,8,0,0,0
0,0,0,0,0,0,7,7,7,7,7,0,0,0,0,0,0
0,0,0,0,0,0,0,0,0,0,0,0,0,0,0,0,0
0,0,0,0,0,0,0,0,0,0,0,0,0,0,0,0,0
0,0,0,0,0,0,0,0,0,0,0,0,0,0,0,0,0
0,0,0,0,0,0,0,0,0,0,0,0,0,0,0,0,0
0,0,0,0,0,0,0,0,0,0,0,0,0,0,0,0,0
0,0,0,0,0,0,0,0,0,0,0,0,0,0,0,0,0
0,0,0,0,0,0,0,0,0,0,0,0,0,0,0,0,0
0,0,0,0,0,0,0,0,0,0,0,0,0,0,0,0,0
0,0,0,0,0,0,0,0,0,0,0,0,0,0,0,0,0
endlayer

layer
0,0,0,0,0,0,0,0,0,0,0,0,0,0,0,0,0
0,0,0,0,0,0,0,0,0,0,0,0,0,0,0,0,0
0,0,0,0,0,0,7,7,7,7,7,0,0,0,0,0,0
0,0,0,8,9,9,0,0,0,0,0,9,9,8,0,0,0
0,0,0,9,0,0,0,0,0,0,0,0,0,9,0,0,0
0,0,0,9,0,0,0,0,0,0,0,0,0,9,0,0,0
0,0,7,0,0,0,0,0,0,0,0,0,0,0,7,0,0
0,0,7,0,0,0,0,0,23,22,0,0,0,0,7,0,0
0,0,7,0,0,0,0,0,11,0,0,0,0,0,7,0,0
0,0,7,0,0,0,0,0,0,0,0,0,0,0,7,0,0
0,0,7,0,0,0,0,0,0,0,0,0,0,0,7,0,0
0,0,0,9,0,0,0,0,0,0,0,0,0,9,0,0,0
0,0,0,9,0,0,0,0,0,0,0,0,0,9,0,0,0
0,0,0,8,9,9,0,0,0,0,0,9,9,8,0,0,0
0,0,0,0,0,0,7,7,7,7,7,0,0,0,0,0,0
0,0,0,0,0,0,0,0,0,0,0,0,0,0,0,0,0
0,0,0,0,0,0,0,0,0,0,0,0,0,0,0,0,0
0,0,0,0,0,0,0,0,0,0,0,0,0,0,0,0,0
0,0,0,0,0,0,0,0,0,0,0,0,0,0,0,0,0
0,0,0,0,0,0,0,0,0,0,0,0,0,0,0,0,0
0,0,0,0,0,0,0,0,0,0,0,0,0,0,0,0,0
0,0,0,0,0,0,0,0,0,0,0,0,0,0,0,0,0
0,0,0,0,0,0,0,0,0,0,0,0,0,0,0,0,0
0,0,0,0,0,0,0,0,0,0,0,0,0,0,0,0,0
endlayer

layer
0,0,0,0,0,0,0,0,0,0,0,0,0,0,0,0,0
0,0,0,0,0,0,0,0,0,0,0,0,0,0,0,0,0
0,0,0,0,0,0,7,7,7,7,7,0,0,0,0,0,0
0,0,0,8,9,9,0,0,0,0,0,9,9,8,0,0,0
0,0,0,9,0,0,0,0,0,0,0,0,0,9,0,0,0
0,0,0,9,0,0,0,0,0,0,0,0,0,9,0,0,0
0,0,7,0,0,0,0,0,0,0,0,0,0,0,7,0,0
0,0,7,0,0,0,0,22,0,0,0,0,0,0,7,0,0
0,0,7,0,0,0,0,28,11,0,0,0,0,0,7,0,0
0,0,7,0,0,0,0,0,0,0,0,0,0,0,7,0,0
0,0,7,0,0,0,0,0,0,0,0,0,0,0,7,0,0
0,0,0,9,0,0,0,0,0,0,0,0,0,9,0,0,0
0,0,0,9,0,0,0,0,0,0,0,0,0,9,0,0,0
0,0,0,8,9,9,0,0,0,0,0,9,9,8,0,0,0
0,0,0,0,0,0,7,7,7,7,7,0,0,0,0,0,0
0,0,0,0,0,0,0,0,0,0,0,0,0,0,0,0,0
0,0,0,0,0,0,0,0,0,0,0,0,0,0,0,0,0
0,0,0,0,0,0,0,0,0,0,0,0,0,0,0,0,0
0,0,0,0,0,0,0,0,0,0,0,0,0,0,0,0,0
0,0,0,0,0,0,0,0,0,0,0,0,0,0,0,0,0
0,0,0,0,0,0,0,0,0,0,0,0,0,0,0,0,0
0,0,0,0,0,0,0,0,0,0,0,0,0,0,0,0,0
0,0,0,0,0,0,0,0,0,0,0,0,0,0,0,0,0
0,0,0,0,0,0,0,0,0,0,0,0,0,0,0,0,0
endlayer

layer
0,0,0,0,0,0,0,0,0,0,0,0,0,0,0,0,0
0,0,0,0,0,0,0,0,0,0,0,0,0,0,0,0,0
0,0,0,0,0,0,7,7,27,7,7,0,0,0,0,0,0
0,0,0,8,9,9,0,0,0,0,0,9,9,8,0,0,0
0,0,0,9,0,0,0,0,0,0,0,0,0,9,0,0,0
0,0,0,9,0,0,0,0,0,0,0,0,0,9,0,0,0
0,0,7,0,0,0,0,0,0,0,0,0,0,0,7,0,0
0,0,7,0,0,0,0,0,0,0,0,0,0,0,7,0,0
0,0,27,0,0,0,0,0,11,0,0,0,0,0,27,0,0
0,0,7,0,0,0,0,22,29,0,0,0,0,0,7,0,0
0,0,7,0,0,0,0,0,0,0,0,0,0,0,7,0,0
0,0,0,9,0,0,0,0,0,0,0,0,0,9,0,0,0
0,0,0,9,0,0,0,0,0,0,0,0,0,9,0,0,0
0,0,0,8,9,9,0,0,0,0,0,9,9,8,0,0,0
0,0,0,0,0,0,7,7,27,7,7,0,0,0,0,0,0
0,0,0,0,0,0,0,0,0,0,0,0,0,0,0,0,0
0,0,0,0,0,0,0,0,0,0,0,0,0,0,0,0,0
0,0,0,0,0,0,0,0,0,0,0,0,0,0,0,0,0
0,0,0,0,0,0,0,0,0,0,0,0,0,0,0,0,0
0,0,0,0,0,0,0,0,0,0,0,0,0,0,0,0,0
0,0,0,0,0,0,0,0,0,0,0,0,0,0,0,0,0
0,0,0,0,0,0,0,0,0,0,0,0,0,0,0,0,0
0,0,0,0,0,0,0,0,0,0,0,0,0,0,0,0,0
0,0,0,0,0,0,0,0,0,0,0,0,0,0,0,0,0
endlayer

layer
0,0,0,0,0,0,0,0,0,0,0,0,0,0,0,0,0
0,0,0,0,0,0,0,0,0,0,0,0,0,0,0,0,0
0,0,0,0,0,0,7,7,7,7,7,0,0,0,0,0,0
0,0,0,8,9,9,0,0,0,0,0,9,9,8,0,0,0
0,0,0,9,0,0,0,0,0,0,0,0,0,9,0,0,0
0,0,0,9,0,0,0,0,0,0,0,0,0,9,0,0,0
0,0,7,0,0,0,0,0,0,0,0,0,0,0,7,0,0
0,0,7,0,0,0,0,0,0,0,0,0,0,0,7,0,0
0,0,7,0,0,0,0,0,11,10,0,0,0,0,7,0,0
0,0,7,0,0,0,0,0,0,22,0,0,0,0,7,0,0
0,0,7,0,0,0,0,0,0,0,0,0,0,0,7,0,0
0,0,0,9,0,0,0,0,0,0,0,0,0,9,0,0,0
0,0,0,9,0,0,0,0,0,0,0,0,0,9,0,0,0
0,0,0,8,9,9,0,0,0,0,0,9,9,8,0,0,0
0,0,0,0,0,0,7,7,7,7,7,0,0,0,0,0,0
0,0,0,0,0,0,0,0,0,0,0,0,0,0,0,0,0
0,0,0,0,0,0,0,0,0,0,0,0,0,0,0,0,0
0,0,0,0,0,0,0,0,0,0,0,0,0,0,0,0,0
0,0,0,0,0,0,0,0,0,0,0,0,0,0,0,0,0
0,0,0,0,0,0,0,0,0,0,0,0,0,0,0,0,0
0,0,0,0,0,0,0,0,0,0,0,0,0,0,0,0,0
0,0,0,0,0,0,0,0,0,0,0,0,0,0,0,0,0
0,0,0,0,0,0,0,0,0,0,0,0,0,0,0,0,0
0,0,0,0,0,0,0,0,0,0,0,0,0,0,0,0,0
endlayer

layer
0,0,0,0,0,0,0,0,0,0,0,0,0,0,0,0,0
0,0,0,0,0,0,0,0,0,0,0,0,0,0,0,0,0
0,0,0,0,0,0,7,7,7,7,7,0,0,0,0,0,0
0,0,0,8,9,9,0,0,0,0,0,9,9,8,0,0,0
0,0,0,9,0,0,0,0,0,0,0,0,0,9,0,0,0
0,0,0,9,0,0,0,0,0,0,0,0,0,9,0,0,0
0,0,7,0,0,0,0,0,0,0,0,0,0,0,7,0,0
0,0,7,0,0,0,0,0,23,22,0,0,0,0,7,0,0
0,0,7,0,0,0,0,0,11,0,0,0,0,0,7,0,0
0,0,7,0,0,0,0,0,0,0,0,0,0,0,7,0,0
0,0,7,0,0,0,0,0,0,0,0,0,0,0,7,0,0
0,0,0,9,0,0,0,0,0,0,0,0,0,9,0,0,0
0,0,0,9,0,0,0,0,0,0,0,0,0,9,0,0,0
0,0,0,8,9,9,0,0,0,0,0,9,9,8,0,0,0
0,0,0,0,0,0,7,7,7,7,7,0,0,0,0,0,0
0,0,0,0,0,0,0,0,0,0,0,0,0,0,0,0,0
0,0,0,0,0,0,0,0,0,0,0,0,0,0,0,0,0
0,0,0,0,0,0,0,0,0,0,0,0,0,0,0,0,0
0,0,0,0,0,0,0,0,0,0,0,0,0,0,0,0,0
0,0,0,0,0,0,0,0,0,0,0,0,0,0,0,0,0
0,0,0,0,0,0,0,0,0,0,0,0,0,0,0,0,0
0,0,0,0,0,0,0,0,0,0,0,0,0,0,0,0,0
0,0,0,0,0,0,0,0,0,0,0,0,0,0,0,0,0
0,0,0,0,0,0,0,0,0,0,0,0,0,0,0,0,0
endlayer

layer
0,0,0,0,0,0,0,0,0,0,0,0,0,0,0,0,0
0,0,0,0,0,0,0,0,0,0,0,0,0,0,0,0,0
0,0,0,0,0,0,7,7,7,7,7,0,0,0,0,0,0
0,0,0,8,9,9,0,0,0,0,0,9,9,8,0,0,0
0,0,0,9,0,0,0,0,0,0,0,0,0,9,0,0,0
0,0,0,9,0,0,0,0,0,0,0,0,0,9,0,0,0
0,0,7,0,0,0,0,0,0,0,0,0,0,0,7,0,0
0,0,7,0,0,0,0,22,0,0,0,0,0,0,7,0,0
0,0,7,0,0,0,0,28,11,0,0,0,0,0,7,0,0
0,0,7,0,0,0,0,0,0,0,0,0,0,0,7,0,0
0,0,7,0,0,0,0,0,0,0,0,0,0,0,7,0,0
0,0,0,9,0,0,0,0,0,0,0,0,0,9,0,0,0
0,0,0,9,0,0,0,0,0,0,0,0,0,9,0,0,0
0,0,0,8,9,9,0,0,0,0,0,9,9,8,0,0,0
0,0,0,0,0,0,7,7,7,7,7,0,0,0,0,0,0
0,0,0,0,0,0,0,0,0,0,0,0,0,0,0,0,0
0,0,0,0,0,0,0,0,0,0,0,0,0,0,0,0,0
0,0,0,0,0,0,0,0,0,0,0,0,0,0,0,0,0
0,0,0,0,0,0,0,0,0,0,0,0,0,0,0,0,0
0,0,0,0,0,0,0,0,0,0,0,0,0,0,0,0,0
0,0,0,0,0,0,0,0,0,0,0,0,0,0,0,0,0
0,0,0,0,0,0,0,0,0,0,0,0,0,0,0,0,0
0,0,0,0,0,0,0,0,0,0,0,0,0,0,0,0,0
0,0,0,0,0,0,0,0,0,0,0,0,0,0,0,0,0
endlayer

layer
0,0,0,0,0,0,0,0,0,0,0,0,0,0,0,0,0
0,0,0,0,0,0,0,0,0,0,0,0,0,0,0,0,0
0,0,0,0,0,0,7,7,27,7,7,0,0,0,0,0,0
0,0,0,8,9,9,0,0,0,0,0,9,9,8,0,0,0
0,0,0,9,0,0,0,0,0,0,0,0,0,9,0,0,0
0,0,0,9,0,0,0,0,0,0,0,0,0,9,0,0,0
0,0,7,0,0,0,0,0,0,0,0,0,0,0,7,0,0
0,0,7,0,0,0,0,0,0,0,0,0,0,0,7,0,0
0,0,27,0,0,0,0,0,11,0,0,0,0,0,27,0,0
0,0,7,0,0,0,0,22,29,0,0,0,0,0,7,0,0
0,0,7,0,0,0,0,0,0,0,0,0,0,0,7,0,0
0,0,0,9,0,0,0,0,0,0,0,0,0,9,0,0,0
0,0,0,9,0,0,0,0,0,0,0,0,0,9,0,0,0
0,0,0,8,9,9,0,0,0,0,0,9,9,8,0,0,0
0,0,0,0,0,0,7,7,27,7,7,0,0,0,0,0,0
0,0,0,0,0,0,0,0,0,0,0,0,0,0,0,0,0
0,0,0,0,0,0,0,0,0,0,0,0,0,0,0,0,0
0,0,0,0,0,0,0,0,0,0,0,0,0,0,0,0,0
0,0,0,0,0,0,0,0,0,0,0,0,0,0,0,0,0
0,0,0,0,0,0,0,0,0,0,0,0,0,0,0,0,0
0,0,0,0,0,0,0,0,0,0,0,0,0,0,0,0,0
0,0,0,0,0,0,0,0,0,0,0,0,0,0,0,0,0
0,0,0,0,0,0,0,0,0,0,0,0,0,0,0,0,0
0,0,0,0,0,0,0,0,0,0,0,0,0,0,0,0,0
endlayer

layer
0,0,0,0,0,0,0,0,0,0,0,0,0,0,0,0,0
0,0,0,0,0,0,0,0,0,0,0,0,0,0,0,0,0
0,0,0,0,0,0,7,7,7,7,7,0,0,0,0,0,0
0,0,0,8,9,9,0,0,0,0,0,9,9,8,0,0,0
0,0,0,9,0,0,0,0,0,0,0,0,0,9,0,0,0
0,0,0,9,0,0,0,0,0,0,0,0,0,9,0,0,0
0,0,7,0,0,0,0,0,0,0,0,0,0,0,7,0,0
0,0,7,0,0,0,0,0,0,0,0,0,0,0,7,0,0
0,0,7,0,0,0,0,0,11,10,0,0,0,0,7,0,0
0,0,7,0,0,0,0,0,0,22,0,0,0,0,7,0,0
0,0,7,0,0,0,0,0,0,0,0,0,0,0,7,0,0
0,0,0,9,0,0,0,0,0,0,0,0,0,9,0,0,0
0,0,0,9,0,0,0,0,0,0,0,0,0,9,0,0,0
0,0,0,8,9,9,0,0,0,0,0,9,9,8,0,0,0
0,0,0,0,0,0,7,7,7,7,7,0,0,0,0,0,0
0,0,0,0,0,0,0,0,0,0,0,0,0,0,0,0,0
0,0,0,0,0,0,0,0,0,0,0,0,0,0,0,0,0
0,0,0,0,0,0,0,0,0,0,0,0,0,0,0,0,0
0,0,0,0,0,0,0,0,0,0,0,0,0,0,0,0,0
0,0,0,0,0,0,0,0,0,0,0,0,0,0,0,0,0
0,0,0,0,0,0,0,0,0,0,0,0,0,0,0,0,0
0,0,0,0,0,0,0,0,0,0,0,0,0,0,0,0,0
0,0,0,0,0,0,0,0,0,0,0,0,0,0,0,0,0
0,0,0,0,0,0,0,0,0,0,0,0,0,0,0,0,0
endlayer

layer
0,0,0,0,0,0,0,0,0,0,0,0,0,0,0,0,0
0,0,0,0,0,0,0,0,0,0,0,0,0,0,0,0,0
0,0,0,0,0,0,7,7,7,7,7,0,0,0,0,0,0
0,0,0,8,9,9,0,0,0,0,0,9,9,8,0,0,0
0,0,0,9,0,0,0,0,0,0,0,0,0,9,0,0,0
0,0,0,9,0,0,0,0,0,0,0,0,0,9,0,0,0
0,0,7,0,0,0,0,0,0,0,0,0,0,0,7,0,0
0,0,7,0,0,0,0,0,23,22,0,0,0,0,7,0,0
0,0,7,0,0,0,0,0,11,0,0,0,0,0,7,0,0
0,0,7,0,0,0,0,0,0,0,0,0,0,0,7,0,0
0,0,7,0,0,0,0,0,0,0,0,0,0,0,7,0,0
0,0,0,9,0,0,0,0,0,0,0,0,0,9,0,0,0
0,0,0,9,0,0,0,0,0,0,0,0,0,9,0,0,0
0,0,0,8,9,9,0,0,0,0,0,9,9,8,0,0,0
0,0,0,0,0,0,7,7,7,7,7,0,0,0,0,0,0
0,0,0,0,0,0,0,0,0,0,0,0,0,0,0,0,0
0,0,0,0,0,0,0,0,0,0,0,0,0,0,0,0,0
0,0,0,0,0,0,0,0,0,0,0,0,0,0,0,0,0
0,0,0,0,0,0,0,0,0,0,0,0,0,0,0,0,0
0,0,0,0,0,0,0,0,0,0,0,0,0,0,0,0,0
0,0,0,0,0,0,0,0,0,0,0,0,0,0,0,0,0
0,0,0,0,0,0,0,0,0,0,0,0,0,0,0,0,0
0,0,0,0,0,0,0,0,0,0,0,0,0,0,0,0,0
0,0,0,0,0,0,0,0,0,0,0,0,0,0,0,0,0
endlayer

layer
0,0,0,0,0,0,0,0,0,0,0,0,0,0,0,0,0
0,0,0,0,0,0,0,0,0,0,0,0,0,0,0,0,0
0,0,0,0,0,0,7,7,7,7,7,0,0,0,0,0,0
0,0,0,8,9,9,0,0,0,0,0,9,9,8,0,0,0
0,0,0,9,0,0,0,0,0,0,0,0,0,9,0,0,0
0,0,0,9,0,0,0,0,0,0,0,0,0,9,0,0,0
0,0,7,0,0,0,0,0,0,0,0,0,0,0,7,0,0
0,0,7,0,0,0,0,22,0,0,0,0,0,0,7,0,0
0,0,7,0,0,0,0,28,11,0,0,0,0,0,7,0,0
0,0,7,0,0,0,0,0,0,0,0,0,0,0,7,0,0
0,0,7,0,0,0,0,0,0,0,0,0,0,0,7,0,0
0,0,0,9,0,0,0,0,0,0,0,0,0,9,0,0,0
0,0,0,9,0,0,0,0,0,0,0,0,0,9,0,0,0
0,0,0,8,9,9,0,0,0,0,0,9,9,8,0,0,0
0,0,0,0,0,0,7,7,7,7,7,0,0,0,0,0,0
0,0,0,0,0,0,0,0,0,0,0,0,0,0,0,0,0
0,0,0,0,0,0,0,0,0,0,0,0,0,0,0,0,0
0,0,0,0,0,0,0,0,0,0,0,0,0,0,0,0,0
0,0,0,0,0,0,0,0,0,0,0,0,0,0,0,0,0
0,0,0,0,0,0,0,0,0,0,0,0,0,0,0,0,0
0,0,0,0,0,0,0,0,0,0,0,0,0,0,0,0,0
0,0,0,0,0,0,0,0,0,0,0,0,0,0,0,0,0
0,0,0,0,0,0,0,0,0,0,0,0,0,0,0,0,0
0,0,0,0,0,0,0,0,0,0,0,0,0,0,0,0,0
endlayer

layer
0,0,0,0,0,0,0,0,0,0,0,0,0,0,0,0,0
0,0,0,0,0,0,0,0,0,0,0,0,0,0,0,0,0
0,0,0,0,0,0,7,7,27,7,7,0,0,0,0,0,0
0,0,0,8,9,9,0,0,0,0,0,9,9,8,0,0,0
0,0,0,9,0,0,0,0,0,0,0,0,0,9,0,0,0
0,0,0,9,0,0,0,0,0,0,0,0,0,9,0,0,0
0,0,7,0,0,0,0,0,0,0,0,0,0,0,7,0,0
0,0,7,0,0,0,0,0,0,0,0,0,0,0,7,0,0
0,0,27,0,0,0,0,0,11,0,0,0,0,0,27,0,0
0,0,7,0,0,0,0,22,29,0,0,0,0,0,7,0,0
0,0,7,0,0,0,0,0,0,0,0,0,0,0,7,0,0
0,0,0,9,0,0,0,0,0,0,0,0,0,9,0,0,0
0,0,0,9,0,0,0,0,0,0,0,0,0,9,0,0,0
0,0,0,8,9,9,0,0,0,0,0,9,9,8,0,0,0
0,0,0,0,0,0,7,7,27,7,7,0,0,0,0,0,0
0,0,0,0,0,0,0,0,0,0,0,0,0,0,0,0,0
0,0,0,0,0,0,0,0,0,0,0,0,0,0,0,0,0
0,0,0,0,0,0,0,0,0,0,0,0,0,0,0,0,0
0,0,0,0,0,0,0,0,0,0,0,0,0,0,0,0,0
0,0,0,0,0,0,0,0,0,0,0,0,0,0,0,0,0
0,0,0,0,0,0,0,0,0,0,0,0,0,0,0,0,0
0,0,0,0,0,0,0,0,0,0,0,0,0,0,0,0,0
0,0,0,0,0,0,0,0,0,0,0,0,0,0,0,0,0
0,0,0,0,0,0,0,0,0,0,0,0,0,0,0,0,0
endlayer

layer
0,0,0,0,0,0,0,0,0,0,0,0,0,0,0,0,0
0,0,0,0,0,0,0,0,0,0,0,0,0,0,0,0,0
0,0,0,0,0,0,7,7,7,7,7,0,0,0,0,0,0
0,0,0,8,9,9,0,0,0,0,0,9,9,8,0,0,0
0,0,0,9,0,0,0,0,0,0,0,0,0,9,0,0,0
0,0,0,9,0,0,0,0,0,0,0,0,0,9,0,0,0
0,0,7,0,0,0,0,0,0,0,0,0,0,0,7,0,0
0,0,7,0,0,0,0,0,0,0,0,0,0,0,7,0,0
0,0,7,0,0,0,0,0,11,10,0,0,0,0,7,0,0
0,0,7,0,0,0,0,0,0,22,0,0,0,0,7,0,0
0,0,7,0,0,0,0,0,0,0,0,0,0,0,7,0,0
0,0,0,9,0,0,0,0,0,0,0,0,0,9,0,0,0
0,0,0,9,0,0,0,0,0,0,0,0,0,9,0,0,0
0,0,0,8,9,9,0,0,0,0,0,9,9,8,0,0,0
0,0,0,0,0,0,7,7,7,7,7,0,0,0,0,0,0
0,0,0,0,0,0,0,0,0,0,0,0,0,0,0,0,0
0,0,0,0,0,0,0,0,0,0,0,0,0,0,0,0,0
0,0,0,0,0,0,0,0,0,0,0,0,0,0,0,0,0
0,0,0,0,0,0,0,0,0,0,0,0,0,0,0,0,0
0,0,0,0,0,0,0,0,0,0,0,0,0,0,0,0,0
0,0,0,0,0,0,0,0,0,0,0,0,0,0,0,0,0
0,0,0,0,0,0,0,0,0,0,0,0,0,0,0,0,0
0,0,0,0,0,0,0,0,0,0,0,0,0,0,0,0,0
0,0,0,0,0,0,0,0,0,0,0,0,0,0,0,0,0
endlayer

layer
0,0,0,0,0,0,0,0,0,0,0,0,0,0,0,0,0
0,0,0,0,0,0,0,0,0,0,0,0,0,0,0,0,0
0,0,0,0,0,0,7,7,7,7,7,0,0,0,0,0,0
0,0,0,8,9,9,0,0,0,0,0,9,9,8,0,0,0
0,0,0,9,0,0,0,0,0,0,0,0,0,9,0,0,0
0,0,0,9,0,0,0,0,0,0,0,0,0,9,0,0,0
0,0,7,0,0,0,0,0,0,0,0,0,0,0,7,0,0
0,0,7,0,0,0,0,0,23,22,0,0,0,0,7,0,0
0,0,7,0,0,0,0,0,11,0,0,0,0,0,7,0,0
0,0,7,0,0,0,0,0,0,0,0,0,0,0,7,0,0
0,0,7,0,0,0,0,0,0,0,0,0,0,0,7,0,0
0,0,0,9,0,0,0,0,0,0,0,0,0,9,0,0,0
0,0,0,9,0,0,0,0,0,0,0,0,0,9,0,0,0
0,0,0,8,9,9,0,0,0,0,0,9,9,8,0,0,0
0,0,0,0,0,0,7,7,7,7,7,0,0,0,0,0,0
0,0,0,0,0,0,0,0,0,0,0,0,0,0,0,0,0
0,0,0,0,0,0,0,0,0,0,0,0,0,0,0,0,0
0,0,0,0,0,0,0,0,0,0,0,0,0,0,0,0,0
0,0,0,0,0,0,0,0,0,0,0,0,0,0,0,0,0
0,0,0,0,0,0,0,0,0,0,0,0,0,0,0,0,0
0,0,0,0,0,0,0,0,0,0,0,0,0,0,0,0,0
0,0,0,0,0,0,0,0,0,0,0,0,0,0,0,0,0
0,0,0,0,0,0,0,0,0,0,0,0,0,0,0,0,0
0,0,0,0,0,0,0,0,0,0,0,0,0,0,0,0,0
endlayer

layer
0,0,0,0,0,0,0,0,0,0,0,0,0,0,0,0,0
0,0,0,0,0,0,0,0,0,0,0,0,0,0,0,0,0
0,0,0,0,0,0,7,7,7,7,7,0,0,0,0,0,0
0,0,0,8,9,9,0,0,0,0,0,9,9,8,0,0,0
0,0,0,9,0,0,0,0,0,0,0,0,0,9,0,0,0
0,0,0,9,0,0,0,0,0,0,0,0,0,9,0,0,0
0,0,7,0,0,0,0,0,0,0,0,0,0,0,7,0,0
0,0,7,0,0,0,0,22,0,0,0,0,0,0,7,0,0
0,0,7,0,0,0,0,28,11,0,0,0,0,0,7,0,0
0,0,7,0,0,0,0,0,0,0,0,0,0,0,7,0,0
0,0,7,0,0,0,0,0,0,0,0,0,0,0,7,0,0
0,0,0,9,0,0,0,0,0,0,0,0,0,9,0,0,0
0,0,0,9,0,0,0,0,0,0,0,0,0,9,0,0,0
0,0,0,8,9,9,0,0,0,0,0,9,9,8,0,0,0
0,0,0,0,0,0,7,7,7,7,7,0,0,0,0,0,0
0,0,0,0,0,0,0,0,0,0,0,0,0,0,0,0,0
0,0,0,0,0,0,0,0,0,0,0,0,0,0,0,0,0
0,0,0,0,0,0,0,0,0,0,0,0,0,0,0,0,0
0,0,0,0,0,0,0,0,0,0,0,0,0,0,0,0,0
0,0,0,0,0,0,0,0,0,0,0,0,0,0,0,0,0
0,0,0,0,0,0,0,0,0,0,0,0,0,0,0,0,0
0,0,0,0,0,0,0,0,0,0,0,0,0,0,0,0,0
0,0,0,0,0,0,0,0,0,0,0,0,0,0,0,0,0
0,0,0,0,0,0,0,0,0,0,0,0,0,0,0,0,0
endlayer

layer
0,0,0,0,0,0,0,0,0,0,0,0,0,0,0,0,0
0,0,0,0,0,0,0,0,0,0,0,0,0,0,0,0,0
0,0,0,0,0,0,7,7,27,7,7,0,0,0,0,0,0
0,0,0,8,9,9,0,0,0,0,0,9,9,8,0,0,0
0,0,0,9,0,0,0,0,0,0,0,0,0,9,0,0,0
0,0,0,9,0,0,0,0,0,0,0,0,0,9,0,0,0
0,0,7,0,0,0,0,0,0,0,0,0,0,0,7,0,0
0,0,7,0,0,0,0,0,0,0,0,0,0,0,7,0,0
0,0,27,0,0,0,0,0,11,0,0,0,0,0,27,0,0
0,0,7,0,0,0,0,22,29,0,0,0,0,0,7,0,0
0,0,7,0,0,0,0,0,0,0,0,0,0,0,7,0,0
0,0,0,9,0,0,0,0,0,0,0,0,0,9,0,0,0
0,0,0,9,0,0,0,0,0,0,0,0,0,9,0,0,0
0,0,0,8,9,9,0,0,0,0,0,9,9,8,0,0,0
0,0,0,0,0,0,7,7,27,7,7,0,0,0,0,0,0
0,0,0,0,0,0,0,0,0,0,0,0,0,0,0,0,0
0,0,0,0,0,0,0,0,0,0,0,0,0,0,0,0,0
0,0,0,0,0,0,0,0,0,0,0,0,0,0,0,0,0
0,0,0,0,0,0,0,0,0,0,0,0,0,0,0,0,0
0,0,0,0,0,0,0,0,0,0,0,0,0,0,0,0,0
0,0,0,0,0,0,0,0,0,0,0,0,0,0,0,0,0
0,0,0,0,0,0,0,0,0,0,0,0,0,0,0,0,0
0,0,0,0,0,0,0,0,0,0,0,0,0,0,0,0,0
0,0,0,0,0,0,0,0,0,0,0,0,0,0,0,0,0
endlayer

layer
0,0,0,0,0,0,0,0,0,0,0,0,0,0,0,0,0
0,0,0,0,0,0,0,0,0,0,0,0,0,0,0,0,0
0,0,0,0,0,0,7,7,7,7,7,0,0,0,0,0,0
0,0,0,8,9,9,0,0,0,0,0,9,9,8,0,0,0
0,0,0,9,0,0,0,0,0,0,0,0,0,9,0,0,0
0,0,0,9,0,0,0,0,0,0,0,0,0,9,0,0,0
0,0,7,0,0,0,0,0,0,0,0,0,0,0,7,0,0
0,0,7,0,0,0,0,0,0,0,0,0,0,0,7,0,0
0,0,7,0,0,0,0,0,11,10,0,0,0,0,7,0,0
0,0,7,0,0,0,0,0,0,22,0,0,0,0,7,0,0
0,0,7,0,0,0,0,0,0,0,0,0,0,0,7,0,0
0,0,0,9,0,0,0,0,0,0,0,0,0,9,0,0,0
0,0,0,9,0,0,0,0,0,0,0,0,0,9,0,0,0
0,0,0,8,9,9,0,0,0,0,0,9,9,8,0,0,0
0,0,0,0,0,0,7,7,7,7,7,0,0,0,0,0,0
0,0,0,0,0,0,0,0,0,0,0,0,0,0,0,0,0
0,0,0,0,0,0,0,0,0,0,0,0,0,0,0,0,0
0,0,0,0,0,0,0,0,0,0,0,0,0,0,0,0,0
0,0,0,0,0,0,0,0,0,0,0,0,0,0,0,0,0
0,0,0,0,0,0,0,0,0,0,0,0,0,0,0,0,0
0,0,0,0,0,0,0,0,0,0,0,0,0,0,0,0,0
0,0,0,0,0,0,0,0,0,0,0,0,0,0,0,0,0
0,0,0,0,0,0,0,0,0,0,0,0,0,0,0,0,0
0,0,0,0,0,0,0,0,0,0,0,0,0,0,0,0,0
endlayer

layer
0,0,0,0,0,0,0,0,0,0,0,0,0,0,0,0,0
0,0,0,0,0,0,0,0,0,0,0,0,0,0,0,0,0
0,0,0,0,0,0,7,7,7,7,7,0,0,0,0,0,0
0,0,0,8,9,9,0,0,0,0,0,9,9,8,0,0,0
0,0,0,9,0,0,0,0,0,0,0,0,0,9,0,0,0
0,0,0,9,0,0,0,0,0,0,0,0,0,9,0,0,0
0,0,7,0,0,0,0,0,0,0,0,0,0,0,7,0,0
0,0,7,0,0,0,0,0,23,22,0,0,0,0,7,0,0
0,0,7,0,0,0,0,0,11,0,0,0,0,0,7,0,0
0,0,7,0,0,0,0,0,0,0,0,0,0,0,7,0,0
0,0,7,0,0,0,0,0,0,0,0,0,0,0,7,0,0
0,0,0,9,0,0,0,0,0,0,0,0,0,9,0,0,0
0,0,0,9,0,0,0,0,0,0,0,0,0,9,0,0,0
0,0,0,8,9,9,0,0,0,0,0,9,9,8,0,0,0
0,0,0,0,0,0,7,7,7,7,7,0,0,0,0,0,0
0,0,0,0,0,0,0,0,0,0,0,0,0,0,0,0,0
0,0,0,0,0,0,0,0,0,0,0,0,0,0,0,0,0
0,0,0,0,0,0,0,0,0,0,0,0,0,0,0,0,0
0,0,0,0,0,0,0,0,0,0,0,0,0,0,0,0,0
0,0,0,0,0,0,0,0,0,0,0,0,0,0,0,0,0
0,0,0,0,0,0,0,0,0,0,0,0,0,0,0,0,0
0,0,0,0,0,0,0,0,0,0,0,0,0,0,0,0,0
0,0,0,0,0,0,0,0,0,0,0,0,0,0,0,0,0
0,0,0,0,0,0,0,0,0,0,0,0,0,0,0,0,0
endlayer

layer
0,0,0,0,0,0,0,0,0,0,0,0,0,0,0,0,0
0,0,0,0,0,0,0,0,0,0,0,0,0,0,0,0,0
0,0,0,0,0,0,7,7,7,7,7,0,0,0,0,0,0
0,0,0,8,9,9,0,0,0,0,0,9,9,8,0,0,0
0,0,0,9,0,0,0,0,0,0,0,0,0,9,0,0,0
0,0,0,9,0,0,0,0,0,0,0,0,0,9,0,0,0
0,0,7,0,0,0,0,0,0,0,0,0,0,0,7,0,0
0,0,7,0,0,0,0,23,0,0,0,0,0,0,7,0,0
0,0,7,0,0,0,0,0,11,0,0,0,0,0,7,0,0
0,0,7,0,0,0,0,0,0,0,0,0,0,0,7,0,0
0,0,7,0,0,0,0,0,0,0,0,0,0,0,7,0,0
0,0,0,9,0,0,0,0,0,0,0,0,0,9,0,0,0
0,0,0,9,0,0,0,0,0,0,0,0,0,9,0,0,0
0,0,0,8,9,9,0,0,0,0,0,9,9,8,0,0,0
0,0,0,0,0,0,7,7,7,7,7,0,0,0,0,0,0
0,0,0,0,0,0,0,0,0,0,0,0,0,0,0,0,0
0,0,0,0,0,0,0,0,0,0,0,0,0,0,0,0,0
0,0,0,0,0,0,0,0,0,0,0,0,0,0,0,0,0
0,0,0,0,0,0,0,0,0,0,0,0,0,0,0,0,0
0,0,0,0,0,0,0,0,0,0,0,0,0,0,0,0,0
0,0,0,0,0,0,0,0,0,0,0,0,0,0,0,0,0
0,0,0,0,0,0,0,0,0,0,0,0,0,0,0,0,0
0,0,0,0,0,0,0,0,0,0,0,0,0,0,0,0,0
0,0,0,0,0,0,0,0,0,0,0,0,0,0,0,0,0
endlayer

layer
0,0,0,0,0,0,0,0,0,0,0,0,0,0,0,0,0
0,0,0,0,0,0,0,0,0,0,0,0,0,0,0,0,0
0,0,0,0,0,0,37,37,37,37,37,0,0,0,0,0,0
0,0,0,8,37,37,0,0,0,0,0,37,37,8,0,0,0
0,0,0,37,0,0,0,0,0,0,0,0,0,37,0,0,0
0,0,0,37,0,0,0,0,0,0,0,0,0,37,0,0,0
0,0,37,0,0,0,0,0,0,0,0,0,0,0,37,0,0
0,0,37,0,0,38,23,0,0,0,0,0,0,0,37,0,0
0,0,37,0,0,0,0,0,11,0,0,0,0,0,37,0,0
0,0,37,0,0,0,0,0,0,0,0,0,0,0,37,0,0
0,0,37,0,0,0,0,0,0,0,0,0,0,0,37,0,0
0,0,0,37,0,0,0,0,0,0,0,0,0,37,0,0,0
0,0,0,37,0,0,0,0,0,0,0,0,0,37,0,0,0
0,0,0,8,37,37,0,0,0,0,0,37,37,8,0,0,0
0,0,0,0,0,0,37,37,37,37,37,0,0,0,0,0,0
0,0,0,0,0,0,0,0,0,0,0,0,0,0,0,0,0
0,0,0,0,0,0,0,0,0,0,0,0,0,0,0,0,0
0,0,0,0,0,0,0,0,0,0,0,0,0,0,0,0,0
0,0,0,0,0,0,0,0,0,0,0,0,0,0,0,0,0
0,0,0,0,0,0,0,0,0,0,0,0,0,0,0,0,0
0,0,0,0,0,0,0,0,0,0,0,0,0,0,0,0,0
0,0,0,0,0,0,0,0,0,0,0,0,0,0,0,0,0
0,0,0,0,0,0,0,0,0,0,0,0,0,0,0,0,0
0,0,0,0,0,0,0,0,0,0,0,0,0,0,0,0,0
endlayer

layer
0,0,0,0,0,0,0,0,0,0,0,0,0,0,0,0,0
0,0,0,0,0,0,0,0,0,0,0,0,0,0,0,0,0
0,0,0,0,0,0,37,37,37,37,37,0,0,0,0,0,0
0,0,0,8,37,37,0,0,0,0,0,37,37,8,0,0,0
0,0,0,37,0,0,0,0,0,0,0,0,0,37,0,0,0
0,0,0,37,0,0,0,0,0,0,0,0,0,37,0,0,0
0,0,37,0,0,0,0,0,0,0,0,0,0,0,37,0,0
0,0,37,0,0,0,0,0,0,0,0,0,0,0,37,0,0
0,0,37,0,0,28,0,0,11,0,0,0,0,0,37,0,0
0,0,37,0,0,0,0,0,0,0,0,0,0,0,37,0,0
0,0,37,0,0,0,0,0,0,0,0,0,0,0,37,0,0
0,0,0,37,0,0,0,0,0,0,0,0,0,37,0,0,0
0,0,0,37,0,0,0,0,0,0,0,0,0,37,0,0,0
0,0,0,8,37,37,0,0,0,0,0,37,37,8,0,0,0
0,0,0,0,0,0,37,37,37,37,37,0,0,0,0,0,0
0,0,0,0,0,0,0,0,0,0,0,0,0,0,0,0,0
0,0,0,0,0,0,0,0,0,0,0,0,0,0,0,0,0
0,0,0,0,0,0,0,0,0,0,0,0,0,0,0,0,0
0,0,0,0,0,0,0,0,0,0,0,0,0,0,0,0,0
0,0,0,0,0,0,0,0,0,0,0,0,0,0,0,0,0
0,0,0,0,0,0,0,0,0,0,0,0,0,0,0,0,0
0,0,0,0,0,0,0,0,0,0,0,0,0,0,0,0,0
0,0,0,0,0,0,0,0,0,0,0,0,0,0,0,0,0
0,0,0,0,0,0,0,0,0,0,0,0,0,0,0,0,0
endlayer

layer
0,0,0,0,0,0,0,0,0,0,0,0,0,0,0,0,0
0,0,0,0,0,39,39,39,39,39,39,39,0,0,0,0,0
0,0,0,39,39,40,37,37,37,37,37,40,39,39,0,0,0
0,0,39,40,37,37,37,37,37,37,37,37,37,40,39,0,0
0,0,39,37,37,37,37,37,37,37,37,37,37,37,39,0,0
0,39,40,37,37,37,37,37,37,37,37,37,37,37,40,39,0
0,39,37,37,37,37,37,37,37,37,37,37,37,37,37,39,0
0,39,37,37,37,0,0,0,37,37,37,37,37,37,37,39,0
0,39,37,37,37,0,37,37,37,37,37,37,37,37,37,39,0
0,39,37,37,37,28,37,37,37,37,37,37,37,37,37,39,0
0,39,37,37,37,37,37,37,37,37,37,37,37,37,37,39,0
0,39,40,37,37,37,37,37,37,37,37,37,37,37,40,39,0
0,0,39,37,37,37,37,37,37,37,37,37,37,37,39,0,0
0,0,39,40,37,37,37,37,37,37,37,37,37,40,39,0,0
0,0,0,39,39,40,37,37,37,37,37,40,39,39,0,0,0
0,0,0,0,0,39,39,39,39,39,39,39,0,0,0,0,0
0,0,0,0,0,0,0,0,0,0,0,0,0,0,0,0,0
0,0,0,0,0,0,0,0,0,0,0,0,0,0,0,0,0
0,0,0,0,0,0,0,0,0,0,0,0,0,0,0,0,0
0,0,0,0,0,0,0,0,0,0,0,0,0,0,0,0,0
0,0,0,0,0,0,0,0,0,0,0,0,0,0,0,0,0
0,0,0,0,0,0,0,0,0,0,0,0,0,0,0,0,0
0,0,0,0,0,0,0,0,0,0,0,0,0,0,0,0,0
0,0,0,0,0,0,0,0,0,0,0,0,0,0,0,0,0
endlayer

layer
0,0,0,0,0,0,0,0,0,0,0,0,0,0,0,0,0
0,0,0,0,0,17,17,17,17,17,17,17,0,0,0,0,0
0,0,0,17,17,17,0,0,0,0,0,17,17,17,0,0,0
0,0,17,17,0,0,0,0,0,0,0,0,0,17,17,0,0
0,0,17,0,0,0,37,37,37,37,37,0,0,0,17,0,0
0,17,17,0,0,40,0,0,0,0,0,37,0,0,17,17,0
0,17,0,0,37,0,0,0,0,0,0,0,37,0,0,17,0
0,17,0,0,37,0,0,0,0,0,0,0,37,0,0,17,0
0,17,0,0,37,0,0,0,8,0,0,41,37,0,0,17,0
0,17,0,0,37,0,0,0,0,0,0,0,37,0,0,17,0
0,17,0,0,37,0,0,0,0,0,0,0,37,0,0,17,0
0,17,17,0,0,37,0,0,0,0,0,40,0,0,17,17,0
0,0,17,0,0,0,37,37,37,37,37,0,0,0,17,0,0
0,0,17,17,0,0,0,0,0,0,0,0,0,17,17,0,0
0,0,0,17,17,17,0,0,0,0,0,17,17,17,0,0,0
0,0,0,0,0,17,17,17,17,17,17,17,0,0,0,0,0
0,0,0,0,0,0,0,0,0,0,0,0,0,0,0,0,0
0,0,0,0,0,0,0,0,0,0,0,0,0,0,0,0,0
0,0,0,0,0,0,0,0,0,0,0,0,0,0,0,0,0
0,0,0,0,0,0,0,0,0,0,0,0,0,0,0,0,0
0,0,0,0,0,0,0,0,0,0,0,0,0,0,0,0,0
0,0,0,0,0,0,0,0,0,0,0,0,0,0,0,0,0
0,0,0,0,0,0,0,0,0,0,0,0,0,0,0,0,0
0,0,0,0,0,0,0,0,0,0,0,0,0,0,0,0,0
endlayer

layer
0,0,0,0,0,0,0,0,0,0,0,0,0,0,0,0,0
0,0,0,0,0,0,0,0,0,0,0,0,0,0,0,0,0
0,0,0,0,0,0,0,0,0,0,0,0,0,0,0,0,0
0,0,0,0,0,0,0,0,0,0,0,0,0,0,0,0,0
0,0,0,0,0,0,42,42,42,42,42,0,0,0,0,0,0
0,0,0,0,0,42,0,0,0,0,0,42,0,0,0,0,0
0,0,0,0,42,0,0,0,0,0,0,0,42,0,0,0,0
0,0,0,0,42,0,0,0,0,0,0,0,42,0,0,0,0
0,0,0,0,42,0,0,0,8,0,0,0,42,0,0,0,0
0,0,0,0,42,0,0,0,0,0,0,0,42,0,0,0,0
0,0,0,0,42,0,0,0,0,0,0,0,42,0,0,0,0
0,0,0,0,0,42,0,0,0,0,0,42,0,0,0,0,0
0,0,0,0,0,0,42,42,42,42,42,0,0,0,0,0,0
0,0,0,0,0,0,0,0,0,0,0,0,0,0,0,0,0
0,0,0,0,0,0,0,0,0,0,0,0,0,0,0,0,0
0,0,0,0,0,0,0,0,0,0,0,0,0,0,0,0,0
0,0,0,0,0,0,0,0,0,0,0,0,0,0,0,0,0
0,0,0,0,0,0,0,0,0,0,0,0,0,0,0,0,0
0,0,0,0,0,0,0,0,0,0,0,0,0,0,0,0,0
0,0,0,0,0,0,0,0,0,0,0,0,0,0,0,0,0
0,0,0,0,0,0,0,0,0,0,0,0,0,0,0,0,0
0,0,0,0,0,0,0,0,0,0,0,0,0,0,0,0,0
0,0,0,0,0,0,0,0,0,0,0,0,0,0,0,0,0
0,0,0,0,0,0,0,0,0,0,0,0,0,0,0,0,0
endlayer

layer
0,0,0,0,0,0,0,0,0,0,0,0,0,0,0,0,0
0,0,0,0,0,0,0,0,0,0,0,0,0,0,0,0,0
0,0,0,0,0,0,0,0,0,0,0,0,0,0,0,0,0
0,0,0,0,0,0,0,0,0,0,0,0,0,0,0,0,0
0,0,0,0,0,0,42,42,42,42,42,0,0,0,0,0,0
0,0,0,0,0,42,0,0,0,0,0,42,0,0,0,0,0
0,0,0,0,42,0,0,0,0,0,0,0,42,0,0,0,0
0,0,0,0,42,0,0,0,43,0,0,0,42,0,0,0,0
0,0,0,0,42,0,0,43,43,43,0,0,42,0,0,0,0
0,0,0,0,42,0,0,0,43,0,0,0,42,0,0,0,0
0,0,0,0,42,0,0,0,0,0,0,0,42,0,0,0,0
0,0,0,0,0,42,0,0,0,0,0,42,0,0,0,0,0
0,0,0,0,0,0,42,42,42,42,42,0,0,0,0,0,0
0,0,0,0,0,0,0,0,0,0,0,0,0,0,0,0,0
0,0,0,0,0,0,0,0,0,0,0,0,0,0,0,0,0
0,0,0,0,0,0,0,0,0,0,0,0,0,0,0,0,0
0,0,0,0,0,0,0,0,0,0,0,0,0,0,0,0,0
0,0,0,0,0,0,0,0,0,0,0,0,0,0,0,0,0
0,0,0,0,0,0,0,0,0,0,0,0,0,0,0,0,0
0,0,0,0,0,0,0,0,0,0,0,0,0,0,0,0,0
0,0,0,0,0,0,0,0,0,0,0,0,0,0,0,0,0
0,0,0,0,0,0,0,0,0,0,0,0,0,0,0,0,0
0,0,0,0,0,0,0,0,0,0,0,0,0,0,0,0,0
0,0,0,0,0,0,0,0,0,0,0,0,0,0,0,0,0
endlayer

layer
0,0,0,0,0,0,0,0,0,0,0,0,0,0,0,0,0
0,0,0,0,0,0,0,0,0,0,0,0,0,0,0,0,0
0,0,0,0,0,0,0,0,0,0,0,0,0,0,0,0,0
0,0,0,0,0,0,0,0,0,0,0,0,0,0,0,0,0
0,0,0,0,0,0,42,42,42,42,42,0,0,0,0,0,0
0,0,0,0,0,42,0,0,0,0,0,42,0,0,0,0,0
0,0,0,0,42,0,0,0,0,0,0,0,42,0,0,0,0
0,0,0,0,42,0,0,0,44,0,0,0,42,0,0,0,0
0,0,0,0,42,0,0,44,44,44,0,0,42,0,0,0,0
0,0,0,0,42,0,0,0,44,0,0,0,42,0,0,0,0
0,0,0,0,42,0,0,0,0,0,0,0,42,0,0,0,0
0,0,0,0,0,42,0,0,0,0,0,42,0,0,0,0,0
0,0,0,0,0,0,42,42,42,42,42,0,0,0,0,0,0
0,0,0,0,0,0,0,0,0,0,0,0,0,0,0,0,0
0,0,0,0,0,0,0,0,0,0,0,0,0,0,0,0,0
0,0,0,0,0,0,0,0,0,0,0,0,0,0,0,0,0
0,0,0,0,0,0,0,0,0,0,0,0,0,0,0,0,0
0,0,0,0,0,0,0,0,0,0,0,0,0,0,0,0,0
0,0,0,0,0,0,0,0,0,0,0,0,0,0,0,0,0
0,0,0,0,0,0,0,0,0,0,0,0,0,0,0,0,0
0,0,0,0,0,0,0,0,0,0,0,0,0,0,0,0,0
0,0,0,0,0,0,0,0,0,0,0,0,0,0,0,0,0
0,0,0,0,0,0,0,0,0,0,0,0,0,0,0,0,0
0,0,0,0,0,0,0,0,0,0,0,0,0,0,0,0,0
endlayer

layer
0,0,0,0,0,0,0,0,0,0,0,0,0,0,0,0,0
0,0,0,0,0,0,0,0,0,0,0,0,0,0,0,0,0
0,0,0,0,0,0,0,0,0,0,0,0,0,0,0,0,0
0,0,0,0,0,0,0,0,0,0,0,0,0,0,0,0,0
0,0,0,0,0,0,42,42,42,42,42,0,0,0,0,0,0
0,0,0,0,0,42,0,0,0,0,0,42,0,0,0,0,0
0,0,0,0,42,0,0,0,0,0,0,0,42,0,0,0,0
0,0,0,0,42,0,0,0,20,0,0,0,42,0,0,0,0
0,0,0,0,42,0,0,20,20,20,0,0,42,0,0,0,0
0,0,0,0,42,0,0,0,20,0,0,0,42,0,0,0,0
0,0,0,0,42,0,0,0,0,0,0,0,42,0,0,0,0
0,0,0,0,0,42,0,0,0,0,0,42,0,0,0,0,0
0,0,0,0,0,0,42,42,42,42,42,0,0,0,0,0,0
0,0,0,0,0,0,0,0,0,0,0,0,0,0,0,0,0
0,0,0,0,0,0,0,0,0,0,0,0,0,0,0,0,0
0,0,0,0,0,0,0,0,0,0,0,0,0,0,0,0,0
0,0,0,0,0,0,0,0,0,0,0,0,0,0,0,0,0
0,0,0,0,0,0,0,0,0,0,0,0,0,0,0,0,0
0,0,0,0,0,0,0,0,0,0,0,0,0,0,0,0,0
0,0,0,0,0,0,0,0,0,0,0,0,0,0,0,0,0
0,0,0,0,0,0,0,0,0,0,0,0,0,0,0,0,0
0,0,0,0,0,0,0,0,0,0,0,0,0,0,0,0,0
0,0,0,0,0,0,0,0,0,0,0,0,0,0,0,0,0
0,0,0,0,0,0,0,0,0,0,0,0,0,0,0,0,0
endlayer

layer
0,0,0,0,0,0,0,0,0,0,0,0,0,0,0,0,0
0,0,0,0,0,0,0,0,0,0,0,0,0,0,0,0,0
0,0,0,0,0,0,0,0,0,0,0,0,0,0,0,0,0
0,0,0,0,0,0,0,0,0,0,0,0,0,0,0,0,0
0,0,0,0,0,0,42,42,42,42,42,0,0,0,0,0,0
0,0,0,0,0,42,0,0,0,0,0,42,0,0,0,0,0
0,0,0,0,42,0,0,0,0,0,0,0,42,0,0,0,0
0,0,0,0,42,0,0,0,0,0,0,0,42,0,0,0,0
0,0,0,0,42,0,0,0,0,0,0,0,42,0,0,0,0
0,0,0,0,42,0,0,0,0,0,0,0,42,0,0,0,0
0,0,0,0,42,0,0,0,0,0,0,0,42,0,0,0,0
0,0,0,0,0,42,0,0,0,0,0,42,0,0,0,0,0
0,0,0,0,0,0,42,42,42,42,42,0,0,0,0,0,0
0,0,0,0,0,0,0,0,0,0,0,0,0,0,0,0,0
0,0,0,0,0,0,0,0,0,0,0,0,0,0,0,0,0
0,0,0,0,0,0,0,0,0,0,0,0,0,0,0,0,0
0,0,0,0,0,0,0,0,0,0,0,0,0,0,0,0,0
0,0,0,0,0,0,0,0,0,0,0,0,0,0,0,0,0
0,0,0,0,0,0,0,0,0,0,0,0,0,0,0,0,0
0,0,0,0,0,0,0,0,0,0,0,0,0,0,0,0,0
0,0,0,0,0,0,0,0,0,0,0,0,0,0,0,0,0
0,0,0,0,0,0,0,0,0,0,0,0,0,0,0,0,0
0,0,0,0,0,0,0,0,0,0,0,0,0,0,0,0,0
0,0,0,0,0,0,0,0,0,0,0,0,0,0,0,0,0
endlayer

layer
0,0,0,0,0,0,0,0,0,0,0,0,0,0,0,0,0
0,0,0,0,0,0,0,0,0,0,0,0,0,0,0,0,0
0,0,0,0,0,0,0,0,0,0,0,0,0,0,0,0,0
0,0,0,0,0,0,0,0,0,0,0,0,0,0,0,0,0
0,0,0,0,0,0,42,42,42,42,42,0,0,0,0,0,0
0,0,0,0,0,42,0,0,0,0,0,42,0,0,0,0,0
0,0,0,0,42,0,0,0,0,0,0,0,42,0,0,0,0
0,0,0,0,42,0,0,0,0,0,0,0,42,0,0,0,0
0,0,0,0,42,0,0,0,0,0,0,0,42,0,0,0,0
0,0,0,0,42,0,0,0,0,0,0,0,42,0,0,0,0
0,0,0,0,42,0,0,0,0,0,0,0,42,0,0,0,0
0,0,0,0,0,42,0,0,0,0,0,42,0,0,0,0,0
0,0,0,0,0,0,42,42,42,42,42,0,0,0,0,0,0
0,0,0,0,0,0,0,0,0,0,0,0,0,0,0,0,0
0,0,0,0,0,0,0,0,0,0,0,0,0,0,0,0,0
0,0,0,0,0,0,0,0,0,0,0,0,0,0,0,0,0
0,0,0,0,0,0,0,0,0,0,0,0,0,0,0,0,0
0,0,0,0,0,0,0,0,0,0,0,0,0,0,0,0,0
0,0,0,0,0,0,0,0,0,0,0,0,0,0,0,0,0
0,0,0,0,0,0,0,0,0,0,0,0,0,0,0,0,0
0,0,0,0,0,0,0,0,0,0,0,0,0,0,0,0,0
0,0,0,0,0,0,0,0,0,0,0,0,0,0,0,0,0
0,0,0,0,0,0,0,0,0,0,0,0,0,0,0,0,0
0,0,0,0,0,0,0,0,0,0,0,0,0,0,0,0,0
endlayer

layer
0,0,0,0,0,0,0,0,0,0,0,0,0,0,0,0,0
0,0,0,0,0,0,0,0,0,0,0,0,0,0,0,0,0
0,0,0,0,0,0,0,0,0,0,0,0,0,0,0,0,0
0,0,0,0,0,0,45,45,45,45,45,0,0,0,0,0,0
0,0,0,0,0,45,45,45,45,45,45,45,0,0,0,0,0
0,0,0,0,45,45,45,45,45,45,45,45,45,0,0,0,0
0,0,0,45,45,45,45,37,37,37,45,45,45,45,0,0,0
0,0,0,45,45,45,37,37,46,37,37,45,45,45,0,0,0
0,0,0,45,45,45,37,46,37,46,37,45,45,45,0,0,0
0,0,0,45,45,45,37,37,46,37,37,45,45,45,0,0,0
0,0,0,45,45,45,45,37,37,37,45,45,45,45,0,0,0
0,0,0,0,45,45,45,45,45,45,45,45,45,0,0,0,0
0,0,0,0,0,45,45,45,45,45,45,45,0,0,0,0,0
0,0,0,0,0,0,45,45,45,45,45,0,0,0,0,0,0
0,0,0,0,0,0,0,0,0,0,0,0,0,0,0,0,0
0,0,0,0,0,0,0,0,0,0,0,0,0,0,0,0,0
0,0,0,0,0,0,0,0,0,0,0,0,0,0,0,0,0
0,0,0,0,0,0,0,0,0,0,0,0,0,0,0,0,0
0,0,0,0,0,0,0,0,0,0,0,0,0,0,0,0,0
0,0,0,0,0,0,0,0,0,0,0,0,0,0,0,0,0
0,0,0,0,0,0,0,0,0,0,0,0,0,0,0,0,0
0,0,0,0,0,0,0,0,0,0,0,0,0,0,0,0,0
0,0,0,0,0,0,0,0,0,0,0,0,0,0,0,0,0
0,0,0,0,0,0,0,0,0,0,0,0,0,0,0,0,0
endlayer

layer
0,0,0,0,0,0,0,0,0,0,0,0,0,0,0,0,0
0,0,0,0,0,0,0,0,0,0,0,0,0,0,0,0,0
0,0,0,0,0,0,0,0,0,0,0,0,0,0,0,0,0
0,0,0,0,0,0,0,0,0,0,0,0,0,0,0,0,0
0,0,0,0,0,0,0,0,0,0,0,0,0,0,0,0,0
0,0,0,0,0,0,0,0,0,0,0,0,0,0,0,0,0
0,0,0,0,0,0,0,0,0,0,0,0,0,0,0,0,0
0,0,0,0,0,0,0,0,47,0,0,0,0,0,0,0,0
0,0,0,0,0,0,0,47,45,47,0,0,0,0,0,0,0
0,0,0,0,0,0,0,0,47,0,0,0,0,0,0,0,0
0,0,0,0,0,0,0,0,0,0,0,0,0,0,0,0,0
0,0,0,0,0,0,0,0,0,0,0,0,0,0,0,0,0
0,0,0,0,0,0,0,0,0,0,0,0,0,0,0,0,0
0,0,0,0,0,0,0,0,0,0,0,0,0,0,0,0,0
0,0,0,0,0,0,0,0,0,0,0,0,0,0,0,0,0
0,0,0,0,0,0,0,0,0,0,0,0,0,0,0,0,0
0,0,0,0,0,0,0,0,0,0,0,0,0,0,0,0,0
0,0,0,0,0,0,0,0,0,0,0,0,0,0,0,0,0
0,0,0,0,0,0,0,0,0,0,0,0,0,0,0,0,0
0,0,0,0,0,0,0,0,0,0,0,0,0,0,0,0,0
0,0,0,0,0,0,0,0,0,0,0,0,0,0,0,0,0
0,0,0,0,0,0,0,0,0,0,0,0,0,0,0,0,0
0,0,0,0,0,0,0,0,0,0,0,0,0,0,0,0,0
0,0,0,0,0,0,0,0,0,0,0,0,0,0,0,0,0
endlayer

