
# Created by Ruins mod version 15.0 Ingame Parser
# authoring Player: SunsOfOld

weight=10
embed_into_distance=0
acceptable_target_blocks=
unacceptable_target_blocks=flowing_water,water,flowing_lava,lava
dimensions=23,18,21
allowable_overhang=0
max_leveling=5
leveling_buffer=0
preserve_water=0
preserve_lava=0
uniqueMinDistance=1000000
preventRotation=1

rule1=0,100,GardenStuff:moss_brick-2
rule2=0,100,minecraft:web-0
rule3=0,100,GardenStuff:moss_brick-4
rule4=0,100,minecraft:stonebrick-0
rule5=0,100,GardenStuff:moss_brick-3
rule6=0,100,dendrology:leaves1-7
rule7=0,100,dendrology:nucis_planks-7
rule8=0,100,dendrology:logs1-3
rule9=0,100,BiblioCraft:BiblioIronLantern-0
rule10=0,100,minecraft:stonebrick-1
rule11=0,100,minecraft:stonebrick-2
rule12=0,100,dendrology:logs2-1
rule13=0,100,minecraft:oak_stairs-6
rule14=0,100,minecraft:oak_stairs-1
rule15=0,100,minecraft:oak_stairs-2
rule16=0,100,minecraft:stone_brick_stairs-3
rule17=0,100,IInventory;minecraft:chest;minecraft:bread#8#0#4+harvestcraft:cornmealItem#32#0#12+harvestcraft:doughItem#20#0#13+harvestcraft:flourItem#32#0#14+minecraft:bread#8#0#22-2
rule18=0,100,plantmegapack:bambooMosoLadder-4
rule19=0,100,dendrology:logs0-0
rule20=0,100,ExtrabiomesXL:door_baldcypress-6
rule21=0,100,chisel:glass_pane-2
rule22=0,100,minecraft:stone_brick_stairs-1
rule23=0,100,minecraft:stone_brick_stairs-7
rule24=0,100,ExtrabiomesXL:door_baldcypress-8
rule25=0,100,minecraft:stone_brick_stairs-6
rule26=0,100,minecraft:stone_brick_stairs-4
rule27=0,100,BiomesOPlenty:woodenSingleSlab1-14
rule28=0,100,dendrology:logs1-11
rule29=0,100,GardenTrees:thin_log_fence-0
rule30=0,100,dendrology:logs1-7
rule31=0,100,minecraft:wool-0
rule32=0,100,minecraft:fence-0
rule33=0,100,dendrology:leaves1-3
rule34=0,100,dendrology:leaves1-15
rule35=0,100,minecraft:stone_brick_stairs-0
rule36=0,100,minecraft:wool-11
rule37=0,100,minecraft:stone_brick_stairs-5
rule38=0,100,dendrology:leaves2-1
rule39=0,100,minecraft:stone_brick_stairs-2
rule40=0,100,BiomesOPlenty:darkStairs-2
rule41=0,100,BiomesOPlenty:darkStairs-0
rule42=0,100,BiomesOPlenty:darkStairs-3
rule43=0,100,dendrology:logs0-4
rule44=0,100,BiomesOPlenty:darkStairs-1
rule45=2,100,minecraft:stone_button-1
rule46=0,100,IInventory;minecraft:chest;BiomesOPlenty:swordAmethyst#1#0#13-4
rule47=0,100,minecraft:oak_stairs-7
rule48=0,100,minecraft:log-1
rule49=0,100,minecraft:log-9
rule50=0,100,minecraft:oak_stairs-3
rule51=0,100,BiomesOPlenty:woodenSingleSlab1-2

layer
0,0,0,0,0,0,0,0,0,1,0,0,0,0,0,0,0,0,0,0,0
0,0,0,0,0,0,0,0,0,0,0,0,0,0,0,0,0,0,0,0,0
0,0,0,0,0,0,0,0,0,0,0,0,0,0,0,0,0,0,0,0,0
0,0,0,0,0,0,0,0,0,0,0,0,0,0,0,0,0,0,0,0,0
0,0,0,0,0,0,0,0,4,4,1,0,0,3,2,0,0,0,0,0,0
0,0,0,0,0,0,2,4,7,7,7,4,6,6,0,5,0,0,0,0,0
0,0,0,0,0,0,1,7,7,7,7,7,4,6,0,0,0,0,0,0,0
0,0,0,0,0,4,7,7,7,7,7,7,7,4,0,0,0,0,0,0,0
0,0,0,8,0,4,7,7,7,7,7,7,7,4,0,0,0,5,0,0,0
0,0,0,0,0,4,7,7,7,7,7,7,7,4,0,0,0,0,0,0,0
0,0,0,0,9,4,7,7,7,7,7,7,7,4,6,0,0,0,0,0,0
0,0,0,5,0,0,1,7,7,7,7,7,10,6,1,0,0,0,0,0,0
0,0,0,0,0,6,6,10,11,4,1,1,0,0,0,0,0,0,0,0,0
0,0,0,0,0,0,6,0,0,0,0,0,0,0,0,12,0,0,0,0,0
0,0,0,0,0,0,0,0,0,0,0,0,0,0,0,0,0,0,0,0,0
0,0,0,0,0,0,0,0,0,0,0,0,0,0,0,0,14,0,13,0,0
0,0,0,0,3,0,0,0,0,0,0,0,0,0,0,0,0,0,0,0,0
0,0,0,0,0,15,0,0,0,0,0,0,0,0,0,0,0,0,0,0,0
endlayer

layer
0,0,0,0,0,0,0,0,0,0,0,0,0,0,0,0,0,0,0,0,0
0,0,0,0,0,0,0,0,0,0,0,0,0,0,0,0,0,0,0,0,0
0,0,0,0,0,0,0,0,0,0,0,0,0,0,0,0,0,0,0,0,0
0,0,0,0,0,0,0,0,0,0,0,0,0,0,0,0,0,0,0,0,0
0,0,0,0,0,0,0,0,16,10,3,0,0,0,0,0,0,0,0,0,0
0,0,0,0,0,0,2,10,0,0,0,4,0,0,0,0,0,0,0,0,0
0,0,0,0,0,0,3,0,0,0,0,0,6,6,0,0,0,0,0,0,0
0,0,0,0,0,4,17,0,0,0,0,0,0,10,0,0,0,0,0,0,0
0,0,0,8,0,10,0,0,0,18,0,0,0,11,0,0,0,0,0,0,0
0,0,0,0,0,11,0,0,0,19,0,0,0,4,0,0,0,0,0,0,0
0,0,0,0,0,10,0,0,0,2,0,0,6,6,0,0,0,0,0,0,0
0,0,0,0,0,0,3,0,0,0,0,0,4,0,0,0,0,0,0,0,0
0,0,0,0,0,0,6,11,4,20,4,3,0,0,0,0,0,0,0,0,0
0,0,0,0,0,0,0,0,0,0,0,0,0,0,0,12,0,0,0,0,0
0,0,0,0,0,0,0,0,0,0,0,0,0,0,0,0,0,0,0,0,0
0,0,0,0,0,0,0,0,0,0,0,0,0,0,0,0,0,0,0,0,0
0,0,0,0,0,0,0,0,0,0,0,0,0,0,0,0,0,0,0,0,0
0,0,0,0,0,0,0,0,0,0,0,0,0,0,0,0,0,0,0,0,0
endlayer

layer
0,0,0,0,0,0,0,0,0,0,0,0,0,0,0,0,0,0,0,0,0
0,0,0,0,0,0,0,0,0,0,0,0,0,0,0,0,0,0,0,0,0
0,0,0,0,0,0,0,0,0,0,0,0,0,0,0,0,0,0,0,0,0
0,0,0,0,0,0,0,0,0,0,0,0,0,0,0,0,0,0,0,0,0
0,0,0,0,0,0,0,9,4,21,5,0,0,0,0,0,0,0,0,0,0
0,0,0,0,0,0,0,4,0,0,0,4,0,0,0,0,0,0,0,0,0
0,0,0,0,0,0,5,0,0,0,0,0,0,0,0,0,0,0,0,0,0
0,0,0,0,9,4,0,0,0,0,0,0,2,4,9,0,0,0,0,0,0
0,0,0,8,0,21,0,0,0,18,0,0,0,21,0,0,0,0,0,0,0
0,0,0,0,0,21,2,0,0,19,0,0,0,21,0,0,0,0,0,0,0
0,0,0,0,0,22,0,0,0,0,0,0,0,3,0,0,0,0,0,0,0
0,0,0,0,0,0,10,0,0,0,0,0,11,0,0,0,0,0,0,0,0
0,0,0,0,0,0,0,4,4,24,23,5,0,0,0,0,0,0,0,0,0
0,0,0,0,0,0,0,9,0,0,0,0,0,0,0,12,0,0,0,0,0
0,0,0,0,0,0,0,0,0,0,0,0,0,0,0,0,0,0,0,0,0
0,0,0,0,0,0,0,0,0,0,0,0,0,0,0,0,0,0,0,0,0
0,0,0,0,0,0,0,0,0,0,0,0,0,0,0,0,0,0,0,0,0
0,0,0,0,0,0,0,0,0,0,0,0,0,0,0,0,0,0,0,0,0
endlayer

layer
0,0,0,0,0,0,0,0,0,0,0,0,0,0,0,0,0,0,0,0,0
0,0,0,0,0,0,0,0,0,0,0,0,0,0,0,0,0,0,0,0,0
0,0,0,0,0,0,0,0,0,0,0,0,0,0,0,0,0,0,0,0,0
0,0,0,0,0,0,0,0,0,0,0,0,0,0,0,0,0,0,0,0,0
0,0,0,0,0,0,0,0,4,5,4,0,0,0,0,0,0,0,0,0,0
0,0,0,0,0,0,0,4,2,0,0,4,0,0,0,0,0,0,0,0,0
0,0,0,0,0,0,4,11,0,0,9,4,25,0,0,0,0,0,0,0,0
0,0,0,0,0,26,4,0,0,0,0,0,2,4,0,0,0,0,0,0,0
0,0,0,8,0,4,11,0,0,18,0,0,0,4,0,0,0,0,0,0,0
0,0,0,0,0,4,4,0,0,19,0,0,0,10,0,0,0,0,0,0,0
0,0,0,0,0,0,10,9,0,0,0,0,0,5,0,0,0,0,0,0,0
0,0,0,0,0,0,4,4,0,0,0,4,10,0,0,0,0,0,0,0,0
0,0,0,0,0,0,2,4,4,4,4,10,0,0,0,0,0,0,0,0,0
0,0,0,0,0,0,0,0,0,0,0,0,0,0,0,12,0,0,0,0,0
0,0,0,0,0,0,0,0,0,0,0,0,0,0,0,0,0,0,0,0,0
0,0,0,0,0,0,0,0,0,0,0,0,0,0,0,0,0,0,0,0,0
0,0,0,0,0,0,0,0,0,0,0,0,0,0,0,0,0,0,0,0,0
0,0,0,0,0,0,0,0,0,0,0,0,0,0,0,0,0,0,0,0,0
endlayer

layer
0,0,0,0,0,0,0,0,0,0,0,0,0,0,0,0,0,0,0,0,0
0,0,0,0,0,0,0,0,0,0,0,0,0,0,0,0,0,0,0,0,0
0,0,0,0,0,0,0,0,0,0,0,0,0,0,0,0,0,0,0,0,0
0,0,0,0,0,0,27,27,27,27,27,27,27,0,0,0,0,0,0,0,0
0,0,0,0,0,27,27,27,27,27,27,27,27,27,0,0,0,0,0,0,0
0,0,0,0,27,27,27,27,4,4,4,27,27,27,27,0,0,0,0,0,0
0,0,0,0,27,27,27,4,7,7,7,4,27,27,27,0,0,0,0,0,0
0,0,0,0,27,27,4,7,7,7,7,7,4,27,27,0,0,0,0,0,0
0,0,0,8,27,27,4,7,7,18,7,7,4,27,27,0,0,0,0,0,0
0,0,28,0,27,27,4,7,7,19,7,7,4,27,27,0,0,0,0,0,0
0,0,0,0,27,27,4,7,7,7,7,7,4,27,27,0,0,0,0,0,0
0,0,0,0,27,27,27,4,10,4,11,4,27,27,27,0,0,0,0,0,0
0,0,0,0,27,27,27,27,27,27,27,27,27,27,27,0,0,0,0,0,0
0,0,0,0,0,27,27,27,27,27,27,27,27,27,0,12,0,0,0,0,0
0,0,0,0,0,0,27,27,27,27,27,27,27,0,0,0,0,0,0,0,0
0,0,0,0,0,0,0,0,0,0,0,0,0,0,0,0,0,0,0,0,0
0,0,0,0,0,0,0,0,0,0,0,0,0,0,0,0,0,0,0,0,0
0,0,0,0,0,0,0,0,0,0,0,0,0,0,0,0,0,0,0,0,0
endlayer

layer
0,0,0,0,0,0,0,0,0,0,0,0,0,0,0,0,0,0,0,0,0
0,0,0,0,0,0,0,0,0,0,0,0,0,0,0,0,0,0,0,0,0
0,0,0,0,0,0,0,0,0,0,0,0,0,0,0,0,0,0,0,0,0
0,0,0,0,0,0,29,29,29,0,3,29,29,0,0,0,0,0,0,0,0
0,0,0,0,0,4,0,0,0,0,0,0,0,29,0,0,0,0,0,0,0
0,0,0,0,0,0,0,0,5,1,5,0,0,0,29,0,0,0,0,0,0
0,0,28,0,29,0,0,4,0,0,0,4,0,0,5,0,0,0,0,0,0
0,0,0,30,29,0,4,0,0,0,0,0,4,0,0,0,0,0,0,0,0
0,0,0,8,29,0,4,0,0,18,0,0,11,0,0,0,0,0,0,0,0
0,28,0,0,29,0,4,0,0,19,0,0,4,0,29,0,0,0,0,0,0
0,0,0,0,29,0,4,2,0,0,0,0,4,0,29,0,0,0,0,0,0
0,0,0,0,0,0,2,11,11,0,4,0,0,0,0,0,0,0,0,0,0
0,0,0,0,3,0,0,0,0,0,0,0,0,4,0,0,0,0,0,0,0
0,0,0,0,0,0,1,0,0,0,0,0,0,0,0,12,0,0,0,0,0
0,0,0,0,0,0,0,0,0,29,29,29,3,0,0,0,0,0,0,0,0
0,0,0,0,0,0,0,0,0,0,0,0,0,0,0,0,0,0,0,0,0
0,0,0,0,0,0,0,0,0,0,0,0,0,0,0,0,32,31,0,0,0
0,0,0,0,0,0,0,0,0,0,0,0,0,0,0,0,0,0,0,0,0
endlayer

layer
0,0,0,0,0,0,0,0,0,0,0,0,0,0,0,0,0,0,0,0,0
0,0,0,0,0,0,0,0,0,0,0,0,0,0,0,0,0,0,0,0,0
0,0,0,0,0,0,0,0,0,0,0,0,0,0,0,0,0,0,0,0,0
0,0,0,0,0,0,0,0,0,0,0,0,0,0,0,0,0,0,0,0,0
0,33,0,0,0,0,0,0,0,0,0,0,0,0,0,0,0,0,0,0,0
33,28,0,0,33,0,0,0,4,21,0,0,0,0,0,0,0,0,0,0,0
0,0,33,33,33,33,0,4,0,0,0,3,0,0,0,0,0,0,0,0,0
0,33,33,8,28,0,34,0,0,0,0,0,0,0,0,0,0,0,0,0,0
0,0,33,8,8,0,21,0,0,18,0,0,21,0,0,0,0,0,0,0,0
0,0,28,0,28,28,21,0,0,19,0,0,21,0,0,0,0,0,0,0,0
0,30,0,0,0,0,6,0,0,0,0,0,3,0,0,0,0,0,0,0,0
33,30,0,0,0,0,0,4,25,0,4,0,0,0,0,0,0,0,0,0,0
0,33,0,0,0,0,0,0,0,0,0,0,0,0,0,0,0,0,0,0,0
0,0,0,0,0,0,0,0,0,0,0,0,0,0,0,12,0,0,0,0,0
0,0,0,0,0,0,0,0,0,0,0,0,0,0,0,0,0,0,0,0,0
0,0,0,0,0,0,0,0,0,0,0,0,0,0,0,0,0,0,0,0,0
0,0,0,0,0,13,0,0,0,0,0,0,0,0,0,32,31,31,0,0,0
0,0,0,0,0,0,0,0,0,0,0,0,0,0,0,0,0,0,0,0,0
endlayer

layer
0,0,0,0,0,0,0,0,0,0,0,0,0,0,0,0,0,0,0,0,0
0,0,0,0,0,0,0,0,0,0,0,0,0,0,0,0,0,0,0,0,0
0,0,0,0,0,0,0,0,0,0,0,0,0,0,0,0,0,0,0,0,0
0,0,33,0,33,0,0,0,0,0,0,0,0,0,0,0,0,0,0,0,0
0,33,33,33,33,33,0,0,0,9,0,0,0,0,0,0,0,0,0,0,0
0,8,33,33,30,33,33,0,4,4,23,0,0,0,0,0,0,0,0,0,0
33,28,33,30,33,28,33,3,0,9,2,5,0,0,0,0,0,0,0,0,0
33,33,28,33,28,33,4,0,0,0,2,2,35,0,0,0,0,0,0,0,0
33,33,28,8,8,9,34,33,0,18,0,0,4,0,0,0,0,0,0,0,0
0,33,33,30,28,33,6,33,2,19,0,0,4,9,0,0,0,0,0,0,0
33,28,0,33,33,33,22,0,0,9,0,0,4,0,0,0,0,0,0,0,0
33,33,33,0,0,33,0,4,10,23,10,23,0,0,0,0,0,0,0,0,0
34,33,33,0,0,0,0,0,0,0,0,0,0,0,0,0,0,0,0,0,0
0,33,33,0,0,0,0,0,0,0,0,0,0,0,0,12,0,0,0,0,0
0,0,0,0,0,0,0,0,0,0,0,0,0,0,0,0,0,0,0,0,0
0,0,0,0,0,0,0,0,0,0,0,0,0,0,0,0,0,0,0,0,0
0,0,0,0,36,36,13,0,0,0,0,0,0,0,32,31,31,31,0,0,0
0,0,0,0,0,0,0,0,0,0,0,0,0,0,0,0,0,0,0,0,0
endlayer

layer
0,0,0,0,0,0,0,0,0,0,0,0,0,0,0,0,0,0,0,0,0
0,0,0,0,0,0,0,0,0,0,0,0,0,0,0,0,0,0,0,0,0
0,0,33,33,33,33,0,0,0,0,0,0,0,0,0,0,0,0,0,0,0
0,0,33,33,33,33,33,0,0,0,0,0,0,0,0,0,0,0,0,0,0
0,33,33,33,30,33,33,33,0,0,0,0,0,0,0,0,0,0,0,0,0
0,33,33,33,33,33,33,33,11,10,4,0,0,0,0,0,0,0,0,0,0
33,33,33,33,30,33,28,4,7,7,7,4,0,0,0,0,0,0,0,0,0
33,33,28,33,30,28,4,7,7,7,7,7,4,0,0,0,0,0,0,0,0
33,28,8,8,28,28,10,7,7,18,7,7,0,0,0,0,0,0,0,0,0
33,33,33,33,33,28,4,7,7,19,7,7,4,0,0,0,0,0,0,0,0
33,33,28,33,33,33,37,7,7,7,7,7,5,0,0,0,0,0,0,0,0
34,33,33,33,33,33,33,4,4,4,4,11,0,0,0,0,0,0,0,0,0
0,0,33,33,33,33,33,0,0,0,0,0,0,0,0,38,0,0,0,0,0
0,33,33,33,0,0,0,0,0,0,0,0,0,0,38,12,38,0,0,0,0
0,0,0,0,0,0,0,0,0,0,0,0,0,0,0,38,0,0,0,0,0
0,0,0,0,0,0,0,0,0,0,0,0,0,0,0,0,0,0,0,0,0
0,0,0,32,36,36,36,13,2,0,0,0,0,32,0,31,31,15,0,0,0
0,0,0,0,0,0,0,0,0,0,0,0,0,0,0,0,0,0,0,0,0
endlayer

layer
0,0,0,0,0,0,0,0,0,0,0,0,0,0,0,0,0,0,0,0,0
0,0,0,0,0,0,0,0,0,0,0,0,0,0,0,0,0,0,0,0,0
0,0,33,33,33,33,33,0,0,0,0,0,0,0,0,0,0,0,0,0,0
0,0,33,33,33,33,33,33,33,0,0,0,0,0,0,0,0,0,0,0,0
0,33,33,33,8,33,33,33,33,33,0,0,0,0,0,0,0,0,0,0,0
0,33,33,33,33,33,33,28,4,4,4,0,0,0,0,0,0,0,0,0,0
33,33,33,33,33,33,28,1,33,33,0,11,0,0,0,0,0,0,0,0,0
33,33,33,33,33,33,10,33,33,0,0,0,11,0,0,0,0,0,0,0,0
33,8,8,8,33,28,4,8,0,18,0,0,4,0,0,0,0,0,0,0,0
33,33,33,30,33,33,6,33,0,19,0,0,25,0,0,0,0,0,0,0,0
33,33,33,33,33,30,6,0,0,0,0,0,3,0,0,0,0,0,0,0,0
33,28,33,33,33,33,33,4,11,11,4,4,0,0,38,38,38,0,0,0,0
0,33,33,33,33,33,33,33,0,0,0,0,0,38,38,38,38,38,0,0,0
0,33,33,33,33,33,33,0,0,0,0,0,0,38,38,12,38,38,0,0,0
0,0,33,0,0,0,0,0,0,0,0,0,0,38,38,38,38,38,0,0,0
0,0,0,0,0,0,0,0,0,0,0,0,0,0,38,38,38,0,0,0,0
0,0,0,0,32,36,36,36,13,2,0,2,32,31,31,0,15,0,0,0,0
0,0,0,0,0,0,0,0,0,0,0,0,0,0,0,0,0,0,0,0,0
endlayer

layer
0,0,0,0,0,0,0,0,0,0,0,0,0,0,0,0,0,0,0,0,0
0,0,0,0,0,0,0,0,0,0,0,0,0,0,0,0,0,0,0,0,0
0,0,0,33,33,33,33,33,33,0,0,0,0,0,0,0,0,0,0,0,0
0,0,33,33,33,33,33,33,33,33,0,0,0,0,0,0,0,0,0,0,0
0,33,33,33,33,33,33,33,33,33,33,0,0,0,0,0,0,0,0,0,0
0,33,33,33,33,33,33,8,33,21,10,0,0,0,0,0,0,0,0,0,0
33,33,33,33,33,33,33,3,33,0,0,25,0,0,0,0,0,0,0,0,0
33,33,33,33,33,33,4,33,0,0,0,0,1,0,0,0,0,0,0,0,0
33,33,33,33,33,8,21,33,0,18,0,0,21,0,0,0,0,0,0,0,0
33,33,33,8,33,33,21,0,0,19,0,0,21,0,0,0,0,0,0,0,0
33,33,33,33,33,33,0,0,0,0,0,0,1,0,38,38,38,0,0,0,0
33,8,33,33,33,33,33,33,4,21,4,11,0,38,38,38,38,38,0,0,0
0,33,33,33,33,33,33,0,0,0,0,0,38,38,38,38,38,38,38,0,0
0,0,33,33,0,0,0,0,0,0,0,0,38,38,38,38,38,38,38,0,0
0,0,0,0,0,0,0,0,0,0,0,0,38,38,38,38,38,38,38,0,0
0,0,0,0,0,0,0,0,0,0,0,0,0,38,38,38,38,38,0,0,0
0,0,0,0,0,32,36,36,36,0,2,32,31,31,31,15,38,0,0,0,0
0,0,0,0,0,0,0,0,0,0,0,0,0,0,0,0,0,0,0,0,0
endlayer

layer
0,0,0,0,0,0,0,0,0,0,0,0,0,0,0,0,0,0,0,0,0
0,0,0,0,0,0,0,0,0,0,0,0,0,0,0,0,0,0,0,0,0
0,0,0,0,0,0,0,0,0,0,0,0,0,0,0,0,0,0,0,0,0
0,0,0,0,33,0,33,33,33,0,0,0,0,0,0,0,0,0,0,0,0
0,0,0,33,33,33,33,33,33,33,0,0,0,0,0,0,0,0,0,0,0
0,33,0,0,33,33,33,33,2,4,4,0,0,0,0,0,0,0,0,0,0
0,0,0,0,33,33,33,5,0,9,0,10,2,0,0,0,0,0,0,0,0
0,33,33,33,33,33,4,0,0,0,0,0,3,0,0,0,0,0,0,0,0
33,33,33,33,33,33,11,33,0,18,0,0,4,0,0,0,0,0,0,0,0
33,33,33,33,33,33,4,33,0,19,0,0,3,0,0,0,0,0,0,0,0
33,33,33,33,33,33,3,0,0,9,0,0,3,0,0,0,0,0,0,0,0
33,33,33,33,33,33,33,0,4,5,4,10,0,0,38,38,38,0,0,0,0
0,33,33,33,0,0,0,0,0,0,0,0,0,38,38,38,38,38,0,0,0
0,0,33,0,0,0,0,0,0,0,0,0,0,38,38,38,38,38,0,0,0
0,0,0,0,0,0,0,0,0,0,0,0,0,38,38,38,38,38,0,0,0
0,0,0,0,0,0,0,0,0,0,0,0,0,0,38,38,38,0,0,0,0
0,0,0,0,0,0,32,36,36,32,32,31,31,31,15,0,0,0,0,0,0
0,0,0,0,0,0,0,0,0,0,0,0,0,0,0,0,0,0,0,0,0
endlayer

layer
0,0,0,0,0,0,0,0,0,0,0,0,0,0,0,0,0,0,0,0,0
0,0,0,0,0,0,0,0,0,0,0,0,0,0,0,0,0,0,0,0,0
0,0,0,0,0,0,0,0,0,0,0,0,0,0,0,0,0,0,0,0,0
0,0,0,0,0,0,0,0,0,0,0,0,0,0,0,0,0,0,0,0,0
0,0,0,0,0,0,0,33,0,0,0,0,0,0,0,0,0,0,0,0,0
0,0,0,0,0,0,33,2,2,0,11,0,0,0,0,0,0,0,0,0,0
0,0,0,0,0,0,0,4,0,0,0,4,0,0,0,0,0,0,0,0,0
0,0,0,0,0,33,4,0,0,0,0,0,10,0,0,0,0,0,0,0,0
0,0,0,33,33,33,5,0,0,18,0,0,4,0,0,0,0,0,0,0,0
0,0,33,33,33,33,4,0,0,19,0,0,26,0,0,0,0,0,0,0,0
0,33,0,33,0,0,4,0,0,0,0,0,11,0,0,0,0,0,0,0,0
33,33,33,0,0,0,0,5,39,2,16,4,0,0,0,0,0,0,0,0,0
0,33,0,0,0,0,0,0,0,0,0,0,0,0,0,38,0,0,0,0,0
0,0,0,0,0,0,0,0,0,0,0,0,0,0,38,38,38,0,0,0,0
0,0,0,0,0,0,0,0,0,0,0,0,0,0,0,38,0,0,0,0,0
0,0,0,0,0,0,0,0,0,0,0,0,0,0,0,0,0,0,0,0,0
0,0,0,0,0,0,0,32,36,32,31,31,31,15,2,0,0,0,0,0,0
0,0,0,0,0,0,0,0,0,0,0,0,0,0,0,0,0,0,0,0,0
endlayer

layer
0,0,0,0,0,0,0,0,0,0,0,0,0,0,0,0,0,0,0,0,0
0,0,0,0,0,0,0,0,0,0,0,0,0,0,0,0,0,0,0,0,0
0,0,0,0,0,0,0,0,0,0,0,0,0,0,0,0,0,0,0,0,0
0,0,0,0,0,0,0,0,0,0,0,0,0,0,0,0,0,0,0,0,0
0,0,0,0,0,0,0,0,0,0,0,0,0,0,0,0,0,0,0,0,0
0,0,0,0,0,0,41,41,41,41,41,41,40,0,0,0,0,0,0,0,0
0,0,0,0,0,0,42,0,0,0,0,0,40,0,0,0,0,0,0,0,0
0,0,0,0,0,0,42,0,0,0,0,0,40,0,0,0,0,0,0,0,0
0,0,0,0,0,0,42,0,0,0,0,0,40,0,0,0,0,0,0,0,0
0,0,0,0,0,0,42,0,0,19,0,0,40,0,0,0,0,0,0,0,0
0,0,0,0,0,0,42,0,0,43,0,0,40,0,0,0,0,0,0,0,0
0,0,0,0,0,0,44,44,0,43,2,44,44,0,0,0,0,0,0,0,0
0,0,0,0,0,0,0,0,0,43,0,0,0,0,0,0,0,0,0,0,0
0,0,0,0,0,0,0,0,0,43,0,0,0,0,0,0,0,0,0,0,0
0,0,0,0,0,0,0,0,0,43,0,0,0,0,0,0,0,0,0,0,0
0,0,0,0,0,0,0,0,0,43,0,0,0,0,0,0,0,0,0,0,0
0,0,0,0,0,0,32,32,32,43,32,32,32,2,2,0,0,0,0,0,0
0,0,0,0,0,0,0,0,0,45,0,0,0,0,0,0,0,0,0,0,0
endlayer

layer
0,0,0,0,0,0,0,0,0,0,0,0,0,0,0,0,0,0,0,0,0
0,0,0,0,0,0,0,0,0,0,0,0,0,0,0,0,0,0,0,0,0
0,0,0,0,0,0,0,0,0,0,0,0,0,0,0,0,0,0,0,0,0
0,0,0,0,0,0,0,0,0,0,0,0,0,0,0,0,0,0,0,0,0
0,0,0,0,0,0,0,0,0,0,0,0,0,0,0,0,0,0,0,0,0
0,0,0,0,0,0,0,0,0,0,0,0,0,0,0,0,0,0,0,0,0
0,0,0,0,0,0,0,41,41,41,41,40,0,0,0,0,0,0,0,0,0
0,0,0,0,0,0,0,42,0,0,0,40,0,0,0,0,0,0,0,0,0
0,0,0,0,0,0,0,42,0,0,0,40,0,0,0,0,0,0,0,0,0
0,0,0,0,0,0,0,42,0,0,0,40,0,0,0,0,0,0,0,0,0
0,0,0,0,0,0,0,42,0,46,0,40,0,0,0,0,0,0,0,0,0
0,0,0,0,0,0,0,44,25,2,23,44,0,0,0,0,0,0,0,0,0
0,0,0,0,0,0,0,0,0,0,0,0,0,0,0,0,0,0,0,0,0
0,0,0,0,0,0,0,0,0,0,0,0,0,0,0,0,0,0,0,0,0
0,0,0,0,0,0,0,0,0,0,0,0,0,0,0,0,0,0,0,0,0
0,0,0,0,0,0,0,0,0,0,0,0,0,0,0,0,0,0,0,0,0
0,0,0,0,0,47,31,31,31,32,36,36,36,32,2,0,0,0,0,0,0
0,0,0,0,0,0,0,0,0,0,0,0,0,0,0,0,0,0,0,0,0
endlayer

layer
0,0,0,0,0,0,0,0,0,0,0,0,0,0,0,0,0,0,0,0,0
0,0,0,0,0,0,0,0,0,0,0,0,0,0,0,0,0,0,0,0,0
0,0,0,0,0,0,0,0,0,0,0,0,0,0,0,0,0,0,0,0,0
0,0,0,0,0,0,0,0,0,0,0,0,0,0,0,0,0,0,0,0,0
0,0,0,0,0,0,0,0,0,0,0,0,0,0,0,0,0,0,0,0,0
0,0,0,0,0,0,0,0,0,0,0,0,0,0,0,0,0,0,0,0,0
0,0,0,0,0,0,0,0,0,0,0,0,0,0,0,0,0,0,0,0,0
0,0,0,0,0,0,0,0,41,41,40,0,0,0,0,0,0,0,0,0,0
0,0,0,0,0,0,0,0,42,0,40,0,0,0,0,0,0,0,0,0,0
0,0,0,0,0,0,0,0,42,0,40,0,0,0,0,0,0,0,0,0,0
0,0,0,0,0,0,0,0,42,0,40,0,0,0,0,0,0,0,0,0,0
0,0,0,0,0,0,0,0,48,49,48,0,0,0,0,0,0,0,0,0,0
0,0,0,0,0,0,0,0,0,0,0,0,0,0,0,0,0,0,0,0,0
0,0,0,0,0,0,0,0,0,0,0,0,0,0,0,0,0,0,0,0,0
0,0,0,0,0,0,0,0,0,0,0,0,0,0,0,0,0,0,0,0,0
0,0,0,0,0,0,0,0,0,0,0,0,0,0,0,0,0,0,0,0,0
0,0,0,0,47,31,31,31,32,32,50,36,36,36,32,0,0,0,0,0,0
0,0,0,0,0,0,0,0,0,0,0,0,0,0,0,0,0,0,0,0,0
endlayer

layer
0,0,0,0,0,0,0,0,0,0,0,0,0,0,0,0,0,0,0,0,0
0,0,0,0,0,0,0,0,0,0,0,0,0,0,0,0,0,0,0,0,0
0,0,0,0,0,0,0,0,0,0,0,0,0,0,0,0,0,0,0,0,0
0,0,0,0,0,0,0,0,0,0,0,0,0,0,0,0,0,0,0,0,0
0,0,0,0,0,0,0,0,0,0,0,0,0,0,0,0,0,0,0,0,0
0,0,0,0,0,0,0,0,0,0,0,0,0,0,0,0,0,0,0,0,0
0,0,0,0,0,0,0,0,0,0,0,0,0,0,0,0,0,0,0,0,0
0,0,0,0,0,0,0,0,0,0,0,0,0,0,0,0,0,0,0,0,0
0,0,0,0,0,0,0,0,0,51,0,0,0,0,0,0,0,0,0,0,0
0,0,0,0,0,0,0,0,0,51,0,0,0,0,0,0,0,0,0,0,0
0,0,0,0,0,0,0,0,0,51,0,0,0,0,0,0,0,0,0,0,0
0,0,0,0,0,0,0,0,0,51,0,0,0,0,0,0,0,0,0,0,0
0,0,0,0,0,0,0,0,0,0,0,0,0,0,0,0,0,0,0,0,0
0,0,0,0,0,0,0,0,0,0,0,0,0,0,0,0,0,0,0,0,0
0,0,0,0,0,0,0,0,0,0,0,0,0,0,0,0,0,0,0,0,0
0,0,0,0,0,0,0,0,0,0,0,0,0,0,0,0,0,0,0,0,0
0,0,0,47,31,31,31,32,0,0,0,50,36,36,36,32,0,0,0,0,0
0,0,0,0,0,0,0,0,0,0,0,0,0,0,0,0,0,0,0,0,0
endlayer

layer
0,0,0,0,0,0,0,0,0,0,0,0,0,0,0,0,0,0,0,0,0
0,0,0,0,0,0,0,0,0,0,0,0,0,0,0,0,0,0,0,0,0
0,0,0,0,0,0,0,0,0,0,0,0,0,0,0,0,0,0,0,0,0
0,0,0,0,0,0,0,0,0,0,0,0,0,0,0,0,0,0,0,0,0
0,0,0,0,0,0,0,0,0,0,0,0,0,0,0,0,0,0,0,0,0
0,0,0,0,0,0,0,0,0,0,0,0,0,0,0,0,0,0,0,0,0
0,0,0,0,0,0,0,0,0,0,0,0,0,0,0,0,0,0,0,0,0
0,0,0,0,0,0,0,0,0,0,0,0,0,0,0,0,0,0,0,0,0
0,0,0,0,0,0,0,0,0,0,0,0,0,0,0,0,0,0,0,0,0
0,0,0,0,0,0,0,0,0,0,0,0,0,0,0,0,0,0,0,0,0
0,0,0,0,0,0,0,0,0,0,0,0,0,0,0,0,0,0,0,0,0
0,0,0,0,0,0,0,0,0,0,0,0,0,0,0,0,0,0,0,0,0
0,0,0,0,0,0,0,0,0,0,0,0,0,0,0,0,0,0,0,0,0
0,0,0,0,0,0,0,0,0,0,0,0,0,0,0,0,0,0,0,0,0
0,0,0,0,0,0,0,0,0,0,0,0,0,0,0,0,0,0,0,0,0
0,0,0,0,0,0,0,0,0,0,0,0,0,0,0,0,0,0,0,0,0
0,0,47,31,31,31,32,0,0,0,0,0,50,0,36,36,32,0,0,0,0
0,0,0,0,0,0,0,0,0,0,0,0,0,0,0,0,0,0,0,0,0
endlayer

layer
0,0,0,0,0,0,0,0,0,0,0,0,0,0,0,0,0,0,0,0,0
0,0,0,0,0,0,0,0,0,0,0,0,0,0,0,0,0,0,0,0,0
0,0,0,0,0,0,0,0,0,0,0,0,0,0,0,0,0,0,0,0,0
0,0,0,0,0,0,0,0,0,0,0,0,0,0,0,0,0,0,0,0,0
0,0,0,0,0,0,0,0,0,0,0,0,0,0,0,0,0,0,0,0,0
0,0,0,0,0,0,0,0,0,0,0,0,0,0,0,0,0,0,0,0,0
0,0,0,0,0,0,0,0,0,0,0,0,0,0,0,0,0,0,0,0,0
0,0,0,0,0,0,0,0,0,0,0,0,0,0,0,0,0,0,0,0,0
0,0,0,0,0,0,0,0,0,0,0,0,0,0,0,0,0,0,0,0,0
0,0,0,0,0,0,0,0,0,0,0,0,0,0,0,0,0,0,0,0,0
0,0,0,0,0,0,0,0,0,0,0,0,0,0,0,0,0,0,0,0,0
0,0,0,0,0,0,0,0,0,0,0,0,0,0,0,0,0,0,0,0,0
0,0,0,0,0,0,0,0,0,0,0,0,0,0,0,0,0,0,0,0,0
0,0,0,0,0,0,0,0,0,0,0,0,0,0,0,0,0,0,0,0,0
0,0,0,0,0,0,0,0,0,0,0,0,0,0,0,0,0,0,0,0,0
0,0,0,0,0,0,0,0,0,0,0,0,0,0,0,0,0,0,0,0,0
0,47,32,32,0,32,0,0,0,0,0,0,0,0,36,36,36,32,0,0,0
0,0,0,0,0,0,0,0,0,0,0,0,0,0,0,0,0,0,0,0,0
endlayer

layer
0,0,0,0,0,0,0,0,0,0,0,0,0,0,0,0,0,0,0,0,0
0,0,0,0,0,0,0,0,0,0,0,0,0,0,0,0,0,0,0,0,0
0,0,0,0,0,0,0,0,0,0,0,0,0,0,0,0,0,0,0,0,0
0,0,0,0,0,0,0,0,0,0,0,0,0,0,0,0,0,0,0,0,0
0,0,0,0,0,0,0,0,0,0,0,0,0,0,0,0,0,0,0,0,0
0,0,0,0,0,0,0,0,0,0,0,0,0,0,0,0,0,0,0,0,0
0,0,0,0,0,0,0,0,0,0,0,0,0,0,0,0,0,0,0,0,0
0,0,0,0,0,0,0,0,0,0,0,0,0,0,0,0,0,0,0,0,0
0,0,0,0,0,0,0,0,0,0,0,0,0,0,0,0,0,0,0,0,0
0,0,0,0,0,0,0,0,0,0,0,0,0,0,0,0,0,0,0,0,0
0,0,0,0,0,0,0,0,0,0,0,0,0,0,0,0,0,0,0,0,0
0,0,0,0,0,0,0,0,0,0,0,0,0,0,0,0,0,0,0,0,0
0,0,0,0,0,0,0,0,0,0,0,0,0,0,0,0,0,0,0,0,0
0,0,0,0,0,0,0,0,0,0,0,0,0,0,0,0,0,0,0,0,0
0,0,0,0,0,0,0,0,0,0,0,0,0,0,0,0,0,0,0,0,0
0,0,0,0,0,0,0,0,0,0,0,0,0,0,0,0,0,0,0,0,0
47,31,32,0,0,0,0,0,0,0,0,0,0,0,50,36,36,36,0,0,0
0,0,0,0,0,0,0,0,0,0,0,0,0,0,0,0,0,0,0,0,0
endlayer

layer
0,0,0,0,0,0,0,0,0,0,0,0,0,0,0,0,0,0,0,0,0
0,0,0,0,0,0,0,0,0,0,0,0,0,0,0,0,0,0,0,0,0
0,0,0,0,0,0,0,0,0,0,0,0,0,0,0,0,0,0,0,0,0
0,0,0,0,0,0,0,0,0,0,0,0,0,0,0,0,0,0,0,0,0
0,0,0,0,0,0,0,0,0,0,0,0,0,0,0,0,0,0,0,0,0
0,0,0,0,0,0,0,0,0,0,0,0,0,0,0,0,0,0,0,0,0
0,0,0,0,0,0,0,0,0,0,0,0,0,0,0,0,0,0,0,0,0
0,0,0,0,0,0,0,0,0,0,0,0,0,0,0,0,0,0,0,0,0
0,0,0,0,0,0,0,0,0,0,0,0,0,0,0,0,0,0,0,0,0
0,0,0,0,0,0,0,0,0,0,0,0,0,0,0,0,0,0,0,0,0
0,0,0,0,0,0,0,0,0,0,0,0,0,0,0,0,0,0,0,0,0
0,0,0,0,0,0,0,0,0,0,0,0,0,0,0,0,0,0,0,0,0
0,0,0,0,0,0,0,0,0,0,0,0,0,0,0,0,0,0,0,0,0
0,0,0,0,0,0,0,0,0,0,0,0,0,0,0,0,0,0,0,0,0
0,0,0,0,0,0,0,0,0,0,0,0,0,0,0,0,0,0,0,0,0
0,0,0,0,0,0,0,0,0,0,0,0,0,0,0,0,0,0,0,0,0
31,31,31,0,0,0,0,0,0,0,0,0,0,0,0,50,36,36,0,0,0
0,0,0,0,0,0,0,0,0,0,0,0,0,0,0,0,0,0,0,0,0
endlayer

layer
0,0,0,0,0,0,0,0,0,0,0,0,0,0,0,0,0,0,0,0,0
0,0,0,0,0,0,0,0,0,0,0,0,0,0,0,0,0,0,0,0,0
0,0,0,0,0,0,0,0,0,0,0,0,0,0,0,0,0,0,0,0,0
0,0,0,0,0,0,0,0,0,0,0,0,0,0,0,0,0,0,0,0,0
0,0,0,0,0,0,0,0,0,0,0,0,0,0,0,0,0,0,0,0,0
0,0,0,0,0,0,0,0,0,0,0,0,0,0,0,0,0,0,0,0,0
0,0,0,0,0,0,0,0,0,0,0,0,0,0,0,0,0,0,0,0,0
0,0,0,0,0,0,0,0,0,0,0,0,0,0,0,0,0,0,0,0,0
0,0,0,0,0,0,0,0,0,0,0,0,0,0,0,0,0,0,0,0,0
0,0,0,0,0,0,0,0,0,0,0,0,0,0,0,0,0,0,0,0,0
0,0,0,0,0,0,0,0,0,0,0,0,0,0,0,0,0,0,0,0,0
0,0,0,0,0,0,0,0,0,0,0,0,0,0,0,0,0,0,0,0,0
0,0,0,0,0,0,0,0,0,0,0,0,0,0,0,0,0,0,0,0,0
0,0,0,0,0,0,0,0,0,0,0,0,0,0,0,0,0,0,0,0,0
0,0,0,0,0,0,0,0,0,0,0,0,0,0,0,0,0,0,0,0,0
0,0,0,0,0,0,0,0,0,0,0,0,0,0,0,0,0,0,0,0,0
31,31,32,0,0,0,0,0,0,0,0,0,0,0,0,0,50,0,0,0,0
0,0,0,0,0,0,0,0,0,0,0,0,0,0,0,0,0,0,0,0,0
endlayer

layer
0,0,0,0,0,0,0,0,0,0,0,0,0,0,0,0,0,0,0,0,0
0,0,0,0,0,0,0,0,0,0,0,0,0,0,0,0,0,0,0,0,0
0,0,0,0,0,0,0,0,0,0,0,0,0,0,0,0,0,0,0,0,0
0,0,0,0,0,0,0,0,0,0,0,0,0,0,0,0,0,0,0,0,0
0,0,0,0,0,0,0,0,0,0,0,0,0,0,0,0,0,0,0,0,0
0,0,0,0,0,0,0,0,0,0,0,0,0,0,0,0,0,0,0,0,0
0,0,0,0,0,0,0,0,0,0,0,0,0,0,0,0,0,0,0,0,0
0,0,0,0,0,0,0,0,0,0,0,0,0,0,0,0,0,0,0,0,0
0,0,0,0,0,0,0,0,0,0,0,0,0,0,0,0,0,0,0,0,0
0,0,0,0,0,0,0,0,0,0,0,0,0,0,0,0,0,0,0,0,0
0,0,0,0,0,0,0,0,0,0,0,0,0,0,0,0,0,0,0,0,0
0,0,0,0,0,0,0,0,0,0,0,0,0,0,0,0,0,0,0,0,0
0,0,0,0,0,0,0,0,0,0,0,0,0,0,0,0,0,0,0,0,0
0,0,0,0,0,0,0,0,0,0,0,0,0,0,0,0,0,0,0,0,0
0,0,0,0,0,0,0,0,0,0,0,0,0,0,0,0,0,0,0,0,0
0,0,0,0,0,0,0,0,0,0,0,0,0,0,0,0,0,0,0,0,0
31,32,0,0,0,0,0,0,0,0,0,0,0,0,0,0,0,0,0,0,0
0,0,0,0,0,0,0,0,0,0,0,0,0,0,0,0,0,0,0,0,0
endlayer

