
# Created by Ruins mod version 15.0 Ingame Parser
# authoring Player: VikingWarlock

weight=100
embed_into_distance=26
acceptable_target_blocks=
unacceptable_target_blocks=flowing_water,water,flowing_lava,lava
dimensions=33,39,19
allowable_overhang=0
max_leveling=10
leveling_buffer=0
preserve_water=0
preserve_lava=0
uniqueMinDistance=1000000
preventRotation=1

rule1=0,100,preserveBlock
rule2=0,100,UndergroundBiomes:sedimentaryStone-12
rule3=0,100,minecraft:gravel-0
rule4=0,100,UndergroundBiomes:sedimentaryStone-15
rule5=0,100,BiomesOPlenty:newBopDirt-0
rule6=0,100,BiomesOPlenty:newBopDirt-1
rule7=0,100,chisel:woolen_clay-15
rule8=0,100,UndergroundBiomes:igneousStone-13
rule9=0,100,UndergroundBiomes:sedimentaryStone-10
rule10=0,100,chisel:netherrack-9
rule11=0,100,chisel:cobblestone-1
rule12=0,100,minecraft:coal_block-0
rule13=0,100,MobSpawner:Mouse
rule14=0,100,UndergroundBiomes:igneousCobblestone-5
rule15=0,100,chisel:nether_brick-5
rule16=0,100,chisel:dirt-3
rule17=0,100,chisel:grimstone-12
rule18=0,100,chisel:grimstone-13
rule19=0,100,BiomesOPlenty:hell_blood-0
rule20=0,100,GardenTrees:thin_log-4
rule21=0,100,MobSpawner:Snake
rule22=0,100,minecraft:lava-0
rule23=0,100,minecraft:cobblestone-0
rule24=0,100,UndergroundBiomes:igneousCobblestoneFullSlab-5
rule25=0,100,UndergroundBiomes:igneousCobblestoneHalfSlab-5
rule26=0,100,IInventory;minecraft:chest;minecraft:bone#1#0#0+BiomesOPlenty:misc#1#3#1+CarpentersBlocks:itemCarpentersHammer#1#0#2+BiblioCraft:item.HandDrill#{RepairCost:2,display:{Name:"Draining Drill",},}#0#3+minecraft:bone#1#0#4+minecraft:skull#1#0#5+minecraft:rotten_flesh#1#0#7+minecraft:string#6#0#8+harvestcraft:cuttingboardItem#1#0#9+minecraft:rotten_flesh#1#0#10+minecraft:golden_sword#{RepairCost:2,ench:[0:{id:16s,lvl:5s,},],display:{Name:"The Evergiving Edge",},}#0#13+BiomesOPlenty:misc#1#3#16+BiblioCraft:item.FramingSaw#{RepairCost:2,ench:[0:{id:16s,lvl:5s,},1:{id:34s,lvl:3s,},],display:{Name:"Marrow Saw",},}#0#18+BiomesOPlenty:bopBucket#{Fluid:{Amount:1000,FluidName:"hell_blood",},}#0#21+minecraft:written_book#{author:"VikingWarlock",title:"Hail Haprend",pages:[0:"Should you stumble upon this sacred scripture you shall acknowledge and pay homage to our gracious Lord Haprend. A blood letting in Haprend's name shall grant you safe passage through the the hellish fires that spread across this desolate land",1:"when society fell apart. That is when our Lord saved us and offered refuge from the shattered remains of this damned land. So be it sacrifice of another, or of one's self, a gift of flesh and blood will be taken. By force, if need be...",2:"Take The Evergiving Blade in your grasp and gift Haprend the essence of life. It shall bless the world with it's sacrifice and cleanse these lands of all the scum that dare oppose the grand word of Lord Haprend.                                            ",3:"Call out to your false gods, denounce them and pledge your life to the one, true god,  Great Lord Haprend.                                                                Hail Haprend or suffer for eternity.",],}#0#22+minecraft:bone#1#0#23+BiomesOPlenty:misc#1#3#24+minecraft:bone#1#0#26-3
rule27=0,100,BiomesOPlenty:logs3-2
rule28=0,100,chisel:marble_slab-11
rule29=0,100,UndergroundBiomes:sedimentary_monsterStoneEgg-2
rule30=0,100,minecraft:stone_slab-13
rule31=0,100,UndergroundBiomes:igneousCobblestoneHalfSlab-13
rule32=0,100,BiomesOPlenty:stoneFormations-0
rule33=0,100,GardenTrees:thin_log-5
rule34=0,100,minecraft:anvil-7
rule35=0,100,GardenStuff:light_chain-4
rule36=0,100,GardenStuff:metal_block-0
rule37=2,100,minecraft:redstone_torch-4
rule38=2,100,minecraft:redstone_torch-3
rule39=0,100,GardenStuff:lattice-2
rule40=0,100,BiomesOPlenty:stoneFormations-1
rule41=2,100,minecraft:redstone_torch-2
rule42=0,100,UndergroundBiomes:sedimentaryStoneHalfSlab-4
rule43=0,100,UndergroundBiomes:sedimentaryStoneHalfSlab-12
rule44=0,100,BiomesOPlenty:logs3-10
rule45=0,100,minecraft:water-0
rule46=2,100,minecraft:redstone_torch-1
rule47=0,100,ExtrabiomesXL:grass-3
rule48=0,100,chisel:cobblestone-2
rule49=0,100,minecraft:stone_slab-0
rule50=0,100,minecraft:stone_slab-8
rule51=0,100,BiomesOPlenty:leaves1-15
rule52=0,100,BiomesOPlenty:logs3-6
rule53=0,100,BiomesOPlenty:leaves1-7

layer
1,1,1,1,1,1,1,1,1,1,1,1,1,1,1,1,1,1,1
1,1,1,1,1,1,1,1,1,1,1,1,1,1,1,1,1,1,1
1,1,1,1,1,1,1,1,1,1,1,1,1,1,1,1,1,1,1
1,1,1,1,1,1,1,1,1,1,1,1,1,1,1,1,1,1,1
1,1,1,1,1,1,1,1,1,1,1,1,1,1,1,1,1,1,1
1,1,1,1,1,1,1,1,1,1,1,1,1,1,1,1,1,1,1
1,1,1,1,1,1,1,1,1,1,1,1,1,1,1,1,1,1,1
1,1,1,1,1,1,1,1,1,1,1,1,1,1,1,1,1,1,1
1,1,1,1,1,1,1,1,1,1,1,1,1,1,1,1,1,1,1
1,1,1,1,1,1,1,1,1,1,1,1,1,1,1,1,1,1,1
1,1,2,0,2,2,2,2,2,2,2,2,2,2,2,2,1,1,1
1,4,5,4,2,2,2,4,4,4,3,2,3,3,2,2,2,1,1
1,4,2,2,2,2,4,4,4,4,4,4,3,3,6,6,2,2,1
1,4,2,4,4,4,4,4,4,4,4,4,4,3,3,6,2,2,1
1,2,2,4,4,4,4,4,4,4,4,4,4,4,4,6,4,2,1
1,2,2,4,4,4,4,4,4,4,4,4,4,4,4,4,2,2,1
1,2,4,4,4,4,4,4,4,4,4,4,4,4,4,0,2,1,1
1,8,4,5,4,4,4,4,4,4,4,4,4,4,4,4,7,1,1
1,8,4,4,4,4,4,4,4,4,4,4,4,4,4,4,4,1,1
1,1,1,4,4,4,4,4,4,4,4,4,4,4,4,4,4,1,1
1,1,9,9,4,4,4,4,4,4,4,4,4,4,4,4,4,1,1
1,1,9,9,4,4,4,4,4,4,4,4,4,4,4,4,4,1,1
1,1,9,9,4,4,4,4,4,4,4,4,4,4,4,4,4,1,1
1,1,1,4,4,4,4,4,4,4,4,4,4,4,4,4,4,1,1
1,1,4,4,4,4,4,4,4,4,4,4,4,4,4,7,1,1,1
1,1,4,4,4,4,4,4,4,4,4,4,4,4,8,7,1,1,1
1,8,4,4,4,4,4,4,4,4,4,4,4,4,4,7,1,1,1
1,4,4,4,4,4,4,4,4,4,4,4,4,4,4,4,1,1,1
1,4,4,4,4,4,4,4,4,4,4,4,4,4,4,4,4,4,1
1,4,4,4,4,4,4,4,4,4,4,4,4,4,4,4,4,4,1
1,4,4,4,4,4,4,4,4,4,4,4,4,4,4,4,4,4,1
1,4,4,4,4,4,4,4,4,4,4,4,4,4,4,4,4,4,1
1,1,4,4,4,4,4,4,10,4,4,4,4,4,4,4,4,1,1
1,1,4,4,4,4,4,4,10,4,4,4,4,4,4,4,4,1,1
1,1,4,4,4,4,4,4,4,4,4,4,4,4,4,4,1,1,1
1,1,1,4,4,4,4,4,4,4,4,4,4,4,4,4,1,1,1
1,1,1,4,4,4,4,4,11,4,4,4,4,4,8,1,1,1,1
1,1,1,1,2,2,2,2,2,2,2,2,1,1,1,1,1,1,1
1,1,1,1,1,1,1,1,1,1,1,1,1,1,1,1,1,1,1
endlayer

layer
1,1,1,1,1,1,1,1,1,1,1,1,1,1,1,1,1,1,1
1,1,1,1,1,1,1,1,1,1,1,1,1,1,1,1,1,1,1
1,1,1,1,1,1,1,1,1,1,1,1,1,1,1,1,1,1,1
1,1,1,1,1,1,1,1,1,1,1,1,1,1,1,1,1,1,1
1,1,1,1,1,1,1,1,1,1,1,1,1,1,1,1,1,1,1
1,1,1,1,1,1,1,1,1,1,1,1,1,1,1,1,1,1,1
1,1,1,1,1,1,1,1,1,1,1,1,1,1,1,1,1,1,1
1,1,1,1,1,1,1,1,1,1,1,1,1,1,1,1,1,1,1
1,1,1,1,1,1,1,1,1,1,1,1,1,1,1,1,1,1,1
1,1,1,1,1,1,1,1,1,1,1,1,1,1,1,1,1,1,1
1,1,2,2,2,2,4,8,8,8,8,8,8,8,0,7,1,1,1
1,4,5,4,4,4,2,3,3,3,5,0,2,5,5,2,2,1,1
1,4,2,2,2,2,14,3,3,6,6,13,6,6,5,8,2,12,1
1,4,2,5,5,5,14,4,4,4,4,4,6,6,5,8,2,8,1
1,8,2,5,5,5,6,4,4,4,4,4,4,6,5,8,8,8,1
1,2,2,5,5,5,6,4,4,4,4,6,4,6,6,0,2,2,1
1,8,4,4,5,5,6,4,4,4,4,4,6,6,3,0,2,1,1
1,1,4,5,5,6,6,6,4,6,4,6,6,6,6,7,7,1,1
1,1,4,4,6,6,6,6,4,4,6,6,6,6,6,7,4,1,1
1,1,1,4,6,6,6,6,6,6,6,6,6,6,6,7,7,1,1
1,1,1,0,4,6,6,6,3,6,6,3,3,3,5,7,7,1,1
1,1,9,9,4,6,6,3,3,6,6,15,6,6,5,7,2,1,1
1,1,9,9,4,6,6,6,6,6,15,6,6,6,5,7,7,1,1
1,1,1,4,6,6,6,6,3,15,6,6,6,6,6,7,1,1,1
1,1,4,6,6,6,6,6,6,6,15,6,6,6,2,2,1,1,1
1,1,4,6,6,6,6,6,6,16,6,6,6,5,8,7,1,1,1
1,8,4,6,6,6,3,6,15,6,16,5,6,6,4,0,1,1,1
1,4,6,6,6,6,6,16,16,15,6,6,6,6,4,4,1,1,1
1,4,6,6,6,6,6,15,15,6,15,6,6,6,6,6,4,1,1
1,4,6,6,6,6,15,15,6,6,15,15,6,6,6,6,4,1,1
1,4,6,3,6,6,17,10,10,15,17,6,6,6,6,6,4,1,1
1,4,6,6,6,6,10,18,19,18,15,6,6,6,6,6,4,1,1
1,1,2,6,3,6,10,19,20,19,10,6,6,6,6,4,4,1,1
1,1,4,6,6,6,10,18,20,18,10,6,6,6,6,4,1,1,1
1,1,2,6,6,6,10,18,19,18,10,6,6,6,6,4,1,1,1
1,1,1,4,6,6,21,10,10,10,17,0,8,4,4,4,1,1,1
1,1,1,4,4,4,4,11,22,11,4,4,2,4,8,1,1,1,1
1,1,1,1,2,2,2,2,11,2,2,2,1,1,1,1,1,1,1
1,1,1,1,1,1,1,1,1,1,1,1,1,1,1,1,1,1,1
endlayer

layer
1,1,1,1,1,1,1,1,1,1,1,1,1,1,1,1,1,1,1
1,1,1,1,1,1,1,1,1,1,1,1,1,1,1,1,1,1,1
1,1,1,1,1,1,1,1,1,1,1,1,1,1,1,1,1,1,1
1,1,1,1,1,1,1,1,1,1,1,1,1,1,1,1,1,1,1
1,1,1,1,1,1,1,1,1,1,1,1,1,1,1,1,1,1,1
1,1,1,1,1,1,1,1,1,1,1,1,1,1,1,1,1,1,1
1,1,1,1,1,1,1,1,1,1,1,1,1,1,1,1,1,1,1
1,1,1,1,1,1,1,1,1,1,1,1,1,1,1,1,1,1,1
1,1,1,1,1,1,1,1,1,1,1,1,1,1,1,1,1,1,1
1,1,1,1,1,1,1,1,1,1,1,1,1,1,1,1,1,1,1
1,1,4,2,23,23,23,5,5,5,5,23,23,8,8,7,1,1,1
1,1,5,4,5,14,7,7,5,24,5,5,3,3,3,8,7,1,1
1,4,4,4,4,4,14,5,5,3,3,5,5,3,3,8,8,7,1
1,4,4,4,3,3,14,5,4,4,4,5,5,3,3,5,8,7,1
1,4,2,5,3,3,3,6,6,6,6,6,4,0,0,5,5,7,1
1,4,2,3,3,3,3,6,6,6,6,6,6,6,0,5,8,8,1
1,4,12,3,5,3,3,6,6,6,6,6,3,0,0,2,2,2,1
1,4,12,13,3,3,5,5,6,6,6,6,3,0,0,2,2,2,1
1,4,12,12,5,5,5,25,6,6,6,6,25,0,0,2,4,1,1
1,1,8,12,5,5,5,5,5,5,25,25,25,0,0,2,7,4,1
1,1,8,8,12,5,5,5,25,25,25,0,0,0,5,5,7,1,1
1,1,9,9,2,5,5,0,0,0,0,0,0,0,5,5,2,1,1
1,1,1,9,2,0,0,0,0,0,0,0,0,0,5,2,2,1,1
1,1,1,2,11,0,0,0,0,0,0,0,0,0,0,2,1,1,1
1,1,2,0,0,0,0,0,0,0,0,0,0,0,0,2,1,1,1
1,1,2,0,0,0,0,0,0,0,0,0,0,11,8,8,8,1,1
1,8,2,0,0,0,0,0,0,0,0,0,0,2,2,8,8,1,1
1,2,11,0,0,0,0,0,0,0,0,0,0,0,2,21,1,1,1
1,2,11,0,0,0,0,0,0,0,0,0,0,0,0,5,2,1,1
1,2,11,0,0,0,0,0,0,0,0,0,0,0,0,11,2,1,1
1,2,0,0,0,0,27,0,0,0,27,0,0,0,0,26,11,1,1
1,2,7,0,0,0,0,0,0,0,0,0,0,0,0,11,7,1,1
1,1,7,3,0,0,0,0,28,0,0,0,0,0,25,2,1,1,1
1,1,2,2,0,0,0,27,28,27,0,0,0,0,29,2,1,1,1
1,1,1,2,0,0,0,0,0,0,0,0,0,29,29,2,1,1,1
1,1,1,2,2,0,27,0,0,0,27,0,0,2,2,2,1,1,1
1,1,1,2,7,2,2,11,30,11,4,2,2,2,8,1,1,1,1
1,1,1,1,7,2,2,7,11,7,2,1,1,1,1,1,1,1,1
1,1,1,1,1,1,1,1,1,1,1,1,1,1,1,1,1,1,1
endlayer

layer
1,1,1,1,1,1,1,1,1,1,1,1,1,1,1,1,1,1,1
1,14,14,14,14,14,14,8,8,14,1,1,1,1,1,1,1,1,1
1,1,14,14,14,6,14,14,14,14,23,1,1,1,1,1,1,1,1
1,1,14,14,23,6,6,14,14,14,14,1,1,1,1,1,1,1,1
1,1,14,14,14,23,6,14,14,14,14,1,1,1,1,1,1,1,1
1,1,1,1,1,1,1,14,14,14,6,6,1,1,1,1,1,1,1
1,1,1,1,1,1,1,14,6,6,14,6,1,1,1,1,1,1,1
1,1,1,1,1,1,1,6,8,6,6,14,14,1,1,1,1,1,1
1,1,1,1,1,1,1,8,8,14,6,6,23,23,1,1,1,1,1
1,1,1,1,1,1,1,1,14,8,8,8,1,1,1,1,1,1,1
1,1,4,2,23,23,23,5,5,5,5,23,23,8,8,7,1,1,1
1,1,5,5,14,23,5,5,25,24,5,25,5,5,3,3,2,1,1
1,1,4,4,4,11,5,5,5,31,5,5,5,5,3,3,8,2,1
1,1,4,4,3,3,0,5,6,6,6,5,0,0,11,0,2,2,1
1,1,2,3,3,3,3,0,25,6,3,6,3,0,0,0,0,7,1
1,1,2,3,3,3,0,0,6,6,6,6,0,0,0,5,0,2,1
1,1,12,3,3,3,0,0,25,3,6,5,0,0,0,0,8,8,1
1,1,5,0,5,5,0,0,25,6,25,25,0,0,0,9,8,4,1
1,1,5,5,11,5,0,0,0,0,0,0,0,0,0,9,0,4,1
1,1,5,5,5,5,5,0,0,0,0,0,0,0,0,0,4,4,1
1,1,9,2,5,5,5,0,0,0,0,0,0,0,0,5,11,1,1
1,1,1,9,8,5,0,0,0,0,0,0,0,0,0,5,2,1,1
1,1,1,1,8,0,0,0,0,0,0,0,0,0,0,5,2,1,1
1,1,1,7,33,0,0,0,0,0,0,0,0,0,0,32,8,1,1
1,1,7,0,0,0,0,0,0,0,0,0,0,0,0,32,8,1,1
1,1,2,0,0,0,0,0,0,0,0,0,0,33,0,2,8,1,1
1,8,32,0,0,0,0,0,0,0,0,0,0,0,2,7,8,1,1
1,11,0,0,0,0,0,0,0,0,0,0,0,0,0,5,1,1,1
1,11,0,0,0,0,0,0,0,0,0,0,0,0,0,5,2,1,1
1,11,34,0,0,0,0,0,0,0,0,0,0,0,0,0,11,1,1
1,2,0,0,0,0,33,0,0,0,33,0,0,0,0,0,11,1,1
1,1,7,0,0,0,0,0,0,0,0,0,0,0,0,0,11,1,1
1,1,2,3,0,0,0,0,0,0,0,0,0,0,0,7,1,1,1
1,1,2,2,0,0,0,35,0,35,0,0,0,0,2,2,1,1,1
1,1,1,2,0,0,0,0,0,0,0,0,0,0,29,2,1,1,1
1,1,1,2,0,0,33,0,0,0,33,0,0,2,2,1,1,1,1
1,1,1,2,7,2,2,0,0,0,2,2,2,2,8,1,1,1,1
1,1,1,1,2,2,2,7,36,7,2,1,1,1,1,1,1,1,1
1,1,1,1,1,1,1,1,1,1,1,1,1,1,1,1,1,1,1
endlayer

layer
1,1,8,8,14,4,4,4,1,1,1,1,1,1,1,1,1,1,1
1,14,0,0,0,0,0,0,14,8,14,14,1,1,1,1,1,1,1
1,14,0,0,0,0,0,0,0,0,0,23,1,1,1,1,1,1,1
1,14,0,0,0,0,0,0,0,0,0,6,1,1,1,1,1,1,1
1,14,8,8,8,4,0,14,0,0,0,6,1,1,1,1,1,1,1
1,14,14,8,8,8,14,0,0,0,0,14,14,1,1,1,1,1,1
1,1,14,1,1,1,14,0,0,0,0,14,14,14,1,1,1,1,1
1,1,14,14,1,1,14,0,0,0,0,0,0,14,1,1,1,1,1
1,1,8,14,1,1,6,0,0,0,0,0,0,14,14,1,1,1,1
1,1,1,1,1,14,6,25,0,0,0,0,14,14,1,1,1,1,1
1,1,4,23,23,23,14,14,25,25,25,14,14,8,8,8,1,1,1
1,1,5,2,0,0,0,25,0,0,25,0,0,0,0,3,12,1,1
1,1,5,5,0,11,0,0,0,0,0,0,0,0,0,0,8,2,1
1,1,4,4,4,0,0,0,0,0,0,0,0,0,11,0,2,1,1
1,1,5,3,3,3,0,0,0,0,0,0,0,0,0,0,0,2,1
1,1,5,3,3,3,0,0,0,0,0,0,0,0,0,0,0,2,1
1,1,8,3,5,0,0,0,0,0,0,0,0,0,0,0,0,8,1
1,1,4,5,5,0,0,0,0,0,0,0,0,0,0,0,0,8,1
1,1,4,5,11,5,0,0,0,0,0,0,0,0,0,0,9,2,1
1,1,8,5,5,5,0,0,0,0,0,0,0,0,0,0,8,8,1
1,1,1,2,5,5,0,0,0,0,0,0,0,0,0,0,11,4,1
1,1,1,9,2,0,0,0,0,0,0,0,0,0,0,5,5,1,1
1,1,1,2,8,0,0,0,0,0,0,0,0,0,0,0,5,1,1
1,1,1,12,33,0,0,0,0,0,0,0,0,0,0,0,2,1,1
1,1,7,0,0,0,0,0,0,0,0,0,0,0,0,0,12,1,1
1,1,7,0,0,0,0,0,0,0,0,0,0,33,0,0,12,1,1
1,8,0,0,0,0,0,0,0,0,0,0,0,0,0,0,2,1,1
1,11,0,0,0,0,0,0,0,0,0,0,0,0,0,5,7,7,1
1,11,37,0,0,0,0,0,0,0,0,0,0,0,0,0,5,7,1
1,11,0,0,0,0,0,0,0,0,0,0,0,0,0,0,11,2,1
1,8,0,0,0,0,33,0,0,0,33,0,0,0,0,38,11,2,1
1,1,7,0,0,0,0,0,0,0,0,0,0,0,0,0,11,1,1
1,1,8,0,0,0,0,0,0,0,0,0,0,0,0,2,1,1,1
1,1,8,2,0,0,0,35,39,35,0,0,0,0,0,2,1,1,1
1,1,1,2,0,0,0,0,0,0,0,0,0,0,25,8,1,1,1
1,1,1,2,0,0,33,33,33,33,33,0,0,0,8,1,1,1,1
1,1,1,2,2,0,0,0,0,0,0,2,2,8,8,1,1,1,1
1,1,1,1,7,2,7,7,36,7,7,2,8,1,1,1,1,1,1
1,1,1,1,1,1,1,1,1,1,1,1,1,1,1,1,1,1,1
endlayer

layer
1,1,8,4,8,8,8,4,8,1,1,1,1,1,1,1,1,1,1
1,8,8,0,0,0,0,0,8,8,8,14,1,1,1,1,1,1,1
1,8,0,0,0,0,0,0,0,0,0,6,1,1,1,1,1,1,1
1,14,0,0,0,0,0,0,0,0,0,6,1,1,1,1,1,1,1
1,14,0,0,0,0,0,0,0,0,0,0,14,1,1,1,1,1,1
1,14,14,0,8,14,4,0,0,0,0,0,14,14,1,1,1,1,1
1,1,8,8,8,6,14,0,0,0,0,0,0,14,6,1,1,1,1
1,1,8,14,1,6,0,0,0,0,0,0,0,14,6,1,1,1,1
1,1,0,8,8,6,6,0,0,0,0,0,0,14,14,1,1,1,1
1,1,1,1,1,14,25,0,0,0,0,0,0,0,8,1,1,1,1
1,1,2,2,23,0,14,0,0,0,0,32,0,23,23,8,1,1,1
1,1,2,0,0,0,0,0,0,0,0,0,0,0,0,0,12,1,1
1,1,5,0,0,33,0,0,0,0,0,0,0,0,0,0,0,12,1
1,1,4,5,0,0,0,0,0,0,0,0,0,0,33,0,8,1,1
1,1,4,3,3,0,0,0,0,0,0,0,0,0,0,0,0,2,1
1,1,5,5,3,0,0,0,0,0,0,0,0,0,0,0,0,2,1
1,1,2,5,0,0,0,0,0,0,0,0,0,0,0,0,0,12,1
1,1,5,5,0,0,0,0,0,0,0,0,0,0,0,0,0,8,1
1,1,5,5,11,0,0,0,0,0,0,0,0,0,0,0,0,9,1
1,1,2,5,5,0,0,0,0,0,0,0,0,0,0,0,9,8,1
1,1,1,7,5,5,0,0,0,0,0,0,0,0,0,38,11,8,1
1,1,1,9,7,0,0,0,0,0,0,0,0,0,0,0,5,4,1
1,1,1,8,0,0,0,0,0,0,0,0,0,0,0,0,5,5,1
1,1,7,0,33,0,0,0,0,0,0,0,0,0,0,0,0,5,1
1,1,12,0,0,0,0,0,0,0,0,0,0,0,0,0,0,12,1
1,1,7,0,0,0,0,0,0,0,0,0,0,33,0,0,0,12,1
1,7,0,0,0,0,0,0,0,0,0,0,0,0,0,0,0,12,1
1,8,0,0,0,0,0,0,0,0,0,0,0,0,0,0,0,2,1
1,8,0,0,0,0,0,0,0,0,0,0,0,0,0,0,0,2,1
1,8,0,0,0,0,0,0,0,0,0,0,0,0,0,0,0,2,1
1,2,0,0,0,0,33,0,0,0,33,0,0,0,0,0,0,8,1
1,8,7,0,0,0,0,0,0,0,0,0,0,0,0,0,8,1,1
1,8,2,0,0,0,0,0,0,0,0,0,0,0,0,7,1,1,1
1,8,2,8,0,0,0,39,39,39,0,0,0,0,0,7,1,1,1
1,1,8,8,0,0,0,0,0,0,0,0,0,0,0,7,1,1,1
1,1,8,8,0,0,33,39,0,39,33,0,0,0,8,4,1,1,1
1,1,1,8,8,0,0,0,0,0,8,0,8,8,1,1,1,1,1
1,1,1,1,8,7,7,36,36,36,7,8,8,1,1,1,1,1,1
1,1,1,1,1,7,1,1,1,1,1,1,1,1,1,1,1,1,1
endlayer

layer
1,1,8,6,4,4,4,4,4,8,1,1,1,1,1,1,1,1,1
1,8,6,0,0,0,0,0,0,8,8,8,1,1,1,1,1,1,1
1,8,0,0,0,0,0,0,0,0,0,14,1,1,1,1,1,1,1
1,8,0,0,0,0,0,0,0,0,0,14,1,1,1,1,1,1,1
1,14,0,0,0,14,14,0,0,0,0,14,14,1,1,1,1,1,1
1,14,8,0,0,23,14,0,0,0,0,0,14,14,1,1,1,1,1
1,1,14,23,8,8,6,0,0,0,0,0,0,0,6,1,1,1,1
1,1,14,14,14,8,6,0,0,0,0,0,0,0,6,1,1,1,1
1,1,0,8,14,6,14,0,0,0,0,0,0,0,14,1,1,1,1
1,1,1,1,1,6,0,0,0,0,0,0,0,0,8,1,1,1,1
1,1,2,4,23,14,40,0,0,0,40,14,40,14,23,5,5,1,1
1,1,2,0,0,0,0,0,0,0,0,0,0,0,0,5,4,1,1
1,1,5,0,0,33,0,0,0,0,0,0,0,0,0,0,0,4,1
1,1,5,0,0,0,0,0,0,0,0,0,0,0,33,0,8,1,1
1,1,4,0,0,0,0,0,0,0,0,0,0,0,0,0,0,12,1
1,1,4,0,0,0,0,0,0,0,0,0,0,0,0,0,0,12,1
1,1,4,0,0,0,0,0,0,0,0,0,0,0,0,0,0,7,1
1,1,5,0,0,0,0,0,0,0,0,0,0,0,0,0,0,8,1
1,1,5,5,11,37,0,0,0,0,0,0,0,0,0,0,0,8,1
1,1,2,5,0,0,0,0,0,0,0,0,0,0,0,0,0,9,1
1,1,1,7,5,0,0,0,0,0,0,0,0,0,0,0,11,2,1
1,1,1,9,7,0,0,0,0,0,0,0,0,0,0,0,5,4,1
1,1,1,7,0,0,0,0,0,0,0,0,0,0,0,0,0,12,1
1,1,7,0,33,0,0,0,0,0,0,0,0,0,0,0,0,5,1
1,1,8,0,0,0,0,0,0,0,0,0,0,0,0,0,0,5,1
1,2,2,0,0,0,0,0,0,0,0,0,0,33,0,0,0,5,1
1,2,0,0,0,0,0,0,0,0,0,0,0,0,0,0,0,5,1
1,2,0,0,0,0,0,0,0,0,0,0,0,0,0,0,0,7,1
1,8,0,0,0,0,0,0,0,0,0,0,0,0,0,0,0,7,1
1,8,0,0,0,0,41,0,0,0,41,0,0,0,0,0,0,7,1
1,8,0,0,0,0,27,33,33,33,27,0,0,0,0,0,0,8,1
1,2,0,0,0,0,33,0,0,0,33,0,0,0,0,0,8,1,1
1,2,0,0,0,0,33,0,0,0,33,0,0,0,0,0,8,1,1
1,2,0,42,0,0,33,0,33,0,33,0,0,0,0,42,8,1,1
1,1,8,42,0,0,33,0,0,0,33,0,0,0,0,5,2,1,1
1,1,8,8,0,0,33,39,39,39,33,0,0,0,5,12,1,1,1
1,1,8,2,0,0,0,0,0,0,0,0,4,8,4,4,1,1,1
1,1,1,1,2,2,7,7,36,7,7,2,1,1,1,1,1,1,1
1,1,1,1,1,7,1,1,1,1,1,1,1,1,1,1,1,1,1
endlayer

layer
1,1,6,6,4,4,8,8,8,8,1,1,1,1,1,1,1,1,1
1,6,4,0,0,0,0,14,40,14,1,1,1,1,1,1,1,1,1
1,6,0,0,0,0,0,6,0,0,14,4,1,1,1,1,1,1,1
1,6,0,0,0,0,0,0,0,0,0,8,8,8,1,1,1,1,1
1,4,0,0,0,0,6,0,0,0,0,0,4,8,1,1,1,1,1
1,4,4,0,0,0,23,0,0,0,0,0,0,8,8,1,1,1,1
1,1,4,0,0,0,4,0,0,0,0,0,0,0,8,1,1,1,1
1,1,4,0,0,0,4,0,0,0,0,0,0,0,6,1,1,1,1
1,1,4,0,0,6,14,0,0,0,0,0,0,0,14,1,1,1,1
1,1,1,1,1,6,0,0,0,0,0,0,0,31,6,1,1,1,1
1,1,1,2,23,14,14,0,0,14,14,14,14,14,14,14,1,1,1
1,1,1,4,14,0,0,0,0,31,0,14,23,23,5,5,5,5,1
1,1,4,0,0,33,0,0,0,0,0,0,0,0,0,0,43,4,1
1,1,4,0,0,0,0,0,0,0,0,0,0,0,33,0,0,4,1
1,1,4,0,0,0,0,0,0,0,0,0,0,0,0,0,0,4,1
1,1,4,0,0,0,0,0,0,0,0,0,0,0,0,0,0,4,1
1,1,4,0,0,0,0,0,0,0,0,0,0,0,0,0,0,7,1
1,1,5,0,0,0,0,0,0,0,0,0,0,0,0,0,7,8,1
1,1,5,0,11,0,0,0,0,0,0,0,0,0,0,0,0,8,1
1,1,2,5,0,0,0,0,0,0,0,0,0,0,0,0,0,9,1
1,1,12,5,0,0,0,0,0,0,0,0,0,0,0,0,11,9,1
1,1,1,9,2,0,0,0,0,0,0,0,0,0,0,0,0,4,1
1,1,1,2,0,0,0,0,0,0,0,0,0,0,0,0,0,12,1
1,1,7,0,33,0,0,0,0,0,0,0,0,0,0,0,0,7,1
1,1,7,0,0,0,0,0,0,0,0,0,0,0,0,0,0,12,1
1,2,2,0,0,0,0,0,0,0,0,0,0,33,0,0,0,12,1
1,2,0,0,0,0,0,0,0,0,0,0,0,0,0,0,0,2,1
1,2,0,0,0,0,0,0,0,0,0,0,0,0,0,0,0,7,1
1,12,0,0,0,0,0,0,0,0,0,0,0,0,0,0,0,7,1
1,12,0,0,0,0,0,0,0,0,0,0,0,0,0,0,2,1,1
1,8,0,0,0,0,35,39,27,39,35,0,0,0,0,0,7,7,1
1,2,0,0,0,0,39,39,39,39,39,0,0,0,0,0,8,1,1
1,2,0,0,0,0,39,39,39,39,39,0,0,0,0,0,7,1,1
1,2,0,0,0,0,39,0,33,0,39,0,0,0,0,0,7,1,1
1,1,8,0,0,0,39,39,33,39,39,0,0,0,0,0,2,1,1
1,1,8,0,0,0,33,33,44,33,33,0,0,0,0,12,1,1,1
1,1,8,2,0,0,0,0,0,0,0,0,4,4,4,4,1,1,1
1,1,1,1,2,12,2,7,36,7,2,2,1,1,1,1,1,1,1
1,1,1,1,1,7,1,1,1,1,1,1,1,1,1,1,1,1,1
endlayer

layer
1,1,6,6,4,8,8,8,1,1,1,1,1,1,1,1,1,1,1
1,6,4,4,0,4,4,14,14,14,1,1,1,1,1,1,1,1,1
1,4,4,4,0,0,4,14,0,14,8,4,1,1,1,1,1,1,1
1,4,4,4,0,0,0,6,0,0,0,8,4,1,1,1,1,1,1
1,14,8,0,0,0,6,0,0,0,0,8,4,4,1,1,1,1,1
1,1,14,37,0,0,8,6,0,0,0,0,4,4,1,1,1,1,1
1,1,4,0,0,0,0,8,0,0,0,0,0,4,1,1,1,1,1
1,1,4,0,0,0,8,8,0,0,0,0,6,6,1,1,1,1,1
1,1,4,0,0,0,4,14,0,0,0,14,6,14,1,1,1,1,1
1,1,1,1,1,1,6,6,31,25,8,8,14,1,1,1,1,1,1
1,1,1,1,1,1,14,23,14,8,1,1,1,1,1,1,1,1,1
1,1,1,1,23,23,23,23,14,14,23,14,23,23,5,5,5,1,1
1,1,2,2,2,33,33,33,33,33,33,33,33,33,33,4,4,1,1
1,1,2,0,0,0,2,2,2,2,2,2,2,2,33,2,4,1,1
1,1,2,7,0,0,0,0,0,7,0,0,7,7,7,2,4,1,1
1,1,2,0,0,0,0,0,0,0,0,0,0,0,0,0,4,4,1
1,1,5,0,0,0,0,0,0,0,0,0,0,0,0,0,7,4,1
1,1,5,0,0,0,0,0,0,0,0,0,0,0,0,0,7,7,1
1,1,5,0,11,0,0,0,0,0,0,0,0,0,0,0,0,8,1
1,1,5,0,0,0,0,0,0,0,0,0,0,0,0,0,0,9,1
1,1,12,5,0,0,0,0,0,0,0,0,0,0,0,0,11,9,1
1,1,9,25,42,0,0,0,0,0,0,0,0,0,0,0,0,2,1
1,1,9,0,0,0,0,0,0,0,0,0,0,0,0,0,12,0,1
1,1,7,0,33,0,0,0,0,0,0,0,0,0,0,0,12,7,1
1,1,7,0,0,0,0,0,0,0,0,0,0,0,0,0,12,7,1
1,12,2,0,0,0,0,0,0,0,0,0,0,33,0,0,0,7,1
1,2,0,0,0,0,0,0,0,0,0,0,0,0,0,0,0,7,1
1,12,0,0,0,0,0,0,0,0,0,0,0,0,0,0,0,8,1
1,12,0,0,0,0,0,0,0,0,0,0,0,0,0,0,2,1,1
1,2,0,0,0,0,0,0,0,0,0,0,0,0,0,0,2,1,1
1,7,0,0,0,0,39,39,33,39,39,0,0,0,0,0,7,1,1
1,8,0,0,0,0,0,0,0,0,0,0,0,0,0,0,7,1,1
1,8,0,0,0,0,0,0,0,0,0,0,0,0,0,0,7,1,1
1,7,0,0,0,0,0,0,0,0,0,0,0,0,0,0,2,1,1
1,1,7,0,0,0,0,0,0,0,0,0,0,0,0,0,2,1,1
1,1,7,0,0,0,0,0,0,0,0,0,0,0,0,2,1,1,1
1,1,2,2,0,0,0,0,0,0,0,0,4,42,0,2,1,1,1
1,1,1,1,2,12,12,7,36,7,2,4,4,2,2,1,1,1,1
1,1,1,1,1,7,1,1,1,1,1,1,1,1,1,1,1,1,1
endlayer

layer
1,1,6,6,6,6,6,1,1,1,1,1,1,1,1,1,1,1,1
1,14,14,14,14,14,14,14,6,6,1,1,1,1,1,1,1,1,1
1,6,14,14,4,4,4,6,6,6,6,4,1,1,1,1,1,1,1
1,1,8,4,8,8,8,6,0,0,0,23,4,1,1,1,1,1,1
1,6,8,0,8,8,8,4,4,4,8,8,1,1,1,1,1,1,1
1,1,14,0,0,0,8,4,4,4,8,8,8,1,1,1,1,1,1
1,1,14,0,0,0,0,8,8,8,8,8,8,4,1,1,1,1,1
1,1,4,0,0,0,0,8,8,8,4,8,4,1,1,1,1,1,1
1,1,14,0,0,0,0,14,14,8,4,4,1,1,1,1,1,1,1
1,1,1,1,1,1,1,1,1,8,1,1,1,1,1,1,1,1,1
1,1,1,1,1,1,1,1,1,1,1,1,1,1,1,1,1,1,1
1,1,1,1,1,1,1,1,1,1,1,1,1,1,2,1,1,1,1
1,1,1,1,1,3,3,3,4,4,2,2,2,2,2,1,1,1,1
1,1,7,7,7,7,7,5,7,5,7,2,7,7,7,1,1,1,1
1,1,7,7,7,7,5,5,7,5,0,0,7,7,7,1,1,1,1
1,1,7,0,0,0,40,0,0,0,0,0,7,0,0,4,4,1,1
1,1,7,0,0,0,0,0,0,0,0,0,0,0,0,2,2,1,1
1,1,5,0,0,0,0,0,0,0,0,0,0,0,0,0,2,2,1
1,1,5,0,11,0,0,0,0,0,0,0,0,0,0,0,0,2,1
1,1,12,0,0,0,0,0,0,0,0,0,0,0,0,0,0,2,1
1,1,2,0,0,0,0,0,0,0,0,0,0,0,0,0,11,9,1
1,1,2,0,0,0,0,0,0,0,0,0,0,0,0,0,2,2,1
1,1,2,0,0,0,0,0,0,0,0,0,0,0,0,0,7,1,1
1,1,9,0,33,0,0,0,0,0,0,0,0,0,0,0,40,2,1
1,1,8,0,0,0,0,0,0,0,0,0,0,0,0,0,0,2,1
1,12,2,0,0,0,0,0,0,0,0,0,0,33,0,0,0,2,1
1,7,0,0,0,0,0,0,0,0,0,0,0,0,0,0,0,2,1
1,7,0,0,0,0,0,0,0,0,0,0,0,0,0,0,0,8,1
1,7,0,0,0,0,0,0,0,0,0,0,0,0,0,0,2,1,1
1,2,0,0,0,0,0,0,0,0,0,0,0,0,0,0,2,1,1
1,7,0,0,0,0,0,0,0,0,0,0,0,0,0,0,2,1,1
1,2,0,0,0,0,0,0,0,0,0,0,0,0,0,31,2,1,1
1,2,0,0,0,0,0,0,0,0,0,0,0,0,0,0,2,1,1
1,2,0,0,0,0,0,0,0,0,0,0,0,0,0,0,2,1,1
1,1,7,0,0,0,0,0,0,0,0,0,0,0,0,0,2,1,1
1,1,7,0,0,0,0,0,0,0,0,0,0,0,0,2,1,1,1
1,1,2,2,0,0,0,0,0,0,0,0,0,0,0,2,1,1,1
1,1,1,1,2,2,12,7,36,7,2,4,2,7,7,1,1,1,1
1,1,1,1,1,2,1,1,1,1,1,1,1,1,1,1,1,1,1
endlayer

layer
1,1,6,6,6,6,1,1,1,1,1,1,1,1,1,1,1,1,1
1,6,32,0,0,0,4,4,4,1,1,1,1,1,1,1,1,1,1
1,6,6,6,0,0,0,0,6,4,4,1,1,1,1,1,1,1,1
1,6,6,6,6,0,0,0,6,23,23,23,1,1,1,1,1,1,1
1,6,0,23,8,6,0,0,32,6,23,14,1,1,1,1,1,1,1
1,1,8,8,40,0,6,6,6,23,23,8,14,1,1,1,1,1,1
1,1,8,8,0,0,0,23,23,23,23,8,14,1,1,1,1,1,1
1,1,6,6,0,0,0,0,0,14,0,14,1,1,1,1,1,1,1
1,1,8,8,40,0,0,0,0,14,14,1,1,1,1,1,1,1,1
1,1,1,1,1,1,1,1,1,1,1,1,1,1,1,1,1,1,1
1,1,1,1,1,1,1,1,1,1,1,1,1,1,1,1,1,1,1
1,1,1,1,1,1,1,1,1,1,1,1,1,1,1,1,1,1,1
1,1,1,1,1,1,1,1,1,1,1,1,1,1,1,1,1,1,1
1,1,1,7,1,1,1,1,1,1,1,1,1,1,1,1,1,1,1
1,1,7,7,7,2,5,5,1,1,2,2,2,1,1,1,1,1,1
1,1,7,2,2,2,2,2,2,5,2,7,7,2,2,4,4,1,1
1,1,8,7,0,0,0,0,2,2,2,0,7,2,2,2,1,1,1
1,1,8,0,43,0,0,0,0,0,0,0,8,8,7,7,2,1,1
1,1,2,0,11,0,0,0,0,0,0,0,0,7,7,2,7,1,1
1,1,12,0,0,0,0,0,0,0,0,0,0,0,7,2,2,1,1
1,1,12,0,0,0,0,0,0,0,0,0,0,7,0,8,8,1,1
1,1,7,0,0,0,0,0,0,0,0,0,2,2,2,2,2,1,1
1,1,2,0,0,0,0,0,0,0,0,0,0,0,0,0,12,1,1
1,1,9,0,33,0,0,0,0,0,0,0,0,0,0,0,4,1,1
1,1,8,9,0,0,0,0,0,0,0,0,0,0,0,0,12,1,1
1,1,2,0,0,0,0,0,0,0,0,0,0,33,0,0,12,1,1
1,12,12,0,0,0,0,0,0,0,0,0,0,0,0,40,12,1,1
1,1,12,40,0,0,0,0,0,0,0,0,0,0,0,0,2,1,1
1,1,12,0,0,0,0,0,0,31,0,0,0,0,0,0,7,1,1
1,1,2,0,0,0,0,0,0,0,0,0,0,0,0,2,2,1,1
1,1,7,0,0,0,0,0,0,0,0,0,0,0,0,2,8,1,1
1,1,7,0,0,0,0,0,0,0,0,0,0,0,0,2,8,1,1
1,1,7,0,0,0,0,0,0,0,0,0,0,0,0,5,7,1,1
1,1,2,0,0,0,0,0,0,0,0,0,0,0,0,0,7,1,1
1,1,7,0,0,0,0,0,0,0,0,0,0,0,0,43,7,1,1
1,1,7,0,0,0,0,0,0,0,0,0,0,0,0,7,1,1,1
1,1,7,2,0,0,0,0,0,0,0,0,0,0,0,2,1,1,1
1,1,1,1,8,2,4,7,7,7,2,4,7,7,7,1,1,1,1
1,1,1,1,1,1,1,1,1,1,1,1,1,1,1,1,1,1,1
endlayer

layer
1,1,6,6,6,6,1,1,1,1,1,1,1,1,1,1,1,1,1
1,8,8,0,0,0,4,4,8,1,1,1,1,1,1,1,1,1,1
1,6,0,0,0,0,0,0,0,14,1,1,1,1,1,1,1,1,1
1,6,6,8,0,0,0,0,0,0,4,1,1,1,1,1,1,1,1
1,6,23,45,23,0,0,0,0,0,0,8,1,1,1,1,1,1,1
1,1,23,14,8,6,0,0,0,0,0,6,8,1,1,1,1,1,1
1,1,14,14,6,6,6,8,0,0,0,6,8,1,1,1,1,1,1
1,1,14,14,6,6,40,0,0,0,8,8,1,1,1,1,1,1,1
1,1,14,14,8,23,0,0,0,0,8,1,1,1,1,1,1,1,1
1,1,1,1,1,1,1,1,1,1,1,1,1,1,1,1,1,1,1
1,1,1,1,1,1,1,1,1,1,1,1,1,1,1,1,1,1,1
1,1,1,1,1,1,1,1,1,1,1,1,1,1,1,1,1,1,1
1,1,1,1,1,1,1,1,1,1,1,1,1,1,1,1,1,1,1
1,1,1,1,1,1,1,1,1,1,1,1,1,1,1,1,1,1,1
1,1,1,1,1,1,1,1,1,1,1,2,1,1,1,1,1,1,1
1,1,1,1,7,1,1,1,1,1,2,7,7,1,1,1,1,1,1
1,1,8,8,7,12,12,12,1,2,2,2,7,1,1,1,1,1,1
1,1,8,8,8,2,2,2,2,8,8,8,1,1,1,1,1,1,1
1,1,8,8,8,8,8,8,8,8,8,8,8,1,1,1,1,1,1
1,1,1,2,0,0,0,0,8,8,8,7,12,7,1,1,1,1,1
1,1,2,0,0,0,0,0,8,8,8,8,8,8,8,1,1,1,1
1,1,2,0,0,0,0,29,29,29,29,4,4,4,1,1,1,1,1
1,1,8,9,0,0,4,0,0,4,0,0,0,0,7,12,1,1,1
1,1,8,9,33,2,2,0,0,2,2,0,0,0,0,12,1,1,1
1,1,7,7,33,2,2,2,2,2,2,2,2,2,2,12,1,1,1
1,1,2,33,33,33,33,33,33,33,33,33,33,33,33,4,1,1,1
1,1,12,2,2,8,2,2,2,2,2,2,2,2,2,4,1,1,1
1,1,12,8,8,8,0,8,2,0,0,0,31,0,0,7,2,1,1
1,1,1,8,8,0,0,0,2,2,0,0,0,0,0,2,7,1,1
1,1,1,8,8,0,0,2,2,0,0,0,0,0,0,7,7,1,1
1,1,1,2,2,0,0,2,2,0,0,0,0,0,2,2,0,1,1
1,1,1,7,7,0,0,0,0,0,0,0,0,0,0,2,8,1,1
1,1,1,7,2,0,0,0,0,0,0,0,0,0,0,2,8,1,1
1,1,1,2,2,7,0,0,0,0,0,0,0,0,29,29,7,1,1
1,1,1,2,7,7,0,0,0,0,0,0,0,29,29,29,7,1,1
1,1,8,8,8,7,0,0,0,0,2,7,7,7,7,7,1,1,1
1,1,1,8,8,4,4,2,2,2,2,7,7,7,7,7,1,1,1
1,1,1,1,8,1,1,4,2,2,1,1,1,1,1,1,1,1,1
1,1,1,1,1,1,1,1,1,1,1,1,1,1,1,1,1,1,1
endlayer

layer
1,4,8,6,6,6,1,1,1,1,1,1,1,1,1,1,1,1,1
1,4,0,0,0,0,4,4,8,1,1,1,1,1,1,1,1,1,1
1,8,0,0,0,0,0,0,0,8,1,1,1,1,1,1,1,1,1
1,8,0,0,0,0,0,0,0,0,4,4,1,1,1,1,1,1,1
1,8,14,8,8,6,0,0,0,0,0,8,1,1,1,1,1,1,1
1,1,8,8,14,6,8,0,40,0,38,8,8,1,1,1,1,1,1
1,1,8,6,14,6,6,14,0,0,0,6,8,1,1,1,1,1,1
1,1,8,6,23,23,8,40,0,0,0,8,14,1,1,1,1,1,1
1,1,8,6,23,45,4,40,0,0,8,0,14,14,1,1,14,1,1
1,1,1,1,1,1,1,1,1,1,1,1,1,1,1,1,1,1,1
1,1,1,1,1,1,1,1,1,1,1,1,1,1,1,1,1,1,1
1,1,1,1,1,1,1,1,1,1,1,1,1,1,1,1,1,1,1
1,1,1,1,1,1,1,1,1,1,1,1,1,1,1,1,1,1,1
1,1,1,1,1,1,1,1,1,1,1,1,1,1,1,1,1,1,1
1,1,1,1,1,1,1,1,1,1,1,1,1,1,1,1,1,1,1
1,1,1,1,1,1,1,1,1,1,1,1,1,1,1,1,1,1,1
1,1,1,1,1,1,1,1,1,1,1,1,1,1,1,1,1,1,1
1,1,1,1,1,1,2,1,1,1,1,1,1,1,1,1,1,1,1
1,1,1,1,1,1,1,1,1,1,1,1,1,1,1,1,1,1,1
1,1,1,7,2,2,2,2,1,1,1,1,1,1,1,1,1,1,1
1,1,1,7,8,8,8,8,1,1,1,1,1,1,1,1,1,1,1
1,1,1,7,9,9,9,8,1,1,1,1,1,1,1,1,1,1,1
1,1,1,8,4,8,4,8,4,29,4,4,4,7,7,1,1,1,1
1,1,1,8,2,2,2,2,2,8,2,2,8,12,7,1,1,1,1
1,1,1,7,7,7,7,7,7,7,7,7,7,7,7,1,1,1,1
1,1,1,7,2,7,7,7,7,2,2,7,2,2,2,1,1,1,1
1,1,1,2,2,2,2,2,2,2,2,2,4,4,4,1,1,1,1
1,1,1,1,2,8,8,8,2,2,2,8,4,2,2,1,1,1,1
1,1,1,1,1,7,2,2,2,2,2,2,8,7,2,1,1,1,1
1,1,1,1,1,7,2,8,2,7,2,2,7,7,7,1,1,1,1
1,1,1,1,1,7,2,8,8,7,7,2,2,2,2,2,1,1,1
1,1,1,1,1,7,2,8,8,8,7,2,7,7,7,7,1,1,1
1,1,1,1,1,7,2,8,8,8,8,2,7,7,7,8,8,1,1
1,1,1,1,1,7,2,4,7,7,7,2,7,7,7,8,1,1,1
1,1,1,1,1,7,2,4,2,2,2,2,2,7,7,8,1,1,1
1,1,1,1,7,7,2,4,2,4,4,2,8,8,7,8,1,1,1
1,1,1,1,7,7,2,2,2,4,1,1,1,1,8,1,1,1,1
1,1,1,1,1,1,1,1,1,1,1,1,1,1,1,1,1,1,1
1,1,1,1,1,1,1,1,1,1,1,1,1,1,1,1,1,1,1
endlayer

layer
1,4,4,8,8,6,1,1,1,1,1,1,1,1,1,1,1,1,1
1,4,4,4,8,8,8,8,8,1,1,1,1,1,1,1,1,1,1
1,6,4,0,0,6,0,0,0,8,8,8,1,1,1,1,1,1,1
1,6,0,0,0,6,0,0,0,0,0,8,1,1,1,1,1,1,1
1,6,0,0,0,6,8,0,0,0,0,14,1,1,1,1,1,1,1
1,8,0,0,0,0,0,14,4,14,14,14,14,8,8,1,1,1,1
1,1,0,0,0,0,0,0,14,14,23,14,8,14,8,8,1,1,1
1,1,32,0,14,14,0,14,8,8,14,14,14,8,14,14,8,1,1
1,1,0,0,0,8,4,4,8,8,14,8,8,8,14,14,8,1,1
1,1,1,1,1,1,1,1,1,1,1,1,1,1,1,1,1,1,1
1,1,1,1,1,1,1,1,1,1,1,1,1,1,1,1,1,1,1
1,1,1,1,1,1,1,1,1,1,1,1,1,1,1,1,1,1,1
1,1,1,1,1,1,1,1,1,1,1,1,1,1,1,1,1,1,1
1,1,1,1,1,1,1,1,1,1,1,1,1,1,1,1,1,1,1
1,1,1,1,1,1,1,1,1,1,1,1,1,1,1,1,1,1,1
1,1,1,1,1,1,1,1,1,1,1,1,1,1,1,1,1,1,1
1,1,1,1,1,1,1,1,1,1,1,1,1,1,1,1,1,1,1
1,1,1,1,1,1,1,1,1,1,1,1,1,1,1,1,1,1,1
1,1,1,1,1,1,1,1,1,1,1,1,1,1,1,1,1,1,1
1,1,1,1,1,1,1,1,1,1,1,1,1,1,1,1,1,1,1
1,1,1,1,1,1,1,1,1,1,1,1,1,1,1,1,1,1,1
1,1,1,1,1,1,1,1,1,1,1,1,1,1,1,1,1,1,1
1,1,1,1,1,1,1,1,1,1,1,1,1,1,1,1,1,1,1
1,1,1,1,1,1,1,1,1,1,1,1,1,1,1,1,1,1,1
1,1,1,1,1,1,1,1,1,1,1,1,1,1,1,1,1,1,1
1,1,1,1,1,1,1,1,1,1,1,1,1,1,1,1,1,1,1
1,1,1,1,1,1,1,1,1,1,1,1,1,1,1,1,1,1,1
1,1,1,1,1,1,1,1,1,1,1,1,1,1,1,1,1,1,1
1,1,1,1,1,1,1,1,1,1,1,1,1,1,1,1,1,1,1
1,1,1,1,1,1,1,1,1,1,1,1,1,1,1,1,1,1,1
1,1,1,1,1,1,1,1,1,1,1,1,1,1,1,1,1,1,1
1,1,1,1,1,1,1,1,1,1,1,1,1,1,1,1,1,1,1
1,1,1,1,1,1,1,1,1,1,1,1,1,1,1,1,1,1,1
1,1,1,1,1,1,1,1,1,1,1,1,1,1,1,1,1,1,1
1,1,1,1,1,1,1,1,1,1,1,1,1,1,1,1,1,1,1
1,1,1,1,1,1,1,1,1,1,1,1,1,1,1,1,1,1,1
1,1,1,1,1,1,1,1,1,1,1,1,1,1,1,1,1,1,1
1,1,1,1,1,1,1,1,1,1,1,1,1,1,1,1,1,1,1
1,1,1,1,1,1,1,1,1,1,1,1,1,1,1,1,1,1,1
endlayer

layer
1,1,1,1,1,1,1,1,1,1,1,1,1,1,1,1,1,1,1
1,1,14,14,14,1,1,1,1,1,1,1,1,1,1,1,1,1,1
1,1,14,0,0,8,8,8,8,8,8,1,1,1,1,1,1,1,1
1,14,0,0,0,0,6,6,6,8,8,1,1,1,1,1,1,1,1
1,14,0,0,0,0,6,6,6,8,8,8,1,1,1,1,1,1,1
1,8,8,0,0,0,0,0,0,32,14,8,8,8,8,8,1,1,1
1,1,8,0,0,0,0,0,0,0,14,5,19,19,19,19,8,1,1
1,1,0,0,0,0,0,0,0,8,8,19,19,19,19,19,19,8,1
1,1,0,0,0,0,0,0,0,14,8,19,19,5,19,19,19,8,1
1,1,1,1,1,1,1,1,1,1,1,1,1,1,1,1,1,1,1
1,1,1,1,1,1,1,1,1,1,1,1,1,1,1,1,1,1,1
1,1,1,1,1,1,1,1,1,1,1,1,1,1,1,1,1,1,1
1,1,1,1,1,1,1,1,1,1,1,1,1,1,1,1,1,1,1
1,1,1,1,1,1,1,1,1,1,1,1,1,1,1,1,1,1,1
1,1,1,1,1,1,1,1,1,1,1,1,1,1,1,1,1,1,1
1,1,1,1,1,1,1,1,1,1,1,1,1,1,1,1,1,1,1
1,1,1,1,1,1,1,1,1,1,1,1,1,1,1,1,1,1,1
1,1,1,1,1,1,1,1,1,1,1,1,1,1,1,1,1,1,1
1,1,1,1,1,1,1,1,1,1,1,1,1,1,1,1,1,1,1
1,1,1,1,1,1,1,1,1,1,1,1,1,1,1,1,1,1,1
1,1,1,1,1,1,1,1,1,1,1,1,1,1,1,1,1,1,1
1,1,1,1,1,1,1,1,1,1,1,1,1,1,1,1,1,1,1
1,1,1,1,1,1,1,1,1,1,1,1,1,1,1,1,1,1,1
1,1,1,1,1,1,1,1,1,1,1,1,1,1,1,1,1,1,1
1,1,1,1,1,1,1,1,1,1,1,1,1,1,1,1,1,1,1
1,1,1,1,1,1,1,1,1,1,1,1,1,1,1,1,1,1,1
1,1,1,1,1,1,1,1,1,1,1,1,1,1,1,1,1,1,1
1,1,1,1,1,1,1,1,1,1,1,1,1,1,1,1,1,1,1
1,1,1,1,1,1,1,1,1,1,1,1,1,1,1,1,1,1,1
1,1,1,1,1,1,1,1,1,1,1,1,1,1,1,1,1,1,1
1,1,1,1,1,1,1,1,1,1,1,1,1,1,1,1,1,1,1
1,1,1,1,1,1,1,1,1,1,1,1,1,1,1,1,1,1,1
1,1,1,1,1,1,1,1,1,1,1,1,1,1,1,1,1,1,1
1,1,1,1,1,1,1,1,1,1,1,1,1,1,1,1,1,1,1
1,1,1,1,1,1,1,1,1,1,1,1,1,1,1,1,1,1,1
1,1,1,1,1,1,1,1,1,1,1,1,1,1,1,1,1,1,1
1,1,1,1,1,1,1,1,1,1,1,1,1,1,1,1,1,1,1
1,1,1,1,1,1,1,1,1,1,1,1,1,1,1,1,1,1,1
1,1,1,1,1,1,1,1,1,1,1,1,1,1,1,1,1,1,1
endlayer

layer
1,1,1,1,1,1,1,1,1,1,1,1,1,1,1,1,1,1,1
1,1,14,14,14,1,1,1,1,1,1,1,1,1,1,1,1,1,1
1,1,14,0,0,6,1,6,6,6,1,1,1,1,1,1,1,1,1
1,14,14,0,0,0,6,6,0,0,6,1,1,1,1,1,1,1,1
1,14,0,0,0,0,0,0,0,0,8,1,1,1,1,1,1,1,1
1,1,14,0,0,0,0,0,0,0,0,6,6,6,6,8,8,1,1
1,1,14,0,0,0,0,0,0,0,0,0,0,0,0,0,0,6,1
1,1,8,0,0,0,0,0,0,0,0,0,0,0,0,0,0,8,1
1,1,0,0,0,0,0,0,0,32,0,0,0,0,0,0,0,14,1
1,1,1,1,1,1,1,1,1,1,1,1,1,1,1,1,1,1,1
1,1,1,1,1,1,1,1,1,1,1,1,1,1,1,1,1,1,1
1,1,1,1,1,1,1,1,1,1,1,1,1,1,1,1,1,1,1
1,1,1,1,1,1,1,1,1,1,1,1,1,1,1,1,1,1,1
1,1,1,1,1,1,1,1,1,1,1,1,1,1,1,1,1,1,1
1,1,1,1,1,1,1,1,1,1,1,1,1,1,1,1,1,1,1
1,1,1,1,1,1,1,1,1,1,1,1,1,1,1,1,1,1,1
1,1,1,1,1,1,1,1,1,1,1,1,1,1,1,1,1,1,1
1,1,1,1,1,1,1,1,1,1,1,1,1,1,1,1,1,1,1
1,1,1,1,1,1,1,1,1,1,1,1,1,1,1,1,1,1,1
1,1,1,1,1,1,1,1,1,1,1,1,1,1,1,1,1,1,1
1,1,1,1,1,1,1,1,1,1,1,1,1,1,1,1,1,1,1
1,1,1,1,1,1,1,1,1,1,1,1,1,1,1,1,1,1,1
1,1,1,1,1,1,1,1,1,1,1,1,1,1,1,1,1,1,1
1,1,1,1,1,1,1,1,1,1,1,1,1,1,1,1,1,1,1
1,1,1,1,1,1,1,1,1,1,1,1,1,1,1,1,1,1,1
1,1,1,1,1,1,1,1,1,1,1,1,1,1,1,1,1,1,1
1,1,1,1,1,1,1,1,1,1,1,1,1,1,1,1,1,1,1
1,1,1,1,1,1,1,1,1,1,1,1,1,1,1,1,1,1,1
1,1,1,1,1,1,1,1,1,1,1,1,1,1,1,1,1,1,1
1,1,1,1,1,1,1,1,1,1,1,1,1,1,1,1,1,1,1
1,1,1,1,1,1,1,1,1,1,1,1,1,1,1,1,1,1,1
1,1,1,1,1,1,1,1,1,1,1,1,1,1,1,1,1,1,1
1,1,1,1,1,1,1,1,1,1,1,1,1,1,1,1,1,1,1
1,1,1,1,1,1,1,1,1,1,1,1,1,1,1,1,1,1,1
1,1,1,1,1,1,1,1,1,1,1,1,1,1,1,1,1,1,1
1,1,1,1,1,1,1,1,1,1,1,1,1,1,1,1,1,1,1
1,1,1,1,1,1,1,1,1,1,1,1,1,1,1,1,1,1,1
1,1,1,1,1,1,1,1,1,1,1,1,1,1,1,1,1,1,1
1,1,1,1,1,1,1,1,1,1,1,1,1,1,1,1,1,1,1
endlayer

layer
1,1,1,1,1,1,1,1,1,1,1,1,1,1,1,1,1,1,1
1,1,1,4,1,1,1,1,1,1,1,1,1,1,1,1,1,1,1
1,1,4,0,4,8,8,6,6,6,1,1,1,1,1,1,1,1,1
1,1,4,0,0,0,0,0,0,0,6,1,1,1,1,1,1,1,1
1,4,4,0,0,0,0,0,0,0,6,1,1,1,1,1,1,1,1
1,1,4,0,0,0,0,0,0,0,8,4,4,8,8,6,8,1,1
1,1,14,4,40,0,0,0,0,0,46,0,0,0,0,0,0,6,1
1,1,8,8,40,0,0,0,0,40,0,0,0,0,0,0,0,6,1
1,1,8,6,0,0,0,0,0,6,5,0,0,0,0,0,0,14,1
1,1,1,1,1,1,1,1,1,1,1,1,1,1,1,1,1,1,1
1,1,1,1,1,1,1,1,1,1,1,1,1,1,1,1,1,1,1
1,1,1,1,1,1,1,1,1,1,1,1,1,1,1,1,1,1,1
1,1,1,1,1,1,1,1,1,1,1,1,1,1,1,1,1,1,1
1,1,1,1,1,1,1,1,1,1,1,1,1,1,1,1,1,1,1
1,1,1,1,1,1,1,1,1,1,1,1,1,1,1,1,1,1,1
1,1,1,1,1,1,1,1,1,1,1,1,1,1,1,1,1,1,1
1,1,1,1,1,1,1,1,1,1,1,1,1,1,1,1,1,1,1
1,1,1,1,1,1,1,1,1,1,1,1,1,1,1,1,1,1,1
1,1,1,1,1,1,1,1,1,1,1,1,1,1,1,1,1,1,1
1,1,1,1,1,1,1,1,1,1,1,1,1,1,1,1,1,1,1
1,1,1,1,1,1,1,1,1,1,1,1,1,1,1,1,1,1,1
1,1,1,1,1,1,1,1,1,1,1,1,1,1,1,1,1,1,1
1,1,1,1,1,1,1,1,1,1,1,1,1,1,1,1,1,1,1
1,1,1,1,1,1,1,1,1,1,1,1,1,1,1,1,1,1,1
1,1,1,1,1,1,1,1,1,1,1,1,1,1,1,1,1,1,1
1,1,1,1,1,1,1,1,1,1,1,1,1,1,1,1,1,1,1
1,1,1,1,1,1,1,1,1,1,1,1,1,1,1,1,1,1,1
1,1,1,1,1,1,1,1,1,1,1,1,1,1,1,1,1,1,1
1,1,1,1,1,1,1,1,1,1,1,1,1,1,1,1,1,1,1
1,1,1,1,1,1,1,1,1,1,1,1,1,1,1,1,1,1,1
1,1,1,1,1,1,1,1,1,1,1,1,1,1,1,1,1,1,1
1,1,1,1,1,1,1,1,1,1,1,1,1,1,1,1,1,1,1
1,1,1,1,1,1,1,1,1,1,1,1,1,1,1,1,1,1,1
1,1,1,1,1,1,1,1,1,1,1,1,1,1,1,1,1,1,1
1,1,1,1,1,1,1,1,1,1,1,1,1,1,1,1,1,1,1
1,1,1,1,1,1,1,1,1,1,1,1,1,1,1,1,1,1,1
1,1,1,1,1,1,1,1,1,1,1,1,1,1,1,1,1,1,1
1,1,1,1,1,1,1,1,1,1,1,1,1,1,1,1,1,1,1
1,1,1,1,1,1,1,1,1,1,1,1,1,1,1,1,1,1,1
endlayer

layer
1,1,1,1,1,1,1,1,1,1,1,1,1,1,1,1,1,1,1
1,1,1,1,1,1,1,1,1,1,1,1,1,1,1,1,1,1,1
1,1,1,4,1,1,1,6,6,6,1,1,1,1,1,1,1,1,1
1,1,1,4,4,8,8,6,6,6,1,1,1,1,1,1,1,1,1
1,1,1,4,4,14,40,0,6,6,1,1,1,1,1,1,1,1,1
1,1,1,4,4,14,0,0,0,40,8,4,4,8,8,8,1,1,1
1,1,1,1,14,0,0,40,0,0,0,0,0,0,0,0,4,4,1
1,1,1,1,8,0,0,0,0,8,5,0,0,0,0,0,0,4,1
1,1,1,1,6,0,6,0,6,8,5,5,0,0,0,0,0,14,1
1,1,1,1,1,1,1,1,1,1,1,1,1,1,1,1,1,1,1
1,1,1,1,1,1,1,1,1,1,1,1,1,1,1,1,1,1,1
1,1,1,1,1,1,1,1,1,1,1,1,1,1,1,1,1,1,1
1,1,1,1,1,1,1,1,1,1,1,1,1,1,1,1,1,1,1
1,1,1,1,1,1,1,1,1,1,1,1,1,1,1,1,1,1,1
1,1,1,1,1,1,1,1,1,1,1,1,1,1,1,1,1,1,1
1,1,1,1,1,1,1,1,1,1,1,1,1,1,1,1,1,1,1
1,1,1,1,1,1,1,1,1,1,1,1,1,1,1,1,1,1,1
1,1,1,1,1,1,1,1,1,1,1,1,1,1,1,1,1,1,1
1,1,1,1,1,1,1,1,1,1,1,1,1,1,1,1,1,1,1
1,1,1,1,1,1,1,1,1,1,1,1,1,1,1,1,1,1,1
1,1,1,1,1,1,1,1,1,1,1,1,1,1,1,1,1,1,1
1,1,1,1,1,1,1,1,1,1,1,1,1,1,1,1,1,1,1
1,1,1,1,1,1,1,1,1,1,1,1,1,1,1,1,1,1,1
1,1,1,1,1,1,1,1,1,1,1,1,1,1,1,1,1,1,1
1,1,1,1,1,1,1,1,1,1,1,1,1,1,1,1,1,1,1
1,1,1,1,1,1,1,1,1,1,1,1,1,1,1,1,1,1,1
1,1,1,1,1,1,1,1,1,1,1,1,1,1,1,1,1,1,1
1,1,1,1,1,1,1,1,1,1,1,1,1,1,1,1,1,1,1
1,1,1,1,1,1,1,1,1,1,1,1,1,1,1,1,1,1,1
1,1,1,1,1,1,1,1,1,1,1,1,1,1,1,1,1,1,1
1,1,1,1,1,1,1,1,1,1,1,1,1,1,1,1,1,1,1
1,1,1,1,1,1,1,1,1,1,1,1,1,1,1,1,1,1,1
1,1,1,1,1,1,1,1,1,1,1,1,1,1,1,1,1,1,1
1,1,1,1,1,1,1,1,1,1,1,1,1,1,1,1,1,1,1
1,1,1,1,1,1,1,1,1,1,1,1,1,1,1,1,1,1,1
1,1,1,1,1,1,1,1,1,1,1,1,1,1,1,1,1,1,1
1,1,1,1,1,1,1,1,1,1,1,1,1,1,1,1,1,1,1
1,1,1,1,1,1,1,1,1,1,1,1,1,1,1,1,1,1,1
1,1,1,1,1,1,1,1,1,1,1,1,1,1,1,1,1,1,1
endlayer

layer
1,1,1,1,1,1,1,1,1,1,1,1,1,1,1,1,1,1,1
1,1,1,1,1,1,1,1,1,1,1,1,1,1,1,1,1,1,1
1,1,1,1,1,1,1,1,6,1,1,1,1,1,1,1,1,1,1
1,1,1,1,1,1,1,1,6,6,1,1,1,1,1,1,1,1,1
1,1,1,1,1,1,8,6,6,6,1,1,1,1,1,1,1,1,1
1,1,1,1,1,8,6,6,6,14,14,8,4,8,8,8,1,1,1
1,1,1,1,1,8,6,8,6,14,40,5,5,0,0,0,4,4,1
1,1,1,1,1,8,6,8,6,8,5,0,0,0,0,0,0,4,1
1,1,1,1,1,6,6,8,1,8,5,0,0,0,0,0,0,14,1
1,1,1,1,1,1,1,1,1,1,1,1,1,1,1,1,1,1,1
1,1,1,1,1,1,1,1,1,1,1,1,1,1,1,1,1,1,1
1,1,1,1,1,1,1,1,1,1,1,1,1,1,1,1,1,1,1
1,1,1,1,1,1,1,1,1,1,1,1,1,1,1,1,1,1,1
1,1,1,1,1,1,1,1,1,1,1,1,1,1,1,1,1,1,1
1,1,1,1,1,1,1,1,1,1,1,1,1,1,1,1,1,1,1
1,1,1,1,1,1,1,1,1,1,1,1,1,1,1,1,1,1,1
1,1,1,1,1,1,1,1,1,1,1,1,1,1,1,1,1,1,1
1,1,1,1,1,1,1,1,1,1,1,1,1,1,1,1,1,1,1
1,1,1,1,1,1,1,1,1,1,1,1,1,1,1,1,1,1,1
1,1,1,1,1,1,1,1,1,1,1,1,1,1,1,1,1,1,1
1,1,1,1,1,1,1,1,1,1,1,1,1,1,1,1,1,1,1
1,1,1,1,1,1,1,1,1,1,1,1,1,1,1,1,1,1,1
1,1,1,1,1,1,1,1,1,1,1,1,1,1,1,1,1,1,1
1,1,1,1,1,1,1,1,1,1,1,1,0,1,1,1,1,1,1
1,1,1,1,1,1,1,1,1,1,1,1,1,1,1,1,1,1,1
1,1,1,1,1,1,1,1,1,1,1,1,1,1,1,1,1,1,1
1,1,1,1,1,1,1,1,1,1,1,1,1,1,1,1,1,1,1
1,1,1,1,1,1,1,1,1,1,1,1,1,1,1,1,1,1,1
1,1,1,1,1,1,1,1,1,1,1,1,1,1,1,1,1,1,1
1,1,1,1,1,1,1,1,1,1,1,1,1,1,1,1,1,1,1
1,1,1,1,1,1,1,1,1,1,1,1,1,1,1,1,1,1,1
1,1,1,1,1,1,1,1,1,1,1,1,1,1,1,1,1,1,1
1,1,1,1,1,1,1,1,1,1,1,1,1,1,1,1,1,1,1
1,1,1,1,1,1,1,1,1,1,1,1,1,1,1,1,1,1,1
1,1,1,1,1,1,1,1,1,1,1,1,1,1,1,1,1,1,1
1,1,1,1,1,1,1,1,1,1,1,1,1,1,1,1,1,1,1
1,1,1,1,1,1,1,1,1,1,1,1,1,1,1,1,1,1,1
1,1,1,1,1,1,1,1,1,1,1,1,1,1,1,1,1,1,1
1,1,1,1,1,1,1,1,1,1,1,1,1,1,1,1,1,1,1
endlayer

layer
1,1,1,1,1,1,1,1,1,1,1,1,1,1,1,1,1,1,1
1,1,1,1,1,1,1,1,1,1,1,1,1,1,1,1,1,1,1
1,1,1,1,1,1,1,1,1,1,1,1,1,1,1,1,1,1,1
1,1,1,1,1,1,1,1,1,1,1,1,1,1,1,1,1,1,1
1,1,1,1,1,1,1,1,1,1,1,1,1,1,1,1,1,1,1
1,1,1,1,1,1,1,1,1,8,8,8,8,8,8,8,1,1,1
1,1,1,1,1,1,1,1,1,8,4,0,0,0,0,0,8,4,1
1,1,1,1,1,1,1,1,1,8,0,0,0,0,0,0,0,4,1
1,1,1,1,1,1,1,1,1,8,0,0,0,0,0,0,0,14,1
1,1,1,1,1,1,1,1,1,1,1,1,1,1,1,1,1,1,1
1,1,1,1,1,1,1,1,1,1,1,1,1,1,1,1,1,1,1
1,1,1,1,1,1,1,1,1,1,1,1,1,1,1,1,1,1,1
1,1,1,1,1,1,1,1,1,1,1,1,1,1,1,1,1,1,1
1,1,1,1,1,1,1,1,1,1,1,1,1,1,1,1,1,1,1
1,1,1,1,1,1,1,1,1,1,1,1,1,1,1,1,1,1,1
1,1,1,1,1,1,1,1,1,1,1,1,1,1,1,1,1,1,1
1,1,1,1,1,1,1,1,1,1,1,1,1,1,1,1,1,1,1
1,1,1,1,1,1,1,1,1,1,1,1,1,1,1,1,1,1,1
1,1,1,1,1,1,1,1,1,1,1,1,1,1,1,1,1,1,1
1,1,1,1,1,1,1,1,1,1,1,1,1,1,1,1,1,1,1
1,1,1,1,1,1,1,1,1,1,1,1,1,1,1,1,1,1,1
1,1,1,1,1,1,1,1,1,1,1,1,1,1,1,1,1,1,1
1,1,1,1,1,1,1,1,1,1,1,1,1,1,1,1,1,1,1
1,1,1,1,1,1,1,1,1,1,1,1,1,1,1,1,1,1,1
1,1,1,1,1,1,1,1,1,1,1,1,1,1,1,1,1,1,1
1,1,1,1,1,1,1,1,1,1,1,1,1,1,1,1,1,1,1
1,1,1,1,1,1,1,1,1,1,1,1,1,1,1,1,1,1,1
1,1,1,1,1,1,1,1,1,1,1,1,1,1,1,1,1,1,1
1,1,1,1,1,1,1,1,1,1,1,1,1,1,1,1,1,1,1
1,1,1,1,1,1,1,1,1,1,1,1,1,1,1,1,1,1,1
1,1,1,1,1,1,1,1,1,1,1,1,1,1,1,1,1,1,1
1,1,1,1,1,1,1,1,1,1,1,1,1,1,1,1,1,1,1
1,1,1,1,1,1,1,1,1,1,1,1,1,1,1,1,1,1,1
1,1,1,1,1,1,1,1,1,1,1,1,1,1,1,1,1,1,1
1,1,1,1,1,1,1,1,1,1,1,1,1,1,1,1,1,1,1
1,1,1,1,1,1,1,1,1,1,1,1,1,1,1,1,1,1,1
1,1,1,1,1,1,1,1,1,1,1,1,1,1,1,1,1,1,1
1,1,1,1,1,1,1,1,1,1,1,1,1,1,1,1,1,1,1
1,1,1,1,1,1,1,1,1,1,1,1,1,1,1,1,1,1,1
endlayer

layer
1,1,1,1,1,1,1,1,1,1,1,1,1,1,1,1,1,1,1
1,1,1,1,1,1,1,1,1,1,1,1,1,1,1,1,1,1,1
1,1,1,1,1,1,1,1,1,1,1,1,1,1,1,1,1,1,1
1,1,1,1,1,1,1,1,1,1,1,1,1,1,1,1,1,1,1
1,1,1,1,1,1,1,1,1,1,1,1,1,1,1,1,1,1,1
1,1,1,1,1,1,1,1,1,8,4,8,8,14,14,14,1,1,1
1,1,1,1,1,1,1,1,1,8,4,0,0,0,0,0,14,14,1
1,1,1,1,1,1,1,1,1,8,0,0,0,0,0,0,0,5,1
1,1,1,1,1,1,1,1,1,4,40,0,0,0,0,0,0,4,1
1,1,1,1,1,1,1,1,1,1,1,1,1,1,1,1,1,1,1
1,1,1,1,1,1,1,1,1,1,1,1,1,1,1,1,1,1,1
1,1,1,1,1,1,1,1,1,1,1,1,1,1,1,1,1,1,1
1,1,1,1,1,1,1,1,1,1,1,1,1,1,1,1,1,1,1
1,1,1,1,1,1,1,1,1,1,1,1,1,1,1,1,1,1,1
1,1,1,1,1,1,1,1,1,1,1,1,1,1,1,1,1,1,1
1,1,1,1,1,1,1,1,1,1,1,1,1,1,1,1,1,1,1
1,1,1,1,1,1,1,1,1,1,1,1,1,1,1,1,1,1,1
1,1,1,1,1,1,1,1,1,1,1,1,1,1,1,1,1,1,1
1,1,1,1,1,1,1,1,1,1,1,1,1,1,1,1,1,1,1
1,1,1,1,1,1,1,1,1,1,1,1,1,1,1,1,1,1,1
1,1,1,1,1,1,1,1,1,1,1,1,1,1,1,1,1,1,1
1,1,1,1,1,1,1,1,1,1,1,1,1,1,1,1,1,1,1
1,1,1,1,1,1,1,1,1,1,1,1,1,1,1,1,1,1,1
1,1,1,1,1,1,1,1,1,1,1,1,1,1,1,1,1,1,1
1,1,1,1,1,1,1,1,1,1,1,1,1,1,1,1,1,1,1
1,1,1,1,1,1,1,1,1,1,1,1,1,1,1,1,1,1,1
1,1,1,1,1,1,1,1,1,1,1,1,1,1,1,1,1,1,1
1,1,1,1,1,1,1,1,1,1,1,1,1,1,1,1,1,1,1
1,1,1,1,1,1,1,1,1,1,1,1,1,1,1,1,1,1,1
1,1,1,1,1,1,1,1,1,1,1,1,1,1,1,1,1,1,1
1,1,1,1,1,1,1,1,1,1,1,1,1,1,1,1,1,1,1
1,1,1,1,1,1,1,1,1,1,1,1,1,1,1,1,1,1,1
1,1,1,1,1,1,1,1,1,1,1,1,1,1,1,1,1,1,1
1,1,1,1,1,1,1,1,1,1,1,1,1,1,1,1,1,1,1
1,1,1,1,1,1,1,1,1,1,1,1,1,1,1,1,1,1,1
1,1,1,1,1,1,1,1,1,1,1,1,1,1,1,1,1,1,1
1,1,1,1,1,1,1,1,1,1,1,1,1,1,1,1,1,1,1
1,1,1,1,1,1,1,1,1,1,1,1,1,1,1,1,1,1,1
1,1,1,1,1,1,1,1,1,1,1,1,1,1,1,1,1,1,1
endlayer

layer
1,1,1,1,1,1,1,1,1,1,1,1,1,1,1,1,1,1,1
1,1,1,1,1,1,1,1,1,1,1,1,1,1,1,1,1,1,1
1,1,1,1,1,1,1,1,1,1,1,1,1,1,1,1,1,1,1
1,1,1,1,1,1,1,1,1,1,1,1,1,1,1,1,1,1,1
1,1,1,1,1,1,1,1,1,1,1,1,1,1,1,1,1,1,1
1,1,1,1,1,1,1,1,1,1,4,8,14,14,14,14,1,1,1
1,1,1,1,1,1,1,1,1,8,4,0,0,0,0,14,4,4,1
1,1,1,1,1,1,1,1,1,8,5,0,0,0,0,0,0,8,1
1,1,1,1,1,1,1,1,1,8,8,0,0,0,0,0,0,4,1
1,1,1,1,1,1,1,1,1,1,1,1,1,1,1,1,1,1,1
1,1,1,1,1,1,1,1,1,1,1,1,1,1,1,1,1,1,1
1,1,1,1,1,1,1,1,1,1,1,1,1,1,1,1,1,1,1
1,1,1,1,1,1,1,1,1,1,1,1,1,1,1,1,1,1,1
1,1,1,1,1,1,1,1,1,1,1,1,1,1,1,1,1,1,1
1,1,1,1,1,1,1,1,1,1,1,1,1,1,1,1,1,1,1
1,1,1,1,1,1,1,1,1,1,1,1,1,1,1,1,1,1,1
1,1,1,1,1,1,1,1,1,1,1,1,1,1,1,1,1,1,1
1,1,1,1,1,1,1,1,1,1,1,1,1,1,1,1,1,1,1
1,1,1,1,1,1,1,1,1,1,1,1,1,1,1,1,1,1,1
1,1,1,1,1,1,1,1,1,1,1,1,1,1,1,1,1,1,1
1,1,1,1,1,1,1,1,1,1,1,1,1,1,1,1,1,1,1
1,1,1,1,1,1,1,1,1,1,1,1,1,1,1,1,1,1,1
1,1,1,1,1,1,1,1,1,1,1,1,1,1,1,1,1,1,1
1,1,1,1,1,1,1,1,1,1,1,1,1,1,1,1,1,1,1
1,1,1,1,1,1,1,1,1,1,1,1,1,1,1,1,1,1,1
1,1,1,1,1,1,1,1,1,1,1,1,1,1,1,1,1,1,1
1,1,1,1,1,1,1,1,1,1,1,1,1,1,1,1,1,1,1
1,1,1,1,1,1,1,1,1,1,1,1,1,1,1,1,1,1,1
1,1,1,1,1,1,1,1,1,1,1,1,1,1,1,1,1,1,1
1,1,1,1,1,1,1,1,1,1,1,1,1,1,1,1,1,1,1
1,1,1,1,1,1,1,1,1,1,1,1,1,1,1,1,1,1,1
1,1,1,1,1,1,1,1,1,1,1,1,1,1,1,1,1,1,1
1,1,1,1,1,1,1,1,1,1,1,1,1,1,1,1,1,1,1
1,1,1,1,1,1,1,1,1,1,1,1,1,1,1,1,1,1,1
1,1,1,1,1,1,1,1,1,1,1,1,1,1,1,1,1,1,1
1,1,1,1,1,1,1,1,1,1,1,1,1,1,1,1,1,1,1
1,1,1,1,1,1,1,1,1,1,1,1,1,1,1,1,1,1,1
1,1,1,1,1,1,1,1,1,1,1,1,1,1,1,1,1,1,1
1,1,1,1,1,1,1,1,1,1,1,1,1,1,1,1,1,1,1
endlayer

layer
1,1,1,1,1,1,1,1,1,1,1,1,1,1,1,1,1,1,1
1,1,1,1,1,1,1,1,1,1,1,1,1,1,1,1,1,1,1
1,1,1,1,1,1,1,1,1,1,1,1,1,1,1,1,1,1,1
1,1,1,1,1,1,1,1,1,1,1,1,1,1,1,1,1,1,1
1,1,1,1,1,1,1,1,1,1,1,1,1,1,1,1,1,1,1
1,1,1,1,1,1,1,1,1,1,4,8,14,14,14,8,1,1,1
1,1,1,1,1,1,1,1,1,1,4,0,0,0,0,0,8,4,1
1,1,1,1,1,1,1,1,1,8,8,0,0,0,0,0,0,4,1
1,1,1,1,1,1,1,1,1,8,8,0,0,0,0,0,0,4,1
1,1,1,1,1,1,1,1,1,1,1,1,1,1,1,1,1,1,1
1,1,1,1,1,1,1,1,1,1,1,1,1,1,1,1,1,1,1
1,1,1,1,1,1,1,1,1,1,1,1,1,1,1,1,1,1,1
1,1,1,1,1,1,1,1,1,1,1,1,1,1,1,1,1,1,1
1,1,1,1,1,1,1,1,1,1,1,1,1,1,1,1,1,1,1
1,1,1,1,1,1,1,1,1,1,1,1,1,1,1,1,1,1,1
1,1,1,1,1,1,1,1,1,1,1,1,1,1,1,1,1,1,1
1,1,1,1,1,1,1,1,1,1,1,1,1,1,1,1,1,1,1
1,1,1,1,1,1,1,1,1,1,1,1,1,1,1,1,1,1,1
1,1,1,1,1,1,1,1,1,1,1,1,1,1,1,1,1,1,1
1,1,1,1,1,1,1,1,1,1,1,1,1,1,1,1,1,1,1
1,1,1,1,1,1,1,1,1,1,1,1,1,1,1,1,1,1,1
1,1,1,1,1,1,1,1,1,1,1,1,1,1,1,1,1,1,1
1,1,1,1,1,1,1,1,1,1,1,1,1,1,1,1,1,1,1
1,1,1,1,1,1,1,1,1,1,1,1,1,1,1,1,1,1,1
1,1,1,1,1,1,1,1,1,1,1,1,1,1,1,1,1,1,1
1,1,1,1,1,1,1,1,1,1,1,1,1,1,1,1,1,1,1
1,1,1,1,1,1,1,1,1,1,1,1,1,1,1,1,1,1,1
1,1,1,1,1,1,1,1,1,1,1,1,1,1,1,1,1,1,1
1,1,1,1,1,1,1,1,1,1,1,1,1,1,1,1,1,1,1
1,1,1,1,1,1,1,1,1,1,1,1,1,1,1,1,1,1,1
1,1,1,1,1,1,1,1,1,1,1,1,1,1,1,1,1,1,1
1,1,1,1,1,1,1,1,1,1,1,1,1,1,1,1,1,1,1
1,1,1,1,1,1,1,1,1,1,1,1,1,1,1,1,1,1,1
1,1,1,1,1,1,1,1,1,1,1,1,1,1,1,1,1,1,1
1,1,1,1,1,1,1,1,1,1,1,1,1,1,1,1,1,1,1
1,1,1,1,1,1,1,1,1,1,1,1,1,1,1,1,1,1,1
1,1,1,1,1,1,1,1,1,1,1,1,1,1,1,1,1,1,1
1,1,1,1,1,1,1,1,1,1,1,1,1,1,1,1,1,1,1
1,1,1,1,1,1,1,1,1,1,1,1,1,1,1,1,1,1,1
endlayer

layer
1,1,1,1,1,1,1,1,1,1,1,1,1,1,1,1,1,1,1
1,1,1,1,1,1,1,1,1,1,1,1,1,1,1,1,1,1,1
1,1,1,1,1,1,1,1,1,1,1,1,1,1,1,1,1,1,1
1,1,1,1,1,1,1,1,1,1,1,1,1,1,1,1,1,1,1
1,1,1,1,1,1,1,1,1,1,1,1,1,1,1,1,1,1,1
1,1,1,1,1,1,1,1,1,1,1,8,8,8,8,8,1,1,1
1,1,1,1,1,1,1,1,1,1,4,0,0,0,0,0,8,8,1
1,1,1,1,1,1,1,1,1,1,4,0,0,0,0,0,0,4,1
1,1,1,1,1,1,1,1,1,1,4,14,40,0,0,0,0,4,1
1,1,1,1,1,1,1,1,1,1,1,1,1,1,1,1,1,1,1
1,1,1,1,1,1,1,1,1,1,1,1,1,1,1,1,1,1,1
1,1,1,1,1,1,1,1,1,1,1,1,1,1,1,1,1,1,1
1,1,1,1,1,1,1,1,1,1,1,1,1,1,1,1,1,1,1
1,1,1,1,1,1,1,1,1,1,1,1,1,1,1,1,1,1,1
1,1,1,1,1,1,1,1,1,1,1,1,1,1,1,1,1,1,1
1,1,1,1,1,1,1,1,1,1,1,1,1,1,1,1,1,1,1
1,1,1,1,1,1,1,1,1,1,1,1,1,1,1,1,1,1,1
1,1,1,1,1,1,1,1,1,1,1,1,1,1,1,1,1,1,1
1,1,1,1,1,1,1,1,1,1,1,1,1,1,1,1,1,1,1
1,1,1,1,1,1,1,1,1,1,1,1,1,1,1,1,1,1,1
1,1,1,1,1,1,1,1,1,1,1,1,1,1,1,1,1,1,1
1,1,1,1,1,1,1,1,1,1,1,1,1,1,1,1,1,1,1
1,1,1,1,1,1,1,1,1,1,1,1,1,1,1,1,1,1,1
1,1,1,1,1,1,1,1,1,1,1,1,1,1,1,1,1,1,1
1,1,1,1,1,1,1,1,1,1,1,1,1,1,1,1,1,1,1
1,1,1,1,1,1,1,1,1,1,1,1,1,1,1,1,1,1,1
1,1,1,1,1,1,1,1,1,1,1,1,1,1,1,1,1,1,1
1,1,1,1,1,1,1,1,1,1,1,1,1,1,1,1,1,1,1
1,1,1,1,1,1,1,1,1,1,1,1,1,1,1,1,1,1,1
1,1,1,1,1,1,1,1,1,1,1,1,1,1,1,1,1,1,1
1,1,1,1,1,1,1,1,1,1,1,1,1,1,1,1,1,1,1
1,1,1,1,1,1,1,1,1,1,1,1,1,1,1,1,1,1,1
1,1,1,1,1,1,1,1,1,1,1,1,1,1,1,1,1,1,1
1,1,1,1,1,1,1,1,1,1,1,1,1,1,1,1,1,1,1
1,1,1,1,1,1,1,1,1,1,1,1,1,1,1,1,1,1,1
1,1,1,1,1,1,1,1,1,1,1,1,1,1,1,1,1,1,1
1,1,1,1,1,1,1,1,1,1,1,1,1,1,1,1,1,1,1
1,1,1,1,1,1,1,1,1,1,1,1,1,1,1,1,1,1,1
1,1,1,1,1,1,1,1,1,1,1,1,1,1,1,1,1,1,1
endlayer

layer
1,1,1,1,1,1,1,1,1,1,1,1,1,1,1,1,1,1,1
1,1,1,1,1,1,1,1,1,1,1,1,1,1,1,1,1,1,1
1,1,1,1,1,1,1,1,1,1,1,1,1,1,1,1,1,1,1
1,1,1,1,1,1,1,1,1,1,1,1,1,1,1,1,1,1,1
1,1,1,1,1,1,1,1,1,1,1,1,1,1,8,8,1,1,1
1,1,1,1,1,1,1,1,1,1,1,1,8,8,8,8,4,1,1
1,1,1,1,1,1,1,1,1,1,1,8,8,0,0,0,0,4,1
1,1,1,1,1,1,1,1,1,1,1,8,0,0,0,0,0,4,1
1,1,1,1,1,1,1,1,1,1,1,8,4,0,0,0,0,4,1
1,1,1,1,1,1,1,1,1,1,1,1,1,1,1,1,1,1,1
1,1,1,1,1,1,1,1,1,1,1,1,1,1,1,1,1,1,1
1,1,1,1,1,1,1,1,1,1,1,1,1,1,1,1,1,1,1
1,1,1,1,1,1,1,1,1,1,1,1,1,1,1,1,1,1,1
1,1,1,1,1,1,1,1,1,1,1,1,1,1,1,1,1,1,1
1,1,1,1,1,1,1,1,1,1,1,1,1,1,1,1,1,1,1
1,1,1,1,1,1,1,1,1,1,1,1,1,1,1,1,1,1,1
1,1,1,1,1,1,1,1,1,1,1,1,1,1,1,1,1,1,1
1,1,1,1,1,1,1,1,1,1,1,1,1,1,1,1,1,1,1
1,1,1,1,1,1,1,1,1,1,1,1,1,1,1,1,1,1,1
1,1,1,1,1,1,1,1,1,1,1,1,1,1,1,1,1,1,1
1,1,1,1,1,1,1,1,1,1,1,1,1,1,1,1,1,1,1
1,1,1,1,1,1,1,1,1,1,1,1,1,1,1,1,1,1,1
1,1,1,1,1,1,1,1,1,1,1,1,1,1,1,1,1,1,1
1,1,1,1,1,1,1,1,1,1,1,1,1,1,1,1,1,1,1
1,1,1,1,1,1,1,1,1,1,1,1,1,1,1,1,1,1,1
1,1,1,1,1,1,1,1,1,1,1,1,1,1,1,1,1,1,1
1,1,1,1,1,1,1,1,1,1,1,1,1,1,1,1,1,1,1
1,1,1,1,1,1,1,1,1,1,1,1,1,1,1,1,1,1,1
1,1,1,1,1,1,1,1,1,1,1,1,1,1,1,1,1,1,1
1,1,1,1,1,1,1,1,1,1,1,1,1,1,1,1,1,1,1
1,1,1,1,1,1,1,1,1,1,1,1,1,1,1,1,1,1,1
1,1,1,1,1,1,1,1,1,1,1,1,1,1,1,1,1,1,1
1,1,1,1,1,1,1,1,1,1,1,1,1,1,1,1,1,1,1
1,1,1,1,1,1,1,1,1,1,1,1,1,1,1,1,1,1,1
1,1,1,1,1,1,1,1,1,1,1,1,1,1,1,1,1,1,1
1,1,1,1,1,1,1,1,1,1,1,1,1,1,1,1,1,1,1
1,1,1,1,1,1,1,1,1,1,1,1,1,1,1,1,1,1,1
1,1,1,1,1,1,1,1,1,1,1,1,1,1,1,1,1,1,1
1,1,1,1,1,1,1,1,1,1,1,1,1,1,1,1,1,1,1
endlayer

layer
1,1,1,1,1,1,1,1,1,1,1,1,1,1,1,1,1,1,1
1,1,1,1,1,1,1,1,1,1,1,1,1,1,1,1,1,1,1
1,1,1,1,1,1,1,1,1,1,1,1,1,1,1,1,1,1,1
1,1,1,1,1,1,1,1,1,1,1,5,5,1,5,5,1,1,1
1,1,1,1,1,1,1,1,1,1,5,5,5,5,5,5,5,1,1
1,1,1,1,1,1,5,1,1,5,5,5,5,5,5,0,5,5,5
1,1,1,1,1,1,1,1,5,5,5,5,5,0,0,0,0,5,1
1,1,1,1,1,1,1,1,1,5,5,5,0,0,0,0,0,5,1
1,1,1,1,1,1,1,1,5,5,5,5,8,0,0,0,0,4,1
1,1,1,1,1,1,1,1,5,5,5,5,5,5,5,5,5,1,1
1,1,1,1,1,1,1,1,5,5,5,5,5,5,5,5,1,1,1
1,1,1,1,1,1,1,5,1,5,19,5,5,5,1,5,5,5,1
1,1,1,1,1,1,1,1,1,5,1,5,5,1,1,5,5,1,1
1,1,1,1,1,1,1,1,1,1,1,1,5,1,1,1,5,1,1
1,1,1,1,1,1,1,1,1,1,1,1,1,1,1,1,1,1,1
1,1,1,1,1,1,1,1,1,5,5,1,1,1,1,1,1,1,1
1,1,1,1,1,1,1,1,1,1,1,1,1,1,1,1,1,1,1
1,1,1,1,1,1,1,1,1,1,1,1,1,1,1,1,1,1,1
1,1,1,1,1,1,1,1,1,1,1,1,1,1,1,1,1,1,1
1,1,1,1,1,1,1,1,1,1,1,1,1,1,1,1,1,1,1
1,1,1,1,1,1,1,1,1,1,1,1,1,1,1,1,1,1,1
1,1,1,1,1,1,1,1,1,1,1,1,1,1,1,1,1,1,1
1,1,1,1,1,1,1,1,1,1,1,1,1,1,1,1,1,1,1
1,1,1,1,1,1,1,1,1,1,1,1,1,1,1,1,1,1,1
1,1,1,1,1,1,1,1,1,1,1,1,1,1,1,1,1,1,1
1,1,1,1,1,1,1,1,1,1,1,1,1,1,1,1,1,1,1
1,1,1,1,1,1,1,1,1,1,1,1,1,1,1,1,1,1,1
1,1,1,1,1,1,1,1,1,1,1,1,1,1,1,1,1,1,1
1,1,1,1,1,1,1,1,1,1,1,1,1,1,1,1,1,1,1
1,1,1,1,1,1,1,1,1,1,1,1,1,1,1,1,1,1,1
1,1,1,1,1,1,1,1,1,1,1,1,1,1,1,1,1,1,1
1,1,1,1,1,1,1,1,1,1,1,1,1,1,1,1,1,1,1
1,1,1,1,1,1,1,1,1,1,1,1,1,1,1,1,1,1,1
1,1,1,1,1,1,1,1,1,1,1,1,1,1,1,1,1,1,1
1,1,1,1,1,1,1,1,1,1,1,1,1,1,1,1,1,1,1
1,1,1,1,1,1,1,1,1,1,1,1,1,1,1,1,1,1,1
1,1,1,1,1,1,1,1,1,1,1,1,1,1,1,1,1,1,1
1,1,1,1,1,1,1,1,1,1,1,1,1,1,1,1,1,1,1
1,1,1,1,1,1,1,1,1,1,1,1,1,1,1,1,1,1,1
endlayer

layer
0,0,0,0,0,0,0,0,0,0,0,0,0,0,0,0,0,0,0
0,0,0,0,0,0,0,0,0,0,0,0,0,0,0,0,0,0,0
0,0,0,0,0,0,0,0,0,0,0,0,0,0,0,0,0,0,0
0,0,0,0,0,0,0,0,0,0,0,0,0,0,0,47,0,0,0
0,0,0,0,0,0,0,0,0,0,0,0,0,0,0,0,0,0,0
0,0,0,0,0,0,0,0,0,0,0,0,0,0,0,0,0,0,0
0,0,0,0,0,0,0,0,0,0,0,0,47,0,0,0,0,0,0
0,0,0,0,0,0,0,0,0,0,0,47,0,0,0,0,0,0,0
0,0,0,0,0,0,0,0,0,0,0,0,0,0,0,0,0,0,0
0,0,0,0,0,0,0,0,0,0,48,47,0,0,0,0,0,0,0
0,0,0,0,0,0,0,0,0,0,0,27,0,0,0,0,0,0,0
0,0,0,0,0,0,0,0,0,0,49,0,0,0,0,0,0,0,0
0,0,0,0,0,0,0,0,0,0,0,47,0,0,0,0,0,0,0
0,0,0,0,0,0,0,0,0,0,0,0,47,0,0,0,0,0,0
0,0,0,0,0,0,0,0,0,0,0,0,0,0,0,0,0,0,0
0,0,0,0,0,0,0,0,0,0,0,0,0,0,0,0,0,0,0
0,0,0,0,0,0,0,0,0,0,0,0,0,0,0,0,0,0,0
0,0,0,0,0,0,0,0,0,0,0,0,0,0,0,0,0,0,0
0,0,0,0,0,0,0,0,0,0,0,0,0,0,0,0,0,0,0
0,0,0,0,0,0,0,0,0,0,0,0,0,0,0,0,0,0,0
0,0,0,0,0,0,0,0,0,0,0,0,0,0,0,0,0,0,0
0,0,0,0,0,0,0,0,0,0,0,0,0,0,0,0,0,0,0
0,0,0,0,0,0,0,0,0,0,0,0,0,0,0,0,0,0,0
0,0,0,0,0,0,0,0,0,0,0,0,0,0,0,0,0,0,0
0,0,0,0,0,0,0,0,0,0,0,0,0,0,0,0,0,0,0
0,0,0,0,0,0,0,0,0,0,0,0,0,0,0,0,0,0,0
0,0,0,0,0,0,0,0,0,0,0,0,0,0,0,0,0,0,0
0,0,0,0,0,0,0,0,0,0,0,0,0,0,0,0,0,0,0
0,0,0,0,0,0,0,0,0,0,0,0,0,0,0,0,0,0,0
0,0,0,0,0,0,0,0,0,0,0,0,0,0,0,0,0,0,0
0,0,0,0,0,0,0,0,0,0,0,0,0,0,0,0,0,0,0
0,0,0,0,0,0,0,0,0,0,0,0,0,0,0,0,0,0,0
0,0,0,0,0,0,0,0,0,0,0,0,0,0,0,0,0,0,0
0,0,0,0,0,0,0,0,0,0,0,0,0,0,0,0,0,0,0
0,0,0,0,0,0,0,0,0,0,0,0,0,0,0,0,0,0,0
0,0,0,0,0,0,0,0,0,0,0,0,0,0,0,0,0,0,0
0,0,0,0,0,0,0,0,0,0,0,0,0,0,0,0,0,0,0
0,0,0,0,0,0,0,0,0,0,0,0,0,0,0,0,0,0,0
0,0,0,0,0,0,0,0,0,0,0,0,0,0,0,0,0,0,0
endlayer

layer
0,0,0,0,0,0,0,0,0,0,0,0,0,0,0,0,0,0,0
0,0,0,0,0,0,0,0,0,0,0,0,0,0,0,0,0,0,0
0,0,0,0,0,0,0,0,0,0,0,0,0,0,0,0,0,0,0
0,0,0,0,0,0,0,0,0,0,0,0,0,0,0,0,0,0,0
0,0,0,0,0,0,0,0,0,0,0,0,0,0,0,0,0,0,0
0,0,0,0,0,0,0,0,0,0,0,0,0,0,0,0,0,0,0
0,0,0,0,0,0,0,0,0,0,0,0,0,0,0,0,0,0,0
0,0,0,0,0,0,0,0,0,0,0,0,0,0,0,0,0,0,0
0,0,0,0,0,0,0,0,0,0,0,0,0,0,0,0,0,0,0
0,0,0,0,0,0,0,0,0,0,35,0,0,0,0,0,0,0,0
0,0,0,0,0,0,0,0,0,0,0,27,0,0,0,0,0,0,0
0,0,0,0,0,0,0,0,0,0,50,0,0,0,0,0,0,0,0
0,0,0,0,0,0,0,0,0,0,0,0,0,0,0,0,0,0,0
0,0,0,0,0,0,0,0,0,0,0,0,0,0,0,0,0,0,0
0,0,0,0,0,0,0,0,0,0,0,0,0,0,0,0,0,0,0
0,0,0,0,0,0,0,0,0,0,0,0,0,0,0,0,0,0,0
0,0,0,0,0,0,0,0,0,0,0,0,0,0,0,0,0,0,0
0,0,0,0,0,0,0,0,0,0,0,0,0,0,0,0,0,0,0
0,0,0,0,0,0,0,0,0,0,0,0,0,0,0,0,0,0,0
0,0,0,0,0,0,0,0,0,0,0,0,0,0,0,0,0,0,0
0,0,0,0,0,0,0,0,0,0,0,0,0,0,0,0,0,0,0
0,0,0,0,0,0,0,0,0,0,0,0,0,0,0,0,0,0,0
0,0,0,0,0,0,0,0,0,0,0,0,0,0,0,0,0,0,0
0,0,0,0,0,0,0,0,0,0,0,0,0,0,0,0,0,0,0
0,0,0,0,0,0,0,0,0,0,0,0,0,0,0,0,0,0,0
0,0,0,0,0,0,0,0,0,0,0,0,0,0,0,0,0,0,0
0,0,0,0,0,0,0,0,0,0,0,0,0,0,0,0,0,0,0
0,0,0,0,0,0,0,0,0,0,0,0,0,0,0,0,0,0,0
0,0,0,0,0,0,0,0,0,0,0,0,0,0,0,0,0,0,0
0,0,0,0,0,0,0,0,0,0,0,0,0,0,0,0,0,0,0
0,0,0,0,0,0,0,0,0,0,0,0,0,0,0,0,0,0,0
0,0,0,0,0,0,0,0,0,0,0,0,0,0,0,0,0,0,0
0,0,0,0,0,0,0,0,0,0,0,0,0,0,0,0,0,0,0
0,0,0,0,0,0,0,0,0,0,0,0,0,0,0,0,0,0,0
0,0,0,0,0,0,0,0,0,0,0,0,0,0,0,0,0,0,0
0,0,0,0,0,0,0,0,0,0,0,0,0,0,0,0,0,0,0
0,0,0,0,0,0,0,0,0,0,0,0,0,0,0,0,0,0,0
0,0,0,0,0,0,0,0,0,0,0,0,0,0,0,0,0,0,0
0,0,0,0,0,0,0,0,0,0,0,0,0,0,0,0,0,0,0
endlayer

layer
0,0,0,0,0,0,0,0,0,0,0,0,0,0,0,0,0,0,0
0,0,0,0,0,0,0,0,0,0,0,0,0,0,0,0,0,0,0
0,0,0,0,0,0,0,0,0,0,0,0,0,0,0,0,0,0,0
0,0,0,0,0,0,0,0,0,0,0,0,0,0,0,0,0,0,0
0,0,0,0,0,0,0,0,0,0,0,0,0,0,0,0,0,0,0
0,0,0,0,0,0,0,0,0,0,0,0,0,0,0,0,0,0,0
0,0,0,0,0,0,0,0,0,0,0,0,0,0,0,0,0,0,0
0,0,0,0,0,0,0,0,0,0,0,0,0,0,0,0,0,0,0
0,0,0,0,0,0,0,0,0,0,0,0,0,0,0,0,0,0,0
0,0,0,0,0,0,0,0,0,0,35,0,0,0,0,0,0,0,0
0,0,0,0,0,0,0,0,0,0,0,27,44,0,0,0,0,0,0
0,0,0,0,0,0,0,0,0,0,35,0,0,0,0,0,0,0,0
0,0,0,0,0,0,0,0,0,0,0,0,0,0,0,0,0,0,0
0,0,0,0,0,0,0,0,0,0,0,0,0,0,0,0,0,0,0
0,0,0,0,0,0,0,0,0,0,0,0,0,0,0,0,0,0,0
0,0,0,0,0,0,0,0,0,0,0,0,0,0,0,0,0,0,0
0,0,0,0,0,0,0,0,0,0,0,0,0,0,0,0,0,0,0
0,0,0,0,0,0,0,0,0,0,0,0,0,0,0,0,0,0,0
0,0,0,0,0,0,0,0,0,0,0,0,0,0,0,0,0,0,0
0,0,0,0,0,0,0,0,0,0,0,0,0,0,0,0,0,0,0
0,0,0,0,0,0,0,0,0,0,0,0,0,0,0,0,0,0,0
0,0,0,0,0,0,0,0,0,0,0,0,0,0,0,0,0,0,0
0,0,0,0,0,0,0,0,0,0,0,0,0,0,0,0,0,0,0
0,0,0,0,0,0,0,0,0,0,0,0,0,0,0,0,0,0,0
0,0,0,0,0,0,0,0,0,0,0,0,0,0,0,0,0,0,0
0,0,0,0,0,0,0,0,0,0,0,0,0,0,0,0,0,0,0
0,0,0,0,0,0,0,0,0,0,0,0,0,0,0,0,0,0,0
0,0,0,0,0,0,0,0,0,0,0,0,0,0,0,0,0,0,0
0,0,0,0,0,0,0,0,0,0,0,0,0,0,0,0,0,0,0
0,0,0,0,0,0,0,0,0,0,0,0,0,0,0,0,0,0,0
0,0,0,0,0,0,0,0,0,0,0,0,0,0,0,0,0,0,0
0,0,0,0,0,0,0,0,0,0,0,0,0,0,0,0,0,0,0
0,0,0,0,0,0,0,0,0,0,0,0,0,0,0,0,0,0,0
0,0,0,0,0,0,0,0,0,0,0,0,0,0,0,0,0,0,0
0,0,0,0,0,0,0,0,0,0,0,0,0,0,0,0,0,0,0
0,0,0,0,0,0,0,0,0,0,0,0,0,0,0,0,0,0,0
0,0,0,0,0,0,0,0,0,0,0,0,0,0,0,0,0,0,0
0,0,0,0,0,0,0,0,0,0,0,0,0,0,0,0,0,0,0
0,0,0,0,0,0,0,0,0,0,0,0,0,0,0,0,0,0,0
endlayer

layer
0,0,0,0,0,0,0,0,0,0,0,0,0,0,0,0,0,0,0
0,0,0,0,0,0,0,0,0,0,0,0,0,0,0,0,0,0,0
0,0,0,0,0,0,0,0,0,0,0,0,0,0,0,0,0,0,0
0,0,0,0,0,0,0,0,0,0,0,0,0,0,0,0,0,0,0
0,0,0,0,0,0,0,0,0,0,0,0,0,0,0,0,0,0,0
0,0,0,0,0,0,0,0,0,0,0,0,0,0,0,0,0,0,0
0,0,0,0,0,0,0,0,0,0,0,0,0,0,0,0,0,0,0
0,0,0,0,0,0,0,0,0,0,0,0,0,0,0,0,0,0,0
0,0,0,0,0,0,0,0,0,0,0,0,0,0,0,0,0,0,0
0,0,0,0,0,0,0,0,0,0,35,0,51,0,0,0,0,0,0
0,0,0,0,0,0,0,0,0,0,0,27,51,51,0,0,0,0,0
0,0,0,0,0,0,0,0,0,0,35,52,0,0,0,0,0,0,0
0,0,0,0,0,0,0,0,0,0,0,53,0,0,0,0,0,0,0
0,0,0,0,0,0,0,0,0,0,0,0,0,0,0,0,0,0,0
0,0,0,0,0,0,0,0,0,0,0,0,0,0,0,0,0,0,0
0,0,0,0,0,0,0,0,0,0,0,0,0,0,0,0,0,0,0
0,0,0,0,0,0,0,0,0,0,0,0,0,0,0,0,0,0,0
0,0,0,0,0,0,0,0,0,0,0,0,0,0,0,0,0,0,0
0,0,0,0,0,0,0,0,0,0,0,0,0,0,0,0,0,0,0
0,0,0,0,0,0,0,0,0,0,0,0,0,0,0,0,0,0,0
0,0,0,0,0,0,0,0,0,0,0,0,0,0,0,0,0,0,0
0,0,0,0,0,0,0,0,0,0,0,0,0,0,0,0,0,0,0
0,0,0,0,0,0,0,0,0,0,0,0,0,0,0,0,0,0,0
0,0,0,0,0,0,0,0,0,0,0,0,0,0,0,0,0,0,0
0,0,0,0,0,0,0,0,0,0,0,0,0,0,0,0,0,0,0
0,0,0,0,0,0,0,0,0,0,0,0,0,0,0,0,0,0,0
0,0,0,0,0,0,0,0,0,0,0,0,0,0,0,0,0,0,0
0,0,0,0,0,0,0,0,0,0,0,0,0,0,0,0,0,0,0
0,0,0,0,0,0,0,0,0,0,0,0,0,0,0,0,0,0,0
0,0,0,0,0,0,0,0,0,0,0,0,0,0,0,0,0,0,0
0,0,0,0,0,0,0,0,0,0,0,0,0,0,0,0,0,0,0
0,0,0,0,0,0,0,0,0,0,0,0,0,0,0,0,0,0,0
0,0,0,0,0,0,0,0,0,0,0,0,0,0,0,0,0,0,0
0,0,0,0,0,0,0,0,0,0,0,0,0,0,0,0,0,0,0
0,0,0,0,0,0,0,0,0,0,0,0,0,0,0,0,0,0,0
0,0,0,0,0,0,0,0,0,0,0,0,0,0,0,0,0,0,0
0,0,0,0,0,0,0,0,0,0,0,0,0,0,0,0,0,0,0
0,0,0,0,0,0,0,0,0,0,0,0,0,0,0,0,0,0,0
0,0,0,0,0,0,0,0,0,0,0,0,0,0,0,0,0,0,0
endlayer

layer
0,0,0,0,0,0,0,0,0,0,0,0,0,0,0,0,0,0,0
0,0,0,0,0,0,0,0,0,0,0,0,0,0,0,0,0,0,0
0,0,0,0,0,0,0,0,0,0,0,0,0,0,0,0,0,0,0
0,0,0,0,0,0,0,0,0,0,0,0,0,0,0,0,0,0,0
0,0,0,0,0,0,0,0,0,0,0,0,0,0,0,0,0,0,0
0,0,0,0,0,0,0,0,0,0,0,0,0,0,0,0,0,0,0
0,0,0,0,0,0,0,0,0,0,0,0,0,0,0,0,0,0,0
0,0,0,0,0,0,0,0,0,0,0,0,0,0,0,0,0,0,0
0,0,0,0,0,0,0,0,0,0,0,0,0,0,0,0,0,0,0
0,0,0,0,0,0,0,0,0,53,51,0,0,0,0,0,0,0,0
0,0,0,0,0,0,0,0,0,53,44,27,51,0,0,0,0,0,0
0,0,0,0,0,0,0,0,0,0,53,53,53,0,0,0,0,0,0
0,0,0,0,0,0,0,0,0,0,0,0,0,0,0,0,0,0,0
0,0,0,0,0,0,0,0,0,0,0,0,0,0,0,0,0,0,0
0,0,0,0,0,0,0,0,0,0,0,0,0,0,0,0,0,0,0
0,0,0,0,0,0,0,0,0,0,0,0,0,0,0,0,0,0,0
0,0,0,0,0,0,0,0,0,0,0,0,0,0,0,0,0,0,0
0,0,0,0,0,0,0,0,0,0,0,0,0,0,0,0,0,0,0
0,0,0,0,0,0,0,0,0,0,0,0,0,0,0,0,0,0,0
0,0,0,0,0,0,0,0,0,0,0,0,0,0,0,0,0,0,0
0,0,0,0,0,0,0,0,0,0,0,0,0,0,0,0,0,0,0
0,0,0,0,0,0,0,0,0,0,0,0,0,0,0,0,0,0,0
0,0,0,0,0,0,0,0,0,0,0,0,0,0,0,0,0,0,0
0,0,0,0,0,0,0,0,0,0,0,0,0,0,0,0,0,0,0
0,0,0,0,0,0,0,0,0,0,0,0,0,0,0,0,0,0,0
0,0,0,0,0,0,0,0,0,0,0,0,0,0,0,0,0,0,0
0,0,0,0,0,0,0,0,0,0,0,0,0,0,0,0,0,0,0
0,0,0,0,0,0,0,0,0,0,0,0,0,0,0,0,0,0,0
0,0,0,0,0,0,0,0,0,0,0,0,0,0,0,0,0,0,0
0,0,0,0,0,0,0,0,0,0,0,0,0,0,0,0,0,0,0
0,0,0,0,0,0,0,0,0,0,0,0,0,0,0,0,0,0,0
0,0,0,0,0,0,0,0,0,0,0,0,0,0,0,0,0,0,0
0,0,0,0,0,0,0,0,0,0,0,0,0,0,0,0,0,0,0
0,0,0,0,0,0,0,0,0,0,0,0,0,0,0,0,0,0,0
0,0,0,0,0,0,0,0,0,0,0,0,0,0,0,0,0,0,0
0,0,0,0,0,0,0,0,0,0,0,0,0,0,0,0,0,0,0
0,0,0,0,0,0,0,0,0,0,0,0,0,0,0,0,0,0,0
0,0,0,0,0,0,0,0,0,0,0,0,0,0,0,0,0,0,0
0,0,0,0,0,0,0,0,0,0,0,0,0,0,0,0,0,0,0
endlayer

layer
0,0,0,0,0,0,0,0,0,0,0,0,0,0,0,0,0,0,0
0,0,0,0,0,0,0,0,0,0,0,0,0,0,0,0,0,0,0
0,0,0,0,0,0,0,0,0,0,0,0,0,0,0,0,0,0,0
0,0,0,0,0,0,0,0,0,0,0,0,0,0,0,0,0,0,0
0,0,0,0,0,0,0,0,0,0,0,0,0,0,0,0,0,0,0
0,0,0,0,0,0,0,0,0,0,0,0,0,0,0,0,0,0,0
0,0,0,0,0,0,0,0,0,0,0,0,0,0,0,0,0,0,0
0,0,0,0,0,0,0,0,0,0,0,0,0,0,0,0,0,0,0
0,0,0,0,0,0,0,0,0,0,0,0,0,0,0,0,0,0,0
0,0,0,0,0,0,0,0,0,0,0,51,0,0,0,0,0,0,0
0,0,0,0,0,0,0,0,0,53,51,27,51,0,0,0,0,0,0
0,0,0,0,0,0,0,0,0,0,53,0,53,0,0,0,0,0,0
0,0,0,0,0,0,0,0,0,0,0,0,0,0,0,0,0,0,0
0,0,0,0,0,0,0,0,0,0,0,0,0,0,0,0,0,0,0
0,0,0,0,0,0,0,0,0,0,0,0,0,0,0,0,0,0,0
0,0,0,0,0,0,0,0,0,0,0,0,0,0,0,0,0,0,0
0,0,0,0,0,0,0,0,0,0,0,0,0,0,0,0,0,0,0
0,0,0,0,0,0,0,0,0,0,0,0,0,0,0,0,0,0,0
0,0,0,0,0,0,0,0,0,0,0,0,0,0,0,0,0,0,0
0,0,0,0,0,0,0,0,0,0,0,0,0,0,0,0,0,0,0
0,0,0,0,0,0,0,0,0,0,0,0,0,0,0,0,0,0,0
0,0,0,0,0,0,0,0,0,0,0,0,0,0,0,0,0,0,0
0,0,0,0,0,0,0,0,0,0,0,0,0,0,0,0,0,0,0
0,0,0,0,0,0,0,0,0,0,0,0,0,0,0,0,0,0,0
0,0,0,0,0,0,0,0,0,0,0,0,0,0,0,0,0,0,0
0,0,0,0,0,0,0,0,0,0,0,0,0,0,0,0,0,0,0
0,0,0,0,0,0,0,0,0,0,0,0,0,0,0,0,0,0,0
0,0,0,0,0,0,0,0,0,0,0,0,0,0,0,0,0,0,0
0,0,0,0,0,0,0,0,0,0,0,0,0,0,0,0,0,0,0
0,0,0,0,0,0,0,0,0,0,0,0,0,0,0,0,0,0,0
0,0,0,0,0,0,0,0,0,0,0,0,0,0,0,0,0,0,0
0,0,0,0,0,0,0,0,0,0,0,0,0,0,0,0,0,0,0
0,0,0,0,0,0,0,0,0,0,0,0,0,0,0,0,0,0,0
0,0,0,0,0,0,0,0,0,0,0,0,0,0,0,0,0,0,0
0,0,0,0,0,0,0,0,0,0,0,0,0,0,0,0,0,0,0
0,0,0,0,0,0,0,0,0,0,0,0,0,0,0,0,0,0,0
0,0,0,0,0,0,0,0,0,0,0,0,0,0,0,0,0,0,0
0,0,0,0,0,0,0,0,0,0,0,0,0,0,0,0,0,0,0
0,0,0,0,0,0,0,0,0,0,0,0,0,0,0,0,0,0,0
endlayer

layer
0,0,0,0,0,0,0,0,0,0,0,0,0,0,0,0,0,0,0
0,0,0,0,0,0,0,0,0,0,0,0,0,0,0,0,0,0,0
0,0,0,0,0,0,0,0,0,0,0,0,0,0,0,0,0,0,0
0,0,0,0,0,0,0,0,0,0,0,0,0,0,0,0,0,0,0
0,0,0,0,0,0,0,0,0,0,0,0,0,0,0,0,0,0,0
0,0,0,0,0,0,0,0,0,0,0,0,0,0,0,0,0,0,0
0,0,0,0,0,0,0,0,0,0,0,0,0,0,0,0,0,0,0
0,0,0,0,0,0,0,0,0,0,0,0,0,0,0,0,0,0,0
0,0,0,0,0,0,0,0,0,0,0,0,0,0,0,0,0,0,0
0,0,0,0,0,0,0,0,0,0,0,0,0,0,0,0,0,0,0
0,0,0,0,0,0,0,0,0,0,0,53,0,0,0,0,0,0,0
0,0,0,0,0,0,0,0,0,0,0,0,0,0,0,0,0,0,0
0,0,0,0,0,0,0,0,0,0,0,0,0,0,0,0,0,0,0
0,0,0,0,0,0,0,0,0,0,0,0,0,0,0,0,0,0,0
0,0,0,0,0,0,0,0,0,0,0,0,0,0,0,0,0,0,0
0,0,0,0,0,0,0,0,0,0,0,0,0,0,0,0,0,0,0
0,0,0,0,0,0,0,0,0,0,0,0,0,0,0,0,0,0,0
0,0,0,0,0,0,0,0,0,0,0,0,0,0,0,0,0,0,0
0,0,0,0,0,0,0,0,0,0,0,0,0,0,0,0,0,0,0
0,0,0,0,0,0,0,0,0,0,0,0,0,0,0,0,0,0,0
0,0,0,0,0,0,0,0,0,0,0,0,0,0,0,0,0,0,0
0,0,0,0,0,0,0,0,0,0,0,0,0,0,0,0,0,0,0
0,0,0,0,0,0,0,0,0,0,0,0,0,0,0,0,0,0,0
0,0,0,0,0,0,0,0,0,0,0,0,0,0,0,0,0,0,0
0,0,0,0,0,0,0,0,0,0,0,0,0,0,0,0,0,0,0
0,0,0,0,0,0,0,0,0,0,0,0,0,0,0,0,0,0,0
0,0,0,0,0,0,0,0,0,0,0,0,0,0,0,0,0,0,0
0,0,0,0,0,0,0,0,0,0,0,0,0,0,0,0,0,0,0
0,0,0,0,0,0,0,0,0,0,0,0,0,0,0,0,0,0,0
0,0,0,0,0,0,0,0,0,0,0,0,0,0,0,0,0,0,0
0,0,0,0,0,0,0,0,0,0,0,0,0,0,0,0,0,0,0
0,0,0,0,0,0,0,0,0,0,0,0,0,0,0,0,0,0,0
0,0,0,0,0,0,0,0,0,0,0,0,0,0,0,0,0,0,0
0,0,0,0,0,0,0,0,0,0,0,0,0,0,0,0,0,0,0
0,0,0,0,0,0,0,0,0,0,0,0,0,0,0,0,0,0,0
0,0,0,0,0,0,0,0,0,0,0,0,0,0,0,0,0,0,0
0,0,0,0,0,0,0,0,0,0,0,0,0,0,0,0,0,0,0
0,0,0,0,0,0,0,0,0,0,0,0,0,0,0,0,0,0,0
0,0,0,0,0,0,0,0,0,0,0,0,0,0,0,0,0,0,0
endlayer

