
# Created by Ruins mod version 15.0 Ingame Parser
# authoring Player: SunsOfOld

weight=100
embed_into_distance=2
acceptable_target_blocks=
unacceptable_target_blocks=flowing_water,water,flowing_lava,lava
dimensions=7,7,7
allowable_overhang=0
max_leveling=4
leveling_buffer=0
preserve_water=0
preserve_lava=0
uniqueMinDistance=1000000
preventRotation=1

rule1=0,100,preserveBlock
rule2=0,100,chisel:glowstone-4
rule3=0,100,IInventory;minecraft:chest;chisel:cloudinabottle#1#0#11+chisel:diamondChisel#{RepairCost:2,ench:[0:{id:34s,lvl:3s,},],}#0#13+chisel:cloudinabottle#1#0#15-5
rule4=0,100,chisel:mossy_cobblestone-15
rule5=0,100,chisel:stained_glass_yellow-4
rule6=0,100,chisel:mossy_cobblestone-13
rule7=0,100,chisel:mossy_cobblestone-11

layer
1,1,1,1,1,1,1
1,1,1,1,1,1,1
1,1,2,1,2,1,1
1,1,1,3,1,1,1
1,1,2,1,2,1,1
1,1,1,1,1,1,1
1,1,1,1,1,1,1
endlayer

layer
1,1,1,4,1,1,1
1,4,4,4,4,4,1
1,4,5,6,5,4,1
4,4,6,7,6,4,4
1,4,5,6,5,4,1
1,4,4,4,4,4,1
1,1,1,4,1,1,1
endlayer

layer
0,0,0,4,0,0,0
0,4,0,0,0,4,0
0,0,0,0,0,0,0
4,0,0,0,0,0,4
0,0,0,0,0,0,0
0,4,0,0,0,4,0
0,0,0,4,0,0,0
endlayer

layer
0,0,0,4,0,0,0
0,4,0,0,0,4,0
0,0,0,0,0,0,0
4,0,0,0,0,0,4
0,0,0,0,0,0,0
0,4,0,0,0,4,0
0,0,0,4,0,0,0
endlayer

layer
0,0,0,4,0,0,0
0,4,0,0,0,4,0
0,0,0,0,0,0,0
4,0,0,0,0,0,4
0,0,0,0,0,0,0
0,4,0,0,0,4,0
0,0,0,4,0,0,0
endlayer

layer
0,0,0,0,0,0,0
0,4,0,0,0,4,0
0,0,0,0,0,0,0
4,0,0,0,0,0,4
0,0,0,0,0,0,0
0,4,0,0,0,0,0
0,0,0,4,0,0,0
endlayer

layer
0,0,0,0,0,0,0
0,4,0,0,0,0,0
0,0,0,0,0,0,0
0,0,0,0,0,0,0
0,0,0,0,0,0,0
0,0,0,0,0,0,0
0,0,0,4,0,0,0
endlayer

