
# Created by Ruins mod version 15.0 Ingame Parser
# authoring Player: MjrSlacker

weight=100
embed_into_distance=-50
acceptable_target_blocks=
unacceptable_target_blocks=flowing_water,water,flowing_lava,lava
dimensions=10,7,7
allowable_overhang=0
max_leveling=4
leveling_buffer=0
preserve_water=0
preserve_lava=0
uniqueMinDistance=1000000
preventRotation=1

rule1=0,100,preserveBlock
rule2=0,100,chisel:glowstone-4
rule3=0,100,chisel:cloud-0

layer
1,1,1,1,1,1,1
1,1,1,1,1,1,1
1,1,1,1,1,1,1
1,1,1,2,1,1,1
1,1,1,1,1,1,1
1,1,1,1,1,1,1
1,1,1,1,1,1,1
endlayer

layer
1,1,1,3,1,1,1
1,3,1,1,1,3,1
1,1,1,1,1,1,1
3,1,1,3,1,1,3
1,1,1,1,1,1,1
1,3,1,1,1,3,1
1,1,1,3,1,1,1
endlayer

layer
0,0,3,0,3,0,0
0,0,0,0,0,0,0
3,0,0,0,0,0,3
0,0,0,3,0,0,0
3,0,0,0,0,0,3
0,0,0,0,0,0,0
0,0,3,0,3,0,0
endlayer

layer
0,0,3,0,3,0,0
0,0,0,0,0,0,0
3,0,0,0,0,0,3
0,0,0,3,0,0,0
3,0,0,0,0,0,3
0,0,0,0,0,0,0
0,0,3,0,3,0,0
endlayer

layer
0,0,3,0,3,0,0
0,0,0,0,0,0,0
3,0,0,0,0,0,3
0,0,0,3,0,0,0
3,0,0,0,0,0,3
0,0,0,0,0,0,0
0,0,3,0,3,0,0
endlayer

layer
0,0,0,0,3,0,0
0,0,0,0,0,0,0
0,0,0,0,0,0,0
0,0,0,3,0,0,0
3,0,0,0,0,0,3
0,0,0,0,0,0,0
0,0,0,0,3,0,0
endlayer

layer
0,0,0,0,0,0,0
0,0,0,0,0,0,0
0,0,0,0,0,0,0
0,0,0,3,0,0,0
0,0,0,0,0,0,0
0,0,0,0,0,0,0
0,0,0,0,0,0,0
endlayer

layer
0,0,0,0,0,0,0
0,0,0,0,0,0,0
0,0,0,0,0,0,0
0,0,0,3,0,0,0
0,0,0,0,0,0,0
0,0,0,0,0,0,0
0,0,0,0,0,0,0
endlayer

layer
0,0,0,0,0,0,0
0,0,0,0,0,0,0
0,0,0,0,0,0,0
0,0,0,3,0,0,0
0,0,0,0,0,0,0
0,0,0,0,0,0,0
0,0,0,0,0,0,0
endlayer

layer
0,0,0,0,0,0,0
0,0,0,0,0,0,0
0,0,0,0,0,0,0
0,0,0,3,0,0,0
0,0,0,0,0,0,0
0,0,0,0,0,0,0
0,0,0,0,0,0,0
endlayer

