
# Created by Ruins mod version 15.0 Ingame Parser
# authoring Player: VikingWarlock

weight=100
embed_into_distance=19
acceptable_target_blocks=
unacceptable_target_blocks=flowing_water,water,flowing_lava,lava
dimensions=47,23,32
allowable_overhang=0
max_leveling=6
leveling_buffer=0
preserve_water=0
preserve_lava=0
uniqueMinDistance=1000000
preventRotation=1

rule1=0,100,preserveBlock
rule2=2,100,minecraft:redstone_torch-2
rule3=2,100,minecraft:redstone_torch-1
rule4=0,100,BiomesOPlenty:stoneDoubleSlab-0
rule5=0,100,chisel:glowstone-4
rule6=0,100,chisel:cobblestone-12
rule7=0,100,minecraft:stained_hardened_clay-15
rule8=0,100,chisel:glowstone-2
rule9=0,100,chisel:limestone-12
rule10=0,100,minecraft:log-1
rule11=0,100,chisel:limestone_stairs.0-1
rule12=0,100,chisel:limestone-8
rule13=0,100,chisel:limestone_stairs.0-3
rule14=0,100,chisel:limestone_stairs.0-2
rule15=0,100,BiomesOPlenty:mudBricks-0
rule16=0,100,minecraft:furnace-4
rule17=0,100,IInventory;minecraft:dispenser;minecraft:potion#1#16388#4-1
rule18=0,100,dendrology:logs2-3
rule19=0,100,IInventory;minecraft:dispenser;minecraft:potion#1#16460#4-1
rule20=0,100,minecraft:furnace-2
rule21=0,100,minecraft:log-9
rule22=0,100,minecraft:furnace-3
rule23=0,100,dendrology:logs2-11
rule24=0,100,minecraft:lit_redstone_lamp-0
rule25=0,100,IInventory;minecraft:dispenser;minecraft:potion#1#16386#4-1
rule26=0,100,chisel:lavastone-5
rule27=0,100,minecraft:furnace-5
rule28=0,100,IInventory;minecraft:dispenser;minecraft:potion#1#16424#4-1
rule29=0,100,IInventory;minecraft:dispenser;minecraft:potion#1#16421#4-1
rule30=0,100,chisel:limestone_stairs.0-0
rule31=0,100,dendrology:leaves2-7
rule32=0,100,ExtrabiomesXL:leaves_1-4
rule33=0,100,dendrology:leaves0-4
rule34=0,100,dendrology:leaves0-12
rule35=0,100,ExtrabiomesXL:leaves_1-12
rule36=0,100,dendrology:leaves2-15
rule37=0,100,minecraft:water-0
rule38=0,100,GardenTrees:thin_log_fence-1
rule39=0,100,minecraft:stone_pressure_plate-0
rule40=0,100,minecraft:dirt-0
rule41=0,100,IInventory;minecraft:chest;ExtrabiomesXL:log2#8#3#11+harvestcraft:muttoncookedItem#8#0#12+harvestcraft:muttoncookedItem#8#0#13+harvestcraft:muttoncookedItem#8#0#14+ExtrabiomesXL:log2#8#3#15+ExtrabiomesXL:log2#8#3#20+ExtrabiomesXL:saplings_1#1#5#21+minecraft:shears#{RepairCost:2,ench:[0:{id:33s,lvl:1s,},1:{id:34s,lvl:3s,},],display:{Name:"Folia Salvator",},}#0#22+ExtrabiomesXL:saplings_1#1#5#23+ExtrabiomesXL:log2#8#3#24-5
rule42=0,100,IInventory;minecraft:chest;ExtrabiomesXL:log2#8#3#2+ExtrabiomesXL:saplings_1#1#5#3+minecraft:diamond_axe#{RepairCost:2,restrictions:[0:{id:34s,lvl:0s,player:"VikingWarlock",},1:{id:34s,lvl:1s,player:"VikingWarlock",},2:{id:34s,lvl:2s,player:"VikingWarlock",},3:{id:34s,lvl:3s,player:"VikingWarlock",},4:{id:35s,lvl:0s,player:"VikingWarlock",},5:{id:35s,lvl:1s,player:"VikingWarlock",},6:{id:35s,lvl:2s,player:"VikingWarlock",},7:{id:35s,lvl:3s,player:"VikingWarlock",},8:{id:16s,lvl:0s,player:"VikingWarlock",},9:{id:16s,lvl:1s,player:"VikingWarlock",},10:{id:16s,lvl:2s,player:"VikingWarlock",},11:{id:16s,lvl:3s,player:"VikingWarlock",},12:{id:16s,lvl:4s,player:"VikingWarlock",},13:{id:16s,lvl:5s,player:"VikingWarlock",},14:{id:32s,lvl:0s,player:"VikingWarlock",},15:{id:32s,lvl:1s,player:"VikingWarlock",},16:{id:32s,lvl:2s,player:"VikingWarlock",},17:{id:32s,lvl:3s,player:"VikingWarlock",},18:{id:32s,lvl:4s,player:"VikingWarlock",},19:{id:32s,lvl:5s,player:"VikingWarlock",},],ench:[0:{id:34s,lvl:3s,},1:{id:35s,lvl:3s,},2:{id:16s,lvl:5s,},3:{id:32s,lvl:5s,},],display:{Name:"Magnanimous Edge",},}#0#4+ExtrabiomesXL:saplings_1#1#5#5+ExtrabiomesXL:log2#8#3#6+ExtrabiomesXL:log2#8#3#11+harvestcraft:muttoncookedItem#8#0#12+harvestcraft:muttoncookedItem#8#0#13+harvestcraft:muttoncookedItem#8#0#14+ExtrabiomesXL:log2#8#3#15-5
rule43=0,100,chisel:limestone_stairs.0-6
rule44=0,100,chisel:limestone_stairs.0-7
rule45=0,100,ExtrabiomesXL:leaves_1-13
rule46=0,100,ExtrabiomesXL:leaves_1-5
rule47=0,100,chisel:limestone_stairs.0-4
rule48=0,100,chisel:limestone_stairs.0-5
rule49=0,100,chisel:limestone-0
rule50=1,100,minecraft:redstone_torch-5
rule51=0,100,minecraft:stone_brick_stairs-5
rule52=0,100,minecraft:stone_brick_stairs-7
rule53=0,100,minecraft:stone_brick_stairs-6
rule54=0,100,minecraft:stone_brick_stairs-4
rule55=0,100,minecraft:log-5
rule56=0,100,minecraft:grass-0
rule57=0,100,ExtrabiomesXL:leaves_1-14
rule58=0,100,BiomesOPlenty:leaves4-4
rule59=0,100,BiomesOPlenty:leaves4-12
rule60=0,100,minecraft:tallgrass-1
rule61=0,100,minecraft:red_flower-0
rule62=0,100,plantmegapack:vineFlowersWhite-2
rule63=0,100,plantmegapack:vineFlowersWhite-1
rule64=0,100,minecraft:double_plant-2
rule65=0,100,plantmegapack:vineFlowersWhite-15
rule66=0,100,minecraft:red_flower-2
rule67=0,100,BiomesOPlenty:flowerVine-8
rule68=0,100,BiomesOPlenty:flowerVine-4
rule69=0,100,BiomesOPlenty:flowerVine-15
rule70=0,100,ExtrabiomesXL:flower1-7
rule71=0,100,plantmegapack:vineFlowersWhite-8
rule72=0,100,GardenTrees:thin_log-1
rule73=0,100,minecraft:stone_brick_stairs-0
rule74=0,100,BiomesOPlenty:flowerVine-3
rule75=0,100,ExtrabiomesXL:log2-1
rule76=0,100,minecraft:stone_brick_stairs-2
rule77=0,100,IInventory;minecraft:chest;harvestcraft:bellpepperseedItem#1#0#0+minecraft:dye#14#15#1+minecraft:dye#14#15#3+minecraft:dye#30#15#5+harvestcraft:bellpepperseedItem#1#0#8+ExtrabiomesXL:extrabiomes.logturner#1#0#11+plantmegapack:flowerRose#1#2#13+minecraft:dye#2#15#15+minecraft:dye#1#15#18+harvestcraft:bellpepperseedItem#1#0#22+minecraft:dye#1#15#24+minecraft:dye#1#15#25+minecraft:dye#1#15#26-3
rule78=0,100,ExtrabiomesXL:flower2-15
rule79=0,100,minecraft:stone_brick_stairs-1
rule80=0,100,BiomesOPlenty:flowerVine-1
rule81=0,100,plantmegapack:vineFlowersWhite-4
rule82=0,100,BiomesOPlenty:flowerVine-2
rule83=0,100,ExtrabiomesXL:flower3-2
rule84=0,100,BiomesOPlenty:flowerVine-7
rule85=0,100,minecraft:yellow_flower-0
rule86=0,100,minecraft:double_plant-8
rule87=0,100,BiomesOPlenty:flowerVine-0
rule88=0,100,ExtrabiomesXL:leaves_1-2
rule89=0,100,ExtrabiomesXL:leaves_1-0
rule90=0,100,BiblioCraft:BiblioIronLantern-15
rule91=0,100,ExtrabiomesXL:log2-5
rule92=0,100,chisel:cobblestone-1
rule93=0,100,ExtrabiomesXL:leaves_1-10
rule94=0,100,ExtrabiomesXL:leaves_1-8
rule95=0,100,plantmegapack:vineFlowersWhite-0
rule96=0,100,minecraft:stone_brick_stairs-3
rule97=0,100,chisel:dirt-7
rule98=0,100,minecraft:dispenser-1
rule99=0,100,IInventory;minecraft:dispenser;minecraft:spider_eye#1#0#4-1
rule100=0,100,ExtrabiomesXL:flower2-13
rule101=0,100,ExtrabiomesXL:flower3-12
rule102=0,100,ExtrabiomesXL:flower1-2
rule103=0,100,ExtrabiomesXL:flower3-7
rule104=0,100,ExtrabiomesXL:flower3-3
rule105=2,100,minecraft:torch-1
rule106=0,100,IInventory;minecraft:chest;Backpack:tannedLeather#1#0#0+minecraft:rotten_flesh#1#0#2+Backpack:tannedLeather#1#0#8+Backpack:tannedLeather#1#0#18+Backpack:tannedLeather#1#0#23-3
rule107=0,100,IInventory;minecraft:chest;minecraft:leather#1#0#8+minecraft:leather#1#0#18+Backpack:tannedLeather#1#0#19+Backpack:tannedLeather#1#0#23+Backpack:tannedLeather#1#0#26-3
rule108=0,100,ExtrabiomesXL:flower2-0
rule109=0,100,ExtrabiomesXL:flower3-0
rule110=0,100,BiomesOPlenty:mudBricksStairs-3
rule111=0,100,ExtrabiomesXL:flower2-4
rule112=0,100,IInventory;minecraft:chest;ExtrabiomesXL:flower3#1#7#1+chisel:obsidianChisel#1#0#15+minecraft:sapling#1#3#19+minecraft:sapling#1#1#26-3
rule113=0,100,IInventory;minecraft:chest;harvestcraft:hardenedleatherchestItem#1#0#10+ExtrabiomesXL:flower3#1#7#25-3
rule114=2,100,minecraft:torch-2
rule115=0,100,ExtrabiomesXL:flower2-11
rule116=0,100,ExtrabiomesXL:flower2-3
rule117=0,100,ExtrabiomesXL:flower2-6
rule118=0,100,chisel:limestone-11
rule119=2,100,minecraft:torch-3
rule120=0,100,BiomesOPlenty:mudBricksStairs-4
rule121=0,100,BiomesOPlenty:mudBricksStairs-5
rule122=0,100,minecraft:stone_slab-5
rule123=0,100,dendrology:logs2-7
rule124=0,100,dendrology:logs0-0
rule125=1,100,minecraft:torch-5
rule126=0,100,plantmegapack:jungleLazarusBell-0
rule127=0,100,dendrology:logs0-8
rule128=0,100,BiomesOPlenty:colorizedLeaves2-7
rule129=0,100,BiomesOPlenty:colorizedLeaves2-15
rule130=0,100,ExtrabiomesXL:leaves_1-6
rule131=0,100,minecraft:leaves-1

layer
1,1,1,1,1,1,1,1,1,1,1,1,1,1,1,1,1,1,1,1,1,1,1,1,1,1,1,1,1,1,1,1
1,1,1,1,1,1,1,1,1,1,1,1,1,1,1,1,1,1,1,1,1,1,1,1,1,1,1,1,1,1,1,1
1,1,1,1,1,1,1,1,1,1,1,1,1,1,1,1,1,1,1,1,1,1,1,1,1,1,1,1,1,1,1,1
1,1,1,1,1,1,1,1,1,1,1,1,1,1,1,1,1,1,1,1,1,1,1,1,1,1,1,1,1,1,1,1
1,1,1,1,1,1,1,1,1,1,1,1,1,1,1,1,1,1,1,1,1,1,1,1,1,1,1,1,1,1,1,1
1,1,1,1,1,1,1,1,1,1,1,1,1,1,1,1,1,1,1,1,1,1,1,1,1,1,1,1,1,1,1,1
1,1,1,1,1,1,1,1,1,1,1,1,1,1,1,1,1,1,1,1,1,1,1,1,1,1,1,1,1,1,1,1
1,1,1,1,1,1,1,1,1,1,1,1,1,1,1,1,1,1,1,1,1,1,1,1,1,1,1,1,1,1,1,1
1,1,1,1,1,1,1,1,1,1,1,1,1,1,1,1,1,1,1,1,1,1,1,1,1,1,1,1,1,1,1,1
1,1,1,1,1,1,1,1,1,1,1,1,1,1,1,1,1,1,1,1,1,1,1,1,1,1,1,1,1,1,1,1
1,1,1,1,1,1,1,1,1,1,1,1,1,1,1,1,1,1,1,1,1,1,1,1,1,1,1,1,1,1,1,1
1,1,1,3,1,1,1,1,1,1,1,1,1,1,1,1,1,1,1,1,1,1,1,1,1,1,1,1,2,1,1,1
1,1,1,1,1,1,1,1,1,1,1,1,1,1,1,1,1,1,1,1,1,1,1,1,1,1,1,1,1,1,1,1
1,1,1,1,1,1,1,1,1,1,1,1,1,1,1,1,1,1,1,1,1,1,1,1,1,1,1,1,1,1,1,1
1,1,1,1,1,1,1,1,1,1,1,1,1,1,1,1,1,1,1,1,1,1,1,1,1,1,1,1,1,1,1,1
1,1,1,1,1,1,1,1,1,1,1,1,1,1,1,1,1,1,1,1,1,1,1,1,1,1,1,1,1,1,1,1
1,1,1,1,1,1,1,1,1,1,1,1,1,1,1,1,1,1,1,1,1,1,1,1,1,1,1,1,1,1,1,1
1,1,1,1,1,1,1,1,1,1,1,1,1,1,1,1,1,1,1,1,1,1,1,1,1,1,1,1,1,1,1,1
1,1,1,1,1,1,1,1,1,1,1,1,1,1,1,1,1,1,1,1,1,1,1,1,1,1,1,1,1,1,1,1
1,1,1,1,1,1,1,1,1,1,1,1,1,1,1,1,1,1,1,1,1,1,1,1,1,1,1,1,1,1,1,1
1,1,1,1,1,1,1,1,1,1,1,1,1,1,1,1,1,1,1,1,1,1,1,1,1,1,1,1,1,1,1,1
1,1,1,1,1,1,1,1,1,1,1,1,1,1,1,1,1,1,1,1,1,1,1,1,1,1,1,1,1,1,1,1
1,1,1,1,1,1,1,1,1,1,1,1,1,1,1,1,1,1,1,1,1,1,1,1,1,1,1,1,1,1,1,1
endlayer

layer
1,1,1,1,1,1,1,1,1,1,1,1,1,1,1,1,1,1,1,1,1,1,1,1,1,1,1,1,1,1,1,1
1,4,4,4,4,4,4,4,4,4,4,4,4,4,4,4,4,4,4,4,4,4,4,4,4,4,4,4,4,4,4,1
1,4,4,4,4,4,4,4,4,4,4,4,4,4,4,4,4,4,4,4,4,4,4,4,4,4,4,4,4,4,4,1
1,4,4,5,6,6,6,6,6,6,6,6,6,6,6,6,6,6,6,6,6,6,6,6,6,6,6,6,5,4,4,1
1,4,4,6,7,4,4,4,4,4,4,4,4,6,8,6,6,8,6,4,4,4,4,4,4,4,4,7,6,4,4,1
1,4,4,6,4,8,9,10,7,6,6,6,6,6,11,12,12,11,6,6,6,6,6,7,10,9,8,4,6,4,4,1
1,4,4,6,4,9,7,9,10,7,6,6,6,7,14,13,14,13,7,6,6,6,7,10,9,7,9,4,6,4,4,1
1,4,4,6,4,10,9,7,9,10,7,6,7,15,12,13,14,12,15,7,6,7,10,9,7,9,10,4,6,4,4,1
1,4,4,6,4,6,10,9,7,9,10,7,16,9,19,18,18,17,9,16,7,10,9,7,9,10,6,4,6,4,4,1
1,4,4,6,4,6,6,10,9,7,9,22,21,21,21,21,21,21,21,21,20,9,7,9,10,6,6,4,6,4,4,1
1,4,12,6,6,6,6,6,10,9,7,9,9,23,23,23,23,23,23,23,9,7,9,10,6,6,6,6,6,12,4,1
1,4,4,24,6,7,7,6,8,12,9,17,9,21,21,26,26,21,21,9,25,9,12,8,6,7,7,6,24,4,4,1
1,4,12,6,6,6,6,6,10,9,7,9,23,23,23,23,23,23,23,23,9,7,9,10,6,6,6,6,6,12,4,1
1,4,4,6,4,6,6,10,9,7,9,22,21,21,21,21,21,21,21,21,20,9,7,9,10,6,6,4,6,4,4,1
1,4,4,6,4,6,10,9,7,9,10,7,27,9,29,18,18,28,9,27,7,10,9,7,9,10,6,4,6,4,4,1
1,4,4,6,4,10,9,7,9,10,7,6,7,15,12,13,14,12,15,7,6,7,10,9,7,9,10,4,6,4,4,1
1,4,4,6,4,9,7,9,10,7,6,6,6,7,14,13,14,13,7,6,6,6,7,10,9,7,9,4,6,4,4,1
1,4,4,6,4,8,9,10,7,6,6,6,6,6,30,12,12,30,6,6,6,6,6,7,10,9,8,4,6,4,4,1
1,4,4,6,7,4,4,4,4,4,4,4,4,6,8,6,6,8,6,4,4,4,4,4,4,4,4,7,6,4,4,1
1,4,4,5,6,6,6,6,6,6,6,6,6,6,6,6,6,6,6,6,6,6,6,6,6,6,6,6,5,4,4,1
1,4,4,4,4,4,4,4,4,4,4,4,4,4,4,4,4,4,4,4,4,4,4,4,4,4,4,4,4,4,4,1
1,4,4,4,4,4,4,4,4,4,4,4,4,4,4,4,4,4,4,4,4,4,4,4,4,4,4,4,4,4,4,1
1,1,1,1,1,1,1,1,1,1,1,1,1,1,1,1,1,1,1,1,1,1,1,1,1,1,1,1,1,1,1,1
endlayer

layer
1,1,1,1,1,1,1,1,1,1,1,1,1,1,1,1,1,1,1,1,1,1,1,1,1,1,1,1,1,1,1,1
1,15,18,10,36,35,34,34,34,34,33,33,33,33,33,33,33,33,33,33,33,34,34,34,33,33,32,31,10,18,15,1
1,18,10,37,10,0,18,38,6,14,13,6,14,6,6,6,6,6,6,13,6,14,13,6,38,18,0,10,37,10,18,1
1,10,37,37,10,0,0,0,0,0,0,0,0,0,0,0,0,0,0,0,0,0,0,0,0,0,0,10,37,37,10,1
1,12,10,10,10,0,0,0,0,0,0,0,0,0,0,0,0,0,0,0,0,0,0,0,0,0,0,10,10,10,12,1
1,12,0,0,0,0,0,0,0,0,0,0,0,0,0,0,0,0,0,0,0,0,0,0,0,0,0,0,0,0,12,1
1,12,0,0,0,0,0,0,0,0,0,0,0,0,0,0,0,0,0,0,0,0,0,0,0,0,0,0,0,0,12,1
1,31,0,0,0,0,0,0,0,0,0,0,0,0,0,0,0,0,0,0,0,0,0,0,0,0,0,0,0,0,36,1
1,32,0,0,0,0,0,0,0,0,0,0,39,0,39,0,0,39,0,39,0,0,0,0,0,0,0,0,0,0,35,1
1,32,0,0,0,0,0,0,0,0,0,39,13,30,30,9,9,30,30,14,39,0,0,0,0,0,0,0,0,0,35,1
1,12,0,0,0,0,0,0,0,0,0,0,13,9,40,40,40,40,40,14,0,0,0,0,0,0,0,0,0,0,12,1
1,35,0,0,0,0,0,0,0,0,0,39,9,40,40,42,41,40,0,9,39,0,0,0,0,0,0,0,0,0,35,1
1,12,0,0,0,0,0,0,0,0,0,0,13,40,40,40,40,40,40,14,0,0,0,0,0,0,0,0,0,0,12,1
1,35,0,0,0,0,0,0,0,0,0,39,13,11,11,9,9,11,11,11,39,0,0,0,0,0,0,0,0,0,35,1
1,35,0,0,0,0,0,0,0,0,0,0,39,0,39,0,0,39,0,39,0,0,0,0,0,0,0,0,0,0,35,1
1,31,0,0,0,0,0,0,0,0,0,0,0,0,0,0,0,0,0,0,0,0,0,0,0,0,0,0,0,0,36,1
1,12,0,0,0,0,0,0,0,0,0,0,0,0,0,0,0,0,0,0,0,0,0,0,0,0,0,0,0,0,12,1
1,12,0,0,0,0,0,0,0,0,0,0,0,0,0,0,0,0,0,0,0,0,0,0,0,0,0,0,0,0,12,1
1,12,10,10,10,0,0,0,0,0,0,0,0,0,0,0,0,0,0,0,0,0,0,0,0,0,0,10,10,10,12,1
1,10,37,37,10,0,0,0,0,0,0,0,0,0,0,0,0,0,0,0,0,0,0,0,0,0,0,10,37,37,10,1
1,18,10,37,10,0,18,38,6,14,13,6,14,6,6,6,6,6,6,13,6,14,13,6,38,18,0,10,37,10,18,1
1,15,18,10,36,35,34,34,34,34,34,34,34,34,34,34,34,34,34,34,34,34,34,34,34,34,35,36,10,18,15,1
1,1,1,1,1,1,1,1,1,1,1,1,1,1,1,1,1,1,1,1,1,1,1,1,1,1,1,1,1,1,1,1
endlayer

layer
1,1,1,1,1,1,1,1,1,1,1,1,1,1,1,1,1,1,1,1,1,1,1,1,1,1,1,1,1,1,1,1
1,15,18,10,36,35,34,34,34,34,34,34,34,34,34,33,33,33,33,33,33,33,33,33,33,33,32,31,10,18,15,1
1,18,38,0,0,0,18,38,6,0,0,6,0,13,44,6,6,43,14,0,6,0,0,6,38,18,0,0,0,38,18,1
1,10,0,0,0,0,0,0,0,0,0,0,0,0,0,0,0,0,0,0,0,0,0,0,0,0,0,0,0,0,10,1
1,12,0,0,0,0,0,0,0,0,0,0,0,0,0,0,0,0,0,0,0,0,0,0,0,0,0,0,0,0,12,1
1,12,0,0,0,0,0,0,0,0,0,0,0,0,0,0,0,0,0,0,0,0,0,0,0,0,0,0,0,0,12,1
1,36,0,0,0,0,0,0,0,0,0,0,0,0,0,0,0,0,0,0,0,0,0,0,0,0,0,0,0,0,36,1
1,32,0,0,0,0,0,0,0,0,0,0,0,0,0,0,0,0,0,0,0,0,0,0,0,0,0,0,0,0,35,1
1,32,0,0,0,0,0,0,0,0,0,0,0,0,0,0,0,0,0,0,0,0,0,0,0,0,0,0,0,0,35,1
1,12,0,0,0,0,0,0,0,0,0,0,0,0,0,0,0,0,0,0,0,0,0,0,0,0,0,0,0,0,12,1
1,32,0,0,0,0,0,0,0,0,0,0,0,45,18,46,45,18,45,0,0,0,0,0,0,0,0,0,0,0,35,1
1,35,0,0,0,0,0,0,0,0,0,0,0,13,45,0,0,45,14,0,0,0,0,0,0,0,0,0,0,0,35,1
1,35,0,0,0,0,0,0,0,0,0,0,0,45,18,45,46,18,45,0,0,0,0,0,0,0,0,0,0,0,35,1
1,12,0,0,0,0,0,0,0,0,0,0,0,0,0,0,0,0,0,0,0,0,0,0,0,0,0,0,0,0,12,1
1,35,0,0,0,0,0,0,0,0,0,0,0,0,0,0,0,0,0,0,0,0,0,0,0,0,0,0,0,0,35,1
1,35,0,0,0,0,0,0,0,0,0,0,0,0,0,0,0,0,0,0,0,0,0,0,0,0,0,0,0,0,35,1
1,31,0,0,0,0,0,0,0,0,0,0,0,0,0,0,0,0,0,0,0,0,0,0,0,0,0,0,0,0,36,1
1,12,0,0,0,0,0,0,0,0,0,0,0,0,0,0,0,0,0,0,0,0,0,0,0,0,0,0,0,0,12,1
1,12,0,0,0,0,0,0,0,0,0,0,0,0,0,0,0,0,0,0,0,0,0,0,0,0,0,0,0,0,12,1
1,10,0,0,0,0,0,0,0,0,0,0,0,0,0,0,0,0,0,0,0,0,0,0,0,0,0,0,0,0,10,1
1,18,38,0,0,0,18,38,6,0,0,6,0,13,44,6,6,43,14,0,6,0,0,6,38,18,0,0,0,38,18,1
1,15,18,10,36,35,34,34,34,34,34,34,34,34,34,34,34,34,34,34,34,34,34,34,34,34,35,36,10,18,15,1
1,1,1,1,1,1,1,1,1,1,1,1,1,1,1,1,1,1,1,1,1,1,1,1,1,1,1,1,1,1,1,1
endlayer

layer
1,1,1,1,1,1,1,1,1,1,1,1,1,1,1,1,1,1,1,1,1,1,1,1,1,1,1,1,1,1,1,1
1,15,18,10,36,35,34,34,34,34,34,34,34,34,34,33,33,33,33,33,33,33,33,33,33,33,32,31,10,18,15,1
1,18,38,0,0,0,18,38,6,0,0,6,0,44,6,14,13,6,43,0,6,0,0,6,38,18,0,0,0,38,18,1
1,10,0,0,0,0,0,0,0,0,0,0,0,0,0,0,0,0,0,0,0,0,0,0,0,0,0,0,0,0,10,1
1,12,0,0,0,0,0,0,0,0,0,0,0,0,0,0,0,0,0,0,0,0,0,0,0,0,0,0,0,0,12,1
1,36,0,0,0,0,0,0,0,0,0,0,0,0,0,0,0,0,0,0,0,0,0,0,0,0,0,0,0,0,36,1
1,35,0,0,0,0,0,0,0,0,0,0,0,0,0,0,0,0,0,0,0,0,0,0,0,0,0,0,0,0,35,1
1,32,0,0,0,0,0,0,0,0,0,0,0,0,0,0,0,0,0,0,0,0,0,0,0,0,0,0,0,0,35,1
1,12,0,0,0,0,0,0,0,0,0,0,0,0,0,0,0,0,0,0,0,0,0,0,0,0,0,0,0,0,12,1
1,35,0,0,0,0,0,0,0,0,0,0,0,47,43,0,0,44,47,0,0,0,0,0,0,0,0,0,0,0,35,1
1,12,0,0,0,0,0,0,0,0,0,0,0,44,18,0,0,18,43,0,0,0,0,0,0,0,0,0,0,0,12,1
1,12,0,0,0,0,0,0,0,0,0,0,0,0,0,0,0,0,0,0,0,0,0,0,0,0,0,0,0,0,12,1
1,12,0,0,0,0,0,0,0,0,0,0,0,44,18,0,0,18,43,0,0,0,0,0,0,0,0,0,0,0,12,1
1,35,0,0,0,0,0,0,0,0,0,0,0,48,48,0,0,48,48,0,0,0,0,0,0,0,0,0,0,0,35,1
1,12,0,0,0,0,0,0,0,0,0,0,0,0,0,0,0,0,0,0,0,0,0,0,0,0,0,0,0,0,12,1
1,35,0,0,0,0,0,0,0,0,0,0,0,0,0,0,0,0,0,0,0,0,0,0,0,0,0,0,0,0,35,1
1,35,0,0,0,0,0,0,0,0,0,0,0,0,0,0,0,0,0,0,0,0,0,0,0,0,0,0,0,0,35,1
1,36,0,0,0,0,0,0,0,0,0,0,0,0,0,0,0,0,0,0,0,0,0,0,0,0,0,0,0,0,36,1
1,12,0,0,0,0,0,0,0,0,0,0,0,0,0,0,0,0,0,0,0,0,0,0,0,0,0,0,0,0,12,1
1,10,0,0,0,0,0,0,0,0,0,0,0,0,0,0,0,0,0,0,0,0,0,0,0,0,0,0,0,0,10,1
1,18,38,0,0,0,18,38,6,0,0,6,0,44,6,14,13,6,43,0,6,0,0,6,38,18,0,0,0,38,18,1
1,15,18,10,36,35,34,34,34,34,34,34,34,34,34,34,34,34,34,34,34,34,34,34,34,34,35,36,10,18,15,1
1,1,1,1,1,1,1,1,1,1,1,1,1,1,1,1,1,1,1,1,1,1,1,1,1,1,1,1,1,1,1,1
endlayer

layer
1,1,1,1,1,1,1,1,1,1,1,1,1,1,1,1,1,1,1,1,1,1,1,1,1,1,1,1,1,1,1,1
1,15,18,10,36,35,34,34,34,34,34,34,34,34,34,33,33,33,33,33,33,33,33,33,33,33,35,36,10,18,15,1
1,18,38,0,0,0,18,38,6,43,44,6,43,6,6,6,6,6,6,44,6,43,44,6,38,18,0,0,0,38,18,1
1,10,0,0,0,0,0,0,0,0,0,0,0,0,0,0,0,0,0,0,0,0,0,0,0,0,0,0,0,0,10,1
1,36,0,0,0,0,0,0,0,0,0,0,0,0,0,0,0,0,0,0,0,0,0,0,0,0,0,0,0,0,36,1
1,35,0,0,0,0,0,0,0,0,0,0,0,0,0,0,0,0,0,0,0,0,0,0,0,0,0,0,0,0,35,1
1,35,0,0,0,0,0,0,0,0,0,0,0,0,0,0,0,0,0,0,0,0,0,0,0,0,0,0,0,0,35,1
1,12,0,0,0,0,0,0,0,0,0,0,0,0,0,0,0,0,0,0,0,0,0,0,0,0,0,0,0,0,12,1
1,35,0,0,0,0,0,0,0,0,0,0,0,0,0,0,0,0,0,0,0,0,0,0,0,0,0,0,0,0,35,1
1,12,0,0,0,0,0,0,0,0,0,0,0,9,18,9,9,18,9,0,0,0,0,0,0,0,0,0,0,0,12,1
1,35,0,0,0,0,0,0,0,0,0,0,0,18,34,0,34,34,18,0,0,0,0,0,0,0,0,0,0,0,35,1
1,12,0,0,0,0,0,0,0,0,0,0,0,9,34,0,0,34,9,0,0,0,0,0,0,0,0,0,0,0,12,1
1,32,0,0,0,0,0,0,0,0,0,0,0,18,34,34,34,34,18,0,0,0,0,0,0,0,0,0,0,0,32,1
1,12,0,0,0,0,0,0,0,0,0,0,0,9,18,9,9,18,9,0,0,0,0,0,0,0,0,0,0,0,12,1
1,35,0,0,0,0,0,0,0,0,0,0,0,0,0,0,0,0,0,0,0,0,0,0,0,0,0,0,0,0,35,1
1,12,0,0,0,0,0,0,0,0,0,0,0,0,0,0,0,0,0,0,0,0,0,0,0,0,0,0,0,0,12,1
1,35,0,0,0,0,0,0,0,0,0,0,0,0,0,0,0,0,0,0,0,0,0,0,0,0,0,0,0,0,35,1
1,35,0,0,0,0,0,0,0,0,0,0,0,0,0,0,0,0,0,0,0,0,0,0,0,0,0,0,0,0,35,1
1,36,0,0,0,0,0,0,0,0,0,0,0,0,0,0,0,0,0,0,0,0,0,0,0,0,0,0,0,0,36,1
1,10,0,0,0,0,0,0,0,0,0,0,0,0,0,0,0,0,0,0,0,0,0,0,0,0,0,0,0,0,10,1
1,18,38,0,0,0,18,38,6,43,44,6,43,6,6,6,6,6,6,44,6,43,44,6,38,18,0,0,0,38,18,1
1,15,18,10,36,35,34,34,34,34,34,34,34,34,34,34,34,34,34,34,34,34,34,34,34,34,35,36,10,18,15,1
1,1,1,1,1,1,1,1,1,1,1,1,1,1,1,1,1,1,1,1,1,1,1,1,1,1,1,1,1,1,1,1
endlayer

layer
1,1,1,1,1,1,1,1,1,1,1,1,1,1,1,1,1,1,1,1,1,1,1,1,1,1,1,1,1,1,1,1
1,6,6,6,6,6,6,6,6,6,6,6,6,6,6,6,6,6,6,6,6,6,6,6,6,6,6,6,6,6,6,1
1,6,49,49,49,49,49,49,49,49,49,49,49,49,50,49,49,3,49,49,49,49,49,49,49,49,49,49,49,49,6,1
1,6,49,0,51,51,51,51,51,51,51,51,51,51,24,51,51,24,51,51,51,51,51,51,51,51,51,51,0,49,6,1
1,6,49,53,0,0,0,0,0,0,0,0,0,0,0,0,0,0,0,0,0,0,0,0,0,0,0,0,52,49,6,1
1,6,49,53,0,0,0,0,0,0,0,0,0,0,0,0,0,0,0,0,0,0,0,0,0,0,0,0,52,49,6,1
1,6,49,53,0,0,0,0,0,0,0,0,0,0,0,0,0,0,0,0,0,0,0,0,0,0,0,0,52,49,6,1
1,6,49,53,0,0,0,0,0,0,0,0,0,0,0,0,0,0,0,0,0,0,0,0,0,0,0,0,52,49,6,1
1,6,49,53,0,0,0,0,0,0,0,0,0,0,0,0,0,0,0,0,0,0,0,0,0,0,0,0,52,49,6,1
1,6,49,53,0,0,0,0,0,0,0,0,0,0,0,0,0,0,0,0,0,0,0,0,0,0,0,0,52,49,6,1
1,6,49,53,0,0,0,0,0,0,0,0,0,0,0,0,0,0,0,0,0,0,0,0,0,0,0,0,52,49,6,1
1,6,49,53,0,0,0,0,0,0,0,0,0,0,8,0,0,8,0,0,0,0,0,0,0,0,0,0,52,49,6,1
1,6,49,53,0,0,0,0,0,0,0,0,0,0,0,0,0,0,0,0,0,0,0,0,0,0,0,0,52,49,6,1
1,6,49,53,0,0,0,0,0,0,0,0,0,0,0,0,0,0,0,0,0,0,0,0,0,0,0,0,52,49,6,1
1,6,49,53,0,0,0,0,0,0,0,0,0,0,0,0,0,0,0,0,0,0,0,0,0,0,0,0,52,49,6,1
1,6,49,53,0,0,0,0,0,0,0,0,0,0,0,0,0,0,0,0,0,0,0,0,0,0,0,0,52,49,6,1
1,6,49,53,0,0,0,0,0,0,0,0,0,0,0,0,0,0,0,0,0,0,0,0,0,0,0,0,52,49,6,1
1,6,49,53,0,0,0,0,0,0,0,0,0,0,0,0,0,0,0,0,0,0,0,0,0,0,0,0,52,49,6,1
1,6,49,53,0,0,0,0,0,0,0,0,0,0,0,0,0,0,0,0,0,0,0,0,0,0,0,0,52,49,6,1
1,6,49,0,54,54,54,54,54,54,54,54,54,54,24,54,54,24,54,54,54,54,54,54,54,54,54,54,0,49,6,1
1,6,49,49,49,49,49,49,49,49,49,49,49,49,2,49,49,50,49,49,49,49,49,49,49,49,49,49,49,49,6,1
1,6,6,6,6,6,6,6,6,6,6,6,6,6,6,6,6,6,6,6,6,6,6,6,6,6,6,6,6,6,6,1
1,1,1,1,1,1,1,1,1,1,1,1,1,1,1,1,1,1,1,1,1,1,1,1,1,1,1,1,1,1,1,1
endlayer

layer
1,1,1,1,1,1,1,1,1,1,1,1,1,1,1,1,1,1,1,1,1,1,1,1,1,1,1,1,1,1,1,1
1,40,40,40,40,40,40,40,40,40,40,40,40,40,40,40,40,40,40,40,40,40,40,40,40,40,40,40,40,40,40,1
1,40,40,12,40,40,40,40,40,40,40,40,40,40,40,40,40,40,40,40,40,40,40,40,40,40,40,40,12,40,40,1
1,40,12,0,12,40,40,40,40,40,40,40,40,40,40,40,40,40,40,40,40,40,40,40,40,40,40,12,0,12,40,1
1,40,40,12,36,36,36,36,36,36,36,36,31,36,36,36,31,31,31,31,31,31,36,36,36,36,36,36,12,40,40,1
1,40,40,40,36,36,36,36,36,36,36,36,31,31,31,31,31,36,36,36,31,31,36,36,36,36,36,36,40,40,40,1
1,40,40,40,36,36,45,45,45,45,45,45,45,45,45,45,46,45,46,45,45,45,45,45,45,45,36,36,40,40,40,1
1,40,40,40,36,36,45,36,36,36,36,36,36,36,36,36,36,36,36,36,36,36,36,36,36,45,36,36,40,40,40,1
1,40,40,40,36,36,45,36,45,45,45,45,45,45,45,45,45,45,45,45,45,45,45,45,36,45,36,36,40,40,40,1
1,40,40,40,36,36,45,36,45,34,34,34,34,34,34,34,34,34,34,34,34,34,34,45,36,45,36,36,40,40,40,1
1,40,40,40,36,36,45,36,45,34,36,36,36,36,36,36,36,36,36,36,36,36,34,45,36,45,36,36,40,40,40,1
1,40,40,40,36,36,45,36,45,34,36,45,45,45,45,45,45,45,45,45,45,36,34,45,36,45,36,36,40,40,40,1
1,40,40,40,36,36,45,36,45,34,36,36,36,36,36,36,36,36,36,36,36,36,34,45,36,45,36,36,40,40,40,1
1,40,40,40,36,36,45,36,45,34,34,34,34,34,34,34,34,34,34,34,34,34,34,45,36,45,36,36,40,40,40,1
1,40,40,40,36,36,45,36,45,45,45,45,45,45,45,45,45,45,45,45,45,45,45,45,36,45,36,36,40,40,40,1
1,40,40,40,36,36,45,36,36,36,36,36,36,36,36,36,36,36,36,36,36,36,36,36,36,45,36,36,40,40,40,1
1,40,40,40,36,36,45,45,45,45,45,45,45,45,45,45,45,45,45,45,45,45,45,45,46,45,36,36,40,40,40,1
1,40,40,40,36,36,36,36,36,36,36,36,31,31,31,31,31,31,31,31,36,36,36,36,36,36,36,36,40,40,40,1
1,40,40,12,36,36,36,36,36,36,36,36,31,31,31,31,31,31,31,31,36,36,36,36,36,36,36,36,12,40,40,1
1,40,12,0,12,40,40,40,40,40,40,40,40,40,40,40,40,40,40,40,40,40,40,40,40,40,40,12,0,12,40,1
1,40,40,12,40,40,40,40,40,40,40,40,40,40,40,40,40,40,40,40,40,40,40,40,40,40,40,40,12,40,40,1
1,40,40,40,40,40,40,40,40,40,40,40,40,40,40,40,40,40,40,40,40,40,40,40,40,40,40,40,40,40,40,1
1,1,1,1,1,1,1,1,1,1,1,1,1,1,1,1,1,1,1,1,1,1,1,1,1,1,1,1,1,1,1,1
endlayer

layer
1,1,1,1,1,1,1,1,1,1,1,1,1,1,1,1,1,1,1,1,1,1,1,1,1,1,1,1,1,1,1,1
1,6,21,21,21,21,21,21,21,21,21,21,21,21,21,21,21,21,21,21,21,21,21,21,21,21,21,21,21,21,6,1
1,55,6,6,6,56,56,56,56,56,56,56,56,56,56,56,56,56,56,56,56,56,56,56,56,56,56,6,6,6,55,1
1,55,6,0,6,56,56,56,56,56,56,56,56,56,56,56,56,56,56,56,56,56,56,56,56,56,56,6,0,6,55,1
1,55,6,6,6,21,21,21,21,21,21,21,21,21,21,21,21,21,21,21,21,21,21,21,21,21,21,6,6,6,55,1
1,55,56,56,55,6,57,57,55,31,31,31,31,31,31,31,31,31,31,31,31,31,31,55,57,57,6,55,56,56,55,1
1,55,56,56,55,57,57,57,55,31,37,37,37,37,37,37,37,37,37,37,37,37,31,55,57,57,57,55,56,56,55,1
1,55,56,56,55,57,57,10,56,31,37,37,37,37,37,37,37,37,37,37,37,37,31,56,10,57,57,55,56,56,55,1
1,55,56,56,55,21,21,56,56,31,31,31,31,31,31,31,31,31,31,31,31,31,31,56,56,21,21,55,56,56,55,1
1,55,40,40,55,56,56,56,6,6,6,6,6,6,6,6,6,6,6,6,6,6,6,6,56,56,56,55,56,56,55,1
1,55,40,40,55,40,6,6,6,40,6,10,10,10,10,10,10,10,10,10,10,6,56,6,6,6,56,55,56,56,55,1
1,55,56,56,55,56,56,40,40,40,6,10,56,40,56,56,56,56,40,56,10,6,56,56,56,56,56,55,56,56,55,1
1,55,40,40,55,40,6,6,6,40,6,10,10,10,10,10,10,10,10,10,10,6,56,6,6,6,56,55,56,56,55,1
1,55,40,40,55,56,56,56,6,6,6,6,6,6,6,6,6,6,6,6,6,6,6,6,56,56,56,55,56,56,55,1
1,55,56,56,55,21,21,56,56,31,31,31,31,31,31,31,31,31,31,31,31,31,31,56,56,21,21,55,56,56,55,1
1,55,56,56,55,57,57,10,56,31,37,37,37,37,37,37,37,37,37,37,37,37,31,56,10,57,57,55,56,56,55,1
1,55,56,56,55,57,57,57,55,31,37,37,37,37,37,37,37,37,37,37,37,37,31,55,57,57,57,55,56,56,55,1
1,55,56,56,55,6,57,57,55,31,31,31,31,31,31,31,31,31,31,31,31,31,31,55,57,57,6,55,56,56,55,1
1,55,6,6,6,21,21,21,21,21,21,21,21,21,21,21,21,21,21,21,21,21,21,21,21,21,21,6,6,6,55,1
1,55,6,0,6,56,56,56,56,56,56,56,56,56,56,56,56,56,56,56,56,56,56,56,56,56,56,6,0,6,55,1
1,55,6,6,6,56,56,56,56,56,56,56,56,56,56,56,56,56,56,56,56,56,56,56,56,56,56,6,6,6,55,1
1,6,21,21,21,21,21,21,21,21,21,21,21,21,21,21,21,21,21,21,21,21,21,21,21,21,21,21,21,21,6,1
1,1,1,1,1,1,1,1,1,1,1,1,1,1,1,1,1,1,1,1,1,1,1,1,1,1,1,1,1,1,1,1
endlayer

layer
1,1,1,1,1,1,1,1,1,1,1,1,1,1,1,1,1,1,1,1,1,1,1,1,1,1,1,1,1,1,1,1
59,59,59,58,58,58,58,58,58,58,58,58,58,58,58,58,58,58,58,58,58,58,58,58,58,58,58,58,58,58,58,1
59,63,0,0,0,60,60,60,60,60,60,60,60,62,61,60,60,60,60,60,60,60,60,60,60,60,60,0,0,0,58,1
59,63,0,0,65,60,60,60,60,60,64,60,60,60,60,60,60,60,60,60,0,60,60,60,0,60,60,0,0,0,58,1
59,63,0,0,0,0,0,0,0,0,0,0,0,0,0,0,0,0,0,0,0,0,65,0,0,0,0,0,0,0,58,1
59,0,60,60,0,0,0,0,0,0,0,0,0,0,0,0,0,0,0,0,0,0,0,0,0,0,0,0,0,60,58,1
59,0,66,60,0,0,0,0,0,0,0,0,0,0,0,65,0,0,0,0,0,0,0,0,0,0,0,0,0,60,58,1
59,0,0,60,0,0,0,0,0,0,0,0,0,67,67,67,0,0,0,0,0,0,0,0,0,0,0,0,60,60,59,1
59,71,60,70,0,0,0,0,0,69,0,0,68,0,0,0,0,0,0,0,0,0,0,0,0,0,0,0,60,0,59,1
59,0,10,10,0,71,71,65,0,0,0,0,0,0,0,0,0,0,0,0,0,0,0,0,0,0,0,0,0,60,59,1
59,0,10,10,21,21,21,9,21,73,0,38,38,72,38,38,38,38,72,38,38,0,0,0,0,0,0,0,60,60,59,1
59,0,60,78,77,0,52,10,10,76,0,38,0,75,60,64,60,0,75,64,38,0,0,74,0,0,0,0,0,60,58,1
59,0,10,10,21,21,21,9,21,79,0,38,38,72,38,38,38,38,72,38,38,0,0,0,0,0,0,0,60,60,58,1
59,0,10,10,0,82,82,69,0,0,0,0,0,0,0,0,81,0,0,0,80,0,0,0,0,0,0,0,0,60,58,1
59,82,83,83,0,0,0,0,0,0,0,0,0,0,0,62,62,0,0,0,80,0,0,0,0,0,0,0,60,0,58,1
59,0,60,60,0,0,0,0,0,0,84,0,0,0,0,0,0,0,0,82,0,0,0,0,0,0,0,0,60,60,58,1
59,0,85,60,0,0,0,0,0,0,0,0,0,0,0,0,0,0,0,0,0,0,0,0,0,0,0,0,60,60,58,1
59,0,60,60,0,0,0,0,0,0,0,0,0,0,0,0,0,0,0,0,0,0,0,0,0,0,0,0,60,60,58,1
59,0,0,0,0,0,0,0,0,0,0,0,0,0,0,0,0,0,0,0,0,0,0,0,0,0,0,0,0,81,58,1
59,0,0,0,0,64,60,60,60,0,60,60,85,60,60,60,60,60,0,60,60,60,60,60,60,0,60,0,0,81,58,1
59,0,0,0,0,0,60,60,60,60,60,60,60,60,60,60,60,60,60,60,60,60,60,60,60,60,0,71,71,71,58,1
59,59,59,58,58,58,58,58,58,58,58,58,59,59,59,58,58,58,58,58,59,59,59,59,59,59,59,59,59,58,58,1
1,1,1,1,1,1,1,1,1,1,1,1,1,1,1,1,1,1,1,1,1,1,1,1,1,1,1,1,1,1,1,1
endlayer

layer
1,1,1,1,1,1,1,1,1,1,1,1,1,1,1,1,1,1,1,1,1,1,1,1,1,1,1,1,1,1,1,1
34,34,34,33,33,33,33,33,33,33,33,33,33,33,33,33,33,33,33,33,33,33,33,33,33,33,33,33,33,33,33,1
34,63,0,0,0,62,0,0,0,0,0,62,62,62,0,0,0,0,0,62,62,62,0,0,62,62,0,0,0,0,34,1
34,63,0,0,65,0,0,0,0,0,86,0,0,0,0,0,0,0,0,0,0,0,0,0,0,0,0,0,0,0,34,1
34,63,0,0,0,0,0,0,0,0,0,0,0,0,0,0,0,0,0,0,0,0,65,0,0,0,0,0,0,0,34,1
34,0,0,0,0,0,0,0,0,0,0,0,0,0,0,0,0,0,0,0,0,0,0,0,0,0,0,0,0,0,33,1
34,0,0,0,0,0,0,0,0,0,0,0,0,0,0,65,0,0,0,0,0,0,0,0,0,0,0,0,0,0,33,1
34,0,0,0,0,0,0,0,0,0,0,0,0,67,67,67,0,0,0,0,0,0,0,0,0,0,0,0,0,0,33,1
34,71,0,0,0,0,0,0,0,69,0,0,68,0,0,0,0,0,0,0,0,0,0,0,0,0,0,0,0,0,33,1
34,0,38,38,0,0,71,65,0,0,0,0,0,0,0,0,0,0,0,0,0,0,0,0,0,0,0,0,0,0,33,1
34,0,38,38,21,21,9,21,21,0,0,0,0,0,0,0,0,0,0,0,0,0,0,0,0,0,0,0,0,0,33,1
34,0,0,0,0,52,10,10,76,0,0,0,0,75,0,86,0,0,75,86,0,0,0,74,0,0,0,0,0,0,33,1
34,0,38,38,21,21,9,21,21,0,0,0,0,0,82,0,0,0,0,0,0,0,0,0,0,0,0,0,0,0,33,1
34,0,38,38,0,82,82,69,0,0,0,0,0,0,0,0,81,0,0,0,80,0,0,0,0,0,0,0,0,0,33,1
34,82,0,0,0,0,0,0,0,0,0,0,0,0,0,62,62,0,0,0,80,0,0,0,0,0,0,0,0,0,33,1
34,0,0,0,0,0,0,0,0,0,84,0,0,0,0,0,0,0,0,82,0,0,0,0,0,0,0,0,0,0,33,1
34,0,0,0,0,0,0,0,0,0,0,0,0,0,0,0,0,0,0,0,0,0,0,0,0,0,0,0,0,0,33,1
34,0,0,0,0,0,0,0,0,0,0,0,0,0,0,0,0,0,0,0,0,0,0,0,0,0,0,0,0,0,33,1
34,0,0,0,0,0,0,0,0,0,0,0,0,0,0,0,0,0,0,0,0,0,0,0,0,0,0,0,0,81,33,1
34,0,0,0,0,86,0,0,0,0,0,0,0,0,0,0,0,0,0,0,0,0,0,0,0,0,0,0,0,81,33,1
34,0,0,0,0,0,0,67,67,67,67,0,0,67,67,67,67,67,0,0,0,0,67,67,67,67,0,71,71,71,33,1
34,34,34,33,33,33,33,33,33,33,33,33,33,33,33,33,33,33,33,33,33,33,33,33,33,34,33,34,33,33,33,1
1,1,1,1,1,1,1,1,1,1,1,1,1,1,1,1,1,1,1,1,1,1,1,1,1,1,1,1,1,1,1,1
endlayer

layer
1,1,1,1,1,1,1,1,1,1,1,1,1,1,1,1,1,1,1,1,1,1,1,1,1,1,1,1,1,1,1,1
31,31,31,31,31,31,31,31,31,31,31,31,31,31,31,31,31,31,31,31,31,31,31,31,31,31,31,31,31,31,31,1
31,63,0,0,0,62,0,0,0,0,0,62,62,62,0,0,0,0,0,62,62,62,0,0,62,62,0,0,0,0,31,1
31,63,0,0,65,0,0,0,0,0,0,0,0,0,0,0,0,0,0,0,0,0,0,0,0,0,0,0,0,0,36,1
31,63,0,0,0,0,0,0,0,0,0,0,0,0,0,0,0,0,0,0,0,0,65,0,0,0,0,0,0,0,36,1
31,0,0,0,0,0,0,0,0,0,0,0,0,0,0,0,0,0,0,0,0,0,0,0,0,0,0,0,0,0,31,1
31,0,0,0,0,0,0,0,0,0,0,0,0,0,0,65,0,0,0,0,0,0,0,0,0,0,0,0,0,0,31,1
31,0,0,0,0,0,0,0,0,0,0,0,0,67,67,67,0,0,0,0,0,0,0,0,0,0,0,0,0,0,31,1
31,71,0,0,0,0,0,0,0,69,0,0,68,0,0,0,0,0,0,0,0,0,0,0,0,0,0,0,0,0,31,1
31,0,38,38,0,0,71,65,0,0,0,0,0,0,88,0,87,0,0,0,0,0,0,0,0,0,0,0,0,0,31,1
31,0,38,38,21,9,21,21,63,0,0,0,0,88,88,88,87,0,0,0,0,0,0,0,0,0,0,0,0,0,31,1
31,0,0,0,52,10,10,76,0,0,0,0,0,75,88,80,87,0,75,0,0,0,0,74,0,0,0,0,0,0,31,1
31,0,38,38,21,9,21,21,0,0,0,0,0,0,82,0,0,0,0,0,0,0,0,0,0,0,0,0,0,0,31,1
31,0,38,38,0,82,82,69,0,0,0,0,0,0,0,0,81,0,0,0,80,0,0,0,0,0,0,0,0,0,31,1
31,82,0,0,0,0,0,0,0,0,0,0,0,0,0,62,62,0,0,0,80,0,0,0,0,0,0,0,0,0,31,1
31,0,0,0,0,0,0,0,0,0,84,0,0,0,0,0,0,0,0,82,0,0,0,0,0,0,0,0,0,0,31,1
31,0,0,0,0,0,0,0,0,0,0,0,0,0,0,0,0,0,0,0,0,0,0,0,0,0,0,0,0,0,31,1
31,0,0,0,0,0,0,0,0,0,0,0,0,0,0,0,0,0,0,0,0,0,0,0,0,0,0,0,0,0,31,1
31,0,0,0,0,0,0,0,0,0,0,0,0,0,0,0,0,0,0,0,0,0,0,0,0,0,0,0,0,81,31,1
31,0,0,0,0,0,0,0,0,0,0,0,0,0,0,0,0,0,0,0,0,0,0,0,0,0,0,0,0,81,31,1
31,0,0,0,0,0,0,67,67,67,67,0,0,67,67,67,67,67,0,0,0,0,67,67,67,67,0,71,71,71,31,1
31,31,31,31,31,31,31,31,31,31,31,31,31,31,31,31,31,31,31,31,31,31,31,31,31,31,31,31,31,31,31,1
1,1,1,1,1,1,1,1,1,1,1,1,1,1,1,1,1,1,1,1,1,1,1,1,1,1,1,1,1,1,1,1
endlayer

layer
1,1,1,1,1,1,1,1,1,1,1,1,1,1,1,1,1,1,1,1,1,1,1,1,1,1,1,1,1,1,1,1
31,36,36,31,31,31,31,31,31,31,31,31,31,31,31,31,31,31,31,31,31,31,31,31,31,31,31,31,31,31,31,1
31,63,0,0,0,62,0,0,0,0,0,62,62,62,0,0,0,0,0,62,62,62,0,0,62,62,0,0,0,0,31,1
31,63,0,0,65,0,0,0,0,0,0,0,0,0,0,0,0,0,0,0,0,0,0,0,0,0,0,0,0,0,36,1
31,63,0,0,0,0,0,0,0,0,0,0,0,0,0,0,0,0,0,0,0,0,65,0,0,0,0,0,0,0,36,1
31,0,0,0,0,0,0,0,0,0,0,0,0,0,0,0,0,0,0,0,0,0,0,0,0,0,0,0,0,0,31,1
31,0,0,0,0,0,0,0,0,0,0,0,0,0,0,65,0,0,0,0,0,0,0,0,0,0,0,0,0,0,31,1
31,0,0,0,0,0,0,0,0,0,0,0,0,67,67,67,0,0,0,0,0,0,0,0,0,0,0,0,0,0,31,1
31,71,0,0,0,0,0,0,0,69,0,0,68,88,88,88,89,89,89,0,0,0,0,0,0,0,0,0,0,0,31,1
31,0,38,38,90,0,71,65,0,0,0,0,88,88,88,88,88,89,0,0,0,0,0,0,0,0,0,0,0,0,31,1
31,0,38,38,9,21,21,0,0,0,0,0,88,88,91,88,88,0,0,32,0,0,0,0,0,0,0,0,0,0,31,1
31,0,0,52,10,10,76,0,0,0,0,0,88,75,88,88,88,0,75,32,0,0,0,74,0,0,0,0,0,0,31,1
31,0,38,38,9,21,21,0,0,0,0,0,57,88,88,88,0,89,0,32,0,0,0,0,0,0,0,0,0,0,31,1
31,0,38,38,90,82,82,69,0,0,0,0,0,0,0,0,81,89,89,0,80,0,0,0,0,0,0,0,0,0,31,1
31,82,0,0,0,0,0,0,0,0,0,0,0,0,0,62,62,0,0,0,80,0,0,0,0,0,0,0,0,0,31,1
31,0,0,0,0,0,0,0,0,0,84,0,0,0,0,0,0,0,0,82,0,0,0,0,0,0,0,0,0,0,31,1
31,0,0,0,0,0,0,0,0,0,0,0,0,0,0,0,0,0,0,0,0,0,0,0,0,0,0,0,0,0,31,1
31,0,0,0,0,0,0,0,0,0,0,0,0,0,0,0,0,0,0,0,0,0,0,0,0,0,0,0,0,0,31,1
31,0,0,0,0,0,0,0,0,0,0,0,0,0,0,0,0,0,0,0,0,0,0,0,0,0,0,0,0,81,31,1
31,0,0,0,0,0,0,0,0,0,0,0,0,0,0,0,0,0,0,0,0,0,0,0,0,0,0,0,0,81,31,1
31,0,0,0,0,0,0,67,67,67,67,0,0,67,67,67,67,67,0,0,0,0,67,67,67,0,0,71,71,71,31,1
31,31,31,31,31,31,31,31,31,31,31,31,31,31,31,31,31,31,31,31,31,31,31,31,31,31,31,31,31,31,31,1
1,1,1,1,1,1,1,1,1,1,1,1,1,1,1,1,1,1,1,1,1,1,1,1,1,1,1,1,1,1,1,1
endlayer

layer
1,1,1,1,1,1,1,1,1,1,1,1,1,1,1,1,1,1,1,1,1,1,1,1,1,1,1,1,1,1,1,1
34,34,34,34,33,33,33,33,33,33,33,33,33,33,33,33,33,33,33,33,33,33,33,33,33,33,33,33,33,33,33,1
34,63,0,0,0,62,0,0,0,0,0,62,62,62,0,0,0,0,0,0,62,62,0,0,62,62,0,0,0,0,33,1
34,63,0,0,65,0,0,0,0,0,0,0,0,0,0,0,0,0,0,0,0,0,0,0,0,0,0,0,0,0,33,1
34,0,0,0,0,0,0,0,0,0,0,0,0,0,0,0,0,0,0,0,0,0,65,0,0,0,0,0,0,0,33,1
33,0,0,0,0,0,0,0,0,0,0,0,0,0,0,0,0,0,0,0,0,0,0,0,0,0,0,0,0,0,33,1
33,0,0,0,0,0,0,0,0,0,0,0,0,0,0,65,0,0,89,0,0,0,0,0,0,0,0,0,0,0,33,1
33,0,0,0,0,0,0,0,0,0,0,0,0,67,67,67,0,89,89,89,0,0,0,0,0,0,0,0,0,0,33,1
33,71,0,0,0,0,0,0,0,69,0,0,68,88,88,89,89,89,89,89,0,0,0,0,0,0,0,0,0,0,33,1
33,33,38,38,0,0,0,65,0,0,0,0,88,88,88,89,89,89,89,89,0,0,0,0,0,0,0,0,0,0,33,1
33,92,38,38,21,21,0,0,0,0,0,0,88,88,88,88,89,89,91,89,32,0,0,0,0,0,0,0,0,0,33,1
33,92,52,10,10,76,0,0,0,0,0,57,88,75,88,89,89,89,75,35,0,0,0,74,0,0,0,0,0,0,33,1
33,92,38,38,21,21,0,0,0,0,0,0,57,88,89,89,89,89,89,89,32,0,0,0,0,0,0,0,0,0,33,1
33,33,38,38,0,0,0,69,0,0,0,0,0,0,0,89,89,89,89,89,80,0,0,0,0,0,0,0,0,0,33,1
33,82,0,0,0,0,0,0,0,0,0,0,0,0,0,62,62,89,89,89,80,0,0,0,0,0,0,0,0,0,33,1
33,0,0,0,0,0,0,0,0,0,84,0,0,0,0,0,0,0,0,82,0,0,0,0,0,0,0,0,0,0,33,1
33,0,0,0,0,0,0,0,0,0,0,0,0,0,0,0,0,0,0,0,0,0,0,0,0,0,0,0,0,0,33,1
33,0,0,0,0,0,0,0,0,0,0,0,0,0,0,0,0,0,0,0,0,0,0,0,0,0,0,0,0,0,33,1
33,0,0,0,0,0,0,0,0,0,0,0,0,0,0,0,0,0,0,0,0,0,0,0,0,0,0,0,0,81,33,1
33,0,0,0,0,0,0,0,0,0,0,0,0,0,0,0,0,0,0,0,0,0,0,0,0,0,0,0,0,81,33,1
33,0,0,0,0,0,0,67,67,67,0,0,0,67,67,67,67,67,0,0,0,0,67,67,67,0,0,71,71,71,33,1
33,33,34,33,33,33,33,33,33,33,33,33,33,33,33,33,33,33,33,33,33,33,33,33,34,34,33,33,33,33,33,1
1,1,1,1,1,1,1,1,1,1,1,1,1,1,1,1,1,1,1,1,1,1,1,1,1,1,1,1,1,1,1,1
endlayer

layer
1,1,1,1,1,1,1,1,1,1,1,1,1,1,1,1,1,1,1,1,1,1,1,1,1,1,1,1,1,1,1,1
58,58,58,58,58,58,58,58,58,58,58,58,58,58,58,58,58,58,58,58,58,58,58,58,58,58,58,58,58,58,58,1
58,63,0,0,0,62,0,0,0,0,0,62,62,62,0,0,0,0,0,0,0,0,0,0,62,62,0,0,0,0,58,1
58,63,0,0,65,0,0,0,0,0,0,0,0,0,0,0,0,0,0,0,0,0,0,0,0,0,0,0,0,0,58,1
58,0,0,0,0,0,0,0,0,0,0,0,0,0,0,0,0,0,0,0,0,0,65,0,0,0,0,0,0,0,58,1
58,0,0,0,0,0,0,0,0,0,0,0,0,0,0,0,0,0,0,0,0,0,0,0,0,0,0,0,0,0,58,1
58,0,0,0,0,0,0,0,0,0,0,0,0,0,0,65,0,89,89,0,0,0,0,0,0,0,0,0,0,0,58,1
58,38,38,38,38,0,0,0,0,0,0,0,0,67,67,67,89,89,89,89,0,0,0,0,0,0,0,0,0,0,58,1
58,38,54,54,38,0,0,0,0,69,0,0,68,88,88,89,89,89,89,89,0,0,0,0,0,0,0,0,0,0,58,1
58,38,10,10,38,0,0,65,0,0,0,0,88,88,88,89,89,89,91,89,35,35,0,0,0,0,0,0,0,0,58,1
58,38,10,10,21,0,0,0,0,0,0,88,88,88,89,89,89,91,91,89,89,35,0,0,0,0,0,0,0,0,58,1
58,38,10,10,76,0,0,0,0,0,0,88,88,89,89,89,89,89,75,89,35,32,0,74,0,0,0,0,0,0,58,1
58,38,10,10,21,0,0,0,0,0,0,88,88,89,89,89,89,89,91,89,35,0,0,0,0,0,0,0,0,0,58,1
58,38,10,10,38,0,0,69,0,0,0,0,88,89,89,89,89,89,89,89,80,0,0,0,0,0,0,0,0,0,58,1
58,38,51,51,38,0,0,0,0,0,0,0,0,0,0,62,89,89,89,89,80,0,0,0,0,0,0,0,0,0,58,1
58,38,38,38,38,0,0,0,0,0,84,0,0,0,0,0,0,0,89,82,0,0,0,0,0,0,0,0,0,0,58,1
58,0,0,0,0,0,0,0,0,0,0,0,0,0,0,0,0,0,0,0,0,0,0,0,0,0,0,0,0,0,58,1
58,0,0,0,0,0,0,0,0,0,0,0,0,0,0,0,0,0,0,0,0,0,0,0,0,0,0,0,0,0,58,1
58,0,0,0,0,0,0,0,0,0,0,0,0,0,0,0,0,0,0,0,0,0,0,0,0,0,0,0,0,81,58,1
59,0,0,0,0,0,0,0,0,0,0,0,0,0,0,0,0,0,0,0,0,0,0,0,0,0,0,0,0,81,58,1
59,0,0,0,0,0,0,67,67,67,0,0,0,0,67,67,0,0,0,0,0,0,67,67,0,0,0,0,71,71,58,1
59,59,59,58,58,58,58,58,58,58,58,58,58,58,58,58,58,58,58,58,58,58,58,59,59,59,58,58,58,58,58,1
1,1,1,1,1,1,1,1,1,1,1,1,1,1,1,1,1,1,1,1,1,1,1,1,1,1,1,1,1,1,1,1
endlayer

layer
1,1,1,1,1,1,1,1,1,1,1,1,1,1,1,1,1,1,1,1,1,1,1,1,1,1,1,1,1,1,1,1
92,21,21,21,21,21,21,21,21,21,21,21,21,21,21,21,21,21,21,21,21,21,21,21,21,21,21,21,21,21,92,1
55,0,0,0,0,62,0,0,0,0,0,0,0,62,0,0,0,0,0,0,0,0,0,0,62,62,0,0,0,0,55,1
55,0,0,0,65,0,0,0,0,0,0,0,0,0,0,0,0,0,0,0,0,0,0,0,0,0,0,0,0,0,55,1
55,0,0,0,0,0,0,0,0,0,0,0,0,0,0,0,0,0,0,0,0,0,65,0,0,0,0,0,0,0,55,1
55,0,0,0,0,0,0,0,0,0,0,0,0,0,0,0,0,0,0,0,0,0,0,0,0,0,0,0,0,0,55,1
55,0,38,38,38,0,0,0,0,0,0,0,0,0,0,65,0,0,0,0,0,0,0,0,0,0,0,0,0,0,55,1
55,0,54,54,38,0,0,0,0,0,0,0,0,0,0,0,0,89,89,91,89,0,0,0,0,0,0,0,0,0,55,1
55,0,10,10,38,0,0,0,0,69,0,0,0,0,0,0,89,89,89,91,35,0,0,0,0,0,0,0,0,0,55,1
55,76,79,79,79,0,0,65,0,0,0,0,0,88,88,89,89,89,89,89,89,35,0,0,0,0,0,0,0,0,55,1
55,76,0,0,0,0,0,0,0,0,0,0,88,88,89,89,89,89,89,91,89,0,0,0,0,0,0,0,0,0,55,1
55,76,0,0,0,0,0,0,0,0,0,93,88,89,89,89,89,89,75,89,89,0,0,74,0,0,0,0,0,0,55,1
55,76,0,0,0,0,0,0,0,0,0,0,88,89,89,89,89,89,89,89,89,0,0,0,0,0,0,0,0,0,55,1
55,76,73,73,73,0,0,69,0,0,0,0,0,94,62,62,89,89,89,89,89,0,0,0,0,0,0,0,0,0,55,1
55,0,10,10,38,0,0,0,0,0,0,0,0,0,0,0,0,89,89,89,0,0,0,0,0,0,0,0,0,0,55,1
55,0,51,51,38,0,0,0,0,0,84,0,0,0,0,0,0,0,0,0,0,0,0,0,0,0,0,0,0,0,55,1
55,0,38,38,38,0,0,0,0,0,0,0,0,0,0,0,0,0,0,0,0,0,0,0,0,0,0,0,0,0,55,1
55,0,0,0,0,0,0,0,0,0,0,0,0,0,0,0,0,0,0,0,0,0,0,0,0,0,0,0,0,0,55,1
55,0,0,0,0,0,0,0,0,0,0,0,0,0,0,0,0,0,0,0,0,0,0,0,0,0,0,0,0,81,55,1
55,0,0,0,0,0,0,0,0,0,0,0,0,0,0,0,0,0,0,0,0,0,0,0,0,0,0,0,0,81,55,1
55,0,0,0,0,0,0,67,67,67,0,0,0,0,67,67,0,0,0,0,0,0,67,67,0,0,0,0,71,71,55,1
92,21,21,21,21,21,21,21,21,21,21,21,21,21,21,21,21,21,21,21,21,21,21,21,21,21,21,21,21,21,92,1
1,1,1,1,1,1,1,1,1,1,1,1,1,1,1,1,1,1,1,1,1,1,1,1,1,1,1,1,1,1,1,1
endlayer

layer
1,1,1,1,1,1,1,1,1,1,1,1,1,1,1,1,1,1,1,1,1,1,1,1,1,1,1,1,1,1,1,1
92,92,92,92,92,92,92,92,92,92,92,92,92,92,92,92,92,92,92,92,92,92,92,92,92,92,92,92,92,92,92,1
92,0,0,0,95,0,0,0,0,0,0,0,0,62,0,0,0,0,0,0,0,0,0,0,0,0,0,0,0,0,92,1
92,0,0,0,65,0,0,0,0,0,0,0,0,95,0,0,0,0,0,0,0,0,0,0,0,0,0,0,0,0,92,1
92,0,0,0,0,0,0,0,0,0,0,0,0,0,0,0,0,0,0,0,0,95,65,0,0,0,0,0,0,0,92,1
92,0,73,73,73,73,0,0,0,0,0,0,0,0,0,0,0,0,0,0,0,0,0,0,0,0,0,0,0,0,92,1
92,92,10,10,10,76,0,0,0,0,0,0,0,0,0,65,0,89,89,89,89,0,0,0,0,0,0,0,0,0,92,1
92,96,10,10,10,76,0,0,87,87,0,0,0,0,0,0,0,89,89,89,89,0,0,0,0,0,0,0,0,0,92,1
92,79,79,79,79,79,0,0,0,69,0,0,0,0,0,0,89,89,89,89,89,89,0,0,0,0,0,0,0,0,92,1
92,0,0,0,0,0,95,65,95,0,0,0,0,0,0,0,89,89,89,89,89,0,0,0,0,0,0,0,0,0,92,1
92,0,0,0,0,0,0,0,0,0,0,0,0,88,0,89,89,89,89,89,35,0,0,0,0,0,0,0,0,0,92,1
92,0,0,0,0,0,0,0,0,0,0,0,93,93,88,89,89,89,75,89,89,0,0,74,87,0,0,0,0,0,92,1
92,0,0,0,0,0,0,0,0,0,0,0,0,88,81,89,89,89,89,89,89,0,0,87,87,0,0,0,0,0,92,1
92,0,0,0,0,0,0,69,0,0,0,0,0,0,0,62,89,89,89,89,89,0,0,0,0,0,0,0,0,0,92,1
92,96,73,73,73,73,0,0,0,0,0,0,0,0,0,95,0,89,89,89,0,0,0,0,0,0,0,0,0,0,92,1
92,96,10,10,10,76,0,0,0,0,84,0,0,0,0,0,0,0,0,0,0,0,0,0,0,0,0,0,0,0,92,1
92,92,10,10,10,76,0,0,0,0,0,0,0,0,0,0,0,0,0,0,0,0,0,0,0,0,0,0,0,0,92,1
92,96,79,79,79,79,0,0,0,0,0,0,0,0,0,0,0,0,0,0,0,0,0,0,0,0,0,0,0,0,92,1
92,0,0,0,0,0,0,0,0,0,0,0,0,0,0,0,0,0,0,0,0,0,0,87,0,0,0,0,0,81,92,1
92,0,0,0,0,0,0,0,0,0,0,0,0,0,87,0,0,0,0,0,0,0,87,87,0,0,0,0,0,81,92,1
92,0,0,0,0,0,0,67,67,67,0,0,0,0,67,67,0,0,0,0,0,0,67,67,0,0,0,0,71,71,92,1
92,92,92,92,92,92,92,92,92,92,92,92,92,92,92,92,92,92,92,92,92,92,92,92,92,92,92,92,92,92,92,1
1,1,1,1,1,1,1,1,1,1,1,1,1,1,1,1,1,1,1,1,1,1,1,1,1,1,1,1,1,1,1,1
endlayer

layer
1,1,1,1,1,1,1,1,1,1,1,1,1,1,1,1,1,1,1,1,1,1,1,1,1,1,1,1,1,1,1,1
92,92,92,92,92,92,92,92,92,92,92,92,92,92,92,92,92,92,92,92,92,92,92,92,92,92,92,92,92,92,92,1
92,92,55,55,40,40,40,40,40,40,40,40,40,40,40,40,40,40,40,40,40,40,40,40,40,40,40,40,40,40,92,1
92,92,55,55,65,40,40,40,40,40,40,40,40,40,40,40,40,40,40,40,40,40,40,40,40,40,40,40,40,40,92,1
92,92,55,55,56,40,40,40,40,40,40,40,40,40,40,40,40,40,40,40,40,40,65,40,40,40,40,40,40,40,92,1
92,92,55,55,56,40,40,40,40,40,40,40,40,40,40,40,40,40,40,40,40,40,40,40,40,40,40,40,40,40,92,1
92,0,79,79,92,40,40,40,40,40,40,40,40,40,40,65,40,40,89,40,40,40,40,40,40,40,40,40,40,40,92,1
92,0,0,0,92,40,40,40,40,40,40,40,40,40,40,40,40,89,89,89,40,40,40,40,40,40,40,40,40,40,92,1
92,0,0,0,52,40,40,40,40,69,40,40,40,40,40,40,40,89,89,89,89,40,40,40,40,40,40,40,40,40,92,1
92,0,0,0,52,40,40,65,40,40,40,40,40,40,40,40,40,40,89,89,89,40,40,40,40,40,40,40,40,40,92,1
92,0,0,0,52,40,40,40,40,40,40,40,40,40,40,40,89,89,89,89,89,40,40,40,40,40,40,40,40,40,92,1
92,0,0,0,52,40,40,40,40,40,40,40,40,40,40,40,89,89,89,89,89,56,56,74,56,56,56,56,56,56,92,1
92,0,0,0,52,40,40,40,40,40,40,40,40,40,40,40,40,89,89,89,40,40,40,40,40,40,40,40,40,40,92,1
92,0,0,0,52,40,40,69,40,40,40,40,40,40,40,40,40,40,89,89,40,40,40,40,40,40,40,40,40,40,92,1
92,0,0,0,52,40,40,40,40,40,40,40,40,40,40,40,40,40,40,40,40,40,40,40,40,40,40,40,40,40,92,1
92,0,0,0,92,40,40,40,40,40,84,40,40,40,40,40,40,40,40,40,40,40,40,40,40,40,40,40,40,40,92,1
92,0,73,73,92,40,40,40,40,40,40,40,40,40,40,40,40,40,40,40,40,40,40,40,40,40,40,40,40,40,92,1
92,92,55,55,40,40,40,40,40,40,40,40,40,40,40,40,40,40,40,40,40,40,40,40,40,40,40,40,40,40,92,1
92,92,55,55,40,40,40,40,40,40,40,40,40,40,40,40,40,40,40,40,40,40,40,40,40,40,40,40,40,40,92,1
92,92,55,55,40,40,40,40,40,40,40,40,40,40,40,40,40,40,40,40,40,40,40,40,40,40,40,40,40,40,92,1
92,92,55,55,40,40,40,40,40,40,40,40,40,40,40,40,40,40,40,40,40,40,40,40,40,40,40,40,40,40,92,1
92,92,92,92,92,92,92,92,92,92,92,92,92,92,92,92,92,92,92,92,92,92,92,92,92,92,92,92,92,92,92,1
1,1,1,1,1,1,1,1,1,1,1,1,1,1,1,1,1,1,1,1,1,1,1,1,1,1,1,1,1,1,1,1
endlayer

layer
1,1,1,1,1,1,1,1,1,1,1,1,1,1,1,1,1,1,1,1,1,1,1,1,1,1,1,1,1,1,1,1
92,92,92,92,92,92,92,92,92,92,92,92,92,92,92,92,92,92,92,92,92,92,92,92,92,92,92,92,92,92,92,1
92,92,10,10,92,40,40,97,97,56,56,56,56,56,56,56,56,56,56,56,56,56,56,56,56,56,56,56,56,56,92,1
92,92,0,0,96,27,56,40,97,97,56,56,56,56,56,56,56,56,56,56,56,56,56,56,56,56,56,56,56,56,92,1
92,92,0,0,96,27,56,56,40,97,97,97,97,97,97,56,97,97,97,97,56,56,56,40,40,56,56,56,56,56,92,1
92,92,0,0,96,27,56,56,56,40,40,40,40,40,97,97,97,40,40,97,97,56,56,40,40,56,56,56,56,56,92,1
92,0,0,0,55,27,56,56,56,56,56,40,56,56,40,40,40,9,56,40,97,56,56,56,56,56,40,40,40,40,92,1
92,0,0,0,55,27,27,56,56,56,56,40,56,56,56,56,9,56,56,40,97,56,56,56,40,40,40,56,56,56,92,1
92,0,0,0,55,9,27,98,56,56,56,56,56,56,56,9,56,56,56,40,97,97,56,56,56,56,56,56,56,56,92,1
92,0,0,0,55,56,9,98,56,56,56,56,56,56,9,56,56,56,40,40,56,97,56,56,56,56,56,56,56,56,92,1
92,0,0,0,55,56,56,9,56,56,40,40,40,9,56,56,56,40,40,40,56,97,97,97,97,97,97,97,97,97,92,1
92,0,0,0,55,10,10,10,10,10,21,10,10,10,10,10,10,40,40,40,56,31,31,36,36,36,31,31,31,31,92,1
92,0,0,0,55,56,56,9,56,56,40,40,40,9,56,56,56,40,40,40,56,97,97,97,97,97,97,97,97,97,92,1
92,0,0,0,55,56,9,99,56,56,56,56,56,56,9,56,56,56,40,40,56,97,56,56,56,56,56,56,56,56,92,1
92,0,0,0,55,9,22,28,56,56,56,56,56,56,56,9,56,56,56,40,97,97,56,56,56,56,56,56,56,56,92,1
92,0,0,0,55,16,16,56,56,56,56,40,56,56,56,56,9,56,56,40,97,56,56,56,40,40,40,56,56,56,92,1
92,0,0,0,55,16,56,56,56,56,56,40,56,56,40,40,40,9,56,40,97,56,56,56,56,56,40,40,40,40,92,1
92,92,0,0,96,22,56,56,56,40,40,40,40,40,97,97,97,40,40,97,97,56,56,40,40,56,56,56,56,56,92,1
92,92,0,0,96,16,56,56,40,97,97,97,97,97,97,56,97,97,97,97,56,56,56,40,40,56,56,56,56,56,92,1
92,92,0,0,96,16,56,40,97,97,56,56,56,56,56,56,56,56,56,56,56,56,56,56,56,56,56,56,56,56,92,1
92,92,10,10,92,40,40,97,97,56,56,56,56,56,56,56,56,56,56,56,56,56,56,56,56,56,56,56,56,56,92,1
92,92,92,92,92,92,92,92,92,92,92,92,92,92,92,92,92,92,92,92,92,92,92,92,92,92,92,92,92,92,92,1
1,1,1,1,1,1,1,1,1,1,1,1,1,1,1,1,1,1,1,1,1,1,1,1,1,1,1,1,1,1,1,1
endlayer

layer
0,0,0,0,0,0,0,0,0,0,0,0,0,0,0,0,0,0,0,0,0,0,0,0,0,0,0,0,0,0,0,0
92,92,92,92,92,92,92,92,92,92,92,92,92,92,92,92,92,92,92,92,92,92,92,92,92,92,92,92,92,92,92,0
92,92,10,10,10,10,10,0,0,0,60,60,78,60,0,60,85,85,60,60,60,60,64,60,60,60,100,60,60,0,92,0
92,92,0,0,0,39,85,10,0,0,60,64,60,60,64,102,60,60,101,60,60,60,60,60,60,60,60,60,83,60,92,0
92,92,0,0,0,39,60,60,10,0,0,0,0,0,0,60,0,0,0,0,60,60,60,10,10,60,60,70,103,0,92,0
92,92,0,0,0,39,60,60,0,10,10,10,10,10,38,38,38,10,10,0,0,60,0,10,10,60,60,60,60,60,92,0
92,105,0,0,36,39,60,64,0,0,0,9,60,60,10,10,10,0,60,10,0,104,31,60,60,60,92,92,92,92,92,0
92,0,0,0,36,39,39,60,0,60,60,9,0,85,0,60,0,60,106,10,0,60,60,31,92,92,92,36,36,31,31,0
92,0,0,0,36,0,39,39,96,36,36,36,60,108,60,0,60,60,107,10,0,0,60,31,36,36,36,31,60,64,0,0
92,0,0,0,36,60,0,39,96,36,36,36,0,60,0,0,60,60,10,10,73,0,60,60,64,109,60,64,60,60,0,0
92,0,0,0,36,60,60,0,60,60,10,10,10,0,0,60,0,10,10,10,76,0,0,0,0,0,0,0,0,0,0,0
92,0,0,0,10,0,0,0,0,0,110,0,110,0,0,0,0,9,10,10,76,0,0,0,0,0,0,0,0,0,0,0
92,0,0,0,36,60,0,0,64,60,10,10,10,0,0,64,60,10,10,10,76,0,0,0,0,0,0,0,0,0,0,0
92,0,0,0,36,60,0,39,96,36,36,36,60,60,0,60,60,66,10,10,79,0,60,101,60,60,60,60,60,64,0,0
92,0,0,0,36,0,39,39,96,36,36,36,0,60,0,0,60,0,112,10,0,0,60,31,31,31,31,111,60,0,0,0
92,0,0,0,36,39,39,0,60,0,0,9,60,60,60,0,0,60,113,10,0,60,60,36,92,92,92,31,31,31,31,0
92,114,0,0,36,39,60,60,60,60,0,9,60,60,10,10,10,0,60,10,0,60,31,60,60,0,92,92,92,92,92,0
92,92,0,0,0,39,60,60,60,10,10,10,10,10,38,38,38,10,10,0,0,60,60,10,10,60,60,60,115,60,92,0
92,92,0,0,0,39,60,60,10,0,0,0,0,0,0,0,0,0,0,0,60,60,60,10,10,0,60,60,64,60,92,0
92,92,0,0,0,39,0,10,0,0,60,64,117,60,60,116,64,60,60,60,60,64,60,0,60,64,60,60,60,64,92,0
92,92,10,10,10,10,10,0,0,60,60,60,60,60,60,0,0,60,60,60,60,109,0,60,60,60,60,60,64,60,92,0
92,92,92,92,92,92,92,92,92,92,92,92,92,92,92,92,92,92,92,92,92,92,92,92,92,92,92,92,92,92,92,0
0,0,0,0,0,0,0,0,0,0,0,0,0,0,0,0,0,0,0,0,0,0,0,0,0,0,0,0,0,0,0,0
endlayer

layer
0,0,0,0,0,0,0,0,0,0,0,0,0,0,0,0,0,0,0,0,0,0,0,0,0,0,0,0,0,0,0,0
0,0,0,0,0,0,0,0,0,0,0,0,0,0,0,0,0,0,0,0,0,0,0,0,0,0,0,0,0,0,0,0
118,9,118,9,118,9,118,0,0,0,0,0,0,0,0,0,0,0,0,0,0,0,86,0,0,0,0,0,0,0,0,0
9,118,0,0,0,0,0,9,0,0,0,86,0,0,86,0,0,0,0,0,0,0,0,0,0,0,0,0,0,0,0,0
118,9,0,0,0,0,0,0,118,0,0,0,0,0,0,0,0,0,0,0,0,0,0,10,10,0,0,0,0,0,0,0
9,118,0,0,0,0,0,0,0,9,118,118,118,9,38,38,38,9,118,0,0,0,0,10,10,0,0,0,0,0,0,0
118,9,0,0,36,0,0,86,0,0,119,9,0,0,118,9,118,0,0,9,0,0,0,0,0,0,0,0,0,0,0,0
9,118,0,0,36,0,0,0,0,0,0,9,0,0,0,0,0,0,0,118,0,0,0,31,0,0,0,31,36,31,0,0
118,9,0,0,36,0,0,0,0,0,96,36,36,0,0,0,0,0,0,9,0,0,0,31,36,36,31,31,0,86,0,0
9,118,0,0,36,0,0,0,0,0,96,36,36,0,0,0,0,0,10,73,0,0,0,0,86,0,0,86,0,0,0,0
118,9,0,0,36,0,0,0,0,0,10,10,10,0,0,0,0,10,10,76,0,0,0,0,0,0,0,0,0,0,0,0
9,118,0,0,10,0,0,0,0,0,121,0,120,0,0,0,119,9,10,76,0,0,0,0,0,0,0,0,0,0,0,0
118,9,0,0,36,0,0,0,86,0,10,10,10,0,0,86,0,10,10,76,0,0,0,0,0,0,0,0,0,0,0,0
9,118,0,0,36,0,0,0,0,0,96,36,36,0,0,0,0,0,10,79,0,0,0,0,0,0,0,0,0,86,0,0
118,9,0,0,36,0,0,0,0,0,96,36,36,0,0,0,0,0,0,9,0,0,0,31,31,31,31,0,0,0,0,0
9,118,0,0,36,0,0,0,0,0,0,9,0,0,0,0,0,0,0,118,0,0,0,31,0,0,0,31,31,31,0,0
118,9,0,0,36,0,0,0,0,0,119,9,0,0,118,9,118,0,0,9,0,0,0,0,0,0,0,0,0,0,0,0
9,118,0,0,0,0,0,0,0,9,118,9,118,9,38,38,38,9,118,0,0,0,0,10,10,0,0,0,0,0,0,0
118,9,0,0,0,0,0,0,118,0,0,0,0,0,0,0,0,0,0,0,0,0,0,10,10,0,0,0,86,0,0,0
9,118,0,0,0,0,0,9,0,0,0,86,0,0,0,0,86,0,0,0,0,86,0,0,0,86,0,0,0,86,0,0
118,9,118,9,118,9,118,0,0,0,0,0,0,0,0,0,0,0,0,0,0,0,0,0,0,0,0,0,86,0,0,0
0,0,0,0,0,0,0,0,0,0,0,0,0,0,0,0,0,0,0,0,0,0,0,0,0,0,0,0,0,0,0,0
0,0,0,0,0,0,0,0,0,0,0,0,0,0,0,0,0,0,0,0,0,0,0,0,0,0,0,0,0,0,0,0
endlayer

layer
0,0,0,0,0,0,0,0,0,0,0,0,0,0,0,0,0,0,0,0,0,0,0,0,0,0,0,0,0,0,0,0
0,0,0,0,0,0,0,0,0,0,0,0,0,0,0,0,0,0,0,0,0,0,0,0,0,0,0,0,0,0,0,0
92,92,92,92,92,92,92,0,0,0,0,0,0,0,0,0,0,0,0,0,0,0,0,0,0,0,0,0,0,0,0,0
92,36,76,79,79,79,96,92,0,0,0,0,0,0,0,0,0,0,0,0,0,0,0,0,0,0,0,0,0,0,0,0
92,9,76,18,18,18,79,96,92,0,0,0,0,0,0,0,0,0,0,0,0,0,0,10,10,0,0,0,0,0,0,0
92,36,73,73,73,122,18,79,96,92,92,92,92,92,38,38,38,92,92,0,0,0,0,10,10,0,0,0,0,0,0,0
92,9,36,36,76,122,122,18,96,79,79,79,79,96,92,92,92,56,56,92,0,0,0,0,0,0,0,0,0,0,0,0
92,36,40,36,76,122,122,122,18,18,18,18,18,96,36,92,92,56,56,92,0,0,0,0,0,0,0,0,0,0,0,0
92,9,40,36,76,122,122,0,0,0,0,0,96,36,36,92,92,56,56,92,0,0,0,0,0,0,0,0,0,0,0,0
92,36,36,36,76,122,122,0,0,0,0,0,96,36,36,92,123,56,92,0,0,0,0,0,0,0,0,0,0,0,0,0
92,123,21,21,21,21,21,21,21,21,21,21,21,21,21,21,123,10,73,0,0,0,0,0,0,0,0,0,0,0,0,0
92,123,23,23,23,23,23,23,23,23,23,23,23,23,23,23,123,10,76,0,0,0,0,0,0,0,0,0,0,0,0,0
92,123,21,21,21,21,21,21,21,21,21,21,21,21,21,21,123,10,79,0,0,0,0,0,0,0,0,0,0,0,0,0
92,36,36,36,76,122,122,0,0,0,0,0,96,36,36,92,123,56,92,0,0,0,0,0,0,0,0,0,0,0,0,0
92,9,40,36,76,122,122,0,0,0,0,0,96,36,36,92,92,56,56,92,0,0,0,0,0,0,0,0,0,0,0,0
92,36,40,36,76,122,122,122,18,18,18,18,18,96,36,92,92,56,56,92,0,0,0,0,0,0,0,0,0,0,0,0
92,9,36,36,76,122,122,18,96,73,73,73,73,96,92,92,92,56,56,92,0,0,0,0,0,0,0,0,0,0,0,0
92,36,79,79,76,122,18,73,96,92,92,92,92,92,38,38,38,92,92,0,0,0,0,10,10,0,0,0,0,0,0,0
92,9,76,18,18,18,73,96,92,0,0,0,0,0,0,0,0,0,0,0,0,0,0,10,10,0,0,0,0,0,0,0
92,36,76,73,73,73,96,92,0,0,0,0,0,0,0,0,0,0,0,0,0,0,0,0,0,0,0,0,0,0,0,0
92,92,92,92,92,92,92,0,0,0,0,0,0,0,0,0,0,0,0,0,0,0,0,0,0,0,0,0,0,0,0,0
0,0,0,0,0,0,0,0,0,0,0,0,0,0,0,0,0,0,0,0,0,0,0,0,0,0,0,0,0,0,0,0
0,0,0,0,0,0,0,0,0,0,0,0,0,0,0,0,0,0,0,0,0,0,0,0,0,0,0,0,0,0,0,0
endlayer

layer
0,0,0,0,0,0,0,0,0,0,0,0,0,0,0,0,0,0,0,0,0,0,0,0,0,0,0,0,0,0,0,0
0,0,0,0,0,0,0,0,0,0,0,0,0,0,0,0,0,0,0,0,0,0,0,0,0,0,0,0,0,0,0,0
38,38,124,36,124,36,124,0,0,0,0,0,0,0,0,0,0,0,0,0,0,0,0,0,0,0,0,0,0,0,0,0
38,9,0,0,0,0,0,124,0,0,0,0,0,0,0,0,0,0,0,0,0,0,0,0,0,0,0,0,0,0,0,0
38,36,0,0,0,0,0,0,124,0,0,0,0,0,0,0,0,0,0,0,0,0,0,10,10,0,0,0,0,0,0,0
38,9,0,0,0,0,0,0,0,124,36,124,36,124,38,38,0,0,0,0,0,0,0,10,10,0,0,0,0,0,0,0
38,36,38,38,0,0,0,0,0,0,0,0,0,0,124,0,0,60,0,0,0,0,0,0,0,0,0,0,0,0,0,0
38,9,56,38,0,0,0,0,0,0,0,0,0,0,0,124,38,60,60,0,0,0,0,0,0,0,0,0,0,0,0,0
38,36,56,38,0,0,0,0,0,0,0,0,0,0,0,36,38,60,60,0,0,0,0,0,0,0,0,0,0,0,0,0
38,9,38,38,0,0,0,0,0,0,0,0,0,0,0,72,124,64,0,0,0,0,0,0,0,0,0,0,0,0,0,0
38,10,0,0,0,0,0,0,0,0,0,0,0,0,0,0,0,0,0,0,0,0,0,0,0,0,0,0,0,0,0,0
38,18,0,0,0,0,0,0,0,0,0,0,0,0,0,0,0,0,0,0,0,0,0,0,0,0,0,0,0,0,0,0
38,10,0,0,0,0,0,0,0,0,0,0,0,0,0,0,0,0,0,0,0,0,0,0,0,0,0,0,0,0,0,0
38,9,38,38,0,0,0,0,0,0,0,0,0,0,0,72,124,0,0,0,0,0,0,0,0,0,0,0,0,0,0,0
38,36,56,38,0,0,0,0,0,0,0,0,0,0,0,36,38,0,60,0,0,0,0,0,0,0,0,0,0,0,0,0
38,9,56,38,0,0,0,0,0,0,0,0,0,0,0,124,38,60,0,0,0,0,0,0,0,0,0,0,0,0,0,0
38,36,38,38,0,0,0,0,0,0,0,0,0,0,124,0,0,60,60,0,0,0,0,0,0,0,0,0,0,0,0,0
38,9,0,0,0,0,0,0,0,124,36,124,36,124,38,38,0,0,0,0,0,0,0,10,10,0,0,0,0,0,0,0
38,36,0,0,0,0,0,0,124,0,0,0,0,0,0,0,0,0,0,0,0,0,0,10,10,0,0,0,0,0,0,0
38,9,0,0,0,0,0,124,0,0,0,0,0,0,0,0,0,0,0,0,0,0,0,0,0,0,0,0,0,0,0,0
38,38,124,36,124,36,124,0,0,0,0,0,0,0,0,0,0,0,0,0,0,0,0,0,0,0,0,0,0,0,0,0
0,0,0,0,0,0,0,0,0,0,0,0,0,0,0,0,0,0,0,0,0,0,0,0,0,0,0,0,0,0,0,0
0,0,0,0,0,0,0,0,0,0,0,0,0,0,0,0,0,0,0,0,0,0,0,0,0,0,0,0,0,0,0,0
endlayer

layer
0,0,0,0,0,0,0,0,0,0,0,0,0,0,0,0,0,0,0,0,0,0,0,0,0,0,0,0,0,0,0,0
0,0,0,0,0,0,0,0,0,0,0,0,0,0,0,0,0,0,0,0,0,0,0,0,0,0,0,0,0,0,0,0
0,0,124,38,124,38,124,0,0,0,0,0,0,0,0,0,0,0,0,0,0,0,0,0,0,0,0,0,0,0,0,0
0,36,0,0,0,0,0,124,0,0,0,0,0,0,0,0,0,0,0,0,0,0,0,0,0,0,0,0,0,0,0,0
0,9,0,0,0,0,0,0,124,0,0,0,0,0,0,0,0,0,0,0,0,0,0,10,10,0,0,0,0,0,0,0
0,36,0,0,0,0,0,0,0,124,38,124,38,124,38,0,0,0,0,0,0,0,0,10,10,0,0,0,0,0,0,0
0,9,0,0,0,0,0,0,0,0,0,0,0,0,124,0,0,0,0,0,0,0,0,0,0,0,0,0,0,0,0,0
0,36,126,0,0,0,0,0,0,0,0,0,0,0,0,124,125,0,0,0,0,0,0,0,0,0,0,0,0,0,0,0
0,9,126,0,0,0,0,0,0,0,0,0,0,0,0,36,38,0,0,0,0,0,0,0,0,0,0,0,0,0,0,0
0,36,0,0,0,0,0,0,0,0,0,0,0,0,0,72,124,86,0,0,0,0,0,0,0,0,0,0,0,0,0,0
0,10,0,0,0,0,0,0,0,0,0,0,0,0,0,0,0,0,0,0,0,0,0,0,0,0,0,0,0,0,0,0
0,18,0,0,0,0,0,0,0,0,0,0,0,0,0,0,0,0,0,0,0,0,0,0,0,0,0,0,0,0,0,0
0,10,0,0,0,0,0,0,0,0,0,0,0,0,0,0,0,0,0,0,0,0,0,0,0,0,0,0,0,0,0,0
0,36,0,0,0,0,0,0,0,0,0,0,0,0,0,72,124,0,0,0,0,0,0,0,0,0,0,0,0,0,0,0
0,9,126,0,0,0,0,0,0,0,0,0,0,0,0,36,38,0,0,0,0,0,0,0,0,0,0,0,0,0,0,0
0,36,126,0,0,0,0,0,0,0,0,0,0,0,0,124,125,0,0,0,0,0,0,0,0,0,0,0,0,0,0,0
0,9,0,0,0,0,0,0,0,0,0,0,0,0,124,0,0,0,0,0,0,0,0,0,0,0,0,0,0,0,0,0
0,36,0,0,0,0,0,0,0,124,38,124,38,124,38,0,0,0,0,0,0,0,0,10,10,0,0,0,0,0,0,0
0,9,0,0,0,0,0,0,124,0,0,0,0,0,0,0,0,0,0,0,0,0,0,10,10,0,0,0,0,0,0,0
0,36,0,0,0,0,0,124,0,0,0,0,0,0,0,0,0,0,0,0,0,0,0,0,0,0,0,0,0,0,0,0
0,0,124,38,124,38,124,0,0,0,0,0,0,0,0,0,0,0,0,0,0,0,0,0,0,0,0,0,0,0,0,0
0,0,0,0,0,0,0,0,0,0,0,0,0,0,0,0,0,0,0,0,0,0,0,0,0,0,0,0,0,0,0,0
0,0,0,0,0,0,0,0,0,0,0,0,0,0,0,0,0,0,0,0,0,0,0,0,0,0,0,0,0,0,0,0
endlayer

layer
0,0,0,0,0,0,0,0,0,0,0,0,0,0,0,0,0,0,0,0,0,0,0,0,0,0,0,0,0,0,0,0
0,0,0,0,0,0,0,0,0,0,0,0,0,0,0,0,0,0,0,0,0,0,0,0,0,0,0,0,0,0,0,0
0,0,36,36,36,36,36,0,0,0,0,0,0,0,0,0,0,0,0,0,0,0,0,0,0,0,0,0,0,0,0,0
0,9,0,0,0,0,0,36,0,0,0,0,0,0,0,0,0,0,0,0,0,0,0,0,0,0,0,0,0,0,0,0
0,36,0,0,0,0,0,0,36,0,0,0,0,0,0,0,0,0,0,0,0,0,0,10,10,0,0,0,0,0,0,0
0,9,0,0,0,0,0,0,0,36,36,36,36,36,0,0,0,0,0,0,0,0,0,10,10,0,0,0,0,0,0,0
0,36,0,0,0,0,0,0,0,0,0,0,0,0,36,0,0,0,0,0,0,0,0,0,0,0,0,0,0,0,0,0
0,9,0,0,0,0,0,0,0,0,0,0,0,0,0,36,0,0,0,0,0,0,0,0,0,0,0,0,0,0,0,0
0,36,0,0,0,0,0,0,0,0,0,0,0,0,0,36,0,0,0,0,0,0,0,0,0,0,0,0,0,0,0,0
0,9,0,0,0,0,0,0,0,0,0,0,0,0,0,72,124,0,0,0,0,0,0,0,0,0,0,0,0,0,0,0
0,10,0,0,0,0,0,0,0,0,0,0,0,0,0,0,0,0,0,0,0,0,0,0,0,0,0,0,0,0,0,0
0,18,0,0,0,0,0,0,0,0,0,0,0,0,0,0,0,0,0,0,0,0,0,0,0,0,0,0,0,0,0,0
0,10,0,0,0,0,0,0,0,0,0,0,0,0,0,0,0,0,0,0,0,0,0,0,0,0,0,0,0,0,0,0
0,9,0,0,0,0,0,0,0,0,0,0,0,0,0,72,124,0,0,0,0,0,0,0,0,0,0,0,0,0,0,0
0,36,0,0,0,0,0,0,0,0,0,0,0,0,0,36,0,0,0,0,0,0,0,0,0,0,0,0,0,0,0,0
0,9,0,0,0,0,0,0,0,0,0,0,0,0,0,36,0,0,0,0,0,0,0,0,0,0,0,0,0,0,0,0
0,36,0,0,0,0,0,0,0,0,0,0,0,0,36,0,0,0,0,0,0,0,0,0,0,0,0,0,0,0,0,0
0,9,0,0,0,0,0,0,0,36,36,36,36,36,0,0,0,0,0,0,0,0,0,10,10,0,0,0,0,0,0,0
0,36,0,0,0,0,0,0,36,0,0,0,0,0,0,0,0,0,0,0,0,0,0,10,10,0,0,0,0,0,0,0
0,9,0,0,0,0,0,36,0,0,0,0,0,0,0,0,0,0,0,0,0,0,0,0,0,0,0,0,0,0,0,0
0,0,36,36,36,36,36,0,0,0,0,0,0,0,0,0,0,0,0,0,0,0,0,0,0,0,0,0,0,0,0,0
0,0,0,0,0,0,0,0,0,0,0,0,0,0,0,0,0,0,0,0,0,0,0,0,0,0,0,0,0,0,0,0
0,0,0,0,0,0,0,0,0,0,0,0,0,0,0,0,0,0,0,0,0,0,0,0,0,0,0,0,0,0,0,0
endlayer

layer
0,0,0,0,0,0,0,0,0,0,0,0,0,0,0,0,0,0,0,0,0,0,0,0,0,0,0,0,0,0,0,0
0,0,0,0,0,0,0,0,0,0,0,0,0,0,0,0,0,0,0,0,0,0,0,0,0,0,0,0,0,0,0,0
0,0,72,72,72,72,72,0,0,0,0,0,0,0,0,0,0,0,0,0,0,0,0,0,0,0,0,0,0,0,0,0
0,36,34,34,34,34,33,72,0,0,0,0,0,0,0,0,0,0,0,0,0,0,0,0,0,0,0,0,0,0,0,0
0,72,0,0,0,0,0,34,72,0,0,0,0,0,0,0,0,0,0,0,0,0,0,10,10,0,0,0,0,0,0,0
0,36,0,0,0,0,0,0,34,72,72,72,72,72,0,0,0,0,0,0,0,0,0,10,10,0,0,0,0,0,0,0
0,72,0,0,0,0,0,0,0,34,34,34,34,34,72,0,0,0,0,0,0,0,0,0,0,0,0,0,0,0,0,0
0,36,0,0,0,0,0,0,0,0,0,0,0,0,34,72,0,0,0,0,0,0,0,0,0,0,0,0,0,0,0,0
0,72,0,0,0,0,90,0,0,0,0,0,0,0,34,72,0,0,0,0,0,0,0,0,0,0,0,0,0,0,0,0
0,36,0,0,0,0,0,0,0,0,0,0,0,0,0,127,36,0,0,0,0,0,0,0,0,0,0,0,0,0,0,0
0,72,0,0,0,0,0,0,0,0,0,0,0,0,0,127,36,0,0,0,0,0,0,0,0,0,0,0,0,0,0,0
0,18,0,0,0,0,0,0,0,0,0,0,0,90,0,127,36,0,0,0,0,0,0,0,0,0,0,0,0,0,0,0
0,72,0,0,0,0,0,0,0,0,0,0,0,0,0,127,36,0,0,0,0,0,0,0,0,0,0,0,0,0,0,0
0,36,0,0,0,0,0,0,0,0,0,0,0,0,0,127,36,0,0,0,0,0,0,0,0,0,0,0,0,0,0,0
0,72,0,0,0,0,90,0,0,0,0,0,0,0,34,72,0,0,0,0,0,0,0,0,0,0,0,0,0,0,0,0
0,36,0,0,0,0,0,0,0,0,0,0,0,0,34,72,0,0,0,0,0,0,0,0,0,0,0,0,0,0,0,0
0,72,0,0,0,0,0,0,0,34,34,34,34,34,72,0,0,0,0,0,0,0,0,0,0,0,0,0,0,0,0,0
0,36,0,0,0,0,0,0,34,72,72,72,72,72,0,0,0,0,0,0,0,0,0,10,10,0,0,0,0,0,0,0
0,72,0,0,0,0,0,34,72,0,0,0,0,0,0,0,0,0,0,0,0,0,0,10,10,0,0,0,0,0,0,0
0,36,34,34,34,34,34,72,0,0,0,0,0,0,0,0,0,0,0,0,0,0,0,0,0,0,0,0,0,0,0,0
0,0,72,72,72,72,72,0,0,0,0,0,0,0,0,0,0,0,0,0,0,0,0,0,0,0,0,0,0,0,0,0
0,0,0,0,0,0,0,0,0,0,0,0,0,0,0,0,0,0,0,0,0,0,0,0,0,0,0,0,0,0,0,0
0,0,0,0,0,0,0,0,0,0,0,0,0,0,0,0,0,0,0,0,0,0,0,0,0,0,0,0,0,0,0,0
endlayer

layer
0,0,0,0,0,0,0,0,0,0,0,0,0,0,0,0,0,0,0,0,0,0,0,0,0,0,0,0,0,0,0,0
0,0,0,0,0,0,0,0,0,0,0,0,0,0,0,0,0,0,0,0,0,0,0,0,0,0,0,0,0,0,0,0
0,0,34,36,34,36,33,0,0,0,0,0,0,0,0,0,0,0,0,0,0,0,0,0,0,0,0,0,0,0,0,0
0,18,0,0,0,0,0,31,0,0,0,0,0,0,0,0,0,0,0,0,0,0,0,0,0,0,0,0,0,0,0,0
0,18,31,31,31,31,31,0,33,0,0,0,0,0,0,0,0,0,0,0,0,0,0,10,10,0,0,0,0,0,0,0
0,18,128,128,128,128,31,31,0,31,33,31,33,36,0,0,0,0,0,0,0,0,0,10,10,0,0,0,0,0,0,0
0,18,33,34,34,34,129,36,36,0,0,0,0,0,34,0,0,0,0,0,0,0,0,0,0,0,0,0,0,0,0,0
0,18,33,9,9,9,34,129,36,36,36,36,36,36,0,36,0,0,0,0,0,0,0,0,0,0,0,0,0,0,0,0
0,18,33,9,57,130,9,34,129,129,129,129,128,36,0,36,0,0,0,0,0,0,0,0,0,0,0,0,0,0,0,0
0,18,33,9,9,57,57,9,34,34,34,34,33,128,34,72,0,0,0,0,0,0,0,0,0,0,0,0,0,0,0,0
0,18,33,9,57,9,57,57,9,57,9,57,9,33,36,72,0,0,0,0,0,0,0,0,0,0,0,0,0,0,0,0
0,18,33,57,127,127,9,127,127,127,127,127,127,9,34,72,0,0,0,0,0,0,0,0,0,0,0,0,0,0,0,0
0,18,33,9,57,9,57,57,9,130,9,57,9,33,36,72,0,0,0,0,0,0,0,0,0,0,0,0,0,0,0,0
0,18,33,9,9,57,57,9,34,34,34,34,33,128,34,72,0,0,0,0,0,0,0,0,0,0,0,0,0,0,0,0
0,18,33,9,57,57,9,34,129,129,129,129,128,31,0,36,0,0,0,0,0,0,0,0,0,0,0,0,0,0,0,0
0,18,33,9,9,9,34,128,31,31,31,31,31,31,0,36,0,0,0,0,0,0,0,0,0,0,0,0,0,0,0,0
0,18,33,33,33,33,128,31,31,0,0,0,0,0,34,0,0,0,0,0,0,0,0,0,0,0,0,0,0,0,0,0
0,18,128,128,128,128,31,31,0,31,33,31,33,31,0,0,0,0,0,0,0,0,0,10,10,0,0,0,0,0,0,0
0,18,31,31,31,31,31,0,33,0,0,0,0,0,0,0,0,0,0,0,0,0,0,10,10,0,0,0,0,0,0,0
0,18,0,0,0,0,0,31,0,0,0,0,0,0,0,0,0,0,0,0,0,0,0,0,0,0,0,0,0,0,0,0
0,0,34,36,34,36,33,0,0,0,0,0,0,0,0,0,0,0,0,0,0,0,0,0,0,0,0,0,0,0,0,0
0,0,0,0,0,0,0,0,0,0,0,0,0,0,0,0,0,0,0,0,0,0,0,0,0,0,0,0,0,0,0,0
0,0,0,0,0,0,0,0,0,0,0,0,0,0,0,0,0,0,0,0,0,0,0,0,0,0,0,0,0,0,0,0
endlayer

layer
0,0,0,0,0,0,0,0,0,0,0,0,0,0,0,0,0,0,0,0,0,0,0,0,0,0,0,0,0,0,0,0
0,0,0,0,0,0,0,0,0,0,0,0,0,0,0,0,0,0,0,0,0,0,0,0,0,0,0,0,0,0,0,0
0,0,0,0,0,0,0,0,0,0,0,0,0,0,0,0,0,0,0,0,0,0,0,0,0,0,0,0,0,0,0,0
0,36,0,0,0,0,0,0,0,0,0,0,0,0,0,0,0,0,0,0,0,0,0,0,0,0,0,0,0,0,0,0
0,36,0,0,0,0,0,0,0,0,0,0,0,0,0,0,0,0,0,0,0,0,0,10,10,0,0,0,0,0,0,0
0,36,0,0,0,0,0,0,0,0,0,0,0,0,0,0,0,0,0,0,0,0,0,10,10,0,0,0,0,0,0,0
0,36,0,0,0,0,0,0,0,0,0,0,0,0,0,0,0,0,0,0,0,0,0,0,0,0,0,0,0,0,0,0
0,36,0,0,0,0,0,0,0,0,0,0,0,0,0,0,0,0,0,0,0,0,0,0,0,0,0,0,0,0,0,0
0,36,0,0,0,0,0,0,0,0,0,0,0,0,0,36,0,0,0,0,0,0,0,0,0,0,0,0,0,0,0,0
0,36,0,0,0,0,0,0,0,0,0,0,0,0,34,72,0,0,0,0,0,0,0,0,0,0,0,0,0,0,0,0
0,36,0,0,0,0,0,0,0,0,0,0,0,0,36,72,0,0,0,0,0,0,0,0,0,0,0,0,0,0,0,0
0,36,0,0,0,0,0,0,0,0,0,0,0,0,34,72,0,0,0,0,0,0,0,0,0,0,0,0,0,0,0,0
0,36,0,0,0,0,0,0,0,0,0,0,0,0,36,72,0,0,0,0,0,0,0,0,0,0,0,0,0,0,0,0
0,36,0,0,0,0,0,0,0,0,0,0,0,0,34,72,0,0,0,0,0,0,0,0,0,0,0,0,0,0,0,0
0,36,0,0,0,0,0,0,0,0,0,0,0,0,0,36,0,0,0,0,0,0,0,0,0,0,0,0,0,0,0,0
0,36,0,0,0,0,0,0,0,0,0,0,0,0,0,0,0,0,0,0,0,0,0,0,0,0,0,0,0,0,0,0
0,36,0,0,0,0,0,0,0,0,0,0,0,0,0,0,0,0,0,0,0,0,0,0,0,0,0,0,0,0,0,0
0,36,0,0,0,0,0,0,0,0,0,0,0,0,0,0,0,0,0,0,0,0,0,10,10,0,0,0,0,0,0,0
0,36,0,0,0,0,0,0,0,0,0,0,0,0,0,0,0,0,0,0,0,0,0,10,10,0,0,0,0,0,0,0
0,36,0,0,0,0,0,0,0,0,0,0,0,0,0,0,0,0,0,0,0,0,0,0,0,0,0,0,0,0,0,0
0,0,0,0,0,0,0,0,0,0,0,0,0,0,0,0,0,0,0,0,0,0,0,0,0,0,0,0,0,0,0,0
0,0,0,0,0,0,0,0,0,0,0,0,0,0,0,0,0,0,0,0,0,0,0,0,0,0,0,0,0,0,0,0
0,0,0,0,0,0,0,0,0,0,0,0,0,0,0,0,0,0,0,0,0,0,0,0,0,0,0,0,0,0,0,0
endlayer

layer
0,0,0,0,0,0,0,0,0,0,0,0,0,0,0,0,0,0,0,0,0,0,0,0,0,0,0,0,0,0,0,0
0,0,0,0,0,0,0,0,0,0,0,0,0,0,0,0,0,0,0,0,0,0,0,0,0,0,0,0,0,0,0,0
0,0,0,0,0,0,0,0,0,0,0,0,0,0,0,0,0,0,0,0,0,0,0,0,0,0,0,0,0,0,0,0
0,0,0,0,0,0,0,0,0,0,0,0,0,0,0,0,0,0,0,0,0,0,0,0,0,0,0,0,0,0,0,0
0,0,0,0,0,0,0,0,0,0,0,0,0,0,0,0,0,0,0,0,0,0,0,10,10,0,0,0,0,0,0,0
0,0,0,0,0,0,0,0,0,0,0,0,0,0,0,0,0,0,0,0,0,0,0,10,10,0,0,0,0,0,0,0
0,0,0,0,0,0,0,0,0,0,0,0,0,0,0,0,0,0,0,0,0,0,0,0,0,0,0,0,0,0,0,0
0,0,0,0,0,0,0,0,0,0,0,0,0,0,0,0,0,0,0,0,0,0,0,0,0,0,0,0,0,0,0,0
0,0,0,0,0,0,0,0,0,0,0,0,0,0,0,0,0,0,0,0,0,0,0,0,0,0,0,0,0,0,0,0
0,0,0,0,0,0,0,0,0,0,0,0,0,0,0,31,0,0,0,0,0,0,0,0,0,0,0,0,0,0,0,0
0,0,0,0,0,0,0,0,0,0,0,0,0,0,34,72,0,0,0,0,0,0,0,0,0,0,0,0,0,0,0,0
0,0,0,0,0,0,0,0,0,0,0,0,0,0,34,72,0,0,0,0,0,0,0,0,0,0,0,0,0,0,0,0
0,0,0,0,0,0,0,0,0,0,0,0,0,0,34,72,0,0,0,0,0,0,0,0,0,0,0,0,0,0,0,0
0,0,0,0,0,0,0,0,0,0,0,0,0,0,0,36,0,0,0,0,0,0,0,0,0,0,0,0,0,0,0,0
0,0,0,0,0,0,0,0,0,0,0,0,0,0,0,0,0,0,0,0,0,0,0,0,0,0,0,0,0,0,0,0
0,0,0,0,0,0,0,0,0,0,0,0,0,0,0,0,0,0,0,0,0,0,0,0,0,0,0,0,0,0,0,0
0,0,0,0,0,0,0,0,0,0,0,0,0,0,0,0,0,0,0,0,0,0,0,0,0,0,0,0,0,0,0,0
0,0,0,0,0,0,0,0,0,0,0,0,0,0,0,0,0,0,0,0,0,0,0,10,10,0,0,0,0,0,0,0
0,0,0,0,0,0,0,0,0,0,0,0,0,0,0,0,0,0,0,0,0,0,0,10,10,0,0,0,0,0,0,0
0,0,0,0,0,0,0,0,0,0,0,0,0,0,0,0,0,0,0,0,0,0,0,0,0,0,0,0,0,0,0,0
0,0,0,0,0,0,0,0,0,0,0,0,0,0,0,0,0,0,0,0,0,0,0,0,0,0,0,0,0,0,0,0
0,0,0,0,0,0,0,0,0,0,0,0,0,0,0,0,0,0,0,0,0,0,0,0,0,0,0,0,0,0,0,0
0,0,0,0,0,0,0,0,0,0,0,0,0,0,0,0,0,0,0,0,0,0,0,0,0,0,0,0,0,0,0,0
endlayer

layer
0,0,0,0,0,0,0,0,0,0,0,0,0,0,0,0,0,0,0,0,0,0,0,0,0,0,0,0,0,0,0,0
0,0,0,0,0,0,0,0,0,0,0,0,0,0,0,0,0,0,0,0,0,0,0,0,0,0,0,0,0,0,0,0
0,0,0,0,0,0,0,0,0,0,0,0,0,0,0,0,0,0,0,0,0,0,0,0,0,0,0,0,0,0,0,0
0,0,0,0,0,0,0,0,0,0,0,0,0,0,0,0,0,0,0,0,0,0,0,0,0,0,0,0,0,0,0,0
0,0,0,0,0,0,0,0,0,0,0,0,0,0,0,0,0,0,0,0,0,0,0,10,10,0,0,0,0,0,0,0
0,0,0,0,0,0,0,0,0,0,0,0,0,0,0,0,0,0,0,0,0,0,0,10,10,0,0,0,0,0,0,0
0,0,0,0,0,0,0,0,0,0,0,0,0,0,0,0,0,0,0,0,0,0,0,0,0,0,0,0,0,0,0,0
0,0,0,0,0,0,0,0,0,0,0,0,0,0,0,0,0,0,0,0,0,0,0,0,0,0,0,0,0,0,0,0
0,0,0,0,0,0,0,0,0,0,0,0,0,0,0,0,0,0,0,0,0,0,0,0,0,0,0,0,0,0,0,0
0,0,0,0,0,0,0,0,0,0,0,0,0,0,0,0,0,0,0,0,0,0,0,0,0,0,0,0,0,0,0,0
0,0,0,0,0,0,0,0,0,0,0,0,0,0,0,36,0,0,0,0,0,0,0,0,0,0,0,0,0,0,0,0
0,0,0,0,0,0,0,0,0,0,0,0,0,0,34,72,0,0,0,0,0,0,0,0,0,0,0,0,0,0,0,0
0,0,0,0,0,0,0,0,0,0,0,0,0,0,0,36,0,0,0,0,0,0,0,0,0,0,0,0,0,0,0,0
0,0,0,0,0,0,0,0,0,0,0,0,0,0,0,0,0,0,0,0,0,0,0,0,0,0,0,0,0,0,0,0
0,0,0,0,0,0,0,0,0,0,0,0,0,0,0,0,0,0,0,0,0,0,0,131,131,0,0,0,0,0,0,0
0,0,0,0,0,0,0,0,0,0,0,0,0,0,0,0,0,0,0,0,0,131,131,131,131,131,131,0,0,0,0,0
0,0,0,0,0,0,0,0,0,0,0,0,0,0,0,0,0,0,0,0,0,131,131,131,131,131,131,0,0,0,0,0
0,0,0,0,0,0,0,0,0,0,0,0,0,0,0,0,0,0,0,0,131,131,131,10,10,131,131,131,0,0,0,0
0,0,0,0,0,0,0,0,0,0,0,0,0,0,0,0,0,0,0,0,131,131,131,10,10,131,131,131,0,0,0,0
0,0,0,0,0,0,0,0,0,0,0,0,0,0,0,0,0,0,0,0,0,131,131,131,131,131,131,0,0,0,0,0
0,0,0,0,0,0,0,0,0,0,0,0,0,0,0,0,0,0,0,0,0,131,131,131,131,131,131,0,0,0,0,0
0,0,0,0,0,0,0,0,0,0,0,0,0,0,0,0,0,0,0,0,0,0,0,131,131,0,0,0,0,0,0,0
0,0,0,0,0,0,0,0,0,0,0,0,0,0,0,0,0,0,0,0,0,0,0,0,0,0,0,0,0,0,0,0
endlayer

layer
0,0,0,0,0,0,0,0,0,0,0,0,0,0,0,0,0,0,0,0,0,0,0,0,0,0,0,0,0,0,0,0
0,0,0,0,0,0,0,0,0,0,0,0,0,0,0,0,0,0,0,0,0,0,0,0,0,0,0,0,0,0,0,0
0,0,0,0,0,0,0,0,0,0,0,0,0,0,0,0,0,0,0,0,0,0,0,0,0,0,0,0,0,0,0,0
0,0,0,0,0,0,0,0,0,0,0,0,0,0,0,0,0,0,0,0,0,0,0,0,0,0,0,0,0,0,0,0
0,0,0,0,0,0,0,0,0,0,0,0,0,0,0,0,0,0,0,0,0,0,0,10,10,0,0,0,0,0,0,0
0,0,0,0,0,0,0,0,0,0,0,0,0,0,0,0,0,0,0,0,0,0,0,10,10,0,0,0,0,0,0,0
0,0,0,0,0,0,0,0,0,0,0,0,0,0,0,0,0,0,0,0,0,0,0,0,0,0,0,0,0,0,0,0
0,0,0,0,0,0,0,0,0,0,0,0,0,0,0,0,0,0,0,0,0,0,0,0,0,0,0,0,0,0,0,0
0,0,0,0,0,0,0,0,0,0,0,0,0,0,0,0,0,0,0,0,0,0,0,0,0,0,0,0,0,0,0,0
0,0,0,0,0,0,0,0,0,0,0,0,0,0,0,0,0,0,0,0,0,0,0,0,0,0,0,0,0,0,0,0
0,0,0,0,0,0,0,0,0,0,0,0,0,0,0,0,0,0,0,0,0,0,0,0,0,0,0,0,0,0,0,0
0,0,0,0,0,0,0,0,0,0,0,0,0,0,0,36,0,0,0,0,0,0,0,0,0,0,0,0,0,0,0,0
0,0,0,0,0,0,0,0,0,0,0,0,0,0,0,0,0,0,0,0,0,0,0,0,0,0,0,0,0,0,0,0
0,0,0,0,0,0,0,0,0,0,0,0,0,0,0,0,0,0,0,0,0,0,0,131,131,0,0,0,0,0,0,0
0,0,0,0,0,0,0,0,0,0,0,0,0,0,0,0,0,0,0,0,0,131,131,131,131,131,131,0,0,0,0,0
0,0,0,0,0,0,0,0,0,0,0,0,0,0,0,0,0,0,0,0,131,131,131,131,131,131,131,131,0,0,0,0
0,0,0,0,0,0,0,0,0,0,0,0,0,0,0,0,0,0,0,0,131,131,131,131,131,131,131,131,0,0,0,0
0,0,0,0,0,0,0,0,0,0,0,0,0,0,0,0,0,0,0,131,131,131,131,10,10,131,131,131,131,0,0,0
0,0,0,0,0,0,0,0,0,0,0,0,0,0,0,0,0,0,0,131,131,131,131,10,10,131,131,131,131,0,0,0
0,0,0,0,0,0,0,0,0,0,0,0,0,0,0,0,0,0,0,0,131,131,131,131,131,131,131,131,0,0,0,0
0,0,0,0,0,0,0,0,0,0,0,0,0,0,0,0,0,0,0,0,131,131,131,131,131,131,131,131,0,0,0,0
0,0,0,0,0,0,0,0,0,0,0,0,0,0,0,0,0,0,0,0,0,131,131,131,131,131,131,0,0,0,0,0
0,0,0,0,0,0,0,0,0,0,0,0,0,0,0,0,0,0,0,0,0,0,0,131,131,0,0,0,0,0,0,0
endlayer

layer
0,0,0,0,0,0,0,0,0,0,0,0,0,0,0,0,0,0,0,0,0,0,0,0,0,0,0,0,0,0,0,0
0,0,0,0,0,0,0,0,0,0,0,0,0,0,0,0,0,0,0,0,0,0,0,0,0,0,0,0,0,0,0,0
0,0,0,0,0,0,0,0,0,0,0,0,0,0,0,0,0,0,0,0,0,0,0,0,0,0,0,0,0,0,0,0
0,0,0,0,0,0,0,0,0,0,0,0,0,0,0,0,0,0,0,0,0,0,0,0,0,0,0,0,0,0,0,0
0,0,0,0,0,0,0,0,0,0,0,0,0,0,0,0,0,0,0,0,0,0,0,10,10,0,0,0,0,0,0,0
0,0,0,0,0,0,0,0,0,0,0,0,0,0,0,0,0,0,0,0,0,0,0,10,10,0,0,0,0,0,0,0
0,0,0,0,0,0,0,0,0,0,0,0,0,0,0,0,0,0,0,0,0,0,0,0,0,0,0,0,0,0,0,0
0,0,0,0,0,0,0,0,0,0,0,0,0,0,0,0,0,0,0,0,0,0,0,0,0,0,0,0,0,0,0,0
0,0,0,0,0,0,0,0,0,0,0,0,0,0,0,0,0,0,0,0,0,0,0,0,0,0,0,0,0,0,0,0
0,0,0,0,0,0,0,0,0,0,0,0,0,0,0,0,0,0,0,0,0,0,0,0,0,0,0,0,0,0,0,0
0,0,0,0,0,0,0,0,0,0,0,0,0,0,0,0,0,0,0,0,0,0,0,0,0,0,0,0,0,0,0,0
0,0,0,0,0,0,0,0,0,0,0,0,0,0,0,0,0,0,0,0,0,0,0,0,0,0,0,0,0,0,0,0
0,0,0,0,0,0,0,0,0,0,0,0,0,0,0,0,0,0,0,0,0,0,0,0,0,0,0,0,0,0,0,0
0,0,0,0,0,0,0,0,0,0,0,0,0,0,0,0,0,0,0,0,0,0,0,0,0,0,0,0,0,0,0,0
0,0,0,0,0,0,0,0,0,0,0,0,0,0,0,0,0,0,0,0,0,0,0,131,131,0,0,0,0,0,0,0
0,0,0,0,0,0,0,0,0,0,0,0,0,0,0,0,0,0,0,0,0,131,131,131,131,131,131,0,0,0,0,0
0,0,0,0,0,0,0,0,0,0,0,0,0,0,0,0,0,0,0,0,0,131,131,131,131,131,131,0,0,0,0,0
0,0,0,0,0,0,0,0,0,0,0,0,0,0,0,0,0,0,0,0,131,131,131,10,10,131,131,131,0,0,0,0
0,0,0,0,0,0,0,0,0,0,0,0,0,0,0,0,0,0,0,0,131,131,131,10,10,131,131,131,0,0,0,0
0,0,0,0,0,0,0,0,0,0,0,0,0,0,0,0,0,0,0,0,0,131,131,131,131,131,131,0,0,0,0,0
0,0,0,0,0,0,0,0,0,0,0,0,0,0,0,0,0,0,0,0,0,131,131,131,131,131,131,0,0,0,0,0
0,0,0,0,0,0,0,0,0,0,0,0,0,0,0,0,0,0,0,0,0,0,0,131,131,0,0,0,0,0,0,0
0,0,0,0,0,0,0,0,0,0,0,0,0,0,0,0,0,0,0,0,0,0,0,0,0,0,0,0,0,0,0,0
endlayer

layer
0,0,0,0,0,0,0,0,0,0,0,0,0,0,0,0,0,0,0,0,0,0,0,0,0,0,0,0,0,0,0,0
0,0,0,0,0,0,0,0,0,0,0,0,0,0,0,0,0,0,0,0,0,0,0,131,131,0,0,0,0,0,0,0
0,0,0,0,0,0,0,0,0,0,0,0,0,0,0,0,0,0,0,0,0,131,131,131,131,131,131,0,0,0,0,0
0,0,0,0,0,0,0,0,0,0,0,0,0,0,0,0,0,0,0,0,0,131,131,131,131,131,131,0,0,0,0,0
0,0,0,0,0,0,0,0,0,0,0,0,0,0,0,0,0,0,0,0,131,131,131,10,10,131,131,131,0,0,0,0
0,0,0,0,0,0,0,0,0,0,0,0,0,0,0,0,0,0,0,0,131,131,131,10,10,131,131,131,0,0,0,0
0,0,0,0,0,0,0,0,0,0,0,0,0,0,0,0,0,0,0,0,0,131,131,131,131,131,131,0,0,0,0,0
0,0,0,0,0,0,0,0,0,0,0,0,0,0,0,0,0,0,0,0,0,131,131,131,131,131,131,0,0,0,0,0
0,0,0,0,0,0,0,0,0,0,0,0,0,0,0,0,0,0,0,0,0,0,0,131,131,0,0,0,0,0,0,0
0,0,0,0,0,0,0,0,0,0,0,0,0,0,0,0,0,0,0,0,0,0,0,0,0,0,0,0,0,0,0,0
0,0,0,0,0,0,0,0,0,0,0,0,0,0,0,0,0,0,0,0,0,0,0,0,0,0,0,0,0,0,0,0
0,0,0,0,0,0,0,0,0,0,0,0,0,0,0,0,0,0,0,0,0,0,0,0,0,0,0,0,0,0,0,0
0,0,0,0,0,0,0,0,0,0,0,0,0,0,0,0,0,0,0,0,0,0,0,0,0,0,0,0,0,0,0,0
0,0,0,0,0,0,0,0,0,0,0,0,0,0,0,0,0,0,0,0,0,0,0,0,0,0,0,0,0,0,0,0
0,0,0,0,0,0,0,0,0,0,0,0,0,0,0,0,0,0,0,0,0,0,0,0,0,0,0,0,0,0,0,0
0,0,0,0,0,0,0,0,0,0,0,0,0,0,0,0,0,0,0,0,0,0,0,131,131,0,0,0,0,0,0,0
0,0,0,0,0,0,0,0,0,0,0,0,0,0,0,0,0,0,0,0,0,0,131,131,131,131,0,0,0,0,0,0
0,0,0,0,0,0,0,0,0,0,0,0,0,0,0,0,0,0,0,0,0,131,131,10,10,131,131,0,0,0,0,0
0,0,0,0,0,0,0,0,0,0,0,0,0,0,0,0,0,0,0,0,0,131,131,10,10,131,131,0,0,0,0,0
0,0,0,0,0,0,0,0,0,0,0,0,0,0,0,0,0,0,0,0,0,0,131,131,131,131,0,0,0,0,0,0
0,0,0,0,0,0,0,0,0,0,0,0,0,0,0,0,0,0,0,0,0,0,0,131,131,0,0,0,0,0,0,0
0,0,0,0,0,0,0,0,0,0,0,0,0,0,0,0,0,0,0,0,0,0,0,0,0,0,0,0,0,0,0,0
0,0,0,0,0,0,0,0,0,0,0,0,0,0,0,0,0,0,0,0,0,0,0,0,0,0,0,0,0,0,0,0
endlayer

layer
0,0,0,0,0,0,0,0,0,0,0,0,0,0,0,0,0,0,0,0,0,0,0,0,0,0,0,0,0,0,0,0
0,0,0,0,0,0,0,0,0,0,0,0,0,0,0,0,0,0,0,0,0,0,0,131,131,0,0,0,0,0,0,0
0,0,0,0,0,0,0,0,0,0,0,0,0,0,0,0,0,0,0,0,0,131,131,131,131,131,131,0,0,0,0,0
0,0,0,0,0,0,0,0,0,0,0,0,0,0,0,0,0,0,0,0,0,131,131,131,131,131,131,0,0,0,0,0
0,0,0,0,0,0,0,0,0,0,0,0,0,0,0,0,0,0,0,0,131,131,131,10,10,131,131,131,0,0,0,0
0,0,0,0,0,0,0,0,0,0,0,0,0,0,0,0,0,0,0,0,131,131,131,10,10,131,131,131,0,0,0,0
0,0,0,0,0,0,0,0,0,0,0,0,0,0,0,0,0,0,0,0,0,131,131,131,131,131,131,0,0,0,0,0
0,0,0,0,0,0,0,0,0,0,0,0,0,0,0,0,0,0,0,0,0,131,131,131,131,131,131,0,0,0,0,0
0,0,0,0,0,0,0,0,0,0,0,0,0,0,0,0,0,0,0,0,0,0,0,131,131,0,0,0,0,0,0,0
0,0,0,0,0,0,0,0,0,0,0,0,0,0,0,0,0,0,0,0,0,0,0,0,0,0,0,0,0,0,0,0
0,0,0,0,0,0,0,0,0,0,0,0,0,0,0,0,0,0,0,0,0,0,0,0,0,0,0,0,0,0,0,0
0,0,0,0,0,0,0,0,0,0,0,0,0,0,0,0,0,0,0,0,0,0,0,0,0,0,0,0,0,0,0,0
0,0,0,0,0,0,0,0,0,0,0,0,0,0,0,0,0,0,0,0,0,0,0,0,0,0,0,0,0,0,0,0
0,0,0,0,0,0,0,0,0,0,0,0,0,0,0,0,0,0,0,0,0,0,0,0,0,0,0,0,0,0,0,0
0,0,0,0,0,0,0,0,0,0,0,0,0,0,0,0,0,0,0,0,0,0,0,0,0,0,0,0,0,0,0,0
0,0,0,0,0,0,0,0,0,0,0,0,0,0,0,0,0,0,0,0,0,0,0,131,131,0,0,0,0,0,0,0
0,0,0,0,0,0,0,0,0,0,0,0,0,0,0,0,0,0,0,0,0,0,131,131,131,131,0,0,0,0,0,0
0,0,0,0,0,0,0,0,0,0,0,0,0,0,0,0,0,0,0,0,0,131,131,10,10,131,131,0,0,0,0,0
0,0,0,0,0,0,0,0,0,0,0,0,0,0,0,0,0,0,0,0,0,131,131,10,10,131,131,0,0,0,0,0
0,0,0,0,0,0,0,0,0,0,0,0,0,0,0,0,0,0,0,0,0,0,131,131,131,131,0,0,0,0,0,0
0,0,0,0,0,0,0,0,0,0,0,0,0,0,0,0,0,0,0,0,0,0,0,131,131,0,0,0,0,0,0,0
0,0,0,0,0,0,0,0,0,0,0,0,0,0,0,0,0,0,0,0,0,0,0,0,0,0,0,0,0,0,0,0
0,0,0,0,0,0,0,0,0,0,0,0,0,0,0,0,0,0,0,0,0,0,0,0,0,0,0,0,0,0,0,0
endlayer

layer
0,0,0,0,0,0,0,0,0,0,0,0,0,0,0,0,0,0,0,0,0,0,0,131,131,0,0,0,0,0,0,0
0,0,0,0,0,0,0,0,0,0,0,0,0,0,0,0,0,0,0,0,0,131,131,131,131,131,131,0,0,0,0,0
0,0,0,0,0,0,0,0,0,0,0,0,0,0,0,0,0,0,0,0,131,131,131,131,131,131,131,131,0,0,0,0
0,0,0,0,0,0,0,0,0,0,0,0,0,0,0,0,0,0,0,0,131,131,131,131,131,131,131,131,0,0,0,0
0,0,0,0,0,0,0,0,0,0,0,0,0,0,0,0,0,0,0,131,131,131,131,10,10,131,131,131,131,0,0,0
0,0,0,0,0,0,0,0,0,0,0,0,0,0,0,0,0,0,0,131,131,131,131,10,10,131,131,131,131,0,0,0
0,0,0,0,0,0,0,0,0,0,0,0,0,0,0,0,0,0,0,0,131,131,131,131,131,131,131,131,0,0,0,0
0,0,0,0,0,0,0,0,0,0,0,0,0,0,0,0,0,0,0,0,131,131,131,131,131,131,131,131,0,0,0,0
0,0,0,0,0,0,0,0,0,0,0,0,0,0,0,0,0,0,0,0,0,131,131,131,131,131,131,0,0,0,0,0
0,0,0,0,0,0,0,0,0,0,0,0,0,0,0,0,0,0,0,0,0,0,0,131,131,0,0,0,0,0,0,0
0,0,0,0,0,0,0,0,0,0,0,0,0,0,0,0,0,0,0,0,0,0,0,0,0,0,0,0,0,0,0,0
0,0,0,0,0,0,0,0,0,0,0,0,0,0,0,0,0,0,0,0,0,0,0,0,0,0,0,0,0,0,0,0
0,0,0,0,0,0,0,0,0,0,0,0,0,0,0,0,0,0,0,0,0,0,0,0,0,0,0,0,0,0,0,0
0,0,0,0,0,0,0,0,0,0,0,0,0,0,0,0,0,0,0,0,0,0,0,0,0,0,0,0,0,0,0,0
0,0,0,0,0,0,0,0,0,0,0,0,0,0,0,0,0,0,0,0,0,0,0,131,131,0,0,0,0,0,0,0
0,0,0,0,0,0,0,0,0,0,0,0,0,0,0,0,0,0,0,0,0,131,131,131,131,131,131,0,0,0,0,0
0,0,0,0,0,0,0,0,0,0,0,0,0,0,0,0,0,0,0,0,0,131,131,131,131,131,131,0,0,0,0,0
0,0,0,0,0,0,0,0,0,0,0,0,0,0,0,0,0,0,0,0,131,131,131,10,10,131,131,131,0,0,0,0
0,0,0,0,0,0,0,0,0,0,0,0,0,0,0,0,0,0,0,0,131,131,131,10,10,131,131,131,0,0,0,0
0,0,0,0,0,0,0,0,0,0,0,0,0,0,0,0,0,0,0,0,0,131,131,131,131,131,131,0,0,0,0,0
0,0,0,0,0,0,0,0,0,0,0,0,0,0,0,0,0,0,0,0,0,131,131,131,131,131,131,0,0,0,0,0
0,0,0,0,0,0,0,0,0,0,0,0,0,0,0,0,0,0,0,0,0,0,0,131,131,0,0,0,0,0,0,0
0,0,0,0,0,0,0,0,0,0,0,0,0,0,0,0,0,0,0,0,0,0,0,0,0,0,0,0,0,0,0,0
endlayer

layer
0,0,0,0,0,0,0,0,0,0,0,0,0,0,0,0,0,0,0,0,0,0,0,0,0,0,0,0,0,0,0,0
0,0,0,0,0,0,0,0,0,0,0,0,0,0,0,0,0,0,0,0,0,0,0,0,0,0,0,0,0,0,0,0
0,0,0,0,0,0,0,0,0,0,0,0,0,0,0,0,0,0,0,0,0,0,0,131,131,0,0,0,0,0,0,0
0,0,0,0,0,0,0,0,0,0,0,0,0,0,0,0,0,0,0,0,0,0,131,131,131,131,0,0,0,0,0,0
0,0,0,0,0,0,0,0,0,0,0,0,0,0,0,0,0,0,0,0,0,131,131,10,10,131,131,0,0,0,0,0
0,0,0,0,0,0,0,0,0,0,0,0,0,0,0,0,0,0,0,0,0,131,131,10,10,131,131,0,0,0,0,0
0,0,0,0,0,0,0,0,0,0,0,0,0,0,0,0,0,0,0,0,0,0,131,131,131,131,0,0,0,0,0,0
0,0,0,0,0,0,0,0,0,0,0,0,0,0,0,0,0,0,0,0,0,0,0,131,131,0,0,0,0,0,0,0
0,0,0,0,0,0,0,0,0,0,0,0,0,0,0,0,0,0,0,0,0,0,0,0,0,0,0,0,0,0,0,0
0,0,0,0,0,0,0,0,0,0,0,0,0,0,0,0,0,0,0,0,0,0,0,0,0,0,0,0,0,0,0,0
0,0,0,0,0,0,0,0,0,0,0,0,0,0,0,0,0,0,0,0,0,0,0,0,0,0,0,0,0,0,0,0
0,0,0,0,0,0,0,0,0,0,0,0,0,0,0,0,0,0,0,0,0,0,0,0,0,0,0,0,0,0,0,0
0,0,0,0,0,0,0,0,0,0,0,0,0,0,0,0,0,0,0,0,0,0,0,0,0,0,0,0,0,0,0,0
0,0,0,0,0,0,0,0,0,0,0,0,0,0,0,0,0,0,0,0,0,0,0,0,0,0,0,0,0,0,0,0
0,0,0,0,0,0,0,0,0,0,0,0,0,0,0,0,0,0,0,0,0,0,0,0,0,0,0,0,0,0,0,0
0,0,0,0,0,0,0,0,0,0,0,0,0,0,0,0,0,0,0,0,0,0,0,131,131,0,0,0,0,0,0,0
0,0,0,0,0,0,0,0,0,0,0,0,0,0,0,0,0,0,0,0,0,0,131,131,131,131,0,0,0,0,0,0
0,0,0,0,0,0,0,0,0,0,0,0,0,0,0,0,0,0,0,0,0,131,131,10,10,131,131,0,0,0,0,0
0,0,0,0,0,0,0,0,0,0,0,0,0,0,0,0,0,0,0,0,0,131,131,10,10,131,131,0,0,0,0,0
0,0,0,0,0,0,0,0,0,0,0,0,0,0,0,0,0,0,0,0,0,0,131,131,131,131,0,0,0,0,0,0
0,0,0,0,0,0,0,0,0,0,0,0,0,0,0,0,0,0,0,0,0,0,0,131,131,0,0,0,0,0,0,0
0,0,0,0,0,0,0,0,0,0,0,0,0,0,0,0,0,0,0,0,0,0,0,0,0,0,0,0,0,0,0,0
0,0,0,0,0,0,0,0,0,0,0,0,0,0,0,0,0,0,0,0,0,0,0,0,0,0,0,0,0,0,0,0
endlayer

layer
0,0,0,0,0,0,0,0,0,0,0,0,0,0,0,0,0,0,0,0,0,0,0,0,0,0,0,0,0,0,0,0
0,0,0,0,0,0,0,0,0,0,0,0,0,0,0,0,0,0,0,0,0,0,0,131,131,0,0,0,0,0,0,0
0,0,0,0,0,0,0,0,0,0,0,0,0,0,0,0,0,0,0,0,0,131,131,131,131,131,131,0,0,0,0,0
0,0,0,0,0,0,0,0,0,0,0,0,0,0,0,0,0,0,0,0,0,131,131,131,131,131,131,0,0,0,0,0
0,0,0,0,0,0,0,0,0,0,0,0,0,0,0,0,0,0,0,0,131,131,131,10,10,131,131,131,0,0,0,0
0,0,0,0,0,0,0,0,0,0,0,0,0,0,0,0,0,0,0,0,131,131,131,10,10,131,131,131,0,0,0,0
0,0,0,0,0,0,0,0,0,0,0,0,0,0,0,0,0,0,0,0,0,131,131,131,131,131,131,0,0,0,0,0
0,0,0,0,0,0,0,0,0,0,0,0,0,0,0,0,0,0,0,0,0,131,131,131,131,131,131,0,0,0,0,0
0,0,0,0,0,0,0,0,0,0,0,0,0,0,0,0,0,0,0,0,0,0,0,131,131,0,0,0,0,0,0,0
0,0,0,0,0,0,0,0,0,0,0,0,0,0,0,0,0,0,0,0,0,0,0,0,0,0,0,0,0,0,0,0
0,0,0,0,0,0,0,0,0,0,0,0,0,0,0,0,0,0,0,0,0,0,0,0,0,0,0,0,0,0,0,0
0,0,0,0,0,0,0,0,0,0,0,0,0,0,0,0,0,0,0,0,0,0,0,0,0,0,0,0,0,0,0,0
0,0,0,0,0,0,0,0,0,0,0,0,0,0,0,0,0,0,0,0,0,0,0,0,0,0,0,0,0,0,0,0
0,0,0,0,0,0,0,0,0,0,0,0,0,0,0,0,0,0,0,0,0,0,0,0,0,0,0,0,0,0,0,0
0,0,0,0,0,0,0,0,0,0,0,0,0,0,0,0,0,0,0,0,0,0,0,131,131,0,0,0,0,0,0,0
0,0,0,0,0,0,0,0,0,0,0,0,0,0,0,0,0,0,0,0,0,131,131,131,131,131,131,0,0,0,0,0
0,0,0,0,0,0,0,0,0,0,0,0,0,0,0,0,0,0,0,0,0,131,131,131,131,131,131,0,0,0,0,0
0,0,0,0,0,0,0,0,0,0,0,0,0,0,0,0,0,0,0,0,131,131,131,10,10,131,131,131,0,0,0,0
0,0,0,0,0,0,0,0,0,0,0,0,0,0,0,0,0,0,0,0,131,131,131,10,10,131,131,131,0,0,0,0
0,0,0,0,0,0,0,0,0,0,0,0,0,0,0,0,0,0,0,0,0,131,131,131,131,131,131,0,0,0,0,0
0,0,0,0,0,0,0,0,0,0,0,0,0,0,0,0,0,0,0,0,0,131,131,131,131,131,131,0,0,0,0,0
0,0,0,0,0,0,0,0,0,0,0,0,0,0,0,0,0,0,0,0,0,0,0,131,131,0,0,0,0,0,0,0
0,0,0,0,0,0,0,0,0,0,0,0,0,0,0,0,0,0,0,0,0,0,0,0,0,0,0,0,0,0,0,0
endlayer

layer
0,0,0,0,0,0,0,0,0,0,0,0,0,0,0,0,0,0,0,0,0,0,0,0,0,0,0,0,0,0,0,0
0,0,0,0,0,0,0,0,0,0,0,0,0,0,0,0,0,0,0,0,0,0,0,0,0,0,0,0,0,0,0,0
0,0,0,0,0,0,0,0,0,0,0,0,0,0,0,0,0,0,0,0,0,0,0,131,131,0,0,0,0,0,0,0
0,0,0,0,0,0,0,0,0,0,0,0,0,0,0,0,0,0,0,0,0,0,131,131,131,131,0,0,0,0,0,0
0,0,0,0,0,0,0,0,0,0,0,0,0,0,0,0,0,0,0,0,0,131,131,10,10,131,131,0,0,0,0,0
0,0,0,0,0,0,0,0,0,0,0,0,0,0,0,0,0,0,0,0,0,131,131,10,10,131,131,0,0,0,0,0
0,0,0,0,0,0,0,0,0,0,0,0,0,0,0,0,0,0,0,0,0,0,131,131,131,131,0,0,0,0,0,0
0,0,0,0,0,0,0,0,0,0,0,0,0,0,0,0,0,0,0,0,0,0,0,131,131,0,0,0,0,0,0,0
0,0,0,0,0,0,0,0,0,0,0,0,0,0,0,0,0,0,0,0,0,0,0,0,0,0,0,0,0,0,0,0
0,0,0,0,0,0,0,0,0,0,0,0,0,0,0,0,0,0,0,0,0,0,0,0,0,0,0,0,0,0,0,0
0,0,0,0,0,0,0,0,0,0,0,0,0,0,0,0,0,0,0,0,0,0,0,0,0,0,0,0,0,0,0,0
0,0,0,0,0,0,0,0,0,0,0,0,0,0,0,0,0,0,0,0,0,0,0,0,0,0,0,0,0,0,0,0
0,0,0,0,0,0,0,0,0,0,0,0,0,0,0,0,0,0,0,0,0,0,0,0,0,0,0,0,0,0,0,0
0,0,0,0,0,0,0,0,0,0,0,0,0,0,0,0,0,0,0,0,0,0,0,0,0,0,0,0,0,0,0,0
0,0,0,0,0,0,0,0,0,0,0,0,0,0,0,0,0,0,0,0,0,0,0,0,0,0,0,0,0,0,0,0
0,0,0,0,0,0,0,0,0,0,0,0,0,0,0,0,0,0,0,0,0,0,0,0,0,0,0,0,0,0,0,0
0,0,0,0,0,0,0,0,0,0,0,0,0,0,0,0,0,0,0,0,0,0,0,131,131,0,0,0,0,0,0,0
0,0,0,0,0,0,0,0,0,0,0,0,0,0,0,0,0,0,0,0,0,0,131,10,10,131,0,0,0,0,0,0
0,0,0,0,0,0,0,0,0,0,0,0,0,0,0,0,0,0,0,0,0,0,131,10,10,131,0,0,0,0,0,0
0,0,0,0,0,0,0,0,0,0,0,0,0,0,0,0,0,0,0,0,0,0,0,131,131,0,0,0,0,0,0,0
0,0,0,0,0,0,0,0,0,0,0,0,0,0,0,0,0,0,0,0,0,0,0,0,0,0,0,0,0,0,0,0
0,0,0,0,0,0,0,0,0,0,0,0,0,0,0,0,0,0,0,0,0,0,0,0,0,0,0,0,0,0,0,0
0,0,0,0,0,0,0,0,0,0,0,0,0,0,0,0,0,0,0,0,0,0,0,0,0,0,0,0,0,0,0,0
endlayer

layer
0,0,0,0,0,0,0,0,0,0,0,0,0,0,0,0,0,0,0,0,0,0,0,0,0,0,0,0,0,0,0,0
0,0,0,0,0,0,0,0,0,0,0,0,0,0,0,0,0,0,0,0,0,0,0,131,131,0,0,0,0,0,0,0
0,0,0,0,0,0,0,0,0,0,0,0,0,0,0,0,0,0,0,0,0,131,131,131,131,131,131,0,0,0,0,0
0,0,0,0,0,0,0,0,0,0,0,0,0,0,0,0,0,0,0,0,0,131,131,131,131,131,131,0,0,0,0,0
0,0,0,0,0,0,0,0,0,0,0,0,0,0,0,0,0,0,0,0,131,131,131,10,10,131,131,131,0,0,0,0
0,0,0,0,0,0,0,0,0,0,0,0,0,0,0,0,0,0,0,0,131,131,131,10,10,131,131,131,0,0,0,0
0,0,0,0,0,0,0,0,0,0,0,0,0,0,0,0,0,0,0,0,0,131,131,131,131,131,131,0,0,0,0,0
0,0,0,0,0,0,0,0,0,0,0,0,0,0,0,0,0,0,0,0,0,131,131,131,131,131,131,0,0,0,0,0
0,0,0,0,0,0,0,0,0,0,0,0,0,0,0,0,0,0,0,0,0,0,0,131,131,0,0,0,0,0,0,0
0,0,0,0,0,0,0,0,0,0,0,0,0,0,0,0,0,0,0,0,0,0,0,0,0,0,0,0,0,0,0,0
0,0,0,0,0,0,0,0,0,0,0,0,0,0,0,0,0,0,0,0,0,0,0,0,0,0,0,0,0,0,0,0
0,0,0,0,0,0,0,0,0,0,0,0,0,0,0,0,0,0,0,0,0,0,0,0,0,0,0,0,0,0,0,0
0,0,0,0,0,0,0,0,0,0,0,0,0,0,0,0,0,0,0,0,0,0,0,0,0,0,0,0,0,0,0,0
0,0,0,0,0,0,0,0,0,0,0,0,0,0,0,0,0,0,0,0,0,0,0,0,0,0,0,0,0,0,0,0
0,0,0,0,0,0,0,0,0,0,0,0,0,0,0,0,0,0,0,0,0,0,0,0,0,0,0,0,0,0,0,0
0,0,0,0,0,0,0,0,0,0,0,0,0,0,0,0,0,0,0,0,0,0,0,131,131,0,0,0,0,0,0,0
0,0,0,0,0,0,0,0,0,0,0,0,0,0,0,0,0,0,0,0,0,0,131,131,131,131,0,0,0,0,0,0
0,0,0,0,0,0,0,0,0,0,0,0,0,0,0,0,0,0,0,0,0,131,131,10,10,131,131,0,0,0,0,0
0,0,0,0,0,0,0,0,0,0,0,0,0,0,0,0,0,0,0,0,0,131,131,10,10,131,131,0,0,0,0,0
0,0,0,0,0,0,0,0,0,0,0,0,0,0,0,0,0,0,0,0,0,0,131,131,131,131,0,0,0,0,0,0
0,0,0,0,0,0,0,0,0,0,0,0,0,0,0,0,0,0,0,0,0,0,0,131,131,0,0,0,0,0,0,0
0,0,0,0,0,0,0,0,0,0,0,0,0,0,0,0,0,0,0,0,0,0,0,0,0,0,0,0,0,0,0,0
0,0,0,0,0,0,0,0,0,0,0,0,0,0,0,0,0,0,0,0,0,0,0,0,0,0,0,0,0,0,0,0
endlayer

layer
0,0,0,0,0,0,0,0,0,0,0,0,0,0,0,0,0,0,0,0,0,0,0,0,0,0,0,0,0,0,0,0
0,0,0,0,0,0,0,0,0,0,0,0,0,0,0,0,0,0,0,0,0,0,0,0,0,0,0,0,0,0,0,0
0,0,0,0,0,0,0,0,0,0,0,0,0,0,0,0,0,0,0,0,0,0,0,0,0,0,0,0,0,0,0,0
0,0,0,0,0,0,0,0,0,0,0,0,0,0,0,0,0,0,0,0,0,0,0,131,131,0,0,0,0,0,0,0
0,0,0,0,0,0,0,0,0,0,0,0,0,0,0,0,0,0,0,0,0,0,131,10,10,131,0,0,0,0,0,0
0,0,0,0,0,0,0,0,0,0,0,0,0,0,0,0,0,0,0,0,0,0,131,10,10,131,0,0,0,0,0,0
0,0,0,0,0,0,0,0,0,0,0,0,0,0,0,0,0,0,0,0,0,0,0,131,131,0,0,0,0,0,0,0
0,0,0,0,0,0,0,0,0,0,0,0,0,0,0,0,0,0,0,0,0,0,0,0,0,0,0,0,0,0,0,0
0,0,0,0,0,0,0,0,0,0,0,0,0,0,0,0,0,0,0,0,0,0,0,0,0,0,0,0,0,0,0,0
0,0,0,0,0,0,0,0,0,0,0,0,0,0,0,0,0,0,0,0,0,0,0,0,0,0,0,0,0,0,0,0
0,0,0,0,0,0,0,0,0,0,0,0,0,0,0,0,0,0,0,0,0,0,0,0,0,0,0,0,0,0,0,0
0,0,0,0,0,0,0,0,0,0,0,0,0,0,0,0,0,0,0,0,0,0,0,0,0,0,0,0,0,0,0,0
0,0,0,0,0,0,0,0,0,0,0,0,0,0,0,0,0,0,0,0,0,0,0,0,0,0,0,0,0,0,0,0
0,0,0,0,0,0,0,0,0,0,0,0,0,0,0,0,0,0,0,0,0,0,0,0,0,0,0,0,0,0,0,0
0,0,0,0,0,0,0,0,0,0,0,0,0,0,0,0,0,0,0,0,0,0,0,0,0,0,0,0,0,0,0,0
0,0,0,0,0,0,0,0,0,0,0,0,0,0,0,0,0,0,0,0,0,0,0,0,0,0,0,0,0,0,0,0
0,0,0,0,0,0,0,0,0,0,0,0,0,0,0,0,0,0,0,0,0,0,0,131,131,0,0,0,0,0,0,0
0,0,0,0,0,0,0,0,0,0,0,0,0,0,0,0,0,0,0,0,0,0,131,10,10,131,0,0,0,0,0,0
0,0,0,0,0,0,0,0,0,0,0,0,0,0,0,0,0,0,0,0,0,0,131,10,10,131,0,0,0,0,0,0
0,0,0,0,0,0,0,0,0,0,0,0,0,0,0,0,0,0,0,0,0,0,0,131,131,0,0,0,0,0,0,0
0,0,0,0,0,0,0,0,0,0,0,0,0,0,0,0,0,0,0,0,0,0,0,0,0,0,0,0,0,0,0,0
0,0,0,0,0,0,0,0,0,0,0,0,0,0,0,0,0,0,0,0,0,0,0,0,0,0,0,0,0,0,0,0
0,0,0,0,0,0,0,0,0,0,0,0,0,0,0,0,0,0,0,0,0,0,0,0,0,0,0,0,0,0,0,0
endlayer

layer
0,0,0,0,0,0,0,0,0,0,0,0,0,0,0,0,0,0,0,0,0,0,0,0,0,0,0,0,0,0,0,0
0,0,0,0,0,0,0,0,0,0,0,0,0,0,0,0,0,0,0,0,0,0,0,0,0,0,0,0,0,0,0,0
0,0,0,0,0,0,0,0,0,0,0,0,0,0,0,0,0,0,0,0,0,0,0,131,131,0,0,0,0,0,0,0
0,0,0,0,0,0,0,0,0,0,0,0,0,0,0,0,0,0,0,0,0,0,131,131,131,131,0,0,0,0,0,0
0,0,0,0,0,0,0,0,0,0,0,0,0,0,0,0,0,0,0,0,0,131,131,10,10,131,131,0,0,0,0,0
0,0,0,0,0,0,0,0,0,0,0,0,0,0,0,0,0,0,0,0,0,131,131,10,10,131,131,0,0,0,0,0
0,0,0,0,0,0,0,0,0,0,0,0,0,0,0,0,0,0,0,0,0,0,131,131,131,131,0,0,0,0,0,0
0,0,0,0,0,0,0,0,0,0,0,0,0,0,0,0,0,0,0,0,0,0,0,131,131,0,0,0,0,0,0,0
0,0,0,0,0,0,0,0,0,0,0,0,0,0,0,0,0,0,0,0,0,0,0,0,0,0,0,0,0,0,0,0
0,0,0,0,0,0,0,0,0,0,0,0,0,0,0,0,0,0,0,0,0,0,0,0,0,0,0,0,0,0,0,0
0,0,0,0,0,0,0,0,0,0,0,0,0,0,0,0,0,0,0,0,0,0,0,0,0,0,0,0,0,0,0,0
0,0,0,0,0,0,0,0,0,0,0,0,0,0,0,0,0,0,0,0,0,0,0,0,0,0,0,0,0,0,0,0
0,0,0,0,0,0,0,0,0,0,0,0,0,0,0,0,0,0,0,0,0,0,0,0,0,0,0,0,0,0,0,0
0,0,0,0,0,0,0,0,0,0,0,0,0,0,0,0,0,0,0,0,0,0,0,0,0,0,0,0,0,0,0,0
0,0,0,0,0,0,0,0,0,0,0,0,0,0,0,0,0,0,0,0,0,0,0,0,0,0,0,0,0,0,0,0
0,0,0,0,0,0,0,0,0,0,0,0,0,0,0,0,0,0,0,0,0,0,0,131,131,0,0,0,0,0,0,0
0,0,0,0,0,0,0,0,0,0,0,0,0,0,0,0,0,0,0,0,0,0,131,131,131,131,0,0,0,0,0,0
0,0,0,0,0,0,0,0,0,0,0,0,0,0,0,0,0,0,0,0,0,131,131,10,10,131,131,0,0,0,0,0
0,0,0,0,0,0,0,0,0,0,0,0,0,0,0,0,0,0,0,0,0,131,131,10,10,131,131,0,0,0,0,0
0,0,0,0,0,0,0,0,0,0,0,0,0,0,0,0,0,0,0,0,0,0,131,131,131,131,0,0,0,0,0,0
0,0,0,0,0,0,0,0,0,0,0,0,0,0,0,0,0,0,0,0,0,0,0,131,131,0,0,0,0,0,0,0
0,0,0,0,0,0,0,0,0,0,0,0,0,0,0,0,0,0,0,0,0,0,0,0,0,0,0,0,0,0,0,0
0,0,0,0,0,0,0,0,0,0,0,0,0,0,0,0,0,0,0,0,0,0,0,0,0,0,0,0,0,0,0,0
endlayer

layer
0,0,0,0,0,0,0,0,0,0,0,0,0,0,0,0,0,0,0,0,0,0,0,0,0,0,0,0,0,0,0,0
0,0,0,0,0,0,0,0,0,0,0,0,0,0,0,0,0,0,0,0,0,0,0,0,0,0,0,0,0,0,0,0
0,0,0,0,0,0,0,0,0,0,0,0,0,0,0,0,0,0,0,0,0,0,0,0,0,0,0,0,0,0,0,0
0,0,0,0,0,0,0,0,0,0,0,0,0,0,0,0,0,0,0,0,0,0,0,131,131,0,0,0,0,0,0,0
0,0,0,0,0,0,0,0,0,0,0,0,0,0,0,0,0,0,0,0,0,0,131,10,10,131,0,0,0,0,0,0
0,0,0,0,0,0,0,0,0,0,0,0,0,0,0,0,0,0,0,0,0,0,131,10,10,131,0,0,0,0,0,0
0,0,0,0,0,0,0,0,0,0,0,0,0,0,0,0,0,0,0,0,0,0,0,131,131,0,0,0,0,0,0,0
0,0,0,0,0,0,0,0,0,0,0,0,0,0,0,0,0,0,0,0,0,0,0,0,0,0,0,0,0,0,0,0
0,0,0,0,0,0,0,0,0,0,0,0,0,0,0,0,0,0,0,0,0,0,0,0,0,0,0,0,0,0,0,0
0,0,0,0,0,0,0,0,0,0,0,0,0,0,0,0,0,0,0,0,0,0,0,0,0,0,0,0,0,0,0,0
0,0,0,0,0,0,0,0,0,0,0,0,0,0,0,0,0,0,0,0,0,0,0,0,0,0,0,0,0,0,0,0
0,0,0,0,0,0,0,0,0,0,0,0,0,0,0,0,0,0,0,0,0,0,0,0,0,0,0,0,0,0,0,0
0,0,0,0,0,0,0,0,0,0,0,0,0,0,0,0,0,0,0,0,0,0,0,0,0,0,0,0,0,0,0,0
0,0,0,0,0,0,0,0,0,0,0,0,0,0,0,0,0,0,0,0,0,0,0,0,0,0,0,0,0,0,0,0
0,0,0,0,0,0,0,0,0,0,0,0,0,0,0,0,0,0,0,0,0,0,0,0,0,0,0,0,0,0,0,0
0,0,0,0,0,0,0,0,0,0,0,0,0,0,0,0,0,0,0,0,0,0,0,0,0,0,0,0,0,0,0,0
0,0,0,0,0,0,0,0,0,0,0,0,0,0,0,0,0,0,0,0,0,0,0,131,131,0,0,0,0,0,0,0
0,0,0,0,0,0,0,0,0,0,0,0,0,0,0,0,0,0,0,0,0,0,131,10,10,131,0,0,0,0,0,0
0,0,0,0,0,0,0,0,0,0,0,0,0,0,0,0,0,0,0,0,0,0,131,10,10,131,0,0,0,0,0,0
0,0,0,0,0,0,0,0,0,0,0,0,0,0,0,0,0,0,0,0,0,0,0,131,131,0,0,0,0,0,0,0
0,0,0,0,0,0,0,0,0,0,0,0,0,0,0,0,0,0,0,0,0,0,0,0,0,0,0,0,0,0,0,0
0,0,0,0,0,0,0,0,0,0,0,0,0,0,0,0,0,0,0,0,0,0,0,0,0,0,0,0,0,0,0,0
0,0,0,0,0,0,0,0,0,0,0,0,0,0,0,0,0,0,0,0,0,0,0,0,0,0,0,0,0,0,0,0
endlayer

layer
0,0,0,0,0,0,0,0,0,0,0,0,0,0,0,0,0,0,0,0,0,0,0,0,0,0,0,0,0,0,0,0
0,0,0,0,0,0,0,0,0,0,0,0,0,0,0,0,0,0,0,0,0,0,0,0,0,0,0,0,0,0,0,0
0,0,0,0,0,0,0,0,0,0,0,0,0,0,0,0,0,0,0,0,0,0,0,131,131,0,0,0,0,0,0,0
0,0,0,0,0,0,0,0,0,0,0,0,0,0,0,0,0,0,0,0,0,0,131,131,131,131,0,0,0,0,0,0
0,0,0,0,0,0,0,0,0,0,0,0,0,0,0,0,0,0,0,0,0,131,131,10,10,131,131,0,0,0,0,0
0,0,0,0,0,0,0,0,0,0,0,0,0,0,0,0,0,0,0,0,0,131,131,10,10,131,131,0,0,0,0,0
0,0,0,0,0,0,0,0,0,0,0,0,0,0,0,0,0,0,0,0,0,0,131,131,131,131,0,0,0,0,0,0
0,0,0,0,0,0,0,0,0,0,0,0,0,0,0,0,0,0,0,0,0,0,0,131,131,0,0,0,0,0,0,0
0,0,0,0,0,0,0,0,0,0,0,0,0,0,0,0,0,0,0,0,0,0,0,0,0,0,0,0,0,0,0,0
0,0,0,0,0,0,0,0,0,0,0,0,0,0,0,0,0,0,0,0,0,0,0,0,0,0,0,0,0,0,0,0
0,0,0,0,0,0,0,0,0,0,0,0,0,0,0,0,0,0,0,0,0,0,0,0,0,0,0,0,0,0,0,0
0,0,0,0,0,0,0,0,0,0,0,0,0,0,0,0,0,0,0,0,0,0,0,0,0,0,0,0,0,0,0,0
0,0,0,0,0,0,0,0,0,0,0,0,0,0,0,0,0,0,0,0,0,0,0,0,0,0,0,0,0,0,0,0
0,0,0,0,0,0,0,0,0,0,0,0,0,0,0,0,0,0,0,0,0,0,0,0,0,0,0,0,0,0,0,0
0,0,0,0,0,0,0,0,0,0,0,0,0,0,0,0,0,0,0,0,0,0,0,0,0,0,0,0,0,0,0,0
0,0,0,0,0,0,0,0,0,0,0,0,0,0,0,0,0,0,0,0,0,0,0,0,0,0,0,0,0,0,0,0
0,0,0,0,0,0,0,0,0,0,0,0,0,0,0,0,0,0,0,0,0,0,0,0,0,0,0,0,0,0,0,0
0,0,0,0,0,0,0,0,0,0,0,0,0,0,0,0,0,0,0,0,0,0,0,10,10,0,0,0,0,0,0,0
0,0,0,0,0,0,0,0,0,0,0,0,0,0,0,0,0,0,0,0,0,0,0,10,10,0,0,0,0,0,0,0
0,0,0,0,0,0,0,0,0,0,0,0,0,0,0,0,0,0,0,0,0,0,0,0,0,0,0,0,0,0,0,0
0,0,0,0,0,0,0,0,0,0,0,0,0,0,0,0,0,0,0,0,0,0,0,0,0,0,0,0,0,0,0,0
0,0,0,0,0,0,0,0,0,0,0,0,0,0,0,0,0,0,0,0,0,0,0,0,0,0,0,0,0,0,0,0
0,0,0,0,0,0,0,0,0,0,0,0,0,0,0,0,0,0,0,0,0,0,0,0,0,0,0,0,0,0,0,0
endlayer

layer
0,0,0,0,0,0,0,0,0,0,0,0,0,0,0,0,0,0,0,0,0,0,0,0,0,0,0,0,0,0,0,0
0,0,0,0,0,0,0,0,0,0,0,0,0,0,0,0,0,0,0,0,0,0,0,0,0,0,0,0,0,0,0,0
0,0,0,0,0,0,0,0,0,0,0,0,0,0,0,0,0,0,0,0,0,0,0,0,0,0,0,0,0,0,0,0
0,0,0,0,0,0,0,0,0,0,0,0,0,0,0,0,0,0,0,0,0,0,0,0,0,0,0,0,0,0,0,0
0,0,0,0,0,0,0,0,0,0,0,0,0,0,0,0,0,0,0,0,0,0,0,10,10,0,0,0,0,0,0,0
0,0,0,0,0,0,0,0,0,0,0,0,0,0,0,0,0,0,0,0,0,0,0,10,10,0,0,0,0,0,0,0
0,0,0,0,0,0,0,0,0,0,0,0,0,0,0,0,0,0,0,0,0,0,0,0,0,0,0,0,0,0,0,0
0,0,0,0,0,0,0,0,0,0,0,0,0,0,0,0,0,0,0,0,0,0,0,0,0,0,0,0,0,0,0,0
0,0,0,0,0,0,0,0,0,0,0,0,0,0,0,0,0,0,0,0,0,0,0,0,0,0,0,0,0,0,0,0
0,0,0,0,0,0,0,0,0,0,0,0,0,0,0,0,0,0,0,0,0,0,0,0,0,0,0,0,0,0,0,0
0,0,0,0,0,0,0,0,0,0,0,0,0,0,0,0,0,0,0,0,0,0,0,0,0,0,0,0,0,0,0,0
0,0,0,0,0,0,0,0,0,0,0,0,0,0,0,0,0,0,0,0,0,0,0,0,0,0,0,0,0,0,0,0
0,0,0,0,0,0,0,0,0,0,0,0,0,0,0,0,0,0,0,0,0,0,0,0,0,0,0,0,0,0,0,0
0,0,0,0,0,0,0,0,0,0,0,0,0,0,0,0,0,0,0,0,0,0,0,0,0,0,0,0,0,0,0,0
0,0,0,0,0,0,0,0,0,0,0,0,0,0,0,0,0,0,0,0,0,0,0,0,0,0,0,0,0,0,0,0
0,0,0,0,0,0,0,0,0,0,0,0,0,0,0,0,0,0,0,0,0,0,0,0,0,0,0,0,0,0,0,0
0,0,0,0,0,0,0,0,0,0,0,0,0,0,0,0,0,0,0,0,0,0,0,0,0,0,0,0,0,0,0,0
0,0,0,0,0,0,0,0,0,0,0,0,0,0,0,0,0,0,0,0,0,0,0,10,10,0,0,0,0,0,0,0
0,0,0,0,0,0,0,0,0,0,0,0,0,0,0,0,0,0,0,0,0,0,0,10,10,0,0,0,0,0,0,0
0,0,0,0,0,0,0,0,0,0,0,0,0,0,0,0,0,0,0,0,0,0,0,0,0,0,0,0,0,0,0,0
0,0,0,0,0,0,0,0,0,0,0,0,0,0,0,0,0,0,0,0,0,0,0,0,0,0,0,0,0,0,0,0
0,0,0,0,0,0,0,0,0,0,0,0,0,0,0,0,0,0,0,0,0,0,0,0,0,0,0,0,0,0,0,0
0,0,0,0,0,0,0,0,0,0,0,0,0,0,0,0,0,0,0,0,0,0,0,0,0,0,0,0,0,0,0,0
endlayer

layer
0,0,0,0,0,0,0,0,0,0,0,0,0,0,0,0,0,0,0,0,0,0,0,0,0,0,0,0,0,0,0,0
0,0,0,0,0,0,0,0,0,0,0,0,0,0,0,0,0,0,0,0,0,0,0,0,0,0,0,0,0,0,0,0
0,0,0,0,0,0,0,0,0,0,0,0,0,0,0,0,0,0,0,0,0,0,0,0,0,0,0,0,0,0,0,0
0,0,0,0,0,0,0,0,0,0,0,0,0,0,0,0,0,0,0,0,0,0,0,131,131,0,0,0,0,0,0,0
0,0,0,0,0,0,0,0,0,0,0,0,0,0,0,0,0,0,0,0,0,0,131,10,10,131,0,0,0,0,0,0
0,0,0,0,0,0,0,0,0,0,0,0,0,0,0,0,0,0,0,0,0,0,131,10,10,131,0,0,0,0,0,0
0,0,0,0,0,0,0,0,0,0,0,0,0,0,0,0,0,0,0,0,0,0,0,131,131,0,0,0,0,0,0,0
0,0,0,0,0,0,0,0,0,0,0,0,0,0,0,0,0,0,0,0,0,0,0,0,0,0,0,0,0,0,0,0
0,0,0,0,0,0,0,0,0,0,0,0,0,0,0,0,0,0,0,0,0,0,0,0,0,0,0,0,0,0,0,0
0,0,0,0,0,0,0,0,0,0,0,0,0,0,0,0,0,0,0,0,0,0,0,0,0,0,0,0,0,0,0,0
0,0,0,0,0,0,0,0,0,0,0,0,0,0,0,0,0,0,0,0,0,0,0,0,0,0,0,0,0,0,0,0
0,0,0,0,0,0,0,0,0,0,0,0,0,0,0,0,0,0,0,0,0,0,0,0,0,0,0,0,0,0,0,0
0,0,0,0,0,0,0,0,0,0,0,0,0,0,0,0,0,0,0,0,0,0,0,0,0,0,0,0,0,0,0,0
0,0,0,0,0,0,0,0,0,0,0,0,0,0,0,0,0,0,0,0,0,0,0,0,0,0,0,0,0,0,0,0
0,0,0,0,0,0,0,0,0,0,0,0,0,0,0,0,0,0,0,0,0,0,0,0,0,0,0,0,0,0,0,0
0,0,0,0,0,0,0,0,0,0,0,0,0,0,0,0,0,0,0,0,0,0,0,0,0,0,0,0,0,0,0,0
0,0,0,0,0,0,0,0,0,0,0,0,0,0,0,0,0,0,0,0,0,0,0,131,131,0,0,0,0,0,0,0
0,0,0,0,0,0,0,0,0,0,0,0,0,0,0,0,0,0,0,0,0,0,131,10,10,131,0,0,0,0,0,0
0,0,0,0,0,0,0,0,0,0,0,0,0,0,0,0,0,0,0,0,0,0,131,10,10,131,0,0,0,0,0,0
0,0,0,0,0,0,0,0,0,0,0,0,0,0,0,0,0,0,0,0,0,0,0,131,131,0,0,0,0,0,0,0
0,0,0,0,0,0,0,0,0,0,0,0,0,0,0,0,0,0,0,0,0,0,0,0,0,0,0,0,0,0,0,0
0,0,0,0,0,0,0,0,0,0,0,0,0,0,0,0,0,0,0,0,0,0,0,0,0,0,0,0,0,0,0,0
0,0,0,0,0,0,0,0,0,0,0,0,0,0,0,0,0,0,0,0,0,0,0,0,0,0,0,0,0,0,0,0
endlayer

layer
0,0,0,0,0,0,0,0,0,0,0,0,0,0,0,0,0,0,0,0,0,0,0,0,0,0,0,0,0,0,0,0
0,0,0,0,0,0,0,0,0,0,0,0,0,0,0,0,0,0,0,0,0,0,0,0,0,0,0,0,0,0,0,0
0,0,0,0,0,0,0,0,0,0,0,0,0,0,0,0,0,0,0,0,0,0,0,0,0,0,0,0,0,0,0,0
0,0,0,0,0,0,0,0,0,0,0,0,0,0,0,0,0,0,0,0,0,0,0,0,0,0,0,0,0,0,0,0
0,0,0,0,0,0,0,0,0,0,0,0,0,0,0,0,0,0,0,0,0,0,0,131,10,0,0,0,0,0,0,0
0,0,0,0,0,0,0,0,0,0,0,0,0,0,0,0,0,0,0,0,0,0,0,131,131,0,0,0,0,0,0,0
0,0,0,0,0,0,0,0,0,0,0,0,0,0,0,0,0,0,0,0,0,0,0,0,0,0,0,0,0,0,0,0
0,0,0,0,0,0,0,0,0,0,0,0,0,0,0,0,0,0,0,0,0,0,0,0,0,0,0,0,0,0,0,0
0,0,0,0,0,0,0,0,0,0,0,0,0,0,0,0,0,0,0,0,0,0,0,0,0,0,0,0,0,0,0,0
0,0,0,0,0,0,0,0,0,0,0,0,0,0,0,0,0,0,0,0,0,0,0,0,0,0,0,0,0,0,0,0
0,0,0,0,0,0,0,0,0,0,0,0,0,0,0,0,0,0,0,0,0,0,0,0,0,0,0,0,0,0,0,0
0,0,0,0,0,0,0,0,0,0,0,0,0,0,0,0,0,0,0,0,0,0,0,0,0,0,0,0,0,0,0,0
0,0,0,0,0,0,0,0,0,0,0,0,0,0,0,0,0,0,0,0,0,0,0,0,0,0,0,0,0,0,0,0
0,0,0,0,0,0,0,0,0,0,0,0,0,0,0,0,0,0,0,0,0,0,0,0,0,0,0,0,0,0,0,0
0,0,0,0,0,0,0,0,0,0,0,0,0,0,0,0,0,0,0,0,0,0,0,0,0,0,0,0,0,0,0,0
0,0,0,0,0,0,0,0,0,0,0,0,0,0,0,0,0,0,0,0,0,0,0,0,0,0,0,0,0,0,0,0
0,0,0,0,0,0,0,0,0,0,0,0,0,0,0,0,0,0,0,0,0,0,0,0,0,0,0,0,0,0,0,0
0,0,0,0,0,0,0,0,0,0,0,0,0,0,0,0,0,0,0,0,0,0,0,131,10,0,0,0,0,0,0,0
0,0,0,0,0,0,0,0,0,0,0,0,0,0,0,0,0,0,0,0,0,0,0,131,131,0,0,0,0,0,0,0
0,0,0,0,0,0,0,0,0,0,0,0,0,0,0,0,0,0,0,0,0,0,0,0,0,0,0,0,0,0,0,0
0,0,0,0,0,0,0,0,0,0,0,0,0,0,0,0,0,0,0,0,0,0,0,0,0,0,0,0,0,0,0,0
0,0,0,0,0,0,0,0,0,0,0,0,0,0,0,0,0,0,0,0,0,0,0,0,0,0,0,0,0,0,0,0
0,0,0,0,0,0,0,0,0,0,0,0,0,0,0,0,0,0,0,0,0,0,0,0,0,0,0,0,0,0,0,0
endlayer

layer
0,0,0,0,0,0,0,0,0,0,0,0,0,0,0,0,0,0,0,0,0,0,0,0,0,0,0,0,0,0,0,0
0,0,0,0,0,0,0,0,0,0,0,0,0,0,0,0,0,0,0,0,0,0,0,0,0,0,0,0,0,0,0,0
0,0,0,0,0,0,0,0,0,0,0,0,0,0,0,0,0,0,0,0,0,0,0,0,0,0,0,0,0,0,0,0
0,0,0,0,0,0,0,0,0,0,0,0,0,0,0,0,0,0,0,0,0,0,0,0,0,0,0,0,0,0,0,0
0,0,0,0,0,0,0,0,0,0,0,0,0,0,0,0,0,0,0,0,0,0,0,131,131,0,0,0,0,0,0,0
0,0,0,0,0,0,0,0,0,0,0,0,0,0,0,0,0,0,0,0,0,0,0,131,131,0,0,0,0,0,0,0
0,0,0,0,0,0,0,0,0,0,0,0,0,0,0,0,0,0,0,0,0,0,0,0,0,0,0,0,0,0,0,0
0,0,0,0,0,0,0,0,0,0,0,0,0,0,0,0,0,0,0,0,0,0,0,0,0,0,0,0,0,0,0,0
0,0,0,0,0,0,0,0,0,0,0,0,0,0,0,0,0,0,0,0,0,0,0,0,0,0,0,0,0,0,0,0
0,0,0,0,0,0,0,0,0,0,0,0,0,0,0,0,0,0,0,0,0,0,0,0,0,0,0,0,0,0,0,0
0,0,0,0,0,0,0,0,0,0,0,0,0,0,0,0,0,0,0,0,0,0,0,0,0,0,0,0,0,0,0,0
0,0,0,0,0,0,0,0,0,0,0,0,0,0,0,0,0,0,0,0,0,0,0,0,0,0,0,0,0,0,0,0
0,0,0,0,0,0,0,0,0,0,0,0,0,0,0,0,0,0,0,0,0,0,0,0,0,0,0,0,0,0,0,0
0,0,0,0,0,0,0,0,0,0,0,0,0,0,0,0,0,0,0,0,0,0,0,0,0,0,0,0,0,0,0,0
0,0,0,0,0,0,0,0,0,0,0,0,0,0,0,0,0,0,0,0,0,0,0,0,0,0,0,0,0,0,0,0
0,0,0,0,0,0,0,0,0,0,0,0,0,0,0,0,0,0,0,0,0,0,0,0,0,0,0,0,0,0,0,0
0,0,0,0,0,0,0,0,0,0,0,0,0,0,0,0,0,0,0,0,0,0,0,0,0,0,0,0,0,0,0,0
0,0,0,0,0,0,0,0,0,0,0,0,0,0,0,0,0,0,0,0,0,0,0,131,131,0,0,0,0,0,0,0
0,0,0,0,0,0,0,0,0,0,0,0,0,0,0,0,0,0,0,0,0,0,0,131,131,0,0,0,0,0,0,0
0,0,0,0,0,0,0,0,0,0,0,0,0,0,0,0,0,0,0,0,0,0,0,0,0,0,0,0,0,0,0,0
0,0,0,0,0,0,0,0,0,0,0,0,0,0,0,0,0,0,0,0,0,0,0,0,0,0,0,0,0,0,0,0
0,0,0,0,0,0,0,0,0,0,0,0,0,0,0,0,0,0,0,0,0,0,0,0,0,0,0,0,0,0,0,0
0,0,0,0,0,0,0,0,0,0,0,0,0,0,0,0,0,0,0,0,0,0,0,0,0,0,0,0,0,0,0,0
endlayer

