
# Created by Ruins mod version 15.0 Ingame Parser
# authoring Player: SunsOfOld

weight=100
embed_into_distance=0
acceptable_target_blocks=
unacceptable_target_blocks=flowing_water,water,flowing_lava,lava
dimensions=18,11,11
allowable_overhang=0
max_leveling=4
leveling_buffer=0
preserve_water=0
preserve_lava=0
uniqueMinDistance=1000000
preventRotation=1

rule1=0,100,minecraft:log2-1
rule2=0,100,UndergroundBiomes:metamorphicCobblestone-7
rule3=0,100,minecraft:planks-5
rule4=0,100,chisel:bookshelf-1
rule5=0,100,chisel:bookshelf-8
rule6=0,100,chisel:bookshelf-7
rule7=0,100,chisel:bookshelf-6
rule8=0,100,chisel:bookshelf-5
rule9=0,100,chisel:bookshelf-4
rule10=0,100,chisel:bookshelf-3
rule11=0,100,minecraft:wooden_door-1
rule12=0,100,minecraft:ladder-2
rule13=0,100,chisel:bookshelf-2
rule14=0,100,UndergroundBiomes:igneousStoneBrick-2
rule15=2,100,minecraft:torch-4
rule16=2,100,minecraft:torch-3
rule17=0,100,minecraft:wooden_door-8
rule18=0,100,chisel:iron_bars-7
rule19=2,100,minecraft:torch-1
rule20=2,100,minecraft:torch-2
rule21=0,100,UndergroundBiomes:igneousStoneBrickHalfSlab-2
rule22=0,100,UndergroundBiomes:stairs-0
rule23=0,100,UndergroundBiomes:stairs-2
rule24=0,100,IInventory;minecraft:chest;VeganOption:chestplateBurlap#1#0#0+minecraft:enchanted_book#{StoredEnchantments:[0:{id:21s,lvl:3s,},],}#0#1-2
rule25=0,100,UndergroundBiomes:stairs-3
rule26=0,100,minecraft:bed-10
rule27=0,100,minecraft:bed-2
rule28=0,100,BiblioCraft:BiblioSeats-0
rule29=0,100,IInventory;BiblioCraft:BiblioDesk;minecraft:writable_book#1#0#0-0
rule30=0,100,minecraft:furnace-2
rule31=0,100,UndergroundBiomes:stairs-1
rule32=0,100,BiblioCraft:Bibliotheca-0
rule33=0,100,UndergroundBiomes:stairs-6
rule34=0,100,UndergroundBiomes:stairs-4
rule35=0,100,UndergroundBiomes:stairs-7
rule36=0,100,UndergroundBiomes:stairs-5

layer
0,0,0,0,0,0,0,0,0,0,0
0,0,0,1,2,2,2,1,0,0,0
0,0,2,3,3,3,3,3,2,0,0
0,1,3,3,3,3,3,3,3,1,0
0,2,3,3,3,3,3,3,3,2,0
0,2,3,3,3,3,3,3,3,2,0
0,2,3,3,3,3,3,3,3,2,0
0,1,3,3,3,3,3,3,3,1,0
0,0,2,3,3,3,3,3,2,0,0
0,0,0,1,2,2,2,1,0,0,0
0,0,0,0,0,0,0,0,0,0,0
endlayer

layer
0,0,0,0,0,0,0,0,0,0,0
0,0,0,1,2,2,2,1,0,0,0
0,0,2,8,7,6,5,4,2,0,0
0,1,9,0,0,0,0,0,0,1,0
0,2,10,0,0,0,0,0,0,2,0
0,2,1,12,0,0,0,0,0,11,0
0,2,13,0,0,0,0,0,0,2,0
0,1,4,0,0,0,0,0,0,1,0
0,0,2,8,9,10,13,4,2,0,0
0,0,0,1,2,2,2,1,0,0,0
0,0,0,0,0,0,0,0,0,0,0
endlayer

layer
0,0,0,0,0,0,0,0,0,0,0
0,0,0,1,14,14,14,1,0,0,0
0,0,14,7,6,5,4,13,14,0,0
0,1,8,0,0,0,0,0,0,1,0
0,14,9,0,0,0,0,0,16,14,15
0,14,1,12,0,0,0,0,0,17,0
0,14,10,0,0,0,0,0,16,14,15
0,1,13,0,0,0,0,0,0,1,0
0,0,14,4,5,6,7,8,14,0,0
0,0,0,1,14,14,14,1,0,0,0
0,0,0,0,0,0,0,0,0,0,0
endlayer

layer
0,0,0,0,0,0,0,0,0,0,0
0,0,0,1,14,14,14,1,0,0,0
0,0,14,9,8,7,6,5,14,0,0
0,1,10,0,0,0,0,0,0,1,0
0,14,13,0,0,0,0,0,0,14,0
0,14,1,12,0,0,0,0,0,14,0
0,14,4,0,0,0,0,0,0,14,0
0,1,5,0,0,0,0,0,0,1,0
0,0,14,6,7,8,9,10,14,0,0
0,0,0,1,14,14,14,1,0,0,0
0,0,0,0,0,0,0,0,0,0,0
endlayer

layer
0,0,0,0,0,0,0,0,0,0,0
0,0,0,1,14,14,14,1,0,0,0
0,0,14,0,0,0,0,0,14,0,0
0,1,0,0,0,0,0,0,0,1,0
0,14,0,0,0,0,0,0,0,14,0
0,14,1,12,0,0,0,0,0,14,0
0,14,0,0,0,0,0,0,0,14,0
0,1,0,0,0,0,0,0,0,1,0
0,0,14,0,0,0,0,0,14,0,0
0,0,0,1,14,14,14,1,0,0,0
0,0,0,0,0,0,0,0,0,0,0
endlayer

layer
0,0,0,0,0,0,0,0,0,0,0
0,0,0,1,14,18,14,1,0,0,0
0,0,14,0,19,0,19,0,14,0,0
0,1,0,0,0,0,0,0,0,1,0
0,14,15,0,0,0,0,0,16,14,0
0,14,1,12,0,0,0,0,0,18,0
0,14,15,0,0,0,0,0,16,14,0
0,1,0,0,0,0,0,0,0,1,0
0,0,14,0,20,0,20,0,14,0,0
0,0,0,1,14,18,14,1,0,0,0
0,0,0,0,0,0,0,0,0,0,0
endlayer

layer
0,0,0,0,0,0,0,0,0,0,0
0,0,0,1,14,18,14,1,0,0,0
0,0,14,0,0,0,0,0,14,0,0
0,1,0,0,0,0,0,0,0,1,0
0,14,0,0,0,0,0,0,0,14,0
0,14,1,12,0,0,0,0,0,18,0
0,14,0,0,0,0,0,0,0,14,0
0,1,0,0,0,0,0,0,0,1,0
0,0,14,0,0,0,0,0,14,0,0
0,0,0,1,14,18,14,1,0,0,0
0,0,0,0,0,0,0,0,0,0,0
endlayer

layer
0,0,0,0,0,0,0,0,0,0,0
0,0,0,1,14,14,14,1,0,0,0
0,0,14,0,0,0,0,0,14,0,0
0,1,0,0,0,0,0,0,0,1,0
0,14,0,0,0,0,0,0,0,14,0
0,14,1,12,0,0,0,0,0,14,0
0,14,0,0,0,0,0,0,0,14,0
0,1,0,0,0,0,0,0,0,1,0
0,0,14,0,0,0,0,0,14,0,0
0,0,0,1,14,14,14,1,0,0,0
0,0,0,0,0,0,0,0,0,0,0
endlayer

layer
0,0,0,0,0,0,0,0,0,0,0
0,0,0,1,14,14,14,1,0,0,0
0,0,14,0,0,0,0,0,14,0,0
0,1,0,0,0,0,0,0,0,1,0
0,14,0,0,0,0,0,0,0,14,0
0,14,1,12,0,0,0,0,0,14,0
0,14,0,0,0,0,0,0,0,14,0
0,1,0,0,0,0,0,0,0,1,0
0,0,14,0,0,0,0,0,14,0,0
0,0,0,1,14,14,14,1,0,0,0
0,0,0,0,0,0,0,0,0,0,0
endlayer

layer
0,0,0,0,0,0,0,0,0,0,0
0,0,0,1,21,21,21,1,0,0,0
0,0,14,2,2,2,2,2,14,0,0
0,1,2,2,2,2,2,2,2,1,0
0,21,2,2,2,2,2,2,2,21,0
0,21,2,12,2,2,2,2,2,21,0
0,21,2,2,2,2,2,2,2,21,0
0,1,2,2,2,2,2,2,2,1,0
0,0,14,2,2,2,2,2,14,0,0
0,0,0,1,21,21,21,1,0,0,0
0,0,0,0,0,0,0,0,0,0,0
endlayer

layer
0,0,0,0,0,0,0,0,0,0,0
0,0,0,22,21,21,21,22,0,0,0
0,0,21,1,2,2,2,1,21,0,0
0,25,1,24,0,0,0,0,1,23,0
0,21,2,0,0,0,27,26,2,21,0
0,21,2,0,0,0,0,0,2,21,0
0,21,2,0,0,0,28,0,2,21,0
0,25,1,30,0,0,29,0,1,23,0
0,0,21,1,2,2,2,1,21,0,0
0,0,0,31,21,21,21,31,0,0,0
0,0,0,0,0,0,0,0,0,0,0
endlayer

layer
0,0,0,0,0,0,0,0,0,0,0
0,0,0,0,0,0,0,0,0,0,0
0,0,0,1,2,2,2,1,0,0,0
0,0,1,0,0,19,0,0,1,0,0
0,0,2,0,0,0,0,0,2,0,0
0,0,2,15,0,0,0,0,2,0,0
0,0,2,0,0,0,0,0,2,0,0
0,0,1,0,0,0,32,0,1,0,0
0,0,0,1,2,2,2,1,0,0,0
0,0,0,0,0,0,0,0,0,0,0
0,0,0,0,0,0,0,0,0,0,0
endlayer

layer
0,0,0,0,0,0,0,0,0,0,0
0,0,0,0,0,0,0,0,0,0,0
0,0,0,1,14,14,14,1,0,0,0
0,0,1,0,0,0,0,0,1,0,0
0,0,14,0,0,0,0,0,14,0,0
0,0,14,0,0,0,0,16,14,0,0
0,0,14,0,0,0,0,0,14,0,0
0,0,1,0,0,20,0,0,1,0,0
0,0,0,1,14,14,14,1,0,0,0
0,0,0,0,0,0,0,0,0,0,0
0,0,0,0,0,0,0,0,0,0,0
endlayer

layer
0,0,0,0,0,0,0,0,0,0,0
0,0,0,0,0,0,0,0,0,0,0
0,0,0,1,14,18,14,1,0,0,0
0,0,1,0,0,0,0,0,1,0,0
0,0,14,0,0,0,0,0,14,0,0
0,0,18,0,0,0,0,0,18,0,0
0,0,14,0,0,0,0,0,14,0,0
0,0,1,0,0,0,0,0,1,0,0
0,0,0,1,14,18,14,1,0,0,0
0,0,0,0,0,0,0,0,0,0,0
0,0,0,0,0,0,0,0,0,0,0
endlayer

layer
0,0,0,0,0,0,0,0,0,0,0
0,0,0,0,0,0,0,0,0,0,0
0,0,0,1,14,18,14,1,0,0,0
0,0,1,0,0,0,0,0,1,0,0
0,0,14,0,0,0,0,0,14,0,0
0,0,18,0,0,0,0,0,18,0,0
0,0,14,0,0,0,0,0,14,0,0
0,0,1,0,0,0,0,0,1,0,0
0,0,0,1,14,18,14,1,0,0,0
0,0,0,0,0,0,0,0,0,0,0
0,0,0,0,0,0,0,0,0,0,0
endlayer

layer
0,0,0,0,0,0,0,0,0,0,0
0,0,0,0,0,0,0,0,0,0,0
0,0,0,1,14,14,14,1,0,0,0
0,0,1,0,0,0,0,0,1,0,0
0,0,14,0,0,0,0,0,14,0,0
0,0,14,0,0,0,0,0,14,0,0
0,0,14,0,0,0,0,0,14,0,0
0,0,1,0,0,0,0,0,1,0,0
0,0,0,1,14,14,14,1,0,0,0
0,0,0,0,0,0,0,0,0,0,0
0,0,0,0,0,0,0,0,0,0,0
endlayer

layer
0,0,0,0,0,0,0,0,0,0,0
0,0,35,34,34,34,34,34,33,0,0
0,34,35,2,2,2,2,2,33,34,0
0,35,2,2,2,2,2,2,2,33,0
0,35,2,2,2,2,2,2,2,33,0
0,35,2,2,2,2,2,2,2,33,0
0,35,2,2,2,2,2,2,2,33,0
0,35,2,2,2,2,2,2,2,33,0
0,36,36,2,2,2,2,2,33,36,0
0,0,35,36,36,36,36,36,33,0,0
0,0,0,0,0,0,0,0,0,0,0
endlayer

layer
0,0,0,0,0,0,0,0,0,0,0
0,0,14,23,23,23,23,23,14,0,0
0,14,0,0,0,0,0,0,0,14,0
0,22,0,0,0,0,0,0,0,22,0
0,22,0,0,0,0,0,0,0,22,0
0,22,0,0,0,0,0,0,0,22,0
0,22,0,0,0,0,0,0,0,22,0
0,22,0,0,0,0,0,0,0,22,0
0,14,0,0,0,0,0,0,0,14,0
0,0,14,25,25,25,25,25,14,0,0
0,0,0,0,0,0,0,0,0,0,0
endlayer

