
# Created by Ruins mod version 15.1 Ingame Parser
# authoring Player: SunsOfOld

weight=100
embed_into_distance=16
acceptable_target_blocks=
unacceptable_target_blocks=flowing_water,water,flowing_lava,lava
dimensions=16,28,10
allowable_overhang=0
max_leveling=6
leveling_buffer=0
preserve_water=0
preserve_lava=0
uniqueMinDistance=1000000
preventRotation=1

rule1=0,100,preserveBlock
rule2=0,100,chisel:tyrian-13
rule3=0,100,minecraft:wool-14
rule4=0,100,chisel:iron2-4
rule5=0,100,chisel:iron_block-15
rule6=0,100,minecraft:lava-0
rule7=0,100,minecraft:redstone_wire-15
rule8=0,100,minecraft:powered_repeater-0
rule9=2,100,minecraft:redstone_torch-1
rule10=0,100,minecraft:redstone_wire-12
rule11=0,100,minecraft:redstone_wire-13
rule12=0,100,minecraft:redstone_wire-14
rule13=0,100,minecraft:powered_repeater-13
rule14=0,100,minecraft:powered_repeater-5
rule15=0,100,minecraft:sticky_piston-9
rule16=0,100,chisel:iron2-0
rule17=0,100,minecraft:web-0
rule18=0,100,IInventory;minecraft:trapped_chest;plantmegapack:oceanCoralWeed#1#0#0+minecraft:diamond#3#0#3+plantmegapack:epiphyteClimbingCactus#1#0#6+minecraft:torch#3#0#9+dendrology:sapling1#1#2#13+plantmegapack:coralPillar#1#0#17+minecraft:diamond#1#0#19+plantmegapack:epiphyteFishBoneCactus#2#0#21+minecraft:diamond#5#0#24-4
rule19=0,100,BiblioCraft:BiblioShelf-1
rule20=0,100,IInventory;BiblioCraft:BiblioTable;BiomesOPlenty:gemOre#6#15#0-1
rule21=0,100,IInventory;minecraft:trapped_chest;minecraft:coal#9#0#0+minecraft:coal#3#0#1+plantmegapack:bambooShortTassledLadder#2#0#3+harvestcraft:beansontoastItem#3#0#4+minecraft:redstone#1#0#6+minecraft:redstone#1#0#7+minecraft:redstone#2#0#8+minecraft:coal#8#0#9+minecraft:coal#10#0#10+minecraft:coal#5#0#11+minecraft:coal#1#0#12+plantmegapack:flowerCandelabraAloe#3#0#15+minecraft:redstone#1#0#16+minecraft:redstone#2#0#17+minecraft:coal#3#0#18+minecraft:coal#7#0#19+minecraft:coal#14#0#20+minecraft:coal#2#0#21+minecraft:coal#2#0#22+dendrology:sapling1#1#0#23+minecraft:redstone#1#0#26-4
rule22=0,100,minecraft:redstone_wire-8
rule23=0,100,minecraft:redstone_wire-7
rule24=0,100,minecraft:redstone_wire-4
rule25=0,100,minecraft:redstone_wire-3
rule26=0,100,minecraft:redstone_wire-9
rule27=0,100,minecraft:sticky_piston-13
rule28=0,100,minecraft:powered_repeater-1
rule29=0,100,minecraft:redstone_wire-11
rule30=0,100,minecraft:redstone_wire-10
rule31=2,100,minecraft:piston_head-13
rule32=0,100,minecraft:sticky_piston-11
rule33=2,100,minecraft:piston_head-11
rule34=2,100,minecraft:piston_head-10
rule35=0,100,minecraft:sticky_piston-10
rule36=0,100,minecraft:redstone_wire-0
rule37=0,100,minecraft:unlit_redstone_torch-5
rule38=2,100,minecraft:piston_head-9
rule39=0,100,chisel:factoryblock-6
rule40=0,100,IInventory;BiblioCraft:BiblioCase;minecraft:diamond_axe#1#0#0-1
rule41=0,100,minecraft:redstone_wire-6
rule42=0,100,minecraft:redstone_wire-5
rule43=2,100,minecraft:redstone_torch-4
rule44=0,100,minecraft:iron_door-2
rule45=0,100,GardenStuff:lantern-1
rule46=0,100,chisel:warningSign-9
rule47=0,100,chisel:warningSign-1
rule48=0,100,GardenStuff:heavy_chain-0
rule49=0,100,minecraft:sticky_piston-5
rule50=0,100,chisel:iron_block-14
rule51=0,100,extrabuttons:extrabuttonsilluminated_button-1
rule52=0,100,minecraft:iron_door-9
rule53=0,100,minecraft:iron_door-8
rule54=0,100,IInventory;minecraft:dispenser;minecraft:potion#1#16452#0-2
rule55=0,100,extrabuttons:extrabuttonsdelay_button-0
rule56=1,100,minecraft:redstone_torch-5
rule57=0,100,chisel:warningSign-13
rule58=0,100,chisel:warningSign-14
rule59=0,100,minecraft:unpowered_repeater-3
rule60=0,100,GardenStuff:light_chain-0
rule61=0,100,minecraft:unlit_redstone_torch-1
rule62=0,100,chisel:laboratoryblock-11
rule63=0,100,chisel:warningSign-12
rule64=0,100,chisel:warningSign-0
rule65=2,100,minecraft:piston_head-8
rule66=0,100,minecraft:sticky_piston-8
rule67=0,100,minecraft:iron_door-0
rule68=0,100,plantmegapack:bambooShortTassledLadder-5
rule69=2,100,minecraft:redstone_torch-3
rule70=0,100,minecraft:sticky_piston-3
rule71=0,100,minecraft:sticky_piston-2
rule72=0,100,minecraft:unpowered_repeater-2
rule73=0,100,minecraft:trapdoor-14

layer
1,1,1,1,1,1,1,1,1,1
1,1,1,1,1,1,1,1,1,1
1,1,1,1,1,1,1,1,1,1
1,1,1,1,1,1,1,1,1,1
1,1,1,1,1,1,1,1,1,1
1,1,1,1,1,1,1,1,1,1
1,1,1,1,1,1,1,1,1,1
1,1,1,1,1,1,1,1,1,1
1,1,1,1,1,1,1,1,1,1
1,1,1,2,2,2,2,1,1,1
1,1,1,2,1,1,2,1,1,1
1,1,1,1,1,1,1,1,1,1
1,1,1,1,1,1,1,1,1,1
1,1,1,1,1,1,1,1,1,1
1,1,3,3,3,1,1,1,1,1
1,1,1,3,3,3,3,1,1,1
1,1,3,1,3,3,1,3,1,1
1,1,3,3,1,1,3,3,1,1
1,1,1,3,1,1,3,1,1,1
1,1,1,1,1,1,1,1,1,1
1,1,1,1,1,1,1,1,1,1
1,1,1,1,1,1,1,1,1,1
1,1,1,1,1,1,1,1,1,1
4,5,5,5,5,5,5,5,5,4
4,5,5,5,5,5,5,5,5,4
4,5,5,5,5,5,5,5,5,4
4,5,5,5,5,5,5,5,5,4
4,4,4,4,4,4,4,4,4,4
endlayer

layer
1,1,1,1,1,1,1,1,1,1
1,1,1,1,1,1,1,1,1,1
1,1,1,1,1,1,1,1,1,1
1,1,1,1,1,1,1,1,1,1
1,1,1,1,1,1,1,1,1,1
1,1,1,1,1,1,1,1,1,1
1,1,4,4,1,1,4,4,1,1
1,1,3,1,1,1,1,3,1,1
1,1,3,2,2,2,2,3,3,3
1,1,2,6,6,6,6,2,1,1
1,1,2,6,2,2,6,2,1,1
1,1,1,2,1,1,2,1,1,1
1,3,3,1,1,1,1,1,1,1
1,1,3,1,1,1,1,1,1,1
1,1,9,8,7,1,1,1,1,1
1,1,3,11,12,11,10,3,1,1
1,1,13,0,14,14,1,13,1,1
1,1,7,12,15,15,12,7,1,1
1,1,1,13,1,1,13,1,1,1
1,1,1,3,15,15,3,1,1,1
1,1,1,1,1,1,1,1,1,1
1,1,1,1,1,1,1,1,1,1
1,4,5,5,5,5,5,5,4,1
4,0,0,0,0,0,0,0,0,4
16,0,0,0,0,0,0,0,0,16
4,0,0,0,0,0,0,0,17,4
16,21,19,19,19,20,19,19,18,16
4,4,16,4,16,4,16,4,16,4
endlayer

layer
1,1,1,1,1,1,1,1,1,1
1,1,1,1,1,1,1,1,1,1
1,1,1,1,1,1,1,1,1,1
1,1,1,1,1,1,1,1,1,1
1,1,1,1,1,1,1,1,1,1
1,1,4,4,1,1,4,4,1,1
1,1,25,24,4,4,23,22,4,1
1,1,28,1,27,27,4,26,1,1
3,3,7,4,31,31,4,30,29,10
3,35,34,5,5,5,5,33,32,3
3,35,34,5,5,5,5,33,32,3
1,1,1,4,5,5,4,1,3,3
1,36,36,5,5,5,5,1,1,1
1,3,36,5,5,5,5,1,1,1
1,1,0,5,5,5,5,1,1,1
1,1,37,1,5,5,1,37,1,1
1,1,1,1,5,5,1,1,1,1
1,1,1,1,38,38,1,1,1,1
1,1,1,1,39,39,1,1,1,1
1,1,1,1,38,38,1,1,1,1
1,1,1,1,5,5,1,1,1,1
1,1,4,5,5,5,5,4,1,1
1,4,0,0,0,0,0,0,4,1
4,40,0,0,0,0,0,0,0,4
16,0,0,0,0,0,0,0,0,16
4,0,0,0,0,0,0,0,0,4
16,19,19,19,19,0,19,19,19,16
4,4,16,4,16,4,16,4,16,4
endlayer

layer
1,1,1,1,1,1,1,1,1,1
1,1,1,1,1,1,1,1,1,1
1,1,1,1,1,1,1,1,1,1
1,1,1,1,1,1,1,1,1,1
1,1,1,1,1,1,1,3,1,1
1,1,1,4,4,4,4,23,1,1
1,1,4,0,42,41,0,0,4,1
1,1,1,4,4,4,0,4,1,1
11,12,0,5,5,5,5,1,1,0
10,1,4,0,0,0,0,4,0,11
29,1,4,0,0,0,0,4,0,12
1,1,1,4,44,44,4,3,43,7
1,0,4,0,0,0,0,4,1,1
1,36,4,0,0,45,0,4,1,1
1,3,4,0,0,0,0,4,1,1
1,3,3,47,0,0,46,3,1,1
1,3,3,4,48,48,4,3,1,1
1,3,3,39,39,39,39,3,1,1
1,3,35,34,39,39,33,32,1,1
1,3,0,39,39,39,39,1,1,1
1,3,0,4,48,48,4,1,1,1
1,3,4,0,48,48,0,4,1,1
1,4,0,0,0,0,0,17,4,1
4,0,0,0,0,0,0,0,0,4
16,0,0,0,0,0,0,0,0,16
4,0,45,0,0,0,0,45,0,4
16,19,19,19,19,19,19,19,19,16
4,4,16,4,16,4,16,4,16,4
endlayer

layer
1,1,1,1,1,1,1,1,1,1
1,1,1,1,1,1,1,1,1,1
1,1,1,1,1,1,3,3,1,1
1,1,1,1,1,1,3,3,1,1
1,1,1,1,1,1,1,41,1,1
1,1,1,3,3,3,4,0,1,1
1,1,4,49,49,49,49,4,1,1
1,1,4,5,5,5,5,4,1,1
1,1,4,0,0,0,0,4,1,1
1,1,50,0,0,0,0,50,1,1
1,1,4,51,0,0,51,4,1,1
1,1,1,4,53,52,4,36,0,1
1,1,4,51,0,0,0,4,1,1
1,0,54,0,0,0,0,50,1,1
1,36,4,55,0,0,0,4,1,1
1,59,56,58,0,0,57,56,1,1
1,36,14,4,48,48,4,14,1,1
1,36,14,39,39,39,39,14,1,1
1,59,35,34,39,39,33,32,1,1
1,36,0,39,39,39,39,1,1,1
1,36,0,4,48,48,4,1,1,1
1,36,4,55,48,48,0,4,1,1
1,4,0,0,0,0,0,17,4,1
4,0,0,0,0,0,0,0,17,4
16,0,0,0,0,0,0,0,0,16
4,0,60,0,0,0,0,60,0,4
16,0,0,0,0,0,0,0,0,16
4,4,16,4,16,4,16,4,16,4
endlayer

layer
1,1,1,1,1,1,1,1,1,1
1,1,1,1,1,1,1,1,1,1
1,1,1,1,1,1,25,24,1,1
1,1,1,1,1,1,28,42,1,1
1,1,1,1,1,1,3,0,1,1
1,1,1,36,36,36,61,0,1,1
1,1,1,5,5,5,5,1,1,1
1,1,4,0,0,0,0,4,1,1
1,1,4,0,0,0,0,4,1,1
1,1,4,0,0,0,0,4,1,1
1,1,4,0,0,0,0,4,1,1
1,1,1,4,4,4,4,1,1,1
1,1,4,0,0,0,0,4,1,1
1,1,4,0,0,0,0,4,1,1
1,1,4,0,0,0,0,4,1,1
1,1,3,64,0,0,63,62,1,1
1,1,62,5,50,50,0,62,1,1
1,1,62,62,65,65,0,62,1,1
1,1,62,62,39,39,0,62,1,1
1,1,62,62,65,65,0,62,1,1
1,1,62,16,4,4,16,62,1,1
1,1,50,48,48,48,48,50,1,1
1,4,0,0,0,0,0,0,4,1
4,0,0,0,0,0,0,0,0,4
16,0,0,0,0,0,0,0,0,16
4,0,60,0,0,0,0,60,0,4
16,17,0,0,0,0,0,0,0,16
4,4,16,4,16,4,16,4,16,4
endlayer

layer
1,1,1,1,1,1,1,1,1,1
1,1,1,1,5,5,1,1,1,1
1,1,4,5,5,5,5,1,1,1
1,1,1,5,5,5,5,1,1,1
1,1,1,5,5,5,5,1,1,1
1,1,1,5,5,5,5,1,1,1
1,1,4,0,0,0,0,4,1,1
1,1,50,0,0,0,0,50,1,1
1,1,4,0,0,0,0,4,1,1
1,1,4,0,0,0,0,4,1,1
1,1,4,4,4,4,4,4,1,1
1,1,1,1,1,1,1,1,1,1
1,1,1,5,5,5,5,1,1,1
1,1,1,5,5,5,5,1,1,1
1,1,1,5,5,5,5,1,1,1
1,1,7,1,5,5,1,1,1,1
1,1,3,3,3,3,3,62,1,1
1,1,1,62,66,66,3,1,1,1
1,1,1,62,62,62,3,1,1,1
1,1,1,62,66,66,3,1,1,1
1,1,1,62,3,3,3,1,1,1
1,1,1,5,5,5,5,1,1,1
1,1,5,5,5,5,5,5,1,1
1,5,5,5,5,5,5,5,5,1
1,5,5,5,5,5,5,5,5,1
1,5,5,5,5,5,5,5,5,1
1,5,5,5,5,5,5,5,5,1
1,1,1,1,1,1,1,1,1,1
endlayer

layer
1,1,1,1,4,4,1,1,1,1
1,1,4,4,0,0,4,1,1,1
35,34,4,0,0,0,0,4,1,1
1,4,4,4,67,67,4,4,1,1
1,1,4,0,0,0,0,4,1,1
1,1,4,0,0,0,0,4,1,1
1,1,4,0,0,0,0,4,1,1
1,1,4,0,0,0,0,4,1,1
1,1,4,0,0,0,0,4,1,1
1,1,4,4,4,4,4,4,1,1
1,1,1,1,1,1,1,1,1,1
1,1,1,1,1,1,1,1,1,1
1,1,1,1,1,1,1,1,1,1
1,1,1,1,1,1,1,1,1,1
1,1,1,1,1,1,1,1,1,1
1,1,0,1,1,1,1,1,1,1
1,1,12,11,10,29,30,1,1,1
1,1,1,1,1,1,28,1,1,1
1,1,1,1,1,1,28,1,1,1
1,1,1,1,1,1,13,1,1,1
1,1,1,1,11,12,7,1,1,1
1,1,1,1,1,1,1,1,1,1
1,1,1,1,1,1,1,1,1,1
1,1,1,1,1,1,1,1,1,1
1,1,1,1,1,1,1,1,1,1
1,1,1,1,1,1,1,1,1,1
1,1,1,1,1,1,1,1,1,1
1,1,1,1,1,1,1,1,1,1
endlayer

layer
1,1,4,1,4,4,1,1,1,1
1,4,6,4,68,68,4,1,1,1
35,34,4,51,0,0,51,4,1,1
4,7,69,4,52,53,4,4,1,1
1,4,50,0,0,0,51,50,1,1
1,1,4,0,0,0,0,4,1,1
1,1,4,0,0,0,0,4,1,1
1,1,4,45,0,0,45,4,1,1
1,1,4,4,4,4,4,4,1,1
1,1,1,1,1,1,1,1,1,1
1,1,1,1,1,1,1,1,1,1
1,1,1,1,1,1,1,1,1,1
1,1,1,1,1,1,1,1,1,1
1,1,1,1,1,1,1,1,1,1
1,1,1,1,1,1,1,1,1,1
1,1,1,1,1,1,1,1,1,1
1,1,1,1,1,1,1,1,1,1
1,1,1,1,1,1,1,1,1,1
1,1,1,1,1,1,1,1,1,1
1,1,1,1,1,1,1,1,1,1
1,1,1,1,1,1,1,1,1,1
1,1,1,1,1,1,1,1,1,1
1,1,1,1,1,1,1,1,1,1
1,1,1,1,1,1,1,1,1,1
1,1,1,1,1,1,1,1,1,1
1,1,1,1,1,1,1,1,1,1
1,1,1,1,1,1,1,1,1,1
1,1,1,1,1,1,1,1,1,1
endlayer

layer
1,1,1,1,4,4,1,1,1,1
1,1,4,4,68,68,4,1,1,1
1,4,4,0,0,0,0,4,1,1
1,4,0,4,4,4,4,4,1,1
1,1,4,0,0,0,0,4,1,1
1,1,4,0,0,0,0,4,1,1
1,1,4,0,0,0,0,4,1,1
1,1,4,4,4,4,4,4,1,1
1,1,1,1,1,1,1,1,1,1
1,1,1,1,1,1,1,1,1,1
1,1,1,1,1,1,1,1,1,1
1,1,1,1,1,1,1,1,1,1
1,1,1,1,1,1,1,1,1,1
1,1,1,1,1,1,1,1,1,1
1,1,1,1,1,1,1,1,1,1
1,1,1,1,1,1,1,1,1,1
1,1,1,1,1,1,1,1,1,1
1,1,1,1,1,1,1,1,1,1
1,1,1,1,1,1,1,1,1,1
1,1,1,1,1,1,1,1,1,1
1,1,1,1,1,1,1,1,1,1
1,1,1,1,1,1,1,1,1,1
1,1,1,1,1,1,1,1,1,1
1,1,1,1,1,1,1,1,1,1
1,1,1,1,1,1,1,1,1,1
1,1,1,1,1,1,1,1,1,1
1,1,1,1,1,1,1,1,1,1
1,1,1,1,1,1,1,1,1,1
endlayer

layer
1,1,1,1,4,4,1,1,1,1
1,1,1,4,68,68,4,1,1,1
1,1,4,4,4,4,4,4,1,1
1,1,4,4,4,4,4,4,1,1
1,1,4,4,4,4,4,4,1,1
1,1,4,4,4,4,4,4,1,1
1,1,4,4,4,4,4,4,1,1
1,1,1,1,1,1,1,1,1,1
1,1,1,1,1,1,1,1,1,1
1,1,1,1,1,1,1,1,1,1
1,1,1,1,1,1,1,1,1,1
1,1,1,1,1,1,1,1,1,1
1,1,1,1,1,1,1,1,1,1
1,1,1,1,1,1,1,1,1,1
1,1,1,1,1,1,1,1,1,1
1,1,1,1,1,1,1,1,1,1
1,1,1,1,1,1,1,1,1,1
1,1,1,1,1,1,1,1,1,1
1,1,1,1,1,1,1,1,1,1
1,1,1,1,1,1,1,1,1,1
1,1,1,1,1,1,1,1,1,1
1,1,1,1,1,1,1,1,1,1
1,1,1,1,1,1,1,1,1,1
1,1,1,1,1,1,1,1,1,1
1,1,1,1,1,1,1,1,1,1
1,1,1,1,1,1,1,1,1,1
1,1,1,1,1,1,1,1,1,1
1,1,1,1,1,1,1,1,1,1
endlayer

layer
1,1,1,1,4,4,1,1,1,1
1,1,35,34,4,4,33,32,1,1
1,1,12,1,4,4,1,11,1,1
1,1,7,69,4,43,7,12,1,1
1,1,1,1,1,1,1,1,1,1
1,1,1,1,1,1,1,1,1,1
1,1,1,1,1,1,1,1,1,1
1,1,1,1,1,1,1,1,1,1
1,1,1,1,1,1,1,1,1,1
1,1,1,1,1,1,1,1,1,1
1,1,1,1,1,1,1,1,1,1
1,1,1,1,1,1,1,1,1,1
1,1,1,1,1,1,1,1,1,1
1,1,1,1,1,1,1,1,1,1
1,1,1,1,1,1,1,1,1,1
1,1,1,1,1,1,1,1,1,1
1,1,1,1,1,1,1,1,1,1
1,1,1,1,1,1,1,1,1,1
1,1,1,1,1,1,1,1,1,1
1,1,1,1,1,1,1,1,1,1
1,1,1,1,1,1,1,1,1,1
1,1,1,1,1,1,1,1,1,1
1,1,1,1,1,1,1,1,1,1
1,1,1,1,1,1,1,1,1,1
1,1,1,1,1,1,1,1,1,1
1,1,1,1,1,1,1,1,1,1
1,1,1,1,1,1,1,1,1,1
1,1,1,1,1,1,1,1,1,1
endlayer

layer
1,1,1,1,4,4,1,1,1,1
1,1,1,4,68,68,4,1,1,1
1,1,1,1,4,4,4,1,1,1
1,1,3,0,36,0,3,3,0,1
1,1,3,3,3,3,3,1,1,1
1,1,1,1,1,1,1,1,1,1
1,1,1,1,1,1,1,1,1,1
1,1,1,1,1,1,1,1,1,1
1,1,1,1,1,1,1,1,1,1
1,1,1,1,1,1,1,1,1,1
1,1,1,1,1,1,1,1,1,1
1,1,1,1,1,1,1,1,1,1
1,1,1,1,1,1,1,1,1,1
1,1,1,1,1,1,1,1,1,1
1,1,1,1,1,1,1,1,1,1
1,1,1,1,1,1,1,1,1,1
1,1,1,1,1,1,1,1,1,1
1,1,1,1,1,1,1,1,1,1
1,1,1,1,1,1,1,1,1,1
1,1,1,1,1,1,1,1,1,1
1,1,1,1,1,1,1,1,1,1
1,1,1,1,1,1,1,1,1,1
1,1,1,1,1,1,1,1,1,1
1,1,1,1,1,1,1,1,1,1
1,1,1,1,1,1,1,1,1,1
1,1,1,1,1,1,1,1,1,1
1,1,1,1,1,1,1,1,1,1
1,1,1,1,1,1,1,1,1,1
endlayer

layer
1,1,1,1,4,4,1,1,1,1
1,1,71,4,68,68,4,70,1,1
1,1,3,4,51,51,4,3,1,1
1,1,36,1,4,4,36,36,1,1
1,1,36,36,72,36,36,1,1,1
1,1,1,1,1,1,1,1,1,1
1,1,1,1,1,1,1,1,1,1
1,1,1,1,1,1,1,1,1,1
1,1,1,1,1,1,1,1,1,1
1,1,1,1,1,1,1,1,1,1
1,1,1,1,1,1,1,1,1,1
1,1,1,1,1,1,1,1,1,1
1,1,1,1,1,1,1,1,1,1
1,1,1,1,1,1,1,1,1,1
1,1,1,1,1,1,1,1,1,1
1,1,1,1,1,1,1,1,1,1
1,1,1,1,1,1,1,1,1,1
1,1,1,1,1,1,1,1,1,1
1,1,1,1,1,1,1,1,1,1
1,1,1,1,1,1,1,1,1,1
1,1,1,1,1,1,1,1,1,1
1,1,1,1,1,1,1,1,1,1
1,1,1,1,1,1,1,1,1,1
1,1,1,1,1,1,1,1,1,1
1,1,1,1,1,1,1,1,1,1
1,1,1,1,1,1,1,1,1,1
1,1,1,1,1,1,1,1,1,1
1,1,1,1,1,1,1,1,1,1
endlayer

layer
1,1,1,1,4,4,1,1,1,1
1,1,71,4,0,0,4,70,1,1
1,1,36,4,4,4,4,36,1,1
1,1,0,1,1,1,1,0,1,1
1,1,1,1,1,1,1,1,1,1
1,1,1,1,1,1,1,1,1,1
1,1,1,1,1,1,1,1,1,1
1,1,1,1,1,1,1,1,1,1
1,1,1,1,1,1,1,1,1,1
1,1,1,1,1,1,1,1,1,1
1,1,1,1,1,1,1,1,1,1
1,1,1,1,1,1,1,1,1,1
1,1,1,1,1,1,1,1,1,1
1,1,1,1,1,1,1,1,1,1
1,1,1,1,1,1,1,1,1,1
1,1,1,1,1,1,1,1,1,1
1,1,1,1,1,1,1,1,1,1
1,1,1,1,1,1,1,1,1,1
1,1,1,1,1,1,1,1,1,1
1,1,1,1,1,1,1,1,1,1
1,1,1,1,1,1,1,1,1,1
1,1,1,1,1,1,1,1,1,1
1,1,1,1,1,1,1,1,1,1
1,1,1,1,1,1,1,1,1,1
1,1,1,1,1,1,1,1,1,1
1,1,1,1,1,1,1,1,1,1
1,1,1,1,1,1,1,1,1,1
1,1,1,1,1,1,1,1,1,1
endlayer

layer
1,1,1,1,4,4,1,1,1,1
1,1,1,4,73,73,4,1,1,1
1,1,1,1,4,4,1,1,1,1
1,1,1,1,1,1,1,1,1,1
1,1,1,1,1,1,1,1,1,1
1,1,1,1,1,1,1,1,1,1
1,1,1,1,1,1,1,1,1,1
1,1,1,1,1,1,1,1,1,1
1,1,1,1,1,1,1,1,1,1
1,1,1,1,1,1,1,1,1,1
1,1,1,1,1,1,1,1,1,1
1,1,1,1,1,1,1,1,1,1
1,1,1,1,1,1,1,1,1,1
1,1,1,1,1,1,1,1,1,1
1,1,1,1,1,1,1,1,1,1
1,1,1,1,1,1,1,1,1,1
1,1,1,1,1,1,1,1,1,1
1,1,1,1,1,1,1,1,1,1
1,1,1,1,1,1,1,1,1,1
1,1,1,1,1,1,1,1,1,1
1,1,1,1,1,1,1,1,1,1
1,1,1,1,1,1,1,1,1,1
1,1,1,1,1,1,1,1,1,1
1,1,1,1,1,1,1,1,1,1
1,1,1,1,1,1,1,1,1,1
1,1,1,1,1,1,1,1,1,1
1,1,1,1,1,1,1,1,1,1
1,1,1,1,1,1,1,1,1,1
endlayer

