
# Created by Ruins mod version 14.9 Ingame Parser
# authoring Player: SunsOfOld

weight=100
embed_into_distance=2
acceptable_target_blocks=
unacceptable_target_blocks=flowing_water,water,flowing_lava,lava
dimensions=10,10,12
allowable_overhang=0
max_leveling=4
leveling_buffer=0
preserve_water=0
preserve_lava=0
uniqueMinDistance=1000000
preventRotation=1

rule1=0,100,preserveBlock
rule2=0,100,BiomesOPlenty:newBopDirt-1
rule3=0,100,BiomesOPlenty:newBopDirt-0
rule4=0,100,BiomesOPlenty:mud-0
rule5=0,100,GardenStuff:moss_brick-1
rule6=0,100,GardenStuff:moss_brick-6
rule7=0,100,GardenStuff:moss_brick-0
rule8=0,100,IInventory;minecraft:dispenser;harvestcraft:mudfishrawItem#5#0#0+harvestcraft:snailrawItem#4#0#2+dendrology:sapling0#1#5#4+harvestcraft:catfishrawItem#5#0#6+harvestcraft:frograwItem#3#0#8-3
rule9=0,100,BiomesOPlenty:foliage-11
rule10=0,100,dendrology:leaves2-7
rule11=0,100,plantmegapack:wetlandsClubrush-0
rule12=0,100,dendrology:leaves2-15
rule13=0,100,plantmegapack:wetlandsCommonRush-0
rule14=0,100,BiomesOPlenty:colorizedLeaves2-4
rule15=0,100,plantmegapack:wetlandsFloweringRush-0
rule16=0,100,plantmegapack:wetlandsCattails-0
rule17=0,100,BiomesOPlenty:colorizedLeaves2-12
rule18=0,100,GardenStuff:lattice-3
rule19=0,100,GardenStuff:heavy_chain-5
rule20=0,100,dendrology:stairs5-4
rule21=0,100,dendrology:stairs5-6
rule22=0,100,dendrology:stairs5-3
rule23=0,100,dendrology:stairs5-1
rule24=0,100,dendrology:stairs5-2
rule25=0,100,dendrology:stairs5-7
rule26=0,100,dendrology:stairs5-0
rule27=0,100,dendrology:stairs5-5
rule28=0,100,dendrology:sslab0-5
rule29=0,100,dendrology:sslab0-13
rule30=0,100,ExtrabiomesXL:woodslab-9
rule31=0,100,ExtrabiomesXL:woodslab-1

layer
1,1,1,1,1,1,1,1,1,1,1,1
1,1,1,1,1,1,1,1,1,1,1,1
1,1,1,1,1,1,1,1,1,1,1,1
1,1,1,1,1,1,1,1,1,1,1,1
1,1,1,1,1,1,1,1,1,1,1,1
1,1,1,1,1,1,1,1,1,1,1,1
1,1,1,1,1,1,1,1,1,1,1,1
1,1,1,1,1,1,1,1,1,1,1,1
1,1,1,1,1,1,1,1,1,1,1,1
1,1,1,1,1,1,1,1,1,1,1,1
endlayer

layer
1,2,1,2,1,3,1,1,3,1,2,1
1,1,4,1,2,1,2,4,1,1,1,3
3,4,1,2,1,2,2,1,2,3,2,1
1,3,2,1,4,2,1,2,4,3,1,3
3,1,2,2,1,1,1,1,1,5,6,5
1,2,3,2,1,1,8,1,1,6,7,1
3,1,2,1,2,2,1,2,4,2,1,2
1,4,1,2,2,2,2,1,3,3,2,1
2,1,4,1,2,1,4,4,1,1,2,1
1,3,1,2,1,3,1,3,1,3,1,2
endlayer

layer
0,11,10,9,0,9,0,10,9,0,9,0
10,5,10,10,11,0,10,12,6,10,0,9
9,12,6,12,10,15,14,7,12,13,9,0
0,16,14,7,14,12,7,17,12,16,0,11
11,10,12,12,6,5,0,5,5,7,0,0
0,9,10,14,5,5,0,6,5,5,0,0
16,10,14,6,14,12,5,17,17,12,0,9
10,10,5,14,15,12,17,5,12,16,13,0
9,6,10,0,16,12,12,12,6,10,9,0
0,9,0,11,0,9,12,16,12,9,0,11
endlayer

layer
0,0,0,0,0,0,0,0,0,0,0,0
0,7,10,0,0,0,0,12,7,0,0,0
0,0,7,18,10,0,18,7,10,0,0,0
0,0,18,5,18,18,5,18,0,0,0,0
0,0,12,18,5,7,18,7,5,0,0,0
0,0,0,18,6,5,18,5,6,0,0,0
0,0,18,5,18,18,6,18,0,0,0,0
0,10,6,18,0,12,18,6,10,0,0,0
0,5,0,0,0,0,0,10,5,0,0,0
0,0,0,0,0,0,0,0,0,0,0,0
endlayer

layer
0,0,0,0,0,0,0,0,0,0,0,0
0,19,0,0,0,0,0,0,19,0,0,0
0,0,5,20,20,20,20,5,0,0,0,0
0,0,25,24,23,23,22,21,0,0,0,0
0,0,25,24,0,0,22,21,0,0,0,0
0,0,25,24,0,0,22,21,0,0,0,0
0,0,25,24,26,26,22,21,0,0,0,0
0,0,6,27,27,27,27,7,0,0,0,0
0,19,0,0,0,0,0,0,19,0,0,0
0,0,0,0,0,0,0,0,0,0,0,0
endlayer

layer
0,0,0,0,0,0,0,0,0,0,0,0
0,19,0,0,0,0,0,0,19,0,0,0
0,0,7,0,0,0,0,7,0,0,0,0
0,0,0,0,0,0,0,0,0,0,0,0
0,0,0,0,0,0,0,0,0,0,0,0
0,0,0,0,0,0,0,0,0,0,0,0
0,0,0,0,0,0,0,0,0,0,0,0
0,0,5,0,0,0,0,5,0,0,0,0
0,19,0,0,0,0,0,0,19,0,0,0
0,0,0,0,0,0,0,0,0,0,0,0
endlayer

layer
0,0,0,0,0,0,0,0,0,0,0,0
0,19,0,0,0,0,0,0,19,0,0,0
0,0,7,0,0,0,0,7,0,0,0,0
0,0,0,0,0,0,0,0,0,0,0,0
0,0,0,0,0,0,0,0,0,0,0,0
0,0,0,0,0,0,0,0,0,0,0,0
0,0,0,0,0,0,0,0,0,0,0,0
0,0,7,0,0,0,0,7,0,0,0,0
0,19,0,0,0,0,0,0,19,0,0,0
0,0,0,0,0,0,0,0,0,0,0,0
endlayer

layer
0,0,0,0,0,0,0,0,0,0,0,0
0,28,29,0,0,0,0,29,28,0,0,0
0,28,5,0,0,0,0,5,28,0,0,0
0,28,30,0,0,0,0,30,28,0,0,0
0,28,30,0,0,0,0,30,28,0,0,0
0,28,30,0,0,0,0,30,28,0,0,0
0,28,30,0,0,0,0,30,28,0,0,0
0,28,7,0,0,0,0,5,28,0,0,0
0,28,29,0,0,0,0,29,28,0,0,0
0,0,0,0,0,0,0,0,0,0,0,0
endlayer

layer
0,0,0,0,0,0,0,0,0,0,0,0
0,0,0,28,29,29,28,0,0,0,0,0
0,0,5,31,30,30,31,7,0,0,0,0
0,0,0,31,30,30,31,0,0,0,0,0
0,0,0,31,30,30,31,0,0,0,0,0
0,0,0,31,30,30,31,0,0,0,0,0
0,0,0,31,30,30,31,0,0,0,0,0
0,0,7,31,30,30,31,7,0,0,0,0
0,0,0,28,29,29,28,0,0,0,0,0
0,0,0,0,0,0,0,0,0,0,0,0
endlayer

layer
0,0,0,0,0,0,0,0,0,0,0,0
0,0,0,0,0,0,0,0,0,0,0,0
0,0,7,0,0,0,0,5,0,0,0,0
0,0,0,0,0,0,0,0,0,0,0,0
0,0,0,0,0,0,0,0,0,0,0,0
0,0,0,0,0,0,0,0,0,0,0,0
0,0,0,0,0,0,0,0,0,0,0,0
0,0,5,0,0,0,0,5,0,0,0,0
0,0,0,0,0,0,0,0,0,0,0,0
0,0,0,0,0,0,0,0,0,0,0,0
endlayer

