
# Created by Ruins mod version 14.9 Ingame Parser
# authoring Player: SunsOfOld

weight=100
embed_into_distance=1
acceptable_target_blocks=
unacceptable_target_blocks=flowing_water,water,flowing_lava,lava
dimensions=10,10,9
allowable_overhang=0
max_leveling=3
leveling_buffer=0
preserve_water=0
preserve_lava=0
uniqueMinDistance=1000000
preventRotation=1

rule1=0,100,minecraft:sand-0
rule2=0,100,preserveBlock
rule3=0,100,BiomesOPlenty:newBopDirt-0
rule4=0,100,BiomesOPlenty:newBopDirt-3
rule5=0,100,BiomesOPlenty:newBopDirt-2
rule6=0,100,BiomesOPlenty:plants-3
rule7=0,100,plantmegapack:grassSeaOats-0
rule8=0,100,ExtrabiomesXL:leaves_4-15
rule9=0,100,chisel:fantasyblock2-3
rule10=0,100,ExtrabiomesXL:grass-0
rule11=0,100,chisel:fantasyblock2-15
rule12=0,100,plantmegapack:grassPrairie-0
rule13=0,100,plantmegapack:leafyDustyMiller-0
rule14=0,100,plantmegapack:flowerMediterraneanSeaHolly-0
rule15=0,100,ExtrabiomesXL:log1-10
rule16=0,100,ExtrabiomesXL:leaves_4-7
rule17=0,100,IInventory;harvestcraft:fishtrap;harvestcraft:fishtrapbaitItem#4#0#18-0
rule18=0,100,IInventory;harvestcraft:fishtrap;harvestcraft:fishtrapbaitItem#5#0#18-0
rule19=0,100,IInventory;harvestcraft:fishtrap;harvestcraft:fishtrapbaitItem#3#0#18-0
rule20=0,100,ExtrabiomesXL:log1-6
rule21=0,100,ExtrabiomesXL:woodslab-7
rule22=0,100,BiomesOPlenty:woodenSingleSlab1-6
rule23=0,100,IInventory;minecraft:chest;minecraft:string#2#0#0+harvestcraft:mudfishrawItem#4#0#3+plantmegapack:groundcoverTwig#1#0#5+minecraft:string#1#0#6+harvestcraft:crabrawItem#3#0#8+harvestcraft:mudfishrawItem#1#0#10+harvestcraft:crabrawItem#5#0#13+harvestcraft:catfishrawItem#2#0#16+harvestcraft:catfishrawItem#4#0#18+plantmegapack:groundcoverTwig#1#0#20+minecraft:string#2#0#21+harvestcraft:mudfishrawItem#5#0#23+plantmegapack:groundcoverTwig#1#0#25+minecraft:string#1#0#26-2
rule24=0,100,GardenStuff:lattice-0
rule25=0,100,GardenStuff:lantern-8

layer
2,1,2,4,1,2,3,2,1
1,2,2,3,4,2,2,4,2
2,2,2,4,3,2,4,2,5
5,3,4,3,4,3,3,4,2
1,2,3,3,4,3,2,5,1
5,5,2,4,3,2,2,3,2
2,4,2,3,4,2,2,2,4
5,2,3,4,4,2,4,2,1
1,4,2,5,5,5,2,4,2
2,1,2,2,1,5,4,1,2
endlayer

layer
0,6,8,7,6,0,7,0,6
6,5,11,8,10,1,9,8,0
0,9,1,8,0,5,8,8,11
10,14,1,13,0,10,12,7,0
13,1,8,5,10,12,4,10,6
7,8,1,4,14,4,8,15,0
0,5,9,8,10,5,11,8,10
10,1,16,7,0,1,8,11,11
6,7,0,10,12,7,17,8,0
0,13,19,0,6,10,12,13,18
endlayer

layer
0,0,0,0,0,0,0,0,0
0,7,9,8,0,6,11,0,0
0,0,1,0,0,7,8,0,0
0,0,6,0,0,0,0,0,0
0,6,0,10,0,0,7,0,0
0,0,1,7,0,10,0,0,0
0,8,11,0,0,7,11,8,0
0,6,0,0,0,6,8,0,0
0,0,0,0,0,0,0,0,0
0,0,0,0,0,0,0,0,0
endlayer

layer
0,0,0,0,0,0,0,0,0
0,0,11,0,0,0,9,0,0
0,0,6,0,0,0,0,0,0
0,0,0,0,0,0,0,0,0
0,0,0,0,0,0,0,0,0
0,0,6,0,0,0,0,0,0
0,0,11,0,0,0,9,0,0
0,0,0,0,0,0,0,0,0
0,0,0,0,0,0,0,0,0
0,0,0,0,0,0,0,0,0
endlayer

layer
0,0,20,0,0,0,20,0,0
0,15,15,15,15,15,15,15,0
0,0,20,0,0,0,20,0,0
0,0,20,0,0,0,20,0,0
0,0,20,0,0,0,20,0,0
0,0,20,0,0,0,20,0,0
0,15,15,15,15,15,0,0,0
0,0,20,0,0,0,20,0,0
0,0,20,0,0,0,20,0,0
0,0,0,0,0,0,0,0,0
endlayer

layer
0,0,22,21,0,22,21,0,0
0,0,11,21,22,22,9,0,0
0,0,22,21,22,0,22,0,0
0,0,22,21,22,21,22,0,0
0,0,0,22,0,21,22,0,0
0,0,21,22,0,21,0,0,0
0,0,9,22,22,21,0,0,0
0,0,21,0,22,0,22,0,0
0,0,0,0,0,0,0,0,0
0,0,0,0,0,0,0,0,0
endlayer

layer
0,0,0,0,0,0,0,0,0
0,0,23,0,0,0,0,0,0
0,0,0,0,0,0,0,0,0
0,0,0,0,0,0,0,0,0
0,0,0,0,0,0,0,0,0
0,0,0,0,0,0,0,0,0
0,0,11,0,0,0,0,0,0
0,0,0,0,0,0,0,0,0
0,0,0,0,0,0,0,0,0
0,0,0,0,0,0,0,0,0
endlayer

layer
0,0,0,0,0,0,0,0,0
0,0,0,0,0,0,0,0,0
0,0,0,0,0,0,0,0,0
0,0,0,0,0,0,0,0,0
0,0,0,0,0,0,0,0,0
0,0,0,0,0,0,0,0,0
0,0,24,0,0,0,0,0,0
0,0,0,0,0,0,0,0,0
0,0,0,0,0,0,0,0,0
0,0,0,0,0,0,0,0,0
endlayer

layer
0,0,0,0,0,0,0,0,0
0,0,0,0,0,0,0,0,0
0,0,0,0,0,0,0,0,0
0,0,0,0,0,0,0,0,0
0,0,0,0,0,0,0,0,0
0,0,0,0,0,0,0,0,0
0,0,24,0,0,0,0,0,0
0,0,25,0,0,0,0,0,0
0,0,0,0,0,0,0,0,0
0,0,0,0,0,0,0,0,0
endlayer

layer
0,0,0,0,0,0,0,0,0
0,0,0,0,0,0,0,0,0
0,0,0,0,0,0,0,0,0
0,0,0,0,0,0,0,0,0
0,0,0,0,0,0,0,0,0
0,0,0,0,0,0,0,0,0
0,0,24,0,0,0,0,0,0
0,0,24,0,0,0,0,0,0
0,0,0,0,0,0,0,0,0
0,0,0,0,0,0,0,0,0
endlayer

