
# Created by Ruins mod version 15.0 Ingame Parser
# authoring Player: VikingWarlock

weight=100
embed_into_distance=1
acceptable_target_blocks=
unacceptable_target_blocks=flowing_water,water,flowing_lava,lava
dimensions=12,7,8
allowable_overhang=0
max_leveling=3
leveling_buffer=0
preserve_water=0
preserve_lava=0
uniqueMinDistance=1000000
preventRotation=1

rule1=0,100,BiomesOPlenty:newBopDirt-3
rule2=0,100,BiomesOPlenty:leaves2-4
rule3=0,100,ExtrabiomesXL:grass-3
rule4=0,100,BiomesOPlenty:leaves2-12
rule5=0,100,MobSpawner:Snake
rule6=0,100,minecraft:web-0
rule7=0,100,IInventory;minecraft:chest;minecraft:string#1#0#0+minecraft:rotten_flesh#1#0#1+harvestcraft:zombiejerkyItem#3#0#2+minecraft:bone#1#0#4+minecraft:bone#1#0#5+harvestcraft:zombiejerkyItem#1#0#6+harvestcraft:zombiejerkyItem#1#0#7+minecraft:string#1#0#8+harvestcraft:zombiejerkyItem#3#0#9+minecraft:bone#1#0#10+harvestcraft:zombiejerkyItem#5#0#11+BiblioCraft:item.HandDrill#1#0#13+harvestcraft:zombiejerkyItem#1#0#14+minecraft:string#1#0#15+minecraft:bone#1#0#17+minecraft:bone#1#0#18+minecraft:rotten_flesh#1#0#20+minecraft:bone#1#0#23+harvestcraft:zombiejerkyItem#1#0#24+harvestcraft:zombiejerkyItem#1#0#25+minecraft:bone#1#0#26-4
rule8=0,100,chisel:cobblestone-1
rule9=0,100,GardenStuff:lattice-0
rule10=0,100,GardenStuff:metal_block-0

layer
1,1,1,1,1,1,1,1
1,1,1,1,1,1,1,1
1,1,1,1,1,1,1,1
1,1,1,1,1,1,1,1
1,1,1,1,1,1,1,1
1,1,1,1,1,1,1,1
1,1,1,1,1,1,1,1
endlayer

layer
0,2,2,0,0,0,0,0
2,2,1,2,1,3,0,0
2,1,1,1,1,1,4,4
2,1,1,1,1,1,1,4
2,1,6,6,5,1,1,4
0,1,6,1,1,1,6,2
0,0,0,0,0,0,0,0
endlayer

layer
0,0,0,0,0,0,0,0
0,0,2,0,0,0,0,0
0,0,1,1,1,3,0,0
0,0,1,1,7,1,2,0
0,0,1,1,1,1,4,0
0,0,6,1,1,3,0,0
0,0,0,0,0,0,0,0
endlayer

layer
0,0,0,0,0,0,0,0
0,0,0,0,0,0,0,0
0,0,0,0,0,0,0,0
0,0,0,3,8,6,0,0
0,0,0,0,0,0,0,0
0,0,0,0,0,0,0,0
0,0,0,0,0,0,0,0
endlayer

layer
0,0,0,0,0,0,0,0
0,0,0,0,0,0,0,0
0,0,0,0,0,0,0,0
0,0,0,9,10,9,0,0
0,0,0,0,0,0,0,0
0,0,0,0,0,0,0,0
0,0,0,0,0,0,0,0
endlayer

layer
0,0,0,0,0,0,0,0
0,0,0,0,0,0,0,0
0,0,0,0,0,0,0,0
0,0,9,8,10,8,9,0
0,0,0,0,0,0,0,0
0,0,0,0,0,0,0,0
0,0,0,0,0,0,0,0
endlayer

layer
0,0,0,0,0,0,0,0
0,0,0,0,0,0,0,0
0,0,0,0,0,0,0,0
0,0,8,10,8,10,8,0
0,0,0,0,0,0,0,0
0,0,0,0,0,0,0,0
0,0,0,0,0,0,0,0
endlayer

layer
0,0,0,0,0,0,0,0
0,0,0,0,0,0,0,0
0,0,0,0,0,0,0,0
0,0,9,8,10,8,9,0
0,0,0,0,0,0,0,0
0,0,0,0,0,0,0,0
0,0,0,0,0,0,0,0
endlayer

layer
0,0,0,0,0,0,0,0
0,0,0,0,0,0,0,0
0,0,0,0,0,0,0,0
0,0,0,9,10,9,0,0
0,0,0,0,0,0,0,0
0,0,0,0,0,0,0,0
0,0,0,0,0,0,0,0
endlayer

layer
0,0,0,0,0,0,0,0
0,0,0,0,0,0,0,0
0,0,0,0,0,0,0,0
0,0,0,9,10,9,0,0
0,0,0,0,0,0,0,0
0,0,0,0,0,0,0,0
0,0,0,0,0,0,0,0
endlayer

layer
0,0,0,0,0,0,0,0
0,0,0,0,0,0,0,0
0,0,0,0,0,0,0,0
0,0,0,9,10,9,0,0
0,0,0,0,0,0,0,0
0,0,0,0,0,0,0,0
0,0,0,0,0,0,0,0
endlayer

layer
0,0,0,0,0,0,0,0
0,0,0,0,0,0,0,0
0,0,0,0,0,0,0,0
0,0,0,9,8,9,0,0
0,0,0,0,0,0,0,0
0,0,0,0,0,0,0,0
0,0,0,0,0,0,0,0
endlayer

