
# Created by Ruins mod version 15.0 Ingame Parser
# authoring Player: SunsOfOld

weight=100
embed_into_distance=1
acceptable_target_blocks=
unacceptable_target_blocks=flowing_water,water,flowing_lava,lava
dimensions=31,15,79
allowable_overhang=0
max_leveling=9
leveling_buffer=0
preserve_water=0
preserve_lava=0
uniqueMinDistance=1000000
preventRotation=1

rule1=0,100,preserveBlock
rule2=0,100,minecraft:grass-0
rule3=0,100,chisel:fantasyblock-2
rule4=0,100,minecraft:dirt-0
rule5=0,100,chisel:mossy_cobblestone-12
rule6=0,100,chisel:mossy_cobblestone-1
rule7=0,100,GardenStuff:moss_brick-4
rule8=0,100,GardenStuff:moss_brick-3
rule9=0,100,ExtrabiomesXL:leaves_2-15
rule10=0,100,plantmegapack:vineJapaneseIvy-8
rule11=0,100,ExtrabiomesXL:leaves_2-7
rule12=0,100,plantmegapack:vineJapaneseIvy-1
rule13=0,100,plantmegapack:vineJapaneseIvy-4
rule14=0,100,minecraft:log-0
rule15=0,100,minecraft:web-0
rule16=0,100,chisel:mossy_cobblestone-14
rule17=0,100,chisel:mossy_cobblestone-2
rule18=0,100,chisel:mossy_cobblestone-4
rule19=0,100,plantmegapack:vineJapaneseIvy-12
rule20=0,100,plantmegapack:vineJapaneseIvy-6
rule21=0,100,plantmegapack:vineJapaneseIvy-2
rule22=0,100,plantmegapack:vineJapaneseIvy-3
rule23=0,100,plantmegapack:vineJapaneseIvy-14
rule24=0,100,plantmegapack:vineJapaneseIvy-9
rule25=0,100,IInventory;minecraft:chest;BiomesOPlenty:chestplateAmethyst#{restrictions:[0:{id:0s,lvl:0s,player:"jkfryman",},1:{id:0s,lvl:1s,player:"jkfryman",},2:{id:0s,lvl:2s,player:"jkfryman",},3:{id:0s,lvl:3s,player:"jkfryman",},4:{id:34s,lvl:0s,player:"jkfryman",},5:{id:34s,lvl:1s,player:"jkfryman",},6:{id:34s,lvl:2s,player:"jkfryman",},7:{id:34s,lvl:3s,player:"jkfryman",},],ench:[0:{id:0s,lvl:3s,},1:{id:34s,lvl:3s,},],}#0#13-4
rule26=0,100,plantmegapack:vineJapaneseIvy-0
rule27=0,100,IInventory;minecraft:chest;minecraft:golden_leggings#{ench:[0:{id:0s,lvl:2s,},1:{id:34s,lvl:2s,},],}#0#3+minecraft:bow#{RepairCost:2,ench:[0:{id:51s,lvl:1s,},],}#0#7+minecraft:chainmail_chestplate#{ench:[0:{id:34s,lvl:1s,},1:{id:0s,lvl:1s,},],}#0#10+minecraft:potion#1#8261#21+minecraft:wooden_sword#{ench:[0:{id:16s,lvl:1s,},1:{id:34s,lvl:1s,},],}#0#23+eplus:item.tableUpgrade#1#0#25-2
rule28=0,100,plantmegapack:vineJapaneseIvy-5
rule29=0,100,IInventory;minecraft:chest;dendrology:sapling1#1#2#0+Backpack:backpack#{name:"item.backpack.big_purple.name",}#206#2+BiomesOPlenty:colorizedSaplings#1#0#6+minecraft:cake#1#0#8+minecraft:record_cat#1#0#13+minecraft:leather#5#0#18+minecraft:speckled_melon#4#0#20+dendrology:sapling0#1#4#22+minecraft:coal#32#0#24+minecraft:diamond#6#0#26-4

layer
1,1,1,4,2,2,2,5,2,1,1,1,1,1,2,2,2,2,2,2,1,1,2,4,2,1,4,4,2,2,2,1,1,1,1,2,2,2,1,1,1,2,2,2,2,2,3,1,1,2,2,2,2,2,2,1,1,1,1,1,1,2,2,2,2,2,2,1,1,1,1,1,2,2,2,1,1,1,1
1,1,2,2,6,2,2,1,1,1,4,1,2,2,1,1,1,2,2,1,1,2,2,2,2,2,2,2,2,2,1,2,1,1,1,6,2,1,1,2,1,2,1,2,1,5,2,2,1,1,1,2,2,1,2,1,1,2,2,1,2,1,2,1,1,1,1,2,1,1,2,1,2,2,1,2,2,1,1
1,2,2,2,1,1,1,1,1,1,1,1,2,1,4,2,2,1,2,2,2,2,6,1,1,2,1,1,1,1,2,2,2,1,1,2,2,1,2,1,2,2,1,2,4,1,1,2,2,1,1,2,1,1,1,2,1,2,2,1,1,2,2,2,1,1,2,2,1,2,2,2,1,2,1,1,2,2,1
1,2,1,1,1,1,1,1,1,1,1,2,2,1,1,2,2,2,1,1,2,2,7,2,2,1,2,2,1,1,1,2,1,2,2,2,2,1,1,2,2,2,2,2,4,1,1,1,1,1,2,2,1,1,1,2,2,2,2,2,2,2,2,2,1,2,1,1,1,2,2,2,1,1,1,1,1,1,2
2,2,2,1,1,1,1,1,1,1,1,2,1,1,2,1,1,1,2,1,2,1,2,2,1,1,1,1,1,1,1,2,1,2,1,1,1,2,2,2,1,2,2,1,1,1,1,1,1,2,2,1,1,1,1,1,2,2,2,1,2,2,2,2,1,2,1,1,1,2,2,2,2,2,1,1,1,8,1
1,2,2,1,1,1,1,1,1,1,1,2,1,1,3,3,1,2,2,1,2,1,1,2,1,1,1,1,1,1,2,2,2,1,2,2,6,2,2,1,1,2,2,2,1,1,1,1,1,2,1,1,2,2,2,8,2,1,1,1,1,2,1,1,1,1,1,1,1,1,2,2,2,1,1,2,2,1,1
1,2,1,1,1,1,1,1,1,1,1,1,2,1,2,1,2,2,2,1,2,2,1,1,1,1,1,1,1,2,2,2,1,2,1,2,1,2,2,1,1,1,2,2,1,1,1,1,1,2,1,7,1,2,2,2,1,2,2,2,2,1,1,2,1,1,1,1,1,2,2,1,2,2,1,1,2,2,1
4,2,1,1,1,1,1,1,1,4,2,2,1,2,2,8,1,2,2,1,1,2,1,2,1,1,1,1,1,2,1,1,2,1,1,1,2,2,2,2,1,1,1,1,1,1,1,1,1,2,2,2,2,1,1,1,1,1,2,2,7,1,2,2,1,1,1,1,1,2,5,1,1,2,1,1,1,2,2
2,1,1,1,1,1,1,1,1,2,2,2,2,2,1,2,7,6,2,2,2,2,2,2,1,1,1,1,1,1,2,1,2,1,2,2,2,1,2,2,2,2,2,2,1,1,1,1,1,4,1,2,2,1,2,1,2,1,1,2,1,1,2,2,1,1,1,1,1,1,1,2,2,1,1,2,6,6,2
2,2,2,1,1,1,1,1,1,2,2,1,1,2,1,2,1,2,2,2,1,1,1,1,1,1,1,1,1,2,2,6,1,1,1,2,1,2,8,2,2,1,2,1,1,1,1,1,1,1,8,1,1,2,2,2,3,2,2,2,2,2,1,1,1,1,1,1,1,1,2,2,2,6,2,2,2,2,2
1,2,1,1,1,1,1,1,1,2,1,1,1,2,2,2,2,1,1,1,1,1,2,1,1,1,1,1,1,2,2,1,1,1,2,2,1,2,2,1,2,2,1,1,1,1,1,1,1,1,2,2,2,2,1,2,2,2,2,1,2,2,1,1,1,1,1,1,1,1,1,1,1,1,1,1,1,1,2
2,6,2,1,1,1,1,2,2,1,2,1,1,1,2,1,1,1,1,1,2,2,1,2,2,1,1,1,1,2,1,2,2,2,2,2,2,2,1,1,2,2,2,1,1,1,1,1,1,1,2,2,1,1,1,1,2,2,1,2,2,2,1,1,1,1,2,1,1,1,1,2,2,2,1,1,1,2,2
1,2,1,2,1,1,1,1,1,2,2,1,1,1,2,1,1,2,1,1,2,2,2,2,2,2,2,1,1,1,1,2,1,2,1,2,1,1,2,2,2,2,1,1,1,1,2,2,1,1,1,2,2,2,2,2,1,1,2,1,2,2,2,1,1,2,2,1,1,1,1,7,1,2,2,2,1,2,1
1,2,1,2,2,1,1,8,2,2,1,1,2,2,1,2,2,2,2,1,1,2,1,1,1,1,2,2,1,1,2,2,1,2,2,2,2,2,2,1,1,2,2,2,2,2,2,2,1,2,1,1,2,1,1,2,1,1,2,2,2,2,1,1,2,2,2,1,1,2,2,1,6,2,2,2,2,1,1
2,1,2,2,2,2,4,2,2,2,2,2,1,1,1,1,2,1,2,1,2,2,2,2,2,4,2,2,1,2,1,1,2,2,2,2,1,1,1,1,2,2,2,2,1,4,1,1,2,2,2,2,2,2,1,1,1,1,1,2,2,2,2,2,4,2,2,2,1,1,1,2,2,2,2,1,2,1,1
endlayer

layer
0,0,0,3,0,0,0,0,0,0,0,0,0,0,0,0,0,0,0,0,0,0,0,3,0,0,3,3,0,0,0,0,0,0,0,0,0,0,0,0,0,0,0,0,0,0,0,0,0,0,0,0,0,0,0,0,0,0,0,0,0,0,0,0,0,0,0,0,0,0,0,0,0,0,0,0,0,0,0
0,0,0,0,0,0,0,6,0,0,3,3,0,0,3,3,0,0,0,0,0,0,0,0,0,0,0,0,0,0,6,0,0,7,8,0,0,0,0,0,0,0,3,0,3,0,10,0,3,3,3,0,0,0,0,0,0,0,0,0,0,0,0,0,3,9,3,0,0,0,0,0,0,0,0,0,0,0,0
0,0,0,0,6,3,0,7,10,0,0,3,12,0,3,12,0,0,0,0,0,0,0,0,3,0,0,0,13,6,0,0,0,0,0,0,13,3,0,0,0,0,0,0,3,13,9,12,10,3,3,0,0,9,0,0,0,0,0,0,0,0,0,0,3,0,0,0,0,0,0,0,3,0,11,0,0,0,0
0,0,0,0,0,0,0,13,11,11,0,0,0,3,0,0,10,0,0,0,0,0,0,0,0,10,10,10,9,9,0,0,0,0,0,0,0,0,0,0,0,0,0,0,2,11,9,9,6,0,0,0,9,14,9,0,0,0,0,0,0,0,0,0,2,0,0,11,10,0,0,0,0,9,14,9,5,0,0
0,0,0,13,7,17,8,7,6,9,9,0,0,0,0,13,3,0,0,6,10,10,10,10,5,8,7,6,8,14,9,0,10,0,0,10,10,10,0,10,10,0,10,10,16,17,17,16,8,10,10,10,0,9,10,0,0,10,10,10,10,0,10,9,6,15,6,7,5,10,10,0,10,0,6,3,0,0,0
0,0,0,13,17,17,17,17,8,14,9,0,0,3,0,19,0,0,0,0,13,5,12,0,6,17,17,17,5,11,0,12,0,0,0,0,0,0,0,0,0,0,13,0,8,8,8,8,5,0,0,0,0,0,0,0,0,0,0,7,0,0,13,9,6,7,17,7,18,12,0,0,13,3,10,0,0,0,0
0,0,9,11,8,17,17,17,17,9,9,0,0,0,13,0,0,0,0,0,0,13,8,0,6,17,17,17,6,0,12,0,0,0,12,0,13,0,0,0,16,5,13,0,7,17,6,6,8,0,5,0,0,0,0,0,0,0,0,21,0,16,20,0,5,17,18,18,5,12,0,0,0,12,6,12,0,0,0
5,0,0,9,6,17,17,17,6,2,0,0,0,0,0,21,0,0,0,6,0,19,0,0,5,17,6,17,6,12,8,12,0,17,12,5,0,0,0,13,21,17,6,0,17,17,17,7,17,0,0,12,0,0,21,0,5,17,0,0,0,18,13,13,6,5,17,7,8,0,0,13,7,12,13,5,12,0,0
0,6,0,8,6,17,17,17,17,12,0,0,0,0,0,0,0,0,0,13,0,0,0,0,7,17,17,17,8,12,12,6,0,12,10,10,0,0,0,13,0,13,0,0,5,7,17,16,16,2,0,12,0,5,0,12,0,0,0,0,13,7,12,13,7,17,7,18,17,2,0,0,0,0,0,22,0,0,0
0,0,0,9,6,17,17,17,17,12,10,10,0,0,6,0,5,0,13,10,0,6,13,13,6,6,6,17,17,12,0,0,0,17,17,0,0,0,0,0,0,0,0,9,8,8,7,7,8,11,0,12,18,12,0,0,0,0,0,0,0,0,0,19,17,6,18,5,6,2,12,0,0,0,0,12,0,0,0
0,0,9,14,8,8,6,6,16,0,3,3,3,0,0,0,0,0,3,3,0,21,21,20,16,17,17,5,17,9,21,21,0,0,0,0,0,0,21,21,21,0,9,14,5,17,7,8,17,11,21,0,0,0,21,21,0,21,21,0,0,21,21,11,6,7,5,18,6,9,21,0,3,3,21,3,9,0,0
0,0,0,9,9,11,21,0,0,0,0,3,3,0,0,0,3,0,0,9,0,0,0,0,21,21,0,2,9,0,0,0,0,0,0,0,0,0,0,0,0,0,0,9,9,11,2,12,11,11,0,0,0,0,6,0,0,0,0,0,0,0,0,9,9,3,0,2,9,14,9,0,0,0,0,9,3,0,0
0,0,0,0,0,0,3,0,0,0,0,21,3,0,0,3,0,0,9,14,9,0,0,0,0,0,0,0,3,3,0,0,0,0,0,0,0,0,0,0,0,0,0,0,3,3,0,0,7,6,0,0,0,0,0,0,0,0,0,0,0,0,0,0,0,0,0,0,0,9,0,0,0,0,0,0,0,0,0
0,0,0,0,0,0,3,0,0,0,0,0,0,0,0,0,0,0,0,9,9,0,0,0,3,0,0,0,13,3,0,0,0,0,0,0,0,0,0,0,0,0,0,0,0,0,0,0,0,0,8,0,0,0,0,0,6,6,0,0,0,0,0,0,0,0,0,3,0,0,0,0,0,0,0,0,0,0,0
0,0,0,0,0,0,3,0,0,0,0,0,0,0,0,0,0,0,0,0,0,0,0,0,0,3,0,0,0,0,0,0,0,0,0,0,0,0,0,0,0,0,0,0,0,3,0,0,0,0,0,0,0,0,0,0,0,0,0,0,0,0,0,0,3,0,0,0,0,0,0,0,0,0,0,3,0,0,0
endlayer

layer
0,0,0,0,0,0,0,0,0,0,0,0,0,0,0,0,0,0,0,0,0,0,0,0,0,0,0,0,0,0,0,0,0,0,0,0,0,0,0,0,0,0,0,0,0,0,0,0,0,0,0,0,0,0,0,0,0,0,0,0,0,0,0,0,0,0,0,0,0,0,0,0,0,0,0,0,0,0,0
0,0,0,0,0,0,0,0,0,0,0,0,0,0,0,0,0,0,0,0,0,0,0,0,0,0,0,0,0,0,0,0,0,0,0,0,0,0,0,0,0,0,0,0,0,0,10,0,0,0,0,0,0,0,0,0,0,0,0,0,0,0,0,0,0,0,0,0,0,0,0,0,0,0,0,0,0,0,0
0,0,0,0,0,0,0,0,10,0,0,3,12,0,0,0,0,0,0,0,0,0,0,0,0,0,0,0,0,0,0,0,0,0,0,0,0,0,0,0,0,0,0,0,0,13,11,12,0,0,0,0,0,0,0,0,0,0,0,0,0,0,0,0,0,0,0,0,0,0,0,0,0,0,0,0,0,0,0
0,0,0,0,0,0,0,13,11,12,0,0,0,0,0,0,0,0,0,0,0,0,0,0,0,0,0,10,9,0,0,0,0,0,0,0,0,0,0,0,0,0,0,0,0,0,11,11,0,0,0,0,0,11,0,0,0,0,0,0,0,0,0,0,0,0,0,0,10,0,0,0,0,0,9,0,0,0,0
0,0,0,13,5,8,6,17,8,9,9,0,0,0,0,0,0,0,0,10,10,10,10,10,6,7,5,6,6,11,0,0,10,0,0,10,10,10,0,10,10,0,10,10,7,13,17,17,5,10,10,10,0,0,10,0,0,10,10,10,10,0,10,10,8,6,9,18,17,10,10,0,10,0,9,0,0,0,0
0,0,0,13,6,7,18,7,6,11,0,0,0,0,0,19,0,0,0,0,0,0,0,0,6,7,7,7,17,0,0,12,0,0,0,0,0,0,0,0,0,0,13,0,6,6,6,17,6,0,0,0,0,0,0,0,0,0,0,0,0,0,13,11,6,18,7,5,6,0,0,0,0,0,10,0,0,0,0
0,0,0,11,17,16,17,6,17,9,0,0,0,0,13,0,0,0,0,0,0,13,0,0,8,0,5,17,16,0,12,0,0,0,12,0,13,0,0,0,0,0,13,0,15,8,16,8,6,0,12,0,0,0,0,0,0,0,0,0,0,0,20,0,7,18,5,5,7,12,0,0,0,12,0,12,0,0,0
0,0,0,0,16,5,18,6,6,0,0,0,0,0,0,21,0,0,0,0,0,19,0,0,15,6,6,8,8,0,12,0,0,0,0,0,0,0,0,13,0,0,0,0,8,8,7,7,8,0,0,12,0,0,21,0,12,13,0,0,0,13,13,0,17,5,17,17,15,0,0,13,0,12,0,0,0,0,0
0,0,0,13,6,17,18,8,5,12,0,0,0,0,0,0,0,0,0,13,0,0,0,0,17,0,6,17,6,12,12,0,0,12,0,10,0,0,0,13,0,13,0,0,17,6,5,6,8,12,0,12,0,0,0,12,0,0,0,0,0,13,0,0,6,7,17,18,12,0,0,0,0,0,0,22,0,0,0
0,0,0,0,7,18,8,5,6,12,0,0,0,0,0,0,0,0,13,0,0,0,13,0,6,7,7,7,6,12,0,0,0,0,0,0,0,0,0,0,0,0,0,0,7,6,6,8,5,12,0,12,0,0,0,0,0,0,0,0,0,0,0,10,23,17,5,17,16,0,12,0,0,0,0,12,0,0,0
0,0,0,9,17,5,6,6,8,0,0,0,0,0,0,0,0,0,0,21,0,21,21,21,7,8,7,6,8,0,21,21,0,0,0,0,0,0,21,21,21,0,21,11,17,8,16,5,17,22,21,0,0,0,21,21,0,21,21,0,0,21,21,11,7,5,5,6,7,0,21,0,0,0,21,11,0,0,0
0,0,0,0,21,21,21,0,0,0,0,0,0,0,0,0,0,0,0,0,0,0,0,0,0,0,0,0,9,0,0,0,0,0,0,0,0,0,0,0,0,0,0,0,0,0,0,0,11,0,0,0,0,0,0,0,0,0,0,0,0,0,0,0,0,0,0,0,0,9,0,0,0,0,0,0,0,0,0
0,0,0,0,0,0,0,0,0,0,0,0,0,0,0,0,0,0,0,9,0,0,0,0,0,0,0,0,0,0,0,0,0,0,0,0,0,0,0,0,0,0,0,0,0,0,0,0,0,5,0,0,0,0,0,0,0,0,0,0,0,0,0,0,0,0,0,0,0,0,0,0,0,0,0,0,0,0,0
0,0,0,0,0,0,0,0,0,0,0,0,0,0,0,0,0,0,0,0,0,0,0,0,0,0,0,0,0,0,0,0,0,0,0,0,0,0,0,0,0,0,0,0,0,0,0,0,0,0,0,0,0,0,0,0,0,0,0,0,0,0,0,0,0,0,0,0,0,0,0,0,0,0,0,0,0,0,0
0,0,0,0,0,0,0,0,0,0,0,0,0,0,0,0,0,0,0,0,0,0,0,0,0,0,0,0,0,0,0,0,0,0,0,0,0,0,0,0,0,0,0,0,0,0,0,0,0,0,0,0,0,0,0,0,0,0,0,0,0,0,0,0,0,0,0,0,0,0,0,0,0,0,0,0,0,0,0
endlayer

layer
0,0,0,0,0,0,0,0,0,0,0,0,0,0,0,0,0,0,0,0,0,0,0,0,0,0,0,0,0,0,0,0,0,0,0,0,0,0,0,0,0,0,0,0,0,0,0,0,0,0,0,0,0,0,0,0,0,0,0,0,0,0,0,0,0,0,0,0,0,0,0,0,0,0,0,0,0,0,0
0,0,0,0,0,0,0,0,0,0,0,0,0,0,0,0,0,0,0,0,0,0,0,0,0,0,0,0,0,0,0,0,0,0,0,0,0,0,0,0,0,0,0,0,0,0,0,0,0,0,0,0,0,0,0,0,0,0,0,0,0,0,0,0,0,0,0,0,0,0,0,0,0,0,0,0,0,0,0
0,0,0,0,0,0,0,0,0,0,0,0,0,0,0,0,0,0,0,0,0,0,0,0,0,0,0,0,0,0,0,0,0,0,0,0,0,0,0,0,0,0,0,0,0,0,0,0,0,0,0,0,0,0,0,0,0,0,0,0,0,0,0,0,0,0,0,0,0,0,0,0,0,0,0,0,0,0,0
0,0,0,0,0,0,0,0,0,0,0,0,0,0,0,0,0,0,0,0,0,0,0,0,0,0,0,0,10,0,0,0,0,0,0,0,0,0,0,0,0,0,0,0,0,0,11,0,0,0,0,0,0,0,0,0,0,0,0,0,0,0,0,0,0,0,0,0,0,0,0,0,0,0,0,0,0,0,0
0,0,0,0,0,0,10,10,9,0,0,0,0,0,0,0,0,0,0,10,10,10,10,10,0,10,10,10,9,10,0,0,10,0,0,10,10,10,0,10,10,0,10,10,0,13,11,11,24,10,10,10,0,0,10,0,0,10,10,10,10,0,10,10,10,0,10,10,10,10,10,0,10,0,0,0,0,0,0
0,0,0,0,11,7,3,6,9,0,0,0,0,0,0,19,0,0,0,0,0,0,0,0,13,17,3,17,0,0,0,12,0,0,0,0,0,0,0,0,0,0,13,0,0,8,3,7,0,0,0,0,0,0,0,0,0,0,0,0,0,0,13,13,11,7,3,18,12,0,0,0,0,0,10,0,0,0,0
0,0,0,0,11,6,15,17,9,0,0,0,0,0,13,0,0,0,0,0,0,13,0,0,13,17,0,17,0,0,12,0,0,0,12,0,13,0,0,0,0,0,13,0,13,6,0,6,0,0,12,0,0,0,0,0,0,0,0,0,0,0,20,0,0,7,0,6,12,0,0,0,0,12,0,12,0,0,0
0,0,0,0,13,18,0,5,0,0,0,0,0,0,0,21,0,0,0,0,0,19,0,0,0,18,0,5,0,0,12,0,0,0,0,0,0,0,0,13,0,0,0,0,13,17,0,8,0,0,0,12,0,0,21,0,12,13,0,0,0,13,13,0,0,15,0,7,0,0,0,13,0,12,0,0,0,0,0
0,0,0,0,0,7,25,17,12,0,0,0,0,0,0,0,0,0,0,13,0,0,0,0,13,17,0,17,12,0,12,0,0,12,0,10,0,0,0,13,0,13,0,0,0,17,0,6,0,0,0,12,0,0,0,12,0,0,0,0,0,13,0,0,0,7,0,7,12,0,0,0,0,0,0,22,0,0,0
0,0,0,0,0,6,3,6,12,0,0,0,0,0,0,0,0,0,13,0,0,0,13,0,13,5,3,5,0,0,0,0,0,0,0,0,0,0,0,0,0,0,0,0,13,8,3,8,0,0,0,12,0,0,0,0,0,0,0,0,0,0,0,0,13,5,3,6,12,0,12,0,0,0,0,12,0,0,0
0,0,0,0,0,21,21,21,0,0,0,0,0,0,0,0,0,0,0,21,0,21,21,21,21,21,21,21,11,0,21,21,0,0,0,0,0,0,21,21,21,0,21,21,21,21,21,0,11,21,21,0,0,0,21,21,0,21,21,0,0,21,21,21,21,21,21,21,11,0,21,0,0,0,21,0,0,0,0
0,0,0,0,0,0,0,0,0,0,0,0,0,0,0,0,0,0,0,0,0,0,0,0,0,0,0,0,0,0,0,0,0,0,0,0,0,0,0,0,0,0,0,0,0,0,0,0,0,0,0,0,0,0,0,0,0,0,0,0,0,0,0,0,0,0,0,0,0,0,0,0,0,0,0,0,0,0,0
0,0,0,0,0,0,0,0,0,0,0,0,0,0,0,0,0,0,0,0,0,0,0,0,0,0,0,0,0,0,0,0,0,0,0,0,0,0,0,0,0,0,0,0,0,0,0,0,0,0,0,0,0,0,0,0,0,0,0,0,0,0,0,0,0,0,0,0,0,0,0,0,0,0,0,0,0,0,0
0,0,0,0,0,0,0,0,0,0,0,0,0,0,0,0,0,0,0,0,0,0,0,0,0,0,0,0,0,0,0,0,0,0,0,0,0,0,0,0,0,0,0,0,0,0,0,0,0,0,0,0,0,0,0,0,0,0,0,0,0,0,0,0,0,0,0,0,0,0,0,0,0,0,0,0,0,0,0
0,0,0,0,0,0,0,0,0,0,0,0,0,0,0,0,0,0,0,0,0,0,0,0,0,0,0,0,0,0,0,0,0,0,0,0,0,0,0,0,0,0,0,0,0,0,0,0,0,0,0,0,0,0,0,0,0,0,0,0,0,0,0,0,0,0,0,0,0,0,0,0,0,0,0,0,0,0,0
endlayer

layer
0,0,0,0,0,0,0,0,0,0,0,0,0,0,0,0,0,0,0,0,0,0,0,0,0,0,0,0,0,0,0,0,0,0,0,0,0,0,0,0,0,0,0,0,0,0,0,0,0,0,0,0,0,0,0,0,0,0,0,0,0,0,0,0,0,0,0,0,0,0,0,0,0,0,0,0,0,0,0
0,0,0,0,0,0,0,0,0,0,0,0,0,0,0,0,0,0,0,0,0,0,0,0,0,0,0,0,0,0,0,0,0,0,0,0,0,0,0,0,0,0,0,0,0,0,0,0,0,0,0,0,0,0,0,0,0,0,0,0,0,0,0,0,0,0,0,0,0,0,0,0,0,0,0,0,0,0,0
0,0,0,0,0,0,0,0,0,0,0,0,0,0,0,0,0,0,0,0,0,0,0,0,0,0,0,0,0,0,0,0,0,0,0,0,0,0,0,0,0,0,0,0,0,0,0,0,0,0,0,0,0,0,0,0,0,0,0,0,0,0,0,0,0,0,0,0,0,0,0,0,0,0,0,0,0,0,0
0,0,0,0,0,0,0,0,0,0,0,0,0,0,0,0,0,0,0,0,0,0,0,0,0,0,0,0,0,0,0,0,0,0,0,0,0,0,0,0,0,0,0,0,0,0,0,0,0,0,0,0,0,0,0,0,0,0,0,0,0,0,0,0,0,0,0,0,0,0,0,0,0,0,0,0,0,0,0
0,0,0,0,0,0,0,10,11,0,0,0,0,0,0,0,0,0,0,10,10,10,10,10,0,10,10,10,10,10,0,0,10,0,0,10,10,10,0,10,10,0,10,10,0,13,11,0,10,10,10,10,0,0,10,0,0,10,10,10,10,0,10,10,10,0,10,10,10,10,10,0,10,0,0,0,0,0,0
0,0,0,0,0,18,3,6,0,0,0,0,0,0,0,19,0,0,0,0,0,0,0,0,0,17,3,6,0,0,0,12,0,0,0,0,0,0,0,0,0,0,13,0,0,7,3,5,0,0,0,0,0,0,0,0,0,0,0,0,0,0,13,0,13,6,3,7,12,0,0,0,0,0,10,0,0,0,0
0,0,0,0,11,17,0,8,0,0,0,0,0,0,13,0,0,0,0,0,0,13,0,0,13,0,15,6,0,0,12,0,0,0,12,0,13,0,0,0,0,0,13,0,13,5,0,17,0,0,12,0,0,0,0,0,0,0,0,0,0,0,20,0,0,17,0,7,12,0,0,0,0,12,0,12,0,0,0
0,0,0,0,13,0,0,6,0,0,0,0,0,0,0,21,0,0,0,0,0,19,0,0,0,5,0,17,0,0,12,0,0,0,0,0,0,0,0,13,0,0,0,0,13,17,0,6,0,0,0,12,0,0,21,0,12,13,0,0,0,13,13,0,0,8,0,16,0,0,0,13,0,12,0,0,0,0,0
0,0,0,0,0,18,10,17,12,0,0,0,0,0,0,0,0,0,0,13,0,0,0,0,13,7,0,5,12,0,12,0,0,12,0,10,0,0,0,13,0,13,0,0,0,0,0,8,0,0,0,12,0,0,0,12,0,0,0,0,0,13,0,0,0,17,0,17,12,0,0,0,0,0,0,22,0,0,0
0,0,0,0,0,18,3,17,0,0,0,0,0,0,0,0,0,0,13,0,0,0,13,0,13,18,3,7,0,0,0,0,0,0,0,0,0,0,0,0,0,0,0,0,13,16,3,6,0,0,0,12,0,0,0,0,0,0,0,0,0,0,0,0,13,7,3,18,12,0,12,0,0,0,0,12,0,0,0
0,0,0,0,0,21,21,21,0,0,0,0,0,0,0,0,0,0,0,21,0,21,21,21,21,21,21,21,21,0,21,21,0,0,0,0,0,0,21,21,21,0,21,21,21,0,21,0,21,21,21,0,0,0,21,21,0,21,21,0,0,21,21,21,21,21,21,21,0,0,21,0,0,0,21,0,0,0,0
0,0,0,0,0,0,0,0,0,0,0,0,0,0,0,0,0,0,0,0,0,0,0,0,0,0,0,0,0,0,0,0,0,0,0,0,0,0,0,0,0,0,0,0,0,0,0,0,0,0,0,0,0,0,0,0,0,0,0,0,0,0,0,0,0,0,0,0,0,0,0,0,0,0,0,0,0,0,0
0,0,0,0,0,0,0,0,0,0,0,0,0,0,0,0,0,0,0,0,0,0,0,0,0,0,0,0,0,0,0,0,0,0,0,0,0,0,0,0,0,0,0,0,0,0,0,0,0,0,0,0,0,0,0,0,0,0,0,0,0,0,0,0,0,0,0,0,0,0,0,0,0,0,0,0,0,0,0
0,0,0,0,0,0,0,0,0,0,0,0,0,0,0,0,0,0,0,0,0,0,0,0,0,0,0,0,0,0,0,0,0,0,0,0,0,0,0,0,0,0,0,0,0,0,0,0,0,0,0,0,0,0,0,0,0,0,0,0,0,0,0,0,0,0,0,0,0,0,0,0,0,0,0,0,0,0,0
0,0,0,0,0,0,0,0,0,0,0,0,0,0,0,0,0,0,0,0,0,0,0,0,0,0,0,0,0,0,0,0,0,0,0,0,0,0,0,0,0,0,0,0,0,0,0,0,0,0,0,0,0,0,0,0,0,0,0,0,0,0,0,0,0,0,0,0,0,0,0,0,0,0,0,0,0,0,0
endlayer

layer
0,0,0,0,0,0,0,0,0,0,0,0,0,0,0,0,0,0,0,0,0,0,0,0,0,0,0,0,0,0,0,0,0,0,0,0,0,0,0,0,0,0,0,0,0,0,0,0,0,0,0,0,0,0,0,0,0,0,0,0,0,0,0,0,0,0,0,0,0,0,0,0,0,0,0,0,0,0,0
0,0,0,0,0,0,0,0,0,0,0,0,0,0,0,0,0,0,0,0,0,0,0,0,0,0,0,0,0,0,0,0,0,0,0,0,0,0,0,0,0,0,0,0,0,0,0,0,0,0,0,0,0,0,0,0,0,0,0,0,0,0,0,0,0,0,0,0,0,0,0,0,0,0,0,0,0,0,0
0,0,0,0,0,0,0,0,0,0,0,0,0,0,0,0,0,0,0,0,0,0,0,0,0,0,0,0,0,0,0,0,0,0,0,0,0,0,0,0,0,0,0,0,0,0,0,0,0,0,0,0,0,0,0,0,0,0,0,0,0,0,0,0,0,0,0,0,0,0,0,0,0,0,0,0,0,0,0
0,0,0,0,0,0,0,0,0,0,0,0,0,0,0,0,0,0,0,0,0,0,0,0,0,0,0,0,0,0,0,0,0,0,0,0,0,0,0,0,0,0,0,0,0,0,0,0,0,0,0,0,0,0,0,0,0,0,0,0,0,0,0,0,0,0,0,0,0,0,0,0,0,0,0,0,0,0,0
0,0,0,0,0,0,0,0,0,0,0,0,0,0,0,0,0,0,0,10,10,10,10,10,0,10,10,10,10,10,0,0,10,0,0,10,10,10,0,10,10,0,10,10,0,13,9,0,10,10,10,10,0,0,10,0,0,10,10,10,10,0,10,10,10,0,10,10,10,10,10,0,10,0,0,0,0,0,0
0,0,0,0,0,18,3,6,11,0,0,0,0,0,0,19,0,0,0,0,0,0,0,0,0,5,3,18,0,0,0,12,0,0,0,0,0,0,0,0,0,0,13,0,0,7,0,17,0,0,0,0,0,0,0,0,0,0,0,0,0,0,13,0,13,18,0,18,12,0,0,0,0,0,10,0,0,0,0
0,0,0,0,0,5,0,7,0,0,0,0,0,0,13,0,0,0,0,0,0,13,0,0,13,7,0,0,0,0,12,0,0,0,12,0,13,0,0,0,0,0,13,0,13,7,0,0,0,0,12,0,0,0,0,0,0,0,0,0,0,0,20,0,0,16,0,17,12,0,0,0,0,12,0,12,0,0,0
0,0,0,0,13,7,15,6,0,0,0,0,0,0,0,21,0,0,0,0,0,19,0,0,0,6,0,17,0,0,12,0,0,0,0,0,0,0,0,13,0,0,0,0,13,15,0,6,0,0,0,12,0,0,21,0,12,13,0,0,0,13,13,0,0,7,0,17,0,0,0,13,0,12,0,0,0,0,0
0,0,0,0,0,6,10,17,12,0,0,0,0,0,0,0,0,0,0,13,0,0,0,0,13,16,0,7,12,0,12,0,0,12,0,10,0,0,0,13,0,13,0,0,0,6,0,6,0,0,0,12,0,0,0,12,0,0,0,0,0,13,0,0,0,0,0,5,12,0,0,0,0,0,0,22,0,0,0
0,0,0,0,0,16,3,5,0,0,0,0,0,0,0,0,0,0,13,0,0,0,13,0,13,6,3,5,0,0,0,0,0,0,0,0,0,0,0,0,0,0,0,0,13,5,3,0,0,0,0,12,0,0,0,0,0,0,0,0,0,0,0,0,13,5,0,7,12,0,12,0,0,0,0,12,0,0,0
0,0,0,0,0,21,21,0,0,0,0,0,0,0,0,0,0,0,0,21,0,21,21,21,21,21,21,21,21,0,21,21,0,0,0,0,0,0,21,21,21,0,21,21,21,0,21,0,21,21,21,0,0,0,21,21,0,21,21,0,0,21,21,21,21,21,21,21,0,0,21,0,0,0,21,0,0,0,0
0,0,0,0,0,0,0,0,0,0,0,0,0,0,0,0,0,0,0,0,0,0,0,0,0,0,0,0,0,0,0,0,0,0,0,0,0,0,0,0,0,0,0,0,0,0,0,0,0,0,0,0,0,0,0,0,0,0,0,0,0,0,0,0,0,0,0,0,0,0,0,0,0,0,0,0,0,0,0
0,0,0,0,0,0,0,0,0,0,0,0,0,0,0,0,0,0,0,0,0,0,0,0,0,0,0,0,0,0,0,0,0,0,0,0,0,0,0,0,0,0,0,0,0,0,0,0,0,0,0,0,0,0,0,0,0,0,0,0,0,0,0,0,0,0,0,0,0,0,0,0,0,0,0,0,0,0,0
0,0,0,0,0,0,0,0,0,0,0,0,0,0,0,0,0,0,0,0,0,0,0,0,0,0,0,0,0,0,0,0,0,0,0,0,0,0,0,0,0,0,0,0,0,0,0,0,0,0,0,0,0,0,0,0,0,0,0,0,0,0,0,0,0,0,0,0,0,0,0,0,0,0,0,0,0,0,0
0,0,0,0,0,0,0,0,0,0,0,0,0,0,0,0,0,0,0,0,0,0,0,0,0,0,0,0,0,0,0,0,0,0,0,0,0,0,0,0,0,0,0,0,0,0,0,0,0,0,0,0,0,0,0,0,0,0,0,0,0,0,0,0,0,0,0,0,0,0,0,0,0,0,0,0,0,0,0
endlayer

layer
0,0,0,0,0,0,0,0,0,0,0,0,0,0,0,0,0,0,0,0,0,0,0,0,0,0,0,0,0,0,0,0,0,0,0,0,0,0,0,0,0,0,0,0,0,0,0,0,0,0,0,0,0,0,0,0,0,0,0,0,0,0,0,0,0,0,0,0,0,0,0,0,0,0,0,0,0,0,0
0,0,0,0,0,0,0,0,0,0,0,0,0,0,0,0,0,0,0,0,0,0,0,0,0,0,0,0,0,0,0,0,0,0,0,0,0,0,0,0,0,0,0,0,0,0,0,0,0,0,0,0,0,0,0,0,0,0,0,0,0,0,0,0,0,0,0,0,0,0,0,0,0,0,0,0,0,0,0
0,0,0,0,0,0,0,0,0,0,0,0,0,0,0,0,0,0,0,0,0,0,0,0,0,0,0,0,0,0,0,0,0,0,0,0,0,0,0,0,0,0,0,0,0,0,0,0,0,0,0,0,0,0,0,0,0,0,0,0,0,0,0,0,0,0,0,0,0,0,0,0,0,0,0,0,0,0,0
0,0,0,0,0,0,0,0,0,0,0,0,0,0,0,0,0,0,0,0,0,0,0,0,0,0,0,0,0,0,0,0,0,0,0,0,0,0,0,0,0,0,0,0,0,0,0,0,0,0,0,0,0,0,0,0,0,0,0,0,0,0,0,0,0,0,0,0,0,0,0,0,0,0,0,0,0,0,0
0,0,0,0,0,0,0,0,0,0,0,0,0,0,0,0,0,0,0,10,10,10,10,10,0,10,10,10,10,10,0,0,10,0,0,10,10,10,0,10,10,0,10,10,0,0,10,0,10,10,10,10,0,0,10,0,0,10,10,10,10,0,10,10,10,0,10,10,10,10,10,0,10,0,0,0,0,0,0
0,0,0,0,0,7,3,6,12,0,0,0,0,0,0,19,0,0,0,0,0,0,0,0,0,18,3,5,0,0,0,12,0,0,0,0,0,0,0,0,0,0,13,0,0,5,3,17,0,0,0,0,0,0,0,0,0,0,0,0,0,0,13,0,13,5,3,18,12,0,0,0,0,0,10,0,0,0,0
0,0,0,0,0,0,0,16,0,0,0,0,0,0,13,0,0,0,0,0,0,13,0,0,13,5,0,7,0,0,12,0,0,0,12,0,13,0,0,0,0,0,13,0,13,5,0,8,0,0,12,0,0,0,0,0,0,0,0,0,0,0,20,0,0,0,15,0,12,0,0,0,0,12,0,12,0,0,0
0,0,0,0,13,16,0,17,0,0,0,0,0,0,0,21,0,0,0,0,0,19,0,0,0,5,0,0,0,0,12,0,0,0,0,0,0,0,0,13,0,0,0,0,13,7,0,17,0,0,0,12,0,0,21,0,12,13,0,0,0,13,13,0,0,6,0,0,0,0,0,13,0,12,0,0,0,0,0
0,0,0,0,0,17,10,7,12,0,0,0,0,0,0,0,0,0,0,13,0,0,0,0,13,0,15,5,12,0,12,0,0,12,0,10,0,0,0,13,0,13,0,0,0,16,15,5,0,0,0,12,0,0,0,12,0,0,0,0,0,13,0,0,0,8,0,17,12,0,0,0,0,0,0,22,0,0,0
0,0,0,0,0,18,3,6,0,0,0,0,0,0,0,0,0,0,13,0,0,0,13,0,13,18,3,6,0,0,0,0,0,0,0,0,0,0,0,0,0,0,0,0,13,8,3,6,0,0,0,12,0,0,0,0,0,0,0,0,0,0,0,0,13,6,3,6,12,0,12,0,0,0,0,12,0,0,0
0,0,0,0,0,21,21,0,0,0,0,0,0,0,0,0,0,0,0,21,0,21,21,21,21,21,21,21,21,0,21,21,0,0,0,0,0,0,21,21,21,0,21,21,21,0,21,0,21,21,21,0,0,0,21,21,0,21,21,0,0,21,21,21,21,21,21,21,0,0,21,0,0,0,21,0,0,0,0
0,0,0,0,0,0,0,0,0,0,0,0,0,0,0,0,0,0,0,0,0,0,0,0,0,0,0,0,0,0,0,0,0,0,0,0,0,0,0,0,0,0,0,0,0,0,0,0,0,0,0,0,0,0,0,0,0,0,0,0,0,0,0,0,0,0,0,0,0,0,0,0,0,0,0,0,0,0,0
0,0,0,0,0,0,0,0,0,0,0,0,0,0,0,0,0,0,0,0,0,0,0,0,0,0,0,0,0,0,0,0,0,0,0,0,0,0,0,0,0,0,0,0,0,0,0,0,0,0,0,0,0,0,0,0,0,0,0,0,0,0,0,0,0,0,0,0,0,0,0,0,0,0,0,0,0,0,0
0,0,0,0,0,0,0,0,0,0,0,0,0,0,0,0,0,0,0,0,0,0,0,0,0,0,0,0,0,0,0,0,0,0,0,0,0,0,0,0,0,0,0,0,0,0,0,0,0,0,0,0,0,0,0,0,0,0,0,0,0,0,0,0,0,0,0,0,0,0,0,0,0,0,0,0,0,0,0
0,0,0,0,0,0,0,0,0,0,0,0,0,0,0,0,0,0,0,0,0,0,0,0,0,0,0,0,0,0,0,0,0,0,0,0,0,0,0,0,0,0,0,0,0,0,0,0,0,0,0,0,0,0,0,0,0,0,0,0,0,0,0,0,0,0,0,0,0,0,0,0,0,0,0,0,0,0,0
endlayer

layer
0,0,0,0,0,0,0,0,0,0,0,0,0,0,0,0,0,0,0,0,0,0,0,0,0,0,0,0,0,0,0,0,0,0,0,0,0,0,0,0,0,0,0,0,0,0,0,0,0,0,0,0,0,0,0,0,0,0,0,0,0,0,0,0,0,0,0,0,0,0,0,0,0,0,0,0,0,0,0
0,0,0,0,0,0,0,0,0,0,0,0,0,0,0,0,0,0,0,0,0,0,0,0,0,0,0,0,0,0,0,0,0,0,0,0,0,0,0,0,0,0,0,0,0,0,0,0,0,0,0,0,0,0,0,0,0,0,0,0,0,0,0,0,0,0,0,0,0,0,0,0,0,0,0,0,0,0,0
0,0,0,0,0,0,0,0,0,0,0,0,0,0,0,0,0,0,0,0,0,0,0,0,0,0,0,0,0,0,0,0,0,0,0,0,0,0,0,0,0,0,0,0,0,0,0,0,0,0,0,0,0,0,0,0,0,0,0,0,0,0,0,0,0,0,0,0,0,0,0,0,0,0,0,0,0,0,0
0,0,0,0,0,0,0,0,0,0,0,0,0,0,0,0,0,0,0,0,0,0,0,0,0,0,0,0,0,0,0,0,0,0,0,0,0,0,0,0,0,0,0,0,0,0,0,0,0,0,0,0,0,0,0,0,0,0,0,0,0,0,0,0,0,0,0,0,0,0,0,0,0,0,0,0,0,0,0
0,0,0,0,0,0,0,0,0,0,0,0,0,0,0,0,0,0,0,10,10,10,10,10,0,10,10,10,10,10,0,0,10,0,0,10,10,10,0,10,10,0,10,10,0,0,10,0,10,10,10,10,0,0,10,0,0,10,10,10,10,0,10,10,10,0,10,10,10,10,10,0,10,0,0,0,0,0,0
0,0,0,0,0,17,3,5,0,0,0,0,0,0,0,19,0,0,0,0,0,0,0,0,0,17,3,6,0,0,0,12,0,0,0,0,0,0,0,0,0,0,13,0,0,0,3,15,0,0,0,0,0,0,0,0,0,0,0,0,0,0,13,0,0,7,3,17,12,0,0,0,0,0,10,0,0,0,0
0,0,0,0,0,17,0,0,0,0,0,0,0,0,13,0,0,0,0,0,0,13,0,0,13,26,15,17,0,0,12,0,0,0,12,0,13,0,0,0,0,0,13,0,13,10,0,8,0,0,12,0,0,0,0,0,0,0,0,0,0,0,20,0,0,17,0,8,12,0,0,0,0,12,0,12,0,0,0
0,0,0,0,0,18,0,15,0,0,0,0,0,0,0,21,0,0,0,0,0,19,0,0,0,0,0,17,0,0,12,0,0,0,0,0,0,0,0,13,0,0,0,0,13,17,0,6,0,0,0,12,0,0,21,0,12,13,0,0,0,13,13,0,0,15,0,17,0,0,0,13,0,12,0,0,0,0,0
0,0,0,0,0,15,10,8,0,0,0,0,0,0,0,0,0,0,0,13,0,0,0,0,13,18,0,16,12,0,12,0,0,12,0,10,0,0,0,13,0,13,0,0,0,5,15,0,0,0,0,12,0,0,0,12,0,0,0,0,0,13,0,0,0,17,0,8,12,0,0,0,0,0,0,22,0,0,0
0,0,0,0,0,7,3,6,0,0,0,0,0,0,0,0,0,0,13,0,0,0,13,0,13,17,3,18,0,0,0,0,0,0,0,0,0,0,0,0,0,0,0,0,13,17,3,6,0,0,0,12,0,0,0,0,0,0,0,0,0,0,0,0,13,8,3,17,12,0,12,0,0,0,0,12,0,0,0
0,0,0,0,0,21,21,0,0,0,0,0,0,0,0,0,0,0,0,21,0,21,21,21,21,21,21,21,21,0,21,21,0,0,0,0,0,0,21,21,21,0,21,21,21,0,21,0,21,21,21,0,0,0,21,21,0,21,21,0,0,21,21,21,21,21,21,21,0,0,21,0,0,0,21,0,0,0,0
0,0,0,0,0,0,0,0,0,0,0,0,0,0,0,0,0,0,0,0,0,0,0,0,0,0,0,0,0,0,0,0,0,0,0,0,0,0,0,0,0,0,0,0,0,0,0,0,0,0,0,0,0,0,0,0,0,0,0,0,0,0,0,0,0,0,0,0,0,0,0,0,0,0,0,0,0,0,0
0,0,0,0,0,0,0,0,0,0,0,0,0,0,0,0,0,0,0,0,0,0,0,0,0,0,0,0,0,0,0,0,0,0,0,0,0,0,0,0,0,0,0,0,0,0,0,0,0,0,0,0,0,0,0,0,0,0,0,0,0,0,0,0,0,0,0,0,0,0,0,0,0,0,0,0,0,0,0
0,0,0,0,0,0,0,0,0,0,0,0,0,0,0,0,0,0,0,0,0,0,0,0,0,0,0,0,0,0,0,0,0,0,0,0,0,0,0,0,0,0,0,0,0,0,0,0,0,0,0,0,0,0,0,0,0,0,0,0,0,0,0,0,0,0,0,0,0,0,0,0,0,0,0,0,0,0,0
0,0,0,0,0,0,0,0,0,0,0,0,0,0,0,0,0,0,0,0,0,0,0,0,0,0,0,0,0,0,0,0,0,0,0,0,0,0,0,0,0,0,0,0,0,0,0,0,0,0,0,0,0,0,0,0,0,0,0,0,0,0,0,0,0,0,0,0,0,0,0,0,0,0,0,0,0,0,0
endlayer

layer
0,0,0,0,0,0,0,0,0,0,0,0,0,0,0,0,0,0,0,0,0,0,0,0,0,0,0,0,0,0,0,0,0,0,0,0,0,0,0,0,0,0,0,0,0,0,0,0,0,0,0,0,0,0,0,0,0,0,0,0,0,0,0,0,0,0,0,0,0,0,0,0,0,0,0,0,0,0,0
0,0,0,0,0,0,0,0,0,0,0,0,0,0,0,0,0,0,0,0,0,0,0,0,0,0,0,0,0,0,0,0,0,0,0,0,0,0,0,0,0,0,0,0,0,0,0,0,0,0,0,0,0,0,0,0,0,0,0,0,0,0,0,0,0,0,0,0,0,0,0,0,0,0,0,0,0,0,0
0,0,0,0,0,0,0,0,0,0,0,0,0,0,0,0,0,0,0,0,0,0,0,0,0,0,0,0,0,0,0,0,0,0,0,0,0,0,0,0,0,0,0,0,0,0,0,0,0,0,0,0,0,0,0,0,0,0,0,0,0,0,0,0,0,0,0,0,0,0,0,0,0,0,0,0,0,0,0
0,0,0,0,0,0,0,0,0,0,0,0,0,0,0,0,0,0,0,0,0,0,0,0,0,0,0,0,0,0,0,0,0,0,0,0,0,0,0,0,0,0,0,0,0,0,0,0,0,0,0,0,0,0,0,0,0,0,0,0,0,0,0,0,0,0,0,0,0,0,0,0,0,0,0,0,0,0,0
0,0,0,0,0,0,0,0,0,0,0,0,0,0,0,0,0,0,0,10,10,10,10,10,0,10,10,10,10,10,0,0,10,0,0,10,10,10,0,10,10,0,10,10,0,0,10,0,10,10,10,10,0,0,10,0,0,10,10,10,10,0,10,10,10,0,10,10,10,10,10,0,10,0,0,0,0,0,0
0,0,0,0,0,16,0,7,0,0,0,0,0,0,0,19,0,0,0,0,0,0,0,0,0,0,3,18,0,0,0,12,0,0,0,0,0,0,0,0,0,0,13,0,0,6,3,16,0,0,0,0,0,0,0,0,0,0,0,0,0,0,13,0,0,8,3,0,12,0,0,0,0,0,10,0,0,0,0
0,0,0,0,0,7,0,0,0,0,0,0,0,0,13,0,0,0,0,0,0,13,0,0,13,17,0,0,0,0,12,0,0,0,12,0,13,0,0,0,0,0,13,0,13,6,0,7,0,0,12,0,0,0,0,0,0,0,0,0,0,0,20,0,0,8,0,0,12,0,0,0,0,12,0,12,0,0,0
0,0,0,0,0,0,0,0,0,0,0,0,0,0,0,21,0,0,0,0,0,19,0,0,0,5,0,18,0,0,12,0,0,0,0,0,0,0,0,13,0,0,0,0,13,0,15,17,0,0,0,12,0,0,21,0,12,13,0,0,0,13,13,0,0,7,0,8,0,0,0,13,0,12,0,0,0,0,0
0,0,0,0,0,0,10,0,0,0,0,0,0,0,0,0,0,0,0,13,0,0,0,0,13,18,0,6,0,0,12,0,0,12,0,10,0,0,0,13,0,13,0,0,0,18,0,8,0,0,0,12,0,0,0,12,0,0,0,0,0,13,0,0,0,0,0,7,0,0,0,0,0,0,0,22,0,0,0
0,0,0,0,0,18,3,12,0,0,0,0,0,0,0,0,0,0,13,0,0,0,13,0,13,5,3,7,0,0,0,0,0,0,0,0,0,0,0,0,0,0,0,0,13,7,3,5,0,0,0,12,0,0,0,0,0,0,0,0,0,0,0,0,13,5,3,8,12,0,12,0,0,0,0,12,0,0,0
0,0,0,0,0,0,21,0,0,0,0,0,0,0,0,0,0,0,0,21,0,21,21,21,21,21,21,21,21,0,21,21,0,0,0,0,0,0,21,21,21,0,21,21,21,0,21,0,21,21,21,0,0,0,21,21,0,21,21,0,0,21,21,21,21,21,21,21,0,0,21,0,0,0,21,0,0,0,0
0,0,0,0,0,0,0,0,0,0,0,0,0,0,0,0,0,0,0,0,0,0,0,0,0,0,0,0,0,0,0,0,0,0,0,0,0,0,0,0,0,0,0,0,0,0,0,0,0,0,0,0,0,0,0,0,0,0,0,0,0,0,0,0,0,0,0,0,0,0,0,0,0,0,0,0,0,0,0
0,0,0,0,0,0,0,0,0,0,0,0,0,0,0,0,0,0,0,0,0,0,0,0,0,0,0,0,0,0,0,0,0,0,0,0,0,0,0,0,0,0,0,0,0,0,0,0,0,0,0,0,0,0,0,0,0,0,0,0,0,0,0,0,0,0,0,0,0,0,0,0,0,0,0,0,0,0,0
0,0,0,0,0,0,0,0,0,0,0,0,0,0,0,0,0,0,0,0,0,0,0,0,0,0,0,0,0,0,0,0,0,0,0,0,0,0,0,0,0,0,0,0,0,0,0,0,0,0,0,0,0,0,0,0,0,0,0,0,0,0,0,0,0,0,0,0,0,0,0,0,0,0,0,0,0,0,0
0,0,0,0,0,0,0,0,0,0,0,0,0,0,0,0,0,0,0,0,0,0,0,0,0,0,0,0,0,0,0,0,0,0,0,0,0,0,0,0,0,0,0,0,0,0,0,0,0,0,0,0,0,0,0,0,0,0,0,0,0,0,0,0,0,0,0,0,0,0,0,0,0,0,0,0,0,0,0
endlayer

layer
0,0,0,0,0,0,0,0,0,0,0,0,0,0,0,0,0,0,0,0,0,0,0,0,0,0,0,0,0,0,0,0,0,0,0,0,0,0,0,0,0,0,0,0,0,0,0,0,0,0,0,0,0,0,0,0,0,0,0,0,0,0,0,0,0,0,0,0,0,0,0,0,0,0,0,0,0,0,0
0,0,0,0,0,0,0,0,0,0,0,0,0,0,0,0,0,0,0,0,0,0,0,0,0,0,0,0,0,0,0,0,0,0,0,0,0,0,0,0,0,0,0,0,0,0,0,0,0,0,0,0,0,0,0,0,0,0,0,0,0,0,0,0,0,0,0,0,0,0,0,0,0,0,0,0,0,0,0
0,0,0,0,0,0,0,0,0,0,0,0,0,0,0,0,0,0,0,0,0,0,0,0,0,0,0,0,0,0,0,0,0,0,0,0,0,0,0,0,0,0,0,0,0,0,0,0,0,0,0,0,0,0,0,0,0,0,0,0,0,0,0,0,0,0,0,0,0,0,0,0,0,0,0,0,0,0,0
0,0,0,0,0,0,0,0,0,0,0,0,0,0,0,0,0,0,0,0,0,0,0,0,0,0,0,0,0,0,0,0,0,0,0,0,0,0,0,0,0,0,0,0,0,0,0,0,0,0,0,0,0,0,0,0,0,0,0,0,0,0,0,0,0,0,0,0,0,0,0,0,0,0,0,0,0,0,0
0,0,0,0,0,0,0,0,0,0,0,0,0,0,0,0,0,0,0,10,10,10,10,10,0,10,10,10,10,10,0,0,10,0,0,10,10,10,0,10,10,0,10,10,0,0,10,0,10,10,10,10,0,0,10,0,0,10,10,10,10,0,10,10,10,0,10,10,10,10,10,0,10,0,0,0,0,0,0
0,0,0,0,0,0,0,0,0,0,0,0,0,0,0,19,0,0,0,0,0,0,0,0,0,6,3,0,0,0,0,12,0,0,0,0,0,0,0,0,0,0,13,0,0,0,3,5,0,0,0,0,0,0,0,0,0,0,0,0,0,0,13,0,0,6,3,8,12,0,0,0,0,0,10,0,0,0,0
0,0,0,0,0,0,0,0,0,0,0,0,0,0,13,0,0,0,0,0,0,13,0,0,13,7,0,7,0,0,12,0,0,0,12,0,13,0,0,0,0,0,13,0,13,17,0,17,0,0,12,0,0,0,0,0,0,0,0,0,0,0,20,0,0,17,0,7,12,0,0,0,0,12,0,12,0,0,0
0,0,0,0,0,0,0,0,0,0,0,0,0,0,0,21,0,0,0,0,0,19,0,0,0,18,0,18,0,0,12,0,0,0,0,0,0,0,0,13,0,0,0,0,13,5,0,5,0,0,0,12,0,0,21,0,12,13,0,0,0,13,13,0,0,0,0,21,0,0,0,13,0,12,0,0,0,0,0
0,0,0,0,0,0,10,0,0,0,0,0,0,0,0,0,0,0,0,13,0,0,0,0,13,15,0,15,0,0,12,0,0,12,0,10,0,0,0,13,0,13,0,0,0,7,0,6,0,0,0,12,0,0,0,12,0,0,0,0,0,13,0,0,0,8,0,6,0,0,0,0,0,0,0,22,0,0,0
0,0,0,0,0,6,3,12,0,0,0,0,0,0,0,0,0,0,13,0,0,0,13,0,13,16,3,5,0,0,0,0,0,0,0,0,0,0,0,0,0,0,0,0,13,17,3,17,0,0,0,12,0,0,0,0,0,0,0,0,0,0,0,0,13,6,3,15,12,0,12,0,0,0,0,12,0,0,0
0,0,0,0,0,0,0,0,0,0,0,0,0,0,0,0,0,0,0,21,0,21,21,21,21,21,21,21,21,0,21,21,0,0,0,0,0,0,21,21,21,0,21,21,21,0,0,0,21,21,21,0,0,0,21,21,0,21,21,0,0,21,21,21,21,21,21,21,0,0,21,0,0,0,21,0,0,0,0
0,0,0,0,0,0,0,0,0,0,0,0,0,0,0,0,0,0,0,0,0,0,0,0,0,0,0,0,0,0,0,0,0,0,0,0,0,0,0,0,0,0,0,0,0,0,0,0,0,0,0,0,0,0,0,0,0,0,0,0,0,0,0,0,0,0,0,0,0,0,0,0,0,0,0,0,0,0,0
0,0,0,0,0,0,0,0,0,0,0,0,0,0,0,0,0,0,0,0,0,0,0,0,0,0,0,0,0,0,0,0,0,0,0,0,0,0,0,0,0,0,0,0,0,0,0,0,0,0,0,0,0,0,0,0,0,0,0,0,0,0,0,0,0,0,0,0,0,0,0,0,0,0,0,0,0,0,0
0,0,0,0,0,0,0,0,0,0,0,0,0,0,0,0,0,0,0,0,0,0,0,0,0,0,0,0,0,0,0,0,0,0,0,0,0,0,0,0,0,0,0,0,0,0,0,0,0,0,0,0,0,0,0,0,0,0,0,0,0,0,0,0,0,0,0,0,0,0,0,0,0,0,0,0,0,0,0
0,0,0,0,0,0,0,0,0,0,0,0,0,0,0,0,0,0,0,0,0,0,0,0,0,0,0,0,0,0,0,0,0,0,0,0,0,0,0,0,0,0,0,0,0,0,0,0,0,0,0,0,0,0,0,0,0,0,0,0,0,0,0,0,0,0,0,0,0,0,0,0,0,0,0,0,0,0,0
endlayer

layer
0,0,0,0,0,0,0,0,0,0,0,0,0,0,0,0,0,0,0,0,0,0,0,0,0,0,0,0,0,0,0,0,0,0,0,0,0,0,0,0,0,0,0,0,0,0,0,0,0,0,0,0,0,0,0,0,0,0,0,0,0,0,0,0,0,0,0,0,0,0,0,0,0,0,0,0,0,0,0
0,0,0,0,0,0,0,0,0,0,0,0,0,0,0,0,0,0,0,0,0,0,0,0,0,0,0,0,0,0,0,0,0,0,0,0,0,0,0,0,0,0,0,0,0,0,0,0,0,0,0,0,0,0,0,0,0,0,0,0,0,0,0,0,0,0,0,0,0,0,0,0,0,0,0,0,0,0,0
0,0,0,0,0,0,0,0,0,0,0,0,0,0,0,0,0,0,0,0,0,0,0,0,0,0,0,0,0,0,0,0,0,0,0,0,0,0,0,0,0,0,0,0,0,0,0,0,0,0,0,0,0,0,0,0,0,0,0,0,0,0,0,0,0,0,0,0,0,0,0,0,0,0,0,0,0,0,0
0,0,0,0,0,0,0,0,0,0,0,0,0,0,0,0,0,0,0,0,0,0,0,0,0,0,0,0,0,0,0,0,0,0,0,0,0,0,0,0,0,0,0,0,0,0,0,0,0,0,0,0,0,0,0,0,0,0,0,0,0,0,0,0,0,0,0,0,0,0,0,0,0,0,0,0,0,0,0
0,0,0,0,0,0,0,0,0,0,0,0,0,0,0,0,0,0,0,10,10,10,10,10,0,10,10,10,10,10,0,0,10,0,0,10,10,10,0,10,10,0,10,10,0,0,10,0,10,10,10,10,0,0,10,0,0,10,10,10,10,0,10,10,10,0,10,10,10,10,10,0,10,0,0,0,0,0,0
0,0,0,0,0,0,0,0,0,0,0,0,0,0,0,19,0,0,0,0,0,0,0,0,0,17,3,0,0,0,0,12,0,0,0,0,0,0,0,0,0,0,13,0,0,17,0,6,0,0,0,0,0,0,0,0,0,0,0,0,0,0,13,0,0,18,0,16,0,0,0,0,0,0,10,0,0,0,0
0,0,0,0,0,0,0,0,0,0,0,0,0,0,13,0,0,0,0,0,0,13,0,0,13,6,15,6,0,0,12,0,0,0,12,0,13,0,0,0,0,0,13,0,13,16,0,0,0,0,12,0,0,0,0,0,0,0,0,0,0,0,20,0,0,0,0,6,0,0,0,0,0,12,0,12,0,0,0
0,0,0,0,0,0,0,0,0,0,0,0,0,0,0,21,0,0,0,0,0,19,0,0,0,21,0,5,0,0,12,0,0,0,0,0,0,0,0,13,0,0,0,0,0,0,0,7,0,0,0,12,0,0,21,0,12,13,0,0,0,13,13,0,0,5,15,0,0,0,0,13,0,12,0,0,0,0,0
0,0,0,0,0,0,10,0,0,0,0,0,0,0,0,0,0,0,0,13,0,0,0,0,13,6,0,17,0,0,12,0,0,12,0,10,0,0,0,13,0,13,0,0,0,0,0,15,0,0,0,12,0,0,0,12,0,0,0,0,0,13,0,0,0,6,0,6,0,0,0,0,0,0,0,22,0,0,0
0,0,0,0,0,13,3,12,0,0,0,0,0,0,0,0,0,0,13,0,0,0,13,0,13,6,3,17,0,0,0,0,0,0,0,0,0,0,0,0,0,0,0,0,13,17,3,17,0,0,0,12,0,0,0,0,0,0,0,0,0,0,0,0,13,7,3,16,12,0,12,0,0,0,0,12,0,0,0
0,0,0,0,0,0,0,0,0,0,0,0,0,0,0,0,0,0,0,21,0,21,21,21,21,21,21,21,21,0,21,21,0,0,0,0,0,0,21,21,21,0,21,21,21,0,0,0,21,21,21,0,0,0,21,21,0,21,21,0,0,21,21,21,21,21,21,21,0,0,21,0,0,0,21,0,0,0,0
0,0,0,0,0,0,0,0,0,0,0,0,0,0,0,0,0,0,0,0,0,0,0,0,0,0,0,0,0,0,0,0,0,0,0,0,0,0,0,0,0,0,0,0,0,0,0,0,0,0,0,0,0,0,0,0,0,0,0,0,0,0,0,0,0,0,0,0,0,0,0,0,0,0,0,0,0,0,0
0,0,0,0,0,0,0,0,0,0,0,0,0,0,0,0,0,0,0,0,0,0,0,0,0,0,0,0,0,0,0,0,0,0,0,0,0,0,0,0,0,0,0,0,0,0,0,0,0,0,0,0,0,0,0,0,0,0,0,0,0,0,0,0,0,0,0,0,0,0,0,0,0,0,0,0,0,0,0
0,0,0,0,0,0,0,0,0,0,0,0,0,0,0,0,0,0,0,0,0,0,0,0,0,0,0,0,0,0,0,0,0,0,0,0,0,0,0,0,0,0,0,0,0,0,0,0,0,0,0,0,0,0,0,0,0,0,0,0,0,0,0,0,0,0,0,0,0,0,0,0,0,0,0,0,0,0,0
0,0,0,0,0,0,0,0,0,0,0,0,0,0,0,0,0,0,0,0,0,0,0,0,0,0,0,0,0,0,0,0,0,0,0,0,0,0,0,0,0,0,0,0,0,0,0,0,0,0,0,0,0,0,0,0,0,0,0,0,0,0,0,0,0,0,0,0,0,0,0,0,0,0,0,0,0,0,0
endlayer

layer
0,0,0,0,0,0,0,0,0,0,0,0,0,0,0,0,0,0,0,0,0,0,0,0,0,0,0,0,0,0,0,0,0,0,0,0,0,0,0,0,0,0,0,0,0,0,0,0,0,0,0,0,0,0,0,0,0,0,0,0,0,0,0,0,0,0,0,0,0,0,0,0,0,0,0,0,0,0,0
0,0,0,0,0,0,0,0,0,0,0,0,0,0,0,0,0,0,0,0,0,0,0,0,0,0,0,0,0,0,0,0,0,0,0,0,0,0,0,0,0,0,0,0,0,0,0,0,0,0,0,0,0,0,0,0,0,0,0,0,0,0,0,0,0,0,0,0,0,0,0,0,0,0,0,0,0,0,0
0,0,0,0,0,0,0,0,0,0,0,0,0,0,0,0,0,0,0,0,0,0,0,0,0,0,0,0,0,0,0,0,0,0,0,0,0,0,0,0,0,0,0,0,0,0,0,0,0,0,0,0,0,0,0,0,0,0,0,0,0,0,0,0,0,0,0,0,0,0,0,0,0,0,0,0,0,0,0
0,0,0,0,0,0,0,0,0,0,0,0,0,0,0,0,0,0,0,0,0,0,0,0,0,0,0,0,0,0,0,0,0,0,0,0,0,0,0,0,0,0,0,0,0,0,0,0,0,0,0,0,0,0,0,0,0,0,0,0,0,0,0,0,0,0,0,0,0,0,0,0,0,0,0,0,0,0,0
0,0,0,0,0,0,0,0,0,0,0,0,0,0,0,0,0,0,0,10,10,10,10,10,0,10,10,10,10,10,0,0,10,0,0,10,10,10,0,10,10,0,10,10,0,0,10,0,10,10,10,10,0,0,10,0,0,10,10,10,10,0,10,10,10,0,10,10,10,10,10,0,10,0,0,0,0,0,0
0,0,0,0,0,0,0,0,0,0,0,0,0,0,0,19,0,0,0,0,0,0,0,0,0,7,0,17,0,0,0,12,0,0,0,0,0,0,0,0,0,0,13,0,0,6,3,6,0,0,0,0,0,0,0,0,0,0,0,0,0,0,13,0,0,5,3,17,0,0,0,0,0,0,10,0,0,0,0
0,0,0,0,0,0,0,0,0,0,0,0,0,0,13,0,0,0,0,0,0,13,0,0,0,5,0,18,0,0,12,0,0,0,12,0,13,0,0,0,0,0,13,0,13,6,0,17,0,0,12,0,0,0,0,0,0,0,0,0,0,0,20,0,0,8,0,0,0,0,0,0,0,12,0,12,0,0,0
0,0,0,0,0,0,0,0,0,0,0,0,0,0,0,21,0,0,0,0,0,19,0,0,0,21,0,0,0,0,12,0,0,0,0,0,0,0,0,13,0,0,0,0,0,18,0,0,0,0,0,12,0,0,21,0,12,13,0,0,0,13,13,0,0,17,0,5,0,0,0,13,0,12,0,0,0,0,0
0,0,0,0,0,0,0,0,0,0,0,0,0,0,0,0,0,0,0,13,0,0,0,0,13,0,0,0,0,0,12,0,0,12,0,10,0,0,0,13,0,13,0,0,0,17,0,7,0,0,0,12,0,0,0,12,0,0,0,0,0,13,0,0,0,15,0,7,0,0,0,0,0,0,0,22,0,0,0
0,0,0,0,0,0,0,0,0,0,0,0,0,0,0,0,0,0,13,0,0,0,13,0,13,18,3,16,0,0,0,0,0,0,0,0,0,0,0,0,0,0,0,0,13,5,3,17,0,0,0,12,0,0,0,0,0,0,0,0,0,0,0,0,13,7,3,5,12,0,12,0,0,0,0,12,0,0,0
0,0,0,0,0,0,0,0,0,0,0,0,0,0,0,0,0,0,0,21,0,21,21,21,21,21,21,21,21,0,21,21,0,0,0,0,0,0,21,21,21,0,21,21,21,0,0,0,21,21,21,0,0,0,21,21,0,21,21,0,0,21,21,21,21,21,21,21,0,0,21,0,0,0,21,0,0,0,0
0,0,0,0,0,0,0,0,0,0,0,0,0,0,0,0,0,0,0,0,0,0,0,0,0,0,0,0,0,0,0,0,0,0,0,0,0,0,0,0,0,0,0,0,0,0,0,0,0,0,0,0,0,0,0,0,0,0,0,0,0,0,0,0,0,0,0,0,0,0,0,0,0,0,0,0,0,0,0
0,0,0,0,0,0,0,0,0,0,0,0,0,0,0,0,0,0,0,0,0,0,0,0,0,0,0,0,0,0,0,0,0,0,0,0,0,0,0,0,0,0,0,0,0,0,0,0,0,0,0,0,0,0,0,0,0,0,0,0,0,0,0,0,0,0,0,0,0,0,0,0,0,0,0,0,0,0,0
0,0,0,0,0,0,0,0,0,0,0,0,0,0,0,0,0,0,0,0,0,0,0,0,0,0,0,0,0,0,0,0,0,0,0,0,0,0,0,0,0,0,0,0,0,0,0,0,0,0,0,0,0,0,0,0,0,0,0,0,0,0,0,0,0,0,0,0,0,0,0,0,0,0,0,0,0,0,0
0,0,0,0,0,0,0,0,0,0,0,0,0,0,0,0,0,0,0,0,0,0,0,0,0,0,0,0,0,0,0,0,0,0,0,0,0,0,0,0,0,0,0,0,0,0,0,0,0,0,0,0,0,0,0,0,0,0,0,0,0,0,0,0,0,0,0,0,0,0,0,0,0,0,0,0,0,0,0
endlayer

layer
0,0,0,0,0,0,0,0,0,0,0,0,0,0,0,0,0,0,0,0,0,0,0,0,0,0,0,0,0,0,0,0,0,0,0,0,0,0,0,0,0,0,0,0,0,0,0,0,0,0,0,0,0,0,0,0,0,0,0,0,0,0,0,0,0,0,0,0,0,0,0,0,0,0,0,0,0,0,0
0,0,0,0,0,0,0,0,0,0,0,0,0,0,0,0,0,0,0,0,0,0,0,0,0,0,0,0,0,0,0,0,0,0,0,0,0,0,0,0,0,0,0,0,0,0,0,0,0,0,0,0,0,0,0,0,0,0,0,0,0,0,0,0,0,0,0,0,0,0,0,0,0,0,0,0,0,0,0
0,0,0,0,0,0,0,0,0,0,0,0,0,0,0,0,0,0,0,0,0,0,0,0,0,0,0,0,0,0,0,0,0,0,0,0,0,0,0,0,0,0,0,0,0,0,0,0,0,0,0,0,0,0,0,0,0,0,0,0,0,0,0,0,0,0,0,0,0,0,0,0,0,0,0,0,0,0,0
0,0,0,0,0,0,0,0,0,0,0,0,0,0,0,0,0,0,0,0,0,0,0,0,0,0,0,0,0,0,0,0,0,0,0,0,0,0,0,0,0,0,0,0,0,0,0,0,0,0,0,0,0,0,0,0,0,0,0,0,0,0,0,0,0,0,0,0,0,0,0,0,0,0,0,0,0,0,0
0,0,0,0,0,0,0,0,0,0,0,0,0,0,0,0,0,0,0,10,10,10,10,10,0,10,10,10,10,10,0,0,10,0,0,10,10,10,0,10,10,0,10,10,0,0,10,0,10,10,10,10,0,0,10,0,0,10,10,10,10,0,10,10,10,0,10,0,10,10,10,0,10,0,0,0,0,0,0
0,0,0,0,0,0,0,0,0,0,0,0,0,0,0,19,0,0,0,0,0,0,0,0,0,18,3,17,0,0,0,12,0,0,0,0,0,0,0,0,0,0,13,0,0,7,3,6,0,0,0,0,0,0,0,0,0,0,0,0,0,0,13,0,0,6,3,18,0,0,0,0,0,0,10,0,0,0,0
0,0,0,0,0,0,0,0,0,0,0,0,0,0,13,0,0,0,0,0,0,13,0,0,0,0,0,16,0,0,12,0,0,0,12,0,13,0,0,0,0,0,13,0,13,0,15,0,0,0,12,0,0,0,0,0,0,0,0,0,0,0,20,0,0,16,0,16,0,0,0,0,0,12,0,12,0,0,0
0,0,0,0,0,0,0,0,0,0,0,0,0,0,0,21,0,0,0,0,0,19,0,0,0,7,0,0,0,0,12,0,0,0,0,0,0,0,0,13,0,0,0,0,0,18,0,5,0,0,0,12,0,0,21,0,12,13,0,0,0,13,13,0,0,0,15,6,0,0,0,13,0,12,0,0,0,0,0
0,0,0,0,0,0,0,0,0,0,0,0,0,0,0,0,0,0,0,13,0,0,0,0,13,5,0,18,0,0,12,0,0,12,0,10,0,0,0,13,0,13,0,0,0,0,0,16,0,0,0,12,0,0,0,12,0,0,0,0,0,13,0,0,0,17,0,17,0,0,0,0,0,0,0,22,0,0,0
0,0,0,0,0,0,0,0,0,0,0,0,0,0,0,0,0,0,13,0,0,0,13,0,13,6,3,17,0,0,0,0,0,0,0,0,0,0,0,0,0,0,0,0,13,8,3,8,0,0,0,12,0,0,0,0,0,0,0,0,0,0,0,0,0,13,3,7,12,0,12,0,0,0,0,12,0,0,0
0,0,0,0,0,0,0,0,0,0,0,0,0,0,0,0,0,0,0,21,0,21,21,21,21,21,21,21,21,0,21,21,0,0,0,0,0,0,21,21,21,0,21,21,21,0,0,0,21,21,21,0,0,0,21,21,0,21,21,0,0,21,21,21,21,21,21,21,0,0,21,0,0,0,21,0,0,0,0
0,0,0,0,0,0,0,0,0,0,0,0,0,0,0,0,0,0,0,0,0,0,0,0,0,0,0,0,0,0,0,0,0,0,0,0,0,0,0,0,0,0,0,0,0,0,0,0,0,0,0,0,0,0,0,0,0,0,0,0,0,0,0,0,0,0,0,0,0,0,0,0,0,0,0,0,0,0,0
0,0,0,0,0,0,0,0,0,0,0,0,0,0,0,0,0,0,0,0,0,0,0,0,0,0,0,0,0,0,0,0,0,0,0,0,0,0,0,0,0,0,0,0,0,0,0,0,0,0,0,0,0,0,0,0,0,0,0,0,0,0,0,0,0,0,0,0,0,0,0,0,0,0,0,0,0,0,0
0,0,0,0,0,0,0,0,0,0,0,0,0,0,0,0,0,0,0,0,0,0,0,0,0,0,0,0,0,0,0,0,0,0,0,0,0,0,0,0,0,0,0,0,0,0,0,0,0,0,0,0,0,0,0,0,0,0,0,0,0,0,0,0,0,0,0,0,0,0,0,0,0,0,0,0,0,0,0
0,0,0,0,0,0,0,0,0,0,0,0,0,0,0,0,0,0,0,0,0,0,0,0,0,0,0,0,0,0,0,0,0,0,0,0,0,0,0,0,0,0,0,0,0,0,0,0,0,0,0,0,0,0,0,0,0,0,0,0,0,0,0,0,0,0,0,0,0,0,0,0,0,0,0,0,0,0,0
endlayer

layer
0,0,0,0,0,0,0,0,0,0,0,0,0,0,0,0,0,0,0,0,0,0,0,0,0,0,0,0,0,0,0,0,0,0,0,0,0,0,0,0,0,0,0,0,0,0,0,0,0,0,0,0,0,0,0,0,0,0,0,0,0,0,0,0,0,0,0,0,0,0,0,0,0,0,0,0,0,0,0
0,0,0,0,0,0,0,0,0,0,0,0,0,0,0,0,0,0,0,0,0,0,0,0,0,0,0,0,0,0,0,0,0,0,0,0,0,0,0,0,0,0,0,0,0,0,0,0,0,0,0,0,0,0,0,0,0,0,0,0,0,0,0,0,0,0,0,0,0,0,0,0,0,0,0,0,0,0,0
0,0,0,0,0,0,0,0,0,0,0,0,0,0,0,0,0,0,0,0,0,0,0,0,0,0,0,0,0,0,0,0,0,0,0,0,0,0,0,0,0,0,0,0,0,0,0,0,0,0,0,0,0,0,0,0,0,0,0,0,0,0,0,0,0,0,0,0,0,0,0,0,0,0,0,0,0,0,0
0,0,0,0,0,0,0,0,0,0,0,0,0,0,0,0,0,0,0,0,0,0,0,0,0,0,0,0,0,0,0,0,0,0,0,0,0,0,0,0,0,0,0,0,0,0,0,0,0,0,0,0,0,0,0,0,0,0,0,0,0,0,0,0,0,0,0,0,0,0,0,0,0,0,0,0,0,0,0
0,0,0,0,0,0,0,0,0,0,0,0,0,0,0,0,0,0,0,10,10,10,10,10,0,10,10,10,10,10,0,0,10,0,0,10,10,10,0,10,10,0,10,10,0,0,10,0,10,10,10,10,0,0,10,0,0,10,10,10,10,0,10,10,10,0,10,0,10,10,10,0,10,0,0,0,0,0,0
0,0,0,0,0,0,0,0,0,0,0,0,0,0,0,19,0,0,0,0,0,0,0,0,0,15,3,5,0,0,0,12,0,0,0,0,0,0,0,0,0,0,13,0,0,8,3,7,0,0,0,0,0,0,0,0,0,0,0,0,0,0,13,0,0,7,3,0,0,0,0,0,0,0,10,0,0,0,0
0,0,0,0,0,0,0,0,0,0,0,0,0,0,13,0,0,0,0,0,0,13,0,0,0,16,0,0,0,0,12,0,0,0,12,0,13,0,0,0,0,0,13,0,13,18,21,0,0,0,12,0,0,0,0,0,0,0,0,0,0,0,20,0,0,0,15,8,0,0,0,0,0,12,0,12,0,0,0
0,0,0,0,0,0,0,0,0,0,0,0,0,0,0,21,0,0,0,0,0,19,0,0,0,6,0,17,0,0,12,0,0,0,0,0,0,0,0,13,0,0,0,0,0,17,0,17,0,0,0,12,0,0,21,0,12,13,0,0,0,13,13,0,0,8,0,7,0,0,0,13,0,12,0,0,0,0,0
0,0,0,0,0,0,0,0,0,0,0,0,0,0,0,0,0,0,0,13,0,0,0,0,13,18,0,18,0,0,12,0,0,12,0,10,0,0,0,13,0,13,0,0,0,18,0,17,0,0,0,12,0,0,0,12,0,0,0,0,0,13,0,0,0,17,0,8,0,0,0,0,0,0,0,22,0,0,0
0,0,0,0,0,0,0,0,0,0,0,0,0,0,0,0,0,0,13,0,0,0,13,0,13,7,3,5,0,0,0,0,0,0,0,0,0,0,0,0,0,0,0,0,13,16,3,7,0,0,0,12,0,0,0,0,0,0,0,0,0,0,0,0,0,5,3,6,12,0,12,0,0,0,0,12,0,0,0
0,0,0,0,0,0,0,0,0,0,0,0,0,0,0,0,0,0,0,21,0,21,21,21,21,21,21,21,21,0,21,21,0,0,0,0,0,0,21,21,21,0,21,21,21,0,0,0,21,21,21,0,0,0,21,21,0,21,21,0,0,21,21,21,21,21,21,21,0,0,21,0,0,0,21,0,0,0,0
0,0,0,0,0,0,0,0,0,0,0,0,0,0,0,0,0,0,0,0,0,0,0,0,0,0,0,0,0,0,0,0,0,0,0,0,0,0,0,0,0,0,0,0,0,0,0,0,0,0,0,0,0,0,0,0,0,0,0,0,0,0,0,0,0,0,0,0,0,0,0,0,0,0,0,0,0,0,0
0,0,0,0,0,0,0,0,0,0,0,0,0,0,0,0,0,0,0,0,0,0,0,0,0,0,0,0,0,0,0,0,0,0,0,0,0,0,0,0,0,0,0,0,0,0,0,0,0,0,0,0,0,0,0,0,0,0,0,0,0,0,0,0,0,0,0,0,0,0,0,0,0,0,0,0,0,0,0
0,0,0,0,0,0,0,0,0,0,0,0,0,0,0,0,0,0,0,0,0,0,0,0,0,0,0,0,0,0,0,0,0,0,0,0,0,0,0,0,0,0,0,0,0,0,0,0,0,0,0,0,0,0,0,0,0,0,0,0,0,0,0,0,0,0,0,0,0,0,0,0,0,0,0,0,0,0,0
0,0,0,0,0,0,0,0,0,0,0,0,0,0,0,0,0,0,0,0,0,0,0,0,0,0,0,0,0,0,0,0,0,0,0,0,0,0,0,0,0,0,0,0,0,0,0,0,0,0,0,0,0,0,0,0,0,0,0,0,0,0,0,0,0,0,0,0,0,0,0,0,0,0,0,0,0,0,0
endlayer

layer
0,0,0,0,0,0,0,0,0,0,0,0,0,0,0,0,0,0,0,0,0,0,0,0,0,0,0,0,0,0,0,0,0,0,0,0,0,0,0,0,0,0,0,0,0,0,0,0,0,0,0,0,0,0,0,0,0,0,0,0,0,0,0,0,0,0,0,0,0,0,0,0,0,0,0,0,0,0,0
0,0,0,0,0,0,0,0,0,0,0,0,0,0,0,0,0,0,0,0,0,0,0,0,0,0,0,0,0,0,0,0,0,0,0,0,0,0,0,0,0,0,0,0,0,0,0,0,0,0,0,0,0,0,0,0,0,0,0,0,0,0,0,0,0,0,0,0,0,0,0,0,0,0,0,0,0,0,0
0,0,0,0,0,0,0,0,0,0,0,0,0,0,0,0,0,0,0,0,0,0,0,0,0,0,0,0,0,0,0,0,0,0,0,0,0,0,0,0,0,0,0,0,0,0,0,0,0,0,0,0,0,0,0,0,0,0,0,0,0,0,0,0,0,0,0,0,0,0,0,0,0,0,0,0,0,0,0
0,0,0,0,0,0,0,0,0,0,0,0,0,0,0,0,0,0,0,0,0,0,0,0,0,0,0,0,0,0,0,0,0,0,0,0,0,0,0,0,0,0,0,0,0,0,0,0,0,0,0,0,0,0,0,0,0,0,0,0,0,0,0,0,0,0,0,0,0,0,0,0,0,0,0,0,0,0,0
0,0,0,0,0,0,0,0,0,0,0,0,0,0,0,0,0,0,0,10,10,10,10,10,0,10,0,10,10,10,0,0,10,0,0,10,10,10,0,10,10,0,10,10,0,0,10,0,10,10,10,10,0,0,10,0,0,10,10,10,10,0,10,10,10,0,10,0,10,10,10,0,10,0,0,0,0,0,0
0,0,0,0,0,0,0,0,0,0,0,0,0,0,0,19,0,0,0,0,0,0,0,0,0,5,3,17,0,0,0,12,0,0,0,0,0,0,0,0,0,0,13,0,0,8,3,17,0,0,0,0,0,0,0,0,0,0,0,0,0,0,13,0,0,5,3,17,0,0,0,0,0,0,10,0,0,0,0
0,0,0,0,0,0,0,0,0,0,0,0,0,0,13,0,0,0,0,0,0,13,0,0,0,18,0,7,0,0,12,0,0,0,12,0,13,0,0,0,0,0,13,0,13,6,21,17,0,0,12,0,0,0,0,0,0,0,0,0,0,0,20,0,0,7,0,5,0,0,0,0,0,12,0,12,0,0,0
0,0,0,0,0,0,0,0,0,0,0,0,0,0,0,21,0,0,0,0,0,19,0,0,0,7,0,17,0,0,12,0,0,0,0,0,0,0,0,13,0,0,0,0,0,18,6,17,0,0,0,12,0,0,21,0,12,13,0,0,0,13,13,0,0,8,0,6,0,0,0,13,0,12,0,0,0,0,0
0,0,0,0,0,0,0,0,0,0,0,0,0,0,0,0,0,0,0,13,0,0,0,0,13,17,0,18,0,0,12,0,0,12,0,10,0,0,0,13,0,13,0,0,0,7,0,8,0,0,0,12,0,0,0,12,0,0,0,0,0,13,0,0,0,7,0,17,0,0,0,0,0,0,0,22,0,0,0
0,0,0,0,0,0,0,0,0,0,0,0,0,0,0,0,0,0,13,0,0,0,13,0,13,18,3,17,0,0,0,0,0,0,0,0,0,0,0,0,0,0,0,0,0,6,3,7,0,0,0,12,0,0,0,0,0,0,0,0,0,0,0,0,0,7,3,17,12,0,12,0,0,0,0,12,0,0,0
0,0,0,0,0,0,0,0,0,0,0,0,0,0,0,0,0,0,0,21,0,21,21,21,21,21,21,21,21,0,21,21,0,0,0,0,0,0,21,21,21,0,21,21,21,0,0,0,21,21,21,0,0,0,21,21,0,21,21,0,0,21,21,21,21,21,21,21,0,0,21,0,0,0,21,0,0,0,0
0,0,0,0,0,0,0,0,0,0,0,0,0,0,0,0,0,0,0,0,0,0,0,0,0,0,0,0,0,0,0,0,0,0,0,0,0,0,0,0,0,0,0,0,0,0,0,0,0,0,0,0,0,0,0,0,0,0,0,0,0,0,0,0,0,0,0,0,0,0,0,0,0,0,0,0,0,0,0
0,0,0,0,0,0,0,0,0,0,0,0,0,0,0,0,0,0,0,0,0,0,0,0,0,0,0,0,0,0,0,0,0,0,0,0,0,0,0,0,0,0,0,0,0,0,0,0,0,0,0,0,0,0,0,0,0,0,0,0,0,0,0,0,0,0,0,0,0,0,0,0,0,0,0,0,0,0,0
0,0,0,0,0,0,0,0,0,0,0,0,0,0,0,0,0,0,0,0,0,0,0,0,0,0,0,0,0,0,0,0,0,0,0,0,0,0,0,0,0,0,0,0,0,0,0,0,0,0,0,0,0,0,0,0,0,0,0,0,0,0,0,0,0,0,0,0,0,0,0,0,0,0,0,0,0,0,0
0,0,0,0,0,0,0,0,0,0,0,0,0,0,0,0,0,0,0,0,0,0,0,0,0,0,0,0,0,0,0,0,0,0,0,0,0,0,0,0,0,0,0,0,0,0,0,0,0,0,0,0,0,0,0,0,0,0,0,0,0,0,0,0,0,0,0,0,0,0,0,0,0,0,0,0,0,0,0
endlayer

layer
0,0,0,0,0,0,0,0,0,0,0,0,0,0,0,0,0,0,0,0,0,0,0,0,0,0,0,0,0,0,0,0,0,0,0,0,0,0,0,0,0,0,0,0,0,0,0,0,0,0,0,0,0,0,0,0,0,0,0,0,0,0,0,0,0,0,0,0,0,0,0,0,0,0,0,0,0,0,0
0,0,0,0,0,0,0,0,0,0,0,0,0,0,0,0,0,0,0,0,0,0,0,0,0,0,0,0,0,0,0,0,0,0,0,0,0,0,0,0,0,0,0,0,0,0,0,0,0,0,0,0,0,0,0,0,0,0,0,0,0,0,0,0,0,0,0,0,0,0,0,0,0,0,0,0,0,0,0
0,0,0,0,0,0,0,0,0,0,0,0,0,0,0,0,0,0,0,0,0,0,0,0,0,0,0,0,0,0,0,0,0,0,0,0,0,0,0,0,0,0,0,0,0,0,0,0,0,0,0,0,0,0,0,0,0,0,0,0,0,0,0,0,0,0,0,0,0,0,0,0,0,0,0,0,0,0,0
0,0,0,0,0,0,0,0,0,0,0,0,0,0,0,0,0,0,0,0,0,0,0,0,0,0,0,0,0,0,0,0,0,0,0,0,0,0,0,0,0,0,0,0,0,0,0,0,0,0,0,0,0,0,0,0,0,0,0,0,0,0,0,0,0,0,0,0,0,0,0,0,0,0,0,0,0,0,0
0,0,0,0,0,0,0,0,0,0,0,0,0,0,0,0,0,0,0,10,10,10,10,10,0,10,0,10,10,10,0,0,10,0,0,10,10,10,0,10,10,0,10,10,0,0,10,0,10,10,10,10,0,0,10,0,0,10,10,10,10,0,10,10,10,0,10,0,10,10,10,0,10,0,0,0,0,0,0
0,0,0,0,0,0,0,0,0,0,0,0,0,0,0,19,0,0,0,0,0,0,0,18,17,18,3,17,6,18,0,12,0,0,0,0,0,0,0,0,0,0,13,6,18,6,3,17,17,7,0,0,0,0,0,0,0,0,0,0,0,0,13,8,17,17,3,7,17,5,0,0,0,0,10,0,0,0,0
0,0,0,0,0,0,0,0,0,0,0,0,0,0,13,0,0,0,0,0,0,13,0,16,18,0,0,0,5,5,12,0,0,0,12,0,13,0,0,0,0,0,13,17,18,7,21,0,5,8,12,0,0,0,0,0,0,0,0,0,0,0,20,6,8,6,0,6,7,6,0,0,0,12,0,12,0,0,0
0,0,0,0,0,0,0,0,0,0,0,0,0,0,0,21,0,0,0,0,0,19,0,17,7,0,0,0,17,6,12,0,0,0,0,0,0,0,0,13,0,0,0,6,7,5,0,0,17,17,0,12,0,0,21,0,12,13,0,0,0,13,13,16,5,5,17,17,6,15,0,13,0,12,0,0,0,0,0
0,0,0,0,0,0,0,0,0,0,0,0,0,0,0,0,0,0,0,13,0,0,0,5,17,0,0,10,7,16,12,0,0,12,0,10,0,0,0,13,0,13,0,16,18,8,0,0,8,17,0,12,0,0,0,12,0,0,0,0,0,13,0,15,6,7,0,8,16,6,0,0,0,0,0,22,0,0,0
0,0,0,0,0,0,0,0,0,0,0,0,0,0,0,0,0,0,13,0,0,0,13,5,6,6,3,6,17,7,0,0,0,0,0,0,0,0,0,0,0,0,0,7,6,6,3,5,6,5,0,12,0,0,0,0,0,0,0,0,0,0,0,17,18,17,3,18,5,7,12,0,0,0,0,12,0,0,0
0,0,0,0,0,0,0,0,0,0,0,0,0,0,0,0,0,0,0,21,0,21,21,21,21,21,21,21,21,0,21,21,0,0,0,0,0,0,21,21,21,0,21,21,21,0,0,0,21,21,21,0,0,0,21,21,0,21,21,0,0,21,21,21,21,21,21,21,0,0,21,0,0,0,21,0,0,0,0
0,0,0,0,0,0,0,0,0,0,0,0,0,0,0,0,0,0,0,0,0,0,0,0,0,0,0,0,0,0,0,0,0,0,0,0,0,0,0,0,0,0,0,0,0,0,0,0,0,0,0,0,0,0,0,0,0,0,0,0,0,0,0,0,0,0,0,0,0,0,0,0,0,0,0,0,0,0,0
0,0,0,0,0,0,0,0,0,0,0,0,0,0,0,0,0,0,0,0,0,0,0,0,0,0,0,0,0,0,0,0,0,0,0,0,0,0,0,0,0,0,0,0,0,0,0,0,0,0,0,0,0,0,0,0,0,0,0,0,0,0,0,0,0,0,0,0,0,0,0,0,0,0,0,0,0,0,0
0,0,0,0,0,0,0,0,0,0,0,0,0,0,0,0,0,0,0,0,0,0,0,0,0,0,0,0,0,0,0,0,0,0,0,0,0,0,0,0,0,0,0,0,0,0,0,0,0,0,0,0,0,0,0,0,0,0,0,0,0,0,0,0,0,0,0,0,0,0,0,0,0,0,0,0,0,0,0
0,0,0,0,0,0,0,0,0,0,0,0,0,0,0,0,0,0,0,0,0,0,0,0,0,0,0,0,0,0,0,0,0,0,0,0,0,0,0,0,0,0,0,0,0,0,0,0,0,0,0,0,0,0,0,0,0,0,0,0,0,0,0,0,0,0,0,0,0,0,0,0,0,0,0,0,0,0,0
endlayer

layer
0,0,0,0,0,0,0,0,0,0,0,0,0,0,0,0,0,0,0,0,0,0,0,0,0,0,0,0,0,0,0,0,0,0,0,0,0,0,0,0,0,0,0,0,0,0,0,0,0,0,0,0,0,0,0,0,0,0,0,0,0,0,0,0,0,0,0,0,0,0,0,0,0,0,0,0,0,0,0
0,0,0,0,0,0,0,0,0,0,0,0,0,0,0,0,0,0,0,0,0,0,0,0,0,0,0,0,0,0,0,0,0,0,0,0,0,0,0,0,0,0,0,0,0,0,0,0,0,0,0,0,0,0,0,0,0,0,0,0,0,0,0,0,0,0,0,0,0,0,0,0,0,0,0,0,0,0,0
0,0,0,0,0,0,0,0,0,0,0,0,0,0,0,0,0,0,0,0,0,0,0,0,0,0,0,0,0,0,0,0,0,0,0,0,0,0,0,0,0,0,0,0,0,0,0,0,0,0,0,0,0,0,0,0,0,0,0,0,0,0,0,0,0,0,0,0,0,0,0,0,0,0,0,0,0,0,0
0,0,0,0,0,0,0,0,0,0,0,0,0,0,0,0,0,0,0,0,0,0,0,0,0,0,0,0,0,0,0,0,0,0,0,0,0,0,0,0,0,0,0,0,0,0,0,0,0,0,0,0,0,0,0,0,0,0,0,0,0,0,0,0,0,0,0,0,0,0,0,0,0,0,0,0,0,0,0
0,0,0,0,0,0,0,0,0,0,0,0,0,0,0,0,0,0,0,10,10,10,10,10,0,10,0,10,10,10,0,0,10,0,0,10,10,10,0,10,10,0,10,10,0,0,10,0,10,10,10,10,0,0,10,0,0,10,10,10,10,0,10,10,10,0,10,0,10,10,10,0,10,0,0,0,0,0,0
0,0,0,0,0,0,0,0,0,0,0,0,0,0,0,19,0,0,0,0,0,0,0,17,18,3,3,3,7,5,0,12,0,0,0,0,0,0,0,0,0,0,0,5,6,3,3,3,5,18,0,0,0,0,0,0,0,0,0,0,0,0,0,18,7,3,3,3,7,16,0,0,0,0,10,0,0,0,0
0,0,0,0,0,0,0,0,0,0,0,0,0,0,13,0,0,0,0,0,0,13,0,17,0,0,0,0,21,17,12,0,0,0,12,0,13,0,0,0,0,0,0,15,21,21,21,0,0,0,0,0,0,0,0,0,0,0,0,0,0,0,21,7,0,0,0,0,21,8,0,0,0,12,0,12,0,0,0
0,0,0,0,0,0,0,0,0,0,0,0,0,0,0,21,0,0,0,0,0,19,0,15,0,0,0,0,0,6,12,0,0,0,0,0,0,0,0,13,0,0,0,17,0,0,0,0,0,16,0,12,0,0,21,0,12,13,0,0,0,13,0,5,0,0,0,0,0,6,0,13,0,12,0,0,0,0,0
0,0,0,0,0,0,0,0,0,0,0,0,0,0,0,0,0,0,0,13,0,0,0,18,10,0,0,10,0,18,0,0,0,12,0,10,0,0,0,13,0,13,0,17,0,0,0,0,0,6,0,12,0,0,0,12,0,0,0,0,0,13,0,8,0,0,0,10,0,5,0,0,0,0,0,22,0,0,0
0,0,0,0,0,0,0,0,0,0,0,0,0,0,0,0,0,0,13,0,0,0,13,17,16,3,3,3,17,5,0,0,0,0,0,0,0,0,0,0,0,0,0,6,5,3,3,3,17,8,0,12,0,0,0,0,0,0,0,0,0,0,0,7,7,0,3,3,8,8,0,0,0,0,0,12,0,0,0
0,0,0,0,0,0,0,0,0,0,0,0,0,0,0,0,0,0,0,21,0,21,21,21,21,21,21,21,21,0,21,21,0,0,0,0,0,0,21,21,21,0,21,21,21,0,0,0,21,21,21,0,0,0,21,21,0,21,21,0,0,21,21,21,21,21,21,21,0,0,21,0,0,0,21,0,0,0,0
0,0,0,0,0,0,0,0,0,0,0,0,0,0,0,0,0,0,0,0,0,0,0,0,0,0,0,0,0,0,0,0,0,0,0,0,0,0,0,0,0,0,0,0,0,0,0,0,0,0,0,0,0,0,0,0,0,0,0,0,0,0,0,0,0,0,0,0,0,0,0,0,0,0,0,0,0,0,0
0,0,0,0,0,0,0,0,0,0,0,0,0,0,0,0,0,0,0,0,0,0,0,0,0,0,0,0,0,0,0,0,0,0,0,0,0,0,0,0,0,0,0,0,0,0,0,0,0,0,0,0,0,0,0,0,0,0,0,0,0,0,0,0,0,0,0,0,0,0,0,0,0,0,0,0,0,0,0
0,0,0,0,0,0,0,0,0,0,0,0,0,0,0,0,0,0,0,0,0,0,0,0,0,0,0,0,0,0,0,0,0,0,0,0,0,0,0,0,0,0,0,0,0,0,0,0,0,0,0,0,0,0,0,0,0,0,0,0,0,0,0,0,0,0,0,0,0,0,0,0,0,0,0,0,0,0,0
0,0,0,0,0,0,0,0,0,0,0,0,0,0,0,0,0,0,0,0,0,0,0,0,0,0,0,0,0,0,0,0,0,0,0,0,0,0,0,0,0,0,0,0,0,0,0,0,0,0,0,0,0,0,0,0,0,0,0,0,0,0,0,0,0,0,0,0,0,0,0,0,0,0,0,0,0,0,0
endlayer

layer
0,0,0,0,0,0,0,0,0,0,0,0,0,0,0,0,0,0,0,0,0,0,0,0,0,0,0,0,0,0,0,0,0,0,0,0,0,0,0,0,0,0,0,0,0,0,0,0,0,0,0,0,0,0,0,0,0,0,0,0,0,0,0,0,0,0,0,0,0,0,0,0,0,0,0,0,0,0,0
0,0,0,0,0,0,0,0,0,0,0,0,0,0,0,0,0,0,0,0,0,0,0,0,0,0,0,0,0,0,0,0,0,0,0,0,0,0,0,0,0,0,0,0,0,0,0,0,0,0,0,0,0,0,0,0,0,0,0,0,0,0,0,0,0,0,0,0,0,0,0,0,0,0,0,0,0,0,0
0,0,0,0,0,0,0,0,0,0,0,0,0,0,0,0,0,0,0,0,0,0,0,0,0,0,0,0,0,0,0,0,0,0,0,0,0,0,0,0,0,0,0,0,0,0,0,0,0,0,0,0,0,0,0,0,0,0,0,0,0,0,0,0,0,0,0,0,0,0,0,0,0,0,0,0,0,0,0
0,0,0,0,0,0,0,0,0,0,0,0,0,0,0,0,0,0,0,0,0,0,0,0,0,0,0,0,0,0,0,0,0,0,0,0,0,0,0,0,0,0,0,0,0,0,0,0,0,0,0,0,0,0,0,0,0,0,0,0,0,0,0,0,0,0,0,0,0,0,0,0,0,0,0,0,0,0,0
0,0,0,0,0,0,0,0,0,0,0,0,0,0,0,0,0,0,0,10,10,10,10,10,0,10,0,10,10,10,0,0,10,0,0,10,10,10,0,10,10,0,10,10,0,0,10,0,10,10,10,10,0,0,10,0,0,10,10,10,10,0,10,10,10,0,10,0,10,10,10,0,10,0,0,0,0,0,0
0,0,0,0,0,0,0,0,0,0,0,0,0,0,0,19,0,0,0,0,0,0,7,6,3,3,3,3,3,18,6,12,0,0,0,0,0,0,0,0,0,0,5,7,3,3,3,3,3,18,6,0,0,0,0,0,0,0,0,0,0,0,5,16,3,3,0,3,3,17,7,0,0,0,10,0,0,0,0
0,0,0,0,0,0,0,0,0,0,0,0,0,0,13,0,0,0,0,0,0,13,18,0,0,0,0,0,21,0,0,0,0,0,12,0,13,0,0,0,0,0,7,0,21,21,21,0,0,0,5,0,0,0,0,0,0,0,0,0,0,0,21,21,0,0,0,0,21,0,6,0,0,12,0,12,0,0,0
0,0,0,0,0,0,0,0,0,0,0,0,0,0,0,21,0,0,0,0,0,19,6,3,0,0,0,0,0,0,7,0,0,0,0,0,0,0,0,13,0,0,6,0,0,0,0,0,0,0,17,12,0,0,21,0,12,13,0,0,0,13,8,0,0,0,0,0,0,0,8,13,0,12,0,0,0,0,0
0,0,0,0,0,0,0,0,0,0,0,0,0,0,0,0,0,0,0,13,0,0,16,0,10,0,0,10,0,0,17,0,0,12,0,10,0,0,0,13,0,13,6,10,0,0,0,0,0,0,8,12,0,0,0,12,0,0,0,0,0,13,6,0,0,0,0,10,0,0,17,0,0,0,0,22,0,0,0
0,0,0,0,0,0,0,0,0,0,0,0,0,0,0,0,0,0,13,0,0,0,6,5,3,3,3,0,3,7,5,0,0,0,0,0,0,0,0,0,0,0,7,16,3,3,0,3,3,6,16,12,0,0,0,0,0,0,0,0,0,0,7,17,3,3,3,3,3,17,18,0,0,0,0,12,0,0,0
0,0,0,0,0,0,0,0,0,0,0,0,0,0,0,0,0,0,0,21,0,21,21,21,21,21,21,21,21,0,21,21,0,0,0,0,0,0,21,21,21,0,21,21,21,0,0,0,21,21,21,0,0,0,21,21,0,21,21,0,0,21,21,21,21,21,21,21,0,0,21,0,0,0,21,0,0,0,0
0,0,0,0,0,0,0,0,0,0,0,0,0,0,0,0,0,0,0,0,0,0,0,0,0,0,0,0,0,0,0,0,0,0,0,0,0,0,0,0,0,0,0,0,0,0,0,0,0,0,0,0,0,0,0,0,0,0,0,0,0,0,0,0,0,0,0,0,0,0,0,0,0,0,0,0,0,0,0
0,0,0,0,0,0,0,0,0,0,0,0,0,0,0,0,0,0,0,0,0,0,0,0,0,0,0,0,0,0,0,0,0,0,0,0,0,0,0,0,0,0,0,0,0,0,0,0,0,0,0,0,0,0,0,0,0,0,0,0,0,0,0,0,0,0,0,0,0,0,0,0,0,0,0,0,0,0,0
0,0,0,0,0,0,0,0,0,0,0,0,0,0,0,0,0,0,0,0,0,0,0,0,0,0,0,0,0,0,0,0,0,0,0,0,0,0,0,0,0,0,0,0,0,0,0,0,0,0,0,0,0,0,0,0,0,0,0,0,0,0,0,0,0,0,0,0,0,0,0,0,0,0,0,0,0,0,0
0,0,0,0,0,0,0,0,0,0,0,0,0,0,0,0,0,0,0,0,0,0,0,0,0,0,0,0,0,0,0,0,0,0,0,0,0,0,0,0,0,0,0,0,0,0,0,0,0,0,0,0,0,0,0,0,0,0,0,0,0,0,0,0,0,0,0,0,0,0,0,0,0,0,0,0,0,0,0
endlayer

layer
0,0,0,0,0,0,0,0,0,0,0,0,0,0,0,0,0,0,0,0,0,0,0,0,0,0,0,0,0,0,0,0,0,0,0,0,0,0,0,0,0,0,0,0,0,0,0,0,0,0,0,0,0,0,0,0,0,0,0,0,0,0,0,0,0,0,0,0,0,0,0,0,0,0,0,0,0,0,0
0,0,0,0,0,0,0,0,0,0,0,0,0,0,0,0,0,0,0,0,0,0,0,0,0,0,0,0,0,0,0,0,0,0,0,0,0,0,0,0,0,0,0,0,0,0,0,0,0,0,0,0,0,0,0,0,0,0,0,0,0,0,0,0,0,0,0,0,0,0,0,0,0,0,0,0,0,0,0
0,0,0,0,0,0,0,0,0,0,0,0,0,0,0,0,0,0,0,0,0,0,0,0,0,0,0,0,0,0,0,0,0,0,0,0,0,0,0,0,0,0,0,0,0,0,0,0,0,0,0,0,0,0,0,0,0,0,0,0,0,0,0,0,0,0,0,0,0,0,0,0,0,0,0,0,0,0,0
0,0,0,0,0,0,0,0,0,0,0,0,0,0,0,0,0,0,0,0,0,0,0,0,0,0,0,0,0,0,0,0,0,0,0,0,0,0,0,0,0,0,0,0,0,0,0,0,0,0,0,0,0,0,0,0,0,0,0,0,0,0,0,0,0,0,0,0,0,0,0,0,0,0,0,0,0,0,0
0,0,0,0,0,0,0,0,0,0,0,0,0,0,0,0,0,0,0,10,10,10,10,0,0,10,0,10,10,10,0,0,10,0,0,10,10,10,0,10,10,0,10,10,0,0,10,0,10,10,10,10,0,0,10,0,0,10,10,10,10,0,10,10,10,0,10,0,10,10,10,0,10,0,0,0,0,0,0
0,0,0,0,0,0,0,0,0,0,0,0,0,0,0,19,0,0,0,0,18,6,5,3,3,15,3,3,3,3,17,5,17,0,0,0,0,0,0,0,7,17,6,3,3,3,0,0,15,3,17,7,5,0,0,0,0,0,0,0,16,17,7,3,3,0,0,3,3,3,6,16,5,0,10,0,0,0,0
0,0,0,0,0,0,0,0,0,0,0,0,0,0,13,0,0,0,0,0,16,18,0,0,0,0,0,0,21,0,15,17,16,0,12,0,13,0,0,0,17,17,0,0,21,21,21,0,0,0,0,17,16,0,0,0,0,0,0,0,8,8,21,21,0,0,0,0,21,0,0,7,7,12,0,12,0,0,0
0,0,0,0,0,0,0,0,0,0,0,0,0,0,0,21,0,0,0,0,17,10,0,0,0,0,0,0,0,0,0,5,17,0,0,0,0,0,0,13,6,8,0,0,0,0,0,0,0,0,0,15,6,0,21,0,12,13,0,0,6,6,0,0,0,0,0,0,0,0,0,13,6,12,0,0,0,0,0
0,0,0,0,0,0,0,0,0,0,0,0,0,0,0,0,0,0,0,13,7,18,3,0,10,0,0,10,0,0,10,17,7,12,0,10,0,0,0,13,6,17,0,10,0,0,0,0,15,0,10,17,8,0,0,12,0,0,0,0,5,6,27,0,0,0,0,10,0,0,0,5,8,0,0,22,0,0,0
0,0,0,0,0,0,0,0,0,0,0,0,0,0,0,0,0,0,13,0,17,6,18,3,3,15,3,3,3,3,18,6,17,0,0,0,0,0,0,0,8,8,6,3,3,3,3,0,3,3,7,5,6,0,0,0,0,0,0,0,8,17,5,3,3,3,3,0,3,3,17,18,7,0,0,12,0,0,0
0,0,0,0,0,0,0,0,0,0,0,0,0,0,0,0,0,0,0,21,0,21,21,0,21,21,21,21,21,0,21,21,0,0,0,0,0,0,21,21,21,0,21,21,21,0,0,0,21,21,21,0,0,0,21,21,0,21,21,0,0,21,21,21,21,21,21,21,0,0,21,0,0,0,21,0,0,0,0
0,0,0,0,0,0,0,0,0,0,0,0,0,0,0,0,0,0,0,0,0,0,0,0,0,0,0,0,0,0,0,0,0,0,0,0,0,0,0,0,0,0,0,0,0,0,0,0,0,0,0,0,0,0,0,0,0,0,0,0,0,0,0,0,0,0,0,0,0,0,0,0,0,0,0,0,0,0,0
0,0,0,0,0,0,0,0,0,0,0,0,0,0,0,0,0,0,0,0,0,0,0,0,0,0,0,0,0,0,0,0,0,0,0,0,0,0,0,0,0,0,0,0,0,0,0,0,0,0,0,0,0,0,0,0,0,0,0,0,0,0,0,0,0,0,0,0,0,0,0,0,0,0,0,0,0,0,0
0,0,0,0,0,0,0,0,0,0,0,0,0,0,0,0,0,0,0,0,0,0,0,0,0,0,0,0,0,0,0,0,0,0,0,0,0,0,0,0,0,0,0,0,0,0,0,0,0,0,0,0,0,0,0,0,0,0,0,0,0,0,0,0,0,0,0,0,0,0,0,0,0,0,0,0,0,0,0
0,0,0,0,0,0,0,0,0,0,0,0,0,0,0,0,0,0,0,0,0,0,0,0,0,0,0,0,0,0,0,0,0,0,0,0,0,0,0,0,0,0,0,0,0,0,0,0,0,0,0,0,0,0,0,0,0,0,0,0,0,0,0,0,0,0,0,0,0,0,0,0,0,0,0,0,0,0,0
endlayer

layer
0,0,0,0,0,0,0,0,0,0,0,0,0,0,0,0,0,0,0,0,0,0,0,0,0,0,0,0,0,0,0,0,0,0,0,0,0,0,0,0,0,0,0,0,0,0,0,0,0,0,0,0,0,0,0,0,0,0,0,0,0,0,0,0,0,0,0,0,0,0,0,0,0,0,0,0,0,0,0
0,0,0,0,0,0,0,0,0,0,0,0,0,0,0,0,0,0,0,0,0,0,0,0,0,0,0,0,0,0,0,0,0,0,0,0,0,0,0,0,0,0,0,0,0,0,0,0,0,0,0,0,0,0,0,0,0,0,0,0,0,0,0,0,0,0,0,0,0,0,0,0,0,0,0,0,0,0,0
0,0,0,0,0,0,0,0,0,0,0,0,0,0,0,0,0,0,0,0,0,0,0,0,0,0,0,0,0,0,0,0,0,0,0,0,0,0,0,0,0,0,0,0,0,0,0,0,0,0,0,0,0,0,0,0,0,0,0,0,0,0,0,0,0,0,0,0,0,0,0,0,0,0,0,0,0,0,0
0,0,0,0,0,0,0,0,0,0,0,0,0,0,0,0,0,0,0,0,0,0,0,0,0,0,0,0,0,0,0,0,0,0,0,0,0,0,0,0,0,0,0,0,0,0,0,0,0,0,0,0,0,0,0,0,0,0,0,0,0,0,0,0,0,0,0,0,0,0,0,0,0,0,0,0,0,0,0
0,0,0,0,0,0,0,0,0,0,0,0,0,0,0,0,0,0,0,10,10,10,10,0,0,10,0,10,10,10,0,0,0,0,0,10,10,10,0,10,0,0,10,10,0,0,10,0,10,10,10,10,0,0,10,0,0,10,10,10,10,0,10,10,10,0,10,0,10,10,10,0,10,0,0,0,0,0,0
0,0,0,0,0,0,0,0,0,0,0,0,0,0,0,19,0,0,0,0,17,3,3,3,3,3,0,0,3,3,3,3,16,6,17,6,17,5,17,18,5,3,3,3,3,0,0,0,13,3,3,3,17,5,18,15,16,5,0,7,17,3,3,15,3,0,3,0,3,0,3,3,17,0,10,0,0,0,0
0,0,0,0,0,0,0,0,0,0,0,0,0,0,13,0,0,0,0,0,3,0,0,0,0,0,0,0,21,0,0,0,0,7,12,8,13,6,17,17,21,0,0,0,21,21,21,0,0,0,0,21,0,5,6,17,6,17,6,17,0,0,21,21,0,0,0,0,21,0,0,21,3,8,8,12,0,0,0
0,0,0,0,0,0,0,0,0,0,0,0,0,0,0,21,0,0,0,0,0,0,0,0,0,0,0,0,0,0,0,0,0,6,7,17,16,7,17,8,0,0,0,0,0,0,0,0,0,0,0,0,0,8,21,17,12,13,6,6,0,0,0,0,0,0,0,0,0,0,0,0,0,17,0,0,0,0,0
0,0,0,0,0,0,0,0,0,0,0,0,0,0,0,0,0,0,0,0,0,0,10,0,10,0,0,10,0,0,10,10,0,6,17,10,17,5,15,17,0,0,0,10,0,0,0,0,0,0,10,0,0,17,17,12,6,8,8,6,0,0,0,0,0,0,0,10,0,0,0,0,10,6,15,22,0,0,0
0,0,0,0,0,0,0,0,0,0,0,0,0,0,0,0,0,0,13,0,7,3,3,3,0,3,3,3,12,3,3,3,17,16,17,5,7,17,5,6,5,3,3,3,3,0,3,3,3,3,3,3,6,7,5,5,7,17,16,8,17,3,3,3,3,0,3,3,3,15,3,3,5,6,7,12,0,0,0
0,0,0,0,0,0,0,0,0,0,0,0,0,0,0,0,0,0,0,21,0,21,21,0,21,21,21,21,21,0,21,21,0,0,0,0,0,0,21,21,21,0,21,21,21,0,0,0,21,0,21,0,0,0,21,21,0,21,21,0,0,21,21,21,21,21,21,21,0,0,21,0,0,0,21,0,0,0,0
0,0,0,0,0,0,0,0,0,0,0,0,0,0,0,0,0,0,0,0,0,0,0,0,0,0,0,0,0,0,0,0,0,0,0,0,0,0,0,0,0,0,0,0,0,0,0,0,0,0,0,0,0,0,0,0,0,0,0,0,0,0,0,0,0,0,0,0,0,0,0,0,0,0,0,0,0,0,0
0,0,0,0,0,0,0,0,0,0,0,0,0,0,0,0,0,0,0,0,0,0,0,0,0,0,0,0,0,0,0,0,0,0,0,0,0,0,0,0,0,0,0,0,0,0,0,0,0,0,0,0,0,0,0,0,0,0,0,0,0,0,0,0,0,0,0,0,0,0,0,0,0,0,0,0,0,0,0
0,0,0,0,0,0,0,0,0,0,0,0,0,0,0,0,0,0,0,0,0,0,0,0,0,0,0,0,0,0,0,0,0,0,0,0,0,0,0,0,0,0,0,0,0,0,0,0,0,0,0,0,0,0,0,0,0,0,0,0,0,0,0,0,0,0,0,0,0,0,0,0,0,0,0,0,0,0,0
0,0,0,0,0,0,0,0,0,0,0,0,0,0,0,0,0,0,0,0,0,0,0,0,0,0,0,0,0,0,0,0,0,0,0,0,0,0,0,0,0,0,0,0,0,0,0,0,0,0,0,0,0,0,0,0,0,0,0,0,0,0,0,0,0,0,0,0,0,0,0,0,0,0,0,0,0,0,0
endlayer

layer
0,0,0,0,0,0,0,0,0,0,0,0,0,0,0,0,0,0,0,0,0,0,0,0,0,0,0,0,0,0,0,0,0,0,0,0,0,0,0,0,0,0,0,0,0,0,0,0,0,0,0,0,0,0,0,0,0,0,0,0,0,0,0,0,0,0,0,0,0,0,0,0,0,0,0,0,0,0,0
0,0,0,0,0,0,0,0,0,0,0,0,0,0,0,0,0,0,0,0,0,0,0,0,0,0,0,0,0,0,0,0,0,0,0,0,0,0,0,0,0,0,0,0,0,0,0,0,0,0,0,0,0,0,0,0,0,0,0,0,0,0,0,0,0,0,0,0,0,0,0,0,0,0,0,0,0,0,0
0,0,0,0,0,0,0,0,0,0,0,0,0,0,0,0,0,0,0,0,0,0,0,0,0,0,0,0,0,0,0,0,0,0,0,0,0,0,0,0,0,0,0,0,0,0,0,0,0,0,0,0,0,0,0,0,0,0,0,0,0,0,0,0,0,0,0,0,0,0,0,0,0,0,0,0,0,0,0
0,0,0,0,0,0,0,0,0,0,0,0,0,0,0,0,0,0,0,0,0,0,0,0,0,0,0,0,0,0,0,0,0,0,0,0,0,0,0,0,0,0,0,0,0,0,0,0,0,0,0,0,0,0,0,0,0,0,0,0,0,0,0,0,0,0,0,0,0,0,0,0,0,0,0,0,0,0,0
0,0,0,0,0,0,0,0,0,0,0,0,0,0,0,0,0,0,0,10,10,10,10,0,0,10,0,10,10,10,0,0,0,0,0,10,10,10,0,10,0,0,10,10,0,0,10,0,10,10,10,10,0,0,10,0,0,10,10,10,10,0,10,10,10,0,10,0,10,10,10,0,10,0,0,0,0,0,0
0,0,0,0,0,0,0,0,0,0,0,0,0,0,0,19,0,0,0,3,3,3,3,3,13,3,3,3,3,3,3,3,3,3,5,7,5,17,5,3,3,3,3,3,3,0,3,0,0,0,3,3,3,3,18,17,5,18,7,3,3,3,3,0,3,3,0,3,0,3,3,3,3,3,10,0,0,0,0
0,0,0,0,0,0,0,0,0,0,0,0,0,0,13,0,0,0,0,0,0,0,0,0,0,0,0,0,21,0,0,0,0,0,0,21,0,0,0,0,21,0,0,0,21,21,21,0,15,0,0,21,0,0,0,21,0,0,0,21,0,0,21,21,0,0,0,0,21,0,0,21,0,10,6,12,0,0,0
0,0,0,0,0,0,0,0,0,0,0,0,0,0,0,21,0,0,0,0,0,0,0,0,0,0,0,0,0,0,0,0,0,0,0,0,0,0,0,0,0,0,0,0,0,0,0,0,0,0,0,0,0,0,0,0,0,0,0,0,0,0,0,0,0,0,0,0,0,0,0,0,0,3,0,0,0,0,0
0,0,0,0,0,0,0,0,0,0,0,0,0,0,0,0,0,0,0,0,0,0,10,0,10,0,0,0,0,0,10,10,0,0,0,15,0,10,0,10,0,0,0,10,0,0,15,0,0,0,10,0,0,0,0,0,10,10,0,0,0,0,0,0,0,0,0,10,0,0,0,0,10,0,7,22,0,0,0
0,0,0,0,0,0,0,0,0,0,0,0,0,0,0,0,0,0,13,3,3,3,3,3,3,3,0,0,0,3,3,3,3,3,5,7,17,17,8,3,3,3,3,3,0,0,3,3,3,3,3,3,3,3,8,16,6,6,7,3,3,3,0,3,3,3,0,3,3,3,3,3,15,3,0,12,0,0,0
0,0,0,0,0,0,0,0,0,0,0,0,0,0,0,0,0,0,0,21,0,21,21,0,21,21,21,21,21,0,21,21,0,0,0,0,0,0,21,21,21,0,21,21,21,0,0,0,21,0,21,0,0,0,21,21,0,21,21,0,0,21,21,21,21,21,21,21,0,0,21,0,0,0,0,0,0,0,0
0,0,0,0,0,0,0,0,0,0,0,0,0,0,0,0,0,0,0,0,0,0,0,0,0,0,0,0,0,0,0,0,0,0,0,0,0,0,0,0,0,0,0,0,0,0,0,0,0,0,0,0,0,0,0,0,0,0,0,0,0,0,0,0,0,0,0,0,0,0,0,0,0,0,0,0,0,0,0
0,0,0,0,0,0,0,0,0,0,0,0,0,0,0,0,0,0,0,0,0,0,0,0,0,0,0,0,0,0,0,0,0,0,0,0,0,0,0,0,0,0,0,0,0,0,0,0,0,0,0,0,0,0,0,0,0,0,0,0,0,0,0,0,0,0,0,0,0,0,0,0,0,0,0,0,0,0,0
0,0,0,0,0,0,0,0,0,0,0,0,0,0,0,0,0,0,0,0,0,0,0,0,0,0,0,0,0,0,0,0,0,0,0,0,0,0,0,0,0,0,0,0,0,0,0,0,0,0,0,0,0,0,0,0,0,0,0,0,0,0,0,0,0,0,0,0,0,0,0,0,0,0,0,0,0,0,0
0,0,0,0,0,0,0,0,0,0,0,0,0,0,0,0,0,0,0,0,0,0,0,0,0,0,0,0,0,0,0,0,0,0,0,0,0,0,0,0,0,0,0,0,0,0,0,0,0,0,0,0,0,0,0,0,0,0,0,0,0,0,0,0,0,0,0,0,0,0,0,0,0,0,0,0,0,0,0
endlayer

layer
0,0,0,0,0,0,0,0,0,0,0,0,0,0,0,0,0,0,0,0,0,0,0,0,0,0,0,0,0,0,0,0,0,0,0,0,0,0,0,0,0,0,0,0,0,0,0,0,0,0,0,0,0,0,0,0,0,0,0,0,0,0,0,0,0,0,0,0,0,0,0,0,0,0,0,0,0,0,0
0,0,0,0,0,0,0,0,0,0,0,0,0,0,0,0,0,0,0,0,0,0,0,0,0,0,0,0,0,0,0,0,0,0,0,0,0,0,0,0,0,0,0,0,0,0,0,0,0,0,0,0,0,0,0,0,0,0,0,0,0,0,0,0,0,0,0,0,0,0,0,0,0,0,0,0,0,0,0
0,0,0,0,0,0,0,0,0,0,0,0,0,0,0,0,0,0,0,0,0,0,0,0,0,0,0,0,0,0,0,0,0,0,0,0,0,0,0,0,0,0,0,0,0,0,0,0,0,0,0,0,0,0,0,0,0,0,0,0,0,0,0,0,0,0,0,0,0,0,0,0,0,0,0,0,0,0,0
0,0,0,0,0,0,0,0,0,0,0,0,0,0,0,0,0,0,0,0,0,0,0,0,0,0,0,0,0,0,0,0,0,0,0,0,0,0,0,0,0,0,0,0,0,0,0,0,0,0,0,0,0,0,0,0,0,0,0,0,0,0,0,0,0,0,0,0,0,0,0,0,0,0,0,0,0,0,0
0,0,0,0,0,0,0,0,0,0,0,0,0,0,0,0,0,0,0,10,10,10,10,0,0,0,0,0,10,10,0,0,0,0,0,10,10,10,0,10,0,0,10,10,0,0,10,0,10,10,10,10,0,0,10,0,0,10,0,10,10,0,10,10,10,0,10,0,10,10,10,0,0,0,0,0,0,0,0
0,0,0,0,0,0,0,0,0,0,0,0,0,0,0,19,3,3,3,3,3,3,3,3,3,3,3,3,3,3,3,3,3,3,3,3,3,3,24,3,3,3,3,3,3,3,3,3,3,3,3,3,3,3,3,3,3,3,3,3,3,3,3,3,3,3,3,3,3,3,3,3,0,3,3,0,0,0,0
0,0,0,0,0,0,0,0,0,0,0,0,0,0,13,0,0,0,0,0,0,0,0,0,0,0,0,0,21,0,0,0,0,0,0,21,0,0,0,0,21,0,0,0,21,21,21,0,0,0,0,21,0,0,0,21,0,0,0,21,0,0,21,21,0,0,0,0,21,0,0,21,0,10,6,0,0,0,0
0,0,0,0,0,0,0,0,0,0,0,0,0,0,0,21,0,0,0,0,0,0,0,0,0,0,0,0,0,0,0,0,0,0,0,0,0,0,0,0,0,0,0,0,0,0,0,0,0,0,0,0,0,0,0,0,0,0,0,0,0,0,0,0,0,0,0,0,0,0,0,0,0,0,8,0,0,0,0
0,0,0,0,0,0,0,0,0,0,0,0,0,0,0,0,0,0,0,0,0,0,10,0,10,0,0,0,0,0,10,10,0,0,0,0,0,10,0,10,0,0,0,0,0,0,0,0,0,0,10,0,0,0,0,0,10,10,0,0,0,0,0,0,0,0,0,10,0,0,0,0,10,0,21,22,0,0,0
0,0,0,0,0,0,0,0,0,0,0,0,0,0,0,0,0,0,0,0,3,3,3,3,3,3,3,3,3,3,3,3,3,3,3,3,3,3,3,3,3,3,3,3,3,3,3,3,3,3,3,3,3,3,3,3,3,3,3,3,3,0,3,3,3,3,3,3,3,3,3,0,3,0,0,12,0,0,0
0,0,0,0,0,0,0,0,0,0,0,0,0,0,0,0,0,0,0,0,0,21,21,0,21,21,21,21,21,0,21,21,0,0,0,0,0,0,21,21,21,0,21,21,21,0,0,0,21,0,21,0,0,0,21,21,0,21,21,0,0,21,21,21,21,21,21,21,0,0,21,0,0,0,0,0,0,0,0
0,0,0,0,0,0,0,0,0,0,0,0,0,0,0,0,0,0,0,0,0,0,0,0,0,0,0,0,0,0,0,0,0,0,0,0,0,0,0,0,0,0,0,0,0,0,0,0,0,0,0,0,0,0,0,0,0,0,0,0,0,0,0,0,0,0,0,0,0,0,0,0,0,0,0,0,0,0,0
0,0,0,0,0,0,0,0,0,0,0,0,0,0,0,0,0,0,0,0,0,0,0,0,0,0,0,0,0,0,0,0,0,0,0,0,0,0,0,0,0,0,0,0,0,0,0,0,0,0,0,0,0,0,0,0,0,0,0,0,0,0,0,0,0,0,0,0,0,0,0,0,0,0,0,0,0,0,0
0,0,0,0,0,0,0,0,0,0,0,0,0,0,0,0,0,0,0,0,0,0,0,0,0,0,0,0,0,0,0,0,0,0,0,0,0,0,0,0,0,0,0,0,0,0,0,0,0,0,0,0,0,0,0,0,0,0,0,0,0,0,0,0,0,0,0,0,0,0,0,0,0,0,0,0,0,0,0
0,0,0,0,0,0,0,0,0,0,0,0,0,0,0,0,0,0,0,0,0,0,0,0,0,0,0,0,0,0,0,0,0,0,0,0,0,0,0,0,0,0,0,0,0,0,0,0,0,0,0,0,0,0,0,0,0,0,0,0,0,0,0,0,0,0,0,0,0,0,0,0,0,0,0,0,0,0,0
endlayer

layer
0,0,0,0,0,0,0,0,0,0,0,0,0,0,0,0,0,0,0,0,0,0,0,0,0,0,0,0,0,0,0,0,0,0,0,0,0,0,0,0,0,0,0,0,0,0,0,0,0,0,0,0,0,0,0,0,0,0,0,0,0,0,0,0,0,0,0,0,0,0,0,0,0,0,0,0,0,0,0
0,0,0,0,0,0,0,0,0,0,0,0,0,0,0,0,0,0,0,0,0,0,0,0,0,0,0,0,0,0,0,0,0,0,0,0,0,0,0,0,0,0,0,0,0,0,0,0,0,0,0,0,0,0,0,0,0,0,0,0,0,0,0,0,0,0,0,0,0,0,0,0,0,0,0,0,0,0,0
0,0,0,0,0,0,0,0,0,0,0,0,0,0,0,0,0,0,0,0,0,0,0,0,0,0,0,0,0,0,0,0,0,0,0,0,0,0,0,0,0,0,0,0,0,0,0,0,0,0,0,0,0,0,0,0,0,0,0,0,0,0,0,0,0,0,0,0,0,0,0,0,0,0,0,0,0,0,0
0,0,0,0,0,0,0,0,0,0,0,0,0,0,0,0,0,0,0,0,0,0,0,0,0,0,0,0,0,0,0,0,0,0,0,0,0,0,0,0,0,0,0,0,0,0,0,0,0,0,0,0,0,0,0,0,0,0,0,0,0,0,0,0,0,0,0,0,0,0,0,0,0,0,0,0,0,0,0
0,0,0,0,0,0,0,0,0,0,0,0,0,0,0,0,0,0,0,0,10,10,10,0,0,0,0,0,10,10,0,0,0,0,0,10,10,10,0,0,0,0,10,0,0,0,0,0,0,0,0,0,0,0,10,0,0,10,0,0,0,0,0,0,10,0,10,0,0,10,10,0,0,0,0,0,0,0,0
0,0,0,0,0,0,0,0,0,0,0,0,0,0,0,10,0,0,0,0,0,0,0,0,0,0,0,0,0,12,0,0,0,0,0,0,0,0,24,0,0,0,0,0,0,0,10,0,0,10,0,0,0,0,0,12,0,0,0,0,0,0,0,0,0,0,0,0,13,0,0,0,0,0,0,0,0,0,0
0,0,0,0,0,0,0,0,0,0,0,0,0,0,13,0,0,0,0,0,3,3,3,3,3,3,3,3,3,3,3,3,3,3,3,3,3,3,3,3,3,3,3,3,3,3,3,3,3,3,3,3,3,3,3,3,3,3,3,3,3,3,3,3,3,3,3,3,3,3,3,3,3,10,0,0,0,0,0
0,0,0,0,0,0,0,0,0,0,0,0,0,0,0,21,0,0,0,0,0,0,3,3,3,3,3,3,3,3,3,3,3,3,3,3,3,3,3,3,3,3,3,3,3,3,3,3,3,3,3,3,3,3,3,3,3,3,3,3,3,3,3,3,3,3,3,3,3,3,3,3,3,0,0,0,0,0,0
0,0,0,0,0,0,0,0,0,0,0,0,0,0,0,0,0,0,0,0,0,0,10,0,3,3,3,3,3,3,3,3,3,3,3,3,3,3,3,3,3,3,3,3,3,3,3,3,3,3,3,3,3,3,3,3,3,3,3,3,3,3,3,3,3,3,3,3,3,3,3,3,3,3,21,22,0,0,0
0,0,0,0,0,0,0,0,0,0,0,0,0,0,0,0,0,0,0,0,8,17,6,12,0,0,15,0,0,0,0,0,12,0,0,15,0,0,0,0,0,0,0,15,0,0,0,0,0,0,0,0,0,0,15,15,0,0,0,21,21,0,0,15,0,0,0,0,21,0,0,0,0,0,0,12,0,0,0
0,0,0,0,0,0,0,0,0,0,0,0,0,0,0,0,0,0,0,0,0,21,21,0,21,21,21,21,0,0,21,21,0,0,0,0,0,0,0,0,0,0,21,21,0,0,0,0,0,0,0,0,0,0,21,21,0,0,0,0,0,21,21,21,0,21,21,21,0,0,0,0,0,0,0,0,0,0,0
0,0,0,0,0,0,0,0,0,0,0,0,0,0,0,0,0,0,0,0,0,0,0,0,0,0,0,0,0,0,0,0,0,0,0,0,0,0,0,0,0,0,0,0,0,0,0,0,0,0,0,0,0,0,0,0,0,0,0,0,0,0,0,0,0,0,0,0,0,0,0,0,0,0,0,0,0,0,0
0,0,0,0,0,0,0,0,0,0,0,0,0,0,0,0,0,0,0,0,0,0,0,0,0,0,0,0,0,0,0,0,0,0,0,0,0,0,0,0,0,0,0,0,0,0,0,0,0,0,0,0,0,0,0,0,0,0,0,0,0,0,0,0,0,0,0,0,0,0,0,0,0,0,0,0,0,0,0
0,0,0,0,0,0,0,0,0,0,0,0,0,0,0,0,0,0,0,0,0,0,0,0,0,0,0,0,0,0,0,0,0,0,0,0,0,0,0,0,0,0,0,0,0,0,0,0,0,0,0,0,0,0,0,0,0,0,0,0,0,0,0,0,0,0,0,0,0,0,0,0,0,0,0,0,0,0,0
0,0,0,0,0,0,0,0,0,0,0,0,0,0,0,0,0,0,0,0,0,0,0,0,0,0,0,0,0,0,0,0,0,0,0,0,0,0,0,0,0,0,0,0,0,0,0,0,0,0,0,0,0,0,0,0,0,0,0,0,0,0,0,0,0,0,0,0,0,0,0,0,0,0,0,0,0,0,0
endlayer

layer
0,0,0,0,0,0,0,0,0,0,0,0,0,0,0,0,0,0,0,0,0,0,0,0,0,0,0,0,0,0,0,0,0,0,0,0,0,0,0,0,0,0,0,0,0,0,0,0,0,0,0,0,0,0,0,0,0,0,0,0,0,0,0,0,0,0,0,0,0,0,0,0,0,0,0,0,0,0,0
0,0,0,0,0,0,0,0,0,0,0,0,0,0,0,0,0,0,0,0,0,0,0,0,0,0,0,0,0,0,0,0,0,0,0,0,0,0,0,0,0,0,0,0,0,0,0,0,0,0,0,0,0,0,0,0,0,0,0,0,0,0,0,0,0,0,0,0,0,0,0,0,0,0,0,0,0,0,0
0,0,0,0,0,0,0,0,0,0,0,0,0,0,0,0,0,0,0,0,0,0,0,0,0,0,0,0,0,0,0,0,0,0,0,0,0,0,0,0,0,0,0,0,0,0,0,0,0,0,0,0,0,0,0,0,0,0,0,0,0,0,0,0,0,0,0,0,0,0,0,0,0,0,0,0,0,0,0
0,0,0,0,0,0,0,0,0,0,0,0,0,0,0,0,0,0,0,0,0,0,0,0,0,0,0,0,0,0,0,0,0,0,0,0,0,0,0,0,0,0,0,0,0,0,0,0,0,0,0,0,0,0,0,0,0,0,0,0,0,0,0,0,0,0,0,0,0,0,0,0,0,0,0,0,0,0,0
0,0,0,0,0,0,0,0,0,0,0,0,0,0,0,0,0,0,0,0,10,10,10,0,0,0,0,0,10,10,0,0,0,0,0,10,10,10,0,0,0,0,10,0,0,0,0,0,0,0,0,0,0,0,10,0,0,10,0,0,0,0,0,0,10,0,10,0,0,10,10,0,0,0,0,0,0,0,0
0,0,0,0,0,0,0,0,0,0,0,0,0,0,0,10,0,0,0,0,17,18,7,18,0,5,18,0,18,12,0,18,0,17,7,18,6,5,24,0,7,5,0,18,5,17,10,6,17,10,7,18,6,0,6,12,7,18,18,0,5,0,5,18,17,7,0,16,13,5,7,0,5,18,0,0,0,0,0
0,0,0,0,0,0,0,0,0,0,0,0,0,0,13,0,0,0,0,0,0,0,0,0,10,10,10,0,0,0,0,0,0,0,0,0,15,0,0,0,10,0,0,0,0,0,0,0,0,0,0,15,0,0,0,0,0,0,0,0,0,10,10,0,10,10,0,0,0,0,0,0,0,10,0,0,0,0,0
0,0,0,0,0,0,0,0,0,0,0,0,0,0,0,21,0,0,0,0,0,0,13,0,0,17,3,6,0,0,0,0,0,0,0,17,3,5,0,0,0,0,15,0,0,6,3,17,0,0,0,0,0,0,0,17,3,18,0,0,0,0,0,0,0,7,3,17,0,0,0,0,0,0,0,0,0,0,0
0,0,0,0,0,0,0,0,0,0,0,0,0,0,0,0,0,0,0,0,0,0,0,0,0,0,0,0,0,0,0,0,0,0,0,21,0,0,21,0,0,0,0,0,0,0,21,21,21,0,0,0,0,0,21,0,0,0,21,0,0,0,15,0,0,0,0,0,0,21,0,0,0,0,21,22,0,0,0
0,0,0,0,0,0,0,0,0,0,0,0,0,0,0,0,0,0,0,0,0,0,0,0,0,7,6,18,0,0,16,18,12,17,17,6,0,17,5,18,7,16,18,0,6,16,5,0,0,18,7,7,0,7,7,17,5,0,0,21,21,5,7,5,17,6,18,7,21,6,0,7,5,17,18,12,0,0,0
0,0,0,0,0,0,0,0,0,0,0,0,0,0,0,0,0,0,0,0,0,0,0,0,21,21,21,21,0,0,21,21,0,0,0,0,0,0,0,0,0,0,21,21,0,0,0,0,0,0,0,0,0,0,21,21,0,0,0,0,0,21,21,21,0,21,21,21,0,0,0,0,0,0,0,0,0,0,0
0,0,0,0,0,0,0,0,0,0,0,0,0,0,0,0,0,0,0,0,0,0,0,0,0,0,0,0,0,0,0,0,0,0,0,0,0,0,0,0,0,0,0,0,0,0,0,0,0,0,0,0,0,0,0,0,0,0,0,0,0,0,0,0,0,0,0,0,0,0,0,0,0,0,0,0,0,0,0
0,0,0,0,0,0,0,0,0,0,0,0,0,0,0,0,0,0,0,0,0,0,0,0,0,0,0,0,0,0,0,0,0,0,0,0,0,0,0,0,0,0,0,0,0,0,0,0,0,0,0,0,0,0,0,0,0,0,0,0,0,0,0,0,0,0,0,0,0,0,0,0,0,0,0,0,0,0,0
0,0,0,0,0,0,0,0,0,0,0,0,0,0,0,0,0,0,0,0,0,0,0,0,0,0,0,0,0,0,0,0,0,0,0,0,0,0,0,0,0,0,0,0,0,0,0,0,0,0,0,0,0,0,0,0,0,0,0,0,0,0,0,0,0,0,0,0,0,0,0,0,0,0,0,0,0,0,0
0,0,0,0,0,0,0,0,0,0,0,0,0,0,0,0,0,0,0,0,0,0,0,0,0,0,0,0,0,0,0,0,0,0,0,0,0,0,0,0,0,0,0,0,0,0,0,0,0,0,0,0,0,0,0,0,0,0,0,0,0,0,0,0,0,0,0,0,0,0,0,0,0,0,0,0,0,0,0
endlayer

layer
0,0,0,0,0,0,0,0,0,0,0,0,0,0,0,0,0,0,0,0,0,0,0,0,0,0,0,0,0,0,0,0,0,0,0,0,0,0,0,0,0,0,0,0,0,0,0,0,0,0,0,0,0,0,0,0,0,0,0,0,0,0,0,0,0,0,0,0,0,0,0,0,0,0,0,0,0,0,0
0,0,0,0,0,0,0,0,0,0,0,0,0,0,0,0,0,0,0,0,0,0,0,0,0,0,0,0,0,0,0,0,0,0,0,0,0,0,0,0,0,0,0,0,0,0,0,0,0,0,0,0,0,0,0,0,0,0,0,0,0,0,0,0,0,0,0,0,0,0,0,0,0,0,0,0,0,0,0
0,0,0,0,0,0,0,0,0,0,0,0,0,0,0,0,0,0,0,0,0,0,0,0,0,0,0,0,0,0,0,0,0,0,0,0,0,0,0,0,0,0,0,0,0,0,0,0,0,0,0,0,0,0,0,0,0,0,0,0,0,0,0,0,0,0,0,0,0,0,0,0,0,0,0,0,0,0,0
0,0,0,0,0,0,0,0,0,0,0,0,0,0,0,0,0,0,0,0,0,0,0,0,0,0,0,0,0,0,0,0,0,0,0,0,0,0,0,0,0,0,0,0,0,0,0,0,0,0,0,0,0,0,0,0,0,0,0,0,0,0,0,0,0,0,0,0,0,0,0,0,0,0,0,0,0,0,0
0,0,0,0,0,0,0,0,0,0,0,0,0,0,0,0,0,0,0,0,0,0,0,0,0,0,0,0,10,10,0,0,0,0,0,10,10,0,0,0,0,0,10,0,0,0,0,0,0,0,0,0,0,0,0,0,0,10,0,0,0,0,0,0,10,0,10,0,0,0,0,0,0,0,0,0,0,0,0
0,0,0,0,0,0,0,0,0,0,0,0,0,0,0,10,0,0,0,0,0,0,0,0,0,0,0,0,0,0,0,0,0,13,0,0,0,0,10,0,0,0,0,0,0,10,10,0,0,10,10,0,10,0,0,0,0,0,0,0,0,0,0,13,0,0,0,0,0,0,10,0,0,0,0,0,0,0,0
0,0,0,0,0,0,0,0,0,0,0,0,0,0,13,0,0,0,0,0,0,0,0,0,10,10,10,0,0,0,0,0,0,0,0,0,0,0,0,0,10,0,0,0,0,0,0,0,0,0,0,0,0,0,0,0,0,0,0,0,0,10,10,0,10,10,0,0,0,0,0,0,0,10,0,0,0,0,0
0,0,0,0,0,0,0,0,0,0,0,0,0,0,0,21,0,0,0,0,0,0,13,0,17,16,3,17,5,0,0,0,0,0,17,7,3,17,6,0,0,0,0,0,6,18,3,5,17,0,0,0,0,0,17,7,3,17,7,0,0,0,0,0,18,18,3,18,5,0,0,0,0,0,7,0,0,0,0
0,0,0,0,0,0,0,0,0,0,0,0,0,0,0,0,0,0,0,0,0,0,0,0,0,0,0,0,0,0,0,0,0,0,0,21,0,0,21,0,0,0,0,0,0,0,0,21,21,0,0,0,0,0,21,0,0,0,21,0,0,0,0,0,0,0,0,0,0,21,0,0,0,0,21,22,0,0,0
0,0,0,0,0,0,0,0,0,0,0,0,0,0,0,0,0,0,0,0,0,0,0,0,0,21,12,0,0,0,0,0,12,0,0,0,0,0,0,0,0,0,0,0,0,0,21,0,0,0,0,0,0,0,0,0,0,0,0,21,21,0,0,0,0,0,0,0,21,0,0,0,0,0,21,0,0,0,0
0,0,0,0,0,0,0,0,0,0,0,0,0,0,0,0,0,0,0,0,0,0,0,0,21,21,0,21,0,0,21,21,0,0,0,0,0,0,0,0,0,0,21,21,0,0,0,0,0,0,0,0,0,0,21,21,0,0,0,0,0,0,0,0,0,21,0,0,0,0,0,0,0,0,0,0,0,0,0
0,0,0,0,0,0,0,0,0,0,0,0,0,0,0,0,0,0,0,0,0,0,0,0,0,0,0,0,0,0,0,0,0,0,0,0,0,0,0,0,0,0,0,0,0,0,0,0,0,0,0,0,0,0,0,0,0,0,0,0,0,0,0,0,0,0,0,0,0,0,0,0,0,0,0,0,0,0,0
0,0,0,0,0,0,0,0,0,0,0,0,0,0,0,0,0,0,0,0,0,0,0,0,0,0,0,0,0,0,0,0,0,0,0,0,0,0,0,0,0,0,0,0,0,0,0,0,0,0,0,0,0,0,0,0,0,0,0,0,0,0,0,0,0,0,0,0,0,0,0,0,0,0,0,0,0,0,0
0,0,0,0,0,0,0,0,0,0,0,0,0,0,0,0,0,0,0,0,0,0,0,0,0,0,0,0,0,0,0,0,0,0,0,0,0,0,0,0,0,0,0,0,0,0,0,0,0,0,0,0,0,0,0,0,0,0,0,0,0,0,0,0,0,0,0,0,0,0,0,0,0,0,0,0,0,0,0
0,0,0,0,0,0,0,0,0,0,0,0,0,0,0,0,0,0,0,0,0,0,0,0,0,0,0,0,0,0,0,0,0,0,0,0,0,0,0,0,0,0,0,0,0,0,0,0,0,0,0,0,0,0,0,0,0,0,0,0,0,0,0,0,0,0,0,0,0,0,0,0,0,0,0,0,0,0,0
endlayer

layer
0,0,0,0,0,0,0,0,0,0,0,0,0,0,0,0,0,0,0,0,0,0,0,0,0,0,0,0,0,0,0,0,0,0,0,0,0,0,0,0,0,0,0,0,0,0,0,0,0,0,0,0,0,0,0,0,0,0,0,0,0,0,0,0,0,0,0,0,0,0,0,0,0,0,0,0,0,0,0
0,0,0,0,0,0,0,0,0,0,0,0,0,0,0,0,0,0,0,0,0,0,0,0,0,0,0,0,0,0,0,0,0,0,0,0,0,0,0,0,0,0,0,0,0,0,0,0,0,0,0,0,0,0,0,0,0,0,0,0,0,0,0,0,0,0,0,0,0,0,0,0,0,0,0,0,0,0,0
0,0,0,0,0,0,0,0,0,0,0,0,0,0,0,0,0,0,0,0,0,0,0,0,0,0,0,0,0,0,0,0,0,0,0,0,0,0,0,0,0,0,0,0,0,0,0,0,0,0,0,0,0,0,0,0,0,0,0,0,0,0,0,0,0,0,0,0,0,0,0,0,0,0,0,0,0,0,0
0,0,0,0,0,0,0,0,0,0,0,0,0,0,0,0,0,0,0,0,0,0,0,0,0,0,0,0,0,0,0,0,0,0,0,0,0,0,0,0,0,0,0,0,0,0,0,0,0,0,0,0,0,0,0,0,0,0,0,0,0,0,0,0,0,0,0,0,0,0,0,0,0,0,0,0,0,0,0
0,0,0,0,0,0,0,0,0,0,0,0,0,0,0,0,0,0,0,0,0,0,0,0,0,0,0,0,10,10,0,0,0,0,0,10,10,0,0,0,0,0,10,0,0,0,0,0,0,0,0,0,0,0,0,0,0,10,0,0,0,0,0,0,10,0,10,0,0,0,0,0,0,0,0,0,0,0,0
0,0,0,0,0,0,0,0,0,0,0,0,0,0,0,10,0,0,0,0,0,0,0,0,0,0,0,0,0,0,0,0,0,13,0,0,0,0,10,0,0,0,0,0,0,10,10,0,0,10,10,0,10,0,0,0,0,0,0,0,0,0,0,13,0,0,0,0,0,0,10,0,0,0,0,0,0,0,0
0,0,0,0,0,0,0,0,0,0,0,0,0,0,13,0,0,0,0,0,0,0,0,0,10,10,10,0,0,0,0,0,0,0,0,0,0,0,0,0,10,0,0,0,0,0,0,0,0,0,0,0,0,0,0,0,0,0,0,0,0,10,10,0,10,10,0,0,0,0,0,0,0,10,0,0,0,0,0
0,0,0,0,0,0,0,0,0,0,0,0,0,0,0,21,0,0,0,0,0,0,13,7,18,3,3,3,18,7,0,0,0,18,6,3,3,3,17,7,0,0,0,6,5,3,3,3,5,17,0,0,15,6,18,3,3,3,5,6,0,0,0,16,5,3,3,3,7,18,15,0,0,5,18,0,0,0,0
0,0,0,0,0,0,0,0,0,0,0,0,0,0,0,0,0,0,0,0,0,0,0,0,0,0,0,0,0,0,0,0,0,0,0,21,0,0,21,0,0,0,0,0,0,0,0,21,21,0,0,0,0,0,21,0,0,0,21,0,0,0,0,0,0,0,0,0,0,21,0,0,0,0,21,22,0,0,0
0,0,0,0,0,0,0,0,0,0,0,0,0,0,0,0,0,0,0,0,0,0,0,0,0,21,12,0,0,0,0,0,12,0,0,0,0,0,0,0,0,0,0,0,0,0,21,0,0,0,0,0,0,0,0,0,0,0,0,21,21,0,0,0,0,0,0,0,21,0,0,0,0,0,21,0,0,0,0
0,0,0,0,0,0,0,0,0,0,0,0,0,0,0,0,0,0,0,0,0,0,0,0,21,21,0,21,0,0,21,21,0,0,0,0,0,0,0,0,0,0,21,21,0,0,0,0,0,0,0,0,0,0,21,21,0,0,0,0,0,0,0,0,0,21,0,0,0,0,0,0,0,0,0,0,0,0,0
0,0,0,0,0,0,0,0,0,0,0,0,0,0,0,0,0,0,0,0,0,0,0,0,0,0,0,0,0,0,0,0,0,0,0,0,0,0,0,0,0,0,0,0,0,0,0,0,0,0,0,0,0,0,0,0,0,0,0,0,0,0,0,0,0,0,0,0,0,0,0,0,0,0,0,0,0,0,0
0,0,0,0,0,0,0,0,0,0,0,0,0,0,0,0,0,0,0,0,0,0,0,0,0,0,0,0,0,0,0,0,0,0,0,0,0,0,0,0,0,0,0,0,0,0,0,0,0,0,0,0,0,0,0,0,0,0,0,0,0,0,0,0,0,0,0,0,0,0,0,0,0,0,0,0,0,0,0
0,0,0,0,0,0,0,0,0,0,0,0,0,0,0,0,0,0,0,0,0,0,0,0,0,0,0,0,0,0,0,0,0,0,0,0,0,0,0,0,0,0,0,0,0,0,0,0,0,0,0,0,0,0,0,0,0,0,0,0,0,0,0,0,0,0,0,0,0,0,0,0,0,0,0,0,0,0,0
0,0,0,0,0,0,0,0,0,0,0,0,0,0,0,0,0,0,0,0,0,0,0,0,0,0,0,0,0,0,0,0,0,0,0,0,0,0,0,0,0,0,0,0,0,0,0,0,0,0,0,0,0,0,0,0,0,0,0,0,0,0,0,0,0,0,0,0,0,0,0,0,0,0,0,0,0,0,0
endlayer

layer
0,0,0,0,0,0,0,0,0,0,0,0,0,0,0,0,0,0,0,0,0,0,0,0,0,0,0,0,0,0,0,0,0,0,0,0,0,0,0,0,0,0,0,0,0,0,0,0,0,0,0,0,0,0,0,0,0,0,0,0,0,0,0,0,0,0,0,0,0,0,0,0,0,0,0,0,0,0,0
0,0,0,0,0,0,0,0,0,0,0,0,0,0,0,0,0,0,0,0,0,0,0,0,0,0,0,0,0,0,0,0,0,0,0,0,0,0,0,0,0,0,0,0,0,0,0,0,0,0,0,0,0,0,0,0,0,0,0,0,0,0,0,0,0,0,0,0,0,0,0,0,0,0,0,0,0,0,0
0,0,0,0,0,0,0,0,0,0,0,0,0,0,0,0,0,0,0,0,0,0,0,0,0,0,0,0,0,0,0,0,0,0,0,0,0,0,0,0,0,0,0,0,0,0,0,0,0,0,0,0,0,0,0,0,0,0,0,0,0,0,0,0,0,0,0,0,0,0,0,0,0,0,0,0,0,0,0
0,0,0,0,0,0,0,0,0,0,0,0,0,0,0,0,0,0,0,0,0,0,0,0,0,0,0,0,0,0,0,0,0,0,0,0,0,0,0,0,0,0,0,0,0,0,0,0,0,0,0,0,0,0,0,0,0,0,0,0,0,0,0,0,0,0,0,0,0,0,0,0,0,0,0,0,0,0,0
0,0,0,0,0,0,0,0,0,0,0,0,0,0,0,0,0,0,0,0,0,0,0,0,0,0,0,0,10,10,0,0,0,0,0,10,10,0,0,0,0,0,10,0,0,0,0,0,0,0,0,0,0,0,0,0,0,10,0,0,0,0,0,0,10,0,10,0,0,0,0,0,0,0,0,0,0,0,0
0,0,0,0,0,0,0,0,0,0,0,0,0,0,0,10,0,0,0,0,0,0,0,0,0,0,0,0,0,0,0,0,0,13,0,0,0,0,10,0,0,0,0,0,0,10,10,0,0,10,10,0,10,0,0,0,0,0,0,0,0,0,0,13,0,0,0,0,0,0,10,0,0,0,0,0,0,0,0
0,0,0,0,0,0,0,0,0,0,0,0,0,0,13,0,0,0,0,0,0,0,0,0,10,10,10,0,0,0,0,0,0,0,0,0,0,0,0,0,10,0,0,0,0,0,0,0,0,0,0,0,0,0,0,0,0,0,0,0,0,10,10,0,10,0,0,0,0,0,0,0,0,0,0,0,0,0,0
0,0,0,0,0,0,0,0,0,0,0,0,0,0,0,21,0,0,0,0,5,0,7,5,3,3,0,3,3,5,18,15,7,5,3,3,0,3,3,5,18,0,7,18,3,3,28,3,3,18,7,0,16,5,3,3,0,3,3,5,18,0,18,17,3,3,0,3,3,17,5,0,17,6,3,0,0,0,0
0,0,0,0,0,0,0,0,0,0,0,0,0,0,0,0,0,0,0,0,0,0,0,0,0,0,0,0,0,0,0,0,0,0,0,21,0,0,21,0,0,0,0,0,0,0,0,21,21,0,0,0,0,0,21,0,0,0,0,0,0,0,0,0,0,0,0,0,0,21,0,0,0,0,21,22,0,0,0
0,0,0,0,0,0,0,0,0,0,0,0,0,0,0,0,0,0,0,0,0,0,0,0,0,21,12,0,0,0,0,0,12,0,0,0,0,0,0,0,0,0,0,0,0,0,21,0,0,0,0,0,0,0,0,0,0,0,0,21,21,0,0,0,0,0,0,0,21,0,0,0,0,0,21,0,0,0,0
0,0,0,0,0,0,0,0,0,0,0,0,0,0,0,0,0,0,0,0,0,0,0,0,21,21,0,21,0,0,21,21,0,0,0,0,0,0,0,0,0,0,21,21,0,0,0,0,0,0,0,0,0,0,21,21,0,0,0,0,0,0,0,0,0,21,0,0,0,0,0,0,0,0,0,0,0,0,0
0,0,0,0,0,0,0,0,0,0,0,0,0,0,0,0,0,0,0,0,0,0,0,0,0,0,0,0,0,0,0,0,0,0,0,0,0,0,0,0,0,0,0,0,0,0,0,0,0,0,0,0,0,0,0,0,0,0,0,0,0,0,0,0,0,0,0,0,0,0,0,0,0,0,0,0,0,0,0
0,0,0,0,0,0,0,0,0,0,0,0,0,0,0,0,0,0,0,0,0,0,0,0,0,0,0,0,0,0,0,0,0,0,0,0,0,0,0,0,0,0,0,0,0,0,0,0,0,0,0,0,0,0,0,0,0,0,0,0,0,0,0,0,0,0,0,0,0,0,0,0,0,0,0,0,0,0,0
0,0,0,0,0,0,0,0,0,0,0,0,0,0,0,0,0,0,0,0,0,0,0,0,0,0,0,0,0,0,0,0,0,0,0,0,0,0,0,0,0,0,0,0,0,0,0,0,0,0,0,0,0,0,0,0,0,0,0,0,0,0,0,0,0,0,0,0,0,0,0,0,0,0,0,0,0,0,0
0,0,0,0,0,0,0,0,0,0,0,0,0,0,0,0,0,0,0,0,0,0,0,0,0,0,0,0,0,0,0,0,0,0,0,0,0,0,0,0,0,0,0,0,0,0,0,0,0,0,0,0,0,0,0,0,0,0,0,0,0,0,0,0,0,0,0,0,0,0,0,0,0,0,0,0,0,0,0
endlayer

layer
0,0,0,0,0,0,0,0,0,0,0,0,0,0,0,0,0,0,0,0,0,0,0,0,0,0,0,0,0,0,0,0,0,0,0,0,0,0,0,0,0,0,0,0,0,0,0,0,0,0,0,0,0,0,0,0,0,0,0,0,0,0,0,0,0,0,0,0,0,0,0,0,0,0,0,0,0,0,0
0,0,0,0,0,0,0,0,0,0,0,0,0,0,0,0,0,0,0,0,0,0,0,0,0,0,0,0,0,0,0,0,0,0,0,0,0,0,0,0,0,0,0,0,0,0,0,0,0,0,0,0,0,0,0,0,0,0,0,0,0,0,0,0,0,0,0,0,0,0,0,0,0,0,0,0,0,0,0
0,0,0,0,0,0,0,0,0,0,0,0,0,0,0,0,0,0,0,0,0,0,0,0,0,0,0,0,0,0,0,0,0,0,0,0,0,0,0,0,0,0,0,0,0,0,0,0,0,0,0,0,0,0,0,0,0,0,0,0,0,0,0,0,0,0,0,0,0,0,0,0,0,0,0,0,0,0,0
0,0,0,0,0,0,0,0,0,0,0,0,0,0,0,0,0,0,0,0,0,0,0,0,0,0,0,0,0,0,0,0,0,0,0,0,0,0,0,0,0,0,0,0,0,0,0,0,0,0,0,0,0,0,0,0,0,0,0,0,0,0,0,0,0,0,0,0,0,0,0,0,0,0,0,0,0,0,0
0,0,0,0,0,0,0,0,0,0,0,0,0,0,0,0,0,0,0,0,0,0,0,0,0,0,0,0,10,10,0,0,0,0,0,10,10,0,0,0,0,0,10,0,0,0,0,0,0,0,0,0,0,0,0,0,0,10,0,0,0,0,0,0,10,0,10,0,0,0,0,0,0,0,0,0,0,0,0
0,0,0,0,0,0,0,0,0,0,0,0,0,0,0,10,0,0,0,0,0,0,0,0,0,0,0,0,0,0,0,0,0,13,0,0,0,0,10,0,0,0,0,0,0,10,10,0,0,10,10,0,10,0,0,0,0,0,0,0,0,0,0,13,0,0,0,0,0,0,10,0,0,0,0,0,0,0,0
0,0,0,0,0,0,0,0,0,0,0,0,0,0,13,0,0,0,0,0,0,0,0,0,10,10,10,0,0,0,0,0,0,0,0,0,0,0,0,0,10,0,0,0,0,0,0,0,0,0,0,0,0,0,0,0,0,0,0,0,0,10,10,0,10,0,0,0,0,0,0,0,0,0,0,0,0,0,0
0,0,0,0,0,0,0,0,0,0,0,0,0,0,0,21,0,0,0,3,17,6,5,3,3,0,0,0,3,3,7,18,6,3,3,0,0,0,3,3,6,6,18,3,3,0,0,15,3,3,5,18,17,3,3,0,0,0,3,3,7,5,6,3,3,15,0,0,3,3,6,16,7,3,3,3,0,0,0
0,0,0,0,0,0,0,0,0,0,0,0,0,0,0,0,0,0,0,0,0,0,0,0,0,0,0,0,0,0,0,0,0,0,0,0,0,0,21,0,0,0,0,0,0,0,0,0,0,0,0,0,0,0,21,0,0,0,0,0,0,0,0,0,0,0,0,0,0,21,0,0,0,0,21,22,0,0,0
0,0,0,0,0,0,0,0,0,0,0,0,0,0,0,0,0,0,0,0,0,0,0,0,0,21,12,0,0,0,0,0,12,0,0,0,0,0,0,0,0,0,0,0,0,0,21,0,0,0,0,0,0,0,0,0,0,0,0,21,21,0,0,0,0,0,0,0,21,0,0,0,0,0,21,0,0,0,0
0,0,0,0,0,0,0,0,0,0,0,0,0,0,0,0,0,0,0,0,0,0,0,0,21,21,0,21,0,0,21,21,0,0,0,0,0,0,0,0,0,0,21,21,0,0,0,0,0,0,0,0,0,0,21,21,0,0,0,0,0,0,0,0,0,21,0,0,0,0,0,0,0,0,0,0,0,0,0
0,0,0,0,0,0,0,0,0,0,0,0,0,0,0,0,0,0,0,0,0,0,0,0,0,0,0,0,0,0,0,0,0,0,0,0,0,0,0,0,0,0,0,0,0,0,0,0,0,0,0,0,0,0,0,0,0,0,0,0,0,0,0,0,0,0,0,0,0,0,0,0,0,0,0,0,0,0,0
0,0,0,0,0,0,0,0,0,0,0,0,0,0,0,0,0,0,0,0,0,0,0,0,0,0,0,0,0,0,0,0,0,0,0,0,0,0,0,0,0,0,0,0,0,0,0,0,0,0,0,0,0,0,0,0,0,0,0,0,0,0,0,0,0,0,0,0,0,0,0,0,0,0,0,0,0,0,0
0,0,0,0,0,0,0,0,0,0,0,0,0,0,0,0,0,0,0,0,0,0,0,0,0,0,0,0,0,0,0,0,0,0,0,0,0,0,0,0,0,0,0,0,0,0,0,0,0,0,0,0,0,0,0,0,0,0,0,0,0,0,0,0,0,0,0,0,0,0,0,0,0,0,0,0,0,0,0
0,0,0,0,0,0,0,0,0,0,0,0,0,0,0,0,0,0,0,0,0,0,0,0,0,0,0,0,0,0,0,0,0,0,0,0,0,0,0,0,0,0,0,0,0,0,0,0,0,0,0,0,0,0,0,0,0,0,0,0,0,0,0,0,0,0,0,0,0,0,0,0,0,0,0,0,0,0,0
endlayer

layer
0,0,0,0,0,0,0,0,0,0,0,0,0,0,0,0,0,0,0,0,0,0,0,0,0,0,0,0,0,0,0,0,0,0,0,0,0,0,0,0,0,0,0,0,0,0,0,0,0,0,0,0,0,0,0,0,0,0,0,0,0,0,0,0,0,0,0,0,0,0,0,0,0,0,0,0,0,0,0
0,0,0,0,0,0,0,0,0,0,0,0,0,0,0,0,0,0,0,0,0,0,0,0,0,0,0,0,0,0,0,0,0,0,0,0,0,0,0,0,0,0,0,0,0,0,0,0,0,0,0,0,0,0,0,0,0,0,0,0,0,0,0,0,0,0,0,0,0,0,0,0,0,0,0,0,0,0,0
0,0,0,0,0,0,0,0,0,0,0,0,0,0,0,0,0,0,0,0,0,0,0,0,0,0,0,0,0,0,0,0,0,0,0,0,0,0,0,0,0,0,0,0,0,0,0,0,0,0,0,0,0,0,0,0,0,0,0,0,0,0,0,0,0,0,0,0,0,0,0,0,0,0,0,0,0,0,0
0,0,0,0,0,0,0,0,0,0,0,0,0,0,0,0,0,0,0,0,0,0,0,0,0,0,0,0,0,0,0,0,0,0,0,0,0,0,0,0,0,0,0,0,0,0,0,0,0,0,0,0,0,0,0,0,0,0,0,0,0,0,0,0,0,0,0,0,0,0,0,0,0,0,0,0,0,0,0
0,0,0,0,0,0,0,0,0,0,0,0,0,0,0,0,0,0,0,0,0,0,0,0,0,0,0,0,10,10,0,0,0,0,0,10,10,0,0,0,0,0,10,0,0,0,0,0,0,0,0,0,0,0,0,0,0,10,0,0,0,0,0,0,10,0,10,0,0,0,0,0,0,0,0,0,0,0,0
0,0,0,0,0,0,0,0,0,0,0,0,0,0,0,10,0,0,0,0,0,0,0,0,0,0,0,0,0,0,0,0,0,13,0,0,0,0,10,0,0,0,0,0,0,10,10,0,0,10,10,0,10,0,0,0,0,0,0,0,0,0,0,13,0,0,0,0,0,0,10,0,0,0,0,0,0,0,0
0,0,0,0,0,0,0,0,0,0,0,0,0,0,13,0,0,0,0,0,0,0,0,0,10,10,10,0,0,0,0,0,0,0,0,0,0,0,0,0,0,0,0,0,0,0,0,0,0,0,0,0,0,0,0,0,0,0,0,0,0,10,10,0,0,0,0,0,0,0,0,0,0,0,0,0,0,0,0
0,0,0,0,0,0,0,0,0,0,0,0,0,0,0,21,0,0,3,3,3,3,3,3,3,3,3,3,3,3,3,3,3,3,3,3,3,3,3,3,3,3,3,3,3,3,3,3,3,3,3,3,3,3,3,3,3,3,3,3,3,3,3,3,3,3,3,3,3,3,3,3,3,3,3,3,0,0,0
0,0,0,0,0,0,0,0,0,0,0,0,0,0,0,0,0,0,0,0,0,0,0,0,0,0,0,0,0,0,0,0,0,0,0,0,0,0,21,0,0,0,0,0,0,0,0,0,0,0,0,0,0,0,21,0,0,0,0,0,0,0,0,0,0,0,0,0,0,21,0,0,0,0,0,12,0,0,0
0,0,0,0,0,0,0,0,0,0,0,0,0,0,0,0,0,0,0,0,0,0,0,0,0,21,12,0,0,0,0,0,12,0,0,0,0,0,0,0,0,0,0,0,0,0,21,0,0,0,0,0,0,0,0,0,0,0,0,21,21,0,0,0,0,0,0,0,21,0,0,0,0,0,21,0,0,0,0
0,0,0,0,0,0,0,0,0,0,0,0,0,0,0,0,0,0,0,0,0,0,0,0,21,21,0,21,0,0,21,21,0,0,0,0,0,0,0,0,0,0,21,21,0,0,0,0,0,0,0,0,0,0,21,21,0,0,0,0,0,0,0,0,0,21,0,0,0,0,0,0,0,0,0,0,0,0,0
0,0,0,0,0,0,0,0,0,0,0,0,0,0,0,0,0,0,0,0,0,0,0,0,0,0,0,0,0,0,0,0,0,0,0,0,0,0,0,0,0,0,0,0,0,0,0,0,0,0,0,0,0,0,0,0,0,0,0,0,0,0,0,0,0,0,0,0,0,0,0,0,0,0,0,0,0,0,0
0,0,0,0,0,0,0,0,0,0,0,0,0,0,0,0,0,0,0,0,0,0,0,0,0,0,0,0,0,0,0,0,0,0,0,0,0,0,0,0,0,0,0,0,0,0,0,0,0,0,0,0,0,0,0,0,0,0,0,0,0,0,0,0,0,0,0,0,0,0,0,0,0,0,0,0,0,0,0
0,0,0,0,0,0,0,0,0,0,0,0,0,0,0,0,0,0,0,0,0,0,0,0,0,0,0,0,0,0,0,0,0,0,0,0,0,0,0,0,0,0,0,0,0,0,0,0,0,0,0,0,0,0,0,0,0,0,0,0,0,0,0,0,0,0,0,0,0,0,0,0,0,0,0,0,0,0,0
0,0,0,0,0,0,0,0,0,0,0,0,0,0,0,0,0,0,0,0,0,0,0,0,0,0,0,0,0,0,0,0,0,0,0,0,0,0,0,0,0,0,0,0,0,0,0,0,0,0,0,0,0,0,0,0,0,0,0,0,0,0,0,0,0,0,0,0,0,0,0,0,0,0,0,0,0,0,0
endlayer

layer
0,0,0,0,0,0,0,0,0,0,0,0,0,0,0,0,0,0,0,0,0,0,0,0,0,0,0,0,0,0,0,0,0,0,0,0,0,0,0,0,0,0,0,0,0,0,0,0,0,0,0,0,0,0,0,0,0,0,0,0,0,0,0,0,0,0,0,0,0,0,0,0,0,0,0,0,0,0,0
0,0,0,0,0,0,0,0,0,0,0,0,0,0,0,0,0,0,0,0,0,0,0,0,0,0,0,0,0,0,0,0,0,0,0,0,0,0,0,0,0,0,0,0,0,0,0,0,0,0,0,0,0,0,0,0,0,0,0,0,0,0,0,0,0,0,0,0,0,0,0,0,0,0,0,0,0,0,0
0,0,0,0,0,0,0,0,0,0,0,0,0,0,0,0,0,0,0,0,0,0,0,0,0,0,0,0,0,0,0,0,0,0,0,0,0,0,0,0,0,0,0,0,0,0,0,0,0,0,0,0,0,0,0,0,0,0,0,0,0,0,0,0,0,0,0,0,0,0,0,0,0,0,0,0,0,0,0
0,0,0,0,0,0,0,0,0,0,0,0,0,0,0,0,0,0,0,0,0,0,0,0,0,0,0,0,0,0,0,0,0,0,0,0,0,0,0,0,0,0,0,0,0,0,0,0,0,0,0,0,0,0,0,0,0,0,0,0,0,0,0,0,0,0,0,0,0,0,0,0,0,0,0,0,0,0,0
0,0,0,0,0,0,0,0,0,0,0,0,0,0,0,0,0,0,0,0,0,0,0,0,0,0,0,0,10,10,0,0,0,0,0,10,10,0,0,0,0,0,10,0,0,0,0,0,0,0,0,0,0,0,0,0,0,10,0,0,0,0,0,0,10,0,10,0,0,0,0,0,0,0,0,0,0,0,0
0,0,0,0,0,0,0,0,0,0,0,0,0,0,0,10,0,0,0,0,0,0,0,0,0,0,0,0,0,0,0,0,0,13,0,0,0,0,10,0,0,0,0,0,0,10,10,0,0,10,10,0,10,0,0,0,0,0,0,0,0,0,0,13,0,0,0,0,0,0,10,0,0,0,0,0,0,0,0
0,0,0,0,0,0,0,0,0,0,0,0,0,0,13,5,7,18,18,18,17,6,16,6,18,7,5,17,6,5,5,18,6,18,7,5,17,18,7,5,16,18,18,6,18,17,5,7,7,17,7,18,7,18,5,5,7,18,6,18,5,18,7,16,17,18,6,5,7,18,17,5,6,17,0,0,0,0,0
0,0,0,0,0,0,0,0,0,0,0,0,0,0,0,21,0,0,0,0,0,0,15,0,0,15,0,0,0,0,0,0,21,15,0,15,0,0,0,0,15,0,0,0,0,0,0,29,0,0,0,15,0,0,0,0,10,0,0,0,0,21,0,15,15,0,0,0,0,0,0,0,15,0,10,0,0,0,0
0,0,0,0,0,0,0,0,0,0,0,0,0,0,0,0,0,0,17,6,7,5,18,6,18,6,16,17,18,18,17,5,7,18,17,5,7,5,17,18,6,18,18,17,7,18,6,5,17,7,18,5,17,6,7,17,18,7,17,6,18,6,5,17,5,16,18,18,7,17,5,17,16,18,5,12,0,0,0
0,0,0,0,0,0,0,0,0,0,0,0,0,0,0,0,0,0,0,0,0,0,0,0,0,21,12,0,0,0,0,0,12,0,0,0,0,0,0,0,0,0,0,0,0,0,21,0,0,0,0,0,0,0,0,0,0,0,0,21,21,0,0,0,0,0,0,0,21,0,0,0,0,0,21,0,0,0,0
0,0,0,0,0,0,0,0,0,0,0,0,0,0,0,0,0,0,0,0,0,0,0,0,21,21,0,21,0,0,21,21,0,0,0,0,0,0,0,0,0,0,21,21,0,0,0,0,0,0,0,0,0,0,21,21,0,0,0,0,0,0,0,0,0,21,0,0,0,0,0,0,0,0,0,0,0,0,0
0,0,0,0,0,0,0,0,0,0,0,0,0,0,0,0,0,0,0,0,0,0,0,0,0,0,0,0,0,0,0,0,0,0,0,0,0,0,0,0,0,0,0,0,0,0,0,0,0,0,0,0,0,0,0,0,0,0,0,0,0,0,0,0,0,0,0,0,0,0,0,0,0,0,0,0,0,0,0
0,0,0,0,0,0,0,0,0,0,0,0,0,0,0,0,0,0,0,0,0,0,0,0,0,0,0,0,0,0,0,0,0,0,0,0,0,0,0,0,0,0,0,0,0,0,0,0,0,0,0,0,0,0,0,0,0,0,0,0,0,0,0,0,0,0,0,0,0,0,0,0,0,0,0,0,0,0,0
0,0,0,0,0,0,0,0,0,0,0,0,0,0,0,0,0,0,0,0,0,0,0,0,0,0,0,0,0,0,0,0,0,0,0,0,0,0,0,0,0,0,0,0,0,0,0,0,0,0,0,0,0,0,0,0,0,0,0,0,0,0,0,0,0,0,0,0,0,0,0,0,0,0,0,0,0,0,0
0,0,0,0,0,0,0,0,0,0,0,0,0,0,0,0,0,0,0,0,0,0,0,0,0,0,0,0,0,0,0,0,0,0,0,0,0,0,0,0,0,0,0,0,0,0,0,0,0,0,0,0,0,0,0,0,0,0,0,0,0,0,0,0,0,0,0,0,0,0,0,0,0,0,0,0,0,0,0
endlayer

layer
0,0,0,0,0,0,0,0,0,0,0,0,0,0,0,0,0,0,0,0,0,0,0,0,0,0,0,0,0,0,0,0,0,0,0,0,0,0,0,0,0,0,0,0,0,0,0,0,0,0,0,0,0,0,0,0,0,0,0,0,0,0,0,0,0,0,0,0,0,0,0,0,0,0,0,0,0,0,0
0,0,0,0,0,0,0,0,0,0,0,0,0,0,0,0,0,0,0,0,0,0,0,0,0,0,0,0,0,0,0,0,0,0,0,0,0,0,0,0,0,0,0,0,0,0,0,0,0,0,0,0,0,0,0,0,0,0,0,0,0,0,0,0,0,0,0,0,0,0,0,0,0,0,0,0,0,0,0
0,0,0,0,0,0,0,0,0,0,0,0,0,0,0,0,0,0,0,0,0,0,0,0,0,0,0,0,0,0,0,0,0,0,0,0,0,0,0,0,0,0,0,0,0,0,0,0,0,0,0,0,0,0,0,0,0,0,0,0,0,0,0,0,0,0,0,0,0,0,0,0,0,0,0,0,0,0,0
0,0,0,0,0,0,0,0,0,0,0,0,0,0,0,0,0,0,0,0,0,0,0,0,0,0,0,0,0,0,0,0,0,0,0,0,0,0,0,0,0,0,0,0,0,0,0,0,0,0,0,0,0,0,0,0,0,0,0,0,0,0,0,0,0,0,0,0,0,0,0,0,0,0,0,0,0,0,0
0,0,0,0,0,0,0,0,0,0,0,0,0,0,0,0,0,0,0,0,0,0,0,0,0,0,0,0,10,10,0,0,0,0,0,10,10,0,0,0,0,0,10,0,0,0,0,0,0,0,0,0,0,0,0,0,0,10,0,0,0,0,0,0,10,0,10,0,0,0,0,0,0,0,0,0,0,0,0
0,0,0,0,0,0,0,0,0,0,0,0,0,0,0,0,0,0,0,0,18,0,6,0,17,5,18,0,18,7,17,0,0,13,16,17,6,5,18,0,6,5,18,17,16,0,18,0,7,18,17,6,0,7,5,0,0,17,5,17,16,7,6,13,5,18,17,6,18,0,18,7,0,0,0,0,0,0,0
0,0,0,0,0,0,0,0,0,0,0,0,0,0,0,0,0,0,0,0,0,0,0,0,0,0,0,0,0,15,0,0,0,0,0,0,15,0,0,0,0,0,15,0,21,0,0,0,21,21,0,0,0,0,0,0,0,0,0,15,0,21,0,0,0,15,0,21,0,0,0,0,15,0,0,0,0,0,0
0,0,0,0,0,0,0,0,0,0,0,0,0,0,0,0,0,0,0,0,0,0,0,0,0,0,0,0,0,0,0,0,0,0,0,0,0,0,0,0,0,0,0,0,0,0,0,0,0,0,0,0,0,0,0,0,0,0,0,0,0,0,0,0,0,0,0,0,0,0,0,0,0,0,0,0,0,0,0
0,0,0,0,0,0,0,0,0,0,0,0,0,0,0,0,0,0,0,0,0,0,0,0,0,0,0,0,0,0,10,0,0,0,0,0,0,0,0,0,0,0,0,0,0,0,0,0,0,0,15,0,0,0,0,10,0,0,0,10,0,0,0,0,0,0,10,0,0,0,10,0,0,0,0,0,0,0,0
0,0,0,0,0,0,0,0,0,0,0,0,0,0,0,0,0,0,0,0,6,18,0,0,18,7,12,17,0,0,17,6,12,17,5,0,7,5,18,0,6,18,5,17,0,5,0,0,0,0,5,18,6,0,18,7,0,6,18,5,17,0,18,7,0,5,17,6,0,0,5,6,18,0,17,0,0,0,0
0,0,0,0,0,0,0,0,0,0,0,0,0,0,0,0,0,0,0,0,0,0,0,0,21,21,0,21,0,0,21,21,0,0,0,0,0,0,0,0,0,0,21,21,0,0,0,0,0,0,0,0,0,0,21,21,0,0,0,0,0,0,0,0,0,21,0,0,0,0,0,0,0,0,0,0,0,0,0
0,0,0,0,0,0,0,0,0,0,0,0,0,0,0,0,0,0,0,0,0,0,0,0,0,0,0,0,0,0,0,0,0,0,0,0,0,0,0,0,0,0,0,0,0,0,0,0,0,0,0,0,0,0,0,0,0,0,0,0,0,0,0,0,0,0,0,0,0,0,0,0,0,0,0,0,0,0,0
0,0,0,0,0,0,0,0,0,0,0,0,0,0,0,0,0,0,0,0,0,0,0,0,0,0,0,0,0,0,0,0,0,0,0,0,0,0,0,0,0,0,0,0,0,0,0,0,0,0,0,0,0,0,0,0,0,0,0,0,0,0,0,0,0,0,0,0,0,0,0,0,0,0,0,0,0,0,0
0,0,0,0,0,0,0,0,0,0,0,0,0,0,0,0,0,0,0,0,0,0,0,0,0,0,0,0,0,0,0,0,0,0,0,0,0,0,0,0,0,0,0,0,0,0,0,0,0,0,0,0,0,0,0,0,0,0,0,0,0,0,0,0,0,0,0,0,0,0,0,0,0,0,0,0,0,0,0
0,0,0,0,0,0,0,0,0,0,0,0,0,0,0,0,0,0,0,0,0,0,0,0,0,0,0,0,0,0,0,0,0,0,0,0,0,0,0,0,0,0,0,0,0,0,0,0,0,0,0,0,0,0,0,0,0,0,0,0,0,0,0,0,0,0,0,0,0,0,0,0,0,0,0,0,0,0,0
endlayer

