
# Created by Ruins mod version 15.1 Ingame Parser
# authoring Player: SunsOfOld

weight=100
embed_into_distance=6
acceptable_target_blocks=
unacceptable_target_blocks=flowing_water,water,flowing_lava,lava
dimensions=12,18,11
allowable_overhang=0
max_leveling=4
leveling_buffer=0
preserve_water=0
preserve_lava=0
uniqueMinDistance=1000000
preventRotation=1

rule1=0,100,preserveBlock
rule2=0,100,minecraft:bedrock-0
rule3=0,100,CommandBlock:/testfor @p[r=10]:@
rule4=0,100,minecraft:unpowered_comparator-2
rule5=0,100,minecraft:unpowered_repeater-2
rule6=0,100,minecraft:redstone_wire-0
rule7=0,100,minecraft:powered_repeater-3
rule8=0,100,CommandBlock:/summon Villager ~ ~5 ~ {CustomName:\"My horses need fodder.\",CustomNameVisible:1,Profession:0,Offers:{Recipes:[{rewardExp:0b,maxUses:2147483647,uses:0,buy:{id:170,Count:5},sell:{id:420,Count:1}},{rewardExp:0b,maxUses:2147483647,uses:0,buy:{id:170,Count:11},sell:{id:421,Count:1}},{rewardExp:0b,maxUses:2147483647,uses:0,buy:{id:170,Count:9},sell:{id:329,Count:1}},{rewardExp:0b,maxUses:2147483647,uses:0,buy:{id:170,Count:5},sell:{id:417,Count:1}},{rewardExp:0b,maxUses:2147483647,uses:0,buy:{id:170,Count:9},sell:{id:418,Count:1}},{rewardExp:0b,maxUses:2147483647,uses:0,buy:{id:170,Count:11},sell:{id:419,Count:1}}]}}:@
rule9=2,100,minecraft:redstone_torch-4
rule10=0,100,CommandBlock:/setblock ~ ~ ~ 152:@
rule11=0,100,minecraft:powered_repeater-5
rule12=0,100,minecraft:powered_repeater-7
rule13=0,100,minecraft:unpowered_repeater-1
rule14=0,100,minecraft:redstone_wire-15
rule15=0,100,minecraft:redstone_wire-14
rule16=0,100,minecraft:redstone_wire-13
rule17=0,100,minecraft:redstone_wire-12
rule18=0,100,minecraft:dirt-2
rule19=0,100,dendrology:kulist_planks-12
rule20=0,100,dendrology:wood0-5
rule21=0,100,BiblioWoodsBoP:BiblioWoodshelf-12
rule22=0,100,ExtrabiomesXL:door_baldcypress-1
rule23=0,100,GardenTrees:thin_log-0
rule24=0,100,GardenStuff:lattice-3
rule25=0,100,ExtrabiomesXL:fencegate_baldcypress-2
rule26=0,100,ExtrabiomesXL:fencegate_baldcypress-0
rule27=0,100,minecraft:hay_block-0
rule28=0,100,VeganOption:juteBundled-11
rule29=0,100,minecraft:hay_block-8
rule30=0,100,ExtrabiomesXL:door_baldcypress-8
rule31=0,100,dendrology:stairs7-2
rule32=0,100,dendrology:stairs7-3
rule33=0,100,ExtrabiomesXL:stairs.baldcypress-2
rule34=0,100,ExtrabiomesXL:planks-7
rule35=0,100,ExtrabiomesXL:stairs.baldcypress-3
rule36=0,100,dendrology:sslab0-7

layer
1,1,1,1,1,1,1,1,1,1,1
1,1,1,1,1,1,1,1,1,1,1
1,1,1,1,1,1,1,1,1,1,1
1,1,1,1,1,1,1,2,1,1,1
1,1,1,1,1,1,1,1,1,1,1
1,1,1,1,1,1,1,1,1,1,1
1,1,1,1,1,1,1,1,1,1,1
1,1,1,1,1,1,1,1,1,1,1
1,1,1,1,1,1,1,1,1,1,1
1,1,1,1,1,1,1,1,1,1,1
1,1,1,1,1,1,1,1,1,1,1
1,1,1,1,1,1,1,1,1,1,1
1,1,1,1,1,1,1,1,1,1,1
1,1,1,1,1,1,1,1,1,1,1
1,1,1,1,1,1,1,1,1,1,1
1,1,1,1,1,1,1,1,1,1,1
1,1,1,1,1,1,1,1,1,1,1
1,1,1,1,1,1,1,1,1,1,1
endlayer

layer
1,1,1,1,1,1,2,1,1,1,1
1,1,1,1,2,2,2,2,2,1,1
1,1,1,1,2,2,2,2,2,1,1
1,1,1,1,2,2,2,0,2,1,1
1,1,1,1,2,2,2,2,2,1,1
1,1,1,1,2,2,2,2,2,1,1
1,1,1,1,1,1,1,1,1,1,1
1,1,1,1,1,1,1,1,1,1,1
1,1,1,1,1,1,1,1,1,1,1
1,1,1,1,1,1,1,1,1,1,1
1,1,1,1,1,1,1,1,1,1,1
1,1,1,1,1,1,1,1,1,1,1
1,1,1,1,1,1,1,1,1,1,1
1,1,1,1,1,1,1,1,1,1,1
1,1,1,1,1,1,1,1,1,1,1
1,1,1,1,1,1,1,1,1,1,1
1,1,1,1,1,1,1,1,1,1,1
1,1,1,1,1,1,1,1,1,1,1
endlayer

layer
1,1,1,1,2,2,2,2,2,1,1
1,1,1,2,6,5,4,3,0,2,1
1,1,1,2,8,0,0,7,0,2,1
1,1,1,2,10,0,2,9,0,2,1
1,1,1,2,13,0,12,11,0,2,1
1,1,1,2,17,16,15,14,0,2,1
1,1,1,1,2,2,2,2,2,1,1
1,1,1,1,1,1,1,1,1,1,1
1,1,1,1,1,1,1,1,1,1,1
1,1,1,1,1,1,1,1,1,1,1
1,1,1,1,1,1,1,1,1,1,1
1,1,1,1,1,1,1,1,1,1,1
1,1,1,1,1,1,1,1,1,1,1
1,1,1,1,1,1,1,1,1,1,1
1,1,1,1,1,1,1,1,1,1,1
1,1,1,1,1,1,1,1,1,1,1
1,1,1,1,1,1,1,1,1,1,1
1,1,1,1,1,1,1,1,1,1,1
endlayer

layer
1,1,1,1,2,2,2,2,2,1,1
1,1,1,2,0,0,0,0,0,2,1
1,1,1,2,6,0,0,0,0,2,1
1,1,1,2,0,0,0,0,0,2,1
1,1,1,2,0,0,0,0,0,2,1
1,1,1,2,0,0,0,0,0,2,1
1,1,1,1,2,2,2,2,2,1,1
1,1,1,1,1,1,1,1,1,1,1
1,1,1,1,1,1,1,1,1,1,1
1,1,1,1,1,1,1,1,1,1,1
1,1,1,1,1,1,1,1,1,1,1
1,1,1,1,1,1,1,1,1,1,1
1,1,1,1,1,1,1,1,1,1,1
1,1,1,1,1,1,1,1,1,1,1
1,1,1,1,1,1,1,1,1,1,1
1,1,1,1,1,1,1,1,1,1,1
1,1,1,1,1,1,1,1,1,1,1
1,1,1,1,1,1,1,1,1,1,1
endlayer

layer
1,1,1,1,1,1,1,1,1,1,1
1,1,1,0,2,2,2,2,2,1,1
1,1,1,0,2,2,2,2,2,1,1
1,1,1,0,2,2,2,2,2,1,1
1,1,1,0,2,2,2,2,2,1,1
1,1,1,0,2,2,2,2,2,1,1
1,1,1,1,1,1,1,1,1,1,1
1,1,1,1,1,1,1,1,1,1,1
1,1,1,1,1,1,1,1,1,1,1
1,1,1,1,1,1,1,1,1,1,1
1,1,1,1,1,1,1,1,1,1,1
1,1,1,1,1,1,1,1,1,1,1
1,1,1,1,1,1,1,1,1,1,1
1,1,1,1,1,1,1,1,1,1,1
1,1,1,1,1,1,1,1,1,1,1
1,1,1,1,1,1,1,1,1,1,1
1,1,1,1,1,1,1,1,1,1,1
1,1,1,1,1,1,1,1,1,1,1
endlayer

layer
1,1,18,1,1,1,18,18,1,1,1
18,1,18,1,1,1,1,18,1,1,18
1,1,18,18,18,1,1,1,18,18,18
1,18,1,1,18,18,1,1,1,18,1
18,1,1,1,18,1,1,1,1,1,1
1,1,1,1,1,1,18,18,18,1,1
1,1,1,1,1,1,18,18,18,1,1
18,1,1,18,1,18,1,1,1,1,18
1,18,1,1,18,1,18,1,18,1,1
1,18,18,18,18,1,18,1,1,1,1
1,1,1,1,18,1,1,1,1,18,18
18,1,1,18,1,18,1,18,18,1,1
1,1,1,1,18,18,1,18,1,18,1
1,18,18,18,18,1,1,1,18,1,1
1,1,1,1,18,1,18,1,1,1,1
1,18,1,1,18,1,1,18,18,1,1
1,1,1,18,18,1,1,1,18,1,18
18,1,1,1,1,1,1,1,1,1,1
endlayer

layer
0,0,0,0,0,0,0,0,0,0,0
0,0,19,20,20,20,19,0,0,0,0
0,0,20,21,0,0,20,0,0,0,0
0,0,20,0,0,0,22,0,0,0,0
0,0,20,21,0,0,20,0,0,0,0
0,0,20,20,20,20,19,0,0,0,0
0,0,20,23,24,24,23,0,0,0,0
0,0,20,24,0,0,25,0,0,0,0
0,0,20,24,0,0,25,0,0,0,0
0,0,20,23,0,0,23,0,0,0,0
0,0,20,24,28,27,26,0,0,0,0
0,0,20,23,0,0,23,0,0,0,0
0,0,20,24,29,0,26,0,0,0,0
0,0,20,24,27,27,26,0,0,0,0
0,0,20,23,24,24,23,0,0,0,0
0,0,19,20,20,20,19,0,0,0,0
0,0,0,0,0,0,0,0,0,0,0
0,0,0,0,0,0,0,0,0,0,0
endlayer

layer
0,0,0,0,0,0,0,0,0,0,0
0,0,19,20,20,20,19,0,0,0,0
0,0,20,0,0,0,20,0,0,0,0
0,0,20,0,0,0,30,0,0,0,0
0,0,20,0,0,0,20,0,0,0,0
0,0,20,20,20,20,19,0,0,0,0
0,0,20,23,23,23,23,0,0,0,0
0,0,20,23,0,0,0,0,0,0,0
0,0,20,23,0,0,0,0,0,0,0
0,0,20,23,23,23,23,0,0,0,0
0,0,20,23,27,0,0,0,0,0,0
0,0,20,23,23,23,23,0,0,0,0
0,0,20,23,0,0,0,0,0,0,0
0,0,20,23,27,0,0,0,0,0,0
0,0,20,23,23,23,23,0,0,0,0
0,0,19,20,20,20,19,0,0,0,0
0,0,0,0,0,0,0,0,0,0,0
0,0,0,0,0,0,0,0,0,0,0
endlayer

layer
0,0,0,0,0,0,0,0,0,0,0
0,0,19,20,20,20,19,0,0,0,0
0,0,20,21,0,0,20,0,0,0,0
0,0,20,0,0,0,20,0,0,0,0
0,0,20,21,0,0,20,0,0,0,0
0,0,20,20,20,20,19,0,0,0,0
0,0,20,23,24,24,23,0,0,0,0
0,0,20,24,0,0,0,0,0,0,0
0,0,20,24,0,0,0,0,0,0,0
0,0,20,23,0,0,23,0,0,0,0
0,0,20,24,0,0,0,0,0,0,0
0,0,20,23,0,0,23,0,0,0,0
0,0,20,24,0,0,0,0,0,0,0
0,0,20,24,0,0,0,0,0,0,0
0,0,20,23,24,24,23,0,0,0,0
0,0,19,20,20,20,19,0,0,0,0
0,0,0,0,0,0,0,0,0,0,0
0,0,0,0,0,0,0,0,0,0,0
endlayer

layer
0,0,0,0,0,0,0,0,0,0,0
0,0,32,20,20,20,31,0,0,0,0
0,0,32,20,20,20,31,0,0,0,0
0,0,32,20,20,20,31,0,0,0,0
0,0,32,20,20,20,31,0,0,0,0
0,0,32,20,20,20,31,0,0,0,0
0,0,35,34,34,34,33,0,0,0,0
0,0,35,34,34,34,33,0,0,0,0
0,0,35,34,34,34,33,0,0,0,0
0,0,35,34,34,34,33,0,0,0,0
0,0,35,34,34,34,33,0,0,0,0
0,0,35,34,34,34,33,0,0,0,0
0,0,35,34,34,34,33,0,0,0,0
0,0,35,34,34,34,33,0,0,0,0
0,0,35,34,34,34,33,0,0,0,0
0,0,35,34,34,34,33,0,0,0,0
0,0,0,0,0,0,0,0,0,0,0
0,0,0,0,0,0,0,0,0,0,0
endlayer

layer
0,0,0,0,0,0,0,0,0,0,0
0,0,0,32,19,31,0,0,0,0,0
0,0,0,32,19,31,0,0,0,0,0
0,0,0,32,19,31,0,0,0,0,0
0,0,0,32,19,31,0,0,0,0,0
0,0,0,32,19,31,0,0,0,0,0
0,0,0,0,0,0,0,0,0,0,0
0,0,0,0,0,0,0,0,0,0,0
0,0,0,0,0,0,0,0,0,0,0
0,0,0,0,0,0,0,0,0,0,0
0,0,0,0,0,0,0,0,0,0,0
0,0,0,0,0,0,0,0,0,0,0
0,0,0,0,0,0,0,0,0,0,0
0,0,0,0,0,0,0,0,0,0,0
0,0,0,0,0,0,0,0,0,0,0
0,0,0,0,0,0,0,0,0,0,0
0,0,0,0,0,0,0,0,0,0,0
0,0,0,0,0,0,0,0,0,0,0
endlayer

layer
0,0,0,0,0,0,0,0,0,0,0
0,0,0,0,36,0,0,0,0,0,0
0,0,0,0,36,0,0,0,0,0,0
0,0,0,0,36,0,0,0,0,0,0
0,0,0,0,36,0,0,0,0,0,0
0,0,0,0,36,0,0,0,0,0,0
0,0,0,0,0,0,0,0,0,0,0
0,0,0,0,0,0,0,0,0,0,0
0,0,0,0,0,0,0,0,0,0,0
0,0,0,0,0,0,0,0,0,0,0
0,0,0,0,0,0,0,0,0,0,0
0,0,0,0,0,0,0,0,0,0,0
0,0,0,0,0,0,0,0,0,0,0
0,0,0,0,0,0,0,0,0,0,0
0,0,0,0,0,0,0,0,0,0,0
0,0,0,0,0,0,0,0,0,0,0
0,0,0,0,0,0,0,0,0,0,0
0,0,0,0,0,0,0,0,0,0,0
endlayer

