
# Created by Ruins mod version 15.0 Ingame Parser
# authoring Player: SunsOfOld

weight=100
embed_into_distance=1
acceptable_target_blocks=
unacceptable_target_blocks=flowing_water,water,flowing_lava,lava
dimensions=9,19,23
allowable_overhang=0
max_leveling=5
leveling_buffer=0
preserve_water=0
preserve_lava=0
uniqueMinDistance=1000000
preventRotation=1

rule1=0,100,minecraft:grass-0
rule2=0,100,minecraft:dirt-0
rule3=0,100,ExtrabiomesXL:planks-7
rule4=0,100,BiomesOPlenty:newBopDirt-1
rule5=0,100,minecraft:double_stone_slab-0
rule6=0,100,GardenStuff:stone_block-0
rule7=0,100,minecraft:tallgrass-1
rule8=0,100,BiomesOPlenty:foliage-11
rule9=0,100,minecraft:double_plant-2
rule10=0,100,BiomesOPlenty:logs3-2
rule11=0,100,dendrology:acemus_planks-4
rule12=0,100,dendrology:acemus_planks-14
rule13=0,100,minecraft:fence-0
rule14=0,100,IInventory;minecraft:chest;antiqueatlas:emptyAntiqueAtlas#1#0#0-5
rule15=0,100,GardenContainers:large_pot_colored-0
rule16=0,100,IInventory;minecraft:chest;harvestcraft:venisoncookedItem#8#0#0-5
rule17=0,100,VeganOption:bedStraw-0
rule18=0,100,VeganOption:bedStraw-8
rule19=0,100,IInventory;minecraft:chest;minecraft:leather_leggings#1#0#0-3
rule20=0,100,minecraft:wooden_door-3
rule21=0,100,minecraft:wooden_door-5
rule22=0,100,IInventory;minecraft:chest;minecraft:stone_sword#1#0#0-3
rule23=0,100,minecraft:wooden_door-2
rule24=0,100,minecraft:wooden_door-1
rule25=0,100,harvestcraft:sink-0
rule26=0,100,BiomesOPlenty:ivy-8
rule27=0,100,GardenCore:compost_bin-0
rule28=0,100,minecraft:fence_gate-1
rule29=0,100,BiomesOPlenty:ivy-2
rule30=0,100,minecraft:double_plant-9
rule31=0,100,minecraft:double_plant-8
rule32=0,100,BiomesOPlenty:ivy-1
rule33=0,100,IInventory;minecraft:chest;harvestcraft:beefjerkyItem#4#0#2-5
rule34=0,100,IInventory;minecraft:chest;harvestcraft:trailmixItem#6#0#0-5
rule35=0,100,IInventory;minecraft:chest;Backpack:backpack#1#0#0-3
rule36=0,100,BiomesOPlenty:ivy-4
rule37=0,100,minecraft:wooden_door-8
rule38=0,100,IInventory;minecraft:chest;minecraft:leather_boots#1#0#0-3
rule39=0,100,minecraft:double_plant-10
rule40=0,100,minecraft:double_plant-11
rule41=0,100,GardenTrees:ivy-2
rule42=0,100,GardenTrees:ivy-3
rule43=0,100,GardenTrees:ivy-4
rule44=0,100,BiomesOPlenty:woodenSingleSlab1-1

layer
1,1,1,1,1,1,1,1,1,1,1,1,1,1,1,1,1,1,1,1,1,1,1
1,2,2,2,2,2,2,2,2,2,2,2,2,2,2,2,2,2,2,2,2,2,1
1,2,2,2,2,2,2,2,2,1,1,1,1,1,2,2,2,2,2,2,2,2,1
1,2,2,3,3,3,3,3,2,1,1,1,1,1,2,3,3,3,3,3,2,2,1
1,2,2,3,3,3,3,3,2,1,1,1,1,1,2,3,3,3,3,3,2,2,1
1,2,2,3,3,3,3,3,3,4,4,4,4,4,3,3,3,3,3,3,2,2,1
1,2,2,3,3,3,3,3,2,1,1,4,1,1,2,3,3,3,3,3,2,2,1
1,2,2,3,3,3,3,3,2,1,1,4,1,1,2,3,3,3,3,3,2,2,1
1,2,2,2,2,3,2,2,2,1,1,4,1,1,2,2,2,3,2,2,2,2,1
1,2,2,3,3,3,3,3,2,1,1,4,1,1,1,1,1,4,1,1,1,2,1
1,2,2,3,3,3,3,3,2,1,1,4,1,1,1,1,1,4,1,1,1,2,1
1,2,2,3,3,3,3,3,3,4,4,4,1,1,1,4,4,4,4,4,1,2,1
1,2,2,3,3,3,3,3,2,1,1,4,1,1,1,4,5,5,5,4,1,2,1
1,2,2,3,3,3,3,3,2,1,1,4,4,4,4,4,5,6,5,4,1,2,1
1,2,2,2,2,2,2,2,2,1,1,4,1,1,1,4,5,5,5,4,1,2,1
1,2,2,4,4,4,4,4,4,4,4,4,1,1,1,4,4,4,4,4,1,2,1
1,2,2,4,4,1,1,1,1,1,1,4,1,1,1,1,1,1,1,1,1,2,1
1,2,2,2,2,2,2,2,2,2,1,1,1,2,2,2,2,2,2,2,2,2,1
1,1,1,1,1,1,1,1,1,1,1,1,1,1,1,1,1,1,1,1,1,1,1
endlayer

layer
7,9,7,7,7,7,7,9,8,9,7,8,8,7,8,7,7,7,8,7,7,7,7
9,10,11,11,11,11,11,11,11,11,11,11,11,11,11,11,11,11,11,11,11,10,7
9,11,12,12,12,12,12,12,12,7,7,13,7,7,12,12,12,12,12,12,12,11,8
7,11,12,18,17,0,0,0,12,7,13,13,13,7,12,0,16,15,14,0,12,11,7
7,11,12,0,0,0,0,0,12,7,7,7,7,7,12,0,0,0,0,19,12,11,7
0,11,12,18,17,0,0,0,21,0,0,0,0,0,20,0,0,0,0,15,12,11,7
9,11,12,0,0,0,0,0,12,8,0,0,8,7,12,0,0,0,0,22,12,11,7
7,11,12,18,17,0,0,0,12,7,7,0,7,7,12,0,0,0,0,0,12,11,8
7,11,12,12,12,0,12,12,12,8,7,0,7,7,12,12,12,23,12,12,12,11,7
7,11,12,18,17,0,0,0,12,7,7,0,7,8,7,7,8,0,0,7,7,11,7
9,11,12,0,0,0,0,0,12,7,0,0,7,7,7,7,7,0,7,7,7,11,8
7,11,12,18,17,0,0,0,24,0,0,0,7,7,7,0,0,0,0,0,7,11,9
7,11,12,0,0,0,0,0,12,7,7,0,8,9,8,0,0,0,0,0,8,11,7
9,11,12,18,17,0,0,0,12,7,7,0,0,0,0,0,0,0,0,0,7,11,7
7,11,12,12,12,12,12,12,12,8,8,0,7,7,7,0,0,0,0,0,7,11,7
9,11,25,0,0,0,0,0,0,0,0,0,8,7,7,0,0,0,0,0,7,11,7
7,11,27,0,0,7,7,26,7,7,0,0,7,7,0,7,8,7,7,8,7,11,7
7,10,11,11,11,11,11,11,11,11,13,28,13,11,11,11,11,11,11,11,11,10,7
7,9,8,8,9,9,8,8,9,8,29,0,7,7,7,0,7,7,7,7,7,7,7
endlayer

layer
0,30,26,0,26,0,26,30,26,30,26,0,26,0,26,0,26,0,26,0,26,0,0
31,10,11,11,11,11,11,11,11,11,11,11,11,11,11,11,11,11,11,11,11,10,0
31,11,12,12,12,12,12,12,12,0,0,0,29,0,12,12,12,12,12,12,12,11,0
0,11,12,0,0,0,0,0,12,32,0,13,0,0,12,0,34,0,33,0,12,11,32
36,11,12,0,0,0,0,0,12,32,0,0,0,0,12,0,0,0,0,35,12,11,0
0,11,12,0,0,0,0,0,37,0,0,0,0,0,37,0,0,0,0,0,12,11,32
31,11,12,0,0,0,0,0,12,0,0,0,0,0,12,0,0,0,0,38,12,11,0
0,11,12,0,0,0,0,0,12,0,0,0,0,36,12,0,0,0,0,0,12,11,32
36,11,12,12,12,0,12,12,12,0,0,0,0,36,12,12,12,37,12,12,12,11,0
0,11,12,0,0,0,0,0,12,32,0,0,0,0,0,0,0,0,0,0,0,11,32
31,11,12,0,0,0,0,0,12,0,0,0,0,0,0,0,0,0,0,0,0,11,0
0,11,12,0,0,0,0,0,37,0,0,0,0,0,0,0,0,0,0,0,0,11,39
36,11,12,0,0,0,0,0,12,0,0,0,0,40,0,0,0,0,0,0,0,11,0
31,11,12,0,0,0,0,0,12,32,0,0,0,0,0,0,0,0,0,0,0,11,32
36,11,12,12,12,12,12,12,12,0,0,0,0,0,0,0,0,0,0,0,0,11,0
31,11,0,0,0,0,0,0,0,0,0,0,0,0,0,0,0,0,0,0,0,11,32
36,11,0,0,0,26,0,26,0,0,0,0,0,0,0,26,26,0,0,0,0,11,0
0,10,11,11,11,11,11,11,11,11,13,28,13,11,11,11,11,11,11,11,11,10,0
0,31,0,29,40,40,29,29,40,0,29,0,29,0,29,0,29,0,0,29,0,0,0
endlayer

layer
0,0,26,0,26,0,26,0,26,0,26,0,26,0,26,0,26,0,26,0,26,0,0
0,10,11,11,11,11,11,11,11,11,11,11,11,11,11,11,11,11,11,11,11,10,0
36,11,12,12,12,12,12,12,12,42,41,41,29,0,12,12,12,12,12,12,12,11,0
0,11,12,0,0,0,0,0,12,32,0,13,0,0,12,0,0,0,0,0,12,11,32
36,11,12,0,0,0,0,0,12,32,0,0,0,0,12,0,0,0,0,0,12,11,0
0,11,12,0,0,0,0,0,12,0,0,0,0,0,12,0,0,0,0,0,12,11,32
36,11,12,0,0,0,0,0,12,0,0,0,0,0,12,0,0,0,0,0,12,11,0
0,11,12,0,0,0,0,0,12,0,0,0,0,36,12,0,0,0,0,0,12,11,32
36,11,12,12,12,12,12,12,12,0,0,0,0,36,12,12,12,12,12,12,12,11,0
0,11,12,0,0,0,0,0,12,32,0,0,0,0,41,41,41,0,41,41,41,11,32
36,11,12,0,0,0,0,0,12,0,0,0,0,0,0,0,0,0,0,0,0,11,0
0,11,12,0,0,0,0,0,12,0,0,0,0,0,0,0,0,0,0,0,0,11,32
36,11,12,0,0,0,0,0,12,0,0,0,0,0,0,0,0,0,0,0,43,11,0
0,11,12,0,0,0,0,0,12,32,0,0,0,0,0,0,0,0,0,0,43,11,32
36,11,12,12,12,12,12,12,12,0,0,0,0,0,0,0,0,0,0,0,43,11,0
36,11,0,0,41,41,41,41,41,0,0,0,0,0,0,0,0,0,0,0,43,11,32
36,11,0,0,0,26,0,26,0,0,0,0,0,0,0,26,26,0,0,0,43,11,0
0,10,11,11,11,11,11,11,11,11,12,12,12,11,11,11,11,11,11,11,11,10,0
0,0,0,29,0,29,29,29,0,0,29,0,29,0,29,0,29,0,0,29,0,0,0
endlayer

layer
0,0,0,0,0,0,0,0,0,0,0,0,0,0,0,0,0,0,0,0,0,0,0
0,10,0,0,0,0,0,0,0,0,0,0,0,0,0,0,0,0,0,0,0,10,0
0,0,44,44,44,44,44,44,44,0,0,0,0,0,44,44,44,44,44,44,44,0,0
0,0,44,44,44,44,44,44,44,0,0,13,0,0,44,44,44,44,44,44,44,0,0
0,0,44,44,44,44,44,44,44,0,0,0,0,0,44,44,44,44,44,44,44,0,0
0,0,44,44,44,44,44,44,44,0,0,0,0,0,44,44,44,44,44,44,44,0,0
0,0,44,44,44,44,44,44,44,0,0,0,0,0,44,44,44,44,44,44,44,0,0
0,0,44,44,44,44,44,44,44,0,0,0,0,0,44,44,44,44,44,44,44,0,0
0,0,44,44,44,44,44,44,44,0,0,0,0,0,44,44,44,44,44,44,44,0,0
0,0,44,44,44,44,44,44,44,0,0,0,0,0,0,0,0,0,0,0,0,0,0
0,0,44,44,44,44,44,44,44,0,0,0,0,0,0,0,0,0,0,0,0,0,0
0,0,44,44,44,44,44,44,44,0,0,0,0,0,0,0,0,0,0,0,0,0,0
0,0,44,44,44,44,44,44,44,0,0,0,0,0,0,0,0,0,0,0,0,0,0
0,0,44,44,44,44,44,44,44,0,0,0,0,0,0,0,0,0,0,0,0,0,0
0,0,44,44,44,44,44,44,44,0,0,0,0,0,0,0,0,0,0,0,0,0,0
0,0,0,0,0,0,0,0,0,0,0,0,0,0,0,0,0,0,0,0,0,0,0
0,0,0,0,0,0,0,0,0,0,0,0,0,0,0,0,0,0,0,0,0,0,0
0,10,0,0,0,0,0,0,0,0,0,0,0,0,0,0,0,0,0,0,0,10,0
0,0,0,0,0,0,0,0,0,0,0,0,0,0,0,0,0,0,0,0,0,0,0
endlayer

layer
0,0,0,0,0,0,0,0,0,0,0,0,0,0,0,0,0,0,0,0,0,0,0
0,0,0,0,0,0,0,0,0,0,0,0,0,0,0,0,0,0,0,0,0,0,0
0,0,0,0,0,0,0,0,0,0,0,0,0,0,0,0,0,0,0,0,0,0,0
0,0,0,0,0,0,0,0,0,0,0,13,0,0,0,0,0,0,0,0,0,0,0
0,0,0,0,0,0,0,0,0,0,0,0,0,0,0,0,0,0,0,0,0,0,0
0,0,0,0,0,0,0,0,0,0,0,0,0,0,0,0,0,0,0,0,0,0,0
0,0,0,0,0,0,0,0,0,0,0,0,0,0,0,0,0,0,0,0,0,0,0
0,0,0,0,0,0,0,0,0,0,0,0,0,0,0,0,0,0,0,0,0,0,0
0,0,0,0,0,0,0,0,0,0,0,0,0,0,0,0,0,0,0,0,0,0,0
0,0,0,0,0,0,0,0,0,0,0,0,0,0,0,0,0,0,0,0,0,0,0
0,0,0,0,0,0,0,0,0,0,0,0,0,0,0,0,0,0,0,0,0,0,0
0,0,0,0,0,0,0,0,0,0,0,0,0,0,0,0,0,0,0,0,0,0,0
0,0,0,0,0,0,0,0,0,0,0,0,0,0,0,0,0,0,0,0,0,0,0
0,0,0,0,0,0,0,0,0,0,0,0,0,0,0,0,0,0,0,0,0,0,0
0,0,0,0,0,0,0,0,0,0,0,0,0,0,0,0,0,0,0,0,0,0,0
0,0,0,0,0,0,0,0,0,0,0,0,0,0,0,0,0,0,0,0,0,0,0
0,0,0,0,0,0,0,0,0,0,0,0,0,0,0,0,0,0,0,0,0,0,0
0,0,0,0,0,0,0,0,0,0,0,0,0,0,0,0,0,0,0,0,0,0,0
0,0,0,0,0,0,0,0,0,0,0,0,0,0,0,0,0,0,0,0,0,0,0
endlayer

layer
0,0,0,0,0,0,0,0,0,0,0,0,0,0,0,0,0,0,0,0,0,0,0
0,0,0,0,0,0,0,0,0,0,0,0,0,0,0,0,0,0,0,0,0,0,0
0,0,0,0,0,0,0,0,0,0,0,0,0,0,0,0,0,0,0,0,0,0,0
0,0,0,0,0,0,0,0,0,0,0,13,0,0,0,0,0,0,0,0,0,0,0
0,0,0,0,0,0,0,0,0,0,0,0,0,0,0,0,0,0,0,0,0,0,0
0,0,0,0,0,0,0,0,0,0,0,0,0,0,0,0,0,0,0,0,0,0,0
0,0,0,0,0,0,0,0,0,0,0,0,0,0,0,0,0,0,0,0,0,0,0
0,0,0,0,0,0,0,0,0,0,0,0,0,0,0,0,0,0,0,0,0,0,0
0,0,0,0,0,0,0,0,0,0,0,0,0,0,0,0,0,0,0,0,0,0,0
0,0,0,0,0,0,0,0,0,0,0,0,0,0,0,0,0,0,0,0,0,0,0
0,0,0,0,0,0,0,0,0,0,0,0,0,0,0,0,0,0,0,0,0,0,0
0,0,0,0,0,0,0,0,0,0,0,0,0,0,0,0,0,0,0,0,0,0,0
0,0,0,0,0,0,0,0,0,0,0,0,0,0,0,0,0,0,0,0,0,0,0
0,0,0,0,0,0,0,0,0,0,0,0,0,0,0,0,0,0,0,0,0,0,0
0,0,0,0,0,0,0,0,0,0,0,0,0,0,0,0,0,0,0,0,0,0,0
0,0,0,0,0,0,0,0,0,0,0,0,0,0,0,0,0,0,0,0,0,0,0
0,0,0,0,0,0,0,0,0,0,0,0,0,0,0,0,0,0,0,0,0,0,0
0,0,0,0,0,0,0,0,0,0,0,0,0,0,0,0,0,0,0,0,0,0,0
0,0,0,0,0,0,0,0,0,0,0,0,0,0,0,0,0,0,0,0,0,0,0
endlayer

layer
0,0,0,0,0,0,0,0,0,0,0,0,0,0,0,0,0,0,0,0,0,0,0
0,0,0,0,0,0,0,0,0,0,0,0,0,0,0,0,0,0,0,0,0,0,0
0,0,0,0,0,0,0,0,0,0,0,0,0,0,0,0,0,0,0,0,0,0,0
0,0,0,0,0,0,0,0,0,0,0,13,0,0,0,0,0,0,0,0,0,0,0
0,0,0,0,0,0,0,0,0,0,0,0,0,0,0,0,0,0,0,0,0,0,0
0,0,0,0,0,0,0,0,0,0,0,0,0,0,0,0,0,0,0,0,0,0,0
0,0,0,0,0,0,0,0,0,0,0,0,0,0,0,0,0,0,0,0,0,0,0
0,0,0,0,0,0,0,0,0,0,0,0,0,0,0,0,0,0,0,0,0,0,0
0,0,0,0,0,0,0,0,0,0,0,0,0,0,0,0,0,0,0,0,0,0,0
0,0,0,0,0,0,0,0,0,0,0,0,0,0,0,0,0,0,0,0,0,0,0
0,0,0,0,0,0,0,0,0,0,0,0,0,0,0,0,0,0,0,0,0,0,0
0,0,0,0,0,0,0,0,0,0,0,0,0,0,0,0,0,0,0,0,0,0,0
0,0,0,0,0,0,0,0,0,0,0,0,0,0,0,0,0,0,0,0,0,0,0
0,0,0,0,0,0,0,0,0,0,0,0,0,0,0,0,0,0,0,0,0,0,0
0,0,0,0,0,0,0,0,0,0,0,0,0,0,0,0,0,0,0,0,0,0,0
0,0,0,0,0,0,0,0,0,0,0,0,0,0,0,0,0,0,0,0,0,0,0
0,0,0,0,0,0,0,0,0,0,0,0,0,0,0,0,0,0,0,0,0,0,0
0,0,0,0,0,0,0,0,0,0,0,0,0,0,0,0,0,0,0,0,0,0,0
0,0,0,0,0,0,0,0,0,0,0,0,0,0,0,0,0,0,0,0,0,0,0
endlayer

layer
0,0,0,0,0,0,0,0,0,0,0,0,0,0,0,0,0,0,0,0,0,0,0
0,0,0,0,0,0,0,0,0,0,0,0,0,0,0,0,0,0,0,0,0,0,0
0,0,0,0,0,0,0,0,0,0,0,0,0,0,0,0,0,0,0,0,0,0,0
0,0,0,0,0,0,0,0,0,0,0,13,0,0,0,0,0,0,0,0,0,0,0
0,0,0,0,0,0,0,0,0,0,0,0,0,0,0,0,0,0,0,0,0,0,0
0,0,0,0,0,0,0,0,0,0,0,0,0,0,0,0,0,0,0,0,0,0,0
0,0,0,0,0,0,0,0,0,0,0,0,0,0,0,0,0,0,0,0,0,0,0
0,0,0,0,0,0,0,0,0,0,0,0,0,0,0,0,0,0,0,0,0,0,0
0,0,0,0,0,0,0,0,0,0,0,0,0,0,0,0,0,0,0,0,0,0,0
0,0,0,0,0,0,0,0,0,0,0,0,0,0,0,0,0,0,0,0,0,0,0
0,0,0,0,0,0,0,0,0,0,0,0,0,0,0,0,0,0,0,0,0,0,0
0,0,0,0,0,0,0,0,0,0,0,0,0,0,0,0,0,0,0,0,0,0,0
0,0,0,0,0,0,0,0,0,0,0,0,0,0,0,0,0,0,0,0,0,0,0
0,0,0,0,0,0,0,0,0,0,0,0,0,0,0,0,0,0,0,0,0,0,0
0,0,0,0,0,0,0,0,0,0,0,0,0,0,0,0,0,0,0,0,0,0,0
0,0,0,0,0,0,0,0,0,0,0,0,0,0,0,0,0,0,0,0,0,0,0
0,0,0,0,0,0,0,0,0,0,0,0,0,0,0,0,0,0,0,0,0,0,0
0,0,0,0,0,0,0,0,0,0,0,0,0,0,0,0,0,0,0,0,0,0,0
0,0,0,0,0,0,0,0,0,0,0,0,0,0,0,0,0,0,0,0,0,0,0
endlayer

