
# Created by Ruins mod version 15.0 Ingame Parser
# authoring Player: SunsOfOld

weight=100
embed_into_distance=6
acceptable_target_blocks=
unacceptable_target_blocks=flowing_water,water,flowing_lava,lava
dimensions=10,21,8
allowable_overhang=0
max_leveling=5
leveling_buffer=0
preserve_water=1
preserve_lava=0
uniqueMinDistance=1000000
preventRotation=1
uniqueMinDistance=1000000
preventRotation=1

rule1=0,100,preserveBlock
rule2=0,100,minecraft:bedrock-0
rule3=0,100,minecraft:redstone_wire-7
rule4=0,100,minecraft:unpowered_repeater-0
rule5=0,100,minecraft:unlit_redstone_torch-2
rule6=0,100,minecraft:powered_repeater-2
rule7=0,100,CommandBlock:/testfor @p[r=16]:@
rule8=0,100,minecraft:redstone_wire-6
rule9=0,100,minecraft:unpowered_comparator-1
rule10=0,100,minecraft:redstone_wire-0
rule11=0,100,minecraft:unpowered_repeater-1
rule12=0,100,CommandBlock:/setblock ~ ~ ~ 152:@
rule13=0,100,CommandBlock:/setblock ~0 ~8 ~0 mob_spawner 0 replace {SpawnCount:1,SpawnRange:24,maxNearbyEntities:8,Delay:20,MinSpawnDelay:60,MaxSpawnDelay:120,EntityId:Spider,SpawnData:{ActiveEffects:[{Id:14,Amplifier:1,Duration:999999}]}}:@
rule14=0,100,dendrology:logs0-0
rule15=0,100,dendrology:sslab1-12
rule16=0,100,GardenTrees:thin_log-1
rule17=0,100,dendrology:logs0-8
rule18=0,100,dendrology:logs0-4
rule19=0,100,dendrology:sslab1-4
rule20=0,100,minecraft:gravel-0
rule21=0,100,dendrology:sslab1-3
rule22=0,100,dendrology:dslab1-4
rule23=0,100,chisel:glowstone-6
rule24=0,100,minecraft:sand-0
rule25=0,100,ChestGenHook:dungeonChest:5-5
rule26=0,100,dendrology:dslab1-3
rule27=0,100,GardenStuff:lattice-3
rule28=0,100,dendrology:sslab1-11
rule29=0,100,minecraft:log-1

layer
1,1,1,1,1,1,1,1
1,1,1,1,1,1,1,1
1,1,1,1,1,1,1,1
1,1,1,1,1,1,1,1
1,1,1,1,2,1,1,1
1,1,1,1,1,1,1,1
1,1,1,1,1,1,1,1
1,1,1,1,1,1,1,1
1,1,1,1,1,1,1,1
1,1,1,1,1,1,1,1
1,1,1,1,1,1,1,1
1,1,1,1,1,1,1,1
1,1,1,1,1,1,1,1
1,1,1,1,1,1,1,1
1,1,1,1,1,1,1,1
1,1,1,1,1,1,1,1
1,1,1,1,1,1,1,1
1,1,1,1,1,1,1,1
1,1,1,1,1,1,1,1
1,1,1,1,1,1,1,1
1,1,1,1,1,1,1,1
endlayer

layer
1,1,1,1,1,1,1,1
1,1,1,1,1,1,1,1
1,1,1,1,1,1,1,1
1,1,2,2,2,2,2,1
1,1,2,2,0,2,2,1
1,1,2,2,2,2,2,1
1,1,2,2,2,2,2,1
1,1,2,2,2,2,2,1
1,1,2,2,2,2,2,1
1,1,1,1,1,1,1,1
1,1,1,1,1,1,1,1
1,1,1,1,1,1,1,1
1,1,1,1,1,1,1,1
1,1,1,1,1,1,1,1
1,1,1,1,1,1,1,1
1,1,1,1,1,1,1,1
1,1,1,1,1,1,1,1
1,1,1,1,1,1,1,1
1,1,1,1,1,1,1,1
1,1,1,1,1,1,1,1
1,1,1,1,1,1,1,1
endlayer

layer
1,1,1,1,1,1,1,1
1,1,1,1,1,1,1,1
1,2,2,2,2,2,2,1
1,2,0,0,0,0,0,2
1,2,7,6,5,4,3,2
1,2,9,0,2,6,8,2
1,2,11,0,0,0,10,2
1,2,10,0,0,0,10,2
1,2,10,13,12,4,10,2
1,1,2,2,2,2,2,2
1,1,1,1,1,1,1,1
1,1,1,1,1,1,1,1
1,1,1,1,1,1,1,1
1,1,1,1,1,1,1,1
1,1,1,1,1,1,1,1
1,1,1,1,1,1,1,1
1,1,1,1,1,1,1,1
1,1,1,1,1,1,1,1
1,1,1,1,1,1,1,1
1,1,1,1,1,1,1,1
1,1,1,1,1,1,1,1
endlayer

layer
1,1,1,1,1,1,1,1
1,1,1,1,1,1,1,1
1,2,2,2,2,2,2,1
1,2,0,0,0,0,0,2
1,2,0,0,0,0,0,2
1,2,0,0,2,0,0,2
1,2,0,0,0,0,0,2
1,2,0,0,0,0,0,2
1,2,0,10,10,0,0,2
1,1,2,2,2,2,2,2
1,1,1,1,1,1,1,1
1,1,1,1,1,1,1,1
1,1,1,1,1,1,1,1
1,1,1,1,1,1,1,1
1,1,1,1,1,1,1,1
1,1,1,1,1,1,1,1
1,1,1,1,1,1,1,1
1,1,1,1,1,1,1,1
1,1,1,1,1,1,1,1
1,1,1,1,1,1,1,1
1,1,1,1,1,1,1,1
endlayer

layer
1,1,1,1,1,1,1,1
1,1,1,1,1,1,1,1
1,1,1,1,1,1,1,1
1,1,2,2,2,2,2,1
1,1,2,2,2,2,2,1
1,1,2,2,2,2,2,1
1,1,2,2,2,2,2,1
1,1,2,2,2,2,2,1
1,1,2,2,2,2,2,1
1,1,1,1,1,1,1,1
1,1,1,1,1,1,1,1
1,1,1,1,1,1,1,1
1,1,1,1,1,1,1,1
1,1,1,1,1,1,1,1
1,0,0,1,1,1,1,1
1,1,1,1,1,1,1,1
1,1,1,1,1,1,1,1
1,1,1,1,1,1,1,1
1,1,1,1,1,1,1,1
1,1,1,1,1,1,1,1
1,1,1,1,1,1,1,1
endlayer

layer
1,1,1,1,14,1,1,1
1,1,1,1,1,1,1,1
1,1,1,1,1,1,1,1
1,1,1,1,1,1,1,1
1,1,1,1,1,1,1,1
1,1,1,1,1,1,1,1
1,1,1,1,1,1,1,1
1,1,1,1,1,1,1,1
1,1,1,1,1,1,1,1
15,1,1,1,1,1,1,1
1,17,17,17,17,17,17,16
1,1,1,1,1,1,1,1
1,1,1,1,1,1,1,1
1,1,1,1,1,1,1,1
1,1,1,1,1,1,1,1
1,1,1,1,1,1,1,1
1,1,1,1,1,1,1,1
1,1,1,1,1,1,1,1
1,1,1,1,1,1,1,1
1,1,1,1,1,1,1,1
1,1,1,1,1,1,1,1
endlayer

layer
0,18,0,0,0,0,0,0
0,18,0,0,0,18,0,0
0,18,20,19,19,18,0,0
0,18,19,19,19,18,0,0
0,18,22,21,19,19,0,0
0,18,23,19,19,18,0,0
0,18,24,21,19,18,0,0
19,24,24,19,20,18,0,0
19,20,19,24,25,18,0,0
0,18,19,19,21,18,0,0
19,18,19,15,19,15,14,16
19,21,26,15,0,22,18,17
18,1,28,15,21,19,28,27
18,17,21,28,0,19,21,18
0,18,21,21,0,19,21,27
0,0,17,17,17,28,17,27
0,0,27,18,18,18,27,0
0,0,0,27,18,27,0,0
0,0,0,0,0,0,0,0
0,0,0,0,0,0,0,0
0,0,0,0,0,0,0,0
endlayer

layer
0,0,0,0,0,0,0,0
0,0,0,0,0,0,0,0
0,27,0,0,0,0,18,0
0,16,0,0,0,0,18,0
0,27,0,0,0,0,18,0
0,16,28,0,0,0,19,0
0,27,21,0,0,0,15,0
0,16,0,0,0,0,18,0
0,0,0,0,29,0,18,0
0,27,0,0,0,0,18,0
0,27,0,0,0,0,19,16
0,19,0,0,0,0,19,15
0,19,0,0,0,0,21,0
0,0,0,0,0,0,0,0
0,0,0,0,0,0,0,0
0,0,29,0,0,0,29,0
0,0,0,29,0,29,0,0
0,0,0,0,29,0,0,0
0,0,0,0,0,0,0,0
0,0,0,0,0,0,0,0
0,0,0,0,0,0,0,0
endlayer

layer
0,0,0,0,0,0,0,0
0,0,0,0,0,0,0,0
0,27,18,0,0,0,0,18
27,27,18,0,0,0,0,18
18,27,0,0,0,0,0,18
18,27,0,0,0,0,0,18
18,27,0,0,0,0,0,18
18,27,0,0,0,0,0,18
18,0,0,0,29,0,0,18
18,27,0,0,0,0,0,18
0,0,0,0,0,0,0,21
0,0,0,0,0,0,0,0
0,0,0,0,0,0,0,0
0,0,0,0,0,0,0,0
0,0,0,0,0,0,0,0
0,0,0,0,0,0,0,0
0,0,0,0,0,0,0,0
0,0,0,0,0,0,0,0
0,0,0,0,0,0,0,0
0,0,0,0,0,0,0,0
0,0,0,0,0,0,0,0
endlayer

layer
0,0,0,0,0,0,0,0
0,0,0,0,0,0,0,0
0,0,0,0,0,0,0,16
0,0,0,0,0,0,0,27
0,0,0,0,0,0,0,16
0,0,0,0,0,0,0,27
0,0,0,0,0,0,0,16
0,0,0,0,0,0,0,27
0,0,0,0,25,0,0,16
0,0,0,0,0,0,0,0
0,0,0,0,0,0,0,0
0,0,0,0,0,0,0,0
0,0,0,0,0,0,0,0
0,0,0,0,0,0,0,0
0,0,0,0,0,0,0,0
0,0,0,0,0,0,0,0
0,0,0,0,0,0,0,0
0,0,0,0,0,0,0,0
0,0,0,0,0,0,0,0
0,0,0,0,0,0,0,0
0,0,0,0,0,0,0,0
endlayer

