
# Created by Ruins mod version 14.9 Ingame Parser
# authoring Player: SunsOfOld

weight=100
embed_into_distance=0
acceptable_target_blocks=
unacceptable_target_blocks=flowing_water,water,flowing_lava,lava
dimensions=6,12,8
allowable_overhang=0
max_leveling=4
leveling_buffer=0
preserve_water=0
preserve_lava=0
uniqueMinDistance=1000000
preventRotation=1

rule1=0,100,preserveBlock
rule2=0,100,minecraft:glass-0
rule3=0,100,chisel:concrete-9
rule4=0,100,ExtrabiomesXL:door_rainboweucalyptus-1
rule5=0,100,ExtrabiomesXL:door_rainboweucalyptus-3
rule6=0,100,ExtrabiomesXL:door_rainboweucalyptus-9
rule7=0,100,ExtrabiomesXL:door_rainboweucalyptus-8

layer
1,3,2,2,1,1,1,1
1,3,0,0,2,1,1,1
1,3,0,0,0,2,1,1
1,3,0,0,0,2,1,1
3,3,0,0,0,0,2,1
5,4,0,0,0,0,0,2
5,4,0,0,0,0,0,2
3,3,0,0,0,0,2,1
1,3,0,0,0,2,1,1
1,3,0,0,0,2,1,1
1,3,0,0,2,1,1,1
1,3,2,2,1,1,1,1
endlayer

layer
1,3,2,2,1,1,1,1
1,3,0,0,2,1,1,1
1,3,0,0,0,2,1,1
1,3,0,0,0,2,1,1
3,3,0,0,0,0,2,1
7,6,0,0,0,0,2,1
6,7,0,0,0,0,2,1
3,3,0,0,0,0,2,1
1,3,0,0,0,2,1,1
1,3,0,0,0,2,1,1
1,3,0,0,2,1,1,1
1,3,2,2,1,1,1,1
endlayer

layer
1,1,1,1,1,1,1,1
1,3,2,2,1,1,1,1
1,3,0,0,2,1,1,1
1,3,0,0,0,2,1,1
1,3,0,0,0,2,1,1
3,3,0,0,0,2,1,1
3,3,0,0,0,2,1,1
1,3,0,0,0,2,1,1
1,3,0,0,0,2,1,1
1,3,0,0,2,1,1,1
1,3,2,2,1,1,1,1
1,1,1,1,1,1,1,1
endlayer

layer
1,1,1,1,1,1,1,1
1,1,1,1,1,1,1,1
1,3,2,2,1,1,1,1
1,3,0,0,2,1,1,1
1,3,0,0,0,1,1,1
1,3,0,0,0,2,1,1
1,3,0,0,0,2,1,1
1,3,0,0,0,2,1,1
1,3,0,0,2,1,1,1
1,3,2,2,1,1,1,1
1,1,1,1,1,1,1,1
1,1,1,1,1,1,1,1
endlayer

layer
1,1,1,1,1,1,1,1
1,1,1,1,1,1,1,1
1,1,1,1,1,1,1,1
1,3,2,2,1,1,1,1
1,3,0,0,2,1,1,1
1,3,0,0,2,1,1,1
1,3,0,0,2,1,1,1
1,3,0,0,2,1,1,1
1,3,2,2,1,1,1,1
1,1,1,1,1,1,1,1
1,1,1,1,1,1,1,1
1,1,1,1,1,1,1,1
endlayer

layer
1,1,1,1,1,1,1,1
1,1,1,1,1,1,1,1
1,1,1,1,1,1,1,1
1,1,1,1,1,1,1,1
1,3,2,2,1,1,1,1
1,3,2,2,1,1,1,1
1,3,2,2,1,1,1,1
1,3,2,2,1,1,1,1
1,1,1,1,1,1,1,1
1,1,1,1,1,1,1,1
1,1,1,1,1,1,1,1
1,1,1,1,1,1,1,1
endlayer

