
# Created by Ruins mod version 14.9 Ingame Parser
# authoring Player: SunsOfOld

weight=100
embed_into_distance=2
acceptable_target_blocks=
unacceptable_target_blocks=flowing_water,water,flowing_lava,lava
dimensions=12,11,10
allowable_overhang=0
max_leveling=4
leveling_buffer=0
preserve_water=0
preserve_lava=0
uniqueMinDistance=1000000
preventRotation=1

rule1=0,100,preserveBlock
rule2=0,100,BiomesOPlenty:newBopDirt-2
rule3=0,100,minecraft:sand-0
rule4=0,100,chisel:fantasyblock2-14
rule5=0,100,BiomesOPlenty:newBopDirt-3
rule6=0,100,BiomesOPlenty:newBopDirt-0
rule7=0,100,chisel:glowstone-4
rule8=0,100,BiomesOPlenty:plants-3
rule9=0,100,ExtrabiomesXL:grass-0
rule10=0,100,plantmegapack:grassSeaOats-0
rule11=0,100,plantmegapack:leafyDustyMiller-0
rule12=0,100,ExtrabiomesXL:leaves_4-15
rule13=0,100,ExtrabiomesXL:log1-2
rule14=0,100,plantmegapack:grassPrairie-0
rule15=0,100,plantmegapack:flowerMediterraneanSeaHolly-0
rule16=0,100,ExtrabiomesXL:leaves_4-7
rule17=0,100,GardenStuff:lattice-0
rule18=0,100,chisel:fantasyblock2-15
rule19=0,100,chisel:fantasyblock2-13
rule20=0,100,BiomesOPlenty:woodenSingleSlab1-6
rule21=0,100,ExtrabiomesXL:log1-6
rule22=0,100,ExtrabiomesXL:log1-10
rule23=0,100,ExtrabiomesXL:woodslab-15
rule24=0,100,ExtrabiomesXL:woodslab-7
rule25=0,100,ExtrabiomesXL:double_woodslab-7
rule26=0,100,IInventory;minecraft:chest;harvestcraft:saltItem#24#0#2+harvestcraft:snapperrawItem#5#0#5+ExtrabiomesXL:flower1#8#3#7+harvestcraft:seaweedItem#7#0#9+GardenContainers:pottery_pattern#1#5#13+harvestcraft:tilapiarawItem#7#0#17+ExtrabiomesXL:flower1#7#3#19+harvestcraft:walleyerawItem#7#0#21+harvestcraft:cranberryItem#8#0#24-4

layer
1,1,1,1,1,1,1,1,1,1
1,1,1,1,1,1,1,1,1,1
1,1,1,1,1,1,1,1,1,1
1,1,1,1,1,1,1,1,1,1
1,1,1,1,1,1,1,1,1,1
1,1,1,1,1,1,1,1,1,1
1,1,1,1,1,1,1,1,1,1
1,1,1,1,1,1,1,1,1,1
1,1,1,1,1,1,1,1,1,1
1,1,1,1,1,1,1,1,1,1
1,1,1,1,1,1,1,1,1,1
endlayer

layer
3,2,3,1,2,1,4,3,2,1
2,3,5,2,3,4,1,5,1,2
1,5,3,2,4,2,5,2,2,3
2,3,5,1,5,4,2,6,6,5
1,5,1,6,4,4,4,5,5,3
1,2,5,6,4,7,4,6,2,5
5,3,6,6,1,4,4,6,5,1
1,5,5,1,6,6,6,1,2,3
1,2,3,2,2,6,5,6,5,2
2,1,2,1,3,5,2,3,2,1
2,5,1,1,2,1,3,2,3,2
endlayer

layer
8,9,8,0,9,0,0,8,0,0
0,0,9,11,8,0,0,9,0,10
0,0,8,10,0,10,11,10,9,8
9,8,11,13,0,0,9,13,12,9
0,0,0,14,0,12,0,10,0,8
0,9,10,16,4,12,16,15,0,9
11,8,12,12,4,4,4,16,10,0
0,0,10,13,12,12,12,13,12,8
0,9,8,11,10,12,15,12,10,0
9,0,9,0,8,14,9,8,0,0
14,11,0,0,9,0,0,0,8,9
endlayer

layer
0,0,0,0,0,0,0,0,0,0
0,0,0,0,0,0,0,0,0,0
0,0,0,0,0,0,0,0,0,0
0,0,0,13,0,0,0,13,0,0
0,0,0,0,0,0,0,0,0,0
0,0,0,0,0,12,0,0,0,0
0,0,0,12,4,4,4,12,0,0
0,0,0,13,0,12,12,13,0,0
0,0,0,0,0,0,0,0,0,0
0,0,0,0,0,0,0,0,0,0
0,0,0,0,0,0,0,0,0,0
endlayer

layer
0,0,0,0,0,0,0,0,0,0
0,0,0,0,0,0,0,0,0,0
0,0,0,17,0,0,0,17,0,0
0,0,17,13,17,17,17,13,17,0
0,0,0,17,0,0,0,17,0,0
0,0,0,17,0,0,0,17,0,0
0,0,0,17,0,4,18,17,0,0
0,0,17,13,17,17,17,13,17,0
0,0,0,17,0,0,0,17,0,0
0,0,0,0,0,0,0,0,0,0
0,0,0,0,0,0,0,0,0,0
endlayer

layer
0,0,0,0,0,0,0,0,0,0
0,0,0,0,0,0,0,0,0,0
0,0,0,0,0,0,0,0,0,0
0,0,0,13,0,0,0,13,0,0
0,0,0,0,0,0,0,0,0,0
0,0,0,0,0,0,0,0,0,0
0,0,0,0,0,0,4,12,12,0
0,0,0,13,12,0,0,13,0,0
0,0,0,0,0,0,0,0,0,0
0,0,0,0,0,0,0,0,0,0
0,0,0,0,0,0,0,0,0,0
endlayer

layer
0,0,0,0,0,0,0,0,0,0
0,0,0,0,0,0,0,0,0,0
0,0,0,0,0,0,0,0,0,0
0,0,0,13,19,19,19,13,0,0
0,0,0,19,20,20,20,19,0,0
0,0,0,19,20,20,20,19,0,0
0,0,0,19,0,0,0,19,0,0
0,0,0,13,19,19,19,13,12,0
0,0,0,0,0,0,0,0,0,0
0,0,0,0,0,0,0,0,0,0
0,0,0,0,0,0,0,0,0,0
endlayer

layer
0,0,0,0,0,0,0,0,0,0
0,0,0,0,0,0,0,0,0,0
0,0,0,0,0,0,0,0,0,0
0,0,0,13,0,0,0,13,0,0
0,0,0,0,0,0,0,0,0,0
0,0,0,0,0,0,0,0,0,0
0,0,0,0,0,0,0,0,0,0
0,0,0,13,0,0,0,13,0,0
0,0,0,0,0,0,0,0,0,0
0,0,0,0,0,0,0,0,0,0
0,0,0,0,0,0,0,0,0,0
endlayer

layer
0,0,0,0,0,0,0,0,0,0
0,0,0,0,0,0,0,0,0,0
0,0,0,0,0,0,0,0,0,0
0,0,0,13,0,0,0,13,0,0
0,0,0,0,0,0,0,0,0,0
0,0,0,0,0,0,0,0,0,0
0,0,0,0,0,0,0,0,0,0
0,0,0,13,0,0,0,13,0,0
0,0,0,0,0,0,0,0,0,0
0,0,0,0,0,0,0,0,0,0
0,0,0,0,0,0,0,0,0,0
endlayer

layer
0,0,0,0,0,0,0,0,0,0
0,0,0,0,0,0,0,0,0,0
0,0,0,21,0,0,0,21,0,0
0,0,0,22,22,22,22,22,0,0
0,0,23,21,0,0,0,21,23,0
0,0,23,21,0,0,0,21,23,0
0,0,23,21,0,0,0,21,23,0
0,0,0,22,22,22,22,22,0,0
0,0,0,21,0,0,0,21,0,0
0,0,0,0,0,0,0,0,0,0
0,0,0,0,0,0,0,0,0,0
endlayer

layer
0,0,0,0,0,0,0,0,0,0
0,0,0,0,0,0,0,0,0,0
0,0,0,0,23,19,23,0,0,0
0,0,0,24,25,0,25,24,0,0
0,0,0,24,23,0,23,24,0,0
0,0,0,24,23,0,23,24,0,0
0,0,0,24,23,0,23,24,0,0
0,0,0,24,25,26,25,24,0,0
0,0,0,0,23,19,23,0,0,0
0,0,0,0,0,0,0,0,0,0
0,0,0,0,0,0,0,0,0,0
endlayer

layer
0,0,0,0,0,0,0,0,0,0
0,0,0,0,0,24,0,0,0,0
0,0,0,0,0,24,0,0,0,0
0,0,0,0,0,24,0,0,0,0
0,0,0,0,0,24,0,0,0,0
0,0,0,0,0,24,0,0,0,0
0,0,0,0,0,24,0,0,0,0
0,0,0,0,0,24,0,0,0,0
0,0,0,0,0,24,0,0,0,0
0,0,0,0,0,24,0,0,0,0
0,0,0,0,0,0,0,0,0,0
endlayer

