
# Created by Ruins mod version 15.0 Ingame Parser
# authoring Player: SunsOfOld

weight=100
embed_into_distance=1
acceptable_target_blocks=
unacceptable_target_blocks=flowing_water,water,flowing_lava,lava
dimensions=7,7,6
allowable_overhang=0
max_leveling=2
leveling_buffer=0
preserve_water=0
preserve_lava=0
uniqueMinDistance=1000000
preventRotation=1

rule1=0,100,minecraft:dirt-0
rule2=0,100,minecraft:grass-0
rule3=0,100,minecraft:log-0
rule4=0,100,BiomesOPlenty:colorizedLeaves2-14
rule5=0,100,BiomesOPlenty:colorizedLeaves2-6
rule6=0,100,ExtrabiomesXL:fence-7
rule7=0,100,minecraft:leaves-4
rule8=0,100,minecraft:leaves-12

layer
1,2,2,2,2,1
2,2,2,2,2,2
2,2,2,2,2,2
2,2,2,2,2,2
2,2,2,2,2,2
2,2,2,2,2,2
1,2,2,2,2,1
endlayer

layer
3,0,0,0,0,3
4,0,0,0,0,4
5,0,0,0,0,5
5,0,0,0,0,5
5,0,0,0,0,5
5,0,0,0,0,5
3,0,0,0,0,3
endlayer

layer
3,0,0,0,0,3
6,0,0,0,0,6
0,0,0,0,0,0
6,0,0,0,0,6
0,0,0,0,0,0
6,0,0,0,0,6
3,0,0,0,0,3
endlayer

layer
3,0,0,0,0,3
6,0,0,0,0,6
6,0,0,0,0,6
6,0,0,0,0,6
6,0,0,0,0,6
6,0,0,0,0,6
3,0,0,0,0,3
endlayer

layer
7,0,0,0,0,7
8,6,6,6,6,7
8,0,0,0,0,7
8,0,0,0,0,7
7,0,0,0,0,7
7,6,6,6,6,7
7,0,0,0,0,7
endlayer

layer
0,0,0,0,0,0
0,7,6,6,7,0
0,0,0,0,0,0
0,0,0,0,0,0
0,0,0,0,0,0
0,7,6,6,7,0
0,0,0,0,0,0
endlayer

layer
0,0,0,0,0,0
0,0,7,7,0,0
0,0,0,0,0,0
0,0,0,0,0,0
0,0,0,0,0,0
0,0,7,7,0,0
0,0,0,0,0,0
endlayer

