
# Created by Ruins mod version 15.0 Ingame Parser
# authoring Player: SunsOfOld

weight=100
embed_into_distance=5
acceptable_target_blocks=
unacceptable_target_blocks=flowing_water,water,flowing_lava,lava
dimensions=8,12,12
allowable_overhang=0
max_leveling=4
leveling_buffer=0
preserve_water=0
preserve_lava=0
uniqueMinDistance=1000000
preventRotation=1

rule1=0,100,preserveBlock
rule2=0,100,BiomesOPlenty:newBopDirt-2
rule3=0,100,chisel:fantasyblock2-13
rule4=0,100,BiomesOPlenty:newBopDirt-0
rule5=0,100,minecraft:sand-0
rule6=0,100,ExtrabiomesXL:log1-2
rule7=0,100,minecraft:water-0
rule8=0,100,BiomesOPlenty:newBopDirt-1
rule9=0,100,chisel:fantasyblock2-14
rule10=0,100,BiomesOPlenty:newBopDirt-3
rule11=0,100,ExtrabiomesXL:leaves_4-15
rule12=0,100,ExtrabiomesXL:leaves_4-7
rule13=0,100,IInventory;minecraft:chest;harvestcraft:freshwaterItem#10#0#4+GardenContainers:pottery_pattern#1#9#10+harvestcraft:potItem#1#0#13+minecraft:bucket#1#0#16+harvestcraft:saltItem#30#0#22-2
rule14=0,100,plantmegapack:leafyDustyMiller-0
rule15=0,100,plantmegapack:grassSeaOats-0
rule16=0,100,BiomesOPlenty:plants-3
rule17=0,100,GardenStuff:lattice-0
rule18=0,100,plantmegapack:flowerMediterraneanSeaHolly-0
rule19=0,100,plantmegapack:grassPrairie-0
rule20=0,100,ExtrabiomesXL:grass-0
rule21=0,100,GardenStuff:lantern-8
rule22=0,100,ExtrabiomesXL:woodslab-15
rule23=0,100,ExtrabiomesXL:woodslab-7

layer
1,1,1,1,1,1,1,1,1,1,1,1
1,1,1,1,1,1,1,1,1,1,1,1
1,1,1,1,1,1,1,1,1,1,1,1
1,1,1,1,2,1,1,1,1,1,1,1
1,1,1,1,1,1,1,1,1,1,1,1
1,1,1,1,1,3,3,1,1,1,1,1
1,1,1,1,1,3,3,1,1,1,1,1
1,1,1,1,1,1,1,1,1,1,1,1
1,1,1,1,1,2,1,1,1,1,1,1
1,1,1,1,1,1,1,1,1,1,1,1
1,1,1,1,1,1,1,1,1,1,1,1
1,1,1,1,1,1,1,1,1,1,1,1
endlayer

layer
1,1,1,1,1,1,1,1,1,1,1,1
1,1,1,1,1,1,1,1,1,1,1,1
1,1,1,1,1,1,1,1,1,1,1,1
1,1,1,1,5,4,2,1,1,1,1,1
1,1,1,5,6,3,3,6,2,1,1,1
1,1,1,2,3,7,7,3,4,1,1,1
1,1,1,2,3,7,7,3,2,1,1,1
1,1,1,8,6,3,3,6,8,1,1,1
1,1,1,1,2,8,2,2,1,1,1,1
1,1,1,1,1,1,1,1,1,1,1,1
1,1,1,1,1,1,1,1,1,1,1,1
1,1,1,1,1,1,1,1,1,1,1,1
endlayer

layer
5,1,1,1,1,1,1,1,1,1,2,5
1,1,1,1,1,1,1,1,1,1,1,5
1,1,1,1,10,9,8,2,1,1,1,1
1,1,1,2,12,11,11,8,1,1,1,1
1,1,2,11,6,3,3,6,11,1,1,1
1,1,10,12,3,0,0,3,11,10,1,1
1,1,8,11,3,0,0,3,13,8,1,1
1,1,5,12,6,3,3,6,11,1,1,1
1,1,1,2,12,11,9,10,1,1,1,1
5,1,1,1,10,10,5,2,1,1,1,1
2,1,1,1,1,1,1,1,1,1,1,1
5,5,2,1,1,1,1,1,1,1,5,0
endlayer

layer
16,0,5,1,5,9,1,5,1,5,15,14
0,1,1,1,1,2,9,1,1,1,5,16
0,1,10,1,10,0,0,5,2,1,1,5
1,1,5,2,12,11,0,11,2,10,1,1
10,1,10,0,6,3,3,6,11,5,10,5
1,2,2,11,3,17,17,3,11,10,2,2
1,1,0,0,3,17,17,3,12,18,1,2
5,2,5,11,6,3,3,6,11,5,1,1
1,1,10,11,12,11,0,11,11,2,10,5
14,1,2,5,2,9,2,5,1,2,10,0
19,2,1,1,9,10,1,1,1,1,5,0
16,16,10,2,9,2,1,5,2,10,16,0
endlayer

layer
0,0,14,5,2,0,5,14,0,16,0,0
0,0,1,2,0,15,0,10,1,2,16,0
0,1,20,0,14,0,0,16,19,2,1,14
0,2,16,15,12,0,0,11,20,15,2,0
20,0,19,12,6,0,21,6,0,16,2,16
0,5,20,0,12,0,0,0,0,15,19,20
10,2,0,0,0,0,0,11,0,0,0,2
16,15,16,0,6,0,12,6,11,16,0,5
0,2,15,0,11,0,0,12,0,20,15,14
0,1,20,14,15,0,15,16,0,19,5,0
0,15,1,10,0,19,2,10,2,10,16,0
0,0,20,5,0,2,0,16,2,15,0,0
endlayer

layer
0,0,0,16,15,0,16,0,0,0,0,0
0,0,0,20,0,0,0,20,0,20,0,0
0,0,0,0,0,0,0,0,0,15,0,0
0,20,0,0,0,0,0,0,0,0,20,0
0,0,0,0,6,0,0,6,0,0,20,0
0,14,0,0,0,0,0,0,0,0,0,0
20,20,0,0,0,0,0,11,0,0,0,20
0,0,0,0,6,0,0,6,0,0,0,16
0,20,0,0,0,0,0,0,0,0,0,0
0,0,0,0,0,0,0,0,0,0,16,0
0,0,0,20,0,0,20,15,20,0,0,0
0,0,0,16,0,20,0,0,19,0,0,0
endlayer

layer
0,0,0,0,0,0,0,0,0,0,0,0
0,0,0,0,0,0,0,0,0,0,0,0
0,0,0,0,0,0,0,0,0,0,0,0
0,0,0,0,0,0,0,0,0,0,0,0
0,0,0,22,6,0,11,6,22,0,0,0
0,0,0,22,11,0,12,11,22,0,0,0
0,0,0,22,0,11,0,11,22,0,0,0
0,0,0,22,6,0,0,6,22,0,0,0
0,0,0,0,0,0,0,0,0,0,0,0
0,0,0,0,0,0,0,0,0,0,0,0
0,0,0,0,0,0,0,0,0,0,0,0
0,0,0,0,0,0,0,0,0,0,0,0
endlayer

layer
0,0,0,0,0,0,0,0,0,0,0,0
0,0,0,0,0,0,0,0,0,0,0,0
0,0,0,0,0,22,22,0,0,0,0,0
0,0,0,0,23,22,22,23,0,0,0,0
0,0,0,0,23,22,22,23,0,0,0,0
0,0,0,0,23,22,22,23,0,0,0,0
0,0,0,0,23,22,22,23,0,0,0,0
0,0,0,0,23,22,22,23,0,0,0,0
0,0,0,0,23,22,22,23,0,0,0,0
0,0,0,0,0,22,22,0,0,0,0,0
0,0,0,0,0,0,0,0,0,0,0,0
0,0,0,0,0,0,0,0,0,0,0,0
endlayer

