
# Created by Ruins mod version 14.8 Ingame Parser
# authoring Player: SunsOfOld

weight=90
embed_into_distance=0
acceptable_target_blocks=
unacceptable_target_blocks=flowing_water,water,flowing_lava,lava
dimensions=10,10,13
allowable_overhang=0
max_leveling=4
leveling_buffer=0
preserve_water=0
preserve_lava=0
uniqueMinDistance=1000000
preventRotation=1

rule1=0,100,preserveBlock
rule2=0,100,BiomesOPlenty:logs1-8
rule3=0,100,minecraft:oak_stairs-7
rule4=0,100,chisel:oak_planks-13
rule5=0,100,IInventory;minecraft:chest;BiomesOPlenty:flippers#1#0#19+minecraft:enchanted_book#{StoredEnchantments:[0:{id:61s,lvl:3s,},],}#0#25-2
rule6=0,100,chisel:oak_planks-2
rule7=0,100,minecraft:gravel-0
rule8=0,100,BiomesOPlenty:logs1-0
rule9=0,100,IInventory;minecraft:chest;antiqueatlas:emptyAntiqueAtlas#1#0#20+minecraft:paper#11#0#22+minecraft:compass#1#0#26-2
rule10=0,100,chisel:oak_planks-1
rule11=0,100,GardenTrees:thin_log_fence-0

layer
1,1,1,1,1,1,1,1,1,1,1,1,1
1,1,1,1,1,1,1,1,1,1,1,1,1
1,1,1,1,1,1,1,1,1,1,1,1,1
1,1,1,1,1,1,1,1,1,1,1,1,1
1,1,1,1,3,2,2,2,2,2,2,1,1
1,1,1,1,1,1,1,1,1,1,1,1,1
1,1,1,1,1,1,1,1,1,1,1,1,4
1,1,1,1,1,1,1,1,1,1,1,1,1
1,1,1,1,1,1,1,1,1,1,1,1,1
1,1,1,1,1,1,1,1,1,1,1,1,1
endlayer

layer
1,1,1,1,1,1,1,1,1,1,1,1,1
1,1,1,1,1,1,1,1,1,1,1,1,1
1,1,1,1,1,1,1,1,1,1,1,1,1
1,1,1,1,1,4,4,4,4,4,4,1,1
1,1,1,3,2,4,1,1,1,1,1,1,1
1,1,1,1,1,4,4,4,4,4,4,4,1
1,1,1,1,1,1,1,1,1,1,1,1,1
1,1,1,1,1,1,1,1,1,1,1,1,1
1,1,1,1,1,1,1,1,1,1,1,1,1
1,1,1,1,1,1,1,1,1,1,1,1,1
endlayer

layer
1,1,1,1,1,1,1,1,1,1,1,1,1
1,1,1,1,1,1,1,1,1,1,1,1,1
1,1,1,1,1,4,4,4,4,4,4,4,1
1,1,1,1,4,1,1,1,1,1,1,1,1
1,1,3,2,1,5,1,1,1,1,1,1,1
1,1,1,1,4,1,1,1,1,1,1,6,1
1,1,1,1,1,4,4,4,4,4,1,4,1
1,1,1,1,1,1,1,1,1,1,1,1,1
1,1,1,1,1,1,1,1,1,1,1,1,1
1,1,1,1,1,1,1,1,1,1,1,1,1
endlayer

layer
1,1,1,1,1,1,1,1,1,1,1,1,1
1,1,1,1,1,4,4,4,4,4,1,1,1
1,1,1,1,6,6,6,6,7,6,6,6,1
1,1,1,4,6,6,6,6,6,6,1,1,1
1,1,8,6,6,6,6,6,6,6,6,1,1
1,1,1,4,6,6,6,6,6,6,1,1,1
1,1,1,1,6,6,6,6,6,1,1,1,1
1,1,1,1,1,4,4,4,4,4,4,4,1
1,1,1,1,1,1,1,1,1,1,1,1,1
1,1,1,1,1,1,1,1,1,1,1,1,1
endlayer

layer
1,1,1,1,1,1,1,1,1,1,1,1,1
1,1,1,1,4,4,4,4,4,4,4,1,1
1,1,1,4,1,1,1,1,1,1,1,1,1
1,1,1,4,1,1,1,1,1,1,1,1,1
1,1,8,1,1,1,1,1,1,1,1,1,1
1,1,1,4,1,1,1,1,1,1,1,1,1
1,1,1,4,9,1,1,1,1,1,1,1,1
1,1,1,1,4,4,4,4,4,4,4,1,1
1,1,1,1,1,1,1,1,1,1,1,1,1
1,1,1,1,1,1,1,1,1,1,1,1,1
endlayer

layer
1,1,1,1,1,1,1,1,1,1,1,1,1
1,1,1,1,4,4,4,4,4,4,1,1,1
1,1,1,4,1,1,1,1,1,1,1,1,1
1,1,4,1,1,1,1,1,1,1,1,1,1
1,8,1,1,1,1,1,1,1,1,1,1,1
1,1,4,1,1,1,1,1,1,1,1,1,1
1,1,1,4,1,1,1,1,1,1,1,1,1
1,1,1,1,4,4,4,1,4,4,1,1,1
1,1,1,1,1,1,1,1,1,1,1,1,1
1,1,1,1,1,1,1,1,1,1,1,1,1
endlayer

layer
1,1,1,1,1,1,1,1,1,1,1,1,1
1,1,1,1,4,4,4,4,4,4,4,1,1
1,1,1,4,1,1,1,1,1,1,1,1,1
1,1,4,1,1,1,1,1,1,1,1,1,1
1,8,1,1,1,1,1,1,1,1,1,1,1
1,1,4,1,0,1,1,1,1,1,1,1,1
1,1,1,4,1,1,1,1,1,1,1,1,1
1,1,1,1,4,4,4,1,1,1,1,1,1
1,1,1,1,1,1,1,1,1,1,1,1,1
1,1,1,1,1,1,1,1,1,1,1,1,1
endlayer

layer
1,1,1,1,4,4,4,4,4,1,1,1,1
1,1,1,4,10,1,10,10,10,1,1,1,1
1,1,4,10,10,10,10,10,10,10,1,1,1
1,4,10,1,10,10,10,10,1,1,1,1,1
8,10,10,10,10,1,1,1,1,1,1,1,1
1,4,10,10,10,10,10,10,1,1,1,1,1
1,1,4,10,10,10,10,1,1,1,1,1,1
1,1,1,4,10,10,10,10,10,10,1,1,1
1,1,1,1,4,4,4,4,1,1,1,1,1
1,1,1,1,1,1,1,1,4,4,4,4,1
endlayer

layer
1,1,1,1,11,1,11,11,1,1,1,1,1
1,1,1,11,1,1,1,1,1,1,1,1,1
1,1,11,1,1,1,1,1,1,1,1,1,1
1,1,1,1,1,1,1,1,1,1,1,1,1
8,1,1,1,1,1,1,1,1,1,1,1,1
1,11,1,1,1,1,1,1,1,1,1,1,1
1,1,11,1,1,1,1,1,1,1,1,1,1
1,1,1,11,1,1,1,1,1,1,1,1,1
1,1,1,1,11,1,11,11,1,1,1,1,1
1,1,1,1,1,1,1,1,1,1,1,1,1
endlayer

layer
1,1,1,1,1,1,1,1,1,1,1,1,1
1,1,1,1,1,1,1,1,1,1,1,1,1
1,1,1,1,1,1,1,1,1,1,1,1,1
1,1,1,1,1,1,1,1,1,1,1,1,1
11,1,1,1,1,1,1,1,1,1,1,1,1
1,1,1,1,1,1,1,1,1,1,1,1,1
1,1,1,1,1,1,1,1,1,1,1,1,1
1,1,1,1,1,1,1,1,1,1,1,1,1
1,1,1,1,1,1,1,1,1,1,1,1,1
1,1,1,1,1,1,1,1,1,1,1,1,1
endlayer

