# Created by Ruins mod version 15.0 Ingame Parser
# authoring Player: MjrSlacker

weight=100
embed_into_distance=5
acceptable_target_blocks=
unacceptable_target_blocks=flowing_water,water,flowing_lava,lava
dimensions=17,63,27
allowable_overhang=0
max_leveling=15
leveling_buffer=0
preserve_water=1
preserve_lava=0
uniqueMinDistance=1000000
preventRotation=1

rule1=0,100,preserveBlock
rule2=0,100,chisel:dark_oak_planks-8
rule3=0,100,minecraft:planks-5
rule4=0,100,BiomesOPlenty:planks-0
rule5=0,100,BiomesOPlenty:sacredoakStairs-7
rule6=0,100,chisel:glowstone-10
rule7=0,100,BiomesOPlenty:sacredoakStairs-2
rule8=0,100,IInventory;minecraft:chest;minecraft:bone#1#0#0+minecraft:bone#1#0#1+harvestcraft:hardenedleatherbootsItem#1#0#2+harvestcraft:saltItem#1#0#3+minecraft:bone#1#0#4+minecraft:bone#1#0#5+UndergroundBiomes:fossilPiece#1#3#6+minecraft:diamond#3#0#7+minecraft:bone#1#0#8+minecraft:bone#1#0#9+minecraft:bone#1#0#10+harvestcraft:saltItem#1#0#11+minecraft:bone#1#0#12+minecraft:bone#1#0#13+minecraft:bone#1#0#14+harvestcraft:hardenedleatherleggingsItem#1#0#15+UndergroundBiomes:fossilPiece#1#5#16+harvestcraft:saltItem#1#0#17+minecraft:bone#1#0#18+harvestcraft:saltItem#1#0#19+minecraft:bone#1#0#20+harvestcraft:saltItem#1#0#21+minecraft:bone#1#0#22+minecraft:bone#1#0#23+harvestcraft:hardenedleatherchestItem#1#0#24+harvestcraft:saltItem#1#0#25+harvestcraft:saltItem#1#0#26-5
rule9=0,100,minecraft:trapdoor-6
rule10=0,100,minecraft:trapdoor-14
rule11=0,100,BiomesOPlenty:sacredoakStairs-3
rule12=0,100,minecraft:trapdoor-7
rule13=0,100,dendrology:kiparis_planks-12
rule14=0,100,minecraft:log2-5
rule15=0,100,IInventory;minecraft:chest;harvestcraft:saltItem#2#0#0+harvestcraft:saltItem#1#0#1+BiomesOPlenty:mudball#1#0#2+BiomesOPlenty:mudball#1#0#3+BiomesOPlenty:mudball#1#0#4+minecraft:golden_sword#1#0#5+BiomesOPlenty:mudball#1#0#6+harvestcraft:saltItem#1#0#7+BiomesOPlenty:mudball#1#0#8+harvestcraft:saltItem#1#0#9+BiomesOPlenty:mudball#1#0#10+harvestcraft:saltItem#1#0#11+BiomesOPlenty:mudball#1#0#12+BiomesOPlenty:mudball#1#0#13+harvestcraft:saltItem#1#0#14+harvestcraft:saltItem#1#0#15+BiomesOPlenty:mudball#1#0#16+BiomesOPlenty:mudball#1#0#17+BiomesOPlenty:mudball#1#0#18+harvestcraft:saltItem#1#0#19+harvestcraft:saltItem#1#0#20+BiomesOPlenty:mudball#1#0#21+BiomesOPlenty:mudball#1#0#22+BiomesOPlenty:mudball#1#0#23+BiomesOPlenty:mudball#1#0#24+BiomesOPlenty:mudball#1#0#25+BiomesOPlenty:mudball#1#0#26-5
rule16=0,100,minecraft:dark_oak_stairs-1
rule17=2,100,WallSign:null:null:null:null-4
rule18=0,100,IInventory;minecraft:chest;BiomesOPlenty:hoeMud#1#0#0+BiomesOPlenty:misc#1#0#11+BiomesOPlenty:axeMud#1#0#16+BiomesOPlenty:scytheMud#1#0#22-3
rule19=0,100,GardenStuff:heavy_chain-5
rule20=0,100,minecraft:fence-0
rule21=2,100,WallSign:null:null:null:null-5
rule22=0,100,BiomesOPlenty:sacredoakStairs-1
rule23=0,100,minecraft:wooden_slab-5
rule24=0,100,IInventory;minecraft:chest;BiomesOPlenty:mudball#1#0#0+BiomesOPlenty:mudball#1#0#1+BiomesOPlenty:mudball#1#0#2+BiomesOPlenty:mudball#1#0#3+harvestcraft:saltItem#1#0#4+BiomesOPlenty:mudball#1#0#5+BiomesOPlenty:mudball#1#0#6+BiomesOPlenty:mudball#1#0#7+BiomesOPlenty:mudball#1#0#8+BiomesOPlenty:mudball#1#0#9+BiomesOPlenty:mudball#1#0#10+harvestcraft:saltItem#1#0#11+BiomesOPlenty:mudball#1#0#12+BiomesOPlenty:mudball#1#0#13+harvestcraft:saltItem#1#0#14+BiomesOPlenty:mudball#1#0#15+BiomesOPlenty:mudball#1#0#16+BiomesOPlenty:mudball#1#0#17+BiomesOPlenty:mudball#1#0#18+harvestcraft:saltItem#1#0#19+BiomesOPlenty:mudball#1#0#20+BiomesOPlenty:mudball#1#0#21+chisel:gold_block#1#5#22+minecraft:gold_ingot#1#0#23+BiomesOPlenty:mudball#1#0#24+harvestcraft:saltItem#1#0#25+BiomesOPlenty:mudball#1#0#26-3
rule25=0,100,BiomesOPlenty:sacredoakStairs-6
rule26=0,100,minecraft:dark_oak_stairs-5
rule27=0,100,IInventory;minecraft:chest;BiomesOPlenty:mudball#1#0#0+BiomesOPlenty:mudball#1#0#1+BiomesOPlenty:mudball#1#0#2+BiomesOPlenty:mudball#1#0#3+BiomesOPlenty:mudball#1#0#4+BiomesOPlenty:mudball#1#0#5+GardenStuff:chain_link#64#1#6+BiomesOPlenty:mudball#1#0#7+harvestcraft:saltItem#1#0#8+BiomesOPlenty:mudball#1#0#9+harvestcraft:saltItem#1#0#10+BiomesOPlenty:mudball#1#0#11+BiomesOPlenty:mudball#1#0#12+BiomesOPlenty:mudball#1#0#13+BiomesOPlenty:mudball#1#0#14+BiomesOPlenty:mudball#1#0#15+harvestcraft:saltItem#1#0#16+BiomesOPlenty:mudball#1#0#17+BiomesOPlenty:mudball#1#0#18+BiomesOPlenty:mudball#1#0#19+BiomesOPlenty:mudball#1#0#20+BiomesOPlenty:mudball#1#0#21+BiomesOPlenty:scytheGold#1#0#22+BiomesOPlenty:mudball#1#0#23+BiomesOPlenty:mudball#1#0#24+BiomesOPlenty:mudball#1#0#25+BiomesOPlenty:record_corruption#1#0#26-4
rule28=0,100,minecraft:wooden_slab-13
rule29=0,100,minecraft:log2-9
rule30=0,100,minecraft:dark_oak_stairs-7
rule31=0,100,minecraft:trapdoor-4
rule32=0,100,BiomesOPlenty:woodenSingleSlab1-0
rule33=0,100,minecraft:trapdoor-8
rule34=0,100,minecraft:trapdoor-10

layer
1,1,1,1,1,1,1,1,1,1,1,1,1,1,1,1,1,1,1,1,1,1,1,1,1,1,1
1,1,1,1,1,1,1,1,1,1,1,1,1,1,1,1,1,1,1,1,1,1,1,1,1,1,1
1,1,1,1,1,1,1,1,1,1,1,1,1,1,1,1,1,1,1,1,1,1,1,1,1,1,1
1,1,1,1,1,1,1,1,1,1,1,1,1,1,1,1,1,1,1,1,1,1,1,1,1,1,1
1,1,1,1,1,1,1,1,1,1,1,1,1,1,1,1,1,1,1,1,1,1,1,1,1,1,1
1,1,1,1,1,1,1,1,1,1,1,1,1,1,1,1,1,1,1,1,1,1,1,1,1,1,1
1,1,1,1,1,1,1,1,1,1,1,1,1,1,1,1,1,1,1,1,1,1,1,1,1,1,1
1,1,1,1,1,1,1,1,1,1,1,1,1,1,1,1,1,1,1,1,1,1,1,1,1,1,1
1,1,1,1,1,1,1,1,1,1,1,1,1,1,1,1,1,1,1,1,1,1,1,1,1,1,1
1,1,1,1,1,1,1,1,1,1,1,1,1,1,1,1,1,1,1,1,1,1,1,1,1,1,1
1,1,1,1,1,1,1,1,1,1,1,1,1,1,1,1,1,1,1,1,1,1,1,1,1,1,1
1,1,1,1,1,1,1,1,1,1,1,1,1,1,1,1,1,1,1,1,1,1,1,1,1,1,1
1,1,1,1,1,1,1,1,1,1,1,1,1,1,1,1,1,1,1,1,1,1,1,1,1,1,1
1,1,1,1,1,1,1,1,1,1,1,1,1,1,1,1,1,1,1,1,1,1,1,1,1,1,1
1,1,1,1,1,1,1,1,1,1,1,1,1,1,1,1,1,1,1,1,1,1,1,1,1,1,1
1,1,1,1,1,1,1,1,1,1,1,1,1,1,1,1,1,1,1,1,1,1,1,1,1,1,1
1,1,1,1,1,1,1,1,1,1,1,1,1,1,1,1,1,1,1,1,1,1,1,1,1,1,1
1,1,1,1,1,1,1,1,1,1,1,1,1,1,1,1,1,1,1,1,1,1,1,1,1,1,1
1,1,1,1,1,1,1,1,1,1,1,1,1,1,1,1,1,1,1,1,1,1,1,1,1,1,1
1,1,1,1,1,1,1,1,1,1,1,1,1,1,1,1,1,1,1,1,1,1,1,1,1,1,1
1,1,1,1,1,1,1,1,1,1,1,1,1,1,1,1,1,1,1,1,1,1,1,1,1,1,1
1,1,1,1,1,1,1,1,1,1,1,1,1,1,1,1,1,1,1,1,1,1,1,1,1,1,1
1,1,1,1,1,1,1,1,1,1,1,1,1,1,1,1,1,1,1,1,1,1,1,1,1,1,1
1,1,1,1,1,1,1,1,1,1,1,1,1,1,1,1,1,1,1,1,1,1,1,1,1,1,1
1,1,1,1,1,1,1,1,1,1,1,1,1,1,1,1,1,1,1,1,1,1,1,1,1,1,1
1,1,1,1,1,1,1,1,1,1,1,1,1,1,1,1,1,1,1,1,1,1,1,1,1,1,1
1,1,1,1,1,1,1,1,1,1,1,1,1,1,1,1,1,1,1,1,1,1,1,1,1,1,1
1,1,1,1,1,1,1,1,1,1,1,1,1,1,1,1,1,1,1,1,1,1,1,1,1,1,1
1,1,1,1,1,1,1,1,1,1,1,1,1,1,1,1,1,1,1,1,1,1,1,1,1,1,1
1,1,1,1,1,1,1,1,1,1,1,1,1,1,1,1,1,1,1,1,1,1,1,1,1,1,1
1,1,1,1,1,1,1,1,1,1,1,1,1,1,1,1,1,1,1,1,1,1,1,1,1,1,1
1,1,1,1,1,1,1,1,1,1,1,1,1,1,1,1,1,1,1,1,1,1,1,1,1,1,1
1,1,1,1,1,1,1,1,1,1,1,1,1,1,1,1,1,1,1,1,1,1,1,1,1,1,1
1,1,1,1,1,1,1,1,1,1,1,1,1,1,1,1,1,1,1,1,1,1,1,1,1,1,1
1,1,1,1,1,1,1,1,1,1,1,1,1,1,1,1,1,1,1,1,1,1,1,1,1,1,1
1,1,1,1,1,1,1,1,1,1,1,1,1,1,1,1,1,1,1,1,1,1,1,1,1,1,1
1,1,1,1,1,1,1,1,1,1,1,1,1,1,1,1,1,1,1,1,1,1,1,1,1,1,1
1,1,1,1,1,1,1,1,1,1,1,1,1,1,1,1,1,1,1,1,1,1,1,1,1,1,1
1,1,1,1,1,1,1,1,1,1,1,1,1,1,1,1,1,1,1,1,1,1,1,1,1,1,1
1,1,1,1,1,1,1,1,1,1,1,1,1,1,1,1,1,1,1,1,1,1,1,1,1,1,1
1,1,1,1,1,1,1,1,1,1,1,1,1,1,1,1,1,1,1,1,1,1,1,1,1,1,1
1,1,1,1,1,1,1,1,1,1,1,1,1,1,1,1,1,1,1,1,1,1,1,1,1,1,1
1,1,1,1,1,1,1,1,1,1,1,1,1,1,1,1,1,1,1,1,1,1,1,1,1,1,1
1,1,1,1,1,1,1,1,1,1,1,1,1,1,1,1,1,1,1,1,1,1,1,1,1,1,1
1,1,1,1,1,1,1,1,1,1,1,1,1,1,1,1,1,1,1,1,1,1,1,1,1,1,1
1,1,1,1,1,1,1,1,1,1,1,1,1,1,1,1,1,1,1,1,1,1,1,1,1,1,1
1,1,1,1,1,1,1,1,1,1,1,1,1,1,1,1,1,1,1,1,1,1,1,1,1,1,1
1,1,1,1,1,1,1,1,1,1,1,1,1,1,1,1,1,1,1,1,1,1,1,1,1,1,1
1,1,1,1,1,1,1,1,1,1,1,1,1,1,1,1,1,1,1,1,1,1,1,1,1,1,1
1,1,1,1,1,1,1,1,1,1,1,1,1,1,1,1,1,1,1,1,1,1,1,1,1,1,1
1,1,1,1,1,1,1,1,1,1,1,1,1,1,1,1,1,1,1,1,1,1,1,1,1,1,1
1,1,1,1,1,1,1,1,1,1,1,1,1,1,1,1,1,1,1,1,1,1,1,1,1,1,1
1,1,1,1,1,1,1,1,1,1,1,1,1,1,1,1,1,1,1,1,1,1,1,1,1,1,1
1,1,1,1,1,1,1,1,1,1,1,1,1,1,1,1,1,1,1,1,1,1,1,1,1,1,1
1,1,1,1,1,1,1,1,1,1,1,1,1,1,1,1,1,1,1,1,1,1,1,1,1,1,1
1,1,1,1,1,1,1,1,1,1,1,1,1,1,1,1,1,1,1,1,1,1,1,1,1,1,1
1,1,1,1,1,1,1,1,1,1,1,1,1,1,1,1,1,1,1,1,1,1,1,1,1,1,1
1,1,1,1,1,1,1,1,1,1,1,1,1,1,1,1,1,1,1,1,1,1,1,1,1,1,1
1,1,1,1,1,1,1,1,1,1,1,1,1,1,1,1,1,1,1,1,1,1,1,1,1,1,1
1,1,1,1,1,1,1,1,1,1,1,1,1,1,1,1,1,1,1,1,1,1,1,1,1,1,1
1,1,1,1,1,1,1,1,1,1,1,1,1,1,1,1,1,1,1,1,1,1,1,1,1,1,1
1,1,1,1,1,1,1,1,1,1,1,1,1,1,1,1,1,1,1,1,1,1,1,1,1,1,1
1,1,1,1,1,1,1,1,1,1,1,1,1,1,1,1,1,1,1,1,1,1,1,1,1,1,1
endlayer

layer
1,1,1,1,1,1,1,1,1,1,1,1,1,1,1,1,1,1,1,1,1,1,1,1,1,1,1
1,1,1,1,1,1,1,1,1,1,1,1,1,1,1,1,1,1,1,1,1,1,1,1,1,1,1
1,1,1,1,1,1,1,1,1,1,1,1,1,1,1,1,1,1,1,1,1,1,1,1,1,1,1
1,1,1,1,1,1,1,1,1,1,1,1,1,1,1,1,1,1,1,1,1,1,1,1,1,1,1
1,1,1,1,1,1,1,1,1,1,1,1,1,1,1,1,1,1,1,1,1,1,1,1,1,1,1
1,1,1,1,1,1,1,1,1,1,1,1,1,1,1,1,1,1,1,1,1,1,1,1,1,1,1
1,1,1,1,1,1,1,1,1,1,1,1,1,1,1,1,1,1,1,1,1,1,1,1,1,1,1
1,1,1,1,1,1,1,1,1,1,1,1,1,1,1,1,1,1,1,1,1,1,1,1,1,1,1
1,1,1,1,1,1,1,1,1,1,1,1,1,1,1,1,1,1,1,1,1,1,1,1,1,1,1
1,1,1,1,1,1,1,1,1,1,1,1,1,1,1,1,1,1,1,1,1,1,1,1,1,1,1
1,1,1,1,1,1,1,1,1,1,1,1,1,1,1,1,1,1,1,1,1,1,1,1,1,1,1
1,1,1,1,1,1,1,1,1,1,1,1,1,1,1,1,1,1,1,1,1,1,1,1,1,1,1
1,1,1,1,1,1,1,1,1,1,1,1,1,1,1,1,1,1,1,1,1,1,1,1,1,1,1
1,1,1,1,1,1,1,1,1,1,1,1,1,1,1,1,1,1,1,1,1,1,1,1,1,1,1
1,1,1,1,1,1,1,1,1,1,1,1,1,1,1,1,1,1,1,1,1,1,1,1,1,1,1
1,1,1,1,1,1,1,1,1,1,1,1,1,1,1,1,1,1,1,1,1,1,1,1,1,1,1
1,1,1,1,1,1,1,1,1,1,1,1,1,1,1,1,1,1,1,1,1,1,1,1,1,1,1
1,1,1,1,1,1,1,1,1,1,1,1,1,1,1,1,1,1,1,1,1,1,1,1,1,1,1
1,1,1,1,1,1,1,1,1,1,1,1,1,1,1,1,1,1,1,1,1,1,1,1,1,1,1
1,1,1,1,1,1,1,1,1,1,1,1,1,1,1,1,1,1,1,1,1,1,1,1,1,1,1
1,1,1,1,1,1,1,1,1,1,1,1,1,1,4,3,2,1,1,1,1,1,1,1,1,1,1
1,1,1,1,1,1,1,1,1,1,1,1,1,4,4,3,1,1,1,1,1,1,1,1,1,1,1
1,1,1,1,1,1,1,1,1,1,1,1,1,4,4,3,2,1,1,1,1,1,1,1,1,1,1
1,1,1,1,1,1,1,1,1,1,1,1,5,4,4,3,2,1,1,1,1,1,1,1,1,1,1
1,1,1,1,1,1,1,1,1,1,1,1,5,4,4,3,2,1,1,1,1,1,1,1,1,1,1
1,1,1,1,1,1,1,1,1,1,1,1,5,4,4,3,2,1,1,1,1,1,1,1,1,1,1
1,1,1,1,1,1,1,1,1,1,1,1,5,4,4,3,1,1,1,1,1,1,1,1,1,1,1
1,1,1,1,1,1,1,1,1,1,1,1,5,4,4,3,2,1,1,1,1,1,1,1,1,1,1
1,1,1,1,1,1,1,1,1,1,1,1,5,4,4,3,2,1,1,1,1,1,1,1,1,1,1
1,1,1,1,1,1,1,1,1,1,1,1,5,4,4,3,2,1,1,1,1,1,1,1,1,1,1
1,1,1,1,1,1,1,1,1,1,1,1,5,4,4,3,2,1,1,1,1,1,1,1,1,1,1
1,1,1,1,1,1,1,1,1,1,1,1,5,4,4,3,1,1,1,1,1,1,1,1,1,1,1
1,1,1,1,1,1,1,1,1,1,1,1,5,4,4,3,2,1,1,1,1,1,1,1,1,1,1
1,1,1,1,1,1,1,1,1,1,1,1,5,4,4,3,2,1,1,1,1,1,1,1,1,1,1
1,1,1,1,1,1,1,1,1,1,1,1,5,4,4,3,2,1,1,1,1,1,1,1,1,1,1
1,1,1,1,1,1,1,1,1,1,1,1,5,4,4,3,2,1,1,1,1,1,1,1,1,1,1
1,1,1,1,1,1,1,1,1,1,1,1,5,4,4,3,1,1,1,1,1,1,1,1,1,1,1
1,1,1,1,1,1,1,1,1,1,1,1,5,4,4,3,2,1,1,1,1,1,1,1,1,1,1
1,1,1,1,1,1,1,1,1,1,1,1,5,4,4,3,2,1,1,1,1,1,1,1,1,1,1
1,1,1,1,1,1,1,1,1,1,1,1,5,4,4,3,2,1,1,1,1,1,1,1,1,1,1
1,1,1,1,1,1,1,1,1,1,1,1,5,4,4,3,2,1,1,1,1,1,1,1,1,1,1
1,1,1,1,1,1,1,1,1,1,1,1,5,4,1,3,1,1,1,1,1,1,1,1,1,1,1
1,1,1,1,1,1,1,1,1,1,1,1,5,4,1,3,2,1,1,1,1,1,1,1,1,1,1
1,1,1,1,1,1,1,1,1,1,1,1,5,4,4,3,2,1,1,1,1,1,1,1,1,1,1
1,1,1,1,1,1,1,1,1,1,1,1,5,1,1,1,2,1,1,1,1,1,1,1,1,1,1
1,1,1,1,1,1,1,1,1,1,1,1,5,1,1,1,1,1,1,1,1,1,1,1,1,1,1
1,1,1,1,1,1,1,1,1,1,1,1,1,1,1,1,1,1,1,1,1,1,1,1,1,1,1
1,1,1,1,1,1,1,1,1,1,1,1,1,1,1,1,1,1,1,1,1,1,1,1,1,1,1
1,1,1,1,1,1,1,1,1,1,1,1,1,1,1,1,1,1,1,1,1,1,1,1,1,1,1
1,1,1,1,1,1,1,1,1,1,1,1,1,1,1,1,1,1,1,1,1,1,1,1,1,1,1
1,1,1,1,1,1,1,1,1,1,1,1,1,1,1,1,1,1,1,1,1,1,1,1,1,1,1
1,1,1,1,1,1,1,1,1,1,1,1,1,1,1,1,1,1,1,1,1,1,1,1,1,1,1
1,1,1,1,1,1,1,1,1,1,1,1,1,1,1,1,1,1,1,1,1,1,1,1,1,1,1
1,1,1,1,1,1,1,1,1,1,1,1,1,1,1,1,1,1,1,1,1,1,1,1,1,1,1
1,1,1,1,1,1,1,1,1,1,1,1,1,1,1,1,1,1,1,1,1,1,1,1,1,1,1
1,1,1,1,1,1,1,1,1,1,1,1,1,1,1,1,1,1,1,1,1,1,1,1,1,1,1
1,1,1,1,1,1,1,1,1,1,1,1,1,1,1,1,1,1,1,1,1,1,1,1,1,1,1
1,1,1,1,1,1,1,1,1,1,1,1,1,1,1,1,1,1,1,1,1,1,1,1,1,1,1
1,1,1,1,1,1,1,1,1,1,1,1,1,1,1,1,1,1,1,1,1,1,1,1,1,1,1
1,1,1,1,1,1,1,1,1,1,1,1,1,1,1,1,1,1,1,1,1,1,1,1,1,1,1
1,1,1,1,1,1,1,1,1,1,1,1,1,1,1,1,1,1,1,1,1,1,1,1,1,1,1
1,1,1,1,1,1,1,1,1,1,1,1,1,1,1,1,1,1,1,1,1,1,1,1,1,1,1
1,1,1,1,1,1,1,1,1,1,1,1,1,1,1,1,1,1,1,1,1,1,1,1,1,1,1
endlayer

layer
1,1,1,1,1,1,1,1,1,1,1,1,1,1,1,1,1,1,1,1,1,1,1,1,1,1,1
1,1,1,1,1,1,1,1,1,1,1,1,1,1,1,1,1,1,1,1,1,1,1,1,1,1,1
1,1,1,1,1,1,1,1,1,1,1,1,1,1,1,1,1,1,1,1,1,1,1,1,1,1,1
1,1,1,1,1,1,1,1,1,1,1,1,1,1,1,1,1,1,1,1,1,1,1,1,1,1,1
1,1,1,1,1,1,1,1,1,1,1,1,1,1,1,1,1,1,1,1,1,1,1,1,1,1,1
1,1,1,1,1,1,1,1,1,1,1,1,1,1,1,1,1,1,1,1,1,1,1,1,1,1,1
1,1,1,1,1,1,1,1,1,1,1,1,1,1,1,1,1,1,1,1,1,1,1,1,1,1,1
1,1,1,1,1,1,1,1,1,1,1,1,1,1,1,1,1,1,1,1,1,1,1,1,1,1,1
1,1,1,1,1,1,1,1,1,1,1,1,1,1,1,1,1,1,1,1,1,1,1,1,1,1,1
1,1,1,1,1,1,1,1,1,1,1,1,1,1,1,1,1,1,1,1,1,1,1,1,1,1,1
1,1,1,1,1,1,1,1,1,1,1,1,1,1,1,1,1,1,1,1,1,1,1,1,1,1,1
1,1,1,1,1,1,1,1,1,1,1,1,1,1,1,1,1,1,1,1,1,1,1,1,1,1,1
1,1,1,1,1,1,1,1,1,1,1,1,1,1,1,1,1,1,1,1,1,1,1,1,1,1,1
1,1,1,1,1,1,1,1,1,1,1,1,1,1,1,1,1,1,1,1,1,1,1,1,1,1,1
1,1,1,1,1,1,1,1,1,1,1,1,1,1,1,1,1,1,1,1,1,1,1,1,1,1,1
1,1,1,1,1,1,1,1,1,1,1,1,1,1,1,1,1,1,1,1,1,1,1,1,1,1,1
1,1,1,1,1,1,1,1,1,1,1,1,1,1,1,1,1,1,1,1,1,1,1,1,1,1,1
1,1,1,1,1,1,1,1,1,1,1,1,1,1,4,3,2,1,1,1,1,1,1,1,1,1,1
1,1,1,1,1,1,1,1,1,1,1,1,1,4,4,3,2,1,1,1,1,1,1,1,1,1,1
1,1,1,1,1,1,1,1,1,1,1,1,4,4,4,3,1,1,1,1,1,1,1,1,1,1,1
1,1,1,1,1,1,1,1,1,1,1,1,4,4,4,3,2,1,1,1,1,1,1,1,1,1,1
1,1,1,1,1,1,1,1,1,1,1,1,4,3,3,3,1,1,1,1,1,1,1,1,1,1,1
1,1,1,1,1,1,1,1,1,1,1,5,4,1,1,3,1,1,1,1,1,1,1,1,1,1,1
1,1,1,1,1,1,1,1,1,1,1,5,4,1,1,3,1,1,1,1,1,1,1,1,1,1,1
1,1,1,1,1,1,1,1,1,1,1,5,4,1,1,3,1,1,1,1,1,1,1,1,1,1,1
1,1,1,1,1,1,1,1,1,1,1,5,4,1,1,3,1,1,1,1,1,1,1,1,1,1,1
1,1,1,1,1,1,1,1,1,1,1,5,4,1,1,3,1,1,1,1,1,1,1,1,1,1,1
1,1,1,1,1,1,1,1,1,1,1,5,4,1,1,3,1,1,1,1,1,1,1,1,1,1,1
1,1,1,1,1,1,1,1,1,1,1,5,4,1,1,3,1,1,1,1,1,1,1,1,1,1,1
1,1,1,1,1,1,1,1,1,1,1,5,4,1,1,3,1,1,1,1,1,1,1,1,1,1,1
1,1,1,1,1,1,1,1,1,1,1,5,4,1,1,3,1,1,1,1,1,1,1,1,1,1,1
1,1,1,1,1,1,1,1,1,1,1,5,4,1,1,3,1,1,1,1,1,1,1,1,1,1,1
1,1,1,1,1,1,1,1,1,1,1,5,4,1,1,3,1,1,1,1,1,1,1,1,1,1,1
1,1,1,1,1,1,1,1,1,1,1,5,4,1,1,3,1,1,1,1,1,1,1,1,1,1,1
1,1,1,1,1,1,1,1,1,1,1,5,4,1,1,3,1,1,1,1,1,1,1,1,1,1,1
1,1,1,1,1,1,1,1,1,1,1,5,4,6,1,3,1,1,1,1,1,1,1,1,1,1,1
1,1,1,1,1,1,1,1,1,1,1,5,4,7,1,3,1,1,1,1,1,1,1,1,1,1,1
1,1,1,1,1,1,1,1,1,1,1,5,4,1,1,3,1,1,1,1,1,1,1,1,1,1,1
1,1,1,1,1,1,1,1,1,1,1,5,4,6,1,3,1,1,1,1,1,1,1,1,1,1,1
1,1,1,1,1,1,1,1,1,1,1,5,4,1,1,3,1,1,1,1,1,1,1,1,1,1,1
1,1,1,1,1,1,1,1,1,1,1,5,4,1,1,3,1,1,1,1,1,1,1,1,1,1,1
1,1,1,1,1,1,1,1,1,1,1,5,4,1,1,3,1,1,1,1,1,1,1,1,1,1,1
1,1,1,1,1,1,1,1,1,1,1,5,4,1,1,1,1,1,1,1,1,1,1,1,1,1,1
1,1,1,1,1,1,1,1,1,1,1,5,4,1,1,1,1,1,1,1,1,1,1,1,1,1,1
1,1,1,1,1,1,1,1,1,1,1,5,1,1,1,1,1,1,1,1,1,1,1,1,1,1,1
1,1,1,1,1,1,1,1,1,1,1,1,1,1,1,1,1,1,1,1,1,1,1,1,1,1,1
1,1,1,1,1,1,1,1,1,1,1,6,1,1,1,1,1,1,1,1,1,1,1,1,1,1,1
1,1,1,1,1,1,1,1,1,1,1,1,1,1,1,1,1,1,1,1,1,1,1,1,1,1,1
1,1,1,1,1,1,1,1,1,1,1,1,1,1,1,1,1,1,1,1,1,1,1,1,1,1,1
1,1,1,1,1,1,1,1,1,1,1,1,1,1,1,1,1,1,1,1,1,1,1,1,1,1,1
1,1,1,1,1,1,1,1,1,1,1,1,1,1,1,1,1,1,1,1,1,1,1,1,1,1,1
1,1,1,1,1,1,1,1,1,1,1,1,1,1,1,1,1,1,1,1,1,1,1,1,1,1,1
1,1,1,1,1,1,1,1,1,1,1,1,1,1,1,1,1,1,1,1,1,1,1,1,1,1,1
1,1,1,1,1,1,1,1,1,1,1,1,1,1,1,1,1,1,1,1,1,1,1,1,1,1,1
1,1,1,1,1,1,1,1,1,1,1,1,1,1,1,1,1,1,1,1,1,1,1,1,1,1,1
1,1,1,1,1,1,1,1,1,1,1,1,1,1,1,1,1,1,1,1,1,1,1,1,1,1,1
1,1,1,1,1,1,1,1,1,1,1,1,1,1,1,1,1,1,1,1,1,1,1,1,1,1,1
1,1,1,1,1,1,1,1,1,1,1,1,1,1,1,1,1,1,1,1,1,1,1,1,1,1,1
1,1,1,1,1,1,1,1,1,1,1,1,1,1,1,1,1,1,1,1,1,1,1,1,1,1,1
1,1,1,1,1,1,1,1,1,1,1,1,1,1,1,1,1,1,1,1,1,1,1,1,1,1,1
1,1,1,1,1,1,1,1,1,1,1,1,1,1,1,1,1,1,1,1,1,1,1,1,1,1,1
1,1,1,1,1,1,1,1,1,1,1,1,1,1,1,1,1,1,1,1,1,1,1,1,1,1,1
1,1,1,1,1,1,1,1,1,1,1,1,1,1,1,1,1,1,1,1,1,1,1,1,1,1,1
endlayer

layer
1,1,1,1,1,1,1,1,1,1,1,1,1,1,1,1,1,1,1,1,1,1,1,1,1,1,1
1,1,1,1,1,1,1,1,1,1,1,1,1,1,1,1,1,1,1,1,1,1,1,1,1,1,1
1,1,1,1,1,1,1,1,1,1,1,1,1,1,1,1,1,1,1,1,1,1,1,1,1,1,1
1,1,1,1,1,1,1,1,1,1,1,1,1,1,1,1,1,1,1,1,1,1,1,1,1,1,1
1,1,1,1,1,1,1,1,1,1,1,1,1,1,1,1,1,1,1,1,1,1,1,1,1,1,1
1,1,1,1,1,1,1,1,1,1,1,1,1,1,1,1,1,1,1,1,1,1,1,1,1,1,1
1,1,1,1,1,1,1,1,1,1,1,1,1,1,1,1,1,1,1,1,1,1,1,1,1,1,1
1,1,1,1,1,1,1,1,1,1,1,1,1,1,1,1,1,1,1,1,1,1,1,1,1,1,1
1,1,1,1,1,1,1,1,1,1,1,1,1,1,1,1,1,1,1,1,1,1,1,1,1,1,1
1,1,1,1,1,1,1,1,1,1,1,1,1,1,1,1,1,1,1,1,1,1,1,1,1,1,1
1,1,1,1,1,1,1,1,1,1,1,1,1,1,1,1,1,1,1,1,1,1,1,1,1,1,1
1,1,1,1,1,1,1,1,1,1,1,1,1,1,1,1,1,1,1,1,1,1,1,1,1,1,1
1,1,1,1,1,1,1,1,1,1,1,1,1,1,1,1,1,1,1,1,1,1,1,1,1,1,1
1,1,1,1,1,1,1,1,1,1,1,1,1,1,1,1,1,1,1,1,1,1,1,1,1,1,1
1,1,1,1,1,1,1,1,1,1,1,1,1,1,1,1,1,1,1,1,1,1,1,1,1,1,1
1,1,1,1,1,1,1,1,1,1,1,1,1,4,4,3,1,1,1,1,1,1,1,1,1,1,1
1,1,1,1,1,1,1,1,1,1,1,1,4,4,4,3,1,1,1,1,1,1,1,1,1,1,1
1,1,1,1,1,1,1,1,1,1,1,4,4,4,4,3,2,1,1,1,1,1,1,1,1,1,1
1,1,1,1,1,1,1,1,1,1,4,4,4,1,1,3,1,1,1,1,1,1,1,1,1,1,1
1,1,1,1,1,1,1,1,1,5,4,4,1,1,1,3,1,1,1,1,1,1,1,1,1,1,1
1,1,1,1,1,1,1,1,1,5,4,4,1,1,1,3,1,1,1,1,1,1,1,1,1,1,1
1,1,1,1,1,1,1,1,1,5,4,4,3,3,3,3,1,1,1,1,1,1,1,1,1,1,1
1,1,1,1,1,1,1,1,1,5,4,4,1,1,1,3,1,1,1,1,1,1,1,1,1,1,1
1,1,1,1,1,1,1,1,1,5,4,4,1,1,8,3,1,1,1,1,1,1,1,1,1,1,1
1,1,1,1,1,1,1,1,1,5,4,4,10,9,1,3,1,1,1,1,1,1,1,1,1,1,1
1,1,1,1,1,1,1,1,1,5,4,4,11,11,1,3,1,1,1,1,1,1,1,1,1,1,1
1,1,1,1,1,1,1,1,1,5,4,4,11,11,1,3,1,1,1,1,1,1,1,1,1,1,1
1,1,1,1,1,1,1,1,1,5,4,4,11,11,1,3,1,1,1,1,1,1,1,1,1,1,1
1,1,1,1,1,1,1,1,1,5,4,4,12,12,1,3,1,1,1,1,1,1,1,1,1,1,1
1,1,1,1,1,1,1,1,1,5,4,4,1,1,1,3,1,1,1,1,1,1,1,1,1,1,1
1,1,1,1,1,1,1,1,1,5,4,4,3,3,3,3,1,1,1,1,1,1,1,1,1,1,1
1,1,1,1,1,1,1,1,1,5,4,4,1,1,1,3,1,1,1,1,1,1,1,1,1,1,1
1,1,1,1,1,1,1,1,1,5,4,4,1,1,13,3,1,1,1,1,1,1,1,1,1,1,1
1,1,1,1,1,1,1,1,1,5,4,4,1,1,1,3,1,1,1,1,1,1,1,1,1,1,1
1,1,1,1,1,1,1,1,1,5,4,4,13,1,1,3,1,1,1,1,1,1,1,1,1,1,1
1,1,1,1,1,1,1,6,6,5,4,4,1,1,1,3,1,1,1,1,1,1,1,1,1,1,1
1,1,1,1,1,1,1,1,1,5,4,4,7,1,1,3,1,1,1,1,1,1,1,1,1,1,1
1,1,1,1,1,1,1,1,1,5,4,4,1,1,1,3,1,1,1,1,1,1,1,1,1,1,1
1,1,1,1,1,1,1,1,1,5,4,4,1,1,13,3,1,1,1,1,1,1,1,1,1,1,1
1,1,1,1,1,1,1,1,1,5,4,4,1,13,13,3,1,1,1,1,1,1,1,1,1,1,1
1,1,1,1,1,1,1,1,1,5,4,4,3,1,3,3,1,1,1,1,1,1,1,1,1,1,1
1,1,1,1,1,1,1,1,1,5,4,4,1,1,1,1,1,1,1,1,1,1,1,1,1,1,1
1,1,1,1,1,1,1,1,1,5,4,4,1,1,1,1,1,1,1,1,1,1,1,1,1,1,1
1,1,1,1,1,1,1,1,1,5,4,1,1,1,1,1,1,1,1,1,1,1,1,1,1,1,1
1,1,1,1,1,1,1,1,1,5,4,1,1,1,1,1,1,1,1,1,1,1,1,1,1,1,1
1,1,1,1,1,1,1,1,1,5,1,1,3,1,1,1,1,1,1,1,1,1,1,1,1,1,1
1,1,1,1,1,1,1,1,1,5,1,1,1,1,1,1,1,1,1,1,1,1,1,1,1,1,1
1,1,1,1,1,1,1,1,1,5,1,3,1,1,1,1,1,1,1,1,1,1,1,1,1,1,1
1,1,1,1,1,1,1,1,1,1,1,1,1,1,1,1,1,1,1,1,1,1,1,1,1,1,1
1,1,1,1,1,1,1,1,1,1,1,1,1,1,1,1,1,1,1,1,1,1,1,1,1,1,1
1,1,1,1,1,1,1,1,1,1,1,1,1,1,1,1,1,1,1,1,1,1,1,1,1,1,1
1,1,1,1,1,1,1,1,1,1,1,1,1,1,1,1,1,1,1,1,1,1,1,1,1,1,1
1,1,1,1,1,1,1,1,1,1,1,1,1,1,1,1,1,1,1,1,1,1,1,1,1,1,1
1,1,1,1,1,1,1,1,1,1,1,1,1,1,1,1,1,1,1,1,1,1,1,1,1,1,1
1,1,1,1,1,1,1,1,1,1,1,1,1,1,1,1,1,1,1,1,1,1,1,1,1,1,1
1,1,1,1,1,1,1,1,1,1,1,1,1,1,1,1,1,1,1,1,1,1,1,1,1,1,1
1,1,1,1,1,1,1,1,1,1,1,1,1,1,1,1,1,1,1,1,1,1,1,1,1,1,1
1,1,1,1,1,1,1,1,1,1,1,1,1,1,1,1,1,1,1,1,1,1,1,1,1,1,1
1,1,1,1,1,1,1,1,1,1,1,1,1,1,1,1,1,1,1,1,1,1,1,1,1,1,1
1,1,1,1,1,1,1,1,1,1,1,1,1,1,1,1,1,1,1,1,1,1,1,1,1,1,1
1,1,1,1,1,1,1,1,1,1,1,1,1,1,1,1,1,1,1,1,1,1,1,1,1,1,1
1,1,1,1,1,1,1,1,1,1,1,1,1,1,1,1,1,1,1,1,1,1,1,1,1,1,1
1,1,1,1,1,1,1,1,1,1,1,1,1,1,1,1,1,1,1,1,1,1,1,1,1,1,1
endlayer

layer
1,1,1,1,1,1,1,1,1,1,1,1,1,1,1,1,1,1,1,1,1,1,1,1,1,1,1
1,1,1,1,1,1,1,1,1,1,1,1,1,1,1,1,1,1,1,1,1,1,1,1,1,1,1
1,1,1,1,1,1,1,1,1,1,1,1,1,1,1,1,1,1,1,1,1,1,1,1,1,1,1
1,1,1,1,1,1,1,1,1,1,1,1,1,1,1,1,1,1,1,1,1,1,1,1,1,1,1
1,1,1,1,1,1,1,1,1,1,1,1,1,1,1,1,1,1,1,1,1,1,1,6,1,1,1
1,1,1,1,1,1,1,1,1,1,1,1,1,1,1,1,1,1,1,1,1,1,1,1,1,1,1
1,1,1,1,1,1,1,1,1,1,1,1,1,1,1,1,1,1,1,1,1,1,1,1,1,1,1
1,1,1,1,1,1,1,1,1,1,1,1,1,1,1,1,1,1,1,1,1,1,1,1,1,1,1
1,1,1,1,1,1,1,1,1,1,1,1,1,1,1,1,1,1,1,1,1,1,1,1,1,1,1
1,1,1,1,1,1,1,1,1,6,1,1,1,1,1,1,1,1,1,1,1,1,1,1,1,1,1
1,1,1,1,1,1,1,1,1,1,1,1,1,1,1,1,1,1,1,1,1,1,1,1,1,1,1
1,1,1,1,1,1,1,1,1,1,1,1,1,1,1,1,1,1,1,1,1,1,1,1,1,1,1
1,1,1,1,1,1,1,1,1,1,1,1,1,1,1,1,1,1,6,1,1,1,1,1,1,1,1
1,1,1,1,1,1,1,1,1,1,1,1,1,1,1,1,1,1,1,1,1,1,1,1,1,1,1
1,1,1,1,1,1,1,1,1,1,1,1,1,4,4,3,2,1,1,1,1,1,1,1,1,1,1
1,1,1,1,1,1,1,1,1,1,1,1,4,4,4,3,2,1,1,1,1,1,1,1,1,1,1
1,1,1,1,1,1,1,1,1,1,1,4,4,1,1,3,1,1,1,1,1,1,1,1,1,1,1
1,1,1,1,1,1,1,1,1,1,4,4,1,1,1,3,1,1,1,1,1,1,6,1,1,1,1
1,1,1,1,1,1,1,1,1,4,4,1,1,1,1,3,1,1,1,1,1,1,1,1,1,1,1
1,1,1,1,1,1,1,1,4,4,4,1,1,1,1,3,1,1,1,1,1,1,1,1,1,1,1
1,1,1,1,1,1,1,5,4,1,1,1,1,1,1,3,1,1,1,1,1,1,1,1,1,1,1
1,1,1,6,1,1,1,5,4,3,3,3,3,3,3,3,1,1,1,1,1,1,1,1,1,1,1
1,1,1,1,1,1,1,5,4,4,3,1,1,1,1,3,1,1,1,1,1,1,1,1,1,1,1
1,1,1,1,1,1,1,5,4,4,3,1,1,1,1,3,1,1,1,1,1,1,1,1,1,1,1
1,1,1,1,1,1,1,5,4,6,3,1,1,1,1,3,1,1,1,1,1,1,1,1,1,1,1
1,1,1,1,1,1,1,5,4,4,3,1,1,1,1,3,1,1,1,1,1,1,1,1,1,1,1
1,1,1,1,1,1,1,5,4,4,3,1,1,1,1,3,1,1,1,1,14,1,1,1,1,1,1
1,1,1,1,1,1,1,5,4,4,3,1,1,1,1,3,1,6,1,1,14,1,1,1,1,1,1
1,1,1,1,1,1,1,5,4,4,3,1,1,1,1,3,1,1,1,1,14,1,1,1,1,1,1
1,1,1,6,1,1,1,5,4,4,3,1,1,1,1,3,1,1,1,14,1,1,1,1,1,1,1
1,1,1,1,1,1,1,5,4,4,3,3,3,3,3,3,1,1,1,14,1,1,1,1,1,1,1
1,1,1,1,1,1,1,5,4,4,1,1,1,1,1,3,1,1,1,14,1,1,1,1,1,1,1
1,1,1,1,1,1,1,5,4,4,1,1,1,1,1,3,1,1,1,1,1,1,1,1,6,1,1
1,1,1,1,1,1,1,5,4,4,1,1,1,1,1,3,1,1,1,1,1,1,1,1,1,1,1
1,1,1,1,1,1,1,5,1,1,1,1,1,1,1,3,1,1,6,1,1,1,1,1,1,1,1
1,1,1,1,1,1,1,1,1,1,1,1,1,1,1,3,1,1,1,1,1,1,1,1,1,1,1
1,1,1,6,1,1,1,5,4,4,7,1,1,1,1,3,1,1,1,1,1,1,1,1,1,1,1
1,1,1,1,1,1,1,5,4,4,1,1,1,1,1,3,1,1,1,1,1,1,1,1,1,1,1
1,1,1,1,1,1,1,5,4,4,1,1,1,1,1,3,1,1,1,1,1,1,1,1,1,1,1
1,1,1,1,1,1,1,5,4,4,1,1,1,1,13,3,6,1,1,1,1,1,1,1,1,1,1
1,1,1,1,1,1,1,5,4,4,1,1,1,1,3,3,1,1,1,1,1,1,13,1,1,1,1
1,1,1,1,1,1,1,5,4,4,1,1,1,1,1,1,1,1,1,1,1,1,1,1,1,1,1
1,1,1,1,1,1,1,5,4,1,1,1,1,1,1,1,1,1,1,1,1,1,1,1,1,1,1
1,1,1,1,1,1,1,5,4,1,1,1,1,1,1,1,1,1,1,1,1,1,1,1,1,1,1
1,1,1,1,1,1,1,5,4,1,1,1,1,1,1,1,1,1,1,1,1,1,1,1,1,1,1
1,1,1,1,1,1,1,5,1,1,1,1,1,1,1,1,1,1,1,1,1,1,6,1,1,1,1
1,1,1,1,1,1,1,1,1,1,1,1,1,1,1,1,1,1,1,1,1,1,1,1,1,1,1
1,1,1,1,1,6,1,1,1,3,1,1,1,1,1,1,1,1,1,1,1,1,1,1,1,1,1
1,1,1,1,1,1,1,1,1,1,1,1,3,1,1,1,1,1,1,1,1,1,1,1,1,1,1
1,1,1,1,1,1,1,1,1,1,1,1,1,1,1,1,1,1,1,1,1,1,1,1,1,1,1
1,1,1,1,1,1,1,1,1,1,1,1,1,1,1,1,1,1,1,1,1,1,1,1,1,1,1
1,1,1,1,1,1,1,1,1,4,1,1,1,1,1,1,6,1,1,1,1,1,1,1,1,1,1
1,1,1,1,1,1,1,1,1,1,4,1,1,1,4,1,1,1,1,1,1,1,1,1,1,1,1
1,1,1,1,1,1,1,1,1,1,1,1,11,1,3,1,1,1,1,1,1,1,1,1,1,1,1
1,1,1,1,1,1,1,1,1,1,1,1,1,1,1,1,1,1,1,1,1,1,1,1,1,1,1
1,1,1,1,1,1,1,1,1,1,1,1,4,1,1,1,1,1,1,1,1,1,1,1,1,1,1
1,1,1,1,1,1,1,1,1,1,1,3,6,1,1,1,1,1,1,1,1,1,1,1,1,1,1
1,1,1,1,1,1,1,1,1,1,1,1,1,1,1,1,1,1,1,1,6,1,1,1,1,1,1
1,1,1,1,1,1,1,1,1,1,1,1,1,1,1,2,1,1,1,1,1,1,1,1,1,1,1
1,1,1,1,1,6,1,1,1,1,4,1,1,1,1,1,1,1,1,1,1,1,1,1,1,1,1
1,1,1,1,1,1,1,1,1,1,1,1,1,1,4,4,1,1,1,1,1,1,1,1,1,1,1
1,1,1,1,1,1,1,1,1,1,1,1,1,1,1,1,1,1,1,1,1,1,1,1,1,1,1
1,1,1,1,1,1,1,1,1,1,1,1,1,1,1,1,1,1,1,1,1,1,1,1,1,1,1
endlayer

layer
0,1,1,1,1,1,1,1,1,1,1,1,1,1,1,1,1,1,1,1,1,1,1,1,1,1,0
0,1,1,1,1,1,1,1,1,1,1,1,1,1,1,1,1,1,1,1,1,1,1,1,1,1,0
0,1,1,1,1,1,1,1,1,1,1,1,1,1,1,1,1,1,1,1,1,1,1,1,1,1,0
0,1,1,1,1,1,1,1,1,1,1,1,1,1,1,1,1,1,1,1,1,1,1,1,1,1,0
0,1,1,1,1,1,1,1,1,1,1,1,1,1,1,1,1,1,1,1,1,1,1,1,1,1,0
0,1,1,1,1,1,1,1,1,1,1,1,1,1,1,1,1,1,1,1,1,1,1,1,1,1,0
0,1,1,1,1,1,1,1,1,1,1,1,1,1,1,1,1,1,1,1,1,1,1,1,1,1,0
0,1,1,1,1,1,1,1,1,1,1,1,1,1,1,1,1,1,1,1,1,1,1,1,1,1,0
0,1,1,1,1,1,1,1,1,1,1,1,1,1,1,1,1,1,1,1,1,1,1,1,1,1,0
0,1,1,1,1,1,1,1,1,1,1,1,1,1,1,1,1,1,1,1,1,1,1,1,1,1,0
0,1,1,1,1,1,1,1,1,1,1,1,1,1,1,1,1,1,1,1,1,1,1,1,1,1,0
0,1,1,1,1,1,1,1,1,1,1,1,1,1,1,1,1,1,1,1,1,1,1,1,1,1,0
0,1,1,1,1,1,1,1,1,1,1,1,1,1,4,3,2,1,1,1,1,1,1,1,1,1,0
0,1,1,1,1,1,1,1,1,1,1,1,1,4,4,3,2,1,1,1,1,1,1,1,1,1,0
0,1,1,1,1,1,1,1,1,1,1,1,4,4,1,3,1,1,1,1,1,1,1,1,1,1,0
0,1,1,1,1,1,1,1,1,1,1,4,4,1,1,3,1,1,1,1,1,1,1,1,1,1,0
0,1,1,1,1,1,1,1,1,1,4,4,1,1,1,3,1,1,1,1,1,1,1,1,1,1,0
0,1,1,1,1,1,1,1,1,4,4,1,1,1,1,3,1,1,1,1,1,1,1,1,1,1,0
0,1,1,1,1,1,1,1,4,4,1,1,1,1,1,3,1,1,1,1,1,1,1,1,1,1,0
0,1,1,1,1,1,1,4,4,1,1,1,1,1,1,3,1,1,1,1,1,1,1,1,1,1,0
0,1,1,1,1,1,1,4,1,1,1,1,1,1,1,3,1,1,1,1,1,1,1,1,1,1,0
0,1,1,1,1,1,5,4,3,3,3,3,3,3,3,3,3,1,1,1,1,1,1,1,1,1,0
0,1,1,1,1,1,5,4,13,15,3,1,1,1,1,3,3,1,1,1,1,1,1,1,1,1,0
0,1,1,1,1,1,5,4,1,13,3,1,1,1,1,3,3,1,1,1,1,1,1,1,1,1,0
0,1,1,1,1,1,5,4,1,1,3,1,1,1,1,3,3,1,1,1,1,1,1,1,1,1,0
0,1,1,1,1,1,5,4,1,1,3,1,1,1,1,3,1,1,1,1,1,1,1,1,1,1,0
0,1,1,1,1,1,5,4,1,1,3,1,1,1,1,3,1,1,1,1,16,1,1,1,1,1,0
0,1,1,1,1,1,5,4,18,1,3,1,1,1,1,3,17,1,1,1,1,1,1,1,1,1,0
0,1,1,1,1,1,5,4,1,1,3,1,1,1,1,3,3,1,1,1,19,1,1,1,1,1,0
0,1,1,1,1,1,5,4,13,1,3,1,1,1,1,3,3,1,1,1,1,1,1,1,1,1,0
0,1,1,1,1,1,5,4,1,3,3,3,3,3,3,3,3,1,1,1,1,1,1,1,1,1,0
0,1,1,1,1,1,5,4,1,13,1,1,1,1,1,3,3,1,1,1,1,1,1,1,1,1,0
0,1,1,1,1,1,5,4,1,1,1,1,1,1,1,3,3,1,1,1,1,1,1,1,1,1,0
0,1,1,1,1,1,5,4,1,1,1,1,1,1,1,3,3,1,1,1,1,1,1,1,1,1,0
0,1,1,1,1,1,5,4,1,1,1,1,1,1,1,3,3,1,1,1,1,1,1,1,1,1,0
0,1,1,1,1,1,1,1,1,1,1,1,1,1,20,3,3,1,1,1,1,1,1,1,1,1,0
0,1,1,1,1,1,5,4,13,1,1,1,1,1,20,3,21,1,1,1,1,1,1,1,1,1,0
0,1,1,1,1,1,5,4,1,1,1,1,1,1,1,3,1,1,1,1,1,1,1,1,1,1,0
0,1,1,1,1,1,5,4,1,1,1,1,1,1,1,3,1,1,1,1,1,13,1,1,1,1,0
0,1,1,1,1,1,5,4,1,1,1,1,1,1,13,3,1,1,1,13,1,1,1,1,1,1,0
0,1,1,1,1,1,5,4,1,1,1,1,1,3,3,3,1,1,1,1,1,1,1,1,1,1,0
0,1,1,1,1,1,5,4,2,1,1,1,1,1,1,3,1,1,1,1,1,1,1,1,1,1,0
0,1,1,1,1,1,5,4,1,1,1,1,1,1,1,3,1,1,1,1,1,1,1,1,1,1,0
0,1,1,1,1,1,5,4,1,1,1,1,1,1,1,1,1,1,1,1,1,1,1,1,1,1,0
0,1,1,1,1,1,1,1,1,1,1,1,1,1,1,1,1,1,1,1,1,1,1,1,1,1,0
0,1,1,1,1,1,1,1,1,1,1,1,1,1,1,1,1,1,1,1,1,1,1,1,1,1,0
0,1,1,1,1,1,1,1,1,1,1,1,1,1,1,1,1,1,1,1,1,1,1,1,1,1,0
0,1,1,1,1,1,1,1,1,1,1,1,1,1,1,1,1,1,1,1,1,1,1,1,1,1,0
0,1,1,1,1,1,1,1,1,1,1,1,1,1,1,1,1,4,1,1,1,4,1,1,1,1,0
0,1,1,1,1,1,1,1,3,1,1,1,1,1,1,1,1,1,1,1,1,1,1,1,1,1,0
0,1,1,1,1,1,1,1,1,1,1,1,1,1,1,1,1,1,1,1,1,1,1,1,1,1,0
0,1,1,1,13,1,1,1,1,1,1,1,1,1,1,1,1,1,1,1,1,1,1,1,1,1,0
0,1,1,1,1,1,1,1,1,1,22,1,1,3,1,1,1,22,1,1,1,1,1,1,1,1,0
0,1,1,1,1,1,1,3,1,1,1,1,1,1,1,1,1,1,1,1,1,23,1,1,1,1,0
0,1,1,1,1,1,1,1,1,1,1,1,1,1,1,1,1,1,3,1,1,1,1,1,1,1,0
0,1,1,1,1,1,1,1,1,1,1,1,1,1,1,1,1,13,1,1,1,1,1,1,1,1,0
0,1,1,4,22,1,1,1,1,1,1,3,1,1,3,1,1,1,1,1,1,1,1,1,1,1,0
0,1,1,1,1,1,1,1,13,1,3,1,1,1,1,1,1,11,1,1,1,1,1,3,1,1,0
0,1,1,1,1,1,1,1,1,1,1,1,1,1,1,1,1,1,1,1,1,1,1,1,1,1,0
0,1,1,1,1,1,1,1,1,1,1,1,1,3,1,1,1,1,3,1,1,1,1,1,1,1,0
0,1,1,1,1,1,1,1,1,1,1,1,1,1,1,1,1,1,1,1,1,1,1,1,1,1,0
0,1,1,1,1,1,1,1,1,1,1,1,1,1,1,1,1,1,2,1,1,1,1,1,1,1,0
0,1,1,1,1,1,1,1,1,1,1,1,1,1,1,1,1,1,1,1,1,1,1,1,1,1,0
endlayer

layer
0,1,1,1,1,1,1,1,1,1,1,1,1,1,1,1,1,1,1,1,1,1,1,1,1,1,0
0,1,1,1,1,1,1,1,1,1,1,1,1,1,1,1,1,1,1,1,1,1,1,1,1,1,0
0,1,1,1,1,1,1,1,1,1,1,1,1,1,1,1,1,1,1,1,1,1,1,1,1,1,0
0,1,1,1,1,1,1,1,1,1,1,1,1,1,1,1,1,1,1,1,1,1,1,1,1,1,0
0,1,1,1,1,1,1,1,1,1,1,1,1,1,1,1,1,1,1,1,1,1,1,1,1,1,0
0,1,1,1,1,1,1,1,1,1,1,1,1,1,1,1,1,1,1,1,1,1,1,1,1,1,0
0,1,1,1,1,1,1,1,1,1,1,1,1,1,1,1,1,1,1,1,1,1,1,1,1,1,0
0,1,1,1,1,1,1,1,1,1,1,1,1,1,1,1,1,1,1,1,1,1,1,1,1,1,0
0,1,1,1,1,1,1,1,1,1,1,1,1,1,1,1,1,1,1,1,1,1,1,1,1,1,0
0,1,1,1,1,1,1,1,1,1,1,1,1,1,1,1,1,1,1,1,1,1,1,1,1,1,0
0,1,1,1,1,1,1,1,1,1,1,1,1,1,4,3,2,1,1,1,1,1,1,1,1,1,0
0,1,1,1,1,1,1,1,1,1,1,1,1,1,4,3,2,1,1,1,1,1,1,1,1,1,0
0,1,1,1,1,1,1,1,1,1,1,1,1,4,4,3,2,1,1,1,1,1,1,1,1,1,0
0,1,1,1,1,1,1,1,1,1,1,1,4,4,1,3,1,1,1,1,1,1,1,1,1,1,0
0,1,1,1,1,1,1,1,1,1,1,4,4,1,1,3,1,1,1,1,1,1,1,1,1,1,0
0,1,1,1,1,1,1,1,1,1,4,4,1,1,1,3,1,1,1,1,1,1,1,1,1,1,0
0,1,1,1,1,1,1,1,1,4,4,1,1,1,1,3,1,1,1,1,1,1,1,1,1,1,0
0,1,1,1,1,1,1,1,4,4,1,1,1,1,1,3,1,1,1,1,1,1,1,1,1,1,0
0,1,1,1,1,1,1,4,4,1,1,1,1,1,1,3,1,1,1,1,1,1,1,1,1,1,0
0,1,1,1,1,1,4,4,1,1,1,1,1,1,1,3,3,1,1,1,1,1,1,1,1,1,0
0,1,1,1,1,1,4,1,1,1,1,1,1,1,1,3,3,1,1,1,1,1,1,1,1,1,0
0,1,1,1,1,5,4,3,3,3,3,3,3,3,3,3,3,3,1,1,1,1,1,1,1,1,0
0,1,1,1,1,5,4,13,13,1,3,1,1,1,1,3,3,3,1,1,1,1,1,1,1,1,0
0,1,1,1,1,5,4,1,1,1,3,1,1,1,1,3,3,3,1,1,1,1,1,1,1,1,0
0,1,1,1,1,5,4,1,1,1,3,1,1,1,1,3,3,1,1,1,1,1,1,1,1,1,0
0,1,1,1,1,5,4,24,1,1,3,1,1,1,1,3,1,1,1,1,1,1,1,1,1,1,0
0,1,1,1,1,5,4,1,1,1,3,1,1,1,1,3,1,1,1,1,1,1,1,1,1,1,0
0,1,1,1,1,5,4,13,13,13,3,1,1,1,1,3,1,1,1,1,1,1,1,1,1,1,0
0,1,1,1,1,5,4,1,1,1,3,1,1,1,1,3,3,1,1,1,1,1,1,1,1,1,0
0,1,1,1,1,5,4,1,1,1,3,1,1,1,1,3,3,3,1,1,1,1,1,1,1,1,0
0,1,1,1,1,5,4,1,1,3,3,3,3,3,3,3,3,3,1,1,1,1,1,1,1,1,0
0,1,1,1,1,5,4,1,1,1,1,1,1,1,1,3,3,3,1,1,1,1,1,1,1,1,0
0,1,1,1,1,5,4,1,1,1,1,1,1,1,1,3,3,3,1,1,1,1,1,1,1,1,0
0,1,1,1,1,5,4,1,1,1,1,1,1,1,1,3,3,3,1,1,1,1,1,1,1,1,0
0,1,1,1,1,5,4,1,1,1,1,1,1,1,1,3,3,3,1,1,1,1,1,1,1,1,0
0,1,1,1,1,5,4,1,1,1,1,1,1,1,1,3,3,1,1,1,1,1,1,1,1,1,0
0,1,1,1,1,5,4,1,1,1,1,1,1,1,1,3,1,1,1,1,1,1,1,1,1,1,0
0,1,1,1,1,5,4,1,1,1,1,1,1,1,1,3,1,1,1,1,1,1,1,1,1,1,0
0,1,1,1,1,5,4,1,1,1,1,1,1,1,1,3,1,1,1,1,1,1,1,1,1,1,0
0,1,1,1,1,5,4,1,1,1,1,1,1,1,1,3,1,1,1,1,1,1,1,1,1,1,0
0,1,1,1,1,5,4,1,1,1,1,1,1,3,3,3,1,1,1,1,1,1,1,1,1,1,0
0,1,1,1,1,5,4,1,1,1,1,1,1,1,1,1,1,1,1,1,1,1,1,1,1,1,0
0,1,1,1,1,5,4,1,1,1,1,1,1,1,1,1,1,1,1,1,1,1,1,1,1,1,0
0,1,1,1,1,5,4,1,1,1,1,1,1,1,1,1,1,1,1,1,1,1,1,1,1,1,0
0,1,1,1,1,5,1,1,1,1,1,1,1,1,1,1,1,1,1,1,1,1,1,1,1,1,0
0,1,1,1,1,5,1,1,1,1,1,1,1,1,1,1,1,1,1,1,1,1,1,1,1,1,0
0,1,1,1,1,1,1,1,1,1,1,1,1,1,1,1,1,1,1,1,1,1,1,1,1,1,0
0,1,1,1,1,1,1,1,1,1,1,1,1,1,1,1,1,1,1,1,1,1,1,1,1,1,0
0,1,1,1,1,1,1,1,1,1,1,1,1,1,1,1,1,1,1,1,1,1,1,1,1,1,0
0,1,1,1,1,1,1,1,1,1,1,1,1,1,1,1,1,1,1,1,1,1,1,1,1,1,0
0,1,1,1,1,1,1,1,1,1,1,1,1,1,1,1,1,1,1,1,1,1,1,1,1,1,0
0,1,1,1,1,1,1,1,1,1,1,1,1,1,1,1,1,1,1,1,1,1,1,1,1,1,0
0,1,1,1,1,1,1,1,1,1,1,1,1,1,1,1,1,1,1,1,1,1,1,1,1,1,0
0,1,1,1,1,1,1,1,1,1,1,1,1,1,1,1,1,1,1,1,1,1,1,1,1,1,0
0,1,1,1,1,1,1,1,1,1,1,1,1,1,1,1,1,1,3,3,1,1,1,1,1,1,0
0,1,1,1,1,1,1,1,1,1,1,1,1,1,1,1,1,1,1,1,1,1,1,1,1,1,0
0,1,1,1,1,1,1,1,1,1,1,1,1,1,1,1,1,1,1,1,1,1,1,1,1,1,0
0,1,1,1,1,1,1,1,1,1,1,1,1,1,1,1,1,1,1,1,1,1,1,1,1,1,0
0,1,1,1,1,1,1,1,1,1,1,1,1,1,1,1,1,1,1,1,1,1,1,1,1,1,0
0,1,1,1,1,1,1,1,1,1,1,1,1,1,1,1,1,1,1,1,1,1,1,1,1,1,0
0,1,1,1,1,1,1,1,1,1,1,1,1,1,1,1,1,1,1,1,1,1,1,1,1,1,0
0,1,1,1,1,1,1,1,1,1,1,1,1,1,1,1,1,1,1,1,1,1,1,1,1,1,0
0,1,1,1,1,1,1,1,1,1,1,1,1,1,1,1,1,1,1,1,1,1,1,1,1,1,0
endlayer

layer
0,1,1,1,1,1,1,1,1,1,1,1,1,1,1,1,1,1,1,1,1,1,1,1,1,1,0
0,1,1,1,1,1,1,1,1,1,1,1,1,1,1,1,1,1,1,1,1,1,1,1,1,1,0
0,1,1,1,1,1,1,1,1,1,1,1,1,1,1,1,1,1,1,1,1,1,1,1,1,1,0
0,1,1,1,1,1,1,1,1,1,1,1,1,1,1,1,1,1,1,1,1,1,1,1,1,1,0
0,1,1,1,1,1,1,1,1,1,1,1,1,1,1,1,1,1,1,1,1,1,1,1,1,1,0
0,1,1,1,1,1,1,1,1,1,1,1,1,1,1,1,1,1,1,1,1,1,1,1,1,1,0
0,1,1,1,1,1,1,1,1,1,1,1,1,1,1,1,1,1,1,1,1,1,1,1,1,1,0
0,1,1,1,1,1,1,1,1,1,1,1,1,1,1,1,1,1,1,1,1,1,1,1,1,1,0
0,1,1,1,1,1,1,1,1,1,1,1,1,1,1,3,2,1,1,1,1,1,1,1,1,1,0
0,1,1,1,1,1,1,1,1,1,1,1,1,1,4,3,2,1,1,1,1,1,1,1,1,1,0
0,1,1,1,1,1,1,1,1,1,1,1,1,1,4,3,2,1,1,1,1,1,1,1,1,1,0
0,1,1,1,1,1,1,1,1,1,1,1,1,4,4,3,25,1,1,1,1,1,1,1,1,1,0
0,1,1,1,1,1,1,1,1,1,1,1,4,4,1,3,1,1,1,1,1,1,1,1,1,1,0
0,1,1,1,1,1,1,1,1,1,1,4,4,1,1,3,1,1,1,1,1,1,1,1,1,1,0
0,1,1,1,1,1,1,1,1,1,4,4,1,1,1,3,1,1,1,1,1,1,1,1,1,1,0
0,1,1,1,1,1,1,1,1,4,4,1,1,1,1,3,1,1,1,1,1,1,1,1,1,1,0
0,1,1,1,1,1,1,1,4,4,1,1,1,1,1,3,1,1,1,1,1,1,1,1,1,1,0
0,1,1,1,1,1,1,4,4,1,1,1,1,1,1,3,1,1,1,1,1,1,1,1,1,1,0
0,1,1,1,1,1,4,4,1,1,1,1,1,1,1,3,3,1,1,1,1,1,1,1,1,1,0
0,1,1,1,1,1,4,1,1,1,1,1,1,1,1,3,3,1,1,1,1,1,1,1,1,1,0
0,1,1,1,1,4,4,1,1,1,1,1,1,1,1,3,3,3,9,1,1,1,1,1,1,1,0
0,1,1,1,1,4,3,3,3,3,3,3,3,3,3,3,3,3,3,1,1,1,1,1,1,1,0
0,1,1,1,1,4,13,1,1,1,3,1,1,1,1,3,3,3,3,1,1,1,1,1,1,1,0
0,1,1,1,1,4,1,1,1,1,3,1,1,1,1,3,3,3,3,1,1,1,1,1,1,1,0
0,1,1,1,1,4,1,1,1,1,3,1,1,1,1,3,3,25,1,1,1,1,1,1,1,1,0
0,1,1,1,1,4,1,1,1,1,3,1,1,1,1,3,1,1,1,1,1,1,1,1,1,1,0
0,1,1,1,1,4,13,1,1,1,3,1,1,1,1,3,1,1,1,1,1,1,1,1,1,1,0
0,1,1,1,1,4,1,1,1,1,3,1,1,1,1,3,1,1,1,1,1,1,1,1,1,1,0
0,1,1,1,1,4,27,1,1,1,3,1,1,1,1,3,3,9,1,1,1,1,1,1,26,1,0
0,1,1,1,1,4,1,1,1,1,3,1,1,1,1,3,3,3,3,25,1,1,1,1,19,1,0
0,1,1,1,1,4,1,1,1,3,3,3,3,3,3,3,3,3,3,1,1,1,1,1,1,1,0
0,1,1,1,1,4,1,1,1,1,1,1,1,1,1,3,3,3,1,1,1,1,1,1,1,1,0
0,1,1,1,1,4,1,1,1,1,1,1,1,1,1,3,3,1,1,1,1,1,1,1,1,1,0
0,1,1,1,1,4,1,1,1,1,1,1,1,1,1,3,3,1,1,1,1,1,1,1,1,1,0
0,1,1,1,1,4,1,1,1,1,1,1,1,1,1,3,3,3,1,1,19,1,1,19,1,1,0
0,1,1,1,1,4,1,1,1,1,1,1,1,1,1,3,3,1,1,1,1,1,1,1,1,1,0
0,1,1,1,1,4,1,1,1,1,1,1,1,1,1,3,1,1,1,1,1,1,1,1,1,1,0
0,1,1,1,1,4,1,1,1,1,1,1,1,1,1,3,1,1,1,1,1,1,1,1,1,1,0
0,1,1,1,1,4,1,1,1,1,1,1,1,1,1,3,1,1,1,1,1,1,1,1,1,1,0
0,1,1,1,1,4,1,1,1,1,1,1,1,1,1,3,1,1,1,1,1,1,1,1,1,1,0
0,1,1,1,1,4,1,1,1,1,1,1,1,1,3,3,1,1,1,1,1,1,1,1,1,1,0
0,1,1,1,1,4,1,1,1,1,1,1,1,1,1,3,1,1,1,1,1,1,1,1,1,1,0
0,1,1,1,1,4,1,1,1,1,1,1,1,1,1,1,1,1,1,1,1,1,1,1,1,1,0
0,1,1,1,1,4,1,1,1,1,1,1,1,1,1,1,1,1,1,1,1,1,1,1,1,1,0
0,1,1,1,1,1,1,1,1,1,1,1,1,1,1,1,1,1,1,1,1,1,1,1,1,1,0
0,1,1,1,1,1,1,1,1,1,1,1,1,1,1,1,1,1,1,1,1,1,1,1,1,1,0
0,1,1,1,1,1,1,1,1,1,1,1,1,1,1,1,1,1,1,1,1,1,1,1,1,1,0
0,1,1,1,1,1,1,1,1,1,1,1,1,1,1,1,1,1,1,1,1,1,1,1,1,1,0
0,1,1,1,1,1,1,1,1,1,1,1,1,1,1,1,1,1,1,1,1,1,1,1,1,1,0
0,1,1,1,1,1,1,1,1,1,1,1,1,1,1,1,1,1,1,1,1,1,1,1,1,1,0
0,1,1,1,1,1,1,1,1,1,1,1,1,1,1,1,1,1,1,1,1,1,1,1,1,1,0
0,1,1,1,1,1,1,1,1,1,1,1,1,1,1,1,1,1,1,1,1,1,1,1,1,1,0
0,1,1,1,1,1,1,1,1,1,1,1,1,1,1,1,1,1,1,1,1,1,1,1,1,1,0
0,1,1,1,1,1,1,1,1,1,1,1,1,1,1,1,1,1,1,1,1,1,1,1,1,1,0
0,1,1,1,1,1,1,1,1,1,1,1,1,1,1,1,1,1,1,1,1,1,1,1,1,1,0
0,1,1,1,1,1,1,1,1,1,1,1,1,1,1,1,1,1,1,1,1,1,1,1,1,1,0
0,1,1,1,1,1,1,1,1,1,1,1,1,1,1,1,1,1,1,1,1,1,1,1,1,1,0
0,1,1,1,1,1,1,1,1,1,1,1,1,1,1,1,1,1,1,1,1,1,1,1,1,1,0
0,1,1,1,1,1,1,1,1,1,1,1,1,1,1,1,1,1,1,1,1,1,1,1,1,1,0
0,1,1,1,1,1,1,1,1,1,1,1,1,1,1,1,1,1,1,1,1,1,1,1,1,1,0
0,1,1,1,1,1,1,1,1,1,1,1,1,1,1,1,1,1,1,1,1,1,1,1,1,1,0
0,1,1,1,1,1,1,1,1,1,1,1,1,1,1,1,1,1,1,1,1,1,1,1,1,1,0
0,1,1,1,1,1,1,1,1,1,1,1,1,1,1,1,1,1,1,1,1,1,1,1,1,1,0
endlayer

layer
0,1,1,1,1,1,1,1,1,1,1,1,1,1,1,1,1,1,1,1,1,1,1,1,1,1,0
0,1,1,1,1,1,1,1,1,1,1,1,1,1,1,1,1,1,1,1,1,1,1,1,1,1,0
0,1,1,1,1,1,1,1,1,1,1,1,1,1,1,1,9,1,1,1,1,1,1,1,1,1,0
0,1,1,1,1,1,1,1,1,1,1,1,1,1,1,1,2,1,1,1,1,1,1,1,1,1,0
0,1,1,1,1,1,1,1,1,1,1,1,1,1,1,1,2,1,1,1,1,1,1,1,1,1,0
0,1,1,1,1,1,1,1,1,1,1,1,1,1,1,3,2,1,1,1,1,1,1,1,1,1,0
0,1,1,1,1,1,1,1,1,1,1,1,1,1,1,3,2,1,1,1,1,1,1,1,1,1,0
0,1,1,1,1,1,1,1,1,1,1,1,1,1,3,3,2,1,1,1,1,1,1,1,1,1,0
0,1,1,1,1,1,1,1,1,1,1,1,1,1,3,3,2,1,1,1,1,1,1,1,1,1,0
0,1,1,1,1,1,1,1,1,1,1,1,1,3,4,3,1,1,1,1,1,1,1,1,1,1,0
0,1,1,1,1,1,1,1,1,1,1,1,1,3,1,3,1,1,1,1,1,1,1,1,1,1,0
0,1,1,1,1,1,1,1,1,1,1,1,3,4,1,3,1,1,1,1,1,1,1,1,1,1,0
0,1,1,1,1,1,1,1,1,1,1,3,4,1,1,3,1,1,1,1,1,1,1,1,1,1,0
0,1,1,1,1,1,1,1,1,1,3,4,1,1,1,3,1,1,1,1,1,1,1,1,1,1,0
0,1,1,1,1,1,1,1,1,3,4,1,1,1,1,3,1,1,1,1,1,1,1,1,1,1,0
0,1,1,1,1,1,1,1,3,4,1,1,1,1,1,3,1,1,1,1,1,1,1,1,1,1,0
0,1,1,1,1,1,1,3,4,1,1,1,1,1,1,3,1,1,1,1,1,1,1,1,1,1,0
0,1,1,1,1,1,3,4,1,1,1,1,1,1,1,3,1,1,1,1,1,1,1,1,1,1,0
0,1,1,1,1,1,3,1,1,1,1,1,1,1,1,3,3,1,1,1,1,1,1,1,1,1,0
0,1,1,1,1,3,1,1,1,1,1,1,1,1,1,3,3,1,1,1,1,1,1,1,1,1,0
0,1,1,1,3,4,1,1,1,1,1,1,1,1,1,3,3,3,10,1,1,1,1,1,1,1,0
0,1,1,1,3,4,3,3,3,3,3,1,1,3,3,3,3,3,3,1,1,1,1,1,1,1,0
0,1,1,1,3,4,1,1,1,1,3,1,1,1,1,3,3,3,3,1,1,1,1,1,1,1,0
0,1,1,1,3,4,1,1,1,1,3,1,1,1,1,3,3,3,3,1,1,1,1,1,1,1,0
0,1,1,1,3,4,1,1,1,1,3,1,1,1,1,3,3,1,1,1,1,1,1,1,1,1,0
0,1,1,1,3,4,1,1,1,1,3,1,1,1,1,3,1,1,1,1,1,1,1,1,1,1,0
0,1,1,1,3,4,1,1,1,1,3,1,1,1,1,3,1,1,1,1,1,1,1,1,1,1,0
0,1,1,1,3,4,1,1,1,1,3,28,1,1,1,3,1,1,1,1,1,1,1,1,1,1,0
0,1,1,1,3,4,1,1,1,1,3,1,1,1,1,3,3,1,1,1,1,1,1,1,14,1,0
0,1,1,1,3,4,1,1,1,1,3,1,1,1,1,3,3,3,3,3,1,1,1,1,14,1,0
0,1,1,1,3,4,1,1,3,3,1,1,1,3,3,3,3,3,3,1,1,1,1,1,14,1,0
0,1,1,1,3,4,1,1,1,1,1,1,1,1,1,3,3,3,1,1,1,1,1,1,14,1,0
0,1,1,1,3,4,1,1,1,1,1,1,1,1,1,3,3,1,1,1,1,1,1,1,14,1,0
0,1,1,1,3,4,1,1,1,1,1,1,1,1,1,1,1,1,1,1,1,1,1,1,14,1,0
0,1,1,1,3,4,1,1,1,1,1,1,1,1,1,3,3,29,29,29,29,29,29,29,1,1,0
0,1,1,1,3,4,1,1,1,1,1,1,1,1,1,3,3,1,1,1,1,1,1,1,1,1,0
0,1,1,1,3,4,1,1,1,1,1,1,1,1,1,3,1,1,1,1,1,1,1,1,1,1,0
0,1,1,1,3,4,1,1,1,1,1,1,1,1,1,3,1,1,1,1,1,1,1,1,1,1,0
0,1,1,1,3,4,1,1,1,1,1,1,1,1,1,3,1,1,1,1,1,1,1,1,1,1,0
0,1,1,1,3,4,1,1,1,1,1,1,1,1,1,3,1,1,1,1,1,1,1,1,1,1,0
0,1,1,1,3,4,1,1,1,1,1,1,1,3,3,3,1,1,1,1,1,1,1,1,1,1,0
0,1,1,1,3,4,1,1,1,1,1,1,1,1,1,3,1,1,1,1,1,1,1,1,1,1,0
0,1,1,1,3,4,1,1,1,1,1,1,1,1,1,1,1,1,1,1,1,1,1,1,1,1,0
0,1,1,1,3,1,1,1,1,1,1,1,1,1,1,1,1,1,1,1,1,1,1,1,1,1,0
0,1,1,1,3,1,1,1,1,1,1,1,1,1,1,1,1,1,1,1,1,1,1,1,1,1,0
0,1,1,1,3,1,1,1,1,1,1,1,1,1,1,1,1,1,1,1,1,1,1,1,1,1,0
0,1,1,1,3,1,1,1,1,1,1,1,1,1,1,1,1,1,1,1,1,1,1,1,1,1,0
0,1,1,1,3,1,1,1,1,1,1,1,1,1,1,1,1,1,1,1,1,1,1,1,1,1,0
0,1,1,1,1,1,1,1,1,1,1,1,1,1,1,1,1,1,1,1,1,1,1,1,1,1,0
0,1,1,1,1,1,1,1,1,1,1,1,1,1,1,1,1,1,1,1,1,1,1,1,1,1,0
0,1,1,1,1,1,1,1,1,1,1,1,1,1,1,1,1,1,1,1,1,1,1,1,1,1,0
0,1,1,1,1,1,1,1,1,1,1,1,1,1,1,1,1,1,1,1,1,1,1,1,1,1,0
0,1,1,1,1,1,1,1,1,1,1,1,1,1,1,1,1,1,1,1,1,1,1,1,1,1,0
0,1,1,1,1,1,1,1,1,1,1,1,1,1,1,1,1,1,1,1,1,1,1,1,1,1,0
0,1,1,1,1,1,1,1,1,1,1,1,1,1,1,1,1,1,1,1,1,1,1,1,1,1,0
0,1,1,1,1,1,1,1,1,1,1,1,1,1,1,1,1,1,1,1,1,1,1,1,1,1,0
0,1,1,1,1,1,1,1,1,1,1,1,1,1,1,1,1,1,1,1,1,1,1,1,1,1,0
0,1,1,1,1,1,1,1,1,1,1,1,1,1,1,1,1,1,1,1,1,1,1,1,1,1,0
0,1,1,1,1,1,1,1,1,1,1,1,1,1,1,1,1,1,1,1,1,1,1,1,1,1,0
0,1,1,1,1,1,1,1,1,1,1,1,1,1,1,1,1,1,1,1,1,1,1,1,1,1,0
0,1,1,1,1,1,1,1,1,1,1,1,1,1,1,1,1,1,1,1,1,1,1,1,1,1,0
0,1,1,1,1,1,1,1,1,1,1,1,1,1,1,1,1,1,1,1,1,1,1,1,1,1,0
0,1,1,1,1,1,1,1,1,1,1,1,1,1,1,1,1,1,1,1,1,1,1,1,1,1,0
endlayer

layer
0,1,1,1,1,1,1,1,1,1,1,1,1,1,1,1,1,1,1,1,1,1,1,1,1,1,0
0,1,1,1,1,1,1,1,1,1,1,1,1,1,1,1,1,1,1,1,1,1,1,1,1,1,0
0,1,1,1,1,1,1,1,1,1,1,1,1,1,1,1,1,1,1,1,1,1,1,1,1,1,0
0,1,1,1,1,1,1,1,1,1,1,1,1,1,1,1,1,1,1,1,1,1,1,1,1,1,0
0,1,1,1,1,1,1,1,1,1,1,1,1,1,1,1,1,1,1,1,1,1,1,1,1,1,0
0,1,1,1,1,1,1,1,1,1,1,1,1,1,1,1,1,1,1,1,1,1,1,1,1,1,0
0,1,1,1,1,1,1,1,1,1,1,1,1,1,1,1,1,1,1,1,1,1,1,1,1,1,0
0,1,1,1,1,1,1,1,1,1,1,1,1,1,1,1,1,1,1,1,1,1,1,1,1,1,0
0,1,1,1,1,1,1,1,1,1,1,1,1,1,1,3,2,1,1,1,1,1,1,1,1,1,0
0,1,1,1,1,1,1,1,1,1,1,1,1,1,4,3,2,1,1,1,1,1,1,1,1,1,0
0,1,1,1,1,1,1,1,1,1,1,1,1,1,4,3,2,1,1,1,1,1,1,1,1,1,0
0,1,1,1,1,1,1,1,1,1,1,1,1,4,1,3,7,1,1,1,1,1,1,1,1,1,0
0,1,1,1,1,1,1,1,1,1,1,1,4,4,1,3,1,1,1,1,1,1,1,1,1,1,0
0,1,1,1,1,1,1,1,1,1,1,4,4,1,1,3,1,1,1,1,1,1,1,1,1,1,0
0,1,1,1,1,1,1,1,1,1,4,4,1,1,1,3,1,1,1,1,1,1,1,1,1,1,0
0,1,1,1,1,1,1,1,1,4,4,1,1,1,1,3,1,1,1,1,1,1,1,1,1,1,0
0,1,1,1,1,1,1,1,4,4,1,1,1,1,1,3,1,1,1,1,1,1,1,1,1,1,0
0,1,1,1,1,1,1,4,4,1,1,1,1,1,1,3,1,1,1,1,1,1,1,1,1,1,0
0,1,1,1,1,1,4,4,1,1,1,1,1,1,1,3,3,1,1,1,1,1,1,1,1,1,0
0,1,1,1,1,1,4,1,1,1,1,1,1,1,1,3,3,1,1,1,1,1,1,1,1,1,0
0,1,1,1,1,4,4,1,1,1,1,1,1,1,1,3,3,3,9,1,1,1,1,1,1,1,0
0,1,1,1,1,4,3,3,3,3,3,3,3,3,3,3,3,3,3,1,1,1,1,1,1,1,0
0,1,1,1,1,4,1,1,1,1,3,1,1,1,1,3,3,3,3,1,1,1,1,1,1,1,0
0,1,1,1,1,4,1,1,1,1,3,1,1,1,1,3,3,3,3,1,1,1,1,1,1,1,0
0,1,1,1,1,4,1,1,1,1,3,1,1,1,1,3,3,7,1,1,1,1,1,1,1,1,0
0,1,1,1,1,4,1,1,1,1,3,1,1,1,1,3,1,1,1,1,1,1,1,1,1,1,0
0,1,1,1,1,4,1,1,1,1,3,1,1,1,1,3,1,1,1,1,1,1,1,1,1,1,0
0,1,1,1,1,4,1,1,1,1,3,30,1,1,1,3,1,1,1,1,1,1,1,1,1,1,0
0,1,1,1,1,4,13,1,1,1,3,1,1,1,1,3,3,9,1,1,1,1,1,1,16,1,0
0,1,1,1,1,4,1,1,1,1,3,1,1,1,1,3,3,3,3,7,1,1,1,1,19,1,0
0,1,1,1,1,4,1,3,3,1,3,3,3,3,3,3,3,3,3,1,1,1,1,1,1,1,0
0,1,1,1,1,4,1,1,1,1,1,1,1,1,1,3,3,3,1,1,1,1,1,1,1,1,0
0,1,1,1,1,4,1,1,1,1,1,1,1,1,1,3,3,1,1,1,1,1,1,1,1,1,0
0,1,1,1,1,4,1,1,1,1,1,1,1,1,1,3,3,1,1,1,1,1,1,1,1,1,0
0,1,1,1,1,4,1,1,1,1,1,1,1,1,1,3,3,3,1,1,19,1,1,19,1,1,0
0,1,1,1,1,4,1,1,1,1,1,1,1,1,1,3,3,1,1,1,1,1,1,1,1,1,0
0,1,1,1,1,4,1,1,1,1,1,1,1,1,1,3,1,1,1,1,1,1,1,1,1,1,0
0,1,1,1,1,4,1,1,1,1,1,1,1,1,1,3,1,1,1,1,1,1,1,1,1,1,0
0,1,1,1,1,4,1,1,1,1,1,1,1,1,1,3,1,1,1,1,1,1,1,1,1,1,0
0,1,1,1,1,4,1,1,1,1,1,1,1,1,1,3,1,1,1,1,1,1,1,1,1,1,0
0,1,1,1,1,4,1,1,1,1,1,1,1,1,3,3,1,1,1,1,1,1,1,1,1,1,0
0,1,1,1,1,4,1,1,1,1,1,1,1,1,1,3,1,1,1,1,1,1,1,1,1,1,0
0,1,1,1,1,4,1,1,1,1,1,1,1,1,1,3,1,1,1,1,1,1,1,1,1,1,0
0,1,1,1,1,4,1,1,1,1,1,1,1,1,1,1,1,1,1,1,1,1,1,1,1,1,0
0,1,1,1,1,1,1,1,1,1,1,1,1,1,1,1,1,1,1,1,1,1,1,1,1,1,0
0,1,1,1,1,1,1,1,1,1,1,1,1,1,1,1,1,1,1,1,1,1,1,1,1,1,0
0,1,1,1,1,1,1,1,1,1,1,1,1,1,1,1,1,1,1,1,1,1,1,1,1,1,0
0,1,1,1,1,1,1,1,1,1,1,1,1,1,1,1,1,1,1,1,1,1,1,1,1,1,0
0,1,1,1,1,1,1,1,1,1,1,1,1,1,1,1,1,1,1,1,1,1,1,1,1,1,0
0,1,1,1,1,1,1,1,1,1,1,1,1,1,1,1,1,1,1,1,1,1,1,1,1,1,0
0,1,1,1,1,1,1,1,1,1,1,1,1,1,1,1,1,1,1,1,1,1,1,1,1,1,0
0,1,1,1,1,1,1,1,1,1,1,1,1,1,1,1,1,1,1,1,1,1,1,1,1,1,0
0,1,1,1,1,1,1,1,1,1,1,1,1,1,1,1,1,1,1,1,1,1,1,1,1,1,0
0,1,1,1,1,1,1,1,1,1,1,1,1,1,1,1,1,1,1,1,1,1,1,1,1,1,0
0,1,1,1,1,1,1,1,1,1,1,1,1,1,1,1,1,1,1,1,1,1,1,1,1,1,0
0,1,1,1,1,1,1,1,1,1,1,1,1,1,1,1,1,1,1,1,1,1,1,1,1,1,0
0,1,1,1,1,1,1,1,1,1,1,1,1,1,1,1,1,1,1,1,1,1,1,1,1,1,0
0,1,1,1,1,1,1,1,1,1,1,1,1,1,1,1,1,1,1,1,1,1,1,1,1,1,0
0,1,1,1,1,1,1,1,1,1,1,1,1,1,1,1,1,1,1,1,1,1,1,1,1,1,0
0,1,1,1,1,1,1,1,1,1,1,1,1,1,1,1,1,1,1,1,1,1,1,1,1,1,0
0,1,1,1,1,1,1,1,1,1,1,1,1,1,1,1,1,1,1,1,1,1,1,1,1,1,0
0,1,1,1,1,1,1,1,1,1,1,1,1,1,1,1,1,1,1,1,1,1,1,1,1,1,0
0,1,1,1,1,1,1,1,1,1,1,1,1,1,1,1,1,1,1,1,1,1,1,1,1,1,0
endlayer

layer
0,1,1,1,1,1,1,1,1,1,1,1,1,1,1,1,1,1,1,1,1,1,1,1,1,1,0
0,1,1,1,1,1,1,1,1,1,1,1,1,1,1,1,1,1,1,1,1,1,1,1,1,1,0
0,1,1,1,1,1,1,1,1,1,1,1,1,1,1,1,1,1,1,1,1,1,1,1,1,1,0
0,1,1,1,1,1,1,1,1,1,1,1,1,1,1,1,1,1,1,1,1,1,1,1,1,1,0
0,1,1,1,1,1,1,1,1,1,1,1,1,1,1,1,1,1,1,1,1,1,1,1,1,1,0
0,1,1,1,1,1,1,1,1,1,1,1,1,1,1,1,1,1,1,1,1,1,1,1,1,1,0
0,1,1,1,1,1,1,1,1,1,1,1,1,1,1,1,1,1,1,1,1,1,1,1,1,1,0
0,1,1,1,1,1,1,1,1,1,1,1,1,1,1,1,1,1,1,1,1,1,1,1,1,1,0
0,1,1,1,1,1,1,1,1,1,1,1,1,1,1,1,1,1,1,1,1,1,1,1,1,1,0
0,1,1,1,1,1,1,1,1,1,1,1,1,1,1,1,1,1,1,1,1,1,1,1,1,1,0
0,1,1,1,1,1,1,1,1,1,1,1,1,1,4,3,2,1,1,1,1,1,1,1,1,1,0
0,1,1,1,1,1,1,1,1,1,1,1,1,1,4,3,2,1,1,1,1,1,1,1,1,1,0
0,1,1,1,1,1,1,1,1,1,1,1,1,4,4,3,2,1,1,1,1,1,1,1,1,1,0
0,1,1,1,1,1,1,1,1,1,1,1,4,4,1,3,1,1,1,1,1,1,1,1,1,1,0
0,1,1,1,1,1,1,1,1,1,1,4,4,1,1,3,1,1,1,1,1,1,1,1,1,1,0
0,1,1,1,1,1,1,1,1,1,4,4,1,1,1,3,1,1,1,1,1,1,1,1,1,1,0
0,1,1,1,1,1,1,1,1,4,4,1,1,1,1,3,1,1,1,1,1,1,1,1,1,1,0
0,1,1,1,1,1,1,1,4,4,1,1,1,1,1,3,1,1,1,1,1,1,1,1,1,1,0
0,1,1,1,1,1,1,4,4,1,1,1,1,1,1,3,1,1,1,1,1,1,1,1,1,1,0
0,1,1,1,1,1,4,4,1,1,1,1,1,1,1,3,3,1,1,1,1,1,1,1,1,1,0
0,1,1,1,1,1,4,1,1,1,1,1,1,1,1,3,3,1,1,1,1,1,1,1,1,1,0
0,1,1,1,1,11,4,3,3,3,3,3,3,3,3,3,3,3,1,1,1,1,1,1,1,1,0
0,1,1,1,1,11,4,1,1,1,3,1,1,1,1,3,3,3,1,1,1,1,1,1,1,1,0
0,1,1,1,1,11,4,1,1,1,3,1,1,1,1,3,3,3,1,1,1,1,1,1,1,1,0
0,1,1,1,1,11,4,1,1,1,3,1,1,1,1,3,3,1,1,1,1,1,1,1,1,1,0
0,1,1,1,1,11,4,1,1,1,3,1,1,1,1,3,1,1,1,1,1,1,1,1,1,1,0
0,1,1,1,1,11,4,1,1,1,3,1,1,1,1,3,1,1,1,1,1,1,1,1,1,1,0
0,1,1,1,1,11,4,1,1,1,3,1,1,1,1,3,1,1,1,1,1,1,1,1,1,1,0
0,1,1,1,1,11,4,1,1,1,3,1,1,1,1,3,3,1,1,1,1,1,1,1,1,1,0
0,1,1,1,1,11,4,1,1,1,3,1,1,1,1,3,3,3,1,1,1,1,1,1,1,1,0
0,1,1,1,1,11,1,1,1,1,1,1,3,3,3,3,3,3,1,1,1,1,1,1,1,1,0
0,1,1,1,1,11,1,1,1,1,1,1,1,1,1,3,3,3,1,1,1,1,1,1,1,1,0
0,1,1,1,1,11,1,1,1,1,1,1,1,1,1,3,3,3,1,1,1,1,1,1,1,1,0
0,1,1,1,1,1,4,1,1,1,1,1,1,1,1,3,3,3,1,1,1,1,1,1,1,1,0
0,1,1,1,1,11,4,1,1,1,1,1,1,1,1,3,3,3,1,1,1,1,1,1,1,1,0
0,1,1,1,1,11,4,1,1,1,1,1,1,1,1,3,3,1,1,1,1,1,1,1,1,1,0
0,1,1,1,1,11,4,1,1,1,1,1,1,1,1,3,1,1,1,1,1,1,1,1,1,1,0
0,1,1,1,1,11,4,1,1,1,1,1,1,1,1,3,1,1,1,1,1,1,1,1,1,1,0
0,1,1,1,1,11,4,1,1,1,1,1,1,1,1,3,1,1,1,1,1,1,1,1,1,1,0
0,1,1,1,1,11,4,1,1,1,1,1,1,1,1,1,1,1,1,1,1,1,1,1,1,1,0
0,1,1,1,1,11,4,1,1,1,1,1,1,1,1,1,1,1,1,1,1,1,1,1,1,1,0
0,1,1,1,1,11,4,1,1,1,1,1,1,1,1,1,1,1,1,1,1,1,1,1,1,1,0
0,1,1,1,1,11,4,1,1,1,1,1,1,1,1,1,1,1,1,1,1,1,1,1,1,1,0
0,1,1,1,1,11,4,1,1,1,1,1,1,1,1,1,1,1,1,1,1,1,1,1,1,1,0
0,1,1,1,1,11,1,1,1,1,1,1,1,1,1,1,1,1,1,1,1,1,1,1,1,1,0
0,1,1,1,1,11,1,1,1,1,1,1,1,1,1,1,1,1,1,1,1,1,1,1,1,1,0
0,1,1,1,1,11,1,1,1,1,1,1,1,1,1,1,1,1,1,1,1,1,1,1,1,1,0
0,1,1,1,1,1,1,1,1,1,1,1,1,1,1,1,1,1,1,1,1,1,1,1,1,1,0
0,1,1,1,1,1,1,1,1,1,1,1,1,1,1,1,1,1,1,1,1,1,1,1,1,1,0
0,1,1,1,1,1,1,1,1,1,1,1,1,1,1,1,1,1,1,1,1,1,1,1,1,1,0
0,1,1,1,1,1,1,1,1,1,1,1,1,1,1,1,1,1,1,1,1,1,1,1,1,1,0
0,1,1,1,1,1,1,1,1,1,1,1,1,1,1,1,1,1,1,1,1,1,1,1,1,1,0
0,1,1,1,1,1,1,1,1,1,1,1,1,1,1,1,1,1,1,1,1,1,1,1,1,1,0
0,1,1,1,1,1,1,1,1,1,1,1,1,1,1,1,1,1,1,1,1,1,1,1,1,1,0
0,1,1,1,1,1,1,1,1,1,1,1,1,1,1,1,1,1,1,1,1,1,1,1,1,1,0
0,1,1,1,1,1,1,1,1,1,1,1,1,1,1,1,1,1,1,1,1,1,1,1,1,1,0
0,1,1,1,1,1,1,1,1,1,1,1,1,1,1,1,1,1,1,1,1,1,1,1,1,1,0
0,1,1,1,1,1,1,1,1,1,1,1,1,1,1,1,1,1,1,1,1,1,1,1,1,1,0
0,1,1,1,1,1,1,1,1,1,1,1,1,1,1,1,1,1,1,1,1,1,1,1,1,1,0
0,1,1,1,1,1,1,1,1,1,1,1,1,1,1,1,1,1,1,1,1,1,1,1,1,1,0
0,1,1,1,1,1,1,1,1,1,1,1,1,1,1,1,1,1,1,1,1,1,1,1,1,1,0
0,1,1,1,1,1,1,1,1,1,1,1,1,1,1,1,1,1,1,1,1,1,1,1,1,1,0
0,1,1,1,1,1,1,1,1,1,1,1,1,1,1,1,1,1,1,1,1,1,1,1,1,1,0
endlayer

layer
0,1,1,1,1,1,1,1,1,1,1,1,1,1,1,1,1,1,1,1,1,1,1,1,1,1,0
0,1,1,1,1,1,1,1,1,1,1,1,1,1,1,1,1,1,1,1,1,1,1,1,1,1,0
0,1,1,1,1,1,1,1,1,1,1,1,1,1,1,1,1,1,1,1,1,1,1,1,1,1,0
0,1,1,1,1,1,1,1,1,1,1,1,1,1,1,1,1,1,1,1,1,1,1,1,1,1,0
0,1,1,1,1,1,1,1,1,1,1,1,1,1,1,1,1,1,1,1,1,1,1,1,1,1,0
0,1,1,1,1,1,1,1,1,1,1,1,1,1,1,1,1,1,1,1,1,1,1,1,1,1,0
0,1,1,1,1,1,1,1,1,1,1,1,1,1,1,1,1,1,1,1,1,1,1,1,1,1,0
0,1,1,1,1,1,1,1,1,1,1,1,1,1,1,1,1,1,1,1,1,1,1,1,1,1,0
0,1,1,1,1,1,1,1,1,1,1,1,1,1,1,1,1,1,1,1,1,1,1,1,1,1,0
0,1,1,1,1,1,1,1,1,1,1,1,1,1,1,1,1,1,1,1,1,1,1,1,1,1,0
0,1,1,1,1,1,1,1,1,1,1,1,1,1,1,1,1,1,1,1,1,1,1,1,1,1,0
0,1,1,1,1,1,1,1,1,1,1,1,1,1,1,1,1,1,1,1,1,1,1,1,1,1,0
0,1,1,1,1,1,1,1,1,1,1,1,1,1,4,3,2,1,1,1,1,1,1,1,1,1,0
0,1,1,1,1,1,1,1,1,1,1,1,1,4,4,3,2,1,1,1,1,1,1,1,1,1,0
0,1,1,1,1,1,1,1,1,1,1,1,4,4,1,3,1,1,1,1,1,1,1,1,1,1,0
0,1,1,1,1,1,1,1,1,1,1,4,4,1,1,3,1,1,1,1,1,1,1,1,1,1,0
0,1,1,1,1,1,1,1,1,1,4,4,1,1,1,3,1,1,1,1,1,1,1,1,1,1,0
0,1,1,1,1,1,1,1,1,4,4,1,1,1,1,3,1,1,1,1,1,1,1,1,1,1,0
0,1,1,1,1,1,1,1,4,4,1,1,1,1,1,3,1,1,1,1,1,1,1,1,1,1,0
0,1,1,1,1,1,1,4,4,1,1,1,1,1,1,3,1,1,1,1,1,1,1,1,1,1,0
0,1,1,1,1,1,1,4,1,1,1,1,1,1,1,3,1,1,1,1,1,1,1,1,1,1,0
0,1,1,1,1,1,11,4,3,3,3,3,3,3,3,3,3,1,1,1,1,1,1,1,1,1,0
0,1,1,1,1,1,11,4,1,1,3,1,1,1,1,3,3,1,1,1,1,1,1,1,1,1,0
0,1,1,1,1,1,11,4,1,1,3,1,1,1,1,3,3,1,1,1,1,1,1,1,1,1,0
0,1,1,1,1,1,11,4,1,1,1,1,1,1,1,3,3,1,1,1,1,1,1,1,1,1,0
0,1,1,1,1,1,11,4,1,1,3,1,1,1,1,3,1,1,1,1,1,1,1,1,1,1,0
0,1,1,1,1,1,11,4,1,1,3,1,1,1,1,3,1,1,1,1,1,1,1,1,1,1,0
0,1,1,1,1,1,11,4,1,1,3,1,1,1,1,3,17,1,1,1,1,1,1,1,1,1,0
0,1,1,1,1,1,1,1,1,1,3,1,1,1,1,3,3,1,1,1,1,1,1,1,1,1,0
0,1,1,1,1,1,1,1,1,1,1,1,1,1,1,3,3,1,1,1,1,1,1,1,1,1,0
0,1,1,1,1,1,1,1,1,1,1,1,1,3,3,3,3,1,1,1,1,1,1,1,1,1,0
0,1,1,1,1,1,1,1,1,1,1,1,1,1,1,3,3,1,1,1,1,1,1,1,1,1,0
0,1,1,1,1,1,1,1,1,1,1,1,1,1,1,3,3,1,1,1,1,1,1,1,1,1,0
0,1,1,1,1,1,1,1,1,1,1,1,1,1,1,3,3,1,1,1,1,1,1,1,1,1,0
0,1,1,1,1,1,1,4,1,1,1,1,1,1,1,3,3,13,1,1,1,1,1,1,1,1,0
0,1,1,1,1,1,11,4,1,1,1,1,1,1,1,3,3,1,1,1,1,1,1,1,1,1,0
0,1,1,1,1,1,11,4,1,1,1,1,1,1,1,3,21,1,1,1,1,1,1,1,1,1,0
0,1,1,1,1,1,11,4,1,1,1,1,1,1,1,3,1,1,1,1,1,1,1,1,1,1,0
0,1,1,1,1,1,11,4,1,1,1,1,1,1,1,3,1,1,1,1,1,1,1,1,1,1,0
0,1,1,1,1,1,11,4,1,1,1,1,1,1,1,3,1,1,1,1,1,1,1,1,1,1,0
0,1,1,1,1,1,11,4,1,1,1,1,1,3,3,3,1,1,1,1,1,1,1,1,1,1,0
0,1,1,1,1,1,11,4,1,1,1,1,1,1,1,3,1,1,1,1,1,1,1,1,1,1,0
0,1,1,1,1,1,11,4,1,1,1,1,1,1,1,1,1,1,1,1,1,1,1,1,1,1,0
0,1,1,1,1,1,11,4,1,1,1,1,1,1,1,1,1,1,1,1,1,1,1,1,1,1,0
0,1,1,1,1,1,11,1,1,1,1,1,1,1,1,1,1,1,1,1,1,1,1,1,1,1,0
0,1,1,1,1,1,11,1,1,1,1,1,1,1,1,1,1,1,1,1,1,1,1,1,1,1,0
0,1,1,1,1,1,11,1,1,1,1,1,1,1,1,1,1,1,1,1,1,1,1,1,1,1,0
0,1,1,1,1,1,11,1,1,1,1,1,1,1,1,1,1,1,1,1,1,1,1,1,1,1,0
0,1,1,1,1,1,1,1,1,1,1,1,1,1,1,1,1,1,1,1,1,1,1,1,1,1,0
0,1,1,1,1,1,1,1,1,1,1,1,1,1,1,1,1,1,1,1,1,1,1,1,1,1,0
0,1,1,1,1,1,1,1,1,1,1,1,1,1,1,1,1,1,1,1,1,1,1,1,1,1,0
0,1,1,1,1,1,1,1,1,1,1,1,1,1,1,1,1,1,1,1,1,1,1,1,1,1,0
0,1,1,1,1,1,1,1,1,1,1,1,1,1,1,1,1,1,1,1,1,1,1,1,1,1,0
0,1,1,1,1,1,1,1,1,1,1,1,1,1,1,1,1,1,1,1,1,1,1,1,1,1,0
0,1,1,1,1,1,1,1,1,1,1,1,1,1,1,1,1,1,1,1,1,1,1,1,1,1,0
0,1,1,1,1,1,1,1,1,1,1,1,1,1,1,1,1,1,1,1,1,1,1,1,1,1,0
0,1,1,1,1,1,1,1,1,1,1,1,1,1,1,1,1,1,1,1,1,1,1,1,1,1,0
0,1,1,1,1,1,1,1,1,1,1,1,1,1,1,1,1,1,1,1,1,1,1,1,1,1,0
0,1,1,1,1,1,1,1,1,1,1,1,1,1,1,1,1,1,1,1,1,1,1,1,1,1,0
0,1,1,1,1,1,1,1,1,1,1,1,1,1,1,1,1,1,1,1,1,1,1,1,1,1,0
0,1,1,1,1,1,1,1,1,1,1,1,1,1,1,1,1,1,1,1,1,1,1,1,1,1,0
0,1,1,1,1,1,1,1,1,1,1,1,1,1,1,1,1,1,1,1,1,1,1,1,1,1,0
0,1,1,1,1,1,1,1,1,1,1,1,1,1,1,1,1,1,1,1,1,1,1,1,1,1,0
endlayer

layer
0,1,1,1,1,1,1,1,1,1,1,1,1,1,1,1,1,1,1,1,1,1,1,1,1,1,0
0,1,1,1,1,1,1,1,1,1,1,1,1,1,1,1,1,1,1,1,1,1,1,1,1,1,0
0,1,1,1,1,1,1,1,1,1,1,1,1,1,1,1,1,1,1,1,1,1,1,1,1,1,0
0,1,1,1,1,1,1,1,1,1,1,1,1,1,1,1,1,1,1,1,1,1,1,1,1,1,0
0,1,1,1,1,1,1,1,1,1,1,1,1,1,1,1,1,1,1,1,1,1,1,1,1,1,0
0,1,1,1,1,1,1,1,1,1,1,1,1,1,1,1,1,1,1,1,1,1,1,1,1,1,0
0,1,1,1,1,1,1,1,1,1,1,1,1,1,1,1,1,1,1,1,1,1,1,1,1,1,0
0,1,1,1,1,1,1,1,1,1,1,1,1,1,1,1,1,1,1,1,1,1,1,1,1,1,0
0,1,1,1,1,1,1,1,1,1,1,1,1,1,1,1,1,1,1,1,1,1,1,1,1,1,0
0,1,1,1,1,1,1,1,1,1,1,1,1,1,1,1,1,1,1,1,1,1,1,1,1,1,0
0,1,1,1,1,1,1,1,1,1,1,1,1,1,1,1,1,1,1,1,1,1,1,1,1,1,0
0,1,1,1,1,1,1,1,1,1,1,1,1,1,1,1,1,1,1,1,1,1,1,1,1,1,0
0,1,1,1,1,1,1,1,1,1,1,1,1,1,1,1,1,1,1,1,1,1,1,1,1,1,0
0,1,1,1,1,1,1,1,1,1,1,1,1,1,1,1,1,1,1,1,1,1,1,1,1,1,0
0,1,1,1,1,1,1,1,1,1,1,1,1,4,4,3,2,1,1,1,1,1,1,1,1,1,0
0,1,1,1,1,1,1,1,1,1,1,1,4,4,4,3,2,1,1,1,1,1,1,1,1,1,0
0,1,1,1,1,1,1,1,1,1,1,4,4,1,1,3,1,1,1,1,1,1,1,1,1,1,0
0,1,1,1,1,1,1,1,1,1,4,4,1,1,1,3,1,1,1,1,1,1,1,1,1,1,0
0,1,1,1,1,1,1,1,1,4,4,1,1,1,1,3,1,1,1,1,1,1,1,1,1,1,0
0,1,1,1,1,1,1,1,4,4,1,1,1,1,1,3,1,1,1,1,1,1,1,1,1,1,0
0,1,1,1,1,1,1,11,4,4,1,1,1,1,1,3,1,1,1,1,1,1,1,1,1,1,0
0,1,1,1,1,1,1,11,4,4,3,3,3,3,3,3,1,1,1,1,1,1,1,1,1,1,0
0,1,1,1,1,1,1,11,4,4,3,1,1,1,1,3,1,1,1,1,1,1,1,1,1,1,0
0,1,1,1,1,1,1,11,4,4,3,1,1,1,1,3,1,1,1,1,1,1,1,1,1,1,0
0,1,1,1,1,1,1,11,4,4,3,31,1,1,1,3,1,1,1,1,1,1,1,1,1,1,0
0,1,1,1,1,1,1,11,4,4,3,1,1,1,1,3,1,1,1,1,1,1,1,1,1,1,0
0,1,1,1,1,1,1,11,4,4,3,1,1,1,1,3,1,1,1,1,1,1,1,1,1,1,0
0,1,1,1,1,1,1,11,4,4,3,1,1,1,1,3,1,1,1,1,1,1,1,1,1,1,0
0,1,1,1,1,1,1,1,1,4,3,1,1,1,1,3,1,1,1,1,1,1,1,1,1,1,0
0,1,1,1,1,1,1,1,1,1,1,1,1,1,1,3,13,1,1,1,1,1,1,1,1,1,0
0,1,1,1,1,1,1,1,1,1,1,1,1,3,3,3,1,1,1,1,1,1,1,1,1,1,0
0,1,1,1,1,1,1,1,1,1,1,1,1,1,1,3,1,1,1,1,1,1,1,1,1,1,0
0,1,1,1,1,1,1,1,1,1,1,1,1,1,1,3,1,1,1,1,1,1,1,1,1,1,0
0,1,1,1,1,1,1,1,1,1,1,1,1,1,20,3,1,1,1,1,1,1,1,1,1,1,0
0,1,1,1,1,1,1,1,4,4,1,1,1,1,20,3,1,1,1,1,1,1,1,1,1,1,0
0,1,1,1,1,1,1,11,4,4,1,1,1,1,1,3,1,1,1,1,1,1,1,1,1,1,0
0,1,1,1,1,1,1,11,4,4,25,1,1,1,20,3,1,1,1,1,1,1,1,1,1,1,0
0,1,1,1,1,1,1,11,4,4,1,1,1,1,20,3,1,1,1,1,1,1,1,1,1,1,0
0,1,1,1,1,1,1,11,4,4,1,1,1,1,1,3,1,1,1,1,1,1,1,1,1,1,0
0,1,1,1,1,1,1,11,4,4,1,1,1,1,1,3,1,1,1,1,1,1,1,1,1,1,0
0,1,1,1,1,1,1,11,4,4,1,1,1,3,3,3,1,1,1,1,1,1,1,1,1,1,0
0,1,1,1,1,1,1,11,4,4,1,1,1,1,1,1,1,1,1,1,1,1,1,1,1,1,0
0,1,1,1,1,1,1,11,4,4,1,1,1,1,1,1,1,1,1,1,1,1,1,1,1,1,0
0,1,1,1,1,1,1,1,1,1,1,1,1,1,1,1,1,1,1,1,1,1,1,1,1,1,0
0,1,1,1,1,1,1,1,1,1,1,1,1,1,1,1,1,1,1,1,1,1,1,1,1,1,0
0,1,1,1,1,1,1,1,1,1,1,1,1,1,1,1,1,1,1,1,1,1,1,1,1,1,0
0,1,1,1,1,1,1,1,1,1,1,1,1,1,1,1,1,1,1,1,1,1,1,1,1,1,0
0,1,1,1,1,1,1,1,1,1,1,1,1,1,1,1,1,1,1,1,1,1,1,1,1,1,0
0,1,1,1,1,1,1,1,1,1,1,1,1,1,1,1,1,1,1,1,1,1,1,1,1,1,0
0,1,1,1,1,1,1,1,1,1,1,1,1,1,1,1,1,1,1,1,1,1,1,1,1,1,0
0,1,1,1,1,1,1,1,1,1,1,1,1,1,1,1,1,1,1,1,1,1,1,1,1,1,0
0,1,1,1,1,1,1,1,1,1,1,1,1,1,1,1,1,1,1,1,1,1,1,1,1,1,0
0,1,1,1,1,1,1,1,1,1,1,1,1,1,1,1,1,1,1,1,1,1,1,1,1,1,0
0,1,1,1,1,1,1,1,1,1,1,1,1,1,1,1,1,1,1,1,1,1,1,1,1,1,0
0,1,1,1,1,1,1,1,1,1,1,1,1,1,1,1,1,1,1,1,1,1,1,1,1,1,0
0,1,1,1,1,1,1,1,1,1,1,1,1,1,1,1,1,1,1,1,1,1,1,1,1,1,0
0,1,1,1,1,1,1,1,1,1,1,1,1,1,1,1,1,1,1,1,1,1,1,1,1,1,0
0,1,1,1,1,1,1,1,1,1,1,1,1,1,1,1,1,1,1,1,1,1,1,1,1,1,0
0,1,1,1,1,1,1,1,1,1,1,1,1,1,1,1,1,1,1,1,1,1,1,1,1,1,0
0,1,1,1,1,1,1,1,1,1,1,1,1,1,1,1,1,1,1,1,1,1,1,1,1,1,0
0,1,1,1,1,1,1,1,1,1,1,1,1,1,1,1,1,1,1,1,1,1,1,1,1,1,0
0,1,1,1,1,1,1,1,1,1,1,1,1,1,1,1,1,1,1,1,1,1,1,1,1,1,0
0,1,1,1,1,1,1,1,1,1,1,1,1,1,1,1,1,1,1,1,1,1,1,1,1,1,0
endlayer

layer
0,1,1,1,1,1,1,1,1,1,1,1,1,1,1,1,1,1,1,1,1,1,1,1,1,1,0
0,1,1,1,1,1,1,1,1,1,1,1,1,1,1,1,1,1,1,1,1,1,1,1,1,1,0
0,1,1,1,1,1,1,1,1,1,1,1,1,1,1,1,1,1,1,1,1,1,1,1,1,1,0
0,1,1,1,1,1,1,1,1,1,1,1,1,1,1,1,1,1,1,1,1,1,1,1,1,1,0
0,1,1,1,1,1,1,1,1,1,1,1,1,1,1,1,1,1,1,1,1,1,1,1,1,1,0
0,1,1,1,1,1,1,1,1,1,1,1,1,1,1,1,1,1,1,1,1,1,1,1,1,1,0
0,1,1,1,1,1,1,1,1,1,1,1,1,1,1,1,1,1,1,1,1,1,1,1,1,1,0
0,1,1,1,1,1,1,1,1,1,1,1,1,1,1,1,1,1,1,1,1,1,1,1,1,1,0
0,1,1,1,1,1,1,1,1,1,1,1,1,1,1,1,1,1,1,1,1,1,1,1,1,1,0
0,1,1,1,1,1,1,1,1,1,1,1,1,1,1,1,1,1,1,1,1,1,1,1,1,1,0
0,1,1,1,1,1,1,1,1,1,1,1,1,1,1,1,1,1,1,1,1,1,1,1,1,1,0
0,1,1,1,1,1,1,1,1,1,1,1,1,1,1,1,1,1,1,1,1,1,1,1,1,1,0
0,1,1,1,1,1,1,1,1,1,1,1,1,1,1,1,1,1,1,1,1,1,1,1,1,1,0
0,1,1,1,1,1,1,1,1,1,1,1,1,1,1,1,1,1,1,1,1,1,1,1,1,1,0
0,1,1,1,1,1,1,1,1,1,1,1,1,1,1,1,1,1,1,1,1,1,1,1,1,1,0
0,1,1,1,1,1,1,1,1,1,1,1,1,4,4,3,1,1,1,1,1,1,1,1,1,1,0
0,1,1,1,1,1,1,1,1,1,1,1,4,4,4,3,1,1,1,1,1,1,1,1,1,1,0
0,1,1,1,1,1,1,1,1,1,1,4,4,4,4,3,2,1,1,1,1,1,1,1,1,1,0
0,1,1,1,1,1,1,1,1,1,4,4,4,1,1,3,1,1,1,1,1,1,1,1,1,1,0
0,1,1,1,1,1,1,1,1,11,4,4,1,1,1,3,1,1,1,1,1,1,1,1,1,1,0
0,1,1,1,1,1,1,1,1,11,4,4,1,1,1,3,1,1,1,1,1,1,1,1,1,1,0
0,1,1,1,1,1,1,1,1,11,4,4,3,3,3,3,1,1,1,1,1,1,1,1,1,1,0
0,1,1,1,1,1,1,1,1,11,4,4,1,1,1,3,1,1,1,1,1,1,1,1,1,1,0
0,1,1,1,1,1,1,1,1,11,4,4,1,1,1,3,1,1,1,1,1,1,1,1,1,1,0
0,1,1,1,1,1,1,1,1,11,4,4,1,1,1,3,1,1,1,1,1,1,1,1,1,1,0
0,1,1,1,1,1,1,1,1,11,4,4,1,1,1,3,1,1,1,1,1,1,1,1,1,1,0
0,1,1,1,1,1,1,1,1,11,4,4,1,1,1,3,1,1,1,1,1,1,1,1,1,1,0
0,1,1,1,1,1,1,1,1,11,4,4,1,1,1,3,1,1,1,1,1,1,1,1,1,1,0
0,1,1,1,1,1,1,1,1,1,1,4,1,1,1,3,1,1,1,1,1,1,1,1,1,1,0
0,1,1,1,1,1,1,1,1,1,1,1,1,1,1,3,1,1,1,1,1,1,1,1,1,1,0
0,1,1,1,1,1,1,1,1,1,1,1,1,3,3,3,1,1,1,1,1,1,1,1,1,1,0
0,1,1,1,1,1,1,1,1,1,1,1,1,1,1,3,1,1,1,1,1,1,1,1,1,1,0
0,1,1,1,1,1,1,1,1,1,1,1,1,1,1,3,1,1,1,1,1,1,1,1,1,1,0
0,1,1,1,1,1,1,1,1,1,1,1,1,1,1,3,1,1,1,1,1,1,1,1,1,1,0
0,1,1,1,1,1,1,1,1,1,1,4,1,1,1,3,1,1,1,1,1,1,1,1,1,1,0
0,1,1,1,1,1,1,1,1,11,4,4,1,1,1,3,1,1,1,1,1,1,1,1,1,1,0
0,1,1,1,1,1,1,1,1,11,4,4,25,1,1,3,1,1,1,1,1,1,1,1,1,1,0
0,1,1,1,1,1,1,1,1,11,4,4,1,1,1,3,1,1,1,1,1,1,1,1,1,1,0
0,1,1,1,1,1,1,1,1,11,4,4,1,1,1,3,1,1,1,1,1,1,1,1,1,1,0
0,1,1,1,1,1,1,1,1,11,4,4,1,1,1,1,1,1,1,1,1,1,1,1,1,1,0
0,1,1,1,1,1,1,1,1,11,4,4,1,1,1,1,1,1,1,1,1,1,1,1,1,1,0
0,1,1,1,1,1,1,1,1,11,4,4,1,1,1,1,1,1,1,1,1,1,1,1,1,1,0
0,1,1,1,1,1,1,1,1,11,4,4,1,1,1,1,1,1,1,1,1,1,1,1,1,1,0
0,1,1,1,1,1,1,1,1,1,1,4,1,1,1,1,1,1,1,1,1,1,1,1,1,1,0
0,1,1,1,1,1,1,1,1,1,1,4,1,1,1,1,1,1,1,1,1,1,1,1,1,1,0
0,1,1,1,1,1,1,1,1,1,1,1,1,1,1,1,1,1,1,1,1,1,1,1,1,1,0
0,1,1,1,1,1,1,1,1,1,1,1,1,1,1,1,1,1,1,1,1,1,1,1,1,1,0
0,1,1,1,1,1,1,1,1,1,1,1,1,1,1,1,1,1,1,1,1,1,1,1,1,1,0
0,1,1,1,1,1,1,1,1,1,1,1,1,1,1,1,1,1,1,1,1,1,1,1,1,1,0
0,1,1,1,1,1,1,1,1,1,1,1,1,1,1,1,1,1,1,1,1,1,1,1,1,1,0
0,1,1,1,1,1,1,1,1,1,1,1,1,1,1,1,1,1,1,1,1,1,1,1,1,1,0
0,1,1,1,1,1,1,1,1,1,1,1,1,1,1,1,1,1,1,1,1,1,1,1,1,1,0
0,1,1,1,1,1,1,1,1,1,1,1,1,1,1,1,1,1,1,1,1,1,1,1,1,1,0
0,1,1,1,1,1,1,1,1,1,1,1,1,1,1,1,1,1,1,1,1,1,1,1,1,1,0
0,1,1,1,1,1,1,1,1,1,1,1,1,1,1,1,1,1,1,1,1,1,1,1,1,1,0
0,1,1,1,1,1,1,1,1,1,1,1,1,1,1,1,1,1,1,1,1,1,1,1,1,1,0
0,1,1,1,1,1,1,1,1,1,1,1,1,1,1,1,1,1,1,1,1,1,1,1,1,1,0
0,1,1,1,1,1,1,1,1,1,1,1,1,1,1,1,1,1,1,1,1,1,1,1,1,1,0
0,1,1,1,1,1,1,1,1,1,1,1,1,1,1,1,1,1,1,1,1,1,1,1,1,1,0
0,1,1,1,1,1,1,1,1,1,1,1,1,1,1,1,1,1,1,1,1,1,1,1,1,1,0
0,1,1,1,1,1,1,1,1,1,1,1,1,1,1,1,1,1,1,1,1,1,1,1,1,1,0
0,1,1,1,1,1,1,1,1,1,1,1,1,1,1,1,1,1,1,1,1,1,1,1,1,1,0
0,1,1,1,1,1,1,1,1,1,1,1,1,1,1,1,1,1,1,1,1,1,1,1,1,1,0
endlayer

layer
0,1,1,1,1,1,1,1,1,1,1,1,1,1,1,1,1,1,1,1,1,1,1,1,1,1,0
0,1,1,1,1,1,1,1,1,1,1,1,1,1,1,1,1,1,1,1,1,1,1,1,1,1,0
0,1,1,1,1,1,1,1,1,1,1,1,1,1,1,1,1,1,1,1,1,1,1,1,1,1,0
0,1,1,1,1,1,1,1,1,1,1,1,1,1,1,1,1,1,1,1,1,1,1,1,1,1,0
0,1,1,1,1,1,1,1,1,1,1,1,1,1,1,1,1,1,1,1,1,1,1,1,1,1,0
0,1,1,1,1,1,1,1,1,1,1,1,1,1,1,1,1,1,1,1,1,1,1,1,1,1,0
0,1,1,1,1,1,1,1,1,1,1,1,1,1,1,1,1,1,1,1,1,1,1,1,1,1,0
0,1,1,1,1,1,1,1,1,1,1,1,1,1,1,1,1,1,1,1,1,1,1,1,1,1,0
0,1,1,1,1,1,1,1,1,1,1,1,1,1,1,1,1,1,1,1,1,1,1,1,1,1,0
0,1,1,1,1,1,1,1,1,1,1,1,1,1,1,1,1,1,1,1,1,1,1,1,1,1,0
0,1,1,1,1,1,1,1,1,1,1,1,1,1,1,1,1,1,1,1,1,1,1,1,1,1,0
0,1,1,1,1,1,1,1,1,1,1,1,1,1,1,1,1,1,1,1,1,1,1,1,1,1,0
0,1,1,1,1,1,1,1,1,1,1,1,1,1,1,1,1,1,1,1,1,1,1,1,1,1,0
0,1,1,1,1,1,1,1,1,1,1,1,1,1,1,1,1,1,1,1,1,1,1,1,1,1,0
0,1,1,1,1,1,1,1,1,1,1,1,1,1,1,1,1,1,1,1,1,1,1,1,1,1,0
0,1,1,1,1,1,1,1,1,1,1,1,1,1,1,1,1,1,1,1,1,1,1,1,1,1,0
0,1,1,1,1,1,1,1,1,1,1,1,1,1,1,1,1,1,1,1,1,1,1,1,1,1,0
0,1,1,1,1,1,1,1,1,1,1,1,1,1,4,3,2,1,1,1,1,1,1,1,1,1,0
0,1,1,1,1,1,1,1,1,1,1,1,1,4,4,3,2,1,1,1,1,1,1,1,1,1,0
0,1,1,1,1,1,1,1,1,1,1,1,4,4,4,3,1,1,1,1,1,1,1,1,1,1,0
0,1,1,1,1,1,1,1,1,1,1,11,4,4,4,3,2,1,1,1,1,1,1,1,1,1,0
0,1,1,1,1,1,1,1,1,1,1,11,4,4,3,3,1,1,1,1,1,1,1,1,1,1,0
0,1,1,1,1,1,1,1,1,1,1,11,4,1,1,3,1,1,1,1,1,1,1,1,1,1,0
0,1,1,1,1,1,1,1,1,1,1,11,4,1,1,3,1,1,1,1,1,1,1,1,1,1,0
0,1,1,1,1,1,1,1,1,1,1,11,4,1,1,3,1,1,1,1,1,1,1,1,1,1,0
0,1,1,1,1,1,1,1,1,1,1,11,4,1,1,3,1,1,1,1,1,1,1,1,1,1,0
0,1,1,1,1,1,1,1,1,1,1,11,4,1,1,3,1,1,1,1,1,1,1,1,1,1,0
0,1,1,1,1,1,1,1,1,1,1,1,4,1,1,3,1,1,1,1,1,1,1,1,1,1,0
0,1,1,1,1,1,1,1,1,1,1,1,4,1,1,3,1,1,1,1,1,1,1,1,1,1,0
0,1,1,1,1,1,1,1,1,1,1,1,4,1,1,3,1,1,1,1,1,1,1,1,1,1,0
0,1,1,1,1,1,1,1,1,1,1,1,1,3,3,3,1,1,1,1,1,1,1,1,1,1,0
0,1,1,1,1,1,1,1,1,1,1,1,1,1,1,3,1,1,1,1,1,1,1,1,1,1,0
0,1,1,1,1,1,1,1,1,1,1,1,1,1,1,3,1,1,1,1,1,1,1,1,1,1,0
0,1,1,1,1,1,1,1,1,1,1,1,4,1,1,3,1,1,1,1,1,1,1,1,1,1,0
0,1,1,1,1,1,1,1,1,1,1,1,4,1,1,3,1,1,1,1,1,1,1,1,1,1,0
0,1,1,1,1,1,1,1,1,1,1,11,4,1,1,3,1,1,1,1,1,1,1,1,1,1,0
0,1,1,1,1,1,1,1,1,1,1,11,4,25,1,3,1,1,1,1,1,1,1,1,1,1,0
0,1,1,1,1,1,1,1,1,1,1,11,4,1,1,3,1,1,1,1,1,1,1,1,1,1,0
0,1,1,1,1,1,1,1,1,1,1,11,4,1,1,3,1,1,1,1,1,1,1,1,1,1,0
0,1,1,1,1,1,1,1,1,1,1,11,4,1,1,3,1,1,1,1,1,1,1,1,1,1,0
0,1,1,1,1,1,1,1,1,1,1,11,4,1,1,3,1,1,1,1,1,1,1,1,1,1,0
0,1,1,1,1,1,1,1,1,1,1,11,4,1,1,3,1,1,1,1,1,1,1,1,1,1,0
0,1,1,1,1,1,1,1,1,1,1,1,4,1,1,3,1,1,1,1,1,1,1,1,1,1,0
0,1,1,1,1,1,1,1,1,1,1,1,1,1,1,1,1,1,1,1,1,1,1,1,1,1,0
0,1,1,1,1,1,1,1,1,1,1,1,1,1,1,1,1,1,1,1,1,1,1,1,1,1,0
0,1,1,1,1,1,1,1,1,1,1,1,1,1,1,1,1,1,1,1,1,1,1,1,1,1,0
0,1,1,1,1,1,1,1,1,1,1,1,1,1,1,1,1,1,1,1,1,1,1,1,1,1,0
0,1,1,1,1,1,1,1,1,1,1,1,1,1,1,1,1,1,1,1,1,1,1,1,1,1,0
0,1,1,1,1,1,1,1,1,1,1,1,1,1,1,1,1,1,1,1,1,1,1,1,1,1,0
0,1,1,1,1,1,1,1,1,1,1,1,1,1,1,1,1,1,1,1,1,1,1,1,1,1,0
0,1,1,1,1,1,1,1,1,1,1,1,1,1,1,1,1,1,1,1,1,1,1,1,1,1,0
0,1,1,1,1,1,1,1,1,1,1,1,1,1,1,1,1,1,1,1,1,1,1,1,1,1,0
0,1,1,1,1,1,1,1,1,1,1,1,1,1,1,1,1,1,1,1,1,1,1,1,1,1,0
0,1,1,1,1,1,1,1,1,1,1,1,1,1,1,1,1,1,1,1,1,1,1,1,1,1,0
0,1,1,1,1,1,1,1,1,1,1,1,1,1,1,1,1,1,1,1,1,1,1,1,1,1,0
0,1,1,1,1,1,1,1,1,1,1,1,1,1,1,1,1,1,1,1,1,1,1,1,1,1,0
0,1,1,1,1,1,1,1,1,1,1,1,1,1,1,1,1,1,1,1,1,1,1,1,1,1,0
0,1,1,1,1,1,1,1,1,1,1,1,1,1,1,1,1,1,1,1,1,1,1,1,1,1,0
0,1,1,1,1,1,1,1,1,1,1,1,1,1,1,1,1,1,1,1,1,1,1,1,1,1,0
0,1,1,1,1,1,1,1,1,1,1,1,1,1,1,1,1,1,1,1,1,1,1,1,1,1,0
0,1,1,1,1,1,1,1,1,1,1,1,1,1,1,1,1,1,1,1,1,1,1,1,1,1,0
0,1,1,1,1,1,1,1,1,1,1,1,1,1,1,1,1,1,1,1,1,1,1,1,1,1,0
0,1,1,1,1,1,1,1,1,1,1,1,1,1,1,1,1,1,1,1,1,1,1,1,1,1,0
endlayer

layer
0,1,1,1,1,1,1,1,1,1,1,1,1,1,1,1,1,1,1,1,1,1,1,1,1,1,0
0,1,1,1,1,1,1,1,1,1,1,1,1,1,1,1,1,1,1,1,1,1,1,1,1,1,0
0,1,1,1,1,1,1,1,1,1,1,1,1,1,1,1,1,1,1,1,1,1,1,1,1,1,0
0,1,1,1,1,1,1,1,1,1,1,1,1,1,1,1,1,1,1,1,1,1,1,1,1,1,0
0,1,1,1,1,1,1,1,1,1,1,1,1,1,1,1,1,1,1,1,1,1,1,1,1,1,0
0,1,1,1,1,1,1,1,1,1,1,1,1,1,1,1,1,1,1,1,1,1,1,1,1,1,0
0,1,1,1,1,1,1,1,1,1,1,1,1,1,1,1,1,1,1,1,1,1,1,1,1,1,0
0,1,1,1,1,1,1,1,1,1,1,1,1,1,1,1,1,1,1,1,1,1,1,1,1,1,0
0,1,1,1,1,1,1,1,1,1,1,1,1,1,1,1,1,1,1,1,1,1,1,1,1,1,0
0,1,1,1,1,1,1,1,1,1,1,1,1,1,1,1,1,1,1,1,1,1,1,1,1,1,0
0,1,1,1,1,1,1,1,1,1,1,1,1,1,1,1,1,1,1,1,1,1,1,1,1,1,0
0,1,1,1,1,1,1,1,1,1,1,1,1,1,1,1,1,1,1,1,1,1,1,1,1,1,0
0,1,1,1,1,1,1,1,1,1,1,1,1,1,1,1,1,1,1,1,1,1,1,1,1,1,0
0,1,1,1,1,1,1,1,1,1,1,1,1,1,1,1,1,1,1,1,1,1,1,1,1,1,0
0,1,1,1,1,1,1,1,1,1,1,1,1,1,1,1,1,1,1,1,1,1,1,1,1,1,0
0,1,1,1,1,1,1,1,1,1,1,1,1,1,1,1,1,1,1,1,1,1,1,1,1,1,0
0,1,1,1,1,1,1,1,1,1,1,1,1,1,1,1,1,1,1,1,1,1,1,1,1,1,0
0,1,1,1,1,1,1,1,1,1,1,1,1,1,1,1,1,1,1,1,1,1,1,1,1,1,0
0,1,1,1,1,1,1,1,1,1,1,1,1,1,1,1,1,1,1,1,1,1,1,1,1,1,0
0,1,1,1,1,1,1,1,1,1,1,1,1,1,1,1,1,1,1,1,1,1,1,1,1,1,0
0,1,1,1,1,1,1,1,1,1,1,1,1,1,4,3,2,1,1,1,1,1,1,1,1,1,0
0,1,1,1,1,1,1,1,1,1,1,1,32,4,4,3,1,1,1,1,1,1,1,1,1,1,0
0,1,1,1,1,1,1,1,1,1,1,1,32,4,4,3,2,1,1,1,1,1,1,1,1,1,0
0,1,1,1,1,1,1,1,1,1,1,1,32,4,4,3,2,1,1,1,1,1,1,1,1,1,0
0,1,1,1,1,1,1,1,1,1,1,1,32,4,4,3,2,1,1,1,1,1,1,1,1,1,0
0,1,1,1,1,1,1,1,1,1,1,1,32,4,4,3,2,1,1,1,1,1,1,1,1,1,0
0,1,1,1,1,1,1,1,1,1,1,1,32,4,1,3,33,1,1,1,1,1,1,1,1,1,0
0,1,1,1,1,1,1,1,1,1,1,1,32,4,4,3,2,1,1,1,1,1,1,1,1,1,0
0,1,1,1,1,1,1,1,1,1,1,1,1,4,4,3,2,1,1,1,1,1,1,1,1,1,0
0,1,1,1,1,1,1,1,1,1,1,1,1,4,4,3,2,1,1,1,1,1,1,1,1,1,0
0,1,1,1,1,1,1,1,1,1,1,1,1,4,4,3,2,1,1,1,1,1,1,1,1,1,0
0,1,1,1,1,1,1,1,1,1,1,1,1,4,1,3,34,1,1,1,1,1,1,1,1,1,0
0,1,1,1,1,1,1,1,1,1,1,1,1,4,4,3,2,1,1,1,1,1,1,1,1,1,0
0,1,1,1,1,1,1,1,1,1,1,1,1,4,4,3,2,1,1,1,1,1,1,1,1,1,0
0,1,1,1,1,1,1,1,1,1,1,1,1,4,4,3,2,1,1,1,1,1,1,1,1,1,0
0,1,1,1,1,1,1,1,1,1,1,1,32,4,4,3,2,1,1,1,1,1,1,1,1,1,0
0,1,1,1,1,1,1,1,1,1,1,1,32,4,1,3,33,1,1,1,1,1,1,1,1,1,0
0,1,1,1,1,1,1,1,1,1,1,1,32,4,4,3,2,1,1,1,1,1,1,1,1,1,0
0,1,1,1,1,1,1,1,1,1,1,1,32,4,4,3,2,1,1,1,1,1,1,1,1,1,0
0,1,1,1,1,1,1,1,1,1,1,1,32,4,4,3,2,1,1,1,1,1,1,1,1,1,0
0,1,1,1,1,1,1,1,1,1,1,1,32,4,4,3,2,1,1,1,1,1,1,1,1,1,0
0,1,1,1,1,1,1,1,1,1,1,1,32,4,1,3,33,1,1,1,1,1,1,1,1,1,0
0,1,1,1,1,1,1,1,1,1,1,1,32,4,4,3,2,1,1,1,1,1,1,1,1,1,0
0,1,1,1,1,1,1,1,1,1,1,1,1,4,4,3,2,1,1,1,1,1,1,1,1,1,0
0,1,1,1,1,1,1,1,1,1,1,1,1,1,1,1,2,1,1,1,1,1,1,1,1,1,0
0,1,1,1,1,1,1,1,1,1,1,1,1,1,1,1,2,1,1,1,1,1,1,1,1,1,0
0,1,1,1,1,1,1,1,1,1,1,1,1,1,1,1,2,1,1,1,1,1,1,1,1,1,0
0,1,1,1,1,1,1,1,1,1,1,1,1,1,1,1,2,1,1,1,1,1,1,1,1,1,0
0,1,1,1,1,1,1,1,1,1,1,1,1,1,1,1,1,1,1,1,1,1,1,1,1,1,0
0,1,1,1,1,1,1,1,1,1,1,1,1,1,1,1,1,1,1,1,1,1,1,1,1,1,0
0,1,1,1,1,1,1,1,1,1,1,1,1,1,1,1,1,1,1,1,1,1,1,1,1,1,0
0,1,1,1,1,1,1,1,1,1,1,1,1,1,1,1,1,1,1,1,1,1,1,1,1,1,0
0,1,1,1,1,1,1,1,1,1,1,1,1,1,1,1,1,1,1,1,1,1,1,1,1,1,0
0,1,1,1,1,1,1,1,1,1,1,1,1,1,1,1,1,1,1,1,1,1,1,1,1,1,0
0,1,1,1,1,1,1,1,1,1,1,1,1,1,1,1,1,1,1,1,1,1,1,1,1,1,0
0,1,1,1,1,1,1,1,1,1,1,1,1,1,1,1,1,1,1,1,1,1,1,1,1,1,0
0,1,1,1,1,1,1,1,1,1,1,1,1,1,1,1,1,1,1,1,1,1,1,1,1,1,0
0,1,1,1,1,1,1,1,1,1,1,1,1,1,1,1,1,1,1,1,1,1,1,1,1,1,0
0,1,1,1,1,1,1,1,1,1,1,1,1,1,1,1,1,1,1,1,1,1,1,1,1,1,0
0,1,1,1,1,1,1,1,1,1,1,1,1,1,1,1,1,1,1,1,1,1,1,1,1,1,0
0,1,1,1,1,1,1,1,1,1,1,1,1,1,1,1,1,1,1,1,1,1,1,1,1,1,0
0,1,1,1,1,1,1,1,1,1,1,1,1,1,1,1,1,1,1,1,1,1,1,1,1,1,0
0,1,1,1,1,1,1,1,1,1,1,1,1,1,1,1,1,1,1,1,1,1,1,1,1,1,0
endlayer

layer
0,1,1,1,1,1,1,1,1,1,1,1,1,1,1,1,1,1,1,1,1,1,1,1,1,1,0
0,1,1,1,1,1,1,1,1,1,1,1,1,1,1,1,1,1,1,1,1,1,1,1,1,1,0
0,1,1,1,1,1,1,1,1,1,1,1,1,1,1,1,1,1,1,1,1,1,1,1,1,1,0
0,1,1,1,1,1,1,1,1,1,1,1,1,1,1,1,1,1,1,1,1,1,1,1,1,1,0
0,1,1,1,1,1,1,1,1,1,1,1,1,1,1,1,1,1,1,1,1,1,1,1,1,1,0
0,1,1,1,1,1,1,1,1,1,1,1,1,1,1,1,1,1,1,1,1,1,1,1,1,1,0
0,1,1,1,1,1,1,1,1,1,1,1,1,1,1,1,1,1,1,1,1,1,1,1,1,1,0
0,1,1,1,1,1,1,1,1,1,1,1,1,1,1,1,1,1,1,1,1,1,1,1,1,1,0
0,1,1,1,1,1,1,1,1,1,1,1,1,1,1,1,1,1,1,1,1,1,1,1,1,1,0
0,1,1,1,1,1,1,1,1,1,1,1,1,1,1,1,1,1,1,1,1,1,1,1,1,1,0
0,1,1,1,1,1,1,1,1,1,1,1,1,1,1,1,1,1,1,1,1,1,1,1,1,1,0
0,1,1,1,1,1,1,1,1,1,1,1,1,1,1,1,1,1,1,1,1,1,1,1,1,1,0
0,1,1,1,1,1,1,1,1,1,1,1,1,1,1,1,1,1,1,1,1,1,1,1,1,1,0
0,1,1,1,1,1,1,1,1,1,1,1,1,1,1,1,1,1,1,1,1,1,1,1,1,1,0
0,1,1,1,1,1,1,1,1,1,1,1,1,1,1,1,1,1,1,1,1,1,1,1,1,1,0
0,1,1,1,1,1,1,1,1,1,1,1,1,1,1,1,1,1,1,1,1,1,1,1,1,1,0
0,1,1,1,1,1,1,1,1,1,1,1,1,1,1,1,1,1,1,1,1,1,1,1,1,1,0
0,1,1,1,1,1,1,1,1,1,1,1,1,1,1,1,1,1,1,1,1,1,1,1,1,1,0
0,1,1,1,1,1,1,1,1,1,1,1,1,1,1,1,1,1,1,1,1,1,1,1,1,1,0
0,1,1,1,1,1,1,1,1,1,1,1,1,1,1,1,1,1,1,1,1,1,1,1,1,1,0
0,1,1,1,1,1,1,1,1,1,1,1,1,1,1,1,1,1,1,1,1,1,1,1,1,1,0
0,1,1,1,1,1,1,1,1,1,1,1,1,1,1,1,1,1,1,1,1,1,1,1,1,1,0
0,1,1,1,1,1,1,1,1,1,1,1,1,1,1,1,1,1,1,1,1,1,1,1,1,1,0
0,1,1,1,1,1,1,1,1,1,1,1,1,1,1,1,1,1,1,1,1,1,1,1,1,1,0
0,1,1,1,1,1,1,1,1,1,1,1,1,1,1,1,1,1,1,1,1,1,1,1,1,1,0
0,1,1,1,1,1,1,1,1,1,1,1,1,1,1,1,1,1,1,1,1,1,1,1,1,1,0
0,1,1,1,1,1,1,1,1,1,1,1,1,1,1,7,1,1,1,1,1,1,1,1,1,1,0
0,1,1,1,1,1,1,1,1,1,1,1,1,1,1,1,1,1,1,1,1,1,1,1,1,1,0
0,1,1,1,1,1,1,1,1,1,1,1,1,1,1,1,1,1,1,1,1,1,1,1,1,1,0
0,1,1,1,1,1,1,1,1,1,1,1,1,1,1,1,1,1,1,1,1,1,1,1,1,1,0
0,1,1,1,1,1,1,1,1,1,1,1,1,1,1,1,1,1,1,1,1,1,1,1,1,1,0
0,1,1,1,1,1,1,1,1,1,1,1,1,1,1,7,1,1,1,1,1,1,1,1,1,1,0
0,1,1,1,1,1,1,1,1,1,1,1,1,1,1,1,1,1,1,1,1,1,1,1,1,1,0
0,1,1,1,1,1,1,1,1,1,1,1,1,1,1,1,1,1,1,1,1,1,1,1,1,1,0
0,1,1,1,1,1,1,1,1,1,1,1,1,1,1,1,1,1,1,1,1,1,1,1,1,1,0
0,1,1,1,1,1,1,1,1,1,1,1,1,1,1,1,1,1,1,1,1,1,1,1,1,1,0
0,1,1,1,1,1,1,1,1,1,1,1,1,1,1,7,1,1,1,1,1,1,1,1,1,1,0
0,1,1,1,1,1,1,1,1,1,1,1,1,1,1,1,1,1,1,1,1,1,1,1,1,1,0
0,1,1,1,1,1,1,1,1,1,1,1,1,1,1,1,1,1,1,1,1,1,1,1,1,1,0
0,1,1,1,1,1,1,1,1,1,1,1,1,1,1,1,1,1,1,1,1,1,1,1,1,1,0
0,1,1,1,1,1,1,1,1,1,1,1,1,1,1,1,1,1,1,1,1,1,1,1,1,1,0
0,1,1,1,1,1,1,1,1,1,1,1,1,1,1,7,1,1,1,1,1,1,1,1,1,1,0
0,1,1,1,1,1,1,1,1,1,1,1,1,1,1,1,1,1,1,1,1,1,1,1,1,1,0
0,1,1,1,1,1,1,1,1,1,1,1,1,1,1,1,1,1,1,1,1,1,1,1,1,1,0
0,1,1,1,1,1,1,1,1,1,1,1,1,1,1,1,1,1,1,1,1,1,1,1,1,1,0
0,1,1,1,1,1,1,1,1,1,1,1,1,1,1,1,1,1,1,1,1,1,1,1,1,1,0
0,1,1,1,1,1,1,1,1,1,1,1,1,1,1,1,1,1,1,1,1,1,1,1,1,1,0
0,1,1,1,1,1,1,1,1,1,1,1,1,1,1,1,1,1,1,1,1,1,1,1,1,1,0
0,1,1,1,1,1,1,1,1,1,1,1,1,1,1,1,1,1,1,1,1,1,1,1,1,1,0
0,1,1,1,1,1,1,1,1,1,1,1,1,1,1,1,1,1,1,1,1,1,1,1,1,1,0
0,1,1,1,1,1,1,1,1,1,1,1,1,1,1,1,1,1,1,1,1,1,1,1,1,1,0
0,1,1,1,1,1,1,1,1,1,1,1,1,1,1,1,1,1,1,1,1,1,1,1,1,1,0
0,1,1,1,1,1,1,1,1,1,1,1,1,1,1,1,1,1,1,1,1,1,1,1,1,1,0
0,1,1,1,1,1,1,1,1,1,1,1,1,1,1,1,1,1,1,1,1,1,1,1,1,1,0
0,1,1,1,1,1,1,1,1,1,1,1,1,1,1,1,1,1,1,1,1,1,1,1,1,1,0
0,1,1,1,1,1,1,1,1,1,1,1,1,1,1,1,1,1,1,1,1,1,1,1,1,1,0
0,1,1,1,1,1,1,1,1,1,1,1,1,1,1,1,1,1,1,1,1,1,1,1,1,1,0
0,1,1,1,1,1,1,1,1,1,1,1,1,1,1,1,1,1,1,1,1,1,1,1,1,1,0
0,1,1,1,1,1,1,1,1,1,1,1,1,1,1,1,1,1,1,1,1,1,1,1,1,1,0
0,1,1,1,1,1,1,1,1,1,1,1,1,1,1,1,1,1,1,1,1,1,1,1,1,1,0
0,1,1,1,1,1,1,1,1,1,1,1,1,1,1,1,1,1,1,1,1,1,1,1,1,1,0
0,1,1,1,1,1,1,1,1,1,1,1,1,1,1,1,1,1,1,1,1,1,1,1,1,1,0
0,1,1,1,1,1,1,1,1,1,1,1,1,1,1,1,1,1,1,1,1,1,1,1,1,1,0
endlayer

