
# Created by Ruins mod version 15.0 Ingame Parser
# authoring Player: SunsOfOld

weight=50
embed_into_distance=0
acceptable_target_blocks=
unacceptable_target_blocks=flowing_water,water,flowing_lava,lava
dimensions=10,13,13
allowable_overhang=0
max_leveling=4
leveling_buffer=0
preserve_water=0
preserve_lava=0
uniqueMinDistance=1000000
preventRotation=1

rule1=0,100,dendrology:stairs5-0
rule2=0,100,dendrology:stairs5-2
rule3=0,100,chisel:concrete-1
rule4=0,100,BiomesOPlenty:logs3-10
rule5=0,100,dendrology:stairs5-3
rule6=0,100,BiomesOPlenty:logs3-6
rule7=0,100,dendrology:logs1-1
rule8=0,100,UndergroundBiomes:sedimentary_monsterStoneEgg-7
rule9=0,100,dendrology:stairs5-1
rule10=0,100,BiblioCraft:BiblioSeats-6
rule11=0,100,BiblioCraft:BiblioSimplePainting-6
rule12=0,100,chisel:limestone_stairs.5-8
rule13=0,100,chisel:limestone_stairs.5-10
rule14=0,100,BiblioCraft:BiblioWorkbench-5
rule15=0,100,ExtrabiomesXL:door_cypress-7
rule16=0,100,chisel:limestone_stairs.5-9
rule17=0,100,minecraft:stained_glass_pane-12
rule18=0,100,BiomesOPlenty:logs3-2
rule19=2,100,WallSign:null:null:null:null-4
rule20=0,100,IInventory;minecraft:chest;harvestcraft:hardenedleatherhelmItem#1#0#0+minecraft:bone#1#0#3+minecraft:bone#1#0#4+minecraft:bone#1#0#5+harvestcraft:hardenedleatherchestItem#1#0#8+harvestcraft:bellpepperseedItem#1#0#10+dendrology:sapling1#1#4#11+minecraft:bone#1#0#12+minecraft:enchanted_book#{RepairCost:2,display:{Name:"Church of the Forgotten",},StoredEnchantments:[0:{id:17s,lvl:5s,},],}#0#13+minecraft:bone#1#0#14+dendrology:sapling1#1#4#15+harvestcraft:bellpepperseedItem#1#0#16+harvestcraft:hardenedleatherleggingsItem#1#0#18+minecraft:bone#1#0#21+minecraft:bone#1#0#22+minecraft:bone#1#0#23+harvestcraft:hardenedleatherbootsItem#1#0#26-2
rule21=2,100,WallSign:null:null:null:null-3
rule22=0,100,ExtrabiomesXL:door_cypress-8
rule23=2,100,WallSign:null:null:null:null-5
rule24=0,100,dendrology:stairs5-4
rule25=0,100,dendrology:hekur_planks-15
rule26=0,100,UndergroundBiomes:igneous_monsterStoneEgg-5
rule27=0,100,dendrology:stairs5-5
rule28=0,100,GardenStuff:fence-0
rule29=0,100,BiblioCraft:BiblioIronLantern-15
rule30=0,100,dendrology:stairs5-7
rule31=0,100,BiomesOPlenty:grave-0
rule32=0,100,BiomesOPlenty:grave-1

layer
0,0,0,0,0,0,0,0,0,0,0,0,0
0,1,1,1,1,1,1,1,1,1,1,1,0
0,5,3,4,4,4,4,4,4,4,3,2,0
0,5,6,7,8,8,8,8,8,7,6,2,0
1,5,6,8,7,8,8,8,7,8,6,2,0
5,3,6,8,8,7,8,7,8,8,6,2,0
5,3,3,8,8,8,7,8,8,8,6,2,0
5,3,6,8,8,7,8,7,8,8,6,2,0
9,9,6,8,7,8,8,8,7,8,6,2,0
0,5,6,7,8,8,8,8,8,7,6,2,0
0,5,3,4,4,4,4,4,4,4,3,2,0
0,9,9,9,9,9,9,9,9,9,9,2,0
0,0,0,0,0,0,0,0,0,0,0,0,0
endlayer

layer
0,0,0,0,0,0,0,0,0,0,0,0,0
0,0,0,0,0,0,0,0,0,0,0,0,0
0,0,3,4,4,4,4,4,4,4,3,0,0
0,0,6,11,11,9,9,9,11,10,6,0,0
0,0,6,2,0,0,0,0,0,0,6,0,0
0,0,1,0,0,0,0,0,12,12,6,0,0
0,0,15,0,0,0,0,14,7,13,6,0,0
0,0,9,11,0,0,0,0,16,16,6,0,0
0,0,6,2,0,0,0,0,0,0,6,0,0
0,0,6,11,11,1,1,1,11,10,6,0,0
0,0,3,4,4,4,4,4,4,4,3,0,0
0,0,0,0,0,0,0,0,0,0,0,0,0
0,0,0,0,0,0,0,0,0,0,0,0,0
endlayer

layer
0,0,0,0,0,0,0,0,0,0,0,0,0
0,0,0,0,0,0,0,0,0,0,0,0,0
0,0,3,17,17,17,17,17,17,17,3,0,0
0,0,17,0,0,0,0,0,0,0,17,0,0
0,0,18,0,0,0,0,0,0,0,3,0,0
0,0,3,0,0,0,0,19,0,0,3,0,0
0,0,22,0,0,0,21,20,0,0,17,0,0
0,0,3,0,0,0,0,23,0,0,3,0,0
0,0,18,0,0,0,0,0,0,0,3,0,0
0,0,17,0,0,0,0,0,0,0,17,0,0
0,0,3,17,17,17,17,17,17,17,3,0,0
0,0,0,0,0,0,0,0,0,0,0,0,0
0,0,0,0,0,0,0,0,0,0,0,0,0
endlayer

layer
0,0,0,0,0,0,0,0,0,0,0,0,0
0,0,0,0,0,0,0,0,0,0,0,0,0
0,0,3,24,24,24,24,24,24,24,3,0,0
0,0,25,26,26,26,26,26,26,26,25,0,0
0,0,18,0,0,0,0,0,0,0,3,0,0
0,0,24,0,0,0,0,0,0,0,3,0,0
0,0,3,0,0,0,0,0,0,0,17,0,0
0,0,27,0,0,0,0,0,0,0,3,0,0
0,0,18,0,0,0,0,0,0,0,3,0,0
0,0,25,26,26,26,26,26,26,26,25,0,0
0,0,3,27,27,27,27,27,27,27,3,0,0
0,0,0,0,0,0,0,0,0,0,0,0,0
0,0,0,0,0,0,0,0,0,0,0,0,0
endlayer

layer
0,0,0,0,0,0,0,0,0,0,0,0,0
0,0,0,0,0,0,0,0,0,0,0,0,0
0,4,4,4,4,4,4,4,4,4,4,4,0
0,0,28,5,1,1,1,1,1,2,28,0,0
0,0,25,4,4,4,4,4,4,4,25,0,0
0,0,5,0,0,0,0,0,0,0,17,0,0
0,0,18,29,0,0,0,0,0,0,3,0,0
0,0,5,0,0,0,0,0,0,0,17,0,0
0,0,25,4,4,4,4,4,4,4,25,0,0
0,0,28,5,9,9,9,9,9,2,28,0,0
0,4,4,4,4,4,4,4,4,4,4,4,0
0,0,0,0,0,0,0,0,0,0,0,0,0
0,0,0,0,0,0,0,0,0,0,0,0,0
endlayer

layer
0,0,0,0,0,0,0,0,0,0,0,0,0
0,0,0,0,0,0,0,0,0,0,0,0,0
0,0,28,28,28,28,28,28,28,28,28,0,0
0,0,28,0,0,0,0,0,0,0,28,0,0
0,0,28,5,1,1,1,1,1,2,28,0,0
0,0,25,26,26,26,26,26,26,26,25,0,0
0,0,30,0,0,0,0,0,0,0,17,0,0
0,0,25,26,26,26,26,26,26,26,25,0,0
0,0,28,5,9,9,9,9,9,2,28,0,0
0,0,28,0,0,0,0,0,0,0,28,0,0
0,0,28,28,28,28,28,28,28,28,28,0,0
0,0,0,0,0,0,0,0,0,0,0,0,0
0,0,0,0,0,0,0,0,0,0,0,0,0
endlayer

layer
0,0,0,0,0,0,0,0,0,0,0,0,0
0,0,0,0,0,0,0,0,0,0,0,0,0
0,0,0,0,0,0,0,0,0,0,0,0,0
0,0,0,0,0,0,0,0,0,0,0,0,0
0,0,28,0,0,0,0,0,0,0,28,0,0
0,0,28,5,1,1,1,1,1,2,28,0,0
0,0,4,4,4,4,4,4,4,4,4,0,0
0,0,28,5,9,9,9,9,9,2,28,0,0
0,0,28,0,0,0,0,0,0,0,28,0,0
0,0,0,0,0,0,0,0,0,0,0,0,0
0,0,0,0,0,0,0,0,0,0,0,0,0
0,0,0,0,0,0,0,0,0,0,0,0,0
0,0,0,0,0,0,0,0,0,0,0,0,0
endlayer

layer
0,0,0,0,0,0,0,0,0,0,0,0,0
0,0,0,0,0,0,0,0,0,0,0,0,0
0,0,0,0,0,0,0,0,0,0,0,0,0
0,0,0,0,0,0,0,0,0,0,0,0,0
0,0,0,0,0,0,0,0,0,0,0,0,0
0,0,0,0,0,5,1,2,0,0,0,0,0
0,0,0,0,0,5,18,2,0,0,0,0,0
0,0,0,0,0,5,9,2,0,0,0,0,0
0,0,0,0,0,0,0,0,0,0,0,0,0
0,0,0,0,0,0,0,0,0,0,0,0,0
0,0,0,0,0,0,0,0,0,0,0,0,0
0,0,0,0,0,0,0,0,0,0,0,0,0
0,0,0,0,0,0,0,0,0,0,0,0,0
endlayer

layer
0,0,0,0,0,0,0,0,0,0,0,0,0
0,0,0,0,0,0,0,0,0,0,0,0,0
0,0,0,0,0,0,0,0,0,0,0,0,0
0,0,0,0,0,0,0,0,0,0,0,0,0
0,0,0,0,0,0,0,0,0,0,0,0,0
0,0,0,0,0,0,0,0,0,0,0,0,0
0,0,0,0,0,0,31,0,0,0,0,0,0
0,0,0,0,0,0,0,0,0,0,0,0,0
0,0,0,0,0,0,0,0,0,0,0,0,0
0,0,0,0,0,0,0,0,0,0,0,0,0
0,0,0,0,0,0,0,0,0,0,0,0,0
0,0,0,0,0,0,0,0,0,0,0,0,0
0,0,0,0,0,0,0,0,0,0,0,0,0
endlayer

layer
0,0,0,0,0,0,0,0,0,0,0,0,0
0,0,0,0,0,0,0,0,0,0,0,0,0
0,0,0,0,0,0,0,0,0,0,0,0,0
0,0,0,0,0,0,0,0,0,0,0,0,0
0,0,0,0,0,0,0,0,0,0,0,0,0
0,0,0,0,0,0,0,0,0,0,0,0,0
0,0,0,0,0,0,32,0,0,0,0,0,0
0,0,0,0,0,0,0,0,0,0,0,0,0
0,0,0,0,0,0,0,0,0,0,0,0,0
0,0,0,0,0,0,0,0,0,0,0,0,0
0,0,0,0,0,0,0,0,0,0,0,0,0
0,0,0,0,0,0,0,0,0,0,0,0,0
0,0,0,0,0,0,0,0,0,0,0,0,0
endlayer

