
# Created by Ruins mod version 15.0 Ingame Parser
# authoring Player: SunsOfOld

weight=100
embed_into_distance=19
acceptable_target_blocks=
unacceptable_target_blocks=flowing_water,water,flowing_lava,lava
dimensions=51,37,48
allowable_overhang=0
max_leveling=7
leveling_buffer=0
preserve_water=0
preserve_lava=0
uniqueMinDistance=1000000
preventRotation=1

rule1=0,100,preserveBlock
rule2=0,100,UndergroundBiomes:igneousStone-3
rule3=0,100,minecraft:gravel-0
rule4=0,100,chisel:andesite-0
rule5=0,100,minecraft:dirt-0
rule6=0,100,chisel:diorite-0
rule7=0,100,UndergroundBiomes:sedimentary_oreIron-0
rule8=0,100,UndergroundBiomes:igneous_oreIron-3
rule9=0,100,UndergroundBiomes:metamorphicStone-6
rule10=0,100,chisel:marble-0
rule11=0,100,chisel:limestone-0
rule12=0,100,UndergroundBiomes:metamorphic_oreIron-6
rule13=0,100,UndergroundBiomes:igneous_oreCoal-3
rule14=0,100,UndergroundBiomes:sedimentaryStone-1
rule15=0,100,UndergroundBiomes:sedimentary_oreIron-1
rule16=0,100,chisel:granite-0
rule17=0,100,harvestcraft:salt-0
rule18=0,100,UndergroundBiomes:metamorphicStone-4
rule19=0,100,UndergroundBiomes:igneousStone-11
rule20=0,100,minecraft:bedrock-0
rule21=0,100,UndergroundBiomes:metamorphicStone-14
rule22=0,100,minecraft:web-0
rule23=0,100,BiomesOPlenty:gemOre-2
rule24=0,100,BiomesOPlenty:hardDirt-0
rule25=0,100,dendrology:logs0-0
rule26=0,100,plantmegapack:epiphyteArtistsConk-5
rule27=0,100,BiomesOPlenty:stoneFormations-1
rule28=0,100,minecraft:redstone_wire-12
rule29=0,100,minecraft:redstone_wire-13
rule30=0,100,minecraft:redstone_wire-14
rule31=0,100,minecraft:redstone_wire-15
rule32=0,100,minecraft:unpowered_repeater-3
rule33=0,100,minecraft:unpowered_repeater-13
rule34=0,100,minecraft:powered_repeater-3
rule35=0,100,CommandBlock:/setblock ~ ~ ~ 152:@
rule36=2,100,minecraft:redstone_torch-3
rule37=0,100,CommandBlock:/summon MinecartChest ~ ~4 ~ {Items:[{id:157,Slot:1,Count:1},{id:263,Slot:0,Count:7},{id:28,Slot:2,Count:1},{id:66,Slot:3,Count:1},{id:27,Slot:4,Count:1},{id:46,Slot:5,Count:5},{id:349,Slot:9,Count:1},{id:285,Slot:14,Count:1,tag:{ench:[{id:35,lvl:3}],display:{Name:"Lucky Strike"}}}]}:@
rule38=0,100,minecraft:powered_repeater-1
rule39=0,100,minecraft:redstone_wire-0
rule40=0,100,minecraft:unpowered_repeater-0
rule41=0,100,minecraft:unpowered_comparator-0
rule42=0,100,CommandBlock:/testfor @p[r=16]:@
rule43=0,100,GardenStuff:lantern-0
rule44=0,100,UndergroundBiomes:sedimentaryStone-5
rule45=0,100,UndergroundBiomes:sedimentary_oreDiamond-1
rule46=0,100,minecraft:ladder-4
rule47=0,100,minecraft:water-0
rule48=0,100,minecraft:rail-1
rule49=0,100,UndergroundBiomes:sedimentaryStone-13
rule50=0,100,minecraft:rail-7
rule51=0,100,minecraft:rail-0
rule52=0,100,minecraft:stone_slab-8
rule53=0,100,minecraft:sand-0
rule54=0,100,UndergroundBiomes:sedimentary_oreCoal-5
rule55=0,100,UndergroundBiomes:sedimentary_oreIron-5
rule56=0,100,GardenStuff:light_chain-4
rule57=0,100,minecraft:sandstone-0
rule58=0,100,dendrology:logs0-4
rule59=0,100,plantmegapack:epiphyteArtistsConk-3
rule60=0,100,minecraft:rail-5
rule61=0,100,UndergroundBiomes:sedimentaryStone-15
rule62=0,100,UndergroundBiomes:igneous_oreGold-3
rule63=0,100,plantmegapack:epiphyteTurkeyTail-5
rule64=0,100,minecraft:rail-3
rule65=0,100,UndergroundBiomes:sedimentaryStone-6
rule66=0,100,UndergroundBiomes:sedimentaryStone-14
rule67=0,100,minecraft:lava-0
rule68=0,100,plantmegapack:epiphyteTurkeyTail-3
rule69=0,100,minecraft:piston-0
rule70=0,100,BiomesOPlenty:hardSand-0
rule71=0,100,minecraft:grass-0
rule72=0,100,minecraft:rail-9
rule73=0,100,minecraft:sand-1
rule74=0,100,minecraft:cactus-3
rule75=0,100,plantmegapack:epiphyteTurkeyTail-4
rule76=0,100,plantmegapack:epiphyteArtistsConk-2
rule77=0,100,dendrology:logs0-8
rule78=0,100,plantmegapack:desertOcotillo-6
rule79=0,100,BiomesOPlenty:mushrooms-1
rule80=0,100,dendrology:leaves0-12
rule81=0,100,dendrology:leaves0-4
rule82=0,100,BiomesOPlenty:foliage-2
rule83=0,100,BiomesOPlenty:mushrooms-0
rule84=0,100,minecraft:cactus-2
rule85=0,100,BiomesOPlenty:colorizedLeaves2-5
rule86=0,100,harvestcraft:desertgarden-0
rule87=0,100,BiomesOPlenty:colorizedLeaves2-13
rule88=0,100,plantmegapack:fungusGiantClub-0
rule89=0,100,minecraft:cactus-0
rule90=0,100,plantmegapack:desertOcotillo-7
rule91=0,100,plantmegapack:flowerWoodlandPinkroot-0
rule92=0,100,plantmegapack:groundcoverGrassGRNLT-0
rule93=0,100,plantmegapack:fungusDeathCap-0
rule94=0,100,plantmegapack:flowerAchillea-2
rule95=0,100,minecraft:rail-2
rule96=0,100,UndergroundBiomes:sedimentaryStone-7
rule97=0,100,minecraft:water-1
rule98=0,100,minecraft:water-8
rule99=0,100,UndergroundBiomes:sedimentary_oreCoal-7
rule100=0,100,plantmegapack:vineFlowersPink-4
rule101=0,100,BiomesOPlenty:logs4-0
rule102=0,100,minecraft:stone_stairs-0
rule103=0,100,plantmegapack:fernSword-1
rule104=0,100,dendrology:leaves0-0
rule105=0,100,minecraft:stone_stairs-3
rule106=0,100,plantmegapack:epiphyteTurkeyTail-2
rule107=0,100,minecraft:dirt-2
rule108=0,100,BiomesOPlenty:foliage-11
rule109=0,100,minecraft:stone_stairs-1
rule110=0,100,BiomesOPlenty:foliage-10
rule111=0,100,plantmegapack:vineFlowersPink-2
rule112=0,100,plantmegapack:epiphyteArtistsConk-4
rule113=0,100,BiomesOPlenty:logs4-8
rule114=0,100,plantmegapack:vineFlowersPink-1
rule115=0,100,plantmegapack:epiphyteSulphurShelf-4
rule116=0,100,plantmegapack:vineFlowersPink-8
rule117=0,100,BiomesOPlenty:mushrooms-4
rule118=0,100,minecraft:leaves2-0
rule119=0,100,plantmegapack:desertOcotillo-2
rule120=0,100,minecraft:log2-0
rule121=0,100,harvestcraft:mushroomgarden-0
rule122=0,100,minecraft:wool-0
rule123=0,100,GardenStuff:lattice-1
rule124=0,100,IInventory;minecraft:chest;minecraft:writable_book#{RepairCost:2,pages:[0:"Day 27    The going is slow but steady.  I am this close to something good.  I can feel it.",1:"Day 32    Any day now, I'll be making my fortune.  I'll hit the motherload and then me and Bloquita are headed into the sunset,",2:"Day 40    I don't understand.  I almost feel like I am missing something.  Did I pass it?",3:"Day 50    I quit.  Maybe whoever finds this will have better luck.  Bloquita and I are going into the sunset early.  Who needs a diamond ring to get married anyway, right?",],display:{Name:"Pages From a Tattered Journal",},}#0#4+minecraft:rail#1#0#13-3
rule125=0,100,chisel:carpet-0
rule126=0,100,chisel:carpet-10
rule127=0,100,plantmegapack:desertOcotillo-3
rule128=0,100,BiomesOPlenty:colorizedLeaves2-1

layer
1,1,1,1,1,1,1,1,1,1,1,1,1,1,1,1,1,1,1,1,1,1,1,1,1,1,1,1,1,1,1,1,1,1,1,1,1,1,1,1,1,1,1,1,1,1,1,1
1,1,2,2,2,2,2,2,2,4,4,4,4,4,4,2,2,2,2,2,3,2,2,2,2,2,2,2,2,2,2,2,2,2,2,1,1,1,1,1,1,1,1,1,1,1,1,1
1,0,0,2,2,2,2,2,2,2,4,4,4,4,4,2,2,2,2,2,2,2,5,5,5,5,2,2,2,2,2,2,2,2,2,2,1,1,2,2,2,2,2,2,2,2,2,1
1,0,0,2,2,2,2,2,2,2,2,2,4,4,4,2,2,2,2,2,2,5,5,5,5,5,2,2,2,2,2,2,2,2,2,6,1,1,2,2,2,2,2,2,2,2,2,1
1,0,0,0,2,2,2,2,2,2,2,2,2,2,2,2,2,2,2,2,2,5,5,5,5,5,2,2,4,4,4,4,4,4,4,6,1,1,6,2,2,2,2,2,2,2,2,1
1,0,0,0,2,2,2,2,2,2,2,2,2,2,2,2,2,2,2,5,5,5,5,5,5,2,2,2,4,4,4,4,4,4,4,4,1,1,6,2,2,2,2,2,2,2,2,1
1,0,0,0,2,2,2,2,2,2,2,2,2,2,2,2,2,2,2,5,5,2,2,2,2,2,2,2,4,4,4,4,4,4,4,4,1,1,2,2,2,2,2,2,2,2,2,1
1,0,0,2,2,2,2,2,2,2,2,2,2,2,2,2,2,2,2,5,5,2,2,2,2,2,2,2,2,2,4,4,4,4,4,2,1,1,2,2,2,2,2,2,2,2,2,1
1,0,0,2,2,2,2,2,2,2,2,2,2,2,2,2,8,8,2,2,2,2,2,2,2,7,2,2,2,2,2,2,2,2,2,2,1,1,2,2,2,2,2,2,2,2,2,1
1,0,0,2,2,2,2,2,2,2,2,2,2,2,2,2,8,8,2,2,2,2,2,2,7,7,7,2,2,2,2,2,2,2,2,2,1,1,2,2,2,2,2,2,2,2,2,1
1,0,2,2,2,2,2,2,2,2,2,6,6,2,2,2,2,2,2,2,2,2,2,2,7,2,2,2,2,2,2,2,2,2,2,2,1,1,2,2,2,2,2,2,2,2,2,1
1,9,2,2,2,2,2,2,2,2,6,6,6,6,2,2,2,2,2,2,2,2,2,2,2,2,2,2,2,2,2,2,2,2,4,4,1,1,2,2,2,2,2,2,2,2,2,1
1,9,2,2,2,2,2,2,2,2,6,6,6,6,2,2,2,2,2,2,2,2,2,2,2,2,2,2,2,2,4,4,4,4,4,4,1,1,2,2,2,2,2,2,2,10,10,1
1,9,2,2,2,2,2,2,2,2,2,6,6,6,2,2,2,2,11,11,2,2,2,2,2,2,2,2,2,4,4,4,4,4,4,4,1,1,5,2,2,2,2,2,10,10,10,1
1,9,2,2,2,2,2,2,2,2,2,6,6,6,6,8,11,11,11,11,11,2,2,2,2,2,2,2,2,4,4,4,4,4,2,2,1,1,5,5,2,2,2,10,10,10,10,1
1,9,2,2,2,2,2,2,2,2,2,6,6,6,6,11,11,11,11,11,11,2,2,2,2,2,2,2,2,2,4,4,2,2,2,2,1,1,5,5,5,2,10,10,10,10,10,1
1,0,2,2,2,2,2,2,2,2,2,6,6,6,6,6,11,11,11,11,11,2,2,2,2,2,2,2,2,2,2,2,2,2,2,2,1,1,5,5,5,2,10,10,10,0,10,1
1,0,0,2,2,2,2,2,2,2,2,2,6,6,6,8,8,11,11,11,2,2,2,2,2,2,2,2,2,2,2,2,2,2,2,2,1,1,5,5,5,2,2,2,2,2,2,1
1,0,0,0,0,2,2,2,2,2,2,2,6,6,6,8,8,11,2,2,2,2,2,2,2,2,2,2,2,2,2,2,2,2,2,2,1,1,2,5,5,5,2,2,2,2,2,1
1,0,0,0,0,0,0,2,2,2,2,2,2,2,6,2,2,2,2,2,2,2,2,2,2,2,2,2,2,2,2,2,2,2,2,2,1,1,2,5,5,5,2,2,2,2,2,1
1,0,0,0,0,0,0,0,2,2,2,2,2,2,2,2,2,2,2,4,4,4,4,2,2,2,2,2,2,2,2,2,2,2,2,2,1,1,2,2,5,2,2,2,2,2,2,1
1,0,0,0,0,0,0,0,0,2,2,2,2,2,2,2,2,2,2,2,4,4,4,4,2,2,2,2,2,2,2,2,2,2,2,2,1,1,2,2,2,2,2,2,2,2,2,1
1,9,0,0,0,0,0,0,0,2,2,2,2,2,2,2,2,2,2,2,4,4,4,4,4,2,2,2,2,2,2,2,2,2,8,2,1,1,2,2,2,2,2,2,2,2,2,1
1,4,4,4,0,0,0,0,0,2,2,2,2,2,2,2,0,0,2,2,2,4,4,4,4,4,2,2,2,2,2,2,2,2,2,2,1,1,2,2,2,2,2,2,2,2,2,1
1,12,4,4,4,4,0,0,0,2,2,2,2,2,2,0,0,0,2,2,2,2,4,4,4,4,2,2,2,2,2,2,2,2,8,2,1,1,2,2,2,2,2,8,2,2,2,1
1,4,4,4,4,4,4,2,2,2,2,2,2,2,2,0,0,0,2,2,2,2,2,4,4,4,4,2,2,13,13,2,2,8,2,2,1,1,2,2,2,2,2,8,8,2,2,1
1,4,4,4,2,2,2,2,2,2,2,2,2,2,2,2,0,0,2,2,2,2,2,2,4,4,4,2,13,13,13,13,2,2,2,2,1,1,2,2,2,2,2,8,2,14,14,1
1,9,2,2,2,2,2,8,2,2,2,2,2,2,2,2,2,2,2,2,2,2,2,2,4,4,4,2,13,13,13,13,13,2,2,2,1,1,2,2,2,6,6,8,15,14,14,1
1,9,2,2,2,2,2,16,2,2,2,2,2,2,2,2,2,2,2,2,2,2,2,4,4,4,4,2,2,13,2,13,13,2,2,2,1,1,2,2,2,6,6,6,14,14,14,1
1,9,2,2,2,16,16,16,16,2,2,2,2,2,2,11,2,2,2,2,2,2,4,4,4,4,2,2,2,2,2,2,2,2,2,2,1,1,2,2,2,6,6,14,14,14,14,1
1,9,2,2,2,16,16,16,16,2,2,2,2,2,2,11,2,2,2,2,2,2,4,4,4,2,2,2,2,2,2,2,2,2,2,2,1,1,2,2,2,6,6,14,14,17,14,1
1,9,2,2,16,16,16,16,16,2,2,2,2,2,2,2,2,2,2,2,2,2,4,4,4,2,2,2,2,2,2,2,2,2,2,2,1,1,2,2,14,14,14,14,14,14,14,1
1,9,2,16,16,16,16,16,2,2,2,2,2,2,2,2,2,2,2,2,2,2,2,4,2,2,5,2,2,2,2,2,2,2,2,2,1,1,8,15,14,14,14,14,14,14,14,1
1,9,2,16,16,16,16,16,2,2,2,2,2,2,2,2,2,2,2,2,2,2,2,2,2,2,2,2,2,2,2,2,2,2,2,2,1,1,14,14,14,14,14,14,14,14,14,1
1,1,2,1,16,16,16,2,2,2,2,2,2,2,2,2,2,2,2,2,2,2,2,2,2,5,5,2,2,2,2,2,2,2,2,2,1,1,14,14,14,14,14,14,14,14,14,1
1,1,1,1,1,1,2,2,2,2,2,2,2,2,2,2,2,2,2,2,2,2,2,2,2,5,5,2,2,2,2,2,2,2,2,2,1,1,14,14,14,14,14,14,14,14,14,1
1,1,1,1,1,1,1,1,1,1,1,1,1,1,1,1,1,1,1,1,1,1,1,1,1,1,1,1,1,1,1,1,1,1,1,1,1,1,1,1,1,1,1,1,1,1,1,1
endlayer

layer
1,1,1,1,1,1,1,1,1,1,1,1,1,1,1,1,1,1,1,1,1,1,1,1,1,1,1,1,1,1,1,1,1,1,1,1,1,1,1,1,1,1,1,1,1,1,1,1
1,1,2,2,2,2,2,2,2,2,4,4,4,2,2,2,2,2,2,2,3,2,2,2,2,2,2,2,2,2,2,2,2,2,2,1,1,1,2,2,1,1,1,1,1,1,1,1
1,0,2,2,2,2,2,2,2,2,2,2,2,4,2,2,2,2,2,2,2,2,2,2,2,2,2,2,2,2,2,2,2,2,2,2,1,1,2,2,2,2,2,2,2,2,2,1
1,0,0,2,2,2,2,2,2,2,2,2,2,2,2,2,2,2,2,2,2,2,5,5,5,2,2,2,2,2,2,2,2,2,2,2,1,1,2,2,2,2,2,2,2,2,2,1
1,0,0,0,2,2,2,2,2,2,2,2,2,2,2,2,2,2,2,2,2,2,5,5,5,2,2,2,4,4,6,6,4,4,4,2,1,1,2,2,2,2,2,2,2,2,2,1
1,0,0,0,0,0,2,2,2,2,2,2,2,2,2,2,2,2,2,2,2,2,2,2,2,2,2,2,4,6,6,6,4,17,17,8,1,1,2,2,2,2,2,2,2,2,2,1
1,0,0,0,0,0,2,2,2,2,2,2,2,2,2,2,2,2,2,2,2,2,2,2,2,2,2,2,13,13,6,4,4,17,17,4,1,1,2,2,2,2,2,2,2,2,2,1
1,0,0,2,2,2,2,2,2,2,2,2,2,2,2,2,2,2,2,2,2,2,2,2,2,0,0,0,13,2,4,4,4,4,4,4,1,1,2,2,2,2,2,2,2,2,2,1
1,0,0,2,2,2,2,2,2,2,2,2,2,2,2,2,8,8,2,2,2,2,2,2,0,0,0,2,2,2,2,2,4,4,2,2,1,1,2,2,2,2,2,2,2,2,2,1
1,0,4,2,2,2,2,2,2,2,2,2,2,2,2,2,8,8,2,2,2,2,2,2,0,0,0,2,2,2,2,2,2,2,2,2,1,1,2,2,2,2,2,2,2,2,2,1
1,0,2,2,2,2,2,2,2,2,2,6,6,2,2,2,2,2,2,2,2,2,2,2,2,0,2,2,2,2,2,2,2,2,4,4,1,1,2,2,2,0,0,2,8,2,2,1
1,9,2,2,2,2,2,2,2,2,6,6,6,6,2,2,2,2,2,2,2,5,2,2,2,2,2,2,2,2,2,2,2,4,4,4,1,1,2,2,2,2,2,2,8,2,2,1
1,9,2,2,2,2,2,2,2,2,6,6,6,6,2,2,2,2,2,2,2,2,2,2,2,2,2,2,2,2,4,4,4,4,4,4,1,1,2,2,2,2,2,2,2,2,2,1
1,9,2,2,2,2,2,2,2,2,2,6,6,6,2,2,2,2,2,2,2,2,2,2,2,2,2,2,2,4,4,4,4,4,4,4,1,1,5,2,2,2,2,2,2,10,10,1
1,9,2,2,2,2,2,2,2,2,2,6,6,6,6,8,2,2,2,2,2,2,2,2,2,2,2,2,2,4,4,4,4,4,4,4,1,1,5,5,2,2,2,2,2,10,10,1
1,9,2,2,2,2,2,2,2,2,2,6,6,6,6,2,11,11,11,11,2,2,2,2,2,2,2,2,2,2,4,4,4,2,2,2,1,1,5,5,5,2,2,2,10,10,10,1
1,0,2,2,2,2,2,2,2,2,2,6,6,6,6,6,11,11,11,2,2,2,2,2,2,2,2,2,2,2,2,2,2,2,2,2,1,1,5,5,5,2,2,2,2,0,5,1
1,0,0,17,2,2,2,2,2,2,2,2,6,6,6,6,11,11,2,2,2,2,2,2,2,2,2,2,2,2,2,2,2,2,2,13,1,1,5,5,5,5,2,2,2,5,5,1
1,0,0,0,0,2,2,2,2,2,2,2,6,6,6,2,2,2,2,2,2,2,2,2,2,2,2,2,2,2,2,2,2,2,2,13,1,1,5,5,5,5,2,2,2,5,5,1
1,0,0,0,0,0,2,2,2,2,2,2,2,2,6,2,2,2,2,2,2,2,2,2,2,2,2,2,2,2,2,2,2,2,2,13,1,1,5,5,5,5,5,2,2,2,5,1
1,0,0,0,0,0,0,2,2,2,2,2,2,2,2,2,2,2,2,4,4,4,4,2,2,2,2,2,2,2,2,2,2,2,2,2,1,1,2,5,5,5,5,2,2,2,2,1
1,0,0,0,0,0,0,0,2,2,2,2,2,2,2,2,2,2,2,4,4,4,4,4,4,2,2,2,2,2,2,2,2,8,8,2,1,1,2,2,5,5,2,2,2,2,2,1
1,9,0,0,0,0,0,0,2,2,2,2,2,2,2,2,2,2,2,2,4,4,4,4,4,4,2,2,2,2,2,2,2,8,8,2,1,1,2,2,2,2,2,2,2,2,2,1
1,4,4,4,4,0,0,0,2,2,2,2,2,2,2,0,0,2,2,2,4,4,4,4,4,4,4,2,2,2,2,2,10,10,2,2,1,1,2,2,2,2,2,2,2,2,2,1
1,4,4,4,4,4,4,2,2,2,2,2,2,2,0,0,0,0,2,2,2,4,4,4,4,4,4,2,2,2,10,10,10,10,2,2,1,1,2,2,2,2,2,8,8,2,2,1
1,4,4,4,4,4,4,2,2,2,2,2,2,2,0,0,0,0,2,2,2,2,2,4,4,4,4,2,2,2,10,10,10,8,2,2,1,1,2,2,2,2,6,6,2,2,2,1
1,4,4,4,4,2,2,2,2,2,2,2,2,2,2,0,0,2,2,2,2,2,2,2,4,4,4,2,2,2,13,13,10,2,2,2,1,1,2,2,2,6,6,8,2,2,2,1
1,9,2,2,2,2,8,8,2,2,2,2,2,2,2,2,2,2,2,2,2,2,2,4,4,4,4,2,2,2,13,13,13,2,2,2,1,1,2,2,2,6,6,8,8,2,2,1
1,9,2,2,2,2,8,8,16,2,2,2,2,2,2,2,2,2,2,2,2,2,2,4,4,4,4,2,2,2,2,13,13,2,2,2,1,1,2,2,6,6,6,6,2,2,2,1
1,9,2,2,2,16,16,16,16,2,2,2,2,2,2,2,2,2,2,2,2,2,4,4,4,4,4,2,2,2,2,2,2,2,2,2,1,1,2,2,6,6,6,6,2,2,2,1
1,9,2,2,2,16,16,16,16,2,2,2,2,2,2,2,2,2,2,2,2,4,4,4,4,4,2,2,2,2,2,8,8,2,2,2,1,1,2,2,6,6,6,6,2,17,14,1
1,9,2,2,16,16,16,16,16,2,2,2,2,2,2,2,2,2,2,2,2,4,4,4,4,4,2,2,2,2,2,8,8,2,2,2,1,1,8,8,6,6,6,6,17,14,14,1
1,1,2,16,16,16,16,16,2,2,2,2,2,2,2,2,2,2,2,2,2,4,4,4,4,2,2,2,2,2,2,2,2,2,2,2,1,1,2,2,6,6,6,14,14,14,14,1
1,1,1,1,16,16,16,16,2,2,2,2,2,2,2,2,2,2,2,2,2,2,4,2,2,2,2,2,2,2,2,2,2,2,2,2,1,1,2,2,6,6,14,14,14,14,14,1
1,1,1,1,1,16,16,2,2,2,2,2,2,2,2,2,2,2,2,2,2,2,2,2,2,2,2,2,2,2,2,2,2,2,2,2,1,1,2,2,2,2,14,14,14,14,14,1
1,1,1,1,1,1,2,2,2,2,2,2,2,2,2,2,2,2,2,2,2,2,2,2,2,2,2,2,2,2,2,2,2,2,2,2,1,1,2,2,2,14,14,14,14,14,14,1
1,1,1,1,1,1,1,1,1,1,1,1,1,1,1,1,1,1,1,1,1,1,1,1,1,1,1,1,1,1,1,1,1,1,1,1,1,1,1,1,1,1,1,1,1,1,1,1
endlayer

layer
1,1,1,1,1,1,1,1,1,1,1,1,1,1,1,1,1,1,1,1,1,1,1,1,1,1,1,1,1,1,1,1,1,1,1,1,1,1,1,1,1,1,1,1,1,1,1,1
1,9,2,2,2,2,2,2,2,2,2,2,2,2,2,2,2,2,2,2,2,2,2,2,2,2,2,2,2,2,2,2,2,2,2,2,1,2,2,2,2,2,2,18,18,2,2,1
1,9,2,2,2,2,2,2,2,2,2,2,2,2,2,2,2,2,2,2,2,2,2,2,2,2,2,2,2,2,2,6,6,6,2,2,1,1,2,2,2,2,2,2,2,2,2,1
1,9,2,2,2,2,2,2,2,2,2,2,2,2,2,2,2,2,2,2,2,2,8,2,2,2,2,2,2,2,6,6,6,6,2,2,1,2,2,2,8,8,2,2,2,2,2,1
1,0,2,2,0,2,2,2,2,2,2,2,2,2,2,2,2,2,2,2,2,2,2,2,2,2,2,2,2,6,6,6,6,4,2,2,1,2,2,2,8,8,2,2,2,2,2,1
1,0,0,0,0,0,2,2,2,2,2,2,2,2,2,2,2,2,2,2,2,2,2,2,2,2,2,2,6,6,6,6,6,4,4,8,1,2,2,2,2,2,2,2,2,2,2,1
1,0,2,0,0,0,2,2,2,2,2,2,2,2,2,2,2,2,2,2,2,2,2,2,2,2,2,2,13,13,6,6,4,4,4,4,1,2,2,2,2,2,2,2,2,2,2,1
1,0,4,2,2,2,2,2,2,2,2,2,2,2,2,2,2,2,2,2,2,2,2,2,2,0,0,0,0,0,6,4,4,4,4,4,1,2,2,2,2,2,2,2,2,2,2,1
1,0,4,2,2,2,2,2,2,2,2,2,2,2,2,2,2,2,2,2,2,2,2,2,0,0,0,6,6,6,2,2,2,2,2,2,1,2,2,2,2,2,2,2,2,2,2,1
1,0,4,2,2,2,2,2,2,2,2,2,2,2,2,2,2,2,2,2,2,2,2,5,2,0,0,2,6,2,2,2,2,2,2,2,1,1,2,2,2,2,2,2,2,2,2,1
1,4,4,4,2,2,2,2,2,2,2,2,2,2,2,2,2,2,2,2,5,5,5,5,5,2,2,2,2,2,2,2,2,2,2,4,1,2,2,2,0,0,0,8,8,2,2,1
1,4,4,4,2,2,2,2,2,2,2,2,2,2,2,2,2,2,2,5,5,5,5,5,5,2,2,2,2,2,2,2,2,2,4,4,1,4,2,2,2,2,2,8,8,2,2,1
1,9,4,2,2,2,2,2,2,2,2,6,6,2,2,2,2,2,5,5,5,5,5,5,2,2,2,2,2,2,2,2,4,4,4,4,1,4,2,2,2,2,2,2,2,2,2,1
1,9,2,2,2,2,2,2,2,2,2,6,6,6,2,8,8,2,5,5,5,5,10,2,2,2,2,2,2,2,4,4,4,4,4,4,1,4,2,2,2,2,2,2,2,2,2,1
1,9,2,2,2,2,2,2,2,2,2,2,6,6,2,2,8,2,2,10,10,10,10,2,2,2,2,2,2,2,4,4,4,2,2,4,1,2,5,5,2,2,2,2,2,2,2,1
1,9,2,2,2,2,2,2,2,2,2,2,6,6,6,2,2,2,2,2,10,10,2,2,2,2,2,2,2,2,2,2,2,2,2,2,1,5,5,5,5,2,2,2,2,2,5,1
1,0,2,2,2,2,2,2,2,2,2,2,6,6,6,2,2,2,2,2,2,2,2,2,2,2,2,2,2,2,2,2,2,2,2,13,1,5,5,5,5,2,2,2,2,0,5,1
1,0,0,17,2,2,2,2,2,2,2,2,6,6,6,2,2,2,2,2,2,2,2,2,2,2,2,2,2,2,2,2,2,2,2,13,1,2,5,5,5,5,2,2,2,5,5,1
1,0,0,0,2,8,2,2,2,2,2,2,2,6,2,2,2,2,2,2,2,2,2,2,2,2,2,2,2,2,2,2,2,2,2,13,1,2,5,5,5,5,5,2,5,5,5,1
1,0,0,0,0,8,2,2,2,2,2,2,2,2,2,2,2,2,2,2,2,2,2,2,2,2,2,2,2,2,2,2,2,8,2,13,1,2,5,5,5,5,5,2,5,5,5,1
1,0,0,0,0,0,2,2,2,2,2,2,2,2,2,2,2,2,2,2,2,4,2,2,2,2,2,2,2,2,2,2,2,2,2,2,1,2,2,5,5,5,5,2,2,5,2,1
1,0,0,0,0,0,0,2,2,2,2,2,2,2,2,2,2,2,2,2,4,4,4,4,2,2,2,2,2,2,2,2,2,2,10,10,1,2,2,5,5,5,5,2,2,2,2,1
1,9,2,2,0,0,2,2,2,2,2,2,2,2,2,2,2,2,2,2,4,4,4,4,4,4,2,2,2,2,2,2,10,10,10,10,1,2,2,2,2,5,5,2,2,2,2,1
1,4,4,4,4,2,2,2,2,2,2,2,2,2,2,0,0,2,2,2,2,4,4,4,4,4,2,2,2,2,2,10,10,10,10,2,1,2,2,2,2,2,2,2,2,2,2,1
1,4,4,4,4,4,2,2,2,2,2,2,2,2,0,0,0,0,2,2,2,2,4,4,4,4,4,2,2,2,10,10,10,10,10,2,1,2,2,2,2,2,2,2,2,2,2,1
1,4,4,4,4,4,2,2,2,2,2,2,2,2,0,0,0,0,2,2,2,2,2,4,4,4,4,2,2,10,10,10,10,10,2,2,1,2,2,2,2,2,6,6,2,2,2,1
1,4,4,4,2,2,2,2,2,2,2,2,2,2,2,0,0,2,2,2,2,2,2,2,2,4,4,2,2,10,10,10,10,2,2,2,1,2,2,2,2,6,6,6,2,2,2,1
1,9,2,2,2,2,2,2,2,2,2,2,2,2,2,2,2,2,2,2,2,2,2,2,4,4,4,2,10,10,10,10,2,2,2,2,1,2,2,2,6,6,6,6,6,2,2,1
1,9,2,2,2,2,8,16,16,2,2,2,2,2,2,2,2,2,2,2,2,2,2,4,4,4,4,2,2,10,2,2,2,2,17,2,1,2,2,2,6,6,6,6,6,2,2,1
1,9,2,2,2,2,16,16,16,2,2,2,2,2,2,2,2,2,2,2,2,4,4,4,4,4,2,2,2,2,2,2,2,2,2,17,1,2,2,2,6,6,6,6,2,2,2,1
1,9,2,2,2,16,16,16,16,2,2,2,2,2,2,2,2,2,2,2,2,4,4,4,4,4,2,2,2,2,2,2,2,2,2,2,1,2,2,2,6,6,6,6,2,2,2,1
1,1,2,2,2,16,16,16,2,2,2,2,2,2,2,2,2,2,2,2,2,4,4,4,4,4,2,2,2,2,2,2,2,2,2,2,1,2,2,2,6,6,6,6,17,2,2,1
1,1,1,2,16,16,16,16,2,2,2,2,2,2,2,2,2,2,2,2,2,4,4,4,4,2,2,2,2,2,2,2,2,2,2,2,1,2,2,2,6,6,6,2,2,2,2,1
1,1,1,2,16,16,16,2,2,2,2,2,2,2,2,2,2,2,2,2,2,4,4,4,2,2,2,2,2,2,2,2,2,2,2,2,1,1,2,2,6,6,6,2,2,2,2,1
1,1,1,1,2,2,2,2,2,2,2,2,2,2,2,2,2,2,2,2,2,2,2,2,2,2,2,2,2,2,2,2,2,2,2,2,1,1,2,2,6,6,2,2,2,2,2,1
1,1,1,1,1,1,2,2,2,2,2,2,2,2,2,2,2,2,2,2,2,2,2,2,2,2,2,2,2,2,2,2,2,2,2,2,1,1,2,2,2,2,2,2,2,2,2,1
1,1,1,1,1,1,1,1,1,1,1,1,1,1,1,1,1,1,1,1,1,1,1,1,1,1,1,1,1,1,1,1,1,1,1,1,1,1,1,1,1,1,1,1,1,1,1,1
endlayer

layer
1,1,1,1,1,1,1,1,1,1,1,1,1,1,1,1,1,1,1,1,1,1,1,1,1,1,1,1,1,1,1,1,1,1,1,1,1,1,1,1,1,1,1,1,1,1,1,1
1,12,17,2,2,2,2,2,2,2,2,2,2,2,2,2,2,2,2,2,2,2,2,2,2,2,2,2,2,2,2,2,17,2,2,2,2,2,2,2,2,2,2,18,18,2,2,1
1,12,2,2,2,2,2,2,2,2,2,2,2,2,2,2,2,2,2,2,2,2,8,8,2,2,2,2,2,2,2,17,6,6,2,2,2,2,2,2,2,2,2,2,2,2,2,1
1,9,2,2,2,2,2,2,2,2,2,2,2,2,2,2,2,2,2,2,2,2,8,8,2,2,2,2,2,6,6,6,6,6,2,2,2,2,2,2,2,2,2,2,2,2,2,1
1,9,2,2,2,2,2,2,2,2,2,2,2,2,2,2,2,2,2,2,2,2,2,2,2,2,2,2,6,6,6,6,6,2,2,2,2,2,2,2,2,8,2,2,2,2,2,1
1,9,2,2,0,2,2,2,2,2,2,2,2,2,2,2,2,2,2,2,2,2,2,2,2,2,2,2,6,6,6,6,6,2,2,2,2,2,2,2,2,2,2,2,2,2,2,1
1,4,2,2,2,2,2,2,2,2,2,2,2,2,2,2,2,2,2,2,2,2,2,2,2,2,2,6,6,6,6,6,4,4,4,2,8,2,2,2,2,2,2,2,2,2,2,1
1,4,4,2,2,2,2,2,2,2,2,2,2,2,2,2,2,2,2,2,2,2,2,2,2,2,6,0,0,0,0,0,0,2,2,2,2,2,2,2,2,2,2,2,2,2,2,1
1,4,4,2,2,2,2,2,2,2,2,2,2,2,2,2,2,2,2,13,2,2,10,10,2,2,6,6,6,6,6,2,2,2,2,2,2,2,2,2,2,2,2,2,2,2,2,1
1,19,4,4,2,2,2,2,2,2,2,2,2,2,2,2,2,2,13,2,2,5,5,5,5,5,5,6,6,6,2,2,2,2,2,2,2,2,2,2,2,2,2,2,2,2,2,1
1,4,4,4,2,2,2,2,2,2,2,2,2,2,2,2,2,2,2,2,5,5,5,5,5,5,2,2,2,2,2,2,2,2,2,2,2,2,2,0,0,0,2,2,2,2,2,1
1,4,4,4,4,2,2,2,6,2,2,2,2,2,2,2,2,13,13,5,5,5,5,5,5,5,2,2,2,2,2,2,2,2,2,4,4,2,2,2,2,2,2,2,2,2,2,1
1,4,4,4,2,2,2,2,6,2,2,2,2,2,2,2,2,2,5,5,5,5,5,5,5,2,2,2,2,2,2,2,2,2,4,4,4,2,2,2,2,2,2,2,2,2,2,1
1,9,2,2,2,2,6,6,2,2,2,2,2,2,2,2,2,2,5,5,5,5,5,10,2,2,2,2,2,2,2,2,2,2,2,4,2,2,2,2,2,2,2,2,2,2,2,1
1,9,2,2,2,6,2,2,2,2,2,2,2,2,2,2,2,2,2,10,10,10,10,2,2,2,2,2,2,2,2,2,2,2,2,2,13,2,2,2,20,2,2,2,2,2,2,1
1,9,2,2,2,2,2,2,2,2,2,2,2,2,2,2,2,2,2,2,10,10,10,2,2,2,2,2,2,2,2,2,2,2,2,2,13,2,2,2,2,2,2,2,2,2,5,1
1,9,2,2,2,2,2,2,2,2,2,2,2,2,2,2,2,2,2,2,2,2,2,2,2,2,2,2,2,2,2,2,2,2,2,2,2,2,5,5,2,2,2,2,2,0,5,1
1,9,2,2,2,2,2,2,2,2,2,2,2,2,2,2,2,2,2,2,2,2,2,2,2,2,2,2,2,2,2,2,2,2,2,13,13,2,2,5,5,5,2,2,2,5,5,1
1,0,2,2,2,8,2,2,2,2,2,2,2,2,2,2,2,2,2,2,2,2,2,2,2,2,2,5,2,2,2,2,2,2,2,2,2,2,2,5,5,5,2,2,5,5,5,1
1,0,2,2,2,2,2,2,2,2,2,2,2,2,2,2,2,2,2,2,2,2,2,2,2,2,5,5,5,2,2,13,2,8,8,2,2,2,2,5,5,5,5,2,5,5,4,1
1,9,2,2,2,2,2,2,2,2,2,2,2,2,2,2,2,2,2,2,2,2,2,2,2,2,2,5,2,5,5,5,2,8,8,2,2,2,2,5,5,5,5,2,2,5,4,1
1,9,2,2,2,2,2,2,2,2,2,2,2,2,2,2,2,2,2,2,2,2,2,2,2,2,2,2,13,5,5,5,5,2,10,10,2,2,2,2,5,5,5,2,2,2,2,1
1,9,2,2,2,2,2,2,2,2,2,2,2,2,2,2,2,2,2,2,2,2,4,4,2,2,2,2,13,5,5,5,5,10,10,10,2,2,2,2,2,5,5,2,2,2,2,1
1,9,2,2,2,2,2,2,2,2,2,2,2,2,2,0,0,2,2,2,2,2,4,4,4,4,2,2,2,2,2,5,10,10,10,2,2,2,2,2,2,2,2,2,2,2,2,1
1,4,4,2,2,2,2,2,2,2,2,2,2,2,0,0,0,0,2,2,2,2,2,4,4,4,2,2,2,2,10,10,10,10,10,2,2,2,2,2,2,2,2,2,2,2,2,1
1,4,4,2,2,2,2,2,2,2,2,2,2,2,0,0,0,0,2,2,2,2,2,2,4,4,2,2,2,10,10,8,8,10,2,2,2,2,2,2,2,2,2,2,2,2,2,1
1,9,2,2,2,2,2,2,2,2,2,2,2,2,0,0,0,2,2,2,2,2,2,2,2,2,2,2,2,10,10,8,8,2,2,2,2,2,2,2,2,2,6,6,2,2,2,1
1,9,2,2,2,2,2,2,2,2,2,2,2,2,2,2,2,2,2,2,2,2,2,2,2,2,2,2,10,10,10,10,2,2,2,2,2,2,2,2,2,6,6,6,2,2,2,1
1,9,2,2,2,2,2,2,2,2,2,2,2,2,2,2,2,2,2,2,2,2,2,2,2,2,2,2,2,10,2,2,2,2,17,2,2,2,2,2,2,6,6,6,2,2,2,1
1,9,2,2,2,2,2,2,2,2,2,2,2,2,8,2,2,2,2,2,2,2,4,4,4,2,2,2,2,2,2,2,2,2,2,17,2,2,2,2,6,6,6,6,2,2,2,1
1,9,2,2,2,2,2,2,2,2,2,2,2,2,2,2,2,2,2,2,2,4,4,4,4,4,2,2,2,2,2,2,2,2,2,2,2,2,2,2,6,6,6,6,2,2,2,1
1,1,2,2,2,2,2,2,2,2,2,2,2,2,2,2,2,2,2,2,2,4,4,4,4,2,2,2,2,2,2,2,2,2,2,2,2,2,2,2,6,6,6,6,2,2,2,1
1,1,2,2,2,2,2,2,2,2,2,2,2,2,2,2,2,2,2,2,2,4,4,4,4,2,2,2,2,2,2,2,2,2,2,2,2,2,2,2,6,6,6,2,2,2,2,1
1,1,1,2,2,2,2,2,2,2,2,2,2,2,2,2,2,2,2,2,2,4,4,2,2,2,2,2,2,2,2,2,2,2,2,2,2,2,2,2,6,6,6,2,2,2,2,1
1,1,1,1,2,2,17,17,2,2,2,2,2,2,2,2,2,2,2,2,2,2,2,2,2,2,2,2,2,2,2,2,2,2,2,2,2,2,2,2,6,6,2,2,2,2,2,1
1,1,1,1,1,1,17,17,2,2,2,2,2,2,2,2,2,2,2,2,2,2,2,2,2,2,2,2,2,2,2,2,2,2,2,2,2,2,2,2,2,2,2,2,2,2,2,1
1,1,1,1,1,1,1,1,1,1,1,1,1,1,1,1,1,1,1,1,1,1,1,1,1,1,1,1,1,1,1,1,1,1,1,1,1,1,1,1,1,1,1,1,1,1,1,1
endlayer

layer
21,9,2,17,2,2,2,2,2,2,2,2,2,2,2,2,2,2,2,2,2,2,2,2,2,2,2,2,2,2,2,2,2,2,2,2,19,19,2,2,2,2,2,18,18,18,2,19
9,9,17,2,2,2,2,2,2,2,2,2,2,2,2,2,2,2,2,2,2,2,2,2,2,2,2,2,2,2,2,2,17,2,2,2,2,2,2,2,2,2,2,18,18,2,2,2
9,12,2,2,2,2,2,2,2,2,2,2,2,2,2,2,2,2,2,2,2,2,2,8,2,2,2,2,2,2,2,17,2,2,2,2,2,2,2,2,2,2,2,2,2,2,2,2
9,9,2,2,2,2,2,2,2,2,2,2,2,2,2,2,2,2,2,2,2,2,2,2,2,2,2,2,2,2,6,6,6,2,2,2,2,2,2,2,2,2,2,2,2,2,2,2
9,9,2,2,2,2,2,2,2,2,2,2,2,2,2,2,2,2,2,2,2,2,2,2,2,2,2,2,2,6,6,6,2,2,2,2,2,2,2,2,2,2,2,2,2,2,2,2
9,9,2,2,2,2,2,2,2,2,2,2,2,2,2,2,2,2,2,2,2,2,2,2,2,2,2,2,6,6,6,6,2,2,2,2,2,2,2,2,2,2,2,2,2,2,10,10
9,9,2,2,2,2,2,2,2,2,2,2,2,2,2,2,2,2,2,2,2,2,2,2,2,2,2,6,6,6,6,6,2,2,2,2,2,2,2,2,2,2,2,2,2,2,10,10
4,4,2,2,2,2,2,2,2,2,2,2,2,2,2,2,2,2,2,2,2,2,2,10,2,2,2,6,6,0,0,0,22,0,2,2,2,2,2,2,2,2,2,2,2,2,10,10
4,4,4,2,2,2,2,2,2,2,2,2,2,2,2,2,2,2,2,0,2,2,10,10,10,5,6,6,6,6,2,2,2,0,2,2,2,2,2,2,2,2,2,2,2,2,2,2
4,4,4,2,13,13,2,2,2,2,2,2,2,2,2,2,2,2,0,0,0,23,5,5,5,5,5,6,6,6,2,2,2,0,2,2,2,2,2,2,2,2,2,2,2,2,2,2
4,4,4,4,13,13,13,2,6,6,2,2,2,2,2,2,2,0,0,0,0,22,0,0,5,5,5,2,2,2,2,2,2,0,0,0,0,0,0,0,0,2,2,2,2,2,2,2
9,4,4,4,2,13,13,13,6,6,2,2,2,2,2,2,2,0,0,5,5,5,0,0,0,0,0,2,2,2,2,2,2,0,2,2,2,2,2,2,2,2,2,2,2,2,2,2
9,9,4,4,2,6,13,13,6,6,2,2,2,2,2,2,2,2,2,5,5,5,19,19,19,0,0,2,2,2,2,2,17,0,2,2,2,2,17,20,20,20,20,20,2,2,2,2
9,9,2,2,6,6,6,6,6,2,2,2,2,2,2,2,2,2,2,2,10,5,10,10,2,0,0,2,2,2,2,2,2,0,2,2,2,2,2,20,20,20,20,20,2,2,2,2
24,24,24,24,24,24,6,6,2,2,2,2,2,2,2,2,2,2,2,2,10,10,10,2,2,0,0,2,2,2,2,2,2,0,2,2,2,2,2,20,0,20,20,20,2,2,2,2
24,24,24,24,24,24,6,2,2,2,2,2,2,2,2,2,2,2,2,2,10,10,2,2,2,0,0,2,2,2,2,2,2,0,2,2,2,2,2,20,20,20,20,20,2,2,2,2
9,24,24,24,24,24,2,2,2,2,2,2,2,2,2,2,2,2,2,2,2,2,2,2,2,0,0,25,2,2,8,2,2,0,2,2,2,2,2,20,20,20,20,20,2,20,5,5
24,24,24,24,24,24,2,2,2,2,2,2,2,2,2,2,2,2,2,2,2,2,2,2,2,0,0,26,0,0,0,0,0,0,2,2,2,2,2,2,2,2,2,2,2,5,5,5
24,24,24,24,24,24,2,2,2,2,2,2,2,2,2,2,2,2,2,2,2,2,2,2,2,0,0,0,0,0,0,0,0,0,0,2,2,2,2,2,2,2,2,2,2,5,5,4
24,24,2,2,24,24,2,2,2,2,2,2,2,2,2,2,2,2,2,2,2,2,2,2,2,2,5,23,5,5,5,5,2,22,2,2,2,2,2,2,5,5,2,2,2,4,4,4
9,9,2,2,2,2,2,2,2,2,2,2,2,2,2,2,2,2,2,2,2,2,2,2,2,2,5,5,5,5,5,5,5,0,8,2,2,2,2,2,5,5,2,2,2,4,4,4
9,9,2,2,2,2,2,2,2,2,2,2,2,2,2,2,2,2,2,2,2,2,2,2,2,2,2,2,5,5,5,5,5,0,2,2,2,2,2,2,2,2,2,2,2,2,4,4
9,9,2,2,2,2,2,2,2,2,2,2,2,2,2,2,2,2,2,2,2,2,2,2,2,2,2,2,13,5,5,5,5,0,2,2,2,2,2,2,2,2,2,2,2,2,2,2
9,9,2,2,2,2,2,2,2,2,2,2,2,2,2,0,2,2,2,2,2,2,2,2,2,2,2,2,2,2,5,5,5,0,2,2,2,2,2,2,2,2,2,2,2,2,2,2
9,9,2,2,2,2,2,2,2,2,2,2,2,2,0,0,0,2,2,2,2,2,2,2,2,2,2,2,2,2,10,10,10,0,2,2,2,2,2,2,2,2,2,2,2,2,2,2
19,19,19,19,19,19,19,19,19,19,19,19,19,19,0,0,0,2,2,2,2,2,2,2,2,2,2,2,2,2,10,10,10,19,2,2,2,2,2,2,2,2,2,2,2,2,2,2
9,9,2,2,2,2,2,2,2,2,2,2,2,2,0,0,0,2,2,2,2,2,2,2,2,2,2,2,2,2,10,10,10,19,2,2,2,2,2,2,2,2,2,2,2,2,2,2
9,9,2,2,2,2,2,2,2,2,2,2,2,2,2,2,2,2,2,2,2,2,2,2,2,2,2,2,2,2,2,2,2,2,2,2,2,2,2,2,2,2,2,2,2,2,2,2
9,9,2,2,2,2,2,2,2,2,2,2,2,2,8,8,2,2,2,2,2,2,2,2,2,2,2,2,2,2,2,2,2,2,2,2,2,2,2,2,2,2,2,2,2,2,2,2
9,9,2,2,2,2,2,2,2,2,2,2,2,2,8,8,2,2,2,2,2,2,2,2,2,2,2,2,2,2,2,2,2,2,2,2,2,2,2,2,2,6,6,2,2,2,2,2
1,9,2,2,2,2,2,2,2,2,2,2,2,2,2,2,2,2,2,2,2,2,16,4,16,2,2,2,2,2,2,2,2,2,2,2,2,2,2,2,2,6,6,2,2,2,2,2
1,9,2,2,2,2,2,2,2,2,2,2,2,2,2,2,2,2,2,2,2,2,4,4,2,2,2,2,2,2,2,2,2,2,2,2,2,2,2,2,2,6,6,2,2,2,2,2
1,9,2,2,2,2,2,2,2,2,2,2,2,2,2,2,2,2,2,2,2,2,2,2,2,2,2,2,2,2,2,2,2,2,2,2,2,2,2,2,2,6,2,2,2,2,2,2
1,1,2,2,2,2,2,2,2,2,2,2,2,2,2,2,2,2,2,2,2,2,2,2,2,2,2,2,2,2,2,2,2,2,2,2,2,2,2,2,2,2,2,2,2,2,2,2
1,1,1,1,2,2,2,2,2,2,2,2,2,2,2,2,2,2,2,2,2,2,2,2,2,2,2,2,2,2,2,2,2,2,2,2,2,2,2,2,2,2,2,2,2,2,2,2
1,1,1,1,1,1,2,2,2,2,2,2,2,2,2,2,2,2,2,2,2,2,2,2,2,2,2,2,2,2,2,2,2,2,2,2,2,2,2,2,2,2,2,2,2,2,2,2
19,19,19,19,19,19,2,2,2,2,8,8,2,2,2,2,2,2,2,2,2,2,2,2,2,2,2,2,2,2,2,2,2,2,2,2,19,2,2,2,2,2,2,2,2,2,2,2
endlayer

layer
21,9,2,2,2,2,2,2,2,2,2,2,2,2,2,2,2,2,2,2,2,2,2,2,2,2,2,2,2,2,2,2,2,2,11,11,19,19,2,2,2,2,2,18,18,18,2,19
9,9,2,2,2,2,2,2,2,2,2,2,2,2,2,2,2,2,2,2,2,2,2,2,2,2,2,2,2,2,2,2,2,2,2,2,2,2,2,2,2,2,2,18,18,2,2,2
9,9,2,2,2,2,2,2,2,2,2,2,2,2,2,2,2,2,2,2,2,2,2,2,2,2,2,2,2,2,2,2,2,2,2,2,2,2,2,2,2,2,2,2,2,2,2,2
9,9,2,2,2,2,2,2,2,2,2,2,2,2,2,2,2,2,2,2,2,2,2,2,2,2,2,2,2,2,2,2,2,2,2,2,2,2,2,2,2,2,2,2,2,2,2,2
9,9,2,2,4,4,4,4,2,2,2,2,2,2,2,2,2,2,2,2,2,2,2,2,2,2,2,2,2,2,2,2,2,2,2,2,2,2,2,2,2,2,2,2,2,10,10,10
9,9,2,2,4,4,4,4,4,2,2,2,2,2,2,2,2,2,2,2,2,2,2,2,2,2,2,2,2,6,6,2,2,2,2,2,2,2,2,2,2,2,2,2,10,10,10,10
9,9,2,2,2,4,4,4,4,4,2,2,2,2,2,2,2,2,2,2,2,2,2,2,2,2,2,2,6,6,6,2,2,2,2,2,2,2,2,2,2,2,2,2,2,10,10,10
9,9,2,2,2,2,4,4,4,4,2,2,2,2,2,2,2,2,2,2,2,2,2,10,2,2,2,6,6,6,2,2,0,0,2,2,2,2,2,2,2,2,2,2,2,10,10,10
9,9,2,2,2,2,2,2,4,2,8,8,2,2,2,2,2,7,0,0,2,2,10,10,2,5,5,6,6,2,2,2,2,0,2,2,2,2,2,2,2,2,2,17,2,2,2,10
9,9,2,2,13,13,2,2,2,2,2,8,2,2,2,2,2,7,0,0,0,10,5,5,5,5,5,5,2,2,2,2,2,0,2,2,2,2,2,2,2,2,2,2,2,2,2,2
9,9,2,2,13,13,13,6,6,6,2,2,2,2,2,2,2,0,0,0,0,22,0,0,5,5,5,2,2,2,2,2,2,0,27,0,22,0,0,0,2,2,2,2,2,2,2,2
9,9,2,2,2,13,13,13,6,6,2,2,2,2,13,2,2,0,0,2,5,5,27,0,0,0,27,2,2,2,2,17,2,0,2,2,2,2,2,20,20,20,20,20,2,2,2,2
9,9,2,2,6,6,13,13,6,6,2,2,2,13,13,2,2,2,2,2,10,5,19,19,19,0,0,2,2,2,2,2,2,0,2,2,2,0,20,0,31,30,29,28,20,2,2,2
9,9,2,6,6,6,6,6,6,2,2,2,2,13,13,2,2,2,2,2,2,10,10,2,2,0,0,2,2,2,2,2,2,0,2,2,2,17,20,0,34,33,0,32,20,2,2,2
24,24,24,24,24,24,6,6,2,2,2,2,2,13,13,2,2,2,2,2,2,2,2,2,2,27,0,2,2,2,2,2,2,0,2,2,2,2,20,0,36,20,0,35,20,2,2,2
24,24,24,24,24,24,6,2,2,2,2,2,2,2,2,2,2,2,2,2,2,2,2,2,2,0,0,2,2,2,2,2,2,0,2,2,2,2,20,0,38,0,0,37,20,2,2,2
24,24,24,24,24,24,2,2,2,2,2,2,2,2,2,2,2,2,2,2,2,2,2,2,2,0,0,25,2,2,2,8,2,0,2,2,2,2,20,0,42,41,40,39,20,0,2,2
24,24,24,24,24,24,2,2,2,2,2,2,2,2,2,2,2,2,2,2,2,2,2,2,2,0,0,0,0,0,22,0,0,0,43,2,2,2,2,20,20,20,20,20,2,2,2,2
24,24,24,24,24,24,2,2,2,2,2,2,2,2,2,2,2,2,2,2,2,2,2,2,2,0,0,0,22,0,0,0,0,0,0,2,2,2,2,2,2,2,2,2,2,2,2,4
24,24,24,24,24,24,2,2,2,2,2,2,2,2,2,2,2,2,2,2,2,2,2,2,2,2,5,5,5,5,5,5,2,0,2,2,2,2,2,2,2,2,2,2,2,4,4,4
24,24,24,24,24,24,2,2,2,2,2,2,2,2,2,2,2,2,2,2,2,2,2,2,2,2,5,5,5,5,5,5,5,0,2,2,2,2,2,2,2,2,2,2,2,4,4,4
24,24,24,24,24,24,2,2,2,2,2,2,2,2,2,2,2,2,2,2,2,2,2,2,2,2,2,2,5,5,5,5,5,27,2,2,2,2,2,2,2,2,2,2,2,2,4,4
24,24,24,24,24,24,2,2,2,2,2,2,2,2,2,2,2,2,2,2,2,2,2,2,2,2,2,2,2,5,5,5,5,0,2,2,2,2,2,2,2,2,2,2,2,2,2,2
24,24,24,24,24,24,2,2,2,2,2,2,2,2,0,0,2,2,2,2,2,2,2,2,2,2,2,2,2,2,5,5,5,0,2,2,2,2,2,2,2,2,2,2,2,2,2,2
24,24,24,24,24,24,2,2,2,2,2,2,2,0,0,0,0,2,2,2,2,2,2,2,2,2,2,2,2,2,2,2,2,0,2,2,2,2,2,2,2,2,2,2,2,2,2,2
19,19,19,19,19,19,19,19,19,19,19,19,19,0,0,0,0,2,2,2,2,8,2,2,2,2,2,2,2,2,2,2,2,0,2,2,2,2,2,2,2,2,2,2,2,11,11,2
24,24,24,24,24,24,2,2,2,2,2,2,2,2,0,0,2,2,2,2,8,2,2,2,2,2,2,2,2,2,2,2,2,0,0,2,2,2,2,2,2,2,2,2,2,2,11,11
9,9,2,2,2,2,2,2,2,2,2,2,2,2,2,2,2,2,2,2,2,2,2,2,2,2,2,2,2,2,2,2,2,2,2,2,2,2,2,2,2,2,2,2,2,2,11,11
9,9,2,2,2,2,2,2,2,2,2,2,2,2,2,8,2,2,2,2,16,2,16,16,2,2,2,2,2,2,2,2,2,2,2,2,2,2,2,2,2,2,2,2,2,2,2,11
9,9,2,2,2,2,2,2,2,2,2,2,2,2,2,2,2,2,2,16,16,16,16,16,16,16,2,2,2,2,2,2,2,2,2,2,2,2,2,2,2,2,2,2,2,2,2,2
9,9,2,2,2,2,2,2,2,2,2,2,2,2,2,2,2,2,2,2,16,16,16,16,16,16,16,2,2,2,2,2,2,2,2,2,2,2,2,2,2,2,2,2,2,2,2,2
9,9,2,2,2,2,2,2,2,2,2,2,2,2,2,2,2,2,2,2,2,16,16,16,16,16,2,2,2,2,2,2,2,2,2,2,2,2,2,2,2,2,2,2,2,2,2,2
9,9,2,2,2,2,2,2,2,2,2,2,2,2,2,2,2,2,2,2,2,2,2,2,2,2,2,2,2,2,2,2,2,2,2,2,2,2,2,2,2,2,2,2,2,2,2,2
1,1,2,2,2,2,2,2,2,2,2,2,2,2,2,2,2,2,2,2,2,2,2,2,2,2,2,2,2,2,2,2,2,2,2,2,2,2,2,2,2,2,2,2,2,2,2,2
1,1,1,1,2,2,2,2,2,2,2,2,2,2,2,2,2,2,2,2,2,2,2,2,2,2,2,2,2,2,2,2,2,2,2,2,2,2,2,2,2,2,2,2,2,2,2,2
1,1,1,1,1,2,2,2,2,2,2,2,2,2,2,2,2,2,2,2,2,2,2,2,2,2,2,2,2,2,2,2,2,2,2,2,2,2,11,2,2,2,2,2,2,2,2,2
19,19,19,19,19,19,2,2,2,2,8,2,2,2,2,2,2,2,2,2,2,2,2,2,2,2,2,2,2,2,2,2,2,2,2,2,19,11,11,11,2,2,2,2,2,2,2,2
endlayer

layer
21,9,2,2,2,2,2,2,2,2,2,2,2,2,2,2,2,2,2,2,2,2,2,2,2,2,2,2,2,2,2,2,2,11,11,11,19,19,2,2,2,2,2,18,18,18,2,19
9,9,2,2,2,2,2,2,2,2,2,2,2,2,2,2,2,2,2,2,2,2,2,2,2,2,2,2,2,2,2,2,2,2,2,11,2,2,2,2,2,2,2,18,18,2,16,2
9,9,2,4,2,2,2,2,2,2,2,2,2,2,2,2,2,2,2,2,2,2,2,2,2,2,2,2,2,2,2,2,2,2,2,2,2,2,2,2,2,2,2,2,16,16,16,2
9,9,4,4,4,4,4,2,2,2,2,2,2,2,2,2,2,2,2,2,2,2,2,2,2,2,2,2,2,2,2,2,2,2,2,6,2,2,2,2,2,2,2,16,16,16,16,2
9,9,2,4,4,4,4,4,4,2,2,2,2,2,2,2,2,2,2,2,2,2,2,2,2,2,2,2,2,2,2,2,2,2,6,6,2,2,2,2,2,2,2,16,10,10,10,10
9,9,2,2,4,4,4,4,4,4,2,2,2,2,2,2,2,2,2,2,2,2,2,2,2,2,2,2,2,2,2,2,2,2,6,6,6,2,2,2,2,2,16,16,10,10,10,10
9,9,2,2,4,4,4,4,4,4,2,2,2,2,2,2,2,2,2,2,2,2,2,2,2,2,2,2,2,2,2,2,2,2,6,6,6,2,2,2,2,2,16,16,10,10,10,10
9,9,2,2,2,4,4,4,4,4,4,2,2,2,2,2,2,2,2,2,2,2,2,2,2,2,2,2,2,2,2,2,2,2,6,6,2,2,2,2,2,2,17,2,2,10,10,10
9,9,2,2,2,2,2,4,4,4,8,8,2,2,2,2,2,2,2,2,2,2,2,2,2,2,2,2,2,2,2,2,2,2,6,6,2,2,2,2,2,2,2,17,2,2,10,10
9,9,2,2,2,2,2,2,2,4,4,8,2,2,2,2,2,2,2,2,27,2,2,2,2,2,2,2,2,2,2,2,2,2,2,2,2,2,2,2,2,2,2,2,2,2,2,2
9,9,2,2,2,2,2,2,2,2,2,2,2,2,2,2,2,2,2,2,2,2,2,2,2,2,2,2,2,2,2,2,2,2,2,2,2,2,2,2,2,2,2,2,2,2,2,2
9,9,2,2,2,2,2,6,6,2,2,2,2,2,13,2,2,2,2,2,2,2,2,2,2,2,2,2,2,2,2,2,2,2,2,2,2,2,2,20,20,20,20,20,2,2,2,2
9,9,2,2,2,6,6,6,6,2,2,2,2,13,13,13,2,2,2,2,2,2,2,2,2,2,2,2,2,2,2,2,2,2,2,2,2,2,20,0,0,0,0,0,20,2,2,2
9,9,2,2,6,6,6,6,2,2,2,2,2,13,13,13,2,2,2,2,2,2,2,2,2,2,2,2,2,2,2,2,2,2,2,2,2,11,20,0,0,0,0,0,20,2,2,2
24,24,24,24,24,24,6,6,2,2,2,2,13,13,13,2,2,2,2,2,2,2,2,2,2,2,2,2,2,2,2,2,2,2,2,2,2,11,20,0,0,0,0,39,20,2,2,2
24,24,24,24,24,24,6,2,2,2,2,2,13,13,13,2,2,2,2,2,2,2,2,2,2,2,2,2,2,2,2,2,2,2,2,2,2,2,20,0,0,0,0,39,20,2,2,2
24,24,24,24,24,24,2,2,2,2,2,2,2,13,2,2,2,2,2,2,2,2,2,2,2,2,2,2,2,2,2,2,2,2,2,2,2,2,20,0,0,0,0,0,20,11,2,2
24,24,24,24,24,24,2,2,2,2,2,2,2,2,2,2,2,2,2,2,2,2,2,2,2,2,2,2,2,2,2,2,2,2,2,2,2,2,2,20,20,20,20,20,2,2,2,2
24,24,24,24,24,24,2,2,2,2,2,2,2,2,2,2,2,2,2,2,2,2,2,2,2,0,0,5,2,2,2,2,2,2,2,2,2,2,2,2,2,2,2,2,2,2,2,2
24,24,24,24,24,24,2,2,2,2,2,2,2,2,2,2,2,2,2,2,2,2,2,2,2,2,5,5,5,2,2,2,2,2,2,2,2,2,2,2,2,2,2,2,2,2,4,4
24,24,24,24,24,24,2,2,2,2,2,2,2,2,2,2,2,2,2,2,2,2,2,2,2,2,2,5,2,5,5,5,2,2,2,2,2,2,2,2,2,2,2,2,2,2,4,4
24,24,24,24,24,24,2,2,2,2,2,2,2,2,2,2,2,2,2,2,2,2,2,2,2,2,2,2,2,5,5,5,5,2,2,2,2,2,2,2,2,2,2,2,2,2,2,2
24,24,24,24,24,24,2,2,2,2,2,2,2,2,2,2,2,2,2,2,2,2,2,2,2,2,2,2,2,5,5,5,5,2,2,2,2,2,2,2,2,2,2,2,2,2,2,2
24,24,24,24,24,24,2,2,2,2,2,2,2,2,0,0,2,2,2,2,2,2,2,2,2,2,2,2,2,2,2,5,2,2,2,2,2,2,2,2,2,2,2,2,2,2,2,2
24,24,24,24,24,24,2,2,2,2,2,2,2,0,0,0,0,2,2,2,4,2,2,2,2,2,2,2,2,2,2,2,2,0,2,2,2,2,2,2,2,2,2,2,11,11,11,2
24,24,24,24,24,24,2,2,2,2,2,2,2,0,0,0,0,2,2,2,8,4,2,2,2,2,2,2,2,2,2,2,2,27,2,2,2,2,2,2,2,2,2,2,11,11,11,11
24,24,24,24,24,24,2,2,2,2,2,2,2,2,0,0,2,2,2,2,8,8,2,2,2,2,2,2,2,2,2,2,2,0,0,2,2,2,2,2,2,2,2,2,2,11,4,4
24,24,24,2,2,2,2,2,2,2,2,2,2,2,2,2,2,2,2,2,2,2,4,2,2,2,2,2,2,2,2,2,2,2,2,2,2,2,2,2,2,2,2,2,2,2,4,4
9,9,2,2,2,2,2,2,2,2,2,2,2,2,2,2,2,2,2,16,16,16,4,4,16,2,2,2,2,2,2,2,2,2,2,2,2,2,2,2,2,2,2,2,2,2,11,4
9,9,2,2,2,2,2,2,2,2,2,2,2,2,2,2,2,2,2,16,16,16,16,16,16,16,2,2,2,2,2,2,2,2,2,2,2,2,2,2,2,2,2,2,2,2,2,2
9,9,2,2,2,2,2,2,2,2,2,11,11,11,2,2,2,2,2,16,16,16,16,16,16,16,16,2,2,2,2,2,2,2,2,2,2,2,2,2,2,2,2,2,2,2,2,4
9,9,2,2,2,2,2,2,2,2,2,11,11,11,2,2,2,2,2,2,16,16,16,16,16,16,16,2,2,2,2,2,2,2,2,2,2,2,2,2,2,2,2,2,2,2,2,2
9,9,2,2,2,2,2,2,2,2,11,11,11,2,2,2,2,2,2,2,2,2,2,2,2,2,2,2,2,2,2,2,2,2,2,17,2,2,2,2,2,2,2,2,2,2,2,2
1,1,2,2,2,2,2,2,2,2,2,2,2,2,2,2,2,2,2,2,2,2,2,2,2,2,2,2,2,2,2,2,2,2,2,2,2,2,2,2,2,2,2,2,2,2,2,2
1,1,1,2,2,2,2,2,2,2,2,2,2,2,2,2,2,2,2,2,2,2,2,2,2,2,2,2,2,2,2,2,2,2,2,2,11,11,11,2,2,2,2,2,2,2,2,2
1,1,1,1,2,2,2,2,2,2,2,2,2,2,2,2,2,2,2,2,2,2,2,2,2,2,2,2,2,2,2,2,2,2,2,13,13,11,11,11,2,2,2,2,2,2,2,2
19,1,1,1,2,2,2,2,2,2,2,2,2,2,2,2,2,2,2,2,2,2,2,2,2,2,2,2,2,2,2,2,2,2,2,13,1,11,11,11,11,11,2,2,2,2,2,2
endlayer

layer
19,9,2,2,2,2,2,2,2,2,6,6,6,2,2,2,2,2,2,2,2,2,2,2,44,44,44,44,44,44,2,2,2,11,11,11,19,19,2,2,2,2,2,18,18,18,2,19
9,9,2,2,2,2,2,2,2,2,6,6,2,2,2,2,2,2,2,2,2,2,2,44,44,44,44,44,44,2,2,2,2,2,2,2,2,2,2,2,2,2,2,18,18,2,16,2
9,9,2,4,2,2,2,2,2,2,6,6,6,2,2,2,2,2,2,2,2,2,2,44,44,44,44,2,2,2,2,2,2,2,6,6,6,2,2,2,2,2,2,16,16,16,16,2
9,9,4,4,4,4,4,2,2,2,6,6,2,2,2,2,2,2,2,2,2,2,2,2,2,2,2,2,2,2,2,2,2,2,6,6,6,2,2,2,2,2,2,16,16,16,16,2
9,9,2,4,4,4,4,4,4,2,6,6,2,2,2,2,2,2,2,2,2,2,2,2,2,2,2,2,2,2,2,2,2,6,6,6,6,2,2,2,2,2,16,16,10,10,10,10
9,9,2,2,4,4,4,4,4,24,2,2,2,2,2,2,2,2,2,2,2,2,2,2,2,2,2,2,2,2,2,2,2,6,6,6,6,2,2,2,2,16,16,16,10,10,10,10
9,9,2,2,4,4,4,4,4,24,2,2,2,2,2,2,2,2,2,2,2,2,2,2,2,2,2,2,2,2,2,2,2,6,6,6,6,2,2,2,2,16,16,16,16,10,10,10
9,9,2,2,2,4,4,4,4,4,4,2,2,2,2,2,2,2,2,2,2,2,2,2,2,2,2,2,2,2,2,2,2,6,6,6,6,2,2,2,2,16,17,16,16,2,10,10
9,9,2,2,2,2,2,4,4,4,4,4,2,2,2,2,2,2,2,2,2,2,2,2,2,2,2,2,2,2,2,2,2,6,6,6,6,2,2,2,2,2,2,2,2,2,2,2
9,9,2,2,2,2,2,2,2,4,4,2,2,2,2,2,2,2,2,2,2,2,2,2,2,2,2,2,2,2,2,2,2,6,6,6,2,2,2,2,2,2,2,2,2,2,2,2
9,9,2,2,2,2,2,2,2,2,2,2,2,2,2,2,2,2,2,2,2,2,2,2,2,2,2,2,2,2,2,2,2,2,6,6,2,2,2,2,2,2,2,2,2,2,2,2
9,9,2,2,2,2,2,2,2,2,2,2,2,2,2,2,2,2,2,2,2,2,2,2,2,2,2,2,2,2,2,2,2,2,2,2,2,2,2,2,2,2,2,2,2,2,2,2
9,9,2,2,2,2,2,2,2,2,2,2,2,2,2,2,2,2,2,2,2,2,2,2,2,2,2,2,2,2,2,2,2,2,2,2,2,2,2,20,20,20,20,20,2,2,2,2
24,24,24,24,24,24,2,2,2,2,2,2,2,13,13,2,2,2,2,2,2,2,2,2,2,2,2,2,2,2,2,2,2,2,2,2,2,11,11,20,20,20,20,20,2,2,2,5
24,24,24,24,24,24,24,2,2,2,2,2,2,13,13,2,2,2,2,2,2,2,2,2,2,2,2,2,2,2,2,2,2,2,2,2,2,11,11,20,20,20,20,20,2,2,2,2
24,24,24,24,24,24,24,2,2,2,2,2,13,13,13,2,2,2,2,2,2,2,2,2,2,2,2,2,2,2,2,2,2,2,2,2,2,2,11,20,20,20,20,20,11,2,2,2
24,24,24,24,24,24,24,2,2,2,2,2,2,13,2,2,2,2,2,2,2,2,2,2,2,2,2,2,2,2,2,2,2,2,2,2,2,2,2,20,20,20,20,20,11,11,2,2
24,24,24,24,24,24,24,2,2,2,2,2,2,2,2,2,2,2,2,2,2,2,2,2,2,2,2,2,2,2,2,2,2,2,2,2,2,2,2,2,11,11,11,11,11,11,2,2
24,24,24,24,24,24,24,2,2,2,2,2,2,2,2,2,2,2,2,2,2,2,2,2,2,46,0,2,2,2,2,2,2,2,2,2,2,2,2,2,45,45,2,2,2,13,2,2
24,24,24,24,24,24,24,2,2,2,2,2,2,2,2,2,2,2,2,2,2,2,2,2,2,2,2,2,2,2,2,2,2,2,2,2,2,2,2,2,13,45,2,2,13,13,2,2
24,24,24,24,24,24,2,2,2,2,2,2,2,2,2,2,2,2,2,2,2,2,2,2,2,2,2,2,2,2,2,2,2,2,2,2,2,2,2,2,13,2,2,2,2,2,2,2
24,24,24,24,24,24,2,2,2,2,2,2,2,2,2,2,2,2,2,2,2,2,2,2,2,2,2,2,2,2,2,2,2,2,2,2,2,2,2,2,13,2,2,2,2,2,2,2
24,24,24,24,24,24,2,2,2,2,2,2,2,2,2,2,2,2,2,4,4,2,2,2,2,2,2,2,2,2,2,2,2,2,2,2,2,2,2,2,2,2,2,2,2,2,2,2
24,24,24,24,24,24,2,2,2,2,2,2,2,2,0,2,2,2,2,4,4,4,2,2,2,2,2,2,2,2,2,2,2,2,2,2,2,2,2,2,2,2,2,2,2,2,2,2
24,24,24,24,24,24,2,2,2,2,2,2,2,0,0,0,2,2,2,4,4,4,4,2,2,2,2,2,2,2,2,2,2,2,2,2,2,2,2,2,2,2,2,2,11,11,11,2
24,24,24,24,24,24,2,2,2,2,2,2,2,0,0,0,2,2,2,4,4,4,4,2,2,2,2,2,2,2,2,2,2,2,2,2,2,2,2,2,2,2,2,2,11,11,4,4
24,24,24,24,24,24,2,2,2,2,2,2,2,0,0,0,2,2,2,2,8,4,4,4,2,2,2,2,2,2,2,2,2,2,2,2,2,2,2,2,2,2,2,2,2,11,4,4
24,24,24,24,24,2,2,2,2,2,2,2,2,2,2,2,2,2,2,2,4,4,4,4,4,2,2,2,2,2,2,2,2,2,2,2,2,2,2,2,2,2,2,2,2,2,4,4
24,9,2,2,2,2,2,2,2,2,2,2,2,11,11,11,2,2,16,16,16,4,4,4,4,2,2,2,2,2,2,2,2,2,2,2,2,2,2,2,2,2,2,2,2,2,4,4
9,9,2,2,2,2,2,8,8,2,2,11,11,11,11,11,2,16,16,16,16,4,4,4,4,16,2,2,2,2,2,2,2,2,2,2,2,2,2,2,2,2,2,2,2,2,4,4
9,9,2,2,2,2,2,8,8,2,11,11,11,11,11,11,2,2,16,16,16,16,16,16,16,16,2,2,2,2,2,2,2,2,2,2,2,2,2,2,2,2,2,2,2,4,4,4
9,9,2,2,2,2,2,2,2,11,11,11,11,11,11,2,2,2,2,16,16,16,3,3,16,16,2,2,2,2,2,2,2,2,17,2,2,2,2,2,2,2,2,2,2,4,4,4
9,9,2,2,2,2,2,2,2,11,11,11,11,11,11,2,2,2,2,2,2,2,3,3,2,2,2,2,2,2,2,2,2,2,2,17,2,2,2,2,2,2,2,2,2,2,4,4
1,9,2,2,2,2,2,2,2,11,11,11,11,2,2,2,2,2,2,2,2,2,3,3,2,2,2,2,2,2,2,2,2,2,2,2,11,2,2,2,2,2,2,2,2,2,2,2
1,1,2,2,2,2,2,2,2,2,2,2,2,2,2,2,2,2,2,2,2,2,3,3,2,2,2,2,2,2,2,2,2,2,2,13,13,11,11,11,2,2,2,2,2,2,2,2
1,1,2,2,2,2,2,2,2,2,2,2,2,2,2,2,2,2,2,2,2,2,3,3,2,2,2,2,2,2,2,2,2,2,2,13,13,11,11,11,11,2,2,2,2,2,2,2
19,9,2,2,2,2,2,2,2,2,2,2,2,2,2,2,2,2,2,2,2,2,2,2,2,2,2,2,2,2,2,2,2,2,2,13,1,11,11,11,11,11,2,2,2,2,2,2
endlayer

layer
19,9,2,2,2,2,2,2,2,6,6,6,6,2,2,2,44,44,44,44,44,44,44,44,44,44,44,44,44,44,44,44,44,44,44,44,19,19,44,44,44,44,44,18,18,18,2,19
9,9,2,2,2,2,2,2,2,6,6,6,6,2,2,44,44,44,44,44,44,44,44,44,44,44,44,44,44,44,44,44,44,44,44,44,44,44,44,44,44,2,2,18,18,2,2,2
9,9,2,2,2,2,2,2,2,6,6,6,6,2,2,44,44,44,44,44,44,44,44,44,44,44,44,44,44,44,44,44,44,44,6,6,6,44,2,2,2,2,2,16,16,16,2,2
9,9,2,2,2,2,2,2,2,2,6,6,6,2,2,44,44,44,44,44,44,44,44,44,44,44,44,44,44,44,44,44,44,44,6,6,6,2,2,2,2,2,2,16,16,16,16,2
9,9,2,2,4,4,4,4,2,24,6,6,2,2,2,44,44,44,44,44,44,44,44,44,44,44,44,44,44,44,44,44,44,6,6,6,6,2,2,2,2,2,16,16,16,16,16,2
9,9,2,2,4,4,4,4,4,24,2,2,2,2,2,44,44,44,44,44,44,44,44,44,44,44,44,44,44,44,44,44,2,6,6,6,6,2,2,2,2,16,16,16,16,10,10,2
9,9,2,2,2,4,4,4,4,24,2,2,2,2,2,2,44,44,44,44,44,44,44,44,44,44,44,44,44,44,2,2,2,6,6,6,6,2,2,2,2,16,16,16,16,2,2,10
9,9,2,2,2,2,4,4,4,4,2,2,2,2,2,2,2,44,44,44,44,44,44,44,44,44,44,44,44,2,2,2,2,6,6,6,6,2,2,2,16,16,16,16,16,2,2,2
9,9,2,2,2,2,2,2,4,2,2,2,2,2,2,2,2,2,44,44,44,44,44,44,44,44,44,2,2,2,2,2,2,6,6,6,6,2,2,2,2,16,16,16,2,2,2,2
9,9,2,2,2,2,2,2,2,2,2,2,2,2,2,2,2,2,2,2,2,2,2,2,2,2,2,2,2,2,2,2,2,6,6,6,6,2,2,2,2,2,2,2,2,2,2,2
9,9,2,2,2,2,2,2,2,2,2,2,2,2,2,2,2,2,2,2,2,2,2,2,2,2,2,2,2,2,2,2,2,6,6,6,2,2,2,2,2,2,2,2,2,2,2,2
9,9,2,2,2,2,2,2,2,11,2,2,2,2,2,2,2,2,2,2,2,2,2,2,2,2,2,2,2,2,2,2,2,2,6,6,2,2,2,2,2,2,2,2,2,2,2,2
9,9,2,2,2,2,2,2,11,11,11,2,2,2,2,2,2,2,2,2,2,2,2,2,2,2,2,2,2,2,2,2,2,2,2,2,17,2,2,2,2,2,2,2,2,2,2,2
24,24,24,24,24,24,2,2,2,11,11,2,11,2,2,2,2,2,2,2,2,2,2,2,2,2,2,2,2,2,2,2,2,2,2,2,2,17,2,11,2,11,2,2,2,2,2,5
24,24,24,24,24,24,24,2,2,2,2,2,2,2,2,2,2,2,2,2,2,2,2,2,2,2,2,2,2,2,2,2,2,2,2,2,2,2,11,11,11,11,11,11,2,2,2,2
24,24,24,24,24,24,24,2,2,2,2,2,2,2,2,2,2,2,2,2,2,2,2,2,2,2,2,2,2,2,2,2,2,2,2,2,2,2,11,11,11,11,11,0,0,2,2,2
24,24,24,24,24,24,24,2,2,2,2,2,2,2,2,2,2,2,2,2,16,16,16,2,2,2,2,2,2,2,2,2,2,2,2,2,2,2,2,11,11,11,11,11,11,11,2,2
24,24,24,24,1,24,24,2,2,2,2,2,2,2,2,2,2,2,2,2,16,16,16,2,2,2,2,2,2,2,2,2,2,2,2,2,2,2,2,2,11,13,11,11,11,11,11,2
1,24,24,24,24,24,24,2,2,2,2,2,2,2,2,2,2,2,2,2,16,16,16,16,2,46,0,2,2,2,2,2,2,2,2,2,2,2,2,2,13,13,2,11,13,13,2,2
24,24,24,24,24,24,24,2,2,2,2,2,2,2,2,2,2,2,2,2,16,16,16,16,2,2,2,2,2,2,2,2,2,2,2,2,2,2,2,2,13,13,2,13,13,13,2,2
24,24,24,24,24,24,24,2,2,2,2,2,2,2,2,2,2,2,2,2,2,16,16,2,2,2,2,2,2,2,2,2,2,2,2,2,2,2,2,2,13,13,13,13,13,13,2,2
24,24,24,24,24,24,24,2,2,2,2,2,2,2,2,2,2,2,2,2,2,2,16,2,2,2,2,2,2,2,2,2,2,2,2,2,2,2,2,2,13,2,2,2,2,2,2,2
24,24,24,24,24,24,24,2,2,2,2,2,2,2,2,2,2,2,2,4,4,2,2,2,2,2,2,2,2,2,2,2,2,2,2,2,2,2,2,2,2,2,2,2,2,2,2,2
24,24,24,24,24,24,24,2,2,2,2,2,2,2,0,2,2,2,2,4,4,4,2,2,2,2,2,2,2,2,2,2,2,2,2,2,2,2,2,2,2,2,2,8,8,2,2,6
24,24,24,24,24,24,24,2,2,2,2,2,8,0,0,0,2,2,2,4,4,4,4,2,2,2,2,2,2,8,8,2,2,2,2,2,2,2,2,2,2,2,2,8,8,2,2,6
24,24,24,24,24,24,24,2,2,2,2,2,0,0,0,0,2,2,2,4,4,4,4,2,2,2,2,2,2,8,8,2,2,2,2,2,2,2,2,2,2,2,2,2,2,11,11,6
24,24,24,24,24,24,24,2,2,2,2,2,2,0,0,2,2,2,2,4,4,4,4,4,2,2,2,2,2,2,2,2,2,2,2,2,2,2,2,2,2,2,2,2,2,2,4,4
24,24,24,24,24,24,2,2,2,2,2,2,2,2,2,2,11,2,2,2,4,4,4,4,4,2,2,2,2,13,2,2,2,2,2,2,2,2,2,2,2,2,2,2,2,2,4,4
24,24,2,2,2,2,2,2,2,2,2,2,2,11,11,11,11,2,16,16,4,4,4,4,4,2,2,2,2,13,13,2,2,2,2,2,2,2,2,2,2,2,2,2,2,2,4,4
9,9,2,2,2,2,2,2,2,2,2,11,11,11,11,11,11,16,16,16,16,4,4,4,4,2,2,2,2,13,13,2,2,2,2,2,2,2,2,2,2,2,2,2,2,2,4,4
9,9,2,2,2,2,2,2,2,2,11,11,11,11,11,11,11,2,16,16,16,16,3,3,4,2,2,2,2,13,13,2,2,2,2,2,2,2,2,2,2,2,2,2,2,4,4,4
9,9,2,2,2,2,2,2,2,11,11,11,11,11,11,11,2,2,2,2,16,3,3,3,3,2,2,2,2,13,13,2,2,2,2,2,2,2,2,2,2,2,2,2,2,4,4,4
9,9,2,2,2,2,2,2,2,11,11,11,11,11,11,2,2,2,2,2,2,3,3,3,3,2,2,2,2,2,13,2,2,2,2,2,2,2,2,2,2,2,2,2,2,4,4,4
9,9,2,2,2,2,2,2,2,11,11,11,11,11,2,2,2,2,2,2,2,3,3,3,3,2,2,2,2,2,2,2,2,2,2,2,2,2,2,2,2,2,2,2,2,2,2,2
9,9,2,2,2,2,2,2,2,2,2,2,2,2,2,2,2,2,2,2,2,3,3,3,3,2,2,2,2,2,2,2,2,2,2,11,13,11,11,2,2,2,2,2,2,2,2,2
9,9,2,2,2,2,2,2,2,2,2,2,2,2,2,2,2,2,2,2,2,3,3,3,3,2,2,2,2,2,2,2,2,2,2,13,13,11,11,11,11,2,2,2,2,2,2,2
19,9,2,2,2,2,2,2,2,2,2,2,2,2,2,2,2,2,2,10,10,3,3,3,3,10,2,2,2,2,2,2,2,2,2,13,1,11,11,11,11,11,2,2,2,2,2,2
endlayer

layer
19,9,2,2,2,2,2,2,2,6,6,6,6,44,44,44,44,44,44,44,44,44,44,44,44,44,44,44,44,44,44,44,44,44,44,44,19,19,44,44,44,44,44,18,18,18,44,19
9,9,2,2,2,2,2,2,2,6,6,6,6,44,44,44,44,44,44,44,44,44,44,44,44,44,44,44,44,44,44,44,44,44,44,44,44,44,44,44,44,44,44,18,18,44,44,2
9,9,2,2,2,2,2,2,2,2,6,6,44,44,44,44,44,44,44,44,44,44,44,44,44,44,44,44,44,44,44,44,44,44,44,44,44,44,44,44,44,44,44,44,44,2,2,2
9,9,2,2,2,2,2,2,2,2,6,6,44,44,44,44,44,44,44,44,44,44,44,44,44,44,44,44,44,44,44,44,44,44,6,6,6,44,44,44,44,44,44,2,16,16,2,2
9,9,2,2,2,2,2,2,2,24,44,44,44,44,44,44,44,44,44,44,44,44,44,44,44,44,44,44,44,44,44,44,44,44,6,6,6,44,44,44,44,2,16,16,16,16,2,2
9,9,2,2,2,2,2,2,2,24,44,44,44,44,44,44,44,44,44,44,44,44,44,44,44,44,44,44,44,44,44,44,44,6,6,6,6,44,2,2,2,16,16,16,16,2,2,2
9,9,2,2,2,2,2,2,2,24,2,44,44,44,44,44,44,44,44,44,44,44,44,44,44,44,44,44,44,44,44,44,44,6,6,6,6,2,2,2,2,16,16,16,16,2,2,2
9,9,2,2,2,2,2,2,2,24,2,44,44,44,44,44,44,44,44,44,44,44,44,44,44,44,44,44,44,44,44,44,44,6,6,6,6,2,2,2,2,16,16,16,2,2,2,2
9,9,2,2,2,2,2,2,2,2,2,2,44,44,44,44,44,44,44,44,44,44,44,44,44,44,44,44,44,44,44,44,44,6,6,6,6,2,2,2,2,16,16,2,2,2,2,2
9,9,2,2,2,2,2,2,2,2,2,2,2,44,44,44,44,44,44,44,44,44,44,44,44,44,44,44,44,44,44,2,2,6,6,6,2,2,2,2,2,17,2,2,2,2,2,2
9,9,2,2,2,2,2,2,2,2,2,2,2,2,44,44,44,44,44,44,44,44,44,44,44,44,44,44,44,2,2,2,2,6,6,6,2,2,2,2,2,2,2,2,2,2,2,2
9,9,2,2,2,2,11,11,11,11,11,11,11,2,2,2,44,44,44,44,44,44,44,44,44,44,44,2,2,2,2,2,2,2,6,2,2,2,2,2,2,2,2,2,2,2,2,2
9,4,4,4,4,2,11,11,11,11,11,11,11,11,2,2,2,2,44,44,44,44,44,44,44,2,2,2,2,2,2,2,2,2,2,2,2,2,2,2,2,2,2,2,2,2,2,2
24,24,24,24,24,24,24,11,11,11,11,11,11,11,11,2,2,2,2,2,2,2,2,2,2,2,2,2,2,2,2,2,2,2,2,2,2,2,2,8,2,2,2,2,2,2,2,2
1,1,1,47,1,1,24,2,2,11,11,11,11,11,11,2,2,2,2,2,16,16,2,2,2,2,2,2,2,2,2,2,2,2,2,2,2,2,2,2,11,11,11,2,2,2,2,2
1,1,1,1,47,1,24,2,2,2,2,2,2,2,2,2,2,2,2,2,16,16,16,11,2,2,2,2,2,2,2,2,2,2,2,2,2,2,2,2,11,25,11,0,0,2,2,2
1,1,1,1,1,1,24,2,2,2,2,2,2,2,2,2,2,2,2,2,16,16,16,16,11,2,2,2,2,2,2,2,2,2,2,2,2,2,2,2,49,0,0,48,0,19,2,2
1,1,1,1,1,1,24,2,2,2,2,2,2,2,2,2,2,2,2,16,16,16,16,16,2,2,2,2,2,2,2,2,2,2,2,2,2,2,2,2,13,0,51,50,11,11,11,2
1,1,1,1,1,1,24,2,2,2,2,2,2,2,2,2,2,2,2,2,16,16,16,16,2,46,52,2,2,2,2,2,2,2,2,2,2,2,2,2,13,0,0,0,11,11,2,2
1,1,1,1,1,1,24,2,2,2,2,2,2,2,2,2,2,2,2,2,16,16,16,16,2,2,2,2,2,2,2,2,2,13,2,2,2,2,2,2,13,25,2,13,13,13,2,2
1,1,1,1,1,1,24,2,2,2,2,2,2,2,2,2,2,2,2,2,16,16,16,16,2,2,2,2,2,16,2,2,2,2,2,2,2,2,2,2,13,2,13,13,13,2,2,17
1,1,1,1,1,1,24,2,2,2,2,2,2,2,2,2,2,2,2,2,2,16,16,16,2,2,2,2,2,16,16,2,2,2,2,2,2,2,2,2,2,2,13,13,2,2,2,17
1,1,1,1,1,1,24,2,2,2,2,2,2,2,2,2,2,2,2,2,2,16,16,16,2,2,2,2,16,16,16,2,2,2,2,2,2,2,2,2,2,2,2,2,2,2,2,2
1,1,1,1,1,1,24,2,2,2,2,2,2,2,2,2,2,2,2,2,4,2,16,16,2,2,2,2,16,16,2,2,2,2,2,2,2,2,2,2,2,2,2,2,2,2,2,6
1,1,47,1,1,1,24,2,2,2,2,2,0,0,0,2,2,2,2,4,4,4,2,2,2,2,2,2,16,16,2,2,2,2,2,2,2,2,2,2,2,2,2,2,2,2,2,13
1,1,47,1,1,1,24,2,2,2,2,2,2,0,0,0,2,2,2,2,4,4,4,2,2,2,2,16,16,16,2,2,2,2,2,2,2,2,2,2,2,2,2,2,2,2,2,13
1,1,53,53,0,53,24,2,8,8,2,2,2,2,0,2,2,2,2,2,4,4,4,4,2,2,2,2,16,16,2,2,2,2,2,2,2,2,2,2,2,2,2,2,2,2,2,4
24,24,24,24,24,24,2,2,8,8,2,2,2,2,2,2,11,2,2,2,4,4,4,4,4,2,2,2,16,13,2,2,2,2,2,2,2,2,2,2,2,2,2,2,2,2,2,4
24,24,24,2,2,2,2,2,2,2,2,2,2,11,11,11,11,2,2,2,4,4,4,4,4,2,2,2,2,13,13,2,2,2,2,2,2,2,2,2,2,2,2,2,2,2,2,2
24,9,2,2,2,2,2,2,2,2,2,11,11,11,11,11,11,2,2,2,16,4,4,4,4,2,2,2,2,13,13,2,2,2,2,2,2,2,2,2,2,2,2,2,2,2,4,4
9,9,2,2,2,2,2,2,2,2,11,11,11,11,11,11,2,2,2,2,2,2,3,3,4,2,2,2,2,13,13,2,2,2,2,2,2,2,2,2,2,2,2,2,2,4,4,4
9,9,2,2,2,2,2,2,2,2,11,11,11,11,11,11,2,2,2,2,2,3,3,3,3,2,2,2,2,13,13,2,2,2,2,2,2,2,2,2,2,2,2,2,2,2,4,4
9,9,2,2,2,2,2,2,2,2,11,11,11,11,11,2,2,2,2,2,2,3,3,3,3,2,2,2,2,2,13,2,2,2,2,2,2,2,2,2,2,2,2,2,2,2,4,4
9,9,2,2,2,2,2,2,2,2,11,11,11,2,2,2,2,2,2,2,2,3,3,3,3,2,2,2,2,2,2,2,2,2,11,11,2,2,2,2,2,2,2,2,2,2,2,2
9,9,2,2,2,2,2,2,2,2,2,2,2,2,2,2,2,2,2,2,2,3,3,3,3,2,2,2,2,2,2,2,2,2,11,11,2,2,2,2,2,2,2,2,2,2,2,2
9,9,2,2,2,2,2,2,2,2,2,13,13,13,13,2,2,2,2,2,2,3,3,3,3,2,2,2,2,2,2,2,2,2,2,2,2,11,11,11,2,2,2,2,2,2,2,13
19,9,2,2,2,2,2,2,2,2,2,2,13,13,13,13,2,2,10,10,10,3,3,3,3,10,2,2,2,2,2,2,2,2,2,2,1,8,11,11,2,2,2,2,2,2,2,13
endlayer

layer
19,9,2,2,2,44,44,44,44,44,6,6,44,44,44,44,44,44,44,44,44,44,44,44,2,2,2,2,2,2,44,44,44,44,44,44,19,19,44,44,44,44,44,18,18,18,44,49
9,9,2,2,2,44,44,44,44,44,6,6,44,44,44,44,44,44,44,44,44,44,44,2,2,2,2,2,2,44,44,44,44,44,44,44,44,44,44,44,44,44,44,18,18,44,44,44
9,9,2,2,2,44,44,44,44,44,44,44,44,44,44,44,44,44,44,44,44,44,44,2,2,2,2,44,44,44,44,44,44,44,44,44,44,44,44,44,44,44,44,44,44,44,44,44
9,9,2,2,2,44,44,44,44,24,44,44,44,44,44,44,44,44,44,44,44,44,44,44,44,44,44,44,44,44,44,44,44,44,44,44,44,44,44,44,44,44,44,44,44,44,44,2
9,9,2,2,2,2,44,44,44,24,44,44,44,44,44,44,44,44,44,44,44,44,44,44,44,44,44,44,44,44,44,44,44,44,44,44,44,44,44,44,44,44,44,44,44,2,2,2
9,9,2,2,2,2,44,44,44,24,44,44,44,44,44,44,44,44,44,44,44,44,44,44,44,44,44,44,44,44,44,44,44,44,6,6,44,44,44,44,44,44,44,2,2,2,2,2
9,9,2,2,2,2,2,44,44,24,44,44,44,44,44,54,54,44,44,44,44,44,44,44,44,44,44,44,44,44,44,44,44,44,6,6,44,44,44,44,44,2,16,16,2,2,2,2
9,9,2,2,2,2,2,44,55,24,44,44,44,44,44,54,54,44,44,44,44,44,44,44,44,44,44,44,44,44,44,44,44,6,6,6,44,44,44,2,2,2,2,2,2,2,2,2
9,9,2,2,2,2,2,2,44,44,44,44,44,44,44,54,54,44,44,44,44,44,44,44,44,44,44,44,44,44,44,44,44,44,6,6,44,44,2,2,2,2,2,2,2,2,2,2
12,9,2,2,2,2,2,2,2,44,44,44,44,44,44,44,44,44,44,44,44,44,44,44,44,44,44,44,44,44,44,44,44,44,6,44,2,2,2,2,2,17,2,2,11,2,2,2
9,9,2,2,2,2,2,2,2,11,44,44,44,44,44,44,44,44,44,44,44,44,44,44,44,44,44,44,44,44,44,44,44,44,6,2,2,2,2,2,2,2,2,11,11,11,2,2
9,9,2,2,2,2,11,11,11,11,11,11,11,11,44,44,44,44,44,44,44,44,44,44,44,44,44,44,44,44,44,44,2,2,2,2,2,2,2,2,2,2,2,2,11,11,11,2
24,24,24,24,24,24,11,11,11,11,11,11,11,11,11,44,44,44,44,44,44,44,44,44,44,44,44,44,44,44,44,2,2,2,2,2,2,2,2,8,8,2,2,2,10,10,11,2
24,24,24,24,24,24,24,11,11,11,11,11,11,11,11,11,44,44,44,11,11,44,44,44,44,44,44,44,44,17,17,2,2,2,2,2,2,17,2,8,8,2,2,10,10,10,2,2
1,1,1,1,1,1,0,24,11,11,11,11,11,11,11,11,44,44,11,11,16,16,11,11,44,44,44,2,2,17,17,2,2,2,2,2,2,2,2,2,2,2,2,10,10,2,2,2
1,1,1,1,1,1,24,24,2,2,2,2,11,11,2,2,2,44,11,11,16,16,16,11,11,2,2,2,2,2,2,2,2,2,2,2,2,2,11,11,49,25,2,0,0,2,2,2
1,1,1,1,1,1,24,24,2,2,2,2,2,2,2,2,2,2,2,11,16,16,16,16,11,11,2,2,2,2,2,2,2,2,2,2,2,2,11,11,0,0,0,0,0,0,19,2
1,1,1,1,1,1,24,24,2,2,2,2,2,2,2,2,2,2,2,16,16,16,16,16,11,3,11,2,2,2,13,13,13,2,2,2,2,2,2,11,0,0,0,0,0,2,19,2
1,1,1,1,1,1,24,24,2,2,2,2,2,2,2,2,2,2,2,2,16,16,16,16,11,0,56,3,2,2,2,13,13,13,2,2,2,2,2,2,0,0,0,0,0,43,2,2
1,1,1,1,1,1,24,24,2,2,2,2,2,2,2,2,2,2,2,2,16,16,16,16,2,2,3,3,3,16,16,2,2,13,2,2,2,2,2,2,2,25,2,0,0,2,2,2
1,1,1,1,1,1,24,2,2,2,2,2,2,2,2,2,2,2,2,2,16,16,16,16,2,2,3,3,16,16,16,2,2,2,2,2,2,2,2,2,2,2,13,13,2,2,2,2
1,1,1,1,1,1,24,2,2,2,2,11,2,2,2,2,2,2,2,2,2,16,16,16,2,2,2,2,16,16,16,2,2,2,2,2,2,2,2,2,2,2,13,2,2,2,2,2
1,1,1,1,1,1,24,2,2,2,11,11,11,2,2,2,2,2,2,2,2,16,16,16,2,2,2,16,16,16,16,2,2,2,2,2,2,2,2,2,2,2,2,2,2,2,2,2
1,1,1,1,1,1,24,2,2,2,11,11,11,11,11,2,2,2,2,2,2,6,16,16,2,2,2,16,16,16,16,2,2,2,2,2,2,2,2,2,2,2,2,2,2,2,2,13
1,1,1,1,1,1,24,2,2,2,2,11,11,0,11,11,2,2,2,2,6,6,6,2,2,2,2,16,16,16,16,2,2,2,2,2,2,2,2,2,2,2,2,2,2,2,2,13
1,1,1,1,1,1,24,2,2,2,2,2,17,11,11,11,2,2,2,2,2,6,6,6,2,2,2,16,16,16,16,2,2,2,2,2,2,2,2,2,2,2,2,2,2,2,13,13
1,1,53,1,1,53,24,2,2,2,2,2,2,11,11,11,2,2,2,2,2,2,6,6,6,2,2,16,16,16,2,2,2,2,2,2,2,2,2,2,2,2,2,2,2,2,13,3
1,1,53,24,24,24,24,2,2,2,2,2,2,2,2,2,2,2,2,2,2,4,4,6,6,2,2,16,16,16,2,2,2,2,2,2,2,2,2,2,2,2,2,2,2,3,3,3
24,24,24,24,24,2,2,2,2,2,2,2,2,2,2,2,2,2,2,2,2,4,4,5,5,2,2,16,16,2,2,2,2,2,2,2,2,2,2,2,2,2,2,2,2,3,3,3
24,9,2,2,2,2,2,2,2,2,2,2,2,11,11,11,2,2,2,2,2,2,4,5,5,8,8,2,2,2,2,8,2,2,2,2,2,2,2,2,2,2,2,2,2,2,2,2
9,9,2,2,2,2,2,2,2,2,2,2,11,11,11,11,2,2,2,2,2,2,2,5,5,5,8,2,2,2,2,2,2,2,2,2,2,2,2,2,2,2,2,2,2,2,2,4
9,9,2,2,2,2,2,2,2,2,2,11,11,11,2,2,2,2,2,2,2,2,3,3,5,5,5,2,2,2,2,2,2,2,2,2,2,2,2,2,2,2,2,2,2,2,2,4
9,9,2,2,2,2,2,2,2,2,2,2,11,2,2,2,2,2,2,2,2,2,3,3,3,5,5,2,2,2,2,11,11,2,11,11,2,2,2,2,2,2,2,2,2,2,2,2
9,9,2,2,2,2,2,2,2,2,2,2,2,2,2,2,2,2,2,2,2,3,3,3,3,5,5,2,2,11,11,11,11,11,11,11,11,11,2,2,2,2,2,2,2,2,2,2
9,9,2,2,2,2,2,2,2,2,2,2,2,2,2,2,2,2,2,2,2,3,3,3,3,5,5,2,2,11,11,11,11,11,11,11,11,11,2,2,2,2,2,2,2,2,2,2
9,9,2,2,2,2,2,2,2,2,2,13,13,13,13,2,2,2,2,2,2,3,3,3,3,5,5,2,2,2,2,11,11,2,11,11,17,2,2,2,2,2,2,2,2,2,2,13
19,9,2,2,2,2,2,2,2,2,2,2,13,13,13,13,2,2,2,10,10,3,3,3,3,2,2,2,2,2,2,2,2,2,2,2,1,2,2,2,13,13,13,2,2,2,11,11
endlayer

layer
19,9,44,44,44,44,44,44,44,44,44,44,44,44,44,44,2,2,2,2,2,2,2,2,2,2,2,2,2,2,2,2,2,13,13,2,19,19,2,2,2,2,2,18,18,18,44,49
9,9,44,44,44,44,44,44,44,44,44,44,44,44,44,2,2,2,2,2,2,2,2,2,2,2,2,2,2,2,2,2,2,2,2,2,2,2,2,2,2,44,44,18,18,44,44,44
9,9,44,44,44,44,44,44,44,44,17,44,44,44,44,2,2,2,2,2,2,2,2,2,2,2,2,2,2,2,2,2,2,2,2,2,2,2,44,44,44,44,44,44,44,44,44,44
9,9,44,44,44,44,44,44,44,24,44,44,44,44,44,2,2,2,2,2,2,2,2,2,2,2,2,2,2,2,2,2,2,2,2,2,44,44,44,44,44,44,44,44,44,44,44,44
9,9,44,44,44,44,44,44,44,24,44,44,44,44,44,2,2,2,2,2,2,2,2,2,2,2,2,2,2,2,2,2,2,2,44,44,44,44,44,44,44,44,44,44,44,44,44,44
9,9,44,44,44,44,44,44,44,24,44,44,44,44,44,2,2,2,2,2,2,2,2,2,2,2,2,2,2,2,2,2,44,44,44,44,44,44,44,44,44,44,44,44,44,44,44,44
9,9,44,44,44,44,44,44,55,24,44,44,44,44,44,54,13,2,2,2,2,2,2,2,2,2,2,2,2,2,44,44,44,44,44,44,44,44,44,44,44,44,44,44,44,3,3,44
9,9,44,44,44,44,44,44,55,24,44,44,44,44,44,54,54,2,2,2,2,2,2,2,2,2,2,2,2,44,44,44,44,44,44,44,44,44,44,44,44,11,11,44,44,3,3,2
9,9,44,44,44,44,44,44,44,44,44,44,44,44,44,54,54,44,2,2,2,2,2,2,11,11,2,44,44,44,44,44,44,44,44,44,44,44,44,44,44,11,11,11,44,3,3,2
12,12,44,44,44,44,44,44,44,44,44,44,44,44,44,54,54,44,44,44,44,44,44,44,11,11,44,44,44,44,44,44,44,44,44,44,44,44,44,44,44,44,11,11,11,3,3,2
12,12,44,44,44,44,44,44,44,44,44,11,44,44,44,54,54,44,44,44,44,44,44,44,11,11,11,11,44,44,44,44,44,44,44,44,44,44,44,44,44,44,2,11,11,3,3,2
9,9,2,44,44,44,44,44,11,11,11,11,11,44,44,54,44,44,44,44,44,44,44,44,44,11,11,11,44,44,44,44,44,44,44,44,44,44,44,44,2,2,2,10,10,10,10,10
24,24,24,24,24,24,44,11,11,11,11,11,11,11,11,44,44,44,44,44,44,44,44,44,44,11,11,11,44,44,44,44,44,44,44,44,17,44,2,2,8,2,2,10,10,10,10,11
24,24,24,24,24,24,24,44,11,11,11,11,11,11,11,11,44,44,11,11,11,11,44,44,44,44,11,11,44,44,44,44,44,44,44,44,44,2,2,2,2,2,10,10,10,10,10,11
1,1,1,1,1,1,24,24,44,44,11,11,11,11,11,11,44,11,11,11,11,11,11,11,44,44,44,44,44,44,44,44,44,44,44,2,11,11,11,11,11,2,10,10,10,10,2,57
1,1,1,1,1,1,24,24,44,44,44,44,44,44,44,44,44,44,11,11,11,11,11,11,11,44,44,44,44,44,44,44,44,44,2,2,11,11,11,11,49,25,10,10,19,2,2,2
1,1,1,1,1,1,24,24,2,44,44,44,44,44,44,44,44,44,44,11,16,16,16,11,3,3,44,44,44,44,54,54,2,2,2,2,2,11,11,0,0,0,0,0,0,0,19,8
1,1,1,1,1,1,24,24,2,2,44,44,44,44,44,44,44,44,44,44,16,16,16,11,3,3,3,3,3,44,54,13,13,2,2,2,2,2,11,0,0,0,0,0,0,0,19,57
1,1,1,1,1,1,24,24,2,2,2,2,44,44,44,44,44,44,44,44,16,16,16,16,3,46,56,3,3,2,2,13,13,2,2,2,2,2,2,0,0,0,0,0,0,27,2,2
1,1,1,1,1,1,24,24,2,2,2,2,2,44,44,44,44,44,44,44,16,16,16,16,44,3,3,3,3,3,16,2,2,2,2,2,2,2,2,2,2,25,11,11,11,11,2,2
1,1,1,1,1,1,24,24,2,2,2,2,2,2,2,10,10,10,44,44,44,16,16,44,44,3,3,3,3,3,3,2,2,2,2,2,2,2,2,2,2,2,2,2,2,2,2,2
1,1,1,1,1,1,24,24,2,2,11,11,2,2,2,10,10,10,44,44,44,44,16,44,2,2,2,3,3,3,3,2,2,2,2,2,2,2,2,2,2,2,2,2,2,2,2,2
1,1,1,1,1,1,24,24,2,2,11,11,11,11,10,10,10,10,2,6,6,6,2,2,2,2,2,16,3,3,16,2,2,2,2,2,2,2,2,2,2,2,2,2,2,57,2,2
1,1,1,1,1,1,24,24,10,2,11,0,0,11,10,10,10,2,11,6,6,6,6,2,2,2,2,16,16,16,16,2,2,2,2,2,2,2,2,2,2,2,2,2,2,2,2,2
1,1,1,1,1,1,24,24,10,2,2,0,0,0,10,10,10,2,11,6,6,6,6,6,6,2,2,16,16,16,16,2,2,2,2,2,2,2,2,2,2,2,2,2,57,2,2,2
1,1,1,1,1,1,24,24,10,10,2,0,0,0,10,10,11,11,11,11,6,6,6,6,6,2,2,16,16,16,16,2,11,11,11,11,11,11,2,2,2,2,2,57,2,2,13,13
1,1,1,1,1,1,24,24,10,10,2,2,0,11,11,11,11,11,11,11,11,6,6,6,6,6,2,16,16,16,2,2,11,11,11,11,11,11,2,2,2,2,2,57,2,2,13,3
1,1,53,53,53,24,24,10,10,10,2,2,2,2,11,11,11,2,11,11,2,6,6,5,5,6,2,16,16,16,2,2,2,2,2,2,2,2,2,2,2,57,2,57,2,3,3,3
1,24,24,24,24,24,2,10,10,10,2,2,2,2,2,2,2,2,11,2,2,2,5,5,5,5,2,16,16,2,2,8,8,2,2,2,2,2,2,2,2,2,2,57,57,3,3,3
24,24,2,2,2,2,2,2,2,2,2,2,2,2,2,2,2,2,11,2,2,2,5,5,5,5,8,2,2,2,2,8,8,2,2,2,2,2,2,2,2,2,2,2,2,2,2,2
9,9,2,2,2,2,2,2,2,2,2,2,2,2,2,2,2,2,2,2,2,2,5,5,5,5,5,2,2,2,2,2,2,2,2,2,2,2,57,2,2,2,2,2,2,2,2,2
9,9,2,2,2,2,2,2,2,2,2,2,2,2,2,2,2,2,2,2,2,2,2,5,5,5,5,2,2,2,2,2,2,2,2,2,2,2,2,57,2,2,2,2,2,2,2,2
9,9,2,2,2,2,2,2,2,2,2,2,2,2,2,2,10,2,2,2,2,2,2,5,5,5,5,5,2,11,11,11,11,11,11,57,57,2,2,2,2,2,2,2,2,2,2,2
9,9,2,2,2,2,2,2,2,2,2,2,2,2,2,10,10,2,2,2,2,2,3,3,5,5,5,5,11,57,11,11,11,11,11,57,11,11,2,57,2,2,2,2,2,2,2,2
9,9,2,2,2,2,2,2,2,2,2,2,2,2,2,2,2,2,2,2,2,2,3,3,5,5,5,5,11,11,11,11,11,11,11,11,11,17,2,2,2,2,2,2,2,2,2,2
9,9,2,2,2,2,2,2,2,2,2,2,2,2,2,2,2,2,2,2,2,2,3,3,5,5,5,5,2,57,11,11,11,11,11,11,2,2,2,2,2,2,2,2,2,2,2,11
19,9,2,2,2,2,2,2,2,2,2,2,2,13,13,2,2,2,2,2,2,2,3,3,2,5,5,2,2,2,57,2,2,2,2,2,1,2,2,2,13,13,13,13,13,2,11,11
endlayer

layer
19,9,44,44,44,44,44,44,44,44,2,2,2,2,2,2,2,2,2,2,2,2,2,2,2,2,2,2,2,2,2,16,16,13,13,2,19,19,2,2,2,2,2,18,18,18,2,49
9,9,44,44,44,44,44,44,44,17,17,2,2,2,2,2,2,2,2,2,2,2,2,2,2,2,2,2,2,2,2,2,2,2,2,2,2,2,2,2,2,2,2,18,18,2,2,44
9,9,44,44,44,44,44,44,44,17,17,2,2,2,2,2,2,2,2,2,2,2,2,2,2,2,2,2,2,2,2,2,2,2,2,2,2,2,2,2,2,2,2,2,2,44,44,44
9,9,44,44,44,44,44,44,44,24,2,2,2,2,2,2,2,2,2,2,2,2,2,2,2,2,2,2,2,2,2,2,2,2,2,2,2,2,2,2,2,2,2,44,44,44,44,44
9,9,44,44,44,44,44,44,44,24,2,2,2,2,2,2,2,2,2,2,2,2,2,2,2,2,2,2,2,2,2,2,2,2,2,2,2,2,2,2,2,44,44,44,44,3,3,44
9,9,44,44,44,44,44,44,44,47,2,2,2,2,2,2,2,2,2,2,2,2,2,2,2,2,2,2,2,2,2,2,2,2,2,2,2,2,44,44,44,44,44,44,3,3,3,3
9,9,44,44,44,44,44,44,44,47,44,2,2,2,2,2,2,2,2,2,2,2,2,11,11,2,2,2,2,2,2,2,2,2,2,2,44,44,44,44,11,11,11,44,3,3,3,3
9,9,44,44,44,44,44,44,44,24,44,2,2,2,2,2,2,2,2,2,2,2,2,11,11,11,2,2,2,2,2,2,2,2,44,44,44,44,44,44,11,11,11,11,3,3,3,3
9,9,44,44,44,44,44,44,44,44,44,11,2,2,2,2,2,2,2,2,2,2,2,11,11,11,11,2,2,2,2,2,2,44,44,44,44,44,44,44,11,11,11,11,3,3,3,3
12,12,44,44,44,44,44,44,44,44,11,11,11,2,2,2,2,2,2,2,2,2,2,11,11,11,11,2,2,2,2,44,44,44,44,44,44,44,44,44,44,44,11,11,3,3,3,3
12,12,44,44,44,44,44,44,44,44,11,11,11,44,13,13,13,2,2,2,2,2,2,2,11,11,11,11,2,44,44,44,44,44,44,44,44,44,44,44,44,44,11,11,3,3,3,3
10,9,44,44,44,44,44,44,44,44,11,11,11,11,44,54,2,2,2,2,2,2,2,2,11,11,11,11,44,44,44,44,44,44,44,44,44,44,44,44,44,44,44,10,10,3,3,10
24,24,24,24,24,24,24,44,44,44,11,11,11,11,44,44,44,44,2,2,2,2,2,2,11,11,11,11,11,44,44,44,44,44,44,44,44,44,44,44,44,44,10,10,10,3,3,10
1,1,1,1,1,1,24,44,44,44,11,11,11,11,44,44,44,44,11,11,11,44,44,44,44,11,11,11,11,44,44,44,44,44,44,44,44,44,44,44,2,2,10,10,10,10,10,11
1,1,1,1,1,1,1,24,44,44,44,11,11,11,44,44,44,11,11,11,11,11,11,11,44,44,11,11,11,54,54,44,44,44,44,44,11,11,11,11,11,10,10,10,10,10,57,57
1,1,1,1,1,1,1,24,44,44,44,11,11,11,44,44,54,54,54,54,11,11,11,11,11,44,44,11,44,44,44,44,44,44,44,44,11,11,11,11,10,58,10,10,19,10,2,2
1,1,1,1,1,1,1,24,44,44,44,44,11,44,44,44,54,54,54,54,11,11,11,11,3,3,44,44,44,44,54,44,44,44,44,44,2,11,0,0,59,58,10,10,2,19,19,57
1,1,1,1,1,1,1,24,44,44,44,44,44,44,44,44,44,44,44,44,11,11,11,11,3,3,3,3,3,44,54,54,44,44,2,2,2,2,60,0,0,58,10,11,11,2,8,57
1,1,1,1,1,1,1,24,44,44,44,44,44,44,44,44,44,44,44,44,44,44,44,11,3,46,56,3,3,44,44,44,44,2,2,2,2,2,0,0,22,58,11,11,11,19,2,2
1,1,1,1,1,1,1,24,2,44,44,44,44,44,44,44,44,44,44,44,44,44,44,44,44,3,3,3,3,3,3,44,2,2,2,2,2,2,2,2,2,58,11,11,11,11,57,57
1,1,1,1,1,1,1,24,2,2,44,44,44,44,44,10,10,10,44,44,44,44,44,44,44,3,3,3,3,3,3,2,2,2,2,2,2,2,2,2,2,2,2,2,2,2,2,57
1,1,1,1,1,1,1,24,2,2,2,2,44,44,10,10,10,10,44,11,11,44,44,44,44,44,3,3,3,3,3,3,2,2,2,2,2,2,2,2,2,2,2,2,2,2,57,2
1,1,1,1,1,1,1,24,10,2,11,11,11,10,10,10,10,10,11,6,6,6,44,44,44,44,44,44,3,3,3,3,2,2,2,2,2,2,2,2,17,17,2,2,57,57,2,2
1,1,1,1,1,1,1,24,10,10,0,0,0,10,10,10,10,11,11,6,6,6,6,6,44,44,2,2,16,16,3,2,2,2,2,2,2,2,2,2,2,2,2,2,2,2,2,2
1,1,1,1,1,1,1,24,24,24,0,0,0,0,10,10,10,11,11,6,6,6,6,6,6,2,2,2,16,16,2,2,11,11,11,11,11,11,2,2,2,2,2,2,57,57,2,2
1,1,1,1,1,1,1,24,10,10,0,0,0,0,10,10,10,11,11,11,6,6,6,6,6,6,2,16,16,16,11,11,11,11,11,11,11,11,11,2,2,2,57,57,57,2,2,2
1,1,1,1,1,1,53,24,10,10,10,2,11,10,10,11,11,11,11,11,6,6,6,6,6,6,2,2,16,16,11,11,11,11,11,11,11,11,11,2,2,2,57,57,57,2,2,3
1,1,53,53,53,53,24,10,10,10,10,2,2,11,11,11,11,11,11,11,11,6,6,5,5,6,6,2,16,2,2,2,11,11,11,11,11,11,2,2,2,57,57,57,2,2,3,3
1,1,24,24,24,24,2,10,10,10,2,2,2,2,2,2,11,11,11,11,2,2,5,5,5,5,6,2,2,2,2,2,2,2,2,2,2,2,2,2,2,2,2,57,57,2,2,3
24,24,24,2,13,13,2,2,10,10,2,2,2,2,2,2,2,11,11,11,2,2,5,5,5,5,2,2,2,2,2,2,2,2,2,2,2,2,2,2,2,2,16,16,2,2,2,2
24,9,2,2,13,13,2,2,2,2,2,2,2,2,2,2,10,10,10,2,2,2,5,5,5,5,5,2,2,2,2,2,2,2,2,2,2,57,57,2,2,2,16,16,2,2,2,2
9,9,2,2,2,13,2,2,2,2,2,2,2,2,2,10,10,10,10,2,2,2,2,5,5,5,5,2,2,2,2,2,2,2,57,57,57,2,57,57,2,2,16,16,2,2,2,2
9,9,2,2,2,2,2,2,2,2,2,2,2,2,10,10,10,10,10,2,2,2,2,5,5,5,5,5,2,11,11,11,11,2,2,57,57,57,2,57,57,2,16,2,2,2,2,2
9,9,2,2,2,2,2,2,2,2,2,2,2,2,10,10,10,10,2,2,2,2,2,5,5,5,5,5,11,57,11,11,11,11,11,57,11,57,2,57,2,2,2,2,2,2,2,2
9,9,2,2,2,2,2,2,2,2,2,2,2,10,10,10,10,2,2,2,2,2,2,2,5,5,5,5,11,11,11,16,16,16,11,11,11,17,2,2,2,2,2,2,2,2,2,2
9,9,2,2,2,2,2,2,2,2,2,2,2,10,10,10,2,2,2,2,2,2,2,2,5,5,5,57,2,57,2,16,16,16,16,11,2,2,2,2,2,2,2,2,2,2,2,2
19,9,2,2,2,2,2,2,2,11,2,2,2,13,13,13,13,2,2,2,2,2,2,2,2,57,5,2,57,57,57,16,16,16,16,16,1,2,2,2,2,13,13,13,13,2,2,11
endlayer

layer
19,9,44,44,44,2,2,2,2,2,2,2,2,2,2,2,2,2,2,2,2,2,2,2,2,2,2,2,2,2,16,16,16,16,16,2,19,19,2,2,2,2,2,18,18,18,2,19
9,9,44,44,44,2,2,2,2,2,2,2,2,2,2,2,2,2,2,2,2,2,2,2,2,2,2,2,2,2,2,2,2,2,2,2,2,2,2,2,2,2,2,18,18,2,2,2
9,9,44,44,44,2,2,2,2,2,2,2,2,2,2,2,2,2,2,2,2,2,2,2,2,2,2,2,2,2,2,2,2,2,2,2,2,2,2,2,2,2,2,2,2,2,2,2
9,9,44,44,44,2,2,2,2,24,2,2,2,2,2,2,2,2,2,2,2,2,2,2,2,2,2,2,2,2,2,2,2,2,2,2,2,2,2,2,2,2,2,2,2,3,3,44
9,9,44,44,44,44,2,2,2,47,2,2,2,2,2,2,2,2,2,2,2,2,2,2,2,2,2,2,2,2,2,2,2,2,2,2,2,2,2,2,2,2,2,2,3,3,3,3
9,9,44,44,44,44,2,2,2,47,2,2,2,2,2,2,2,2,2,2,2,2,2,2,2,2,2,2,2,2,2,2,2,2,2,2,2,2,2,2,2,2,2,44,3,3,3,3
9,9,44,44,44,44,44,2,2,47,2,2,2,2,2,2,2,2,2,2,2,2,2,11,11,2,2,2,2,2,2,2,2,2,2,2,2,2,2,2,11,11,11,44,3,3,3,3
9,9,44,44,44,44,44,2,2,24,2,2,2,2,2,2,2,2,2,2,2,2,2,11,11,11,2,2,2,2,2,2,2,2,2,2,2,2,2,44,11,11,11,11,3,3,3,3
9,9,44,44,44,44,44,44,2,2,11,11,2,2,2,2,2,2,2,2,2,2,2,11,11,11,11,2,2,2,2,2,2,2,2,2,2,2,44,44,11,11,11,11,3,3,3,3
9,9,44,44,44,44,44,44,44,2,11,11,13,13,13,13,2,2,2,2,2,2,2,11,11,11,11,2,2,2,2,2,2,2,2,2,44,44,44,44,44,44,11,11,3,3,3,3
9,9,44,44,44,44,44,44,44,44,11,11,11,13,13,13,13,13,13,2,2,2,2,2,11,11,11,11,2,2,2,2,2,2,44,44,44,44,44,44,44,44,44,11,3,3,3,3
24,24,24,44,44,44,44,44,44,11,11,11,11,11,2,2,13,13,13,13,2,2,2,2,11,11,11,11,2,2,2,2,44,44,44,44,44,44,44,44,44,44,44,11,10,3,3,2
24,24,24,24,24,24,24,44,44,11,11,11,11,11,2,2,2,2,2,2,2,2,2,2,11,11,11,11,11,2,2,44,44,44,44,44,44,44,44,44,44,44,44,10,10,3,3,2
1,1,1,1,1,1,24,24,44,44,11,11,11,11,2,2,2,2,2,2,2,2,2,2,2,11,13,13,13,54,44,44,44,44,44,44,44,44,44,44,44,44,10,10,10,10,10,2
1,1,1,1,1,1,1,24,44,44,11,11,11,11,44,2,2,2,2,11,11,2,2,2,2,2,13,54,54,54,54,44,44,44,44,44,44,44,44,44,44,44,10,10,10,57,57,57
1,1,1,1,1,1,1,24,44,44,11,11,11,11,44,44,54,13,13,13,11,11,11,2,2,44,44,11,44,44,44,44,44,44,44,44,44,44,11,11,11,10,10,10,10,57,2,2
1,1,1,1,1,1,1,24,44,44,44,11,11,11,44,44,54,54,54,54,44,11,11,11,44,44,44,44,44,44,44,44,44,61,61,44,44,0,0,0,0,10,10,2,2,11,19,57
1,1,1,1,1,1,1,24,44,44,44,44,11,44,44,44,44,44,44,44,44,44,44,44,44,3,3,3,44,44,44,44,44,44,44,44,44,0,0,0,0,10,10,11,2,57,8,57
1,1,1,1,1,1,1,24,44,44,44,44,44,44,44,44,44,44,44,44,19,44,44,44,44,46,56,3,3,44,44,44,44,44,44,44,2,0,0,0,0,11,11,11,11,2,57,57
1,1,1,1,1,1,1,24,44,44,44,44,44,44,44,44,44,44,44,44,19,44,44,44,44,3,3,3,3,3,44,44,44,44,44,2,2,2,2,2,2,2,2,2,2,2,57,57
1,1,1,1,1,1,1,24,44,44,44,44,44,44,44,44,10,44,44,44,44,44,44,44,44,3,3,62,62,3,3,44,44,44,2,2,2,2,2,2,2,2,2,2,2,2,2,57
1,1,1,1,1,1,1,24,44,44,44,44,44,44,44,10,10,10,44,11,11,44,44,44,44,44,44,62,62,3,3,3,44,2,2,2,2,2,2,2,2,2,2,2,2,2,57,57
1,1,1,1,1,1,1,24,10,44,44,44,44,10,10,10,10,10,11,11,11,44,44,44,44,44,44,44,3,3,3,3,2,2,2,2,2,2,2,2,2,2,2,2,57,57,2,2
1,1,1,1,1,1,1,24,10,10,0,0,11,10,10,10,10,11,11,11,6,17,6,44,44,44,44,44,44,44,3,2,2,2,2,2,2,2,2,2,17,17,2,57,57,2,2,2
1,1,1,1,1,1,1,24,24,24,0,0,0,10,10,10,10,11,11,11,6,6,6,6,6,44,44,44,44,2,11,11,11,11,11,11,11,11,2,2,2,2,57,57,57,57,2,2
1,1,1,1,1,1,1,24,10,10,0,0,10,10,10,10,10,11,11,11,6,6,6,6,6,6,44,44,2,11,11,11,11,11,11,11,11,11,11,2,2,2,57,57,57,57,57,2
1,1,1,1,1,1,53,24,10,10,10,2,10,10,10,10,11,11,11,11,11,6,6,6,6,6,2,2,2,11,11,11,11,11,11,11,11,11,11,2,2,2,57,57,57,57,2,2
1,1,53,53,53,53,24,10,10,10,10,2,10,10,10,11,11,11,11,11,11,6,6,6,6,6,6,2,11,11,11,11,11,11,11,11,11,11,2,2,2,57,57,57,16,2,2,2
1,1,53,24,24,24,2,10,10,10,2,2,2,2,2,2,2,11,11,11,2,2,6,5,5,6,6,2,11,11,11,11,2,2,2,2,2,2,2,2,2,16,57,57,57,2,2,2
1,24,24,24,13,13,2,2,10,10,2,2,2,2,2,2,10,10,10,10,2,2,2,5,5,6,2,2,2,11,2,2,2,2,2,2,57,2,2,2,2,16,57,57,16,2,2,2
24,24,2,2,13,13,2,2,2,2,2,2,2,2,2,10,10,10,10,2,2,2,2,5,5,5,2,2,2,2,2,2,2,2,2,57,2,57,57,2,2,16,16,57,16,2,2,2
9,9,2,2,2,13,2,2,2,2,2,2,2,2,10,10,10,10,10,10,2,2,2,5,5,5,5,2,2,2,2,2,2,2,57,57,57,2,57,57,2,16,16,16,2,2,2,2
9,9,2,2,2,2,2,2,2,2,2,2,2,2,10,10,10,10,10,10,2,2,2,5,5,5,5,2,2,2,2,2,2,2,57,57,57,57,2,57,57,16,16,16,2,2,2,2
9,9,2,2,2,2,2,2,2,2,2,2,2,2,10,10,10,10,10,2,2,2,2,2,5,5,5,2,2,57,16,16,16,2,2,57,2,57,57,57,2,2,16,2,2,2,2,2
9,9,2,2,2,2,2,2,2,2,2,2,2,10,10,10,10,10,2,2,2,2,2,2,5,5,5,2,57,2,16,16,16,16,16,2,2,57,2,2,2,2,2,2,2,2,2,2
9,9,2,2,2,2,2,2,2,2,2,2,2,10,10,10,10,2,2,2,2,2,2,2,2,5,5,57,2,57,16,16,16,16,16,2,2,2,2,2,2,2,2,2,2,2,2,2
19,9,2,2,2,2,2,11,11,11,11,11,2,2,2,13,13,13,2,2,2,2,2,2,2,57,57,57,57,57,57,57,16,16,16,16,1,2,2,2,2,2,2,2,2,2,2,2
endlayer

layer
19,9,2,2,2,2,2,2,2,2,2,2,2,2,2,2,2,2,2,2,2,2,2,2,2,2,2,2,2,2,16,16,16,16,16,2,19,19,17,17,2,2,2,18,18,18,2,19
9,9,2,2,2,2,2,2,2,2,2,2,2,2,2,2,2,2,2,2,2,2,2,2,2,2,2,2,2,2,2,2,2,2,2,2,2,2,2,2,2,2,2,18,18,2,2,2
9,9,2,2,2,2,2,2,2,2,2,2,2,2,2,2,2,2,2,2,2,2,2,2,2,2,2,2,2,2,2,2,2,2,2,2,2,2,2,2,2,2,2,2,2,2,2,2
9,9,2,2,2,2,2,2,2,24,2,2,2,2,2,2,2,2,2,2,2,2,2,2,2,2,2,2,2,2,2,2,2,2,2,2,2,2,2,2,2,2,2,2,2,3,3,2
9,9,2,2,2,2,2,2,2,0,2,2,2,2,2,2,2,2,2,2,2,2,4,2,2,2,2,2,2,2,2,2,2,2,2,2,2,2,2,2,2,2,2,2,3,3,3,3
9,9,2,2,2,2,2,2,2,0,2,2,2,2,2,2,2,5,5,2,2,2,2,2,2,2,2,2,2,2,2,2,2,2,2,2,2,2,2,2,2,2,2,2,3,3,3,3
9,9,2,2,2,2,2,2,2,0,2,2,2,2,2,2,2,5,5,2,2,2,2,2,2,2,2,2,2,2,2,2,2,2,2,2,2,2,2,2,2,2,2,2,3,3,3,3
9,9,2,2,2,2,2,2,2,0,2,2,2,2,2,2,5,2,2,2,2,2,2,2,2,2,2,2,2,2,2,2,2,2,2,2,2,2,2,2,2,11,2,2,3,3,3,3
9,9,2,2,2,2,2,2,2,2,2,2,13,13,2,2,2,2,2,2,2,2,2,2,11,11,2,2,2,2,2,2,2,2,2,2,2,2,2,2,2,2,2,2,3,3,3,3
9,9,2,2,2,2,2,2,2,2,2,13,13,13,13,2,13,2,2,2,2,2,2,2,11,11,2,2,2,2,2,2,2,2,2,2,2,2,2,2,2,2,2,2,3,3,3,3
9,9,2,2,2,2,2,2,2,2,11,11,13,13,13,13,13,13,13,2,2,2,2,2,11,11,11,11,2,2,2,2,2,2,2,2,2,2,2,2,2,2,44,44,3,3,3,3
24,24,24,24,24,4,2,16,2,2,11,11,11,11,2,13,13,13,13,13,2,2,2,2,2,11,11,11,2,2,2,2,2,2,2,2,2,2,2,2,44,44,44,44,11,44,44,44
24,24,24,24,24,24,24,16,16,2,11,11,11,11,2,2,2,2,2,2,2,2,2,2,2,11,11,11,2,2,2,2,2,2,2,2,2,2,44,44,44,44,44,44,44,44,44,44
1,1,1,1,1,1,24,24,16,2,11,11,11,11,2,2,2,2,2,2,2,2,2,2,2,2,13,11,2,2,2,2,2,2,2,2,2,44,44,44,44,44,44,10,10,44,44,44
1,1,1,1,1,1,1,24,16,2,11,11,11,11,2,2,2,2,2,2,2,2,2,2,2,2,13,2,2,2,2,2,2,2,2,44,44,44,44,44,44,44,44,10,10,57,57,57
1,1,1,1,1,1,1,24,16,2,11,11,11,11,2,2,2,2,2,2,2,2,2,25,2,2,2,2,2,25,2,2,2,25,61,44,44,25,44,44,44,44,44,44,2,57,57,57
1,1,1,1,1,1,1,24,44,2,2,11,11,11,2,2,2,2,2,2,2,2,2,63,0,0,0,0,0,0,0,0,0,0,0,0,0,0,0,27,44,44,44,2,2,11,19,57
1,1,1,1,1,1,1,24,44,44,2,2,11,2,2,2,2,2,2,2,19,19,0,0,0,0,0,51,0,0,0,51,51,0,0,0,51,0,0,0,44,2,2,2,2,57,57,57
1,1,1,1,1,1,1,24,44,44,44,44,2,2,2,2,2,2,2,2,0,19,19,0,0,0,56,0,0,0,0,0,0,0,0,0,0,0,0,0,2,2,2,2,2,2,57,57
1,1,1,1,1,1,1,24,11,44,44,44,44,2,2,2,2,2,2,2,0,19,2,25,2,2,3,13,13,25,44,44,44,25,6,6,6,25,23,2,2,2,2,2,2,2,57,57
1,1,1,1,1,1,1,24,11,44,44,44,44,44,44,2,2,2,2,2,2,2,2,2,2,2,44,62,62,3,44,44,44,44,6,6,6,6,6,2,2,2,2,2,2,2,57,57
1,1,1,1,1,1,1,24,44,44,44,44,44,44,44,44,44,2,2,2,2,2,2,2,44,44,44,62,62,3,44,44,44,44,44,6,6,6,6,6,2,2,2,2,2,2,57,57
1,1,1,1,1,1,1,24,44,44,44,44,44,44,10,10,44,44,44,11,44,44,44,44,44,44,44,44,54,44,44,44,44,44,44,2,2,6,6,6,6,2,2,2,57,57,2,2
1,1,1,1,1,1,1,24,10,44,0,0,44,10,10,10,10,44,11,11,11,17,44,44,44,44,44,44,44,44,44,44,44,44,2,2,2,2,6,6,2,2,57,57,57,57,2,16
1,1,1,1,1,1,1,24,10,44,0,0,44,10,10,10,44,44,11,11,11,44,44,44,44,44,44,44,44,44,11,11,11,11,11,11,11,2,2,2,2,6,57,57,57,57,5,2
1,1,1,1,1,1,1,24,10,10,0,0,10,10,10,10,44,11,11,11,11,44,6,6,44,44,44,44,44,11,11,11,11,11,11,11,11,11,2,2,2,6,57,57,57,57,57,2
1,1,1,1,1,1,1,24,10,10,44,44,10,10,10,44,44,11,11,11,11,44,6,6,6,44,44,44,11,11,11,11,11,11,11,11,11,11,2,2,2,5,57,57,57,57,2,2
1,1,1,1,1,1,1,10,10,10,2,44,10,10,44,44,44,44,11,11,44,44,44,6,6,6,11,11,11,11,11,11,11,11,11,11,11,2,2,2,2,57,57,57,57,2,2,2
1,1,1,1,1,24,24,10,10,10,2,2,44,44,44,44,44,44,10,10,44,44,44,44,6,6,11,11,11,11,11,11,11,11,2,2,2,2,2,2,2,16,57,57,57,2,2,2
1,24,24,24,24,2,2,2,2,2,2,2,2,2,44,44,10,10,10,10,10,44,44,44,44,44,11,11,11,11,11,11,11,2,2,2,57,2,2,2,2,16,57,57,16,2,2,2
24,24,24,2,2,2,2,2,2,2,2,2,2,2,2,10,10,10,10,10,44,44,44,44,44,44,2,2,2,2,2,2,2,2,57,57,57,57,57,2,2,16,16,57,16,2,2,2
24,9,2,2,2,2,2,2,2,2,2,2,2,2,2,10,10,10,10,10,44,44,44,44,2,2,2,2,2,2,2,2,2,2,57,57,57,57,57,57,2,16,16,16,16,2,2,2
9,9,2,2,2,2,2,2,2,2,2,2,2,2,10,10,10,10,10,10,44,2,2,2,2,2,2,2,2,2,2,2,2,2,57,57,57,57,57,57,57,16,16,16,2,2,2,2
9,9,2,2,2,2,2,2,2,2,2,2,2,2,10,10,10,10,10,2,2,2,2,2,2,2,2,2,57,57,16,16,16,2,2,57,57,57,57,57,2,2,16,2,2,2,2,2
9,9,2,2,2,2,2,2,2,2,2,2,2,2,10,10,10,10,2,2,2,2,2,2,2,2,2,57,57,57,16,16,16,16,16,2,57,57,2,2,2,2,2,2,2,2,2,2
9,9,2,2,2,2,2,2,11,11,2,2,2,2,10,10,2,2,2,2,2,2,2,2,2,2,57,57,57,57,57,16,16,16,19,19,2,2,2,2,2,2,2,2,2,2,2,2
19,9,2,2,2,2,11,11,11,11,11,11,2,2,2,2,2,2,2,2,2,2,2,2,2,57,57,57,57,57,57,57,16,16,16,16,1,2,2,2,2,2,2,2,2,2,2,2
endlayer

layer
19,9,2,2,2,2,2,2,2,2,2,2,2,2,2,2,2,2,2,2,4,4,11,17,2,2,2,2,2,2,2,16,16,2,2,2,19,19,2,2,2,2,2,18,18,18,2,19
9,9,2,2,2,2,2,2,2,2,2,2,2,2,2,2,2,2,2,2,2,2,2,2,2,2,16,16,16,2,2,2,2,2,2,2,2,2,2,2,2,2,2,18,18,2,2,2
9,9,2,2,2,2,2,2,2,2,2,2,2,2,2,2,2,2,2,4,4,2,2,2,2,2,16,16,16,16,2,2,2,2,2,2,2,2,2,2,2,2,2,2,2,2,2,2
11,9,2,2,2,2,2,2,2,0,2,2,2,2,2,2,2,4,5,5,5,4,4,4,4,2,16,16,16,16,16,2,2,2,2,2,2,2,2,2,2,2,2,2,2,2,2,2
11,9,2,2,2,2,2,2,2,0,2,2,2,2,2,2,2,5,5,5,5,4,4,4,4,2,2,16,16,16,16,2,2,2,2,2,2,2,2,2,2,2,2,2,2,2,2,2
11,9,2,2,2,2,2,2,2,0,2,2,2,2,2,2,5,5,5,5,4,4,4,4,4,2,2,2,16,16,16,16,2,2,2,2,2,2,2,2,2,2,2,2,2,3,3,2
9,9,2,2,2,2,2,2,2,0,2,2,2,2,2,5,5,5,5,5,2,2,2,2,2,2,2,2,2,2,16,16,2,2,2,2,2,2,2,2,2,2,2,2,2,3,3,2
9,9,2,2,2,2,2,2,2,0,2,2,2,2,2,5,5,5,5,2,2,2,2,2,2,2,2,2,2,2,2,2,2,2,2,2,2,2,2,2,2,2,2,2,2,3,3,2
9,9,2,2,2,2,2,2,2,2,2,2,2,2,5,5,5,5,2,2,2,2,2,2,2,2,2,2,2,2,2,2,2,2,2,2,2,2,2,2,2,2,2,2,2,3,3,2
9,24,2,2,2,2,2,2,2,2,2,13,13,13,5,5,5,2,2,2,2,2,2,2,2,2,2,2,2,2,2,2,2,2,2,2,2,2,2,2,2,2,2,2,2,2,2,44
9,24,2,2,2,2,2,16,16,2,2,2,2,2,2,13,13,13,2,2,2,2,2,2,2,2,2,2,2,2,2,2,2,2,2,2,2,2,2,2,2,2,2,2,2,2,44,44
24,24,24,24,24,24,16,16,16,2,2,11,11,2,2,13,13,13,2,2,2,2,2,2,2,2,2,2,2,2,2,2,2,2,2,2,2,2,2,2,2,2,2,2,44,44,44,44
1,1,1,1,24,24,24,16,16,2,2,11,11,2,2,2,2,2,2,2,2,2,2,2,2,2,2,2,2,2,2,2,2,2,2,2,2,2,2,2,2,2,44,44,44,44,44,5
1,1,1,1,1,1,1,24,16,2,2,2,11,2,2,2,2,2,2,2,2,2,2,2,2,2,2,2,2,2,2,2,2,2,2,2,2,2,2,2,44,44,44,44,44,44,44,5
1,1,1,1,1,1,1,1,16,2,2,11,11,11,2,2,2,2,2,2,2,2,2,2,2,2,2,2,2,2,2,2,2,2,2,2,2,2,2,44,44,44,44,44,44,57,53,53
1,1,1,1,1,1,1,1,16,2,2,11,11,2,2,2,2,2,2,2,2,2,2,25,2,2,2,2,2,25,0,64,22,25,2,2,2,25,44,44,44,44,44,44,44,57,53,53
1,1,1,1,1,1,1,1,16,2,2,2,2,2,2,2,2,2,2,2,2,19,0,0,0,0,0,0,0,0,0,0,0,0,0,0,0,0,0,44,44,44,44,44,44,11,19,53
1,1,1,1,1,1,1,1,11,2,2,2,2,2,2,2,2,2,2,2,2,22,0,0,0,0,0,0,0,0,0,0,0,0,0,0,0,0,0,44,44,44,44,44,44,53,53,53
1,1,1,1,1,1,1,1,24,2,2,2,2,2,2,2,2,2,2,2,2,0,22,0,0,0,56,0,0,0,0,0,0,0,0,0,22,0,0,44,44,44,44,2,2,2,53,53
1,1,1,1,1,1,1,1,11,11,2,2,2,2,2,2,2,2,2,2,2,2,2,25,2,2,2,13,13,25,2,2,44,25,6,6,6,25,44,44,44,44,2,2,2,2,53,53
1,1,1,1,1,1,1,1,11,11,2,2,2,2,2,2,2,2,2,2,2,2,2,2,2,2,2,13,13,2,44,44,44,6,6,6,6,6,6,6,44,2,2,2,2,2,57,57
1,1,1,1,1,1,1,1,11,11,44,44,2,2,2,2,2,2,2,2,2,2,2,2,2,2,2,13,13,44,44,44,44,44,6,6,6,6,6,6,6,2,2,2,2,2,57,57
1,1,1,1,1,1,1,1,11,11,44,44,44,2,2,2,2,2,2,2,2,2,2,2,2,2,2,2,54,44,44,44,44,44,44,6,6,6,6,6,6,6,2,2,57,57,5,5
1,1,1,1,1,1,1,1,11,44,44,44,44,44,44,2,2,2,2,2,2,2,2,2,2,2,44,44,44,44,44,44,44,44,44,44,44,6,6,6,6,6,57,57,57,57,5,5
1,1,1,1,1,1,1,1,44,44,24,44,44,44,44,44,44,2,2,2,2,2,2,2,44,44,10,10,44,44,44,44,44,44,44,44,2,2,6,6,6,6,57,57,57,57,5,5
1,1,1,1,1,1,1,1,44,44,44,44,44,44,44,44,44,44,44,44,44,44,44,44,44,10,10,10,10,10,11,11,11,11,11,11,2,2,2,6,5,5,57,57,57,57,57,16
1,1,1,1,1,1,1,1,44,44,44,44,44,44,44,44,44,44,44,44,44,44,44,44,44,44,10,10,10,10,10,11,11,11,11,11,2,2,2,5,5,5,57,57,57,57,2,2
1,1,1,1,1,1,1,1,44,44,44,44,44,44,44,44,44,44,44,44,44,44,44,44,44,44,11,10,10,10,10,10,11,11,11,11,2,2,2,2,5,57,57,57,57,6,6,2
1,1,1,1,1,1,24,2,44,44,44,44,44,44,44,44,44,44,10,10,44,44,44,44,44,44,11,11,10,10,10,10,11,11,11,2,2,2,2,2,2,16,57,57,57,2,2,2
1,1,24,24,24,24,2,2,2,44,44,44,44,44,44,44,44,44,10,10,10,44,44,44,44,44,11,11,11,11,11,11,11,11,2,2,57,2,2,2,2,16,57,57,16,2,2,2
24,24,24,24,2,2,2,2,2,2,44,44,44,44,44,44,10,10,10,10,44,44,44,44,44,44,44,44,44,44,2,2,13,13,57,57,57,57,57,2,2,16,16,57,16,2,2,2
24,24,5,2,2,2,2,2,2,2,2,44,44,44,44,10,10,10,10,44,44,44,44,44,44,44,44,44,44,2,2,2,13,13,57,57,57,57,57,57,2,16,16,16,2,2,2,2
5,5,5,2,2,2,2,2,2,2,2,2,44,44,44,10,10,10,10,44,44,44,44,44,44,44,44,44,2,2,2,13,13,2,57,57,57,57,57,57,57,2,16,16,2,2,2,2
5,5,5,2,2,2,2,2,2,2,2,2,2,44,44,10,10,10,44,44,44,44,44,44,44,44,44,44,57,57,2,2,2,2,2,57,57,57,57,57,2,2,2,2,2,2,17,2
9,9,2,2,2,2,2,2,2,2,2,2,2,44,44,44,44,44,44,3,44,44,44,44,44,44,44,57,57,57,2,16,16,16,2,2,57,57,2,2,2,2,2,2,2,2,17,2
9,9,2,2,2,2,2,2,2,2,2,2,2,2,44,44,44,44,3,3,44,44,44,44,44,44,57,57,57,57,57,16,16,16,19,19,2,2,2,2,2,2,2,2,2,10,2,2
19,9,2,2,2,2,11,11,11,11,11,2,2,2,44,44,44,44,44,3,44,44,44,44,44,57,57,57,57,57,57,57,16,16,16,16,1,2,2,2,2,2,2,2,10,10,2,2
endlayer

layer
66,65,2,2,2,2,2,2,2,2,2,2,2,2,2,2,2,2,4,4,4,4,4,17,2,2,16,16,2,2,2,2,2,2,2,2,19,19,2,2,2,2,2,18,18,24,24,24
65,65,2,2,2,2,2,2,2,2,2,2,2,2,2,2,2,2,4,4,4,11,11,11,11,16,16,16,16,16,2,2,2,2,2,2,2,2,2,2,2,2,2,18,18,2,2,24
65,65,2,2,2,2,2,2,2,2,2,2,2,2,2,2,2,4,4,4,4,4,4,11,2,16,16,16,16,16,16,2,2,2,2,2,2,2,2,2,2,2,2,2,2,2,2,2
11,65,2,2,2,2,2,2,2,2,2,2,2,2,2,2,4,4,5,5,5,4,4,4,4,2,16,16,16,16,16,2,2,2,2,2,2,2,2,2,2,2,2,2,2,2,2,2
11,65,2,2,2,2,2,2,2,0,2,2,2,2,2,2,5,5,5,5,5,4,4,4,4,2,16,16,16,16,16,16,2,2,2,2,2,2,2,2,2,2,2,2,2,2,2,2
11,65,2,2,2,2,2,2,2,0,2,2,2,2,2,2,5,5,5,5,4,4,4,4,4,2,2,16,16,16,16,16,16,2,2,2,2,2,2,2,2,2,2,2,2,2,2,2
65,65,2,2,2,2,2,2,2,0,2,2,2,2,2,5,5,5,5,5,2,2,2,2,2,2,2,2,2,16,16,16,16,2,2,2,2,2,2,2,2,2,2,2,2,2,2,2
65,65,2,2,2,2,2,2,2,0,2,2,2,2,5,5,5,5,5,2,2,2,2,2,2,2,2,2,2,2,16,16,16,2,2,2,2,2,2,2,2,2,2,2,2,2,2,2
65,65,24,2,2,2,2,2,2,2,2,2,2,5,5,5,5,5,5,2,2,2,2,2,2,2,2,2,2,2,2,2,2,2,2,2,2,2,2,2,2,2,2,2,2,2,2,2
24,24,24,2,2,2,2,2,2,2,2,2,2,5,5,5,5,5,2,2,2,2,2,2,2,2,2,2,2,2,2,2,2,2,2,2,2,2,2,2,2,2,2,2,2,2,2,2
24,24,24,2,2,2,2,16,16,2,2,2,2,5,5,5,2,2,2,2,2,2,2,2,2,2,2,2,2,2,2,2,2,2,2,2,2,2,2,2,2,2,2,2,2,2,2,5
24,24,24,24,24,24,16,16,16,2,2,2,2,2,2,2,2,2,2,2,2,2,2,2,2,2,2,2,2,2,2,2,2,2,2,2,2,2,2,2,2,2,2,2,2,2,2,5
1,1,1,1,1,24,24,16,16,2,2,2,2,2,2,2,2,2,2,2,2,2,2,2,2,2,2,2,2,2,2,2,2,2,2,2,2,2,2,2,2,2,2,2,2,2,5,5
1,1,1,1,1,1,1,1,16,2,2,2,2,2,2,2,2,2,2,2,2,2,2,2,2,2,2,2,2,2,2,2,2,2,2,2,2,2,2,2,2,2,2,2,44,44,5,5
1,1,1,1,1,1,1,1,16,2,2,2,2,2,2,2,2,2,2,2,2,2,2,2,2,2,2,2,2,2,0,48,0,2,2,2,2,2,2,2,2,2,44,44,44,53,53,53
1,1,1,1,1,1,1,1,16,2,2,2,2,2,2,2,2,2,2,2,2,2,2,25,2,2,2,2,2,25,0,0,0,25,2,2,2,25,2,2,2,44,44,44,44,53,53,53
1,1,1,1,1,1,1,1,16,2,2,2,2,2,2,2,2,2,2,2,2,27,0,0,0,0,0,0,0,0,0,0,0,0,27,0,0,0,2,44,44,44,44,44,44,11,19,53
1,1,1,1,1,1,1,1,24,2,2,2,2,2,2,2,2,2,2,2,2,0,0,0,0,27,27,0,0,0,0,0,0,0,27,0,0,0,44,44,44,44,44,44,44,53,53,53
1,1,1,1,1,1,1,1,24,2,2,2,2,2,2,2,2,2,2,2,2,22,0,0,0,0,56,27,0,0,0,0,0,43,0,0,22,22,44,44,44,44,44,44,44,5,53,53
1,1,1,1,1,1,1,1,24,11,2,2,2,2,2,2,2,2,2,2,2,2,2,25,2,2,2,2,2,25,2,2,2,25,6,6,6,25,44,44,44,44,44,44,44,5,53,53
1,1,1,1,1,1,1,1,11,11,2,2,2,2,2,2,2,2,2,2,2,2,2,2,2,2,2,2,2,2,2,2,2,6,6,6,6,6,6,6,44,44,44,44,2,5,57,57
1,1,1,1,1,1,1,1,11,11,2,2,2,2,2,2,2,2,2,2,2,2,2,2,2,2,2,2,2,2,2,2,2,44,6,6,6,6,6,6,6,44,44,2,2,2,57,57
1,1,1,1,1,1,1,1,11,11,2,2,2,2,2,2,2,2,2,2,2,2,2,2,2,2,2,2,2,2,2,2,44,44,44,6,6,6,6,6,6,6,2,2,57,57,5,5
1,1,1,1,1,1,1,1,11,44,2,2,2,2,2,2,2,2,2,2,2,2,2,2,2,2,2,2,2,2,44,44,44,44,44,44,44,6,6,6,6,6,57,57,57,57,5,5
1,1,1,1,1,1,1,1,44,44,24,2,2,2,2,2,2,2,13,2,2,2,2,2,10,10,10,10,10,44,44,44,44,44,44,44,44,44,6,6,6,6,57,57,57,57,5,5
1,1,1,1,1,1,1,1,44,44,44,44,44,2,2,2,2,13,2,2,2,2,2,2,10,10,10,10,10,10,10,44,44,44,44,44,44,44,2,6,5,5,57,57,57,57,57,16
1,1,1,1,1,1,1,1,44,44,44,44,44,44,2,2,13,13,2,2,2,2,2,2,2,10,17,10,10,10,10,10,11,11,11,11,44,2,2,5,5,5,57,57,57,57,6,2
1,1,1,1,1,1,1,24,44,44,44,44,44,44,44,44,2,2,2,2,2,2,2,2,2,44,17,17,10,10,10,10,10,11,11,11,2,2,2,2,5,57,57,57,57,6,6,2
1,1,1,1,1,1,24,44,44,44,44,44,44,44,44,44,44,44,44,44,44,44,44,44,44,44,44,10,10,10,10,10,10,11,11,2,2,2,2,2,2,2,57,57,57,6,6,2
1,1,1,24,24,24,24,44,44,44,44,44,44,44,44,44,44,44,44,44,44,44,44,44,44,17,44,44,11,10,10,10,10,54,13,2,57,2,2,2,2,2,57,57,2,2,2,2
1,24,24,24,24,2,2,44,44,44,44,44,44,44,44,44,44,44,44,44,44,44,44,44,17,44,44,44,44,44,44,44,54,13,57,57,57,57,57,2,2,2,16,57,2,13,13,2
24,24,24,24,2,2,2,44,44,44,44,44,44,44,44,44,44,10,44,44,44,44,44,44,44,44,44,44,44,44,44,54,54,13,57,57,57,57,57,57,2,2,2,2,2,13,13,2
24,5,5,5,2,2,2,2,44,44,44,44,44,44,44,44,44,44,3,3,44,44,44,44,44,44,44,44,44,44,44,54,13,2,57,57,57,57,57,57,57,2,2,2,2,2,2,2
5,5,5,5,5,13,13,13,13,44,44,44,44,44,44,44,44,44,3,3,44,44,44,44,44,44,44,44,57,57,44,2,2,2,2,57,57,57,57,57,2,2,2,2,2,17,5,2
5,5,5,5,5,13,13,13,13,44,44,44,44,44,44,44,44,3,3,3,3,44,44,44,44,44,44,57,57,57,44,2,2,2,2,2,57,57,2,2,2,2,2,2,10,17,2,2
9,9,5,5,5,2,2,2,2,44,44,44,44,44,44,44,44,3,3,3,3,44,44,44,44,44,57,57,57,57,57,2,2,2,19,19,2,2,2,2,2,2,2,2,10,10,10,2
19,9,2,2,2,2,2,2,2,2,44,44,44,44,44,44,44,3,3,3,3,44,44,44,10,57,57,57,57,57,57,57,2,2,2,2,1,2,2,2,2,2,2,10,10,10,10,2
endlayer

layer
66,65,2,2,2,2,2,2,2,2,2,2,2,2,2,2,2,2,4,4,4,4,4,11,2,2,16,16,2,2,2,2,2,2,2,2,19,19,2,2,2,2,2,18,24,24,24,24
65,65,2,2,2,2,2,2,2,2,2,2,2,2,2,2,2,2,4,4,4,11,11,11,11,16,16,16,16,16,2,2,2,2,2,2,2,2,2,2,2,2,2,18,24,24,24,24
65,65,2,2,2,2,2,2,2,2,2,2,2,2,2,4,4,4,4,4,4,4,11,11,2,16,16,16,16,16,16,2,2,2,2,2,2,2,2,2,2,2,2,2,2,24,24,24
65,65,2,2,2,2,2,2,2,2,2,2,2,2,2,4,4,4,4,4,4,4,4,4,2,2,16,16,16,16,16,2,2,2,2,2,2,2,2,2,2,2,2,2,2,2,24,24
65,65,2,2,2,2,2,2,2,2,2,2,2,2,2,4,4,5,5,4,4,4,4,4,2,2,16,16,16,16,16,16,2,2,2,2,2,2,2,2,2,2,2,2,2,2,2,24
65,65,2,2,2,10,2,2,2,0,2,2,2,2,2,2,5,5,5,5,4,4,4,2,2,2,2,16,16,16,16,16,16,2,2,2,2,2,2,2,2,2,2,2,2,2,2,24
65,65,2,2,24,10,10,2,2,0,2,2,2,2,2,5,5,5,5,5,2,2,2,2,2,2,2,2,2,16,16,16,16,2,2,2,2,2,2,2,2,2,2,2,2,2,2,2
65,24,24,24,2,2,2,2,2,2,2,2,2,2,5,5,5,5,5,2,2,2,2,2,2,2,2,2,2,2,16,16,16,2,2,2,2,2,2,2,2,2,2,2,2,2,2,2
24,24,24,24,2,2,2,2,2,2,2,2,2,2,5,5,5,5,2,2,2,2,2,2,2,2,2,2,2,2,2,2,2,2,2,3,2,2,2,2,2,2,2,2,2,2,2,24
24,24,24,24,2,2,2,2,2,2,2,2,2,5,5,5,5,2,2,2,2,2,2,2,2,2,2,2,2,2,2,2,2,2,2,19,2,2,2,2,2,2,2,2,2,2,2,24
24,24,24,24,2,2,2,2,2,2,2,2,2,5,5,5,2,2,2,2,2,2,2,2,2,2,2,2,2,25,2,2,2,2,2,2,2,2,2,2,2,2,2,2,2,2,2,5
24,24,24,24,24,24,2,16,2,2,2,2,2,2,2,2,2,2,2,2,2,2,2,2,2,17,2,2,2,26,0,0,0,2,2,2,2,2,2,2,2,2,2,2,2,2,5,5
1,1,1,1,1,1,24,16,16,2,2,2,2,2,2,2,2,2,2,2,2,2,2,2,67,2,2,2,6,0,51,51,0,2,2,2,2,2,2,2,2,2,2,2,2,2,5,5
1,1,1,1,1,1,1,1,16,2,2,2,2,2,2,2,2,2,2,2,2,2,2,2,2,2,2,2,2,0,0,0,0,2,2,2,2,2,2,2,2,2,2,2,2,24,1,5
1,1,1,1,1,1,1,1,16,2,2,2,2,2,2,2,2,2,2,2,2,2,2,2,2,2,2,2,2,25,0,0,0,25,2,2,2,2,2,2,2,2,2,2,2,53,53,53
1,1,1,1,1,1,1,1,16,2,2,2,2,2,2,2,2,2,2,2,2,2,2,58,2,2,2,2,2,58,0,0,0,58,2,2,2,58,11,11,19,19,19,19,19,19,53,53
1,1,1,1,1,1,1,1,24,2,2,2,2,2,2,2,2,2,2,2,2,2,2,58,2,19,19,2,16,58,0,0,68,58,2,2,2,58,11,11,19,19,19,19,19,19,19,19
1,1,1,1,1,1,1,1,24,2,2,2,2,2,2,2,2,2,2,2,2,27,68,58,2,2,2,2,2,58,16,2,2,58,2,2,2,58,2,2,2,44,44,44,5,19,19,53
1,1,1,1,1,1,1,1,24,2,2,2,2,2,2,2,2,2,2,2,2,22,13,58,2,2,69,2,16,58,16,2,19,58,19,19,2,58,2,2,44,44,44,44,5,5,53,53
1,1,1,1,1,1,1,1,24,2,2,2,2,2,2,2,2,2,2,2,2,2,2,58,2,17,2,2,2,58,16,16,2,58,6,6,6,58,44,44,44,11,44,44,5,5,53,53
1,1,1,1,1,1,1,1,11,11,2,2,2,2,2,2,2,2,2,2,2,2,2,2,2,2,17,2,2,16,16,16,2,2,6,6,6,6,6,44,44,44,44,44,5,5,53,53
1,1,1,1,1,1,1,1,11,2,2,2,2,2,2,2,2,2,2,2,2,2,2,2,2,2,2,2,2,16,16,2,2,2,2,6,6,6,6,6,44,44,44,44,5,5,53,53
1,1,1,1,1,1,1,1,11,2,2,2,2,2,2,2,2,2,2,2,2,2,2,2,2,2,2,2,2,2,2,2,2,2,2,44,44,6,6,6,6,44,5,5,53,53,70,2
1,1,1,1,1,1,1,1,2,2,2,2,2,2,2,2,2,13,13,13,2,2,2,2,2,2,2,2,2,2,2,2,2,2,44,44,44,44,6,6,1,44,53,53,53,53,2,2
1,1,1,1,1,1,1,1,2,2,24,2,2,2,2,2,2,13,13,13,2,2,2,2,10,10,10,10,10,2,2,2,2,44,44,44,44,44,44,6,1,5,53,53,53,53,5,2
1,1,1,1,1,1,1,1,44,2,2,2,2,2,2,2,2,13,13,2,2,2,2,2,10,10,10,10,10,10,10,2,44,44,44,44,44,44,44,44,6,5,53,53,53,53,57,2
1,1,1,1,1,1,1,1,44,17,17,2,2,2,2,2,13,13,2,2,2,2,2,2,2,10,10,10,10,10,10,10,11,44,44,44,44,44,44,44,5,5,53,53,53,53,6,2
1,1,1,1,1,1,1,24,44,44,44,2,2,2,2,2,2,2,2,2,2,2,2,2,17,2,10,10,10,10,10,10,10,11,44,44,44,44,44,44,2,53,57,57,57,6,6,2
1,1,1,1,1,1,24,24,44,44,44,44,2,2,2,2,2,2,2,2,2,2,2,2,2,2,2,10,10,10,10,10,10,11,44,44,44,44,44,2,2,2,57,57,57,13,13,2
1,1,1,1,5,24,24,44,44,44,44,44,44,44,2,2,2,2,2,2,2,2,2,2,2,17,2,44,44,10,10,10,10,54,54,44,57,44,2,2,2,2,57,57,2,13,13,19
1,1,24,24,24,24,44,44,44,44,44,44,44,44,44,2,2,2,2,2,2,2,2,2,17,17,44,44,44,44,44,44,54,54,57,57,57,57,57,2,2,2,2,57,2,13,13,2
24,24,24,24,24,44,44,44,44,44,44,44,44,44,44,44,44,2,2,2,2,2,2,10,10,10,17,44,44,44,44,44,54,54,57,57,57,57,57,57,2,2,2,2,5,5,5,5
24,24,5,5,10,44,44,44,44,44,44,44,44,44,44,44,44,44,3,3,2,44,44,10,10,10,10,10,44,44,44,44,44,5,57,57,57,57,57,57,57,2,2,2,5,5,5,5
5,5,5,5,5,54,54,54,54,44,44,44,44,44,44,44,44,44,3,3,3,44,44,44,10,10,10,10,57,57,44,5,5,5,44,57,57,57,57,57,2,2,2,2,5,5,5,5
9,5,5,5,5,54,54,54,54,44,44,44,44,44,44,44,44,3,3,3,3,44,44,44,44,10,10,57,57,53,5,5,70,70,2,2,57,57,2,2,2,2,2,2,10,10,5,5
9,9,5,10,10,10,10,10,10,44,44,44,44,44,44,44,44,3,3,3,3,44,44,10,10,24,57,57,53,53,53,5,70,70,19,19,2,2,2,2,2,2,19,2,10,10,10,2
19,9,2,10,10,5,61,61,44,44,44,44,44,44,44,44,44,3,3,3,3,44,44,10,10,53,53,53,53,53,53,53,70,70,70,2,1,2,2,2,2,2,2,2,10,10,10,2
endlayer

layer
1,1,1,1,1,1,1,1,1,1,1,1,1,1,1,1,1,1,1,1,1,1,1,1,1,1,1,1,1,1,1,1,1,1,1,1,1,1,1,1,1,1,1,1,1,1,1,1
1,1,1,1,1,1,1,1,1,1,1,1,1,1,1,1,1,1,1,1,1,1,1,1,1,1,1,1,1,1,1,1,1,1,1,1,71,71,1,1,1,1,1,1,1,1,1,1
1,1,2,2,2,2,2,2,2,2,2,2,2,2,2,2,4,4,4,4,4,2,2,2,2,2,16,16,16,16,2,2,2,2,2,1,1,71,71,1,1,1,1,1,1,1,1,1
1,1,2,2,2,2,2,2,2,2,2,2,2,2,2,4,4,4,4,4,4,4,2,2,2,2,16,16,16,16,16,2,2,2,2,1,1,71,53,53,1,1,1,1,1,1,1,1
1,1,10,10,10,10,10,2,2,2,2,2,2,2,2,2,4,4,4,4,4,4,2,2,2,2,2,16,16,16,16,2,2,2,2,1,1,71,71,53,53,1,1,1,1,1,1,1
1,1,10,10,10,10,10,10,2,2,2,2,2,2,2,2,2,2,4,4,4,2,2,2,2,2,2,2,16,16,16,16,2,2,2,1,1,1,71,53,53,1,1,1,1,1,1,1
1,1,24,24,24,24,10,10,2,2,2,2,2,2,2,2,5,2,2,2,2,2,2,2,2,2,2,2,2,2,16,16,2,2,2,1,1,1,71,71,53,1,1,1,1,1,1,1
1,1,24,24,24,24,10,2,2,2,2,2,2,2,2,5,5,5,2,2,2,2,2,2,2,2,2,2,2,2,2,2,2,2,2,1,1,1,1,71,71,1,1,5,1,1,1,1
1,1,24,24,24,2,2,2,2,2,2,2,2,2,2,2,5,2,2,2,2,2,2,2,2,2,2,2,2,2,2,2,2,2,2,1,1,1,1,1,71,1,1,1,1,1,1,1
1,1,24,24,24,2,2,2,2,2,2,2,2,2,5,5,2,10,2,2,2,2,2,2,2,2,2,2,2,2,2,2,2,2,2,1,1,1,1,1,71,1,1,1,1,1,1,1
1,1,24,24,24,2,2,2,2,2,2,2,2,2,2,10,10,10,10,2,2,2,2,2,2,2,2,2,2,25,6,2,2,2,2,1,1,1,1,1,71,71,1,1,1,1,1,1
1,71,1,24,24,24,24,2,2,2,2,2,2,2,10,10,10,10,2,2,2,2,2,2,2,17,0,0,0,0,0,0,0,2,2,1,1,1,1,71,71,71,1,1,1,1,1,1
1,71,71,71,5,24,24,24,2,2,2,2,2,2,10,10,10,2,2,2,2,2,2,2,0,19,0,72,51,0,0,0,0,2,2,1,1,1,71,71,71,71,1,1,1,1,1,1
1,1,1,71,71,71,24,24,2,2,2,2,2,2,2,2,2,2,2,2,2,2,2,2,2,2,0,48,0,0,0,0,0,2,2,1,1,1,71,71,71,71,1,1,1,1,1,1
1,1,1,1,71,71,71,19,2,2,2,2,2,2,2,2,2,2,2,2,2,2,2,2,2,2,2,2,16,25,0,0,0,25,2,1,1,1,71,71,71,1,1,1,1,1,1,1
1,1,1,1,1,24,71,71,2,2,2,2,2,2,2,2,2,2,2,2,2,2,2,2,2,2,2,2,16,16,0,0,27,2,2,1,1,71,71,71,1,1,1,1,1,1,1,1
1,71,1,1,1,1,1,71,24,2,2,2,2,2,2,2,2,2,2,2,2,2,2,2,2,19,19,2,16,16,16,2,2,2,2,1,1,71,71,71,1,1,1,1,1,1,1,1
1,1,1,1,1,1,1,61,24,2,2,2,2,2,2,2,2,2,2,2,2,2,2,2,2,47,2,2,16,16,16,16,2,2,47,1,1,71,71,1,1,1,1,1,1,1,1,1
1,1,1,1,1,1,1,71,24,2,2,2,2,2,2,2,2,2,2,2,2,13,2,2,2,2,24,2,16,16,16,16,19,19,19,19,71,71,1,1,1,1,1,1,1,1,1,1
1,1,1,71,1,1,71,71,24,2,2,2,2,2,2,2,2,2,2,2,2,2,2,2,2,17,2,2,16,16,16,16,2,2,2,1,1,71,1,1,1,1,1,1,1,1,1,1
1,1,1,1,1,71,71,71,24,2,2,2,2,2,2,2,2,2,2,2,2,2,2,2,2,2,17,2,16,16,16,16,2,2,2,1,1,71,1,1,1,1,1,1,1,1,1,1
1,71,1,1,71,71,71,71,2,2,2,2,2,2,2,2,2,2,2,2,2,2,2,2,2,2,2,2,2,16,16,16,2,2,2,1,1,71,1,1,1,1,1,1,1,1,1,1
1,1,1,71,71,71,71,71,2,2,2,2,2,2,2,2,2,2,2,2,2,2,2,2,2,2,3,3,2,2,16,16,2,2,2,1,1,71,71,1,1,1,1,1,1,1,1,1
1,1,1,71,71,71,71,19,2,2,2,2,2,2,2,2,2,2,13,13,2,2,2,3,3,3,3,3,3,2,16,16,2,2,2,1,1,1,71,71,1,1,1,1,1,1,1,1
1,24,1,71,71,71,71,19,2,2,24,2,2,2,2,2,2,13,13,13,2,3,3,3,3,3,10,10,2,2,2,2,2,2,13,1,1,1,71,71,1,1,1,1,1,1,1,1
1,1,1,1,71,71,71,1,2,2,2,2,2,2,2,2,2,2,2,2,2,2,2,2,2,10,10,10,10,10,2,2,2,13,13,1,1,1,71,71,1,1,1,1,5,1,1,1
1,1,24,24,1,71,5,1,2,2,2,2,2,2,2,2,2,2,2,2,2,2,2,2,2,2,10,10,10,10,10,2,2,2,44,1,1,1,1,71,1,1,1,1,1,1,1,1
1,1,24,1,1,71,1,24,2,2,17,2,2,2,2,2,2,2,2,2,2,2,2,17,17,2,2,10,10,10,10,10,2,44,44,1,1,1,1,71,1,1,1,1,1,1,1,1
1,1,1,1,71,24,24,24,2,2,2,2,2,2,2,2,2,2,2,2,2,2,2,17,17,2,2,2,10,10,10,10,44,44,44,1,1,1,71,71,71,1,1,1,1,1,1,1
1,1,1,71,24,71,24,24,44,2,2,2,2,2,2,2,2,2,2,4,2,2,2,2,2,2,2,2,2,2,2,44,44,44,44,1,1,1,71,71,71,1,1,1,1,1,1,1
1,71,71,24,24,24,24,44,44,44,2,2,2,2,2,2,4,4,4,4,4,2,10,10,10,10,2,2,2,2,44,44,44,24,53,1,1,1,71,71,53,1,1,1,1,1,1,1
1,24,24,24,24,24,44,44,44,44,44,2,2,2,2,4,4,4,4,4,4,2,10,10,10,10,17,10,2,44,44,5,5,5,53,1,1,71,71,53,53,1,1,1,1,1,1,1
1,24,24,24,10,44,44,44,44,44,10,10,2,2,4,4,4,4,4,2,2,2,10,10,10,10,10,10,10,44,5,5,5,71,53,1,1,71,71,53,1,1,1,1,1,1,1,1
1,1,5,5,5,10,10,10,10,10,10,10,44,2,2,4,4,4,3,3,2,2,2,10,10,10,5,10,53,53,5,71,71,71,70,1,71,71,53,1,1,1,1,1,1,1,1,1
1,1,5,5,10,10,10,10,10,10,10,44,44,2,2,2,2,2,3,3,2,2,2,2,10,5,5,53,53,5,5,71,73,71,70,1,71,71,1,1,1,1,1,1,1,1,1,1
1,1,1,1,1,1,1,1,1,1,1,1,1,1,1,1,1,1,1,1,1,1,1,1,1,1,1,1,1,1,1,1,1,1,1,71,1,1,1,1,1,1,1,1,1,1,1,1
1,1,1,1,1,1,1,1,1,1,1,1,1,1,1,1,1,1,1,1,1,1,1,1,1,1,1,1,1,1,1,1,1,1,1,1,1,1,1,1,1,1,1,1,1,1,1,1
endlayer

layer
0,0,0,0,0,0,0,0,0,0,0,0,0,0,0,0,0,0,0,0,0,0,0,0,0,0,0,0,0,0,0,0,0,0,0,0,0,0,0,0,0,0,0,0,0,0,0,0
0,71,71,71,19,71,71,71,71,19,19,19,19,19,19,71,71,71,71,71,71,19,19,19,19,19,19,19,19,71,71,71,71,71,71,71,0,0,0,0,0,0,0,0,0,0,0,0
0,71,2,2,2,2,2,2,2,2,2,2,2,2,2,2,2,16,16,16,2,2,2,2,2,2,2,2,2,2,2,2,2,2,2,71,71,0,0,0,0,0,0,0,0,0,0,0
0,71,2,2,2,2,2,2,2,2,2,2,2,2,2,2,2,2,4,16,2,2,2,2,2,2,2,2,2,2,2,2,2,2,2,71,71,0,0,0,0,0,0,0,0,0,0,0
0,71,10,10,10,10,10,2,2,2,2,2,2,2,2,2,2,2,2,2,2,2,2,2,2,2,2,2,2,2,2,2,2,2,2,71,71,0,0,0,74,0,0,0,0,0,0,0
0,71,24,24,24,10,10,10,2,2,2,2,2,2,2,2,2,2,2,2,2,2,2,2,2,2,2,2,2,2,2,2,2,2,2,71,71,71,0,0,0,0,0,0,0,0,0,0
0,71,24,24,24,24,10,10,10,10,2,2,2,2,2,2,2,2,2,2,2,2,2,2,2,2,2,2,2,2,2,2,2,2,3,5,71,71,0,0,0,0,0,75,0,0,0,0
0,71,24,24,24,24,10,10,10,10,2,2,2,2,2,2,2,2,2,2,2,2,2,2,2,2,2,2,2,2,2,2,2,2,2,5,71,71,71,0,0,0,0,25,76,0,0,0
0,71,24,24,24,10,2,10,10,10,10,2,2,2,2,2,2,10,10,10,2,2,2,2,2,2,2,2,2,2,2,2,2,2,2,19,5,5,71,71,0,0,0,0,0,0,0,0
0,71,24,24,24,2,2,2,10,10,2,2,2,2,2,10,10,10,10,10,10,2,2,2,2,2,2,2,2,2,2,2,2,2,2,19,5,5,71,71,0,0,0,0,0,0,0,0
0,24,71,24,24,2,2,2,2,2,2,2,2,2,10,10,10,10,10,10,2,2,2,2,2,2,2,2,6,25,6,6,6,6,6,19,5,5,71,71,0,0,0,0,0,0,0,0
0,0,71,71,5,24,24,2,2,2,2,2,2,2,10,10,10,10,10,10,2,2,2,2,2,2,0,0,0,0,0,0,0,6,6,19,5,5,71,0,0,0,0,0,0,0,0,0
0,0,0,0,71,71,71,24,2,2,2,2,2,10,10,10,10,10,10,2,2,2,2,2,2,2,0,0,0,0,0,0,27,6,2,19,71,71,0,0,0,0,0,0,0,0,0,0
0,0,0,0,0,0,71,5,2,2,2,2,2,10,10,10,10,2,2,2,2,2,2,2,2,2,0,0,0,0,0,0,27,2,2,19,71,71,0,0,0,0,0,0,0,0,0,0
0,0,0,0,0,0,0,71,2,2,2,2,2,2,2,2,2,2,2,2,2,2,2,2,2,25,0,0,68,77,77,77,77,77,2,19,71,71,0,0,0,0,0,0,0,0,0,0
0,0,0,0,0,0,0,0,24,2,2,2,2,2,2,2,2,2,2,2,2,2,2,2,2,2,2,2,16,16,16,2,2,2,2,19,71,0,0,0,0,0,0,0,0,0,0,0
0,78,0,0,0,0,0,0,24,2,2,2,2,2,2,2,2,2,2,2,2,2,2,2,2,0,0,2,16,16,16,2,2,2,2,19,71,0,0,0,0,0,0,0,0,0,0,0
0,0,0,0,0,0,0,0,24,2,2,2,2,2,2,2,2,2,2,2,2,2,2,2,2,0,0,2,16,16,16,16,2,2,0,19,71,0,0,0,0,0,0,0,0,0,0,0
0,0,0,0,0,0,0,0,24,2,2,2,2,2,2,2,2,2,2,2,2,2,2,2,2,2,2,2,16,3,16,16,19,19,19,19,79,0,0,0,0,0,0,0,0,0,0,0
0,0,0,0,0,0,0,0,24,11,2,2,2,2,2,2,2,2,2,2,2,2,2,2,2,2,2,3,3,16,16,16,2,2,2,71,71,0,0,0,0,0,0,0,0,0,0,0
0,0,0,0,0,0,0,0,24,11,11,11,11,2,2,2,2,2,2,2,2,2,2,2,2,2,3,3,3,16,16,16,2,2,2,5,71,0,0,0,0,0,0,0,0,0,0,0
0,0,0,0,0,0,0,0,24,11,11,11,11,2,2,2,2,2,2,2,2,2,2,2,2,3,3,3,2,16,16,16,2,2,2,5,71,0,0,0,0,0,0,0,0,0,0,0
0,0,0,0,0,0,0,0,2,11,2,11,2,2,2,2,2,2,2,2,2,2,2,3,3,3,3,3,3,3,16,16,2,2,2,5,71,0,0,0,0,0,0,0,0,0,0,0
0,0,0,0,0,0,0,71,2,2,2,2,2,2,2,2,2,2,2,2,2,3,3,3,3,3,3,3,3,3,16,16,2,2,13,19,71,71,0,0,0,0,0,0,0,0,0,0
0,0,0,0,0,0,0,71,2,2,0,2,2,2,2,2,2,2,2,2,3,3,3,3,3,3,3,3,3,2,2,2,2,13,13,19,71,71,0,0,0,0,0,0,80,0,0,0
0,0,0,0,0,0,0,71,2,2,2,2,2,2,2,2,2,2,2,2,3,3,3,3,3,3,3,2,2,2,2,2,2,13,13,19,5,71,0,0,0,0,0,81,25,80,0,0
0,0,0,0,0,0,71,71,2,2,2,2,2,2,2,2,2,2,2,2,2,2,2,2,2,2,2,2,2,2,2,2,2,17,17,19,71,71,71,0,0,0,0,0,80,0,0,0
0,0,0,0,0,0,71,71,2,2,2,2,2,2,2,2,2,2,2,2,2,2,2,2,2,2,2,2,2,2,2,2,2,17,17,19,5,71,71,0,0,0,0,0,0,0,0,0
0,0,0,0,0,0,71,24,2,2,2,2,2,2,2,2,2,2,2,2,4,4,4,17,2,2,2,2,2,2,2,2,2,2,2,19,5,71,0,0,0,0,0,0,0,0,0,0
0,0,0,0,0,82,24,24,2,2,2,2,2,2,2,2,2,2,4,4,4,4,4,2,2,2,2,2,2,2,2,2,2,24,5,19,71,71,0,0,0,0,0,0,0,0,0,0
0,0,83,0,24,24,24,24,2,2,2,2,2,2,2,2,4,4,4,4,4,4,10,10,10,10,2,2,2,2,2,24,24,24,5,19,71,71,0,0,0,0,0,0,0,0,0,0
0,0,71,24,24,24,24,2,2,2,2,2,2,2,2,4,4,4,4,4,4,4,10,10,10,10,10,10,2,5,5,71,71,71,71,71,71,0,0,84,0,0,0,0,0,0,0,0
0,0,24,24,24,44,44,44,2,2,10,10,2,2,4,4,4,4,4,4,4,2,10,10,10,10,10,10,5,5,71,71,71,85,71,71,71,0,0,0,0,0,0,0,0,0,0,0
0,24,10,10,10,10,10,10,10,10,10,10,2,2,2,4,4,4,2,2,2,2,2,10,10,5,5,5,71,71,71,85,85,85,71,71,0,86,0,0,0,0,0,0,0,0,0,0
0,24,71,10,10,10,10,10,10,10,10,2,2,2,2,2,2,2,2,2,2,2,2,2,24,5,71,71,71,71,71,87,87,85,71,71,0,0,0,0,0,0,0,0,0,0,0,0
0,81,24,24,24,24,24,24,24,24,24,24,24,24,24,24,24,24,24,24,24,24,24,24,24,24,24,71,71,71,71,71,85,71,71,0,0,0,0,0,0,0,0,0,0,0,0,0
0,0,0,0,0,0,0,0,0,0,0,0,0,0,0,0,0,0,0,0,0,0,0,0,0,0,0,0,0,0,0,0,0,0,0,0,0,0,0,0,0,0,0,0,0,0,0,0
endlayer

layer
0,0,0,0,0,0,0,0,0,0,0,0,0,0,0,0,0,0,0,0,0,0,0,0,0,0,0,0,0,0,0,0,0,0,0,0,0,0,0,0,0,0,0,0,0,0,0,0
0,0,0,0,0,88,0,0,0,0,71,0,0,0,0,0,0,0,0,0,0,0,0,0,0,0,0,0,0,0,0,0,0,0,0,0,0,0,0,0,0,0,0,0,0,0,0,0
0,0,71,2,2,2,2,2,2,2,2,2,2,2,2,2,2,16,16,16,5,5,5,71,2,2,2,2,2,2,2,2,2,2,71,0,0,0,0,0,0,0,0,0,0,0,0,0
0,0,2,2,2,2,2,2,2,2,2,2,2,2,2,2,2,2,16,16,2,2,2,2,2,2,2,2,2,2,2,2,2,2,2,0,0,0,0,0,0,0,0,0,0,0,0,0
0,0,2,2,10,10,10,2,2,2,2,2,2,2,2,2,2,2,2,2,2,2,2,2,2,2,2,2,2,2,2,2,2,3,2,0,0,0,0,0,89,0,0,0,0,0,0,0
0,0,24,24,24,10,10,10,2,2,2,2,2,2,2,2,2,2,2,2,2,2,2,2,2,2,2,2,2,2,2,2,2,2,3,0,0,0,0,0,0,0,0,0,0,0,0,0
0,0,24,24,24,24,10,10,10,10,2,2,2,2,2,2,2,2,2,2,2,2,2,2,2,2,2,2,2,2,2,2,2,2,3,71,0,0,0,0,0,0,0,0,0,0,0,0
0,0,24,24,24,24,10,10,10,10,10,2,2,2,2,2,2,2,2,2,2,2,2,2,2,2,2,2,2,2,2,2,2,2,2,71,87,0,0,0,0,0,68,25,0,0,0,0
0,0,71,24,24,2,5,10,5,10,10,10,2,2,2,2,2,10,10,10,10,2,2,2,2,2,2,2,2,2,2,2,2,2,2,71,71,71,0,0,0,0,0,0,0,0,0,0
0,0,0,24,24,2,5,10,5,10,10,10,2,2,2,10,10,10,10,10,10,2,2,2,2,2,2,2,2,2,2,2,6,6,2,71,71,71,0,0,0,0,0,0,0,0,0,0
0,0,0,24,24,0,2,2,2,2,2,2,2,2,10,10,10,10,10,10,10,2,2,2,2,2,2,2,2,58,6,6,6,6,6,71,71,71,0,0,0,0,0,0,0,0,0,0
0,0,0,0,71,24,24,2,2,2,2,2,2,10,10,10,10,10,10,10,2,2,2,2,2,2,0,27,22,58,6,19,19,6,6,71,71,71,0,0,0,0,0,0,0,0,0,0
0,0,0,0,0,0,0,24,2,2,2,2,2,10,10,10,10,10,10,2,2,2,2,2,2,2,0,0,27,58,6,19,19,6,6,71,0,0,0,0,0,0,0,0,0,0,0,0
0,0,0,0,0,0,0,71,2,2,2,2,2,10,10,10,10,10,2,2,2,2,2,2,2,2,27,0,0,58,6,6,19,2,2,71,0,0,0,0,0,0,0,0,0,0,0,0
0,0,0,0,0,0,0,0,2,2,2,2,2,2,2,2,2,2,2,2,2,2,2,2,2,25,0,0,0,58,0,2,2,0,2,71,0,0,0,0,0,0,0,0,0,0,0,0
0,0,0,0,0,0,0,0,24,2,2,2,2,2,2,2,2,2,2,2,2,2,2,2,2,2,0,0,0,16,2,2,2,2,2,71,0,0,0,0,0,0,0,0,0,0,0,0
0,90,0,0,0,0,0,0,24,2,2,2,2,2,2,2,2,2,2,2,2,2,2,2,2,2,2,2,16,16,2,2,2,2,2,71,0,0,0,0,0,0,0,0,0,0,0,0
0,0,0,0,0,0,0,0,24,2,2,2,2,2,2,2,2,2,2,2,2,2,2,2,2,2,2,2,2,3,3,2,2,2,2,71,85,0,0,0,0,0,0,0,0,0,0,0
0,0,0,0,0,0,0,0,11,2,2,2,2,2,2,2,2,2,2,2,2,2,2,2,2,2,2,3,3,3,3,2,2,2,2,85,85,0,0,0,0,0,0,0,0,0,0,0
0,0,0,0,0,0,0,0,24,11,11,11,2,2,2,2,16,16,16,2,2,2,2,2,2,2,3,3,3,3,3,16,2,2,2,85,85,0,0,0,0,0,0,0,0,0,0,0
0,0,0,0,0,0,0,0,24,11,11,11,11,11,2,2,16,16,2,2,2,2,2,2,2,3,3,3,3,3,16,16,2,2,5,71,0,0,0,0,0,0,0,0,0,0,0,0
0,0,0,0,0,0,0,0,24,11,11,11,11,11,2,16,16,2,2,2,2,2,2,2,3,3,3,3,3,16,16,2,2,2,5,71,0,0,0,0,0,0,0,0,0,0,0,0
0,0,0,0,0,0,0,0,11,11,11,11,11,11,2,2,16,2,2,2,2,2,2,3,3,3,3,3,17,3,2,2,2,2,2,71,0,0,0,0,0,0,0,0,0,0,0,0
0,0,0,0,0,0,0,0,2,2,2,2,2,2,2,2,2,2,2,2,2,3,3,3,3,3,3,3,3,3,2,2,2,2,13,71,0,0,0,0,0,0,0,0,0,0,0,0
0,0,0,0,0,0,0,0,2,2,24,2,2,2,2,2,2,2,2,2,3,3,3,3,3,3,3,3,3,2,2,11,2,11,13,71,0,0,0,0,0,0,0,0,0,0,0,0
0,0,0,0,0,0,0,0,2,2,2,2,2,2,2,2,2,2,2,2,3,3,3,3,3,3,3,2,2,2,2,11,2,11,13,71,71,0,0,0,0,0,0,0,80,0,0,0
0,0,0,0,0,0,0,0,2,2,2,2,2,2,2,2,2,2,2,2,2,2,2,2,2,2,2,2,2,2,2,2,2,2,2,71,0,0,0,0,0,0,0,0,0,0,0,0
0,0,0,0,0,0,0,91,2,2,2,2,2,2,2,2,2,2,2,2,2,2,2,2,2,2,2,2,2,2,2,2,2,2,2,71,71,0,0,0,0,0,0,0,0,0,0,0
0,0,0,0,0,0,0,24,2,2,2,2,2,2,2,2,2,2,2,4,4,4,4,2,2,2,2,2,2,2,2,2,2,2,5,71,71,0,0,0,0,0,0,0,0,0,0,0
0,0,0,0,0,0,0,24,2,2,2,2,2,2,2,2,2,2,4,4,4,4,4,4,2,2,2,2,2,2,2,24,24,24,71,71,0,0,0,0,0,0,0,0,0,0,0,0
0,0,0,0,0,24,24,24,2,2,2,2,2,2,2,2,4,4,4,4,4,4,4,2,2,2,2,2,2,24,24,24,24,71,71,71,0,0,0,0,0,0,0,0,0,0,0,0
0,0,92,0,71,24,24,2,2,2,2,2,2,2,2,4,4,4,4,4,4,4,2,10,10,10,10,2,5,71,71,78,0,92,82,86,86,0,0,89,0,0,0,0,0,0,0,0
0,0,24,24,24,24,2,2,2,2,2,2,2,2,2,4,4,4,4,4,4,2,2,10,10,5,10,5,71,71,0,0,92,0,0,93,0,0,0,0,0,0,0,0,0,0,0,0
0,0,71,10,44,2,10,10,2,2,2,2,2,2,2,2,4,4,2,2,2,2,2,2,24,5,71,71,82,0,0,0,0,0,82,0,0,0,0,0,0,0,0,0,0,0,0,0
0,0,0,71,24,24,24,24,24,24,24,24,5,71,0,24,24,71,71,71,71,71,71,5,5,24,0,0,0,0,94,0,85,0,0,0,0,0,0,0,0,0,0,0,0,0,0,0
0,0,0,0,85,85,0,71,71,71,71,71,0,0,0,0,0,0,0,0,0,0,0,0,0,0,0,0,0,0,0,0,0,0,0,0,0,0,0,0,0,0,0,0,0,0,0,0
0,0,0,0,0,0,0,0,0,0,0,0,0,0,0,0,0,0,0,0,0,0,0,0,0,0,0,0,0,0,0,0,0,0,0,0,0,0,0,0,0,0,0,0,0,0,0,0
endlayer

layer
0,0,0,0,0,0,0,0,0,0,0,0,0,0,0,0,0,0,0,0,0,0,0,0,0,0,0,0,0,0,0,0,0,0,0,0,0,0,0,0,0,0,0,0,0,0,0,0
0,0,0,0,0,0,0,0,0,0,0,0,0,0,0,0,0,0,0,0,0,0,0,0,0,0,0,0,0,0,0,0,0,0,0,0,0,0,0,0,0,0,0,0,0,0,0,0
0,0,0,71,71,2,2,2,2,2,71,2,2,2,2,2,2,71,5,2,5,5,71,88,5,2,2,6,71,5,6,2,3,71,0,0,0,0,0,0,0,0,0,0,0,0,0,0
0,0,71,2,2,2,2,2,2,2,2,2,2,2,2,2,2,2,2,2,2,2,2,2,2,2,2,2,6,6,6,6,3,3,71,0,0,0,0,0,0,0,0,0,0,0,0,0
0,0,71,2,2,2,2,2,2,2,2,2,2,2,2,2,2,2,2,2,2,2,2,2,2,2,2,2,2,6,6,6,3,3,3,0,0,0,0,0,89,0,0,0,0,0,0,0
0,0,24,24,24,10,10,2,2,2,2,2,2,2,2,2,2,2,2,2,2,2,2,2,2,2,2,2,2,2,6,6,3,3,3,0,0,0,0,0,0,0,0,0,0,0,0,0
0,0,24,24,24,24,10,2,10,10,2,2,2,2,2,2,2,2,2,2,2,2,2,2,2,2,2,2,2,2,2,2,2,3,5,87,0,0,0,0,0,0,0,0,0,0,0,0
0,0,71,5,24,24,5,5,5,10,10,2,2,2,2,2,2,2,2,2,2,2,2,2,2,2,2,2,2,2,2,2,2,3,3,87,0,0,0,0,0,0,0,25,0,0,0,0
0,0,0,71,24,5,5,5,5,5,10,10,2,2,2,2,2,10,10,10,10,2,2,2,2,2,2,2,2,2,2,2,2,2,3,0,86,0,0,0,0,0,0,0,0,0,0,0
0,0,0,24,24,5,5,5,5,5,5,10,2,2,2,10,10,10,10,10,10,2,2,2,2,2,2,2,2,2,2,2,2,2,2,0,0,0,0,0,0,0,0,0,0,0,0,0
0,0,0,0,24,5,5,5,5,5,2,2,2,2,10,10,10,10,10,10,10,2,2,2,2,2,2,2,2,19,2,6,17,6,71,0,0,0,0,0,0,0,0,0,0,0,0,0
0,0,0,0,0,71,24,2,2,2,2,2,2,2,10,10,10,10,10,10,2,2,2,2,2,2,2,2,2,19,6,6,6,6,5,0,0,0,0,0,0,0,0,0,0,0,0,0
0,0,0,0,0,0,0,24,2,2,2,2,2,2,10,10,10,10,10,2,2,2,2,2,2,2,19,19,19,19,6,6,6,6,6,0,0,0,0,0,0,0,0,0,0,0,0,0
0,0,0,0,0,0,0,0,2,2,2,2,2,2,2,10,2,2,2,2,2,2,2,2,2,2,2,2,2,19,6,2,2,2,2,0,0,0,0,0,0,0,0,0,0,0,0,0
0,0,0,0,0,0,0,0,2,2,2,2,2,2,2,2,2,2,2,2,2,2,2,2,2,25,0,0,0,25,2,2,2,2,2,0,0,0,0,0,0,0,0,0,0,0,0,0
0,0,0,0,0,0,0,0,24,2,2,2,2,2,2,2,2,2,2,2,2,2,2,2,2,2,0,0,0,2,2,2,2,2,5,0,0,0,0,0,0,0,0,0,0,0,0,0
0,0,0,0,0,0,0,0,71,2,2,2,2,2,2,2,2,2,2,2,2,2,2,2,2,2,0,95,0,2,2,2,2,2,71,0,0,0,0,0,0,0,0,0,0,0,0,0
0,0,0,0,0,0,0,0,11,2,2,2,2,2,2,2,2,2,2,2,2,2,2,2,2,2,2,2,3,3,3,2,2,2,2,0,0,0,0,0,0,0,0,0,0,0,0,0
0,0,0,0,0,0,0,0,11,2,2,2,2,2,2,2,16,16,16,2,2,2,2,2,2,2,2,3,3,3,3,2,2,2,2,85,0,0,0,0,0,0,0,0,0,0,0,0
0,0,0,0,0,0,0,0,19,11,11,11,2,2,2,16,16,16,16,2,2,2,2,2,2,3,3,3,3,3,3,2,2,2,2,85,0,0,0,0,0,0,0,0,0,0,0,0
0,0,0,0,0,0,0,0,19,11,11,11,11,11,2,16,16,16,16,2,2,2,2,2,3,3,3,3,3,3,2,2,2,2,71,85,0,0,0,0,0,0,0,0,0,0,0,0
0,0,0,0,0,0,0,0,24,11,11,11,11,11,16,16,16,16,16,2,2,2,2,2,3,3,3,3,3,3,2,2,2,2,2,0,0,0,0,0,0,0,0,0,0,0,0,0
0,0,0,0,0,0,0,0,24,11,11,11,11,11,16,16,16,16,2,2,2,2,2,3,3,3,3,3,3,2,2,2,2,2,2,0,0,0,0,0,0,0,0,0,0,0,0,0
0,0,0,0,0,0,0,0,24,2,2,2,2,16,16,16,16,2,2,2,2,2,2,3,3,3,3,3,3,2,2,11,11,11,11,0,0,0,0,0,0,0,0,0,0,0,0,0
0,0,0,0,0,0,0,0,24,2,24,2,2,16,16,16,2,2,2,2,2,3,3,3,3,3,3,3,2,11,11,11,11,11,5,0,0,0,0,0,0,0,0,0,0,0,0,0
0,0,0,0,0,0,0,0,24,2,2,2,2,2,2,2,2,2,2,2,2,2,2,2,2,2,2,2,11,11,11,11,11,11,11,0,0,0,0,0,0,0,0,0,0,0,0,0
0,0,0,0,0,0,0,0,24,2,2,2,2,2,2,2,2,2,2,2,2,2,2,2,2,2,2,2,11,11,11,11,11,11,11,0,0,0,0,0,0,0,0,0,0,0,0,0
0,0,0,0,0,0,0,0,2,2,2,2,2,2,2,2,2,2,2,2,2,2,2,2,2,2,2,2,2,2,2,2,2,2,5,0,0,0,0,0,0,0,0,0,0,0,0,0
0,0,0,0,0,0,0,0,2,2,2,2,2,2,2,2,2,2,2,2,4,4,4,2,2,2,2,2,2,2,2,2,2,24,71,0,0,0,0,0,0,0,0,0,0,0,0,0
0,0,0,0,0,0,0,24,2,2,2,11,11,2,2,2,2,2,4,4,4,4,4,2,2,2,2,2,2,2,24,24,71,0,0,0,0,0,0,0,0,0,0,0,0,0,0,0
0,0,0,0,0,0,24,24,2,2,11,11,11,2,2,2,2,2,4,4,4,4,4,2,2,2,2,2,24,24,24,0,0,0,0,0,0,0,0,0,0,0,0,0,0,0,0,0
0,0,0,0,92,24,24,2,2,2,11,11,11,2,2,2,2,2,4,4,4,4,2,2,2,2,2,5,71,0,92,90,0,0,0,0,0,0,0,89,0,0,0,0,0,0,0,0
0,0,0,24,24,24,2,2,2,2,11,11,2,2,2,2,2,2,2,2,2,2,2,2,2,5,5,71,0,94,0,0,0,0,0,0,0,0,0,0,0,0,0,0,0,0,0,0
0,0,0,71,11,11,2,2,2,11,11,2,2,2,2,2,2,2,2,2,2,2,2,24,24,71,0,94,0,0,0,0,0,0,0,0,0,0,0,0,0,0,0,0,0,0,0,0
0,0,0,92,85,85,24,24,24,11,11,5,71,0,0,0,0,0,0,0,0,0,0,24,24,0,0,0,0,0,0,0,0,0,0,0,0,0,0,0,0,0,0,0,0,0,0,0
0,0,0,0,0,0,0,0,0,0,0,0,0,0,0,0,0,0,0,0,0,0,0,0,0,0,0,0,0,0,0,0,0,0,0,0,0,0,0,0,0,0,0,0,0,0,0,0
0,0,0,0,0,0,0,0,0,0,0,0,0,0,0,0,0,0,0,0,0,0,0,0,0,0,0,0,0,0,0,0,0,0,0,0,0,0,0,0,0,0,0,0,0,0,0,0
endlayer

layer
0,0,0,0,0,0,0,0,0,0,0,0,0,0,0,0,0,0,0,0,0,0,0,0,0,0,0,0,0,0,0,0,0,0,0,0,0,0,0,0,0,0,0,0,0,0,0,0
0,0,0,0,0,0,0,0,0,0,0,0,0,0,0,0,0,0,0,0,0,0,0,0,0,0,0,0,0,0,0,0,0,0,0,0,0,0,0,0,0,0,0,0,0,0,0,0
0,0,0,0,0,71,71,5,5,0,0,5,2,2,2,2,5,0,71,5,2,71,0,0,71,96,96,5,88,71,5,5,71,0,0,0,0,0,0,0,0,0,0,0,0,0,0,0
0,0,0,71,2,2,2,2,2,5,5,5,2,2,2,2,2,2,2,2,2,2,2,2,2,2,2,3,3,3,3,3,3,71,0,0,0,0,0,0,0,0,0,0,0,0,0,0
0,0,0,2,2,2,2,2,2,2,2,2,2,2,2,2,2,2,2,2,2,2,2,2,2,2,2,3,3,3,3,6,3,3,71,0,0,0,0,0,0,0,0,0,0,0,0,0
0,0,24,24,24,2,2,2,2,2,2,2,2,2,2,2,2,2,2,2,2,2,2,2,2,2,2,2,2,6,6,6,3,3,71,0,0,0,0,0,0,0,0,0,0,0,0,0
0,0,71,24,24,24,2,2,2,2,2,2,2,2,2,2,2,2,2,2,2,2,2,2,2,2,2,2,2,2,2,2,3,3,71,87,0,0,0,0,0,0,0,0,0,0,0,0
0,0,0,71,24,24,5,5,5,5,2,2,2,2,2,2,2,2,2,2,2,2,2,2,2,2,2,2,2,2,2,2,2,3,71,87,0,0,0,0,0,0,0,25,0,0,0,0
0,0,0,0,24,5,5,5,5,5,2,2,2,2,2,2,2,2,2,2,2,2,2,2,2,2,2,2,2,2,2,2,2,3,71,0,0,0,0,0,0,0,0,0,0,0,0,0
0,0,0,0,24,5,5,5,5,5,5,2,2,2,2,2,2,10,10,10,2,2,2,2,2,2,2,2,2,2,2,2,2,2,71,0,0,0,0,0,0,0,0,0,0,0,0,0
0,0,0,0,24,5,5,5,5,5,2,2,2,2,2,10,10,10,10,10,2,2,2,2,2,2,2,2,2,2,2,2,17,2,0,0,0,0,0,0,0,0,0,0,0,0,0,0
0,0,0,0,0,0,71,2,2,2,2,2,2,2,2,10,10,17,10,2,2,2,2,2,2,2,2,2,2,2,2,2,2,6,71,0,0,0,0,0,0,0,0,0,0,0,0,0
0,0,0,0,0,0,0,71,2,2,2,2,2,2,2,2,10,17,2,2,2,2,2,2,2,2,19,2,47,2,2,2,2,2,5,0,0,0,0,0,0,0,0,0,0,0,0,0
0,0,0,0,0,0,0,0,2,2,2,2,2,2,2,2,2,2,2,2,2,2,2,2,5,5,2,2,2,2,2,2,2,2,2,0,0,0,0,0,0,0,0,0,0,0,0,0
0,0,0,0,0,0,0,0,6,6,2,6,2,2,2,2,2,2,2,2,2,2,2,5,5,77,77,77,77,77,2,2,2,2,71,0,0,0,0,0,0,0,0,0,0,0,0,0
0,0,0,0,0,0,0,85,24,6,6,6,2,2,2,2,2,2,2,2,2,2,2,5,5,5,0,0,0,4,2,2,2,2,71,0,0,0,0,0,0,0,0,0,0,0,0,0
0,0,0,0,0,0,0,0,85,6,2,2,2,2,2,2,2,2,2,2,2,2,2,5,5,5,0,0,0,19,2,2,2,2,88,0,0,0,0,0,0,0,0,0,0,0,0,0
0,0,0,0,0,0,0,0,87,2,2,2,2,2,2,2,2,2,2,2,2,2,2,2,5,4,0,0,0,19,2,2,2,2,5,0,0,0,0,0,0,0,0,0,0,0,0,0
0,0,0,0,0,0,0,0,11,2,2,2,2,2,2,2,16,16,16,2,2,2,2,2,5,4,4,4,3,3,2,2,2,2,2,0,0,0,0,0,0,0,0,0,0,0,0,0
0,0,0,0,0,0,0,24,11,11,2,2,2,2,2,16,16,16,16,16,2,2,2,2,4,3,3,3,3,3,2,2,2,2,71,0,0,0,0,0,0,0,0,0,0,0,0,0
0,0,0,0,0,0,0,19,11,11,11,11,11,2,16,16,16,16,16,2,2,2,2,2,3,3,3,3,3,3,2,2,2,2,85,0,0,0,0,0,0,0,0,0,0,0,0,0
0,0,0,0,0,0,0,24,24,11,11,11,11,2,16,16,16,16,16,2,2,2,2,2,3,3,3,3,3,17,2,2,2,2,71,0,0,0,0,0,0,0,0,0,0,0,0,0
0,0,0,0,0,0,0,0,24,11,2,11,2,16,16,16,16,16,2,2,2,2,2,3,3,3,3,3,2,2,2,2,2,11,11,0,0,0,0,0,0,0,0,0,0,0,0,0
0,0,0,0,0,0,0,0,24,2,2,2,2,16,16,16,16,2,2,2,2,2,2,3,3,3,3,2,2,2,2,11,11,11,71,0,0,0,0,0,0,0,0,0,0,0,0,0
0,0,0,0,0,0,0,0,24,2,24,2,2,16,16,16,16,2,2,2,2,2,2,3,3,2,2,2,2,11,11,11,11,11,71,0,0,0,0,0,0,0,0,0,0,0,0,0
0,0,0,0,0,0,0,0,24,2,2,2,16,16,16,16,2,2,2,2,2,2,2,2,2,2,2,2,11,11,11,11,11,11,71,0,0,0,0,0,0,0,0,0,0,0,0,0
0,0,0,0,0,0,0,0,24,2,2,2,2,2,2,2,2,2,2,2,2,2,2,2,2,2,2,2,11,11,11,11,11,11,11,0,0,0,0,0,0,0,0,0,0,0,0,0
0,0,0,0,0,0,0,0,24,2,2,2,2,2,2,2,2,2,2,2,2,2,2,2,2,2,2,2,2,2,2,2,2,2,71,0,0,0,0,0,0,0,0,0,0,0,0,0
0,0,0,0,0,0,0,0,2,2,2,11,11,11,2,2,2,2,2,2,2,2,2,2,2,2,2,2,2,2,2,24,24,24,0,0,0,0,0,0,0,0,0,0,0,0,0,0
0,0,0,0,0,0,0,0,2,2,11,11,11,11,2,2,2,2,2,2,2,4,2,2,2,2,2,2,2,24,24,0,0,0,0,0,0,0,0,0,0,0,0,0,0,0,0,0
0,0,0,0,0,0,5,24,2,2,11,11,11,11,2,2,2,2,2,2,2,2,2,2,2,2,2,2,24,0,0,0,0,0,0,0,0,0,0,0,0,0,0,0,0,0,0,0
0,0,0,0,0,71,24,2,2,11,11,11,11,11,2,2,2,2,2,2,2,2,2,2,2,2,5,71,0,0,0,0,0,0,0,0,0,0,0,0,0,0,0,0,0,0,0,0
0,0,0,0,24,24,2,2,2,11,11,11,11,2,2,2,2,2,2,2,2,2,2,2,24,71,71,92,0,0,0,0,0,0,0,0,0,0,0,0,0,0,0,0,0,0,0,0
0,0,0,92,71,71,71,2,11,11,11,11,2,2,2,2,2,2,2,2,24,24,24,24,24,0,0,0,0,0,0,0,0,0,0,0,0,0,0,0,0,0,0,0,0,0,0,0
0,0,0,0,0,0,0,0,0,0,24,71,0,0,0,0,0,0,0,0,0,0,0,0,0,0,0,0,0,0,0,0,0,0,0,0,0,0,0,0,0,0,0,0,0,0,0,0
0,0,0,0,0,0,0,0,0,0,0,0,0,0,0,0,0,0,0,0,0,0,0,0,0,0,0,0,0,0,0,0,0,0,0,0,0,0,0,0,0,0,0,0,0,0,0,0
0,0,0,0,0,0,0,0,0,0,0,0,0,0,0,0,0,0,0,0,0,0,0,0,0,0,0,0,0,0,0,0,0,0,0,0,0,0,0,0,0,0,0,0,0,0,0,0
endlayer

layer
0,0,0,0,0,0,0,0,0,0,0,0,0,0,0,0,0,0,0,0,0,0,0,0,0,0,0,0,0,0,0,0,0,0,0,0,0,0,0,0,0,0,0,0,0,0,0,0
0,0,0,0,0,0,0,0,0,0,0,0,0,0,0,0,0,0,0,0,0,0,0,0,0,0,0,0,0,0,0,0,0,0,0,0,0,0,0,0,0,0,0,0,0,0,0,0
0,0,0,0,0,0,0,71,71,0,0,71,71,0,0,96,71,0,0,71,0,0,0,0,0,71,5,71,0,0,71,71,0,0,0,0,0,0,0,0,0,0,0,0,0,0,0,0
0,0,0,0,71,2,2,2,6,6,6,6,6,2,2,96,96,96,96,96,96,96,96,96,96,96,3,3,3,24,24,3,3,0,0,0,0,0,0,0,0,0,0,0,0,0,0,0
0,0,0,71,2,2,2,2,2,6,6,6,6,2,2,96,96,96,96,96,96,96,96,96,96,3,3,3,3,24,24,24,3,3,0,0,0,0,0,0,0,0,0,0,0,0,0,0
0,0,0,24,24,2,2,2,2,2,6,6,2,2,2,96,96,96,96,96,96,96,96,96,96,96,3,3,3,24,24,96,3,3,94,0,0,0,0,0,0,0,0,0,0,0,0,0
0,0,0,71,24,24,2,2,2,2,2,2,2,2,2,2,96,96,96,96,96,96,96,96,96,96,96,96,96,96,2,2,3,3,85,0,0,0,0,0,0,0,0,0,0,0,0,0
0,0,0,0,24,24,5,5,5,2,2,2,2,2,2,2,2,96,96,96,96,96,96,96,96,96,96,96,96,2,2,2,2,3,85,0,0,0,0,0,0,0,0,25,0,0,0,0
0,0,0,0,24,5,5,5,5,5,2,2,2,2,2,2,2,2,96,96,96,96,96,96,96,96,96,2,2,17,2,2,2,3,88,0,0,0,0,0,0,0,0,0,0,0,0,0
0,0,0,0,24,5,5,5,5,5,2,2,2,2,2,2,2,2,2,2,2,2,2,2,2,2,2,2,2,17,17,2,2,2,0,0,0,0,0,0,0,0,0,0,0,0,0,0
0,0,0,0,5,5,5,5,5,5,2,2,2,2,2,2,2,2,2,2,2,2,2,2,2,2,2,2,2,2,2,2,2,2,0,0,0,0,0,0,0,0,0,0,0,0,0,0
0,0,0,0,0,0,0,2,2,2,2,2,2,2,2,2,2,2,2,2,2,2,2,2,2,2,2,2,2,2,2,17,2,2,0,0,0,0,0,0,0,0,0,0,0,0,0,0
0,0,0,0,0,0,0,83,2,2,2,2,2,2,2,2,17,2,2,2,2,2,2,2,5,2,19,19,0,2,2,2,2,2,71,0,0,0,0,0,0,0,0,0,0,0,0,0
0,0,0,0,0,0,0,0,2,2,2,2,2,2,2,2,2,2,2,2,2,2,2,5,5,5,2,2,2,2,2,2,2,2,71,0,0,0,0,0,0,0,0,0,0,0,0,0
0,0,0,0,0,0,0,0,6,6,6,6,6,2,2,2,2,2,2,2,2,2,2,5,5,5,5,19,4,4,4,2,2,16,0,0,0,0,0,0,0,0,0,0,0,0,0,0
0,0,0,0,0,0,0,0,24,6,6,6,6,2,2,2,2,2,2,2,2,2,2,5,5,19,19,61,17,4,4,4,16,16,0,0,0,0,0,0,0,0,0,0,0,0,0,0
0,0,0,0,0,0,0,85,85,6,6,6,2,2,2,2,2,2,2,2,2,2,2,5,5,19,27,0,0,61,4,2,16,16,0,0,0,0,0,0,0,0,0,0,0,0,0,0
0,0,0,0,0,0,0,0,87,6,2,2,2,2,2,2,2,2,2,2,2,2,2,5,5,19,0,0,0,61,4,2,2,2,71,0,0,0,0,0,0,0,0,0,0,0,0,0
0,0,0,0,0,0,0,87,87,16,2,2,2,2,2,2,2,16,2,2,2,2,2,5,5,25,0,0,43,25,2,2,2,2,71,0,0,0,0,0,0,0,0,0,0,0,0,0
0,0,0,0,0,0,0,87,24,16,2,2,2,2,2,2,16,16,16,2,2,2,2,5,4,4,4,4,2,2,2,2,2,2,0,0,0,0,0,0,0,0,0,0,0,0,0,0
0,0,0,0,0,0,19,24,0,16,16,2,2,2,2,16,16,16,16,2,2,2,2,2,5,3,3,3,2,2,2,2,2,2,0,0,0,0,0,0,0,0,0,0,0,0,0,0
