
# Created by Ruins mod version 15.0 Ingame Parser
# authoring Player: SunsOfOld

weight=100
embed_into_distance=1
acceptable_target_blocks=
unacceptable_target_blocks=flowing_water,water,flowing_lava,lava
dimensions=3,11,11
allowable_overhang=0
max_leveling=3
leveling_buffer=0
preserve_water=0
preserve_lava=0
uniqueMinDistance=1000000
preventRotation=1

rule1=0,100,preserveBlock
rule2=0,100,BiomesOPlenty:newBopDirt-0
rule3=0,100,ExtrabiomesXL:terrain_blocks2-0
rule4=0,100,minecraft:dirt-0
rule5=0,100,chisel:grimstone-12
rule6=0,100,chisel:tyrian-13
rule7=0,100,BiomesOPlenty:ash-0
rule8=0,100,chisel:diamond_block-5
rule9=0,100,BiomesOPlenty:leaves1-7
rule10=0,100,minecraft:web-0
rule11=0,100,BiomesOPlenty:mushrooms-2
rule12=0,100,ExtrabiomesXL:grass-3
rule13=0,100,ExtrabiomesXL:grass-4
rule14=0,100,BiomesOPlenty:leaves1-15
rule15=0,100,BiomesOPlenty:plants-5
rule16=0,100,BiomesOPlenty:mushrooms-5
rule17=0,100,chisel:road_line-0
rule18=0,100,chisel:road_line-2
rule19=0,100,harvestcraft:pamcandleDeco16-5

layer
2,4,2,2,4,2,2,4,3,2,1
3,2,4,2,2,3,2,2,2,2,3
2,2,2,5,5,5,5,5,2,4,2
4,3,5,5,6,7,6,5,5,3,4
2,2,5,6,7,5,7,6,5,2,1
2,3,5,7,5,8,5,7,5,2,2
4,2,5,6,7,5,7,6,5,3,4
2,2,5,5,6,7,6,5,5,2,3
3,4,2,5,5,5,5,5,2,4,2
4,2,3,2,2,4,4,2,2,3,4
1,4,2,2,3,1,2,4,2,2,1
endlayer

layer
12,12,13,14,14,13,12,11,10,9,0
10,12,16,15,12,0,12,13,12,15,9
12,13,12,17,17,17,17,17,13,11,12
11,0,17,17,19,17,18,17,17,0,12
15,0,17,19,18,18,18,18,17,13,10
12,0,17,17,18,0,18,17,17,15,12
11,12,17,18,18,18,18,19,17,0,16
12,13,17,17,18,17,19,17,17,12,0
0,16,12,17,17,17,17,17,13,11,12
12,9,9,15,12,11,12,15,12,9,12
9,9,13,12,10,0,12,12,13,12,9
endlayer

layer
0,0,0,0,0,0,0,0,0,0,0
0,0,0,0,0,0,0,0,0,0,0
0,0,0,0,0,0,0,0,0,0,0
0,0,0,0,0,0,0,0,0,0,0
0,0,0,0,0,0,0,0,0,0,0
0,0,0,0,0,0,0,0,0,0,0
0,0,0,0,0,0,0,0,0,0,0
0,0,0,0,0,0,0,0,0,0,0
0,0,0,0,0,0,0,0,0,0,0
0,9,0,0,0,0,0,0,0,0,0
0,0,0,0,0,0,0,0,0,0,0
endlayer

