
# Created by Ruins mod version 15.0 Ingame Parser
# authoring Player: SunsOfOld

weight=100
embed_into_distance=1
acceptable_target_blocks=
unacceptable_target_blocks=flowing_water,water,flowing_lava,lava
dimensions=10,11,11
allowable_overhang=0
max_leveling=4
leveling_buffer=0
preserve_water=0
preserve_lava=0
uniqueMinDistance=1000000
preventRotation=1

rule1=0,100,preserveBlock
rule2=0,100,preserveBlock
rule3=0,100,chisel:fantasyblock2-14
rule4=0,100,BiomesOPlenty:planks-6
rule5=0,100,BiomesOPlenty:foliage-2
rule6=0,100,plantmegapack:plainsReedCanaryGrass-0
rule7=0,100,BiomesOPlenty:leaves1-5
rule8=0,100,plantmegapack:flowerDaisy-4
rule9=0,100,plantmegapack:flowerDaisy-3
rule10=0,100,ExtrabiomesXL:door_baldcypress-2
rule11=0,100,plantmegapack:plainsPrairieBrome-0
rule12=0,100,plantmegapack:flowerDelphinium-0
rule13=0,100,plantmegapack:flowerDaisy-7
rule14=0,100,minecraft:hay_block-8
rule15=0,100,BiomesOPlenty:leaves1-13
rule16=0,100,IInventory;harvestcraft:quern;minecraft:stone_pressure_plate#7#0#1+harvestcraft:flourItem#8#0#2-3
rule17=0,100,minecraft:hay_block-0
rule18=0,100,minecraft:hay_block-4
rule19=0,100,MobSpawner:Mouse
rule20=0,100,plantmegapack:flowerWildDaffodil-0
rule21=0,100,ExtrabiomesXL:door_baldcypress-8
rule22=0,100,BiomesOPlenty:logs2-2
rule23=0,100,IInventory;minecraft:chest;VeganOption:seedSunflower#4#0#4+minecraft:wheat_seeds#4#0#7+minecraft:wheat_seeds#2#0#11+minecraft:golden_hoe#{display:{Lore:[0:"Refined",],},}#0#13+minecraft:wheat_seeds#1#0#15+minecraft:wheat_seeds#3#0#19+VeganOption:fertilizer#4#0#22-4
rule24=0,100,CarpentersBlocks:blockCarpentersLadder-4
rule25=0,100,chisel:stained_glass_pane_magenta-12
rule26=0,100,BiomesOPlenty:woodenSingleSlab1-14
rule27=0,100,IInventory;minecraft:chest;VeganOption:burlap#2#0#8+ExtrabiomesXL:extrabiomes.scarecrow#1#0#11+BiomesOPlenty:dartBlower#{RepairCost:2,display:{Name:"Cracked Pipe Flute",},}#0#13+BiomesOPlenty:scytheIron#1#0#15+VeganOption:burlap#3#0#18-3
rule28=0,100,BiomesOPlenty:logs2-10
rule29=0,100,BiomesOPlenty:logs2-6
rule30=0,100,chisel:glowstone-4
rule31=0,100,BiomesOPlenty:woodenSingleSlab1-6

layer
1,2,1,2,1,3,1,2,1,2,1
2,1,1,1,3,3,3,1,2,1,2
1,2,1,3,3,3,3,3,1,2,1
2,1,3,3,3,4,4,3,3,1,1
1,3,3,4,4,4,4,4,3,3,1
2,3,3,4,4,4,4,4,3,3,1
1,3,3,4,4,4,4,4,3,3,2
2,1,3,3,4,4,4,3,3,2,1
1,2,1,3,3,3,3,3,1,1,2
1,1,1,1,3,3,3,1,1,1,1
2,1,2,1,2,1,2,1,2,1,2
endlayer

layer
5,0,6,0,8,0,7,7,6,0,5
0,11,5,7,3,10,3,7,7,9,0
5,0,7,3,0,0,0,3,12,0,11
0,13,3,0,0,0,0,0,3,7,6
15,3,0,14,0,0,0,0,0,3,7
0,3,14,18,17,0,0,0,16,3,7
15,3,19,17,18,14,0,0,0,3,0
15,7,3,0,0,0,0,0,3,7,13
13,15,7,3,0,18,0,3,15,15,0
11,12,15,15,3,3,3,20,5,6,15
0,5,0,6,0,7,15,5,0,5,0
endlayer

layer
0,0,0,0,0,0,0,0,0,0,0
0,0,0,0,3,21,3,7,0,0,0
0,0,7,22,0,0,0,22,0,0,0
0,0,22,0,0,0,0,0,22,7,0
0,3,0,0,0,0,0,0,0,3,0
0,3,18,0,0,0,0,0,0,3,0
0,3,23,18,14,0,0,0,0,3,0
0,7,22,24,0,0,0,0,22,7,0
0,0,7,22,0,0,0,22,15,0,0
0,0,0,15,3,3,3,0,0,0,0
0,0,0,0,0,7,0,0,0,0,0
endlayer

layer
0,0,0,0,0,0,0,0,0,0,0
0,0,0,0,3,3,3,0,0,0,0
0,0,0,22,0,0,0,22,0,0,0
0,0,22,0,0,0,0,0,22,0,0
0,3,0,0,0,0,0,0,0,3,0
0,25,0,0,0,0,0,0,0,25,0
0,3,26,26,26,26,26,26,26,3,0
0,0,22,24,26,26,26,26,22,7,0
0,0,7,22,26,26,26,22,0,0,0
0,0,0,0,3,3,3,0,0,0,0
0,0,0,0,0,0,0,0,0,0,0
endlayer

layer
0,0,0,0,0,0,0,0,0,0,0
0,0,0,0,3,25,3,0,0,0,0
0,0,0,22,0,0,0,22,0,0,0
0,0,22,0,0,0,0,0,22,0,0
0,3,0,0,0,0,0,0,0,3,0
0,3,0,0,0,0,0,0,0,3,0
0,3,0,14,17,0,0,0,0,3,0
0,0,22,0,0,18,17,0,22,0,0
0,0,0,22,0,27,0,22,0,0,0
0,0,0,0,3,3,3,0,0,0,0
0,0,0,0,0,0,0,0,0,0,0
endlayer

layer
0,0,0,0,0,0,0,0,0,0,0
0,0,0,0,3,3,3,0,0,0,0
0,0,0,22,0,0,0,22,0,0,0
0,0,22,0,0,0,0,0,22,0,0
0,3,0,0,0,0,0,0,0,3,0
28,28,28,28,28,28,28,28,28,28,28
0,3,0,0,18,0,0,0,0,3,0
0,0,22,0,0,0,0,0,22,0,0
0,0,0,22,0,0,0,22,0,0,0
0,0,0,0,3,3,3,0,0,0,0
0,0,0,0,0,0,0,0,0,0,0
endlayer

layer
0,0,0,0,0,29,0,0,0,0,0
0,0,0,0,3,29,3,0,0,0,0
0,0,26,22,0,29,0,22,26,0,0
0,0,22,0,0,29,0,0,22,0,0
0,3,0,0,0,29,0,0,0,3,0
0,3,0,0,0,30,0,0,0,3,0
0,3,0,0,0,29,0,0,0,3,0
0,0,22,0,0,29,0,0,22,0,0
0,0,26,22,0,29,0,22,26,0,0
0,0,0,0,3,29,3,0,0,0,0
0,0,0,0,0,29,0,0,0,0,0
endlayer

layer
0,0,0,0,0,0,0,0,0,0,0
0,0,0,0,31,31,31,0,0,0,0
0,0,0,31,26,26,26,31,0,0,0
0,0,31,26,0,0,0,26,31,0,0
0,31,26,0,0,0,0,0,26,31,0
0,31,26,0,0,0,0,0,26,31,0
0,31,26,0,0,0,0,0,26,31,0
0,0,31,26,0,0,0,26,31,0,0
0,0,0,31,26,26,26,31,0,0,0
0,0,0,0,31,31,31,0,0,0,0
0,0,0,0,0,0,0,0,0,0,0
endlayer

layer
0,0,0,0,0,0,0,0,0,0,0
0,0,0,0,0,0,0,0,0,0,0
0,0,0,0,0,0,0,0,0,0,0
0,0,0,0,31,31,31,0,0,0,0
0,0,0,31,31,26,31,31,0,0,0
0,0,0,31,26,0,26,31,0,0,0
0,0,0,31,31,26,31,31,0,0,0
0,0,0,0,31,31,31,0,0,0,0
0,0,0,0,0,0,0,0,0,0,0
0,0,0,0,0,0,0,0,0,0,0
0,0,0,0,0,0,0,0,0,0,0
endlayer

layer
0,0,0,0,0,0,0,0,0,0,0
0,0,0,0,0,0,0,0,0,0,0
0,0,0,0,0,0,0,0,0,0,0
0,0,0,0,0,0,0,0,0,0,0
0,0,0,0,0,0,0,0,0,0,0
0,0,0,0,0,31,0,0,0,0,0
0,0,0,0,0,0,0,0,0,0,0
0,0,0,0,0,0,0,0,0,0,0
0,0,0,0,0,0,0,0,0,0,0
0,0,0,0,0,0,0,0,0,0,0
0,0,0,0,0,0,0,0,0,0,0
endlayer

