
# Created by Ruins mod version 14.9 Ingame Parser
# authoring Player: SunsOfOld

weight=100
embed_into_distance=3
acceptable_target_blocks=
unacceptable_target_blocks=flowing_water,water,flowing_lava,lava
dimensions=7,8,10
allowable_overhang=0
max_leveling=3
leveling_buffer=0
preserve_water=0
preserve_lava=0
uniqueMinDistance=1000000
preventRotation=1

rule1=0,100,preserveBlock
rule2=0,100,BiomesOPlenty:newBopDirt-1
rule3=0,100,BiomesOPlenty:mud-0
rule4=0,100,BiomesOPlenty:newBopDirt-0
rule5=0,100,BiomesOPlenty:colorizedLeaves2-12
rule6=0,100,GardenStuff:moss_brick-6
rule7=0,100,dendrology:leaves2-15
rule8=0,100,BiomesOPlenty:foliage-11
rule9=0,100,plantmegapack:wetlandsCattails-0
rule10=0,100,BiomesOPlenty:colorizedLeaves2-4
rule11=0,100,dendrology:leaves2-7
rule12=0,100,plantmegapack:wetlandsClubrush-0
rule13=0,100,plantmegapack:wetlandsFloweringRush-0
rule14=0,100,plantmegapack:wetlandsCommonRush-0
rule15=0,100,GardenStuff:moss_brick-2
rule16=0,100,dendrology:sslab0-5
rule17=0,100,dendrology:sslab0-13
rule18=0,100,GardenStuff:lattice-3
rule19=0,100,GardenStuff:moss_brick-1
rule20=0,100,GardenStuff:moss_brick-0

layer
1,1,1,1,1,1,1,1,1,1
1,1,1,2,1,1,2,1,1,1
1,1,1,3,2,2,3,1,1,1
1,1,1,1,3,2,1,1,1,1
1,1,1,2,2,2,2,1,1,1
1,1,1,1,3,2,1,3,1,1
1,1,1,1,1,1,1,1,1,1
1,1,1,1,1,1,1,1,1,1
endlayer

layer
1,1,4,0,1,3,1,5,4,3
1,6,3,5,0,4,7,4,6,1
1,1,4,7,9,8,7,2,1,1
1,1,1,2,5,10,3,1,1,1
1,1,3,10,11,10,7,2,1,1
1,6,1,2,0,11,10,10,6,1
1,1,1,1,0,2,0,1,1,1
1,1,10,4,1,0,1,11,4,1
endlayer

layer
4,10,13,0,0,0,0,0,12,0
1,6,7,0,0,9,5,7,6,2
1,2,10,7,0,0,7,2,1,2
1,1,3,7,0,0,5,2,1,4
1,2,10,0,0,0,7,7,2,1
1,6,2,11,0,0,0,10,6,1
4,1,10,0,0,8,0,0,10,4
1,0,0,14,0,0,0,0,8,0
endlayer

layer
8,0,11,0,0,0,0,0,0,0
11,15,7,11,0,0,7,5,15,14
0,16,7,5,7,0,0,17,16,16
16,16,17,0,0,0,5,17,16,12
16,11,17,0,0,0,7,17,16,0
0,15,10,0,0,0,0,11,15,7
12,0,0,0,0,0,0,0,0,13
0,0,0,0,0,0,0,0,0,0
endlayer

layer
0,0,0,0,0,0,0,0,0,0
18,19,7,0,0,0,0,7,19,18
0,0,0,16,16,16,7,0,0,0
0,0,0,16,16,16,16,0,0,0
0,11,0,16,16,0,16,0,0,0
18,19,0,11,0,0,0,11,19,18
0,0,0,0,0,0,0,0,0,0
0,0,0,0,0,0,0,0,0,0
endlayer

layer
0,0,0,0,0,0,0,0,0,0
18,20,18,18,18,18,18,18,20,18
0,0,0,0,0,0,0,0,0,0
0,0,0,0,0,0,0,0,0,0
0,0,0,0,0,0,0,0,0,0
18,20,18,18,18,18,18,18,20,18
0,0,0,0,0,0,0,0,0,0
0,0,0,0,0,0,0,0,0,0
endlayer

layer
0,0,0,0,0,0,0,0,0,0
0,18,18,0,0,0,0,18,18,0
0,0,0,0,0,0,0,0,0,0
0,0,0,0,0,0,0,0,0,0
0,0,0,0,0,0,0,0,0,0
0,18,18,0,0,0,0,18,18,0
0,0,0,0,0,0,0,0,0,0
0,0,0,0,0,0,0,0,0,0
endlayer

