
# Created by Ruins mod version 15.0 Ingame Parser
# authoring Player: SunsOfOld

weight=100
embed_into_distance=6
acceptable_target_blocks=
unacceptable_target_blocks=flowing_water,water,flowing_lava,lava
dimensions=16,17,8
allowable_overhang=0
max_leveling=4
leveling_buffer=0
preserve_water=0
preserve_lava=0
uniqueMinDistance=1000000
preventRotation=1

rule1=0,100,preserveBlock
rule2=0,100,minecraft:bedrock-0
rule3=0,100,minecraft:redstone_wire-15
rule4=0,100,minecraft:powered_repeater-0
rule5=0,100,minecraft:unlit_redstone_torch-2
rule6=0,100,minecraft:powered_repeater-2
rule7=0,100,CommandBlock:/testfor @p[r=10]:@
rule8=0,100,minecraft:redstone_wire-14
rule9=0,100,minecraft:unpowered_comparator-1
rule10=0,100,minecraft:redstone_wire-13
rule11=0,100,minecraft:unpowered_repeater-1
rule12=0,100,minecraft:redstone_wire-12
rule13=0,100,minecraft:unpowered_repeater-0
rule14=0,100,CommandBlock:/setblock ~ ~ ~ 152:@
rule15=0,100,CommandBlock:/summon Villager ~ ~8 ~ {CustomName:"Rosso",CustomNameVisible:1,Profession:0,Offers:{Recipes:[{rewardExp:0b,maxUses:2147483647,uses:0,buy:{id:349,Damage:3,Count:4},sell:{id:4200,Count:1}},{rewardExp:0b,maxUses:2147483647,uses:0,buy:{id:349,Damage:3,Count:3},sell:{id:351,Damage:3,Count:1}},{rewardExp:0b,maxUses:2147483647,uses:0,buy:{id:349,Damage:3,Count:3},sell:{id:4152,Damage:5,Count:1}},{rewardExp:0b,maxUses:2147483647,uses:0,buy:{id:349,Damage:3,Count:2},sell:{id:351,Damage:5,Count:1}},{rewardExp:0b,maxUses:2147483647,uses:0,buy:{id:349,Damage:3,Count:1},sell:{id:4152,Damage:7,Count:2}},{rewardExp:0b,maxUses:2147483647,uses:0,buy:{id:349,Damage:3,Count:1},sell:{id:5169,Count:1}}]}}:@
rule16=0,100,minecraft:redstone_wire-0
rule17=0,100,CarpentersBlocks:blockCarpentersLadder-2
rule18=0,100,BiomesOPlenty:magicStairs-4
rule19=0,100,BiomesOPlenty:magicStairs-5
rule20=0,100,BiomesOPlenty:planks-5
rule21=0,100,BiomesOPlenty:magicStairs-0
rule22=0,100,BiomesOPlenty:magicStairs-1
rule23=0,100,dendrology:sslab1-10
rule24=0,100,dendrology:stairs10-5
rule25=0,100,dendrology:stairs10-7
rule26=0,100,dendrology:stairs10-6
rule27=0,100,BiomesOPlenty:woodenSingleSlab1-5
rule28=0,100,dendrology:stairs10-4
rule29=0,100,dendrology:ewcaly_planks-7
rule30=0,100,ExtrabiomesXL:door_rainboweucalyptus-4
rule31=0,100,IInventory;BiblioWoodsEBXL:BiblioWoodSeat;minecraft:carpet#1#2#0-8
rule32=0,100,IInventory;VeganOption:composter;minecraft:stick#1#0#0+minecraft:leaves#1#0#1+minecraft:stick#1#0#2+minecraft:stick#1#0#3+minecraft:stick#1#0#4+minecraft:stick#1#0#5+minecraft:stick#1#0#6+minecraft:leaves#1#0#7+minecraft:stick#1#0#8+minecraft:stick#1#0#9+VeganOption:compost#1#0#10+minecraft:stick#1#0#11+minecraft:leaves#1#0#12+minecraft:stick#1#0#13+minecraft:leaves#1#0#15+minecraft:stick#1#0#16+minecraft:stick#1#0#17+minecraft:stick#1#0#18+minecraft:leaves#1#0#19+minecraft:stick#1#0#20+minecraft:leaves#1#0#21+minecraft:stick#1#0#22+minecraft:stick#1#0#23+minecraft:stick#1#0#24+minecraft:leaves#1#0#26-4
rule33=0,100,IInventory;BiblioWoodsBoP:BiblioWoodtable;VeganOption:frozenBubble#1#0#0-7
rule34=0,100,chisel:carpet-4
rule35=0,100,chisel:carpet-14
rule36=0,100,dendrology:stairs4-0
rule37=0,100,chisel:carpet_block-9
rule38=0,100,dendrology:dslab1-2
rule39=0,100,chisel:technical-5
rule40=0,100,chisel:stained_glass_yellow-9
rule41=0,100,ExtrabiomesXL:door_rainboweucalyptus-8
rule42=0,100,GardenTrees:thin_log_fence-2
rule43=0,100,BiblioCraft:BiblioLantern-13
rule44=0,100,chisel:carpet_block-2
rule45=0,100,chisel:carpet_block-1
rule46=0,100,dendrology:stairs4-5
rule47=0,100,dendrology:stairs4-7
rule48=0,100,dendrology:stairs4-6
rule49=0,100,chisel:carpet-1
rule50=0,100,dendrology:stairs4-2
rule51=0,100,dendrology:stairs4-3
rule52=0,100,chisel:valentines-4

layer
1,1,1,1,1,1,1,1
1,1,1,1,1,1,1,1
1,1,1,1,1,1,1,1
1,1,1,1,1,1,1,1
1,1,1,1,1,1,1,1
1,1,1,1,1,1,1,1
1,1,1,1,1,1,1,1
1,1,1,1,1,1,1,1
1,1,1,1,1,1,1,1
1,1,1,1,1,1,1,1
1,1,1,1,1,1,1,1
1,1,1,1,2,1,1,1
1,1,1,1,2,1,1,1
1,1,1,1,1,1,1,1
1,1,1,1,1,1,1,1
1,1,1,1,1,1,1,1
1,1,1,1,0,1,1,1
endlayer

layer
1,1,1,1,1,1,1,1
1,1,1,1,1,1,1,1
1,1,1,1,1,1,1,1
1,1,1,1,1,1,1,1
1,1,1,1,1,1,1,1
1,1,1,1,1,1,1,1
1,1,1,1,1,1,1,1
1,1,1,1,1,1,1,1
1,1,1,1,1,1,1,1
1,2,2,2,2,2,2,2
1,2,2,2,2,2,2,2
1,2,2,2,0,2,2,2
1,2,2,2,2,2,2,2
1,2,2,2,2,2,2,2
1,2,2,2,2,2,2,2
1,2,2,2,2,2,2,2
1,1,1,1,1,1,1,1
endlayer

layer
1,1,1,1,1,1,1,1
1,1,1,1,1,1,1,1
1,1,1,1,1,1,1,1
1,1,1,1,1,1,1,1
1,1,1,1,1,1,1,1
1,1,1,1,1,1,1,1
1,1,1,1,1,1,1,1
1,1,1,1,1,1,1,1
1,1,1,1,1,1,1,1
1,2,2,2,2,2,2,2
1,2,0,0,0,0,0,2
1,2,7,6,5,4,3,2
1,2,9,0,2,6,8,2
1,2,11,0,0,0,10,2
1,2,16,15,14,13,12,2
1,2,2,2,2,2,2,2
1,1,1,1,1,1,1,1
endlayer

layer
1,1,1,1,1,1,1,1
1,1,1,1,1,1,1,1
1,1,1,1,1,1,1,1
1,1,1,1,1,1,1,1
1,1,1,1,1,1,1,1
1,1,1,1,1,1,1,1
1,1,1,1,1,1,1,1
1,1,1,1,1,1,1,1
1,1,1,1,1,1,1,1
1,2,2,2,2,2,2,2
1,2,0,0,0,0,0,2
1,2,0,0,0,0,0,2
1,2,0,0,0,0,0,2
1,2,0,0,0,0,0,2
1,2,0,16,16,0,0,2
1,2,2,2,2,2,2,2
1,1,1,1,1,1,1,1
endlayer

layer
1,1,1,1,1,1,1,1
1,1,1,1,1,1,1,1
1,1,1,1,1,1,1,1
1,1,1,1,1,1,1,1
1,1,1,1,1,1,1,1
1,1,1,1,1,1,1,1
1,1,1,1,1,1,1,1
1,1,1,1,1,1,1,1
1,1,1,1,1,1,1,1
1,2,2,2,2,2,2,2
1,2,2,2,2,2,2,2
1,2,2,2,2,2,2,2
1,2,2,2,2,2,2,2
1,2,2,2,2,2,2,2
1,2,2,2,2,2,2,2
1,2,2,2,2,2,2,2
1,1,1,1,1,1,1,1
endlayer

layer
1,1,1,1,1,1,1,1
1,1,1,1,1,1,1,1
1,1,1,1,1,1,1,1
1,1,1,1,1,1,1,1
1,1,1,1,1,1,1,1
1,1,1,1,1,1,1,1
1,1,1,1,1,1,1,1
1,1,1,1,1,1,1,1
1,1,1,1,1,1,1,1
1,1,1,1,1,1,1,1
1,1,1,1,1,1,1,1
1,1,1,1,1,1,1,1
1,1,1,1,1,1,1,1
1,1,1,1,1,1,1,1
1,1,1,1,1,1,1,1
1,1,1,1,1,1,1,1
1,1,1,1,1,1,1,1
endlayer

layer
0,0,0,17,0,0,0,0
0,0,0,0,0,0,0,0
0,0,0,0,0,0,0,0
0,0,0,0,0,0,0,0
18,0,0,0,0,0,18,0
19,0,0,0,0,0,19,0
0,0,0,0,0,0,0,0
0,0,0,0,0,0,0,0
0,0,0,0,0,0,0,0
0,0,0,0,0,0,0,0
18,0,0,0,0,0,18,0
20,0,0,0,0,0,20,0
19,0,0,0,0,0,19,0
0,0,0,0,0,0,0,0
0,0,0,0,0,0,0,0
0,0,0,0,0,0,0,0
0,0,0,0,0,0,0,0
endlayer

layer
0,0,0,0,0,0,0,0
0,0,0,17,0,0,0,0
0,0,0,0,0,0,0,0
0,0,0,0,0,0,0,0
21,0,0,0,0,0,21,0
22,0,0,0,0,0,22,0
0,0,0,0,0,0,0,0
0,0,0,0,0,0,0,0
0,0,0,0,0,0,0,0
0,0,0,0,0,0,0,0
21,0,0,0,0,0,21,0
20,0,0,0,0,0,20,0
22,0,0,0,0,0,22,0
0,0,0,0,0,0,0,0
0,0,0,0,0,0,0,0
0,0,0,0,0,0,0,0
0,0,0,0,0,0,0,0
endlayer

layer
0,0,0,0,0,0,0,0
0,0,0,0,0,0,0,0
0,23,23,17,23,23,0,0
0,23,23,23,23,23,0,0
0,24,24,24,24,24,0,0
0,26,23,23,23,25,0,0
0,26,23,23,23,25,0,0
0,26,23,23,23,25,0,0
0,26,23,23,23,25,0,0
0,26,23,23,23,25,0,0
0,26,23,23,23,25,0,0
27,26,23,23,23,25,27,0
0,26,28,28,28,25,0,0
0,0,0,0,0,0,0,0
0,0,0,0,0,0,0,0
0,0,0,0,0,0,0,0
0,0,0,0,0,0,0,0
endlayer

layer
0,0,0,0,0,0,0,0
0,0,0,0,0,0,0,0
0,0,0,0,0,0,0,0
0,29,29,30,29,29,0,0
0,29,32,0,31,29,0,0
0,29,0,0,33,29,0,0
0,29,0,0,31,29,0,0
0,29,34,34,34,29,0,0
0,29,34,35,34,29,0,0
0,29,34,35,34,29,0,0
0,29,34,34,34,29,0,0
0,29,0,0,0,29,0,0
0,29,36,36,36,29,0,0
0,29,37,37,37,29,0,0
0,38,37,37,37,38,0,0
0,38,38,38,38,38,0,0
0,0,0,0,0,0,0,0
endlayer

layer
0,0,0,0,0,0,0,0
0,0,0,0,0,0,0,0
0,0,0,0,0,0,0,0
0,39,40,41,40,39,0,0
0,40,0,0,0,40,0,0
0,39,0,0,0,39,0,0
0,39,0,0,0,39,0,0
0,40,0,0,0,40,0,0
0,39,0,0,0,39,0,0
0,40,0,0,0,40,0,0
0,39,0,17,0,39,0,0
0,39,0,0,0,39,0,0
0,40,0,0,0,40,0,0
0,39,0,0,0,39,0,0
0,0,0,0,0,0,0,0
0,42,0,0,0,42,0,0
0,0,0,0,0,0,0,0
endlayer

layer
0,0,0,0,0,0,0,0
0,0,0,0,0,0,0,0
0,0,0,0,0,0,0,0
0,39,40,40,40,39,0,0
0,40,0,0,0,40,0,0
0,39,0,0,0,39,0,0
0,39,0,0,0,39,0,0
0,40,0,0,0,40,0,0
0,39,0,0,0,39,0,0
0,40,0,0,0,40,0,0
0,39,0,17,0,39,0,0
0,39,0,0,0,39,0,0
0,40,0,0,0,40,0,0
0,39,0,0,0,39,0,0
0,0,0,0,0,0,0,0
0,42,0,0,0,42,0,0
0,0,0,0,0,0,0,0
endlayer

layer
0,0,0,0,0,0,0,0
0,0,0,0,0,0,0,0
0,0,0,0,0,0,0,0
0,29,29,29,29,29,0,0
0,29,0,43,0,29,0,0
0,29,0,0,0,29,0,0
0,29,0,0,0,29,0,0
0,29,0,0,0,29,0,0
0,29,43,0,43,29,0,0
0,29,0,0,0,29,0,0
0,29,0,17,0,29,0,0
0,29,44,44,44,29,0,0
0,29,44,44,44,29,0,0
0,29,44,44,44,29,0,0
0,29,45,45,45,29,0,0
0,42,0,0,0,42,0,0
0,43,0,0,0,43,0,0
endlayer

layer
0,0,0,0,0,0,0,0
0,0,0,0,0,0,0,0
0,0,0,0,0,0,0,0
0,36,36,36,36,36,0,0
0,46,46,46,46,46,0,0
0,48,0,0,0,47,0,0
0,48,0,0,0,47,0,0
0,48,0,0,0,47,0,0
0,48,0,0,0,47,0,0
0,48,0,0,0,47,0,0
0,48,0,0,0,47,0,0
0,48,0,0,0,47,0,0
0,48,0,0,0,47,0,0
0,48,0,0,0,47,0,0
0,48,49,49,49,47,0,0
0,46,46,46,46,46,0,0
0,0,0,0,0,0,0,0
endlayer

layer
0,0,0,0,0,0,0,0
0,0,0,0,0,0,0,0
0,0,0,0,0,0,0,0
0,0,0,0,0,0,0,0
0,51,36,36,36,50,0,0
0,51,48,46,46,50,0,0
0,51,48,0,47,50,0,0
0,51,48,0,47,50,0,0
0,51,48,0,47,50,0,0
0,51,48,0,47,50,0,0
0,51,48,0,47,50,0,0
0,51,48,0,47,50,0,0
0,51,48,0,47,50,0,0
0,51,48,0,47,50,0,0
0,51,48,43,47,50,0,0
0,51,29,52,29,50,0,0
0,0,0,0,0,0,0,0
endlayer

layer
0,0,0,0,0,0,0,0
0,0,0,0,0,0,0,0
0,0,0,0,0,0,0,0
0,0,0,0,0,0,0,0
0,0,0,0,0,0,0,0
0,0,51,36,50,0,0,0
0,0,51,29,50,0,0,0
0,0,51,29,50,0,0,0
0,0,51,29,50,0,0,0
0,0,51,29,50,0,0,0
0,0,51,29,50,0,0,0
0,0,51,29,50,0,0,0
0,0,51,29,50,0,0,0
0,0,51,29,50,0,0,0
0,0,51,29,50,0,0,0
0,0,51,29,50,0,0,0
0,0,0,0,0,0,0,0
endlayer

