
# Created by Ruins mod version 15.0 Ingame Parser
# authoring Player: SunsOfOld

weight=100
embed_into_distance=4
acceptable_target_blocks=
unacceptable_target_blocks=flowing_water,water,flowing_lava,lava
dimensions=18,13,11
allowable_overhang=0
max_leveling=4
leveling_buffer=0
preserve_water=0
preserve_lava=0
uniqueMinDistance=1000000
preventRotation=1

rule1=0,100,preserveBlock
rule2=0,100,UndergroundBiomes:metamorphicCobblestone-1
rule3=0,100,IInventory;minecraft:chest;minecraft:skull#1#2#2+minecraft:skull#1#3#13+minecraft:skull#1#1#19+minecraft:skull#1#4#24-5
rule4=0,100,minecraft:web-0
rule5=0,100,minecraft:dirt-7
rule6=0,100,minecraft:gravel-0
rule7=0,100,minecraft:dirt-0
rule8=0,100,minecraft:stone_slab-3
rule9=0,100,minecraft:log-0
rule10=0,100,minecraft:log-4
rule11=0,100,minecraft:planks-0
rule12=0,100,minecraft:log-8
rule13=0,100,Skull:1:0-1
rule14=0,100,minecraft:leaves-0
rule15=0,100,minecraft:leaves-8
rule16=0,100,minecraft:leaves-12
rule17=0,100,minecraft:trapdoor-2
rule18=0,100,Skull:0:8-1
rule19=0,100,harvestcraft:pamApple-2
rule20=0,100,harvestcraft:pamApple-1

layer
1,1,1,1,1,1,1,1,1,1,1
1,1,1,1,1,1,1,1,1,1,1
1,1,1,1,1,1,1,1,1,1,1
1,1,1,1,1,2,2,2,2,1,1
1,1,1,1,1,2,3,2,2,1,1
1,1,1,1,1,2,2,2,2,1,1
1,1,1,1,1,2,2,2,2,1,1
1,1,1,1,1,2,2,2,2,1,1
1,1,1,1,1,1,1,1,1,1,1
1,1,1,1,1,1,1,1,1,1,1
1,1,1,1,1,1,1,1,1,1,1
1,1,1,1,1,1,1,1,1,1,1
1,1,1,1,1,1,1,1,1,1,1
endlayer

layer
1,1,1,1,1,1,1,1,1,1,1
1,1,1,1,1,1,1,1,1,1,1
1,1,1,1,1,1,1,1,1,1,1
1,1,1,1,1,2,2,2,2,1,1
1,1,1,1,1,2,4,0,2,1,1
1,1,1,1,1,2,0,0,2,1,1
1,1,1,1,1,2,4,0,2,1,1
1,1,1,1,1,2,2,2,2,1,1
1,1,1,1,1,1,1,1,1,1,1
1,1,1,1,1,1,1,1,1,1,1
1,1,1,1,1,1,1,1,1,1,1
1,1,1,1,1,1,1,1,1,1,1
1,1,1,1,1,1,1,1,1,1,1
endlayer

layer
1,1,1,1,1,1,1,1,1,1,1
1,1,1,1,1,1,1,1,1,1,1
1,1,1,1,1,1,1,1,1,1,1
1,1,1,1,1,2,2,2,2,1,1
1,1,1,1,1,2,0,0,2,1,1
1,1,1,1,1,2,0,0,2,1,1
1,1,1,1,1,2,0,0,2,1,1
1,1,1,1,1,2,2,2,2,1,1
1,1,1,1,1,1,1,1,1,1,1
1,1,1,1,1,1,1,1,1,1,1
1,1,1,1,1,1,1,1,1,1,1
1,1,1,1,1,1,1,1,1,1,1
1,1,1,1,1,1,1,1,1,1,1
endlayer

layer
1,1,1,1,1,1,1,1,1,1,1
1,1,1,1,1,1,1,1,1,1,1
1,1,1,1,1,5,1,1,1,1,1
1,1,1,1,1,2,2,2,2,5,1
1,1,1,1,1,2,0,4,2,1,1
1,1,1,1,1,2,0,0,2,1,1
1,1,1,1,5,6,0,4,2,1,1
1,1,7,1,6,2,2,2,2,1,5
1,1,1,6,6,6,1,1,1,1,1
1,1,1,1,1,6,1,1,1,1,1
1,1,1,1,1,1,5,1,1,1,1
1,1,1,1,1,1,1,1,1,1,5
1,1,1,1,1,1,1,1,1,1,1
endlayer

layer
0,0,0,0,0,0,0,0,0,0,0
0,0,0,0,0,0,0,0,0,0,0
0,0,0,0,0,9,8,8,8,0,0
0,0,0,0,0,2,2,2,2,9,10
0,0,0,0,0,2,11,11,2,11,0
0,0,0,0,0,2,11,11,2,12,12
0,0,0,0,9,0,4,11,2,0,0
0,0,9,0,0,0,2,2,2,0,0
0,0,0,0,0,0,0,10,13,4,0
0,0,0,0,0,0,0,0,9,0,0
0,0,0,0,0,0,9,0,0,0,0
0,0,0,0,0,0,0,0,0,9,0
0,0,0,0,0,0,0,0,0,0,0
endlayer

layer
0,0,0,0,14,14,14,0,0,0,0
0,0,0,14,14,14,14,0,0,0,0
0,0,0,14,14,9,14,0,0,0,0
0,0,0,14,14,9,15,0,9,9,0
0,0,0,14,14,11,14,0,16,0,0
0,0,0,0,0,11,0,0,12,0,0
0,0,0,0,9,4,17,0,11,0,0
0,0,9,0,0,9,11,0,9,0,0
0,0,0,0,0,0,0,0,4,0,0
0,0,0,0,0,0,0,0,14,14,14
0,0,0,0,0,0,9,0,15,14,15
0,0,0,0,0,0,0,0,14,9,16
0,0,0,0,0,0,0,0,14,14,14
endlayer

layer
0,0,0,0,14,14,14,0,0,0,0
0,0,0,14,14,14,14,0,0,0,0
0,0,0,14,14,9,14,0,0,16,0
0,0,0,14,14,9,14,4,9,9,16
0,0,0,14,14,11,0,0,16,16,0
0,0,0,0,0,18,0,0,0,0,0
0,0,0,0,9,0,0,0,11,0,0
0,0,9,0,0,9,0,0,9,4,0
0,0,0,0,0,14,15,14,14,0,0
0,0,0,0,14,14,14,14,15,14,14
0,0,0,0,14,14,9,15,15,14,15
0,0,0,0,14,14,15,14,14,9,16
0,0,0,0,14,14,14,14,15,14,15
endlayer

layer
0,0,0,0,0,0,0,0,0,0,0
0,0,0,0,0,14,14,0,14,14,0
0,0,0,0,14,9,14,14,14,14,14
0,0,0,0,0,9,14,14,9,9,14
0,0,0,0,0,0,0,14,15,15,0
0,0,0,0,0,0,0,0,15,14,14
19,0,0,0,9,4,0,0,11,14,14
0,0,9,0,0,9,0,0,9,15,0
19,19,0,0,14,15,15,15,14,15,14
0,0,20,0,14,15,14,14,14,15,15
0,0,0,0,14,14,9,14,15,14,14
0,0,0,0,14,14,14,14,14,9,16
0,0,0,0,14,14,14,14,0,0,14
endlayer

layer
0,0,0,0,0,0,0,0,0,0,0
0,0,0,0,0,14,0,0,14,14,0
0,0,0,0,14,14,14,14,14,15,14
0,0,0,0,0,14,9,9,14,9,15
0,0,0,0,0,9,4,15,14,14,0
0,14,14,14,0,10,0,0,14,14,0
14,14,14,14,9,12,14,0,9,14,14
14,14,9,10,14,14,9,4,15,15,0
14,14,14,10,14,15,14,15,14,15,15
0,14,14,14,0,0,14,14,14,15,15
0,0,0,0,0,15,9,15,0,0,14
0,0,0,0,0,0,15,14,0,14,14
0,0,0,0,0,0,0,0,0,0,14
endlayer

layer
0,0,0,0,0,0,0,0,0,0,0
0,0,0,0,0,0,0,0,0,0,0
0,0,0,0,0,0,0,0,14,14,14
0,0,0,0,0,0,15,0,14,9,15
0,0,0,0,14,14,10,9,0,15,0
0,14,14,10,14,14,9,4,0,0,0
14,14,14,14,9,14,9,9,0,0,15
14,14,9,14,14,14,14,14,14,15,0
14,14,14,14,14,14,15,14,14,15,0
14,14,10,14,14,14,14,15,14,0,0
0,14,10,14,0,14,15,15,0,0,0
0,0,14,0,0,0,14,0,0,0,0
0,0,0,0,0,0,0,0,0,0,0
endlayer

layer
0,0,0,0,0,0,0,0,0,0,0
0,0,0,0,0,0,0,0,0,0,0
0,0,0,0,0,14,14,14,0,14,0
0,0,14,0,14,14,14,15,14,14,14
0,14,10,14,14,14,14,15,15,14,0
0,0,14,10,10,14,14,14,14,0,0
0,14,14,14,9,14,14,14,0,0,15
0,14,9,14,14,14,14,15,15,15,0
0,14,14,14,14,14,14,15,15,0,0
14,14,14,14,14,14,15,14,0,0,0
14,14,14,14,14,14,15,14,0,0,0
14,14,14,14,14,0,0,0,0,0,0
0,14,14,14,0,0,0,0,0,0,0
endlayer

layer
0,0,0,0,0,0,0,0,0,0,0
0,0,0,0,0,0,0,0,0,0,0
0,14,14,14,0,14,14,14,0,0,0
14,14,14,14,14,14,14,15,14,0,0
14,14,10,14,10,14,14,14,14,0,0
14,14,14,14,10,14,15,14,15,0,0
0,14,14,14,9,14,14,15,0,0,0
0,14,14,10,10,14,15,0,0,0,0
0,14,14,10,14,10,14,14,0,0,0
14,14,14,14,14,14,14,0,0,0,0
14,14,14,14,14,0,0,0,0,0,0
14,14,14,14,14,0,0,0,0,0,0
0,14,14,14,0,0,0,0,0,0,0
endlayer

layer
0,0,0,0,0,0,0,0,0,0,0
0,0,0,0,14,0,0,0,0,0,0
0,14,14,14,10,14,0,0,0,0,0
14,14,14,14,10,14,15,0,0,0,0
14,14,14,14,14,14,15,15,0,0,0
14,14,14,14,14,14,14,0,0,0,0
0,14,14,14,9,14,15,0,0,0,0
0,0,0,10,14,14,14,14,0,0,0
0,0,14,14,14,14,14,14,0,0,0
0,14,10,14,14,14,14,14,0,0,0
0,14,14,14,14,14,15,0,0,0,0
0,0,14,0,0,0,0,0,0,0,0
0,0,0,0,0,0,0,0,0,0,0
endlayer

layer
0,0,0,14,14,14,0,0,0,0,0
0,0,14,14,14,14,14,0,0,0,0
0,14,14,14,14,14,14,0,0,0,0
14,14,14,14,14,14,14,0,0,0,0
14,14,14,14,14,14,0,0,0,0,0
14,14,14,14,14,14,0,0,0,0,0
0,14,14,14,9,14,15,0,0,0,0
0,14,14,14,10,14,14,15,0,0,0
14,14,10,14,10,14,14,14,0,0,0
14,14,14,14,14,14,15,15,0,0,0
14,14,14,14,14,14,15,0,0,0,0
0,14,14,14,0,0,0,0,0,0,0
0,0,0,0,0,0,0,0,0,0,0
endlayer

layer
0,0,0,14,14,14,0,0,0,0,0
0,0,14,14,14,14,14,0,0,0,0
0,0,14,14,14,14,14,0,0,0,0
0,0,14,14,14,14,14,0,0,0,0
0,14,14,14,14,14,0,0,0,0,0
0,0,14,0,14,0,0,0,0,0,0
0,14,14,14,9,14,0,0,0,0,0
14,14,14,14,14,14,14,0,0,0,0
14,14,14,14,14,14,14,0,0,0,0
14,14,14,14,14,14,14,0,0,0,0
14,14,14,14,14,14,0,0,0,0,0
0,14,14,14,0,0,0,0,0,0,0
0,0,0,0,0,0,0,0,0,0,0
endlayer

layer
0,0,0,0,0,0,0,0,0,0,0
0,0,0,0,14,0,0,0,0,0,0
0,0,0,14,14,14,0,0,0,0,0
0,0,0,0,14,0,0,0,0,0,0
0,0,0,14,14,14,0,0,0,0,0
0,0,14,14,14,14,14,0,0,0,0
0,14,14,14,14,14,14,0,0,0,0
14,14,14,14,14,14,14,0,0,0,0
14,14,14,14,14,14,14,0,0,0,0
14,14,14,14,14,14,14,0,0,0,0
0,14,14,14,14,14,0,0,0,0,0
0,0,0,0,0,0,0,0,0,0,0
0,0,0,0,0,0,0,0,0,0,0
endlayer

layer
0,0,0,0,0,0,0,0,0,0,0
0,0,0,0,0,0,0,0,0,0,0
0,0,0,0,0,0,0,0,0,0,0
0,0,0,0,0,0,0,0,0,0,0
0,0,0,14,14,14,0,0,0,0,0
0,0,14,14,14,14,14,0,0,0,0
0,0,14,14,14,14,14,0,0,0,0
0,0,14,14,14,14,14,0,0,0,0
0,14,14,14,14,14,0,0,0,0,0
0,0,14,0,14,0,0,0,0,0,0
0,0,0,0,0,0,0,0,0,0,0
0,0,0,0,0,0,0,0,0,0,0
0,0,0,0,0,0,0,0,0,0,0
endlayer

layer
0,0,0,0,0,0,0,0,0,0,0
0,0,0,0,0,0,0,0,0,0,0
0,0,0,0,0,0,0,0,0,0,0
0,0,0,0,0,0,0,0,0,0,0
0,0,0,0,0,0,0,0,0,0,0
0,0,0,0,14,0,0,0,0,0,0
0,0,0,14,14,14,0,0,0,0,0
0,0,0,0,14,0,0,0,0,0,0
0,0,0,0,0,0,0,0,0,0,0
0,0,0,0,0,0,0,0,0,0,0
0,0,0,0,0,0,0,0,0,0,0
0,0,0,0,0,0,0,0,0,0,0
0,0,0,0,0,0,0,0,0,0,0
endlayer

