
# Created by Ruins mod version 15.0 Ingame Parser
# authoring Player: SunsOfOld

weight=100
embed_into_distance=5
acceptable_target_blocks=
unacceptable_target_blocks=flowing_water,water,flowing_lava,lava
dimensions=19,33,23
allowable_overhang=0
max_leveling=14
leveling_buffer=0
preserve_water=0
preserve_lava=0
uniqueMinDistance=1000000
preventRotation=1

rule1=0,100,minecraft:sponge-0
rule2=0,100,minecraft:bedrock-0
rule3=0,100,CommandBlock:/setblock ~0 ~5 ~0 mob_spawner 0 replace {SpawnCount:1,SpawnRange:4,maxNearbyEntities:6,Delay:20,MinSpawnDelay:60,MaxSpawnDelay:120,EntityId:CaveSpider} :@
rule4=0,100,minecraft:redstone_wire-0
rule5=0,100,minecraft:unpowered_repeater-3
rule6=0,100,CommandBlock:/summon Spider ~ ~5 ~ {Silent:1,Riding:{id:"CaveSpider",Silent:1,Riding:{id:"FallingSand",Block:0,Time:0.9,DropItem:0,Riding:{id:"Spider",Silent:1,Riding:{id:"CaveSpider",Silent:1}}}}}:@
rule7=0,100,CommandBlock:/setblock ~ ~ ~ 152:@
rule8=0,100,CommandBlock:/setblock ~0 ~8 ~0 mob_spawner 0 replace {SpawnCount:1,SpawnRange:4,maxNearbyEntities:6,Delay:20,MinSpawnDelay:60,MaxSpawnDelay:120,EntityId:Spider,SpawnData:{ActiveEffects:[{Id:14,Amplifier:1,Duration:999999}]}} :@
rule9=0,100,chisel:factoryblock-10
rule10=0,100,chisel:factoryblock-11
rule11=0,100,chisel:factoryblock-9
rule12=0,100,chisel:woolen_clay-0
rule13=0,100,minecraft:quartz_block-1
rule14=0,100,chisel:tyrian-3
rule15=0,100,chisel:tyrian-2
rule16=0,100,minecraft:quartz_stairs-0
rule17=0,100,minecraft:quartz_stairs-3
rule18=0,100,UndergroundBiomes:sedimentaryStoneHalfSlab-4
rule19=0,100,minecraft:quartz_stairs-2
rule20=0,100,BiomesOPlenty:newBopDirt-1
rule21=0,100,chisel:tyrian-13
rule22=0,100,BiomesOPlenty:newBopDirt-0
rule23=0,100,BiomesOPlenty:logs1-6
rule24=0,100,UndergroundBiomes:sedimentaryStoneHalfSlab-12
rule25=0,100,chisel:redstone_block-1
rule26=0,100,chisel:redstone_block-2
rule27=0,100,GardenStuff:metal_block-0
rule28=0,100,GardenStuff:stone_block-0
rule29=0,100,chisel:redstone_block-12
rule30=0,100,minecraft:nether_brick_stairs-0
rule31=0,100,minecraft:quartz_stairs-1
rule32=0,100,GardenStuff:lattice-2
rule33=0,100,minecraft:quartz_stairs-6
rule34=0,100,minecraft:quartz_stairs-7
rule35=0,100,minecraft:web-0
rule36=0,100,MobSpawner:CaveSpider
rule37=0,100,IInventory;minecraft:trapped_chest;minecraft:web#1#0#0+minecraft:web#1#0#1+minecraft:web#1#0#2+minecraft:web#1#0#3+minecraft:web#1#0#4+minecraft:web#1#0#5+minecraft:web#1#0#6+minecraft:web#1#0#7+minecraft:web#1#0#8+minecraft:web#1#0#9+minecraft:web#1#0#10+minecraft:web#1#0#11+minecraft:web#1#0#12+BiomesOPlenty:ancientStaff#{RepairCost:3,ench:[0:{id:21s,lvl:3s,},1:{id:34s,lvl:3s,},2:{id:16s,lvl:5s,},3:{id:20s,lvl:2s,},4:{id:19s,lvl:2s,},],display:{Name:"Widow Maker",},}#4#13+minecraft:web#1#0#14+minecraft:web#1#0#15+minecraft:web#1#0#16+minecraft:web#1#0#17+minecraft:web#1#0#18+minecraft:web#1#0#19+minecraft:web#1#0#20+minecraft:web#1#0#21+minecraft:web#1#0#22+minecraft:web#1#0#23+minecraft:web#1#0#24+minecraft:web#1#0#25+minecraft:web#1#0#26-4
rule38=0,100,BiomesOPlenty:logs1-10
rule39=0,100,BiomesOPlenty:logs1-2
rule40=2,100,minecraft:redstone_torch-1
rule41=0,100,MobSpawner:Spider
rule42=0,100,BiomesOPlenty:darkStairs-5
rule43=0,100,BiomesOPlenty:darkStairs-7
rule44=0,100,BiomesOPlenty:darkStairs-6
rule45=0,100,BiomesOPlenty:darkStairs-4
rule46=0,100,chisel:factoryblock-5
rule47=0,100,minecraft:lit_redstone_lamp-0
rule48=0,100,chisel:stained_glass_brown-12
rule49=0,100,BiomesOPlenty:darkStairs-1
rule50=0,100,BiomesOPlenty:darkStairs-3
rule51=0,100,BiomesOPlenty:darkStairs-2
rule52=0,100,BiomesOPlenty:darkStairs-0
rule53=0,100,chisel:factoryblock-4

layer
1,1,1,1,1,1,1,1,1,1,1,1,1,1,1,1,1,1,1,1,1,1,1
1,1,1,1,1,1,1,1,1,1,1,1,1,1,1,1,1,1,1,1,1,1,1
1,1,2,1,1,1,1,1,1,1,1,1,1,1,1,1,1,1,1,1,2,1,1
1,1,1,1,1,1,1,1,1,1,1,1,1,1,1,1,1,1,1,1,2,1,1
1,1,1,1,1,1,1,1,1,1,1,1,1,1,1,1,1,1,1,1,1,1,1
1,1,1,1,1,1,1,1,1,1,1,1,1,1,1,1,1,1,1,1,1,1,1
1,1,1,1,1,1,1,1,1,1,1,1,1,1,1,1,1,1,1,1,1,1,1
1,1,1,1,1,1,1,1,1,1,1,1,1,1,1,1,1,1,1,1,1,1,1
1,1,1,1,1,1,1,1,1,1,1,1,1,1,1,1,1,1,1,1,1,1,1
1,1,1,1,1,1,1,1,1,1,1,1,1,1,1,1,1,1,1,1,1,1,1
1,1,1,1,1,1,1,1,1,1,1,1,1,1,1,1,1,1,1,1,1,1,1
1,1,1,1,1,1,1,1,1,1,1,1,1,1,1,1,1,1,1,1,1,1,1
1,1,1,1,1,1,1,1,1,1,1,1,1,1,1,1,1,1,1,1,1,1,1
1,1,1,1,1,1,1,1,1,1,1,1,1,1,1,1,1,1,1,1,1,1,1
1,1,1,1,1,1,1,1,1,1,1,1,1,1,1,1,1,1,1,1,1,1,1
1,1,1,1,1,1,1,1,1,1,1,1,1,1,1,1,1,1,1,1,1,1,1
1,1,1,1,1,1,1,1,1,1,1,1,1,1,1,1,1,1,1,1,1,1,1
1,1,1,1,1,1,1,1,1,1,1,1,1,1,1,1,1,1,1,1,1,1,1
1,1,1,1,1,1,1,1,1,1,1,1,1,1,1,1,1,1,1,1,1,1,1
1,1,1,1,1,1,1,1,1,1,1,1,1,1,1,1,1,1,1,1,1,1,1
1,1,1,1,1,1,1,1,1,1,1,1,1,1,1,1,1,1,1,1,1,1,1
1,1,1,1,1,1,1,1,1,1,1,1,1,1,1,1,1,1,1,1,1,1,1
1,1,1,1,1,1,1,1,1,1,1,1,1,1,1,1,1,1,1,1,1,1,1
1,1,1,1,1,1,1,1,1,1,1,1,1,1,1,1,1,1,1,1,1,1,1
1,1,1,1,1,1,1,1,1,1,1,1,1,1,1,1,1,1,1,1,1,1,1
1,1,1,1,1,1,1,1,1,1,1,1,1,1,1,1,1,1,1,1,1,1,1
1,1,1,1,1,1,1,1,1,1,1,1,1,1,1,1,1,1,1,1,1,1,1
1,1,1,1,1,1,1,1,1,1,1,1,1,1,1,1,1,1,1,1,1,1,1
1,1,1,1,1,1,1,1,1,1,1,1,1,1,1,1,1,1,1,1,1,1,1
1,1,1,1,1,1,1,1,1,1,1,1,1,1,1,1,1,1,1,1,1,1,1
1,1,1,1,1,1,1,1,1,1,1,1,1,1,1,1,1,1,1,1,1,1,1
1,1,1,1,1,1,1,1,1,1,1,1,1,1,1,1,1,1,1,1,1,1,1
1,1,1,1,1,1,1,1,1,1,1,1,1,1,1,1,1,1,1,1,1,1,1
endlayer

layer
1,1,1,1,1,1,1,1,1,1,1,1,1,1,1,1,1,1,1,1,1,1,1
1,1,2,1,1,1,1,1,1,1,1,1,1,1,1,1,1,1,1,1,2,1,1
1,2,3,2,1,1,1,1,1,1,1,1,1,1,1,1,1,1,2,2,3,2,1
1,1,2,2,1,1,1,1,1,1,1,1,1,1,1,1,1,1,2,2,2,1,1
1,1,1,2,1,1,1,1,1,1,1,1,1,1,1,1,1,1,2,2,1,1,1
1,1,1,2,1,1,1,1,1,1,1,1,1,1,1,1,1,1,2,2,1,1,1
1,1,1,2,2,2,2,2,2,2,2,2,2,2,2,2,2,2,2,2,1,1,1
1,1,1,1,1,1,1,1,1,1,1,2,1,1,1,1,1,1,1,1,1,1,1
1,1,1,1,1,1,1,1,1,1,1,2,1,1,1,1,1,1,1,1,1,1,1
1,1,1,1,1,1,1,1,1,1,1,2,1,1,1,1,1,1,1,1,1,1,1
1,1,1,1,1,1,1,1,1,1,1,2,1,1,1,1,1,1,1,1,1,1,1
1,1,1,1,1,1,1,1,1,1,1,2,1,1,1,1,1,1,1,1,1,1,1
1,1,1,1,1,1,1,1,1,1,1,2,1,1,1,1,1,1,1,1,1,1,1
1,1,1,1,1,1,1,1,1,1,1,2,1,1,1,1,1,1,1,1,1,1,1
1,1,1,1,1,1,1,1,1,1,1,2,1,1,1,1,1,1,1,1,1,1,1
1,1,1,1,1,1,1,1,1,1,1,2,1,1,1,1,1,1,1,1,1,1,1
1,1,1,1,1,1,1,1,1,1,1,2,1,1,1,1,1,1,1,1,1,1,1
1,1,1,1,1,1,1,1,1,1,1,2,1,1,1,1,1,1,1,1,1,1,1
1,1,1,1,1,1,1,1,1,1,1,2,1,1,1,1,1,1,1,1,1,1,1
1,1,1,1,1,1,1,1,1,1,1,2,1,1,1,1,1,1,1,1,1,1,1
1,1,1,1,1,1,1,1,1,1,1,2,1,1,1,1,1,1,1,1,1,1,1
1,1,1,1,1,1,1,1,1,1,1,2,1,1,1,1,1,1,1,1,1,1,1
1,1,1,1,1,1,1,1,1,1,1,2,1,1,1,1,1,1,1,1,1,1,1
1,1,1,1,1,1,1,1,1,1,1,2,1,1,1,1,1,1,1,1,1,1,1
1,1,1,1,1,1,1,1,1,1,1,2,1,1,1,1,1,1,1,1,1,1,1
1,1,1,1,1,1,1,1,1,1,1,2,1,1,1,1,1,1,1,1,1,1,1
1,1,1,1,1,1,1,1,1,1,1,2,1,1,1,1,1,1,1,1,1,1,1
1,1,1,1,1,1,1,1,1,1,1,1,1,1,1,1,1,1,1,1,1,1,1
1,1,1,1,1,1,1,1,1,1,1,1,1,1,1,1,1,1,1,1,1,1,1
1,1,1,1,1,1,1,1,1,1,1,1,1,1,1,1,1,1,1,1,1,1,1
1,1,1,1,1,1,1,1,1,1,1,1,1,1,1,1,1,1,1,1,1,1,1
1,1,1,1,1,1,1,1,1,1,1,1,1,1,1,1,1,1,1,1,1,1,1
1,1,1,1,1,1,1,1,1,1,1,1,1,1,1,1,1,1,1,1,1,1,1
endlayer

layer
1,1,1,1,1,1,1,1,1,1,1,1,1,1,1,1,1,1,1,1,1,1,1
1,1,2,2,1,1,1,1,1,1,1,1,1,1,1,1,1,1,2,2,2,1,1
1,2,4,4,2,1,1,1,1,1,1,1,1,1,1,1,1,2,2,4,4,2,1
1,1,2,4,2,1,1,1,1,1,1,1,1,1,1,1,1,2,2,4,2,2,1
1,1,2,4,2,1,1,1,1,1,1,1,1,1,1,1,1,2,2,4,2,1,1
1,1,2,4,2,2,2,2,2,2,2,2,2,2,2,2,2,2,0,4,2,1,1
1,1,2,4,4,4,4,4,4,4,4,4,4,4,4,4,4,4,4,4,2,1,1
1,1,1,2,2,2,2,2,2,2,2,4,2,2,2,2,2,2,2,2,2,1,1
1,1,1,1,1,1,1,1,1,1,2,5,2,1,1,1,1,1,1,1,1,1,1
1,1,1,1,1,1,1,1,1,1,2,4,2,1,1,1,1,1,1,1,1,1,1
1,1,1,1,1,1,1,1,1,1,2,4,2,1,1,1,1,1,1,1,1,1,1
1,1,1,1,1,1,1,1,1,1,2,4,2,1,1,1,1,1,1,1,1,1,1
1,1,1,1,1,1,1,1,1,1,2,4,2,1,1,1,1,1,1,1,1,1,1
1,1,1,1,1,1,1,1,1,1,2,4,2,1,1,1,1,1,1,1,1,1,1
1,1,1,1,1,1,1,1,1,1,2,4,2,1,1,1,1,1,1,1,1,1,1
1,1,1,1,1,1,1,1,1,1,2,4,2,1,1,1,1,1,1,1,1,1,1
1,1,1,1,1,1,1,1,1,1,2,4,2,1,1,1,1,1,1,1,1,1,1
1,1,1,1,1,1,1,1,1,1,2,6,2,1,1,1,1,1,1,1,1,1,1
1,1,1,1,1,1,1,1,1,1,2,7,2,1,1,1,1,1,1,1,1,1,1
1,1,1,1,1,1,1,1,1,1,2,4,2,1,1,1,1,1,1,1,1,1,1
1,1,1,1,1,1,1,1,1,1,2,4,2,1,1,1,1,1,1,1,1,1,1
1,1,1,1,1,1,1,1,1,1,2,4,2,1,1,1,1,1,1,1,1,1,1
1,1,1,1,1,1,1,1,1,1,2,4,2,1,1,1,1,1,1,1,1,1,1
1,1,1,1,1,1,1,1,1,1,2,5,2,1,1,1,1,1,1,1,1,1,1
1,1,1,1,1,1,1,1,1,1,2,2,2,1,1,1,1,1,1,1,1,1,1
1,1,1,1,1,1,1,1,1,1,2,5,2,1,1,1,1,1,1,1,1,1,1
1,1,1,1,1,1,1,1,1,1,2,2,2,1,1,1,1,1,1,1,1,1,1
1,1,1,1,1,1,1,1,1,1,1,2,1,1,1,1,1,1,1,1,1,1,1
1,1,1,1,1,1,1,1,1,1,1,2,1,1,1,1,1,1,1,1,1,1,1
1,1,1,1,1,1,1,1,1,1,1,1,1,1,1,1,1,1,1,1,1,1,1
1,1,1,1,1,1,1,1,1,1,1,1,1,1,1,1,1,1,1,1,1,1,1
1,1,1,1,1,1,1,1,1,1,1,1,1,1,1,1,1,1,1,1,1,1,1
1,1,1,1,1,1,1,1,1,1,1,1,1,1,1,1,1,1,1,1,1,1,1
endlayer

layer
1,1,1,1,1,1,1,1,1,1,1,1,1,1,1,1,1,1,1,1,1,1,1
1,1,2,1,1,1,1,1,1,1,1,1,1,1,1,1,1,1,1,1,2,1,1
1,2,8,2,1,1,1,1,1,1,1,1,1,1,1,1,1,1,2,2,8,2,1
1,2,4,0,2,1,1,1,1,1,1,1,1,1,1,1,1,2,0,0,4,2,1
1,2,0,0,2,1,1,1,1,1,1,1,1,1,1,1,1,2,0,0,4,2,1
1,1,2,0,2,2,2,2,2,2,2,2,2,2,2,2,2,2,0,0,2,1,1
1,1,2,0,0,0,0,0,0,0,0,0,0,0,0,0,0,0,0,0,2,1,1
1,1,1,2,2,2,2,2,2,2,2,0,2,2,2,2,2,2,2,2,2,1,1
1,1,1,1,1,1,1,1,1,1,2,0,2,1,1,1,1,1,1,1,1,1,1
1,1,1,1,1,1,1,1,1,1,2,0,2,1,1,1,1,1,1,1,1,1,1
1,1,1,1,1,1,1,1,1,1,2,0,2,1,1,1,1,1,1,1,1,1,1
1,1,1,1,1,1,1,1,1,1,2,0,2,1,1,1,1,1,1,1,1,1,1
1,1,1,1,1,1,1,1,1,1,2,0,2,1,1,1,1,1,1,1,1,1,1
1,1,1,1,1,1,1,1,1,1,2,0,2,1,1,1,1,1,1,1,1,1,1
1,1,1,1,1,1,1,1,1,1,2,0,2,1,1,1,1,1,1,1,1,1,1
1,1,1,1,1,1,1,1,1,1,2,0,2,1,1,1,1,1,1,1,1,1,1
1,1,1,1,1,1,1,1,1,1,2,0,2,1,1,1,1,1,1,1,1,1,1
1,1,1,1,1,1,1,1,1,1,2,4,2,1,1,1,1,1,1,1,1,1,1
1,1,1,1,1,1,1,1,1,1,2,4,2,1,1,1,1,1,1,1,1,1,1
1,1,1,1,1,1,1,1,1,1,2,0,2,1,1,1,1,1,1,1,1,1,1
1,1,1,1,1,1,1,1,1,1,2,0,2,1,1,1,1,1,1,1,1,1,1
1,1,1,1,1,1,1,1,1,1,2,0,2,1,1,1,1,1,1,1,1,1,1
1,1,1,1,1,1,1,1,1,1,2,0,2,1,1,1,1,1,1,1,1,1,1
1,1,1,1,1,1,1,1,1,1,2,2,2,1,1,1,1,1,1,1,1,1,1
1,1,1,1,1,1,1,1,1,1,2,2,2,1,1,1,1,1,1,1,1,1,1
1,1,1,1,1,1,1,1,1,1,2,0,2,1,1,1,1,1,1,1,1,1,1
1,1,1,1,1,1,1,1,1,1,2,4,2,1,1,1,1,1,1,1,1,1,1
1,1,1,1,1,1,1,1,1,1,2,5,2,1,1,1,1,1,1,1,1,1,1
1,1,1,1,1,1,1,1,1,1,1,2,2,1,1,1,1,1,1,1,1,1,1
1,1,1,1,1,1,1,1,1,1,1,2,1,1,1,1,1,1,1,1,1,1,1
1,1,1,1,1,1,1,1,1,1,1,1,1,1,1,1,1,1,1,1,1,1,1
1,1,1,1,1,1,1,1,1,1,1,1,1,1,1,1,1,1,1,1,1,1,1
1,1,1,1,1,1,1,1,1,1,1,1,1,1,1,1,1,1,1,1,1,1,1
endlayer

layer
1,1,1,1,1,1,1,1,1,1,1,1,1,1,1,1,1,1,1,1,1,1,1
1,1,2,1,1,1,1,1,1,1,1,1,1,1,1,1,1,1,1,1,2,1,1
1,2,4,2,1,1,1,1,1,1,1,1,1,1,1,1,1,1,2,2,4,2,1
1,2,0,2,1,1,1,1,1,1,1,1,1,1,1,1,1,1,2,2,0,2,1
1,2,2,2,1,1,1,1,1,1,1,1,1,1,1,1,1,1,2,2,2,1,1
1,1,2,2,1,1,1,1,1,1,1,1,1,1,1,1,1,1,2,2,1,1,1
1,1,2,2,2,2,2,2,2,2,2,2,2,2,2,2,2,2,2,2,1,1,1
1,1,1,2,2,2,2,2,2,2,2,2,1,1,1,1,1,1,1,1,1,1,1
1,1,1,1,1,1,1,1,1,1,2,2,1,1,1,1,1,1,1,1,1,1,1
1,1,1,1,1,1,1,1,1,1,2,2,1,1,1,1,1,1,1,1,1,1,1
1,1,1,1,1,1,1,1,1,1,2,2,1,1,1,1,1,1,1,1,1,1,1
1,1,1,1,1,1,1,1,1,1,2,2,1,1,1,1,1,1,1,1,1,1,1
1,1,1,1,1,1,1,1,1,1,2,2,1,1,1,1,1,1,1,1,1,1,1
1,1,1,1,1,1,1,1,1,1,2,2,1,1,1,1,1,1,1,1,1,1,1
1,1,1,1,1,1,1,1,1,1,2,2,1,1,1,1,1,1,1,1,1,1,1
1,1,1,1,1,1,1,1,1,1,2,2,1,1,1,1,1,1,1,1,1,1,1
1,1,1,1,1,1,1,1,1,1,2,2,1,1,1,1,1,1,1,1,1,1,1
1,1,1,1,1,1,1,1,1,1,2,2,1,1,1,1,1,1,1,1,1,1,1
1,1,1,1,1,1,1,1,1,1,2,2,1,1,1,1,1,1,1,1,1,1,1
1,1,1,1,1,1,1,1,1,1,2,2,1,1,1,1,1,1,1,1,1,1,1
1,1,1,1,1,1,1,1,1,1,2,2,1,1,1,1,1,1,1,1,1,1,1
1,1,1,1,1,1,1,1,1,1,2,2,1,1,1,1,1,1,1,1,1,1,1
1,1,1,1,1,1,1,1,1,1,2,2,1,1,1,1,1,1,1,1,1,1,1
1,1,1,1,1,1,1,1,1,1,2,2,1,1,1,1,1,1,1,1,1,1,1
1,1,1,1,1,1,1,1,1,1,2,2,1,1,1,1,1,1,1,1,1,1,1
1,1,1,1,1,1,1,1,1,1,2,2,1,1,1,1,1,1,1,1,1,1,1
1,1,1,1,1,1,1,1,1,1,2,2,2,1,1,1,1,1,1,1,1,1,1
1,1,1,1,1,1,1,1,1,1,2,0,2,1,1,1,1,1,1,1,1,1,1
1,1,1,1,1,1,1,1,1,1,2,4,2,1,1,1,1,1,1,1,1,1,1
1,1,1,1,1,1,1,1,1,1,1,2,1,1,1,1,1,1,1,1,1,1,1
1,1,1,1,1,1,1,1,1,1,1,1,1,1,1,1,1,1,1,1,1,1,1
1,1,1,1,1,1,1,1,1,1,1,1,1,1,1,1,1,1,1,1,1,1,1
1,1,1,1,1,1,1,1,1,1,1,1,1,1,1,1,1,1,1,1,1,1,1
endlayer

layer
0,0,0,0,0,0,0,0,0,0,0,0,0,0,0,0,0,0,0,0,0,0,0
0,9,9,9,9,9,9,9,9,9,9,9,9,9,9,9,9,9,9,9,9,9,0
0,9,2,10,10,10,10,10,10,10,10,10,10,10,10,10,10,10,10,10,2,9,0
0,9,10,11,9,12,12,12,12,12,12,13,12,12,12,12,12,12,9,11,10,9,0
0,9,10,9,9,12,12,13,12,12,13,12,13,12,12,13,12,12,9,9,10,9,0
0,9,10,14,15,9,19,12,13,13,18,18,18,13,13,17,16,9,15,14,10,9,0
0,9,10,20,20,15,16,16,19,18,18,21,18,18,17,16,9,15,20,20,10,9,0
0,9,10,20,20,22,21,22,19,18,21,23,21,18,16,22,21,22,20,20,10,9,0
0,9,10,20,21,20,21,22,22,21,21,23,21,21,22,22,21,20,21,20,10,9,0
0,9,10,20,21,20,21,22,21,24,21,23,21,24,21,22,21,20,21,20,10,9,0
0,9,10,20,21,20,20,21,21,21,24,21,24,21,21,21,22,20,21,20,10,9,0
0,9,10,20,20,21,20,22,21,25,23,24,23,25,21,22,20,21,20,20,10,9,0
0,9,10,20,20,20,21,21,20,21,26,23,26,21,20,21,21,20,20,20,10,9,0
0,9,10,20,20,20,20,22,21,21,21,25,21,21,21,22,20,20,20,20,10,9,0
0,9,10,20,27,20,20,22,20,28,26,29,26,28,20,22,20,20,27,20,10,9,0
0,9,10,20,20,20,20,21,21,21,18,18,18,21,21,21,20,20,20,20,10,9,0
0,9,10,20,15,20,21,22,20,28,18,23,18,28,20,22,21,20,15,20,10,9,0
0,9,10,15,14,21,20,21,21,21,18,23,18,21,21,21,20,21,14,15,10,9,0
0,9,10,20,20,22,21,22,20,22,28,23,28,22,20,22,21,22,20,20,10,9,0
0,9,10,20,20,21,22,22,22,21,18,23,18,21,22,22,22,21,20,20,10,9,0
0,9,10,20,21,20,20,22,20,21,26,28,26,21,20,22,22,20,21,20,10,9,0
0,9,10,20,21,20,20,9,22,18,21,21,21,18,22,9,20,20,21,20,10,9,0
0,9,10,20,20,21,20,14,22,9,19,30,17,22,15,14,20,21,20,20,10,9,0
0,9,10,20,20,20,20,9,15,22,15,15,15,22,15,9,20,20,20,20,10,9,0
0,9,10,20,27,20,20,14,9,19,15,12,15,17,9,14,20,20,27,20,10,9,0
0,9,10,20,20,20,20,9,31,31,12,12,12,31,31,9,20,20,20,20,10,9,0
0,9,10,20,20,20,9,31,19,12,12,13,12,12,17,31,9,20,20,20,10,9,0
0,9,10,20,20,9,31,19,12,12,13,13,13,12,12,17,31,9,20,20,10,9,0
0,9,10,9,9,31,19,12,12,13,13,13,13,13,12,12,17,31,9,9,10,9,0
0,9,10,11,9,19,12,13,13,13,12,12,12,13,13,13,12,17,9,11,10,9,0
0,9,10,10,10,10,10,10,10,10,10,10,10,10,10,10,10,10,10,10,10,9,0
0,9,9,9,9,9,9,9,9,9,9,9,9,9,9,9,9,9,9,9,9,9,0
0,0,0,0,0,0,0,0,0,0,0,0,0,0,0,0,0,0,0,0,0,0,0
endlayer

layer
32,32,32,32,32,32,32,32,34,19,0,0,0,17,33,32,32,32,32,32,32,32,32
32,21,21,21,21,21,21,21,10,0,0,0,0,0,10,21,21,21,21,21,21,21,32
32,21,36,35,35,35,21,32,0,0,0,0,0,0,0,32,21,35,35,35,27,21,32
32,21,35,35,35,35,21,0,0,0,0,0,0,0,0,0,21,35,35,35,35,21,32
32,21,35,35,0,0,32,0,0,0,0,0,0,0,0,0,32,0,0,35,35,21,32
32,21,35,35,0,0,0,0,0,0,0,0,0,0,0,0,0,0,0,35,35,21,32
32,21,21,21,32,0,0,0,0,0,0,0,0,0,0,0,0,0,32,21,21,21,32
32,27,0,0,0,0,0,0,0,0,0,0,0,0,0,0,0,0,0,0,0,27,32
32,27,0,0,0,0,0,0,0,0,0,0,0,0,0,0,0,0,0,0,0,27,32
32,27,0,0,0,0,0,0,0,0,0,0,0,0,0,0,0,0,0,0,0,27,32
32,27,0,0,0,0,0,0,0,0,0,0,0,0,0,0,0,0,0,0,0,27,32
32,27,0,0,0,0,0,0,0,0,0,0,0,0,0,0,0,0,0,0,0,10,32
32,27,21,21,0,0,0,0,0,0,0,0,0,0,0,0,0,0,0,21,21,27,32
32,10,21,21,21,0,0,0,0,0,0,0,0,0,0,0,0,0,21,21,21,27,32
32,27,21,21,27,21,0,0,0,0,0,0,0,0,0,0,0,21,27,21,21,27,32
32,27,21,21,21,0,0,0,0,0,0,0,0,0,0,0,0,0,21,21,21,27,32
32,27,21,21,0,0,0,0,0,0,0,0,0,0,0,0,0,0,0,21,21,27,32
32,27,0,0,0,0,0,0,0,0,0,0,0,0,0,0,0,0,0,0,0,27,32
32,27,0,0,0,0,0,0,0,0,0,0,0,0,0,0,0,0,0,0,0,27,32
32,27,0,0,0,0,0,0,0,0,0,0,0,0,0,0,0,0,0,0,0,27,32
32,27,0,0,0,0,0,0,0,0,0,0,0,0,0,0,0,0,0,0,0,21,32
32,10,0,0,0,0,0,0,0,0,0,0,0,0,0,0,0,0,0,0,0,10,32
32,27,21,21,0,0,0,0,0,0,0,0,0,0,0,0,0,0,0,21,21,27,32
32,10,21,21,21,0,0,0,0,0,0,0,0,0,0,0,0,0,21,21,21,10,32
32,27,21,21,27,21,0,0,0,0,0,0,0,0,0,0,0,21,27,21,21,27,32
32,10,21,21,21,0,0,0,0,32,33,0,34,32,0,0,0,0,21,21,21,10,32
32,10,21,21,0,0,0,0,0,21,0,0,0,21,0,0,0,0,0,21,21,10,32
32,10,35,0,0,0,0,0,0,21,0,0,0,21,0,0,0,0,0,0,35,10,32
32,27,35,0,0,0,0,0,21,0,0,37,0,0,21,0,0,0,0,0,35,27,32
32,10,35,0,0,0,0,21,38,38,38,38,38,38,38,21,0,0,0,0,35,10,32
32,10,35,35,35,35,35,10,10,10,10,10,10,10,10,10,35,35,35,35,35,10,32
32,10,10,10,27,10,10,10,10,10,10,10,10,10,10,10,10,10,27,10,10,10,32
32,32,32,32,32,32,32,32,32,32,32,32,32,32,32,32,32,32,32,32,32,32,32
endlayer

layer
0,0,0,0,0,0,0,34,13,0,0,0,0,0,13,33,0,0,0,0,0,0,0
0,27,27,10,10,27,27,10,0,0,0,0,0,0,0,10,27,27,10,10,27,27,0
0,27,27,35,35,35,27,32,0,0,0,0,0,0,0,32,27,35,35,35,27,27,0
0,27,35,35,35,35,39,0,0,0,0,0,0,0,0,0,39,35,35,35,35,27,0
0,27,35,35,0,0,32,0,0,0,0,0,0,0,0,0,32,0,0,35,35,27,0
0,27,35,35,0,0,0,0,0,0,0,0,0,0,0,0,0,0,0,35,35,27,0
0,21,21,39,32,0,0,0,0,0,0,0,0,0,0,0,0,0,32,39,21,21,0
0,27,0,0,0,0,0,0,0,0,0,0,0,0,0,0,0,0,0,0,0,27,0
0,27,0,0,0,0,0,0,0,0,0,0,0,0,0,0,0,0,0,0,0,27,0
0,27,0,0,0,0,0,0,0,0,0,0,0,0,0,0,0,0,0,0,0,27,0
0,27,0,0,0,0,0,0,0,0,0,0,0,0,0,0,0,0,0,0,0,10,0
0,27,0,0,0,0,0,0,0,0,0,0,0,0,0,0,0,0,0,0,0,27,0
0,10,15,39,0,0,0,0,0,0,0,0,0,0,0,0,0,0,0,39,21,10,0
0,21,10,32,0,0,0,0,0,0,0,0,0,0,0,0,0,0,0,32,10,21,0
0,10,10,32,0,0,0,0,0,0,0,0,0,0,0,0,0,0,0,32,10,27,0
0,27,10,32,0,0,0,0,0,0,0,0,0,0,0,0,0,0,0,32,10,27,0
0,27,15,39,0,0,0,0,0,0,0,0,0,0,0,0,0,0,0,39,21,27,0
0,27,0,0,0,0,0,0,0,0,0,0,0,0,0,0,0,0,0,0,0,27,0
0,27,0,0,0,0,0,0,0,0,0,0,0,0,0,0,0,0,0,0,0,27,0
0,27,0,0,0,0,0,0,0,0,0,0,0,0,0,0,0,0,0,0,0,21,0
0,10,0,0,0,0,0,0,0,0,0,0,0,0,0,0,0,0,0,0,0,10,0
0,27,0,0,0,0,0,0,0,0,0,0,0,0,0,0,0,0,0,0,0,27,0
0,10,21,39,0,0,0,0,0,0,0,0,0,0,0,0,0,0,0,39,21,10,0
0,10,10,32,0,0,0,0,0,0,0,0,0,0,0,0,0,0,0,32,10,10,0
0,10,10,32,0,0,0,0,0,0,0,0,0,0,0,0,0,0,0,32,10,10,0
0,27,10,32,0,0,0,0,0,32,12,0,12,32,0,0,0,0,0,32,10,27,0
0,10,21,39,0,0,0,0,0,21,0,0,0,21,0,0,0,0,0,39,21,10,0
0,10,35,0,0,0,0,0,0,21,0,0,0,21,0,0,0,0,0,0,35,10,0
0,10,35,0,0,0,0,0,21,0,0,0,0,0,21,0,0,0,0,0,35,10,0
0,27,35,0,0,0,0,21,38,38,38,38,38,38,38,21,0,0,0,0,35,27,0
0,10,35,35,35,35,35,10,10,10,10,10,10,10,10,10,35,35,35,35,35,10,0
0,10,10,27,10,27,10,10,10,10,27,10,27,10,10,10,10,27,10,27,10,10,0
0,0,0,0,0,0,0,0,0,0,0,0,0,0,0,0,0,0,0,0,0,0,0
endlayer

layer
0,0,0,0,0,0,0,13,13,33,0,0,0,34,13,13,0,0,0,0,0,0,0
0,21,10,10,21,21,10,0,0,0,0,0,0,0,0,0,10,21,21,10,10,21,0
0,21,27,35,35,35,21,32,0,0,0,0,0,0,0,32,21,35,35,35,27,21,0
0,21,35,32,32,32,39,0,0,0,0,0,0,0,0,0,39,32,32,32,35,21,0
0,21,35,32,10,32,32,0,0,0,0,0,0,0,0,0,32,32,10,32,35,21,0
0,21,35,32,32,0,0,0,0,0,0,0,0,0,0,0,0,0,32,32,35,21,0
0,21,21,39,32,0,0,0,0,0,0,0,0,0,0,0,0,0,32,39,21,21,0
0,27,0,0,0,0,0,0,0,0,0,0,0,0,0,0,0,0,0,0,0,27,0
0,27,0,0,0,0,0,0,0,0,0,0,0,0,0,0,0,0,0,0,0,27,0
0,27,0,0,0,0,0,0,0,0,0,0,0,0,0,0,0,0,0,0,0,10,0
0,27,0,0,0,0,0,0,0,0,0,0,0,0,0,0,0,0,0,0,0,27,0
0,10,0,0,0,0,0,0,0,0,0,0,0,0,0,0,0,0,0,0,0,10,0
0,21,15,39,0,0,0,0,0,0,0,0,0,0,0,0,0,0,0,39,21,21,0
0,10,10,32,0,0,0,0,0,0,0,0,0,0,0,0,0,0,0,32,10,10,0
0,21,10,32,0,0,0,0,0,0,0,0,0,0,0,0,0,0,0,32,10,21,0
0,10,10,32,0,0,0,0,0,0,0,0,0,0,0,0,0,0,0,32,10,27,0
0,27,15,39,0,0,0,0,0,0,0,0,0,0,0,0,0,0,0,39,21,27,0
0,27,0,0,0,0,0,0,0,0,0,0,0,0,0,0,0,0,0,0,0,27,0
0,27,0,0,0,0,0,0,0,0,0,0,0,0,0,0,0,0,0,0,0,21,0
0,10,0,0,0,0,0,0,0,0,0,0,0,0,0,0,0,0,0,0,0,10,0
0,27,0,0,0,0,0,0,0,0,0,0,0,0,0,0,0,0,0,0,0,27,0
0,10,0,0,0,0,0,0,0,0,0,0,0,0,0,0,0,0,0,0,0,10,0
0,10,21,39,0,0,0,0,0,0,0,0,0,0,0,0,0,0,0,39,21,10,0
0,10,10,32,0,0,0,0,0,0,0,0,0,0,0,0,0,0,0,32,10,10,0
0,10,10,32,0,0,0,0,0,0,0,0,0,0,0,0,0,0,0,32,10,10,0
0,10,10,32,0,0,0,0,0,32,39,32,39,32,0,0,0,0,0,32,10,10,0
0,27,10,39,0,0,0,0,0,39,0,0,0,39,0,0,0,0,0,39,21,27,0
0,10,35,0,0,0,0,0,0,39,0,0,0,21,0,0,0,0,0,0,35,10,0
0,10,35,0,0,0,0,0,21,0,0,0,0,0,21,0,0,0,0,0,35,10,0
0,10,35,0,0,0,0,21,21,21,21,21,21,21,21,21,0,0,0,0,35,10,0
0,27,35,35,35,35,35,10,10,10,10,10,10,10,10,10,35,35,35,35,35,27,0
0,10,27,10,10,10,27,10,10,27,10,27,10,27,10,10,27,10,10,10,27,10,0
0,0,0,0,0,0,0,0,0,0,0,0,0,0,0,0,0,0,0,0,0,0,0
endlayer

layer
0,0,0,0,0,0,0,13,13,13,0,0,0,13,13,13,0,0,0,0,0,0,0
0,27,10,27,27,10,27,0,0,0,0,0,0,0,0,0,27,10,27,27,10,27,0
0,27,27,35,35,35,27,32,0,0,0,0,0,0,0,32,27,35,35,35,27,27,0
0,27,35,32,32,32,39,0,0,0,0,0,0,0,0,0,39,32,32,32,35,27,0
0,27,35,32,0,0,0,0,0,0,0,0,0,0,0,0,0,0,0,32,35,27,0
0,27,35,32,0,0,0,0,0,0,0,0,0,0,0,0,0,0,0,32,35,27,0
0,21,21,39,0,0,0,0,0,0,0,0,0,0,0,0,0,0,0,39,21,21,0
0,27,0,0,0,0,0,0,0,0,0,0,0,0,0,0,0,0,0,0,0,27,0
0,27,0,0,0,0,0,0,0,0,0,0,0,0,0,0,0,0,0,0,0,10,0
0,27,0,0,0,0,0,0,0,0,0,0,0,0,0,0,0,0,0,0,0,27,0
0,10,0,0,0,0,0,0,0,0,0,0,0,0,0,0,0,0,0,0,0,10,0
0,21,0,0,0,0,0,0,0,0,0,0,0,0,0,0,0,0,0,0,0,21,0
0,10,15,39,0,0,0,0,0,0,0,0,0,0,0,0,0,0,0,39,21,10,0
0,10,10,32,0,0,0,0,0,0,0,0,0,0,0,0,0,0,0,32,10,10,0
0,10,10,32,0,0,0,0,0,0,0,0,0,0,0,0,0,0,0,32,10,10,0
0,21,10,32,0,0,0,0,0,0,0,0,0,0,0,0,0,0,0,32,10,21,0
0,10,15,39,0,0,0,0,0,0,0,0,0,0,0,0,0,0,0,39,21,27,0
0,27,0,0,0,0,0,0,0,0,0,0,0,0,0,0,0,0,0,0,0,21,0
0,10,0,0,0,0,0,0,0,0,0,0,0,0,0,0,0,0,0,0,0,10,0
0,27,0,0,0,0,0,0,0,0,0,0,0,0,0,0,0,0,0,0,0,27,0
0,10,0,0,0,0,0,0,0,0,0,0,0,0,0,0,0,0,0,0,0,10,0
0,10,0,0,0,0,0,0,0,0,0,0,0,0,0,0,0,0,0,0,0,10,0
0,10,21,39,0,0,0,0,0,0,0,0,0,0,0,0,0,0,0,39,21,10,0
0,21,10,32,0,0,0,0,0,0,0,0,0,0,0,0,0,0,0,32,10,21,0
0,10,10,32,0,0,0,0,0,0,0,0,0,0,0,0,0,0,0,32,10,10,0
0,10,10,32,0,0,0,0,0,32,39,21,39,32,0,0,0,0,0,32,10,10,0
0,10,10,39,0,0,0,0,0,39,0,40,0,39,0,0,0,0,0,39,21,10,0
0,27,35,0,0,0,0,0,0,39,0,0,0,39,0,0,0,0,0,0,35,27,0
0,10,35,0,0,0,0,0,39,0,0,0,0,0,39,0,0,0,0,0,35,10,0
0,10,35,0,0,0,0,39,15,15,15,15,15,15,15,39,0,0,0,0,35,10,0
0,10,35,35,35,35,35,10,10,10,10,10,10,10,10,10,35,35,35,35,35,10,0
0,27,10,10,10,10,10,27,27,10,10,10,10,10,27,27,10,10,10,10,10,27,0
0,0,0,0,0,0,0,0,0,0,0,0,0,0,0,0,0,0,0,0,0,0,0
endlayer

layer
0,0,0,0,0,0,0,13,13,13,32,27,32,13,13,13,0,0,0,0,0,0,0
0,21,21,21,10,21,21,0,0,0,10,10,10,0,0,0,21,21,10,21,21,21,0
0,21,27,35,35,35,21,32,0,0,0,0,0,0,0,32,21,35,35,35,27,21,0
0,21,35,32,32,32,39,0,0,0,0,0,0,0,0,0,39,32,32,32,35,21,0
0,21,35,32,0,0,0,0,0,0,0,0,0,0,0,0,0,0,0,32,35,21,0
0,21,35,32,0,0,0,0,0,0,0,0,0,0,0,0,0,0,0,32,35,21,0
0,21,21,39,0,0,0,0,0,0,0,0,0,0,0,0,0,0,0,39,21,21,0
0,27,0,0,0,0,0,0,0,0,0,0,0,0,0,0,0,0,0,0,0,10,0
0,27,0,0,0,0,0,0,0,0,0,0,0,0,0,0,0,0,0,0,0,27,0
0,10,0,0,0,0,0,0,0,0,0,0,0,0,0,0,0,0,0,0,0,10,0
0,21,0,0,0,0,0,0,0,0,0,0,0,0,0,0,0,0,0,0,0,21,0
0,10,0,0,0,0,0,0,0,0,0,0,0,0,0,0,0,0,0,0,0,10,0
0,10,15,39,0,0,0,0,0,0,0,0,0,0,0,0,0,0,0,39,21,10,0
0,10,10,32,0,0,0,0,0,0,0,0,0,0,0,0,0,0,0,32,10,10,0
0,10,10,32,0,0,0,0,0,0,0,0,0,0,0,0,0,0,0,32,10,10,0
0,10,10,32,0,0,0,0,0,0,0,0,0,0,0,0,0,0,0,32,10,10,0
0,21,15,39,0,0,0,0,0,0,0,0,0,0,0,0,0,0,0,39,21,21,0
0,10,0,0,0,0,0,0,0,0,0,0,0,0,0,0,0,0,0,0,0,10,0
0,27,0,0,0,0,0,0,0,0,0,0,0,0,0,0,0,0,0,0,0,27,0
0,10,0,0,0,0,0,0,0,0,0,0,0,0,0,0,0,0,0,0,0,10,0
0,10,0,0,0,0,0,0,0,0,0,0,0,0,0,0,0,0,0,0,0,10,0
0,10,0,0,0,0,0,0,0,0,0,0,0,0,0,0,0,0,0,0,0,10,0
0,21,21,39,0,0,0,0,0,0,0,0,0,0,0,0,0,0,0,39,21,21,0
0,21,10,32,0,0,0,0,0,0,0,0,0,0,0,0,0,0,0,32,10,21,0
0,21,10,32,0,0,0,0,0,0,0,0,0,0,0,0,0,0,0,32,10,21,0
0,10,10,32,0,0,0,0,0,32,39,38,39,32,0,0,0,0,0,32,10,10,0
0,10,10,39,0,0,0,0,0,27,0,0,0,27,0,0,0,0,0,39,10,10,0
0,10,35,0,0,0,0,0,0,27,0,0,0,27,0,0,0,0,0,0,35,10,0
0,27,35,0,0,0,0,0,27,0,0,0,0,0,27,0,0,0,0,0,35,27,0
0,10,35,0,0,0,0,39,38,38,38,38,38,38,38,39,0,0,0,0,35,10,0
0,10,35,35,35,35,35,10,10,10,10,10,10,10,10,10,35,35,35,35,35,10,0
0,10,10,10,10,10,10,10,10,10,10,27,10,10,10,10,10,10,10,10,10,10,0
0,0,0,0,0,0,0,0,0,0,0,0,0,0,0,0,0,0,0,0,0,0,0
endlayer

layer
0,0,0,0,0,0,0,17,13,32,32,0,32,32,13,19,0,0,0,0,0,0,0
0,27,10,10,10,0,0,0,0,10,10,27,10,10,0,0,0,0,10,10,10,27,0
0,10,41,27,27,27,27,27,27,27,27,27,27,27,27,27,27,27,27,27,41,10,0
0,10,27,27,42,42,39,42,42,42,42,42,42,42,42,42,39,42,42,42,27,10,0
0,10,27,44,0,0,0,0,0,0,0,0,0,0,0,0,0,0,0,43,27,10,0
0,10,27,44,0,0,0,0,0,0,0,0,0,0,0,0,0,0,0,43,27,10,0
0,10,27,39,0,0,0,0,0,0,0,0,0,0,0,0,0,0,0,39,27,10,0
0,27,27,44,0,0,0,0,0,0,0,0,0,0,0,0,0,0,0,43,27,27,0
0,10,27,44,0,0,0,0,0,0,0,0,0,0,0,0,0,0,0,43,27,10,0
0,21,27,44,0,0,0,0,0,0,0,0,0,0,0,0,0,0,0,43,27,21,0
0,10,27,44,0,0,0,0,0,0,0,0,0,0,0,0,0,0,0,43,27,10,0
0,10,27,44,0,0,0,0,0,0,0,0,0,0,0,0,0,0,0,43,27,10,0
0,10,27,39,0,0,0,0,0,0,0,0,0,0,0,0,0,0,0,39,27,10,0
0,10,27,44,0,0,0,0,0,0,0,0,0,0,0,0,0,0,0,43,27,10,0
0,10,27,44,0,0,0,0,0,0,0,0,0,0,0,0,0,0,0,43,27,10,0
0,10,27,44,0,0,0,0,0,0,0,0,0,0,0,0,0,0,0,43,27,10,0
0,10,27,39,0,0,0,0,0,0,0,0,0,0,0,0,0,0,0,39,27,10,0
0,27,27,44,0,0,0,0,0,0,0,0,0,0,0,0,0,0,0,43,27,27,0
0,10,27,44,0,0,0,0,0,0,0,0,0,0,0,0,0,0,0,43,27,10,0
0,10,27,44,0,0,0,0,0,0,0,0,0,0,0,0,0,0,0,43,27,10,0
0,10,27,44,0,0,0,0,0,0,0,0,0,0,0,0,0,0,0,43,27,10,0
0,10,27,44,0,0,0,0,0,0,0,0,0,0,0,0,0,0,0,43,27,10,0
0,10,27,39,0,0,0,0,0,0,0,0,0,0,0,0,0,0,0,39,27,10,0
0,21,27,44,0,0,0,0,0,0,0,0,0,0,0,0,0,0,0,43,27,21,0
0,10,27,44,0,0,0,0,0,0,0,0,0,0,0,0,0,0,0,43,27,10,0
0,10,27,44,0,0,0,0,0,0,18,18,18,0,0,0,0,0,0,43,27,10,0
0,10,27,39,0,0,0,0,0,32,21,27,21,32,0,0,0,0,0,39,27,10,0
0,10,27,44,0,0,0,0,0,39,27,21,27,39,0,0,0,0,0,43,27,10,0
0,10,27,44,0,0,43,45,46,27,27,27,27,27,46,45,45,0,0,43,27,10,0
0,27,27,44,0,0,43,39,25,47,25,45,25,47,25,39,44,0,0,43,27,27,0
0,10,27,45,45,45,43,27,27,27,27,27,27,27,27,27,45,45,45,43,27,10,0
0,27,27,27,27,27,27,27,27,10,10,10,10,10,27,27,27,27,27,27,27,27,0
0,0,0,0,0,0,0,0,0,0,0,0,0,0,0,0,0,0,0,0,0,0,0
endlayer

layer
0,0,0,0,0,0,0,0,17,33,0,0,0,34,19,0,0,0,0,0,0,0,0
0,10,27,10,10,10,10,27,10,10,27,10,27,10,10,27,10,10,10,10,27,10,0
0,27,27,10,48,48,10,35,35,35,35,35,35,35,35,35,10,48,48,10,27,27,0
0,10,10,32,32,32,39,32,32,32,32,32,32,32,32,32,39,32,32,32,10,10,0
0,10,48,32,0,0,0,0,0,0,0,0,0,0,0,0,0,0,0,32,48,10,0
0,10,48,32,0,0,0,0,0,0,0,0,0,0,0,0,0,0,0,32,48,10,0
0,27,10,39,0,0,0,0,0,0,0,0,0,0,0,0,0,0,0,39,10,27,0
0,10,48,32,0,0,0,0,0,0,0,0,0,0,0,0,0,0,0,32,48,10,0
0,21,48,32,0,0,0,0,0,0,0,0,0,0,0,0,0,0,0,32,48,21,0
0,10,48,32,0,0,0,0,0,0,0,0,0,0,0,0,0,0,0,32,48,10,0
0,10,48,32,0,0,0,0,0,0,0,0,0,0,0,0,0,0,0,32,48,10,0
0,10,48,32,0,0,0,0,0,0,0,0,0,0,0,0,0,0,0,32,48,10,0
0,10,10,39,0,0,0,0,0,0,0,0,0,0,0,0,0,0,0,39,10,10,0
0,10,48,32,0,0,0,0,0,0,0,0,0,0,0,0,0,0,0,32,48,10,0
0,10,48,32,0,0,0,0,0,0,0,0,0,0,0,0,0,0,0,32,48,10,0
0,10,48,32,0,0,0,0,0,0,0,0,0,0,0,0,0,0,0,32,48,10,0
0,27,10,39,0,0,0,0,0,0,0,0,0,0,0,0,0,0,0,39,10,27,0
0,10,48,32,0,0,0,0,0,0,0,0,0,0,0,0,0,0,0,32,48,10,0
0,10,48,32,0,0,0,0,0,0,0,0,0,0,0,0,0,0,0,32,48,10,0
0,10,48,32,0,0,0,0,0,0,0,0,0,0,0,0,0,0,0,32,48,21,0
0,21,48,32,0,0,0,0,0,0,0,0,0,0,0,0,0,0,0,32,48,21,0
0,21,48,32,0,0,0,0,0,0,0,0,0,0,0,0,0,0,0,32,48,10,0
0,10,10,39,0,0,0,0,0,0,0,0,0,0,0,0,0,0,0,39,10,10,0
0,21,48,32,0,0,0,0,0,0,0,0,0,0,0,0,0,0,0,32,48,21,0
0,10,48,32,0,0,0,0,0,0,0,0,0,0,0,0,0,0,0,32,48,10,0
0,21,48,32,0,0,0,0,0,0,0,0,0,0,0,0,0,0,0,32,48,10,0
0,21,10,39,0,0,0,0,0,0,0,32,0,0,0,0,0,0,0,39,10,21,0
0,10,48,32,0,0,0,0,0,0,0,32,0,0,0,0,0,0,0,32,48,21,0
0,10,48,32,0,0,0,0,18,18,18,32,18,18,18,0,0,0,0,32,48,10,0
0,10,48,32,0,0,0,39,32,32,32,39,32,32,32,39,0,0,0,32,48,10,0
0,27,10,39,32,32,32,39,25,25,25,10,25,25,25,39,32,32,32,39,10,27,0
0,10,10,10,10,10,10,10,10,27,10,10,10,27,10,10,10,10,10,10,10,10,0
0,0,0,0,0,0,0,0,0,0,0,0,0,0,0,0,0,0,0,0,0,0,0
endlayer

layer
0,0,0,0,0,0,0,32,32,17,0,0,0,19,32,32,0,0,0,0,0,0,0
0,10,10,27,10,10,27,10,10,27,10,27,10,27,10,10,27,10,10,27,10,10,0
0,10,27,10,48,48,10,35,26,35,35,35,35,35,26,35,10,48,48,10,27,10,0
0,27,10,32,32,32,27,32,32,32,32,32,32,32,32,32,27,32,32,32,10,27,0
0,10,48,32,0,0,0,0,0,0,0,0,0,0,0,0,0,0,0,32,48,10,0
0,27,48,32,0,0,0,0,0,0,0,0,0,0,0,0,0,0,0,32,48,27,0
0,10,10,27,0,0,0,0,0,0,0,0,0,0,0,0,0,0,0,27,10,10,0
0,21,48,32,0,0,0,0,0,0,0,0,0,0,0,0,0,0,0,32,48,21,0
0,10,48,32,0,0,0,0,0,0,0,0,0,0,0,0,0,0,0,32,48,10,0
0,10,48,32,0,0,0,0,0,0,0,0,0,0,0,0,0,0,0,32,48,10,0
0,10,48,32,0,0,0,0,0,0,0,0,0,0,0,0,0,0,0,32,48,10,0
0,10,48,32,0,0,0,0,0,0,0,0,0,0,0,0,0,0,0,32,48,10,0
0,10,10,27,0,0,0,0,0,0,0,0,0,0,0,0,0,0,0,27,10,10,0
0,27,48,32,0,0,0,0,0,0,0,0,0,0,0,0,0,0,0,32,48,27,0
0,27,48,32,0,0,0,0,0,0,0,0,0,0,0,0,0,0,0,32,48,27,0
0,27,48,32,0,0,0,0,0,0,0,0,0,0,0,0,0,0,0,32,48,27,0
0,10,10,27,0,0,0,0,0,0,0,0,0,0,0,0,0,0,0,27,10,10,0
0,10,48,32,0,0,0,0,0,0,0,0,0,0,0,0,0,0,0,32,48,10,0
0,10,48,32,0,0,0,0,0,0,0,0,0,0,0,0,0,0,0,32,48,10,0
0,10,48,32,0,0,0,0,0,0,0,0,0,0,0,0,0,0,0,32,48,21,0
0,21,48,32,0,0,0,0,0,0,0,0,0,0,0,0,0,0,0,32,48,10,0
0,10,48,32,0,0,0,0,0,0,0,0,0,0,0,0,0,0,0,32,48,10,0
0,10,10,27,0,0,0,0,0,0,0,0,0,0,0,0,0,0,0,27,10,10,0
0,21,48,32,0,0,0,0,0,0,0,0,0,0,0,0,0,0,0,32,48,21,0
0,10,48,32,0,0,0,0,0,0,0,0,0,0,0,0,0,0,0,32,48,10,0
0,10,48,32,0,0,0,0,0,0,0,0,0,0,0,0,0,0,0,32,48,10,0
0,21,10,27,0,0,0,0,0,0,0,0,0,0,0,0,0,0,0,27,10,10,0
0,10,48,32,0,0,0,0,0,0,0,32,0,0,0,0,0,0,0,32,48,21,0
0,10,48,32,0,0,0,0,0,0,0,32,0,0,0,0,0,0,0,32,48,10,0
0,10,48,32,0,0,0,27,32,32,32,27,32,32,32,27,0,0,0,32,48,10,0
0,10,10,39,32,32,32,27,25,25,25,10,25,25,25,27,32,32,32,39,10,10,0
0,10,10,10,10,10,10,10,10,10,27,10,27,10,10,10,10,10,10,10,10,10,0
0,0,0,0,0,0,0,0,0,0,0,0,0,0,0,0,0,0,0,0,0,0,0
endlayer

layer
0,0,0,0,0,0,32,32,0,0,0,0,0,0,0,32,32,0,0,0,0,0,0
0,0,0,10,10,27,10,10,27,10,10,27,10,10,27,10,10,27,10,10,0,0,0
0,0,27,10,10,10,27,10,10,27,10,10,10,27,10,10,27,10,10,10,27,0,0
0,10,10,46,38,38,49,38,38,38,38,38,38,38,38,38,49,38,38,27,10,10,0
0,27,10,23,0,0,0,0,0,0,0,0,0,0,0,0,0,0,0,23,10,27,0
0,10,10,23,0,0,0,0,0,0,0,0,0,0,0,0,0,0,0,23,10,10,0
0,21,10,51,0,0,0,0,0,0,0,0,0,0,0,0,0,0,0,50,10,21,0
0,10,10,23,0,0,0,0,0,0,0,0,0,0,0,0,0,0,0,23,10,10,0
0,10,10,23,0,0,0,0,0,0,0,0,0,0,0,0,0,0,0,23,10,10,0
0,10,10,23,0,0,0,0,0,0,0,0,0,0,0,0,0,0,0,23,10,10,0
0,10,10,23,0,0,0,0,0,0,0,0,0,0,0,0,0,0,0,23,10,10,0
0,10,10,23,0,0,0,0,0,0,0,0,0,0,0,0,0,0,0,23,10,10,0
0,27,10,51,0,0,0,0,0,0,0,0,0,0,0,0,0,0,0,50,10,27,0
0,10,10,23,0,0,0,0,0,0,0,0,0,0,0,0,0,0,0,23,10,10,0
0,10,10,23,0,0,0,0,0,0,0,0,0,0,0,0,0,0,0,23,10,10,0
0,10,10,23,0,0,0,0,0,0,0,0,0,0,0,0,0,0,0,23,10,10,0
0,10,10,51,0,0,0,0,0,0,0,0,0,0,0,0,0,0,0,50,10,10,0
0,10,10,23,0,0,0,0,0,0,0,0,0,0,0,0,0,0,0,23,10,10,0
0,10,10,23,0,0,0,0,0,0,0,0,0,0,0,0,0,0,0,23,10,10,0
0,10,10,23,0,0,0,0,0,0,0,0,0,0,0,0,0,0,0,23,10,10,0
0,10,10,23,0,0,0,0,0,0,0,0,0,0,0,0,0,0,0,23,10,10,0
0,10,10,23,0,0,0,0,0,0,0,0,0,0,0,0,0,0,0,23,10,10,0
0,10,10,51,0,0,0,0,0,0,0,0,0,0,0,0,0,0,0,50,10,10,0
0,10,10,23,0,0,0,0,0,0,0,0,0,0,0,0,0,0,0,23,10,10,0
0,10,10,23,0,0,0,0,0,0,0,0,0,0,0,0,0,0,0,23,10,10,0
0,10,10,23,0,0,0,0,0,0,0,0,0,0,0,0,0,0,0,23,10,10,0
0,10,10,51,0,0,0,0,0,0,0,0,0,0,0,0,0,0,0,50,10,10,0
0,10,10,23,0,0,0,0,0,0,0,0,0,0,0,0,0,0,0,23,10,10,0
0,10,10,23,0,0,0,0,0,0,0,32,0,0,0,0,0,0,0,23,10,10,0
0,10,10,23,0,0,0,52,38,38,38,52,38,38,38,52,0,0,0,23,10,10,0
0,0,10,27,38,38,38,49,10,10,10,10,10,10,10,49,38,38,38,27,10,0,0
0,0,0,10,10,10,10,10,10,10,10,27,10,10,10,10,10,10,0,10,0,0,0
0,0,0,0,0,0,0,0,0,0,0,0,0,0,0,0,0,0,0,0,0,0,0
endlayer

layer
0,0,0,0,0,0,0,0,0,0,0,0,0,0,0,0,0,0,0,0,0,0,0
0,0,0,0,0,0,32,32,0,0,0,0,0,0,0,32,32,0,0,0,0,0,0
0,0,0,0,0,0,0,32,0,0,0,27,0,0,0,32,0,0,0,0,0,0,0
0,0,0,46,46,46,27,27,46,46,46,46,46,46,46,27,27,46,46,27,0,0,0
0,0,0,46,24,0,24,24,46,46,46,46,46,46,46,24,24,0,24,46,0,0,0
0,0,0,46,0,0,0,0,0,0,0,53,0,0,0,0,0,0,0,46,0,0,0
0,0,0,27,0,0,0,0,0,0,0,53,0,0,0,0,0,0,0,27,0,0,0
0,0,0,46,0,0,0,0,0,0,0,53,0,0,0,0,0,0,0,46,0,0,0
0,0,0,46,0,0,0,0,0,0,0,53,0,0,0,0,0,0,0,46,0,0,0
0,0,0,46,0,0,0,0,0,0,0,53,0,0,0,0,0,0,0,46,0,0,0
0,0,0,46,0,0,0,0,0,0,0,53,0,0,0,0,0,0,0,46,0,0,0
0,0,0,46,0,0,0,0,0,0,0,53,0,0,0,0,0,0,0,46,0,0,0
0,0,0,27,0,0,0,0,0,0,0,53,0,0,0,0,0,0,0,27,0,0,0
0,0,0,46,0,0,0,0,0,0,0,53,0,0,0,0,0,0,0,46,0,0,0
0,0,0,46,0,0,0,0,0,0,0,53,0,0,0,0,0,0,0,46,0,0,0
0,0,0,46,0,0,0,0,0,0,0,53,0,0,0,0,0,0,0,46,0,0,0
0,0,0,27,0,0,0,0,0,0,0,53,0,0,0,0,0,0,0,27,0,0,0
0,0,0,46,0,0,0,0,0,0,0,53,0,0,0,0,0,0,0,46,0,0,0
0,0,0,46,0,0,0,0,0,0,0,53,0,0,0,0,0,0,0,46,0,0,0
0,0,0,46,0,0,0,0,0,0,0,53,0,0,0,0,0,0,0,46,0,0,0
0,0,0,46,0,0,0,0,0,0,0,53,0,0,0,0,0,0,0,46,0,0,0
0,0,0,46,0,0,0,0,0,0,0,53,0,0,0,0,0,0,0,46,0,0,0
0,0,0,27,0,0,0,0,0,0,0,53,0,0,0,0,0,0,0,27,0,0,0
0,0,0,46,0,0,0,0,0,0,0,53,0,0,0,0,0,0,0,46,0,0,0
0,0,0,46,0,0,0,0,0,0,0,53,0,0,0,0,0,0,0,46,0,0,0
0,0,0,46,0,0,0,0,0,0,0,53,0,0,0,0,0,0,0,46,0,0,0
0,0,0,27,0,0,0,0,0,0,0,53,0,0,0,0,0,0,0,27,0,0,0
0,0,0,46,0,0,0,0,0,0,0,53,0,0,0,0,0,0,0,46,0,0,0
0,0,0,46,0,0,0,0,0,0,0,53,0,0,0,0,0,0,0,46,0,0,0
0,0,0,46,24,0,0,0,18,18,18,27,18,18,18,0,0,0,24,46,0,0,0
0,0,0,27,46,46,46,27,46,46,46,27,46,46,46,27,46,46,46,27,0,0,0
0,0,0,0,0,0,0,0,0,0,0,0,0,0,0,0,0,0,0,0,0,0,0
0,0,0,0,0,0,0,0,0,0,0,0,0,0,0,0,0,0,0,0,0,0,0
endlayer

layer
0,0,0,0,0,0,0,0,0,0,0,0,0,0,0,0,0,0,0,0,0,0,0
0,0,0,0,0,0,0,0,0,0,0,0,0,0,0,0,0,0,0,0,0,0,0
0,0,0,0,0,0,0,0,0,0,0,0,0,0,0,0,0,0,0,0,0,0,0
0,0,0,0,0,0,0,0,0,0,0,27,0,0,0,0,0,0,0,0,0,0,0
0,0,0,0,27,46,27,27,53,53,53,53,53,53,53,27,27,46,27,0,0,0,0
0,0,0,0,46,24,0,0,48,48,48,24,48,48,48,24,0,24,46,0,0,0,0
0,0,0,0,27,0,0,0,48,48,48,24,48,48,48,24,0,0,27,0,0,0,0
0,0,0,0,46,0,0,0,48,48,48,24,48,48,48,24,0,0,46,0,0,0,0
0,0,0,0,46,0,0,0,48,48,48,24,48,48,48,24,0,0,46,0,0,0,0
0,0,0,0,46,0,0,0,48,48,48,24,48,48,48,24,0,0,46,0,0,0,0
0,0,0,0,46,0,0,0,48,48,48,24,48,48,48,24,0,0,46,0,0,0,0
0,0,0,0,46,0,0,0,48,48,48,24,48,48,48,24,0,0,46,0,0,0,0
0,0,0,0,27,0,0,0,48,48,48,24,48,48,48,24,0,0,27,0,0,0,0
0,0,0,0,46,0,0,0,48,48,48,24,48,48,48,24,0,0,46,0,0,0,0
0,0,0,0,46,0,0,0,48,48,48,24,48,48,48,24,0,0,46,0,0,0,0
0,0,0,0,46,0,0,0,48,48,48,24,48,48,48,24,0,0,46,0,0,0,0
0,0,0,0,27,0,0,0,48,48,48,24,48,48,48,24,0,0,27,0,0,0,0
0,0,0,0,46,0,0,0,48,48,48,24,48,48,48,24,0,0,46,0,0,0,0
0,0,0,0,46,0,0,0,48,48,48,24,48,48,48,24,0,0,46,0,0,0,0
0,0,0,0,46,0,0,0,48,48,48,24,48,48,48,24,0,0,46,0,0,0,0
0,0,0,0,46,0,0,0,48,48,48,24,48,48,48,24,0,0,46,0,0,0,0
0,0,0,0,46,0,0,0,48,48,48,24,48,48,48,24,0,0,46,0,0,0,0
0,0,0,0,27,0,0,0,48,48,48,24,48,48,48,24,0,0,27,0,0,0,0
0,0,0,0,46,0,0,0,48,48,48,24,48,48,48,24,0,0,46,0,0,0,0
0,0,0,0,46,0,0,0,48,48,48,24,48,48,48,24,0,0,46,0,0,0,0
0,0,0,0,46,0,0,0,48,48,48,24,48,48,48,24,0,0,46,0,0,0,0
0,0,0,0,27,0,0,24,0,0,0,24,0,0,0,24,0,0,27,0,0,0,0
0,0,0,0,46,0,24,0,0,0,0,24,0,0,0,0,24,0,46,0,0,0,0
0,0,0,0,46,24,0,0,0,0,0,27,0,0,0,0,0,24,46,0,0,0,0
0,0,0,0,27,46,46,27,46,46,46,27,46,46,46,27,46,46,27,0,0,0,0
0,0,0,0,0,0,0,0,0,0,0,0,0,0,0,0,0,0,0,0,0,0,0
0,0,0,0,0,0,0,0,0,0,0,0,0,0,0,0,0,0,0,0,0,0,0
0,0,0,0,0,0,0,0,0,0,0,0,0,0,0,0,0,0,0,0,0,0,0
endlayer

layer
0,0,0,0,0,0,0,0,0,0,0,0,0,0,0,0,0,0,0,0,0,0,0
0,0,0,0,0,0,0,0,0,0,0,0,0,0,0,0,0,0,0,0,0,0,0
0,0,0,0,0,0,0,0,0,0,0,0,0,0,0,0,0,0,0,0,0,0,0
0,0,0,0,0,0,0,0,0,0,0,0,0,0,0,0,0,0,0,0,0,0,0
0,0,0,0,0,0,0,0,0,0,0,27,0,0,0,0,0,0,0,0,0,0,0
0,0,0,0,0,27,27,27,38,38,38,27,38,38,38,27,27,27,0,0,0,0,0
0,0,0,0,0,27,53,23,26,26,26,0,26,26,26,23,53,27,0,0,0,0,0
0,0,0,0,0,46,53,23,26,26,26,0,26,26,26,23,53,46,0,0,0,0,0
0,0,0,0,0,46,53,23,26,26,26,0,26,26,26,23,53,46,0,0,0,0,0
0,0,0,0,0,46,53,23,26,26,26,0,26,26,26,23,53,46,0,0,0,0,0
0,0,0,0,0,46,53,23,26,26,26,0,26,26,26,23,53,46,0,0,0,0,0
0,0,0,0,0,46,53,23,26,26,26,0,26,26,26,23,53,46,0,0,0,0,0
0,0,0,0,0,27,46,27,26,26,26,0,26,26,26,27,46,27,0,0,0,0,0
0,0,0,0,0,46,53,23,26,26,26,0,26,26,26,23,53,46,0,0,0,0,0
0,0,0,0,0,46,53,23,26,26,26,0,26,26,26,23,53,46,0,0,0,0,0
0,0,0,0,0,46,53,23,26,26,26,0,26,26,26,23,53,46,0,0,0,0,0
0,0,0,0,0,27,46,27,26,26,26,0,26,26,26,27,46,27,0,0,0,0,0
0,0,0,0,0,46,53,23,26,26,26,0,26,26,26,23,53,46,0,0,0,0,0
0,0,0,0,0,46,53,23,26,26,26,0,26,26,26,23,53,46,0,0,0,0,0
0,0,0,0,0,46,53,23,26,26,26,0,26,26,26,23,53,46,0,0,0,0,0
0,0,0,0,0,46,53,23,26,26,26,0,26,26,26,23,53,46,0,0,0,0,0
0,0,0,0,0,46,53,23,26,26,26,0,26,26,26,23,53,46,0,0,0,0,0
0,0,0,0,0,27,46,27,26,26,26,0,26,26,26,27,46,27,0,0,0,0,0
0,0,0,0,0,46,53,23,26,26,26,0,26,26,26,23,53,46,0,0,0,0,0
0,0,0,0,0,46,53,23,26,26,26,0,26,26,26,23,53,46,0,0,0,0,0
0,0,0,0,0,46,53,23,26,26,26,0,26,26,26,23,53,46,0,0,0,0,0
0,0,0,0,0,27,27,27,38,38,38,38,38,38,38,27,27,27,0,0,0,0,0
0,0,0,0,0,46,27,27,46,46,46,27,46,46,46,27,27,46,0,0,0,0,0
0,0,0,0,0,27,46,27,46,46,46,27,46,46,46,27,46,27,0,0,0,0,0
0,0,0,0,0,0,0,0,0,0,0,0,0,0,0,0,0,0,0,0,0,0,0
0,0,0,0,0,0,0,0,0,0,0,0,0,0,0,0,0,0,0,0,0,0,0
0,0,0,0,0,0,0,0,0,0,0,0,0,0,0,0,0,0,0,0,0,0,0
0,0,0,0,0,0,0,0,0,0,0,0,0,0,0,0,0,0,0,0,0,0,0
endlayer

layer
0,0,0,0,0,0,0,0,0,0,0,0,0,0,0,0,0,0,0,0,0,0,0
0,0,0,0,0,0,0,0,0,0,0,0,0,0,0,0,0,0,0,0,0,0,0
0,0,0,0,0,0,0,0,0,0,0,0,0,0,0,0,0,0,0,0,0,0,0
0,0,0,0,0,0,0,0,0,0,0,0,0,0,0,0,0,0,0,0,0,0,0
0,0,0,0,0,0,0,0,0,0,0,0,0,0,0,0,0,0,0,0,0,0,0
0,0,0,0,0,0,0,0,0,0,0,0,0,0,0,0,0,0,0,0,0,0,0
0,0,0,0,0,0,46,27,38,38,38,27,38,38,38,27,46,0,0,0,0,0,0
0,0,0,0,0,0,46,0,18,18,10,23,10,18,18,0,46,0,0,0,0,0,0
0,0,0,0,0,0,46,0,18,10,18,23,18,10,18,0,46,0,0,0,0,0,0
0,0,0,0,0,0,46,0,10,18,18,23,18,18,10,0,46,0,0,0,0,0,0
0,0,0,0,0,0,46,0,18,10,18,23,18,10,18,0,46,0,0,0,0,0,0
0,0,0,0,0,0,46,0,18,18,10,23,10,18,18,0,46,0,0,0,0,0,0
0,0,0,0,0,0,27,38,38,38,38,27,38,38,38,38,27,0,0,0,0,0,0
0,0,0,0,0,0,46,0,10,18,10,23,10,18,10,0,46,0,0,0,0,0,0
0,0,0,0,0,0,46,0,18,10,18,23,18,10,18,0,46,0,0,0,0,0,0
0,0,0,0,0,0,46,0,10,18,10,23,10,18,10,0,46,0,0,0,0,0,0
0,0,0,0,0,0,27,38,38,38,38,27,38,38,38,38,27,0,0,0,0,0,0
0,0,0,0,0,0,46,0,18,18,10,23,10,18,18,0,46,0,0,0,0,0,0
0,0,0,0,0,0,46,0,18,10,18,23,18,10,18,0,46,0,0,0,0,0,0
0,0,0,0,0,0,46,0,10,18,18,23,18,18,10,0,46,0,0,0,0,0,0
0,0,0,0,0,0,46,0,18,10,18,23,18,10,18,0,46,0,0,0,0,0,0
0,0,0,0,0,0,46,0,18,18,10,23,10,18,18,0,46,0,0,0,0,0,0
0,0,0,0,0,0,27,38,38,38,38,27,38,38,38,38,27,0,0,0,0,0,0
0,0,0,0,0,0,46,0,18,18,10,23,10,18,18,0,46,0,0,0,0,0,0
0,0,0,0,0,0,46,0,18,10,18,23,18,10,18,0,46,0,0,0,0,0,0
0,0,0,0,0,0,46,0,10,18,18,23,18,18,10,0,46,0,0,0,0,0,0
0,0,0,0,0,0,27,46,46,46,46,27,46,46,46,46,27,0,0,0,0,0,0
0,0,0,0,0,0,0,0,0,0,0,0,0,0,0,0,0,0,0,0,0,0,0
0,0,0,0,0,0,0,0,0,0,0,0,0,0,0,0,0,0,0,0,0,0,0
0,0,0,0,0,0,0,0,0,0,0,0,0,0,0,0,0,0,0,0,0,0,0
0,0,0,0,0,0,0,0,0,0,0,0,0,0,0,0,0,0,0,0,0,0,0
0,0,0,0,0,0,0,0,0,0,0,0,0,0,0,0,0,0,0,0,0,0,0
0,0,0,0,0,0,0,0,0,0,0,0,0,0,0,0,0,0,0,0,0,0,0
endlayer

