
# Created by Ruins mod version 15.1 Ingame Parser
# authoring Player: VikingWarlock

weight=100
embed_into_distance=22
acceptable_target_blocks=
unacceptable_target_blocks=flowing_water,water,flowing_lava,lava
dimensions=38,49,29
allowable_overhang=0
max_leveling=2
leveling_buffer=0
preserve_water=0
preserve_lava=0
uniqueMinDistance=1000000
preventRotation=1

rule1=0,100,preserveBlock
rule2=0,100,chisel:marble-0
rule3=0,100,chisel:marble-5
rule4=0,100,minecraft:quartz_block-0
rule5=0,100,chisel:glowstone-4
rule6=0,100,GardenStuff:lattice-0
rule7=0,100,chisel:marble_pillar-9
rule8=0,100,chisel:marble_pillar_slab-14
rule9=0,100,chisel:packedice_pillar-3
rule10=0,100,chisel:marble_pillar-8
rule11=0,100,IInventory;minecraft:chest;ExtrabiomesXL:saplings_1#1#2#0+minecraft:gold_ingot#1#0#2+minecraft:bone#1#0#4+minecraft:gold_ingot#1#0#6+minecraft:bone#1#0#9+minecraft:gold_ingot#1#0#10+minecraft:rotten_flesh#16#0#11+minecraft:gold_ingot#1#0#12+BiomesOPlenty:axeAmethyst#{RepairCost:2,ench:[0:{id:16s,lvl:5s,},1:{id:34s,lvl:3s,},2:{id:20s,lvl:1s,},],display:{Name:\"Ragnarok's Rejection\",},}#0#13+minecraft:gold_ingot#1#0#14+minecraft:rotten_flesh#16#0#15+minecraft:gold_ingot#1#0#16+minecraft:bone#1#0#17+minecraft:gold_ingot#1#0#20+minecraft:bone#1#0#22+minecraft:gold_ingot#1#0#24-4
rule12=0,100,chisel:marble-10
rule13=0,100,IInventory;minecraft:chest;minecraft:bone#1#0#0+minecraft:bone#1#0#4+minecraft:string#1#0#5+minecraft:string#3#0#6+minecraft:bone#1#0#8+minecraft:bone#1#0#11+dendrology:sapling0#1#0#12+minecraft:stone_sword#{RepairCost:2,ench:[0:{id:34s,lvl:2s,},1:{id:16s,lvl:3s,},],display:{Name:\"Baldr's Blade\",},}#35#13+dendrology:sapling0#1#0#14+minecraft:bone#1#0#15+minecraft:bone#1#0#18+minecraft:bone#1#0#22+minecraft:bone#1#0#26-4
rule14=0,100,chisel:carpet-0
rule15=0,100,chisel:marble-11
rule16=0,100,chisel:packedice_stairs.5-2
rule17=0,100,chisel:packedice_stairs.5-0
rule18=0,100,chisel:packedice_stairs.5-3
rule19=0,100,chisel:packedice_pillar-6
rule20=0,100,chisel:packedice_stairs.5-1
rule21=0,100,chisel:marble_slab-5
rule22=0,100,chisel:fantasyblock-8
rule23=0,100,ExtrabiomesXL:log1-2
rule24=0,100,chisel:packedice-10
rule25=0,100,minecraft:water-0
rule26=0,100,chisel:packedice-3
rule27=0,100,ExtrabiomesXL:leaves_1-13
rule28=0,100,chisel:glowstone-10
rule29=0,100,chisel:packedice_stairs.6-8
rule30=0,100,chisel:packedice_stairs.6-11
rule31=0,100,chisel:packedice_stairs.6-10
rule32=0,100,chisel:fantasyblock2-7
rule33=0,100,chisel:packedice_stairs.6-9
rule34=0,100,chisel:marble_stairs.0-14
rule35=0,100,chisel:marble-9
rule36=0,100,chisel:marble_stairs.0-15
rule37=0,100,chisel:marble_stairs.0-9
rule38=0,100,chisel:packedice_pillar-4
rule39=0,100,ExtrabiomesXL:leaves_1-5
rule40=0,100,chisel:marble_stairs.0-11
rule41=0,100,chisel:marble_stairs.0-10
rule42=0,100,chisel:packedice-15
rule43=0,100,chisel:marble_stairs.1-11
rule44=0,100,chisel:marble_stairs.1-10
rule45=0,100,GardenStuff:light_chain-4
rule46=0,100,chisel:marble_stairs.2-11
rule47=0,100,chisel:marble_stairs.2-10
rule48=0,100,chisel:packedice-13
rule49=0,100,chisel:marble_pillar_slab_top-14
rule50=0,100,chisel:marble_stairs.0-8
rule51=0,100,chisel:marble_stairs.2-8
rule52=0,100,chisel:marble-2
rule53=0,100,chisel:ice-13
rule54=0,100,GardenStuff:heavy_chain-4
rule55=0,100,chisel:marble_slab_top-3
rule56=0,100,chisel:packedice_stairs.6-13
rule57=0,100,chisel:packedice_stairs.7-12
rule58=0,100,chisel:packedice_stairs.7-14
rule59=0,100,minecraft:dirt-0
rule60=0,100,chisel:packedice_stairs.7-15
rule61=0,100,chisel:packedice_stairs.7-13
rule62=0,100,chisel:marble_pillar-14
rule63=0,100,minecraft:trapdoor-6
rule64=0,100,minecraft:trapdoor-4
rule65=0,100,minecraft:grass-0
rule66=0,100,minecraft:trapdoor-5
rule67=0,100,chisel:marble_slab_top-4
rule68=0,100,chisel:marble_stairs.1-8
rule69=0,100,chisel:marble_stairs.0-13
rule70=0,100,BiomesOPlenty:flowers-3
rule71=0,100,chisel:marble_slab-3
rule72=0,100,chisel:marble-3
rule73=0,100,chisel:marble-4
rule74=0,100,chisel:packedice_stairs.6-12
rule75=0,100,chisel:packedice_stairs.6-14
rule76=0,100,chisel:packedice_stairs.6-15
rule77=0,100,chisel:iron_bars-7
rule78=0,100,chisel:marble_stairs.0-12
rule79=0,100,chisel:marble_slab-4
rule80=0,100,chisel:packedice_stairs.3-5
rule81=0,100,UndergroundBiomes:sedimentaryStoneHalfSlab-12
rule82=0,100,chisel:packedice_stairs.3-7
rule83=0,100,chisel:packedice_stairs.3-6
rule84=0,100,UndergroundBiomes:sedimentaryStoneFullSlab-4
rule85=0,100,chisel:packedice_stairs.3-4
rule86=0,100,minecraft:snow-0
rule87=0,100,BiomesOPlenty:leaves1-7
rule88=0,100,BiomesOPlenty:leaves1-15
rule89=0,100,chisel:marble-1
rule90=0,100,chisel:marble_stairs.2-9
rule91=0,100,GardenStuff:fence-3
rule92=0,100,BiomesOPlenty:logs1-2
rule93=0,100,minecraft:tallgrass-1
rule94=0,100,BiomesOPlenty:leaves1-3
rule95=0,100,chisel:packedice_stairs.5-6
rule96=0,100,chisel:packedice_stairs.5-4
rule97=0,100,chisel:packedice_stairs.5-7
rule98=0,100,chisel:marble_stairs.2-15
rule99=0,100,chisel:marble_stairs.2-13
rule100=0,100,chisel:marble_stairs.2-14
rule101=0,100,chisel:marble_slab_top-10
rule102=0,100,chisel:marble_stairs.2-12
rule103=0,100,chisel:packedice_stairs.5-5
rule104=0,100,dendrology:leaves2-6
rule105=0,100,dendrology:leaves2-14
rule106=0,100,BiomesOPlenty:leaves4-13
rule107=0,100,IInventory;minecraft:chest;minecraft:experience_bottle#1#0#0+minecraft:experience_bottle#1#0#3+minecraft:experience_bottle#1#0#5+minecraft:experience_bottle#1#0#7+minecraft:experience_bottle#1#0#10+eplus:item.tableUpgrade#1#0#13+minecraft:experience_bottle#1#0#18+BiblioCraft:Armor Stand#1#0#21+minecraft:experience_bottle#1#0#23+minecraft:experience_bottle#1#0#25+minecraft:experience_bottle#1#0#26-4

layer
1,1,1,1,1,1,1,1,1,1,1,1,1,1,1,1,1,1,1,1,1,1,1,1,1,1,1,1,1
1,2,2,2,2,2,2,2,2,2,2,2,2,2,2,2,2,2,2,2,2,2,2,2,2,2,2,2,1
1,2,3,3,3,3,3,3,3,3,3,3,3,3,3,3,3,3,3,3,3,3,3,3,3,3,3,2,1
1,2,3,3,3,3,3,3,3,3,3,3,3,3,3,3,3,3,3,3,3,3,3,3,3,3,3,2,1
1,2,3,3,3,3,3,3,3,3,3,3,3,3,3,3,3,3,3,3,3,3,3,3,3,3,3,2,1
1,2,3,3,3,4,3,3,3,3,3,3,3,3,3,3,3,3,3,3,3,3,3,4,3,3,3,2,1
1,2,3,3,3,3,4,3,3,3,3,3,3,3,3,3,3,3,3,3,3,3,4,3,3,3,3,2,1
1,2,3,3,3,3,3,3,3,3,3,3,3,3,3,3,3,3,3,3,3,3,3,3,3,3,3,2,1
1,2,3,3,3,3,3,3,3,3,3,3,3,3,3,3,3,3,3,3,3,3,3,3,3,3,3,2,1
1,2,3,3,3,3,3,3,3,3,3,3,3,3,3,3,3,3,3,3,3,3,3,3,3,3,3,2,1
1,2,3,3,3,3,3,3,3,3,3,3,3,3,3,3,3,3,3,3,3,3,3,3,3,3,3,2,1
1,2,3,3,3,3,3,3,3,3,3,3,3,3,3,3,3,3,3,3,3,3,3,3,3,3,3,2,1
1,2,3,3,3,3,3,3,3,3,3,3,3,3,3,3,3,3,3,3,3,3,3,3,3,3,3,2,1
1,2,3,3,3,3,3,3,3,3,3,3,3,3,3,3,3,3,3,3,3,3,3,3,3,3,3,2,1
1,2,3,3,3,3,3,3,3,3,3,3,3,3,3,3,3,3,3,3,3,3,3,3,3,3,3,2,1
1,2,3,3,3,3,3,3,3,3,3,3,3,3,3,3,3,3,3,3,3,3,3,3,3,3,3,2,1
1,2,3,3,3,3,3,3,3,3,3,3,3,3,3,3,3,3,3,3,3,3,3,3,3,3,3,2,1
1,2,3,3,3,3,3,3,3,3,3,3,3,3,3,3,3,3,3,3,3,3,3,3,3,3,3,2,1
1,2,3,3,3,3,3,3,3,3,3,3,3,3,5,3,3,3,3,3,3,3,3,3,3,3,3,2,1
1,2,3,3,3,3,3,3,3,3,3,3,3,3,3,3,3,3,3,3,3,3,3,3,3,3,3,2,1
1,2,3,3,3,3,3,3,3,3,3,3,3,3,3,3,3,3,3,3,3,3,3,3,3,3,3,2,1
1,2,3,3,3,3,3,3,3,3,3,3,3,3,3,3,3,3,3,3,3,3,3,3,3,3,3,2,1
1,2,3,3,3,3,3,3,3,3,3,3,3,3,3,3,3,3,3,3,3,3,3,3,3,3,3,2,1
1,2,3,3,3,3,3,3,3,3,3,3,3,3,3,3,3,3,3,3,3,3,3,3,3,3,3,2,1
1,2,3,3,3,3,3,3,3,3,3,3,3,3,3,3,3,3,3,3,3,3,3,3,3,3,3,2,1
1,2,3,3,3,3,3,3,3,3,3,3,3,3,3,3,3,3,3,3,3,3,3,3,3,3,3,2,1
1,2,3,3,3,3,3,3,3,3,3,3,3,3,3,3,3,3,3,3,3,3,3,3,3,3,3,2,1
1,2,3,3,3,3,3,3,3,3,3,3,3,3,3,3,3,3,3,3,3,3,3,3,3,3,3,2,1
1,2,3,3,3,3,3,3,3,3,3,3,3,3,5,3,3,3,3,3,3,3,3,3,3,3,3,2,1
1,2,3,3,3,3,3,3,3,3,3,3,3,3,3,3,3,3,3,3,3,3,3,3,3,3,3,2,1
1,2,3,3,3,3,3,3,3,3,3,3,3,3,3,3,3,3,3,3,3,3,3,3,3,3,3,2,1
1,2,3,3,3,3,3,3,3,3,3,3,3,3,3,3,3,3,3,3,3,3,3,3,3,3,3,2,1
1,2,3,3,3,3,3,3,3,3,3,3,3,3,3,3,3,3,3,3,3,3,3,3,3,3,3,2,1
1,2,3,3,3,3,3,3,3,3,3,3,3,3,3,3,3,3,3,3,3,3,3,3,3,3,3,2,1
1,2,3,3,3,3,3,3,3,3,3,3,3,3,3,3,3,3,3,3,3,3,3,3,3,3,3,2,1
1,2,3,3,3,3,3,3,3,3,3,3,3,3,3,3,3,3,3,3,3,3,3,3,3,3,3,2,1
1,2,3,3,3,3,3,3,3,3,3,3,3,3,3,3,3,3,3,3,3,3,3,3,3,3,3,2,1
1,2,3,3,3,3,3,3,3,3,3,3,3,3,3,3,3,3,3,3,3,3,3,3,3,3,3,2,1
1,2,3,3,3,3,3,3,3,3,3,3,3,3,3,3,3,3,3,3,3,3,3,3,3,3,3,2,1
1,2,3,3,3,3,3,3,3,3,3,3,3,3,3,3,3,3,3,3,3,3,3,3,3,3,3,2,1
1,2,3,3,3,3,3,3,3,3,3,3,3,3,3,3,3,3,3,3,3,3,3,3,3,3,3,2,1
1,2,3,3,3,3,4,3,3,3,3,3,3,3,3,3,3,3,3,3,3,3,4,3,3,3,3,2,1
1,2,3,3,3,4,3,3,3,3,3,3,3,3,3,3,3,3,3,3,3,3,3,4,3,3,3,2,1
1,2,3,3,4,3,3,3,3,3,3,3,3,3,3,3,3,3,3,3,3,3,3,3,4,3,3,2,1
1,2,3,4,3,3,3,3,3,3,3,3,3,3,3,3,3,3,3,3,3,3,3,3,3,4,3,2,1
1,2,4,3,3,3,3,3,3,3,3,3,3,3,3,3,3,3,3,3,3,3,3,3,3,3,4,2,1
1,2,2,2,2,2,2,2,2,2,2,2,2,2,2,2,2,2,2,2,2,2,2,2,2,2,2,2,1
1,2,2,2,2,2,2,2,2,2,2,2,2,2,2,2,2,2,2,2,2,2,2,2,2,2,2,2,1
1,1,1,1,1,1,1,1,1,1,1,1,1,1,1,1,1,1,1,1,1,1,1,1,1,1,1,1,1
endlayer

layer
1,1,1,1,1,1,1,1,1,1,1,1,1,1,1,1,1,1,1,1,1,1,1,1,1,1,1,1,1
1,2,2,2,2,2,2,2,2,2,2,2,2,2,2,2,2,2,2,2,2,2,2,2,2,2,2,2,1
1,2,0,0,0,0,0,0,0,0,0,0,0,0,0,0,0,0,0,0,0,0,0,0,0,0,0,2,1
1,2,0,0,0,0,0,0,0,0,0,0,0,0,0,0,0,0,0,0,0,0,0,0,0,0,0,2,1
1,2,0,0,0,6,10,8,9,0,0,0,0,0,0,0,0,0,0,0,9,8,7,6,0,0,0,2,1
1,2,13,9,8,10,0,10,8,12,0,0,0,0,0,0,0,0,0,12,8,7,0,7,8,9,11,2,1
1,2,9,8,10,0,10,8,14,8,9,0,0,0,0,0,0,0,9,8,14,8,7,0,7,8,9,2,1
1,2,8,14,8,10,8,14,0,14,8,15,0,0,0,0,0,15,8,14,0,14,8,7,8,14,8,2,1
1,2,0,0,14,8,14,0,0,0,14,8,9,0,0,0,9,8,14,0,0,0,14,8,14,0,0,2,1
1,2,0,0,0,0,0,0,0,0,0,14,8,7,0,7,8,14,0,0,0,0,0,0,0,0,0,2,1
1,2,0,0,0,0,0,0,0,0,0,0,14,8,0,8,14,0,0,0,0,0,0,0,0,0,0,2,1
1,2,0,0,18,17,17,0,0,0,0,0,0,0,0,0,0,0,0,0,0,0,17,17,16,0,0,2,1
1,2,0,0,18,19,16,0,0,0,0,0,0,0,0,0,0,0,0,0,0,0,18,19,16,0,0,2,1
1,2,0,0,18,20,16,0,0,0,0,0,0,0,0,0,0,0,0,0,0,0,18,20,16,0,0,2,1
1,2,0,0,0,0,0,0,0,0,0,0,0,0,0,0,0,0,0,0,0,0,0,0,0,0,0,2,1
1,2,0,0,0,0,0,0,0,0,0,21,21,21,21,21,21,21,0,0,0,0,0,0,0,0,0,2,1
1,2,0,0,0,0,0,0,0,0,21,22,22,22,22,22,22,22,21,0,0,0,0,0,0,0,0,2,1
1,2,9,0,0,0,0,0,0,21,22,23,23,23,23,23,23,23,22,21,0,0,0,0,0,0,9,2,1
1,2,24,9,0,0,0,0,21,22,23,23,25,25,25,25,25,23,23,22,21,0,0,0,0,9,24,2,1
1,2,9,0,0,0,0,21,22,23,23,25,25,26,26,26,25,25,23,23,22,21,0,0,0,0,9,2,1
1,2,0,0,0,0,0,21,22,23,25,25,26,27,27,27,26,25,25,23,22,21,0,0,0,0,0,2,1
1,2,0,0,0,0,0,21,22,23,25,26,27,27,25,27,27,26,25,23,22,21,0,0,0,0,0,2,1
1,2,0,0,0,0,0,21,22,23,25,26,27,25,25,25,27,26,25,23,22,21,0,0,0,0,0,2,1
1,2,0,0,0,0,0,21,22,28,25,26,27,25,22,25,27,26,25,28,22,21,0,0,0,0,0,2,1
1,2,0,0,0,0,0,21,22,23,25,26,27,25,25,25,27,26,25,23,22,21,0,0,0,0,0,2,1
1,2,0,0,0,0,0,21,22,23,25,26,27,27,25,27,27,26,25,23,22,21,0,0,0,0,0,2,1
1,2,0,0,0,0,0,21,22,23,25,25,26,27,27,27,26,25,25,23,22,21,0,0,0,0,0,2,1
1,2,9,0,0,0,0,21,22,23,23,25,25,26,26,26,25,25,23,23,22,21,0,0,0,0,9,2,1
1,2,24,9,0,0,0,0,21,22,23,23,25,25,25,25,25,23,23,22,21,0,0,0,0,9,24,2,1
1,2,9,0,0,0,0,0,0,21,22,23,23,23,23,23,23,23,22,21,0,0,0,0,0,0,9,2,1
1,2,0,0,0,0,0,0,0,0,21,22,22,22,22,22,22,22,21,0,0,0,0,0,0,0,0,2,1
1,2,0,0,0,0,0,0,0,0,0,21,21,21,21,21,21,21,0,0,0,0,0,0,0,0,0,2,1
1,2,0,0,0,0,0,0,0,0,0,0,0,0,0,0,0,0,0,0,0,0,0,0,0,0,0,2,1
1,2,0,0,0,0,0,0,0,0,0,0,0,0,0,0,0,0,0,0,0,0,0,0,0,0,0,2,1
1,2,0,0,0,0,30,29,29,0,0,0,0,0,0,0,0,0,0,29,29,29,0,0,0,0,0,2,1
1,2,0,0,0,0,30,32,31,0,0,0,0,0,0,0,0,0,0,30,32,31,0,0,0,0,0,2,1
1,2,0,0,0,0,30,33,31,0,0,0,0,0,0,0,0,0,0,33,33,31,0,0,0,0,0,2,1
1,2,0,0,0,0,0,0,0,0,0,0,0,0,0,0,0,0,0,0,0,0,0,0,0,0,0,2,1
1,2,0,0,0,0,0,0,0,0,0,0,0,0,15,0,0,0,0,0,0,0,0,0,0,0,0,2,1
1,2,0,0,0,8,0,0,0,0,0,0,36,35,3,35,34,0,0,0,0,0,0,8,0,0,0,2,1
1,2,0,0,8,10,8,0,0,0,0,0,36,3,3,3,34,0,0,0,0,0,8,10,8,0,0,2,1
1,2,0,8,10,0,10,8,0,0,0,0,0,3,3,3,0,0,0,0,0,8,10,0,10,8,0,2,1
1,2,0,0,8,10,0,10,8,0,0,0,0,3,3,3,0,0,0,0,8,10,0,10,8,0,0,2,1
1,2,0,0,0,8,10,8,0,0,0,0,0,37,37,37,0,0,0,0,0,8,10,8,0,0,0,2,1
1,2,0,0,0,0,8,0,0,0,0,0,0,0,0,0,0,0,0,0,0,0,8,0,0,0,0,2,1
1,2,0,0,0,0,0,0,0,0,0,0,0,0,0,0,0,0,0,0,0,0,0,0,0,0,0,2,1
1,2,2,2,2,2,2,2,2,2,2,2,2,2,2,2,2,2,2,2,2,2,2,2,2,2,2,2,1
1,2,2,2,2,2,2,2,2,2,2,2,2,2,2,2,2,2,2,2,2,2,2,2,2,2,2,2,1
1,1,1,1,1,1,1,1,1,1,1,1,1,1,1,1,1,1,1,1,1,1,1,1,1,1,1,1,1
endlayer

layer
1,1,1,1,1,1,1,1,1,1,1,1,1,1,1,1,1,1,1,1,1,1,1,1,1,1,1,1,1
1,2,2,2,2,2,2,2,2,2,2,2,2,2,2,2,2,2,2,2,2,2,2,2,2,2,2,2,1
1,2,0,0,0,0,0,0,0,0,0,0,0,0,0,0,0,0,0,0,0,0,0,0,0,0,0,2,1
1,2,0,0,0,0,0,0,0,0,0,0,0,0,0,0,0,0,0,0,0,0,0,0,0,0,0,2,1
1,2,0,0,0,6,10,0,9,0,0,0,0,0,0,0,0,0,0,0,9,0,7,6,0,0,0,2,1
1,2,8,9,0,10,0,10,0,12,0,0,0,0,0,0,0,0,0,12,0,7,0,7,0,9,8,2,1
1,2,9,0,10,0,10,0,0,0,9,0,0,0,0,0,0,0,9,0,0,0,7,0,7,0,9,2,1
1,2,0,0,0,10,0,0,0,0,0,15,0,0,0,0,0,15,0,0,0,0,0,7,0,0,0,2,1
1,2,0,0,0,0,0,0,0,0,0,0,9,0,0,0,9,0,0,0,0,0,0,0,0,0,0,2,1
1,2,0,0,0,0,0,0,0,0,0,0,0,7,0,7,0,0,0,0,0,0,0,0,0,0,0,2,1
1,2,0,0,0,0,0,0,0,0,0,0,0,0,0,0,0,0,0,0,0,0,0,0,0,0,0,2,1
1,2,0,0,0,0,0,0,0,0,0,0,0,0,0,0,0,0,0,0,0,0,0,0,0,0,0,2,1
1,2,0,0,0,5,0,0,0,0,0,0,0,0,0,0,0,0,0,0,0,0,0,5,0,0,0,2,1
1,2,0,0,0,0,0,0,0,0,0,0,0,0,0,0,0,0,0,0,0,0,0,0,0,0,0,2,1
1,2,0,0,0,0,0,0,0,0,0,0,0,0,0,0,0,0,0,0,0,0,0,0,0,0,0,2,1
1,2,0,0,0,0,0,0,0,0,0,0,0,0,0,0,0,0,0,0,0,0,0,0,0,0,0,2,1
1,2,0,0,0,0,0,0,0,0,0,0,0,0,0,0,0,0,0,0,0,0,0,0,0,0,0,2,1
1,2,38,0,0,0,0,0,0,0,0,27,27,27,27,27,27,27,0,0,0,0,0,0,0,0,38,2,1
1,2,24,9,0,0,0,0,0,0,27,27,0,0,0,0,0,27,27,0,0,0,0,0,0,9,24,2,1
1,2,38,0,0,0,0,0,0,27,27,0,0,0,0,0,0,0,27,27,0,0,0,0,0,0,38,2,1
1,2,0,0,0,0,0,0,0,27,0,0,0,0,0,0,0,0,0,27,0,0,0,0,0,0,0,2,1
1,2,0,0,0,0,0,0,0,27,0,0,0,0,0,0,0,0,0,27,0,0,0,0,0,0,0,2,1
1,2,0,0,0,0,0,0,0,27,0,0,0,0,0,0,0,0,0,27,0,0,0,0,0,0,0,2,1
1,2,0,0,0,0,0,0,0,27,0,0,0,0,32,0,0,0,0,27,0,0,0,0,0,0,0,2,1
1,2,0,0,0,0,0,0,0,27,0,0,0,0,0,0,0,0,0,27,0,0,0,0,0,0,0,2,1
1,2,0,0,0,0,0,0,0,27,0,0,0,0,0,0,0,0,0,27,0,0,0,0,0,0,0,2,1
1,2,0,0,0,0,0,0,0,27,0,0,0,0,0,0,0,0,0,27,0,0,0,0,0,0,0,2,1
1,2,38,0,0,0,0,0,0,27,27,0,0,0,0,0,0,0,27,27,0,0,0,0,0,0,38,2,1
1,2,24,9,0,0,0,0,0,0,27,27,0,0,0,0,0,27,27,0,0,0,0,0,0,9,24,2,1
1,2,38,0,0,0,0,0,0,0,0,27,27,27,27,27,27,27,0,0,0,0,0,0,0,0,38,2,1
1,2,0,0,0,0,0,0,0,0,0,0,0,0,0,0,0,0,0,0,0,0,0,0,0,0,0,2,1
1,2,0,0,0,0,0,0,0,0,0,0,0,0,0,0,0,0,0,0,0,0,0,0,0,0,0,2,1
1,2,0,0,0,0,0,0,0,0,0,0,0,0,0,0,0,0,0,0,0,0,0,0,0,0,0,2,1
1,2,0,0,0,0,0,0,0,0,0,0,0,0,0,0,0,0,0,0,0,0,0,0,0,0,0,2,1
1,2,0,0,0,0,27,39,39,0,0,0,0,0,0,0,0,0,0,39,39,39,0,0,0,0,0,2,1
1,2,0,0,0,0,27,5,39,0,0,0,0,0,0,0,0,0,0,39,5,27,0,0,0,0,0,2,1
1,2,0,0,0,0,39,39,39,0,0,0,0,0,0,0,0,0,0,39,39,39,0,0,0,0,0,2,1
1,2,0,0,0,0,0,0,0,0,0,0,0,0,0,0,0,0,0,0,0,0,0,0,0,0,0,2,1
1,2,0,0,0,0,0,0,0,0,0,0,6,6,15,6,6,6,0,0,0,0,0,0,0,0,0,2,1
1,2,0,0,0,0,0,0,0,0,0,36,35,41,0,40,35,34,0,0,0,0,0,0,0,0,0,2,1
1,2,0,0,0,10,0,0,0,0,0,36,35,41,0,40,35,34,0,0,0,0,0,10,0,0,0,2,1
1,2,0,0,10,0,10,0,0,0,0,0,0,0,0,0,0,0,0,0,0,0,10,0,10,0,0,2,1
1,2,0,0,0,10,0,10,0,0,0,0,0,0,0,0,0,0,0,0,0,10,0,10,0,0,0,2,1
1,2,0,0,0,0,10,0,0,0,0,0,0,0,0,0,0,0,0,0,0,0,10,0,0,0,0,2,1
1,2,0,0,0,0,0,0,0,0,0,0,0,0,0,0,0,0,0,0,0,0,0,0,0,0,0,2,1
1,2,0,0,0,0,0,0,0,0,0,0,0,0,0,0,0,0,0,0,0,0,0,0,0,0,0,2,1
1,2,2,2,2,2,2,2,2,2,2,2,2,2,2,2,2,2,2,2,2,2,2,2,2,2,2,2,1
1,2,2,2,2,2,2,2,2,2,2,2,2,2,2,2,2,2,2,2,2,2,2,2,2,2,2,2,1
1,1,1,1,1,1,1,1,1,1,1,1,1,1,1,1,1,1,1,1,1,1,1,1,1,1,1,1,1
endlayer

layer
1,1,1,1,1,1,1,1,1,1,1,1,1,1,1,1,1,1,1,1,1,1,1,1,1,1,1,1,1
1,2,2,2,2,2,2,2,2,2,2,2,2,2,2,2,2,2,2,2,2,2,2,2,2,2,2,2,1
1,2,0,0,0,0,0,0,0,0,0,0,0,0,0,0,0,0,0,0,0,0,0,0,0,0,0,2,1
1,2,0,0,0,0,0,0,0,0,0,0,0,0,0,0,0,0,0,0,0,0,0,0,0,0,0,2,1
1,2,0,0,0,6,10,0,9,0,0,0,0,0,0,0,0,0,0,0,9,0,7,6,0,0,0,2,1
1,2,8,9,0,10,0,10,0,12,0,0,0,0,0,0,0,0,0,12,0,7,5,7,0,9,8,2,1
1,2,9,0,10,0,10,0,0,0,9,0,0,0,0,0,0,0,9,0,0,0,7,5,7,0,9,2,1
1,2,0,0,0,10,0,0,0,0,0,15,0,0,0,0,0,15,0,0,0,0,0,7,0,0,0,2,1
1,2,0,0,0,0,0,0,0,0,0,0,9,0,0,0,9,0,0,0,0,0,0,0,0,0,0,2,1
1,2,0,0,0,0,0,0,0,0,0,0,0,7,0,7,0,0,0,0,0,0,0,0,0,0,0,2,1
1,2,0,0,0,0,0,0,0,0,0,0,0,0,0,0,0,0,0,0,0,0,0,0,0,0,0,2,1
1,2,0,0,0,0,0,0,0,0,0,0,0,0,0,0,0,0,0,0,0,0,0,0,0,0,0,2,1
1,2,0,0,0,42,0,0,0,0,0,0,0,0,0,0,0,0,0,0,0,0,0,42,0,0,0,2,1
1,2,0,0,0,0,0,0,0,0,0,0,0,0,0,0,0,0,0,0,0,0,0,0,0,0,0,2,1
1,2,0,0,0,0,0,0,0,0,0,0,0,0,0,0,0,0,0,0,0,0,0,0,0,0,0,2,1
1,2,0,0,0,0,0,0,0,0,0,0,0,0,0,0,0,0,0,0,0,0,0,0,0,0,0,2,1
1,2,0,0,0,0,0,0,0,0,0,0,0,0,0,0,0,0,0,0,0,0,0,0,0,0,0,2,1
1,2,38,0,0,0,0,0,0,0,0,0,0,0,0,0,0,0,0,0,0,0,0,0,0,0,38,2,1
1,2,24,9,0,0,0,0,0,0,0,0,0,0,0,0,0,0,0,0,0,0,0,0,0,9,24,2,1
1,2,38,0,0,0,0,0,0,0,0,0,0,0,0,0,0,0,0,0,0,0,0,0,0,0,38,2,1
1,2,0,0,0,0,0,0,0,0,0,0,0,0,0,0,0,0,0,0,0,0,0,0,0,0,0,2,1
1,2,0,0,0,0,0,0,0,0,0,0,0,0,0,0,0,0,0,0,0,0,0,0,0,0,0,2,1
1,2,0,0,0,0,0,0,0,0,0,0,0,0,0,0,0,0,0,0,0,0,0,0,0,0,0,2,1
1,2,0,0,0,0,0,0,0,0,0,0,0,0,32,0,0,0,0,0,0,0,0,0,0,0,0,2,1
1,2,0,0,0,0,0,0,0,0,0,0,0,0,0,0,0,0,0,0,0,0,0,0,0,0,0,2,1
1,2,0,0,0,0,0,0,0,0,0,0,0,0,0,0,0,0,0,0,0,0,0,0,0,0,0,2,1
1,2,0,0,0,0,0,0,0,0,0,0,0,0,0,0,0,0,0,0,0,0,0,0,0,0,0,2,1
1,2,38,0,0,0,0,0,0,0,0,0,0,0,0,0,0,0,0,0,0,0,0,0,0,0,38,2,1
1,2,24,9,0,0,0,0,0,0,0,0,0,0,0,0,0,0,0,0,0,0,0,0,0,9,24,2,1
1,2,38,0,0,0,0,0,0,0,0,0,0,0,0,0,0,0,0,0,0,0,0,0,0,0,38,2,1
1,2,0,0,0,0,0,0,0,0,0,0,0,0,0,0,0,0,0,0,0,0,0,0,0,0,0,2,1
1,2,0,0,0,0,0,0,0,0,0,0,0,0,0,0,0,0,0,0,0,0,0,0,0,0,0,2,1
1,2,0,0,0,0,0,0,0,0,0,0,0,0,0,0,0,0,0,0,0,0,0,0,0,0,0,2,1
1,2,0,0,0,0,0,0,0,0,0,0,0,0,0,0,0,0,0,0,0,0,0,0,0,0,0,2,1
1,2,0,0,0,0,0,0,0,0,0,0,0,0,0,0,0,0,0,0,0,0,0,0,0,0,0,2,1
1,2,0,0,0,0,0,32,0,0,0,0,0,0,0,0,0,0,0,0,32,0,0,0,0,0,0,2,1
1,2,0,0,0,0,0,0,0,0,0,0,0,0,0,0,0,0,0,0,0,0,0,0,0,0,0,2,1
1,2,0,0,0,0,0,0,0,0,0,0,0,0,0,0,0,0,0,0,0,0,0,0,0,0,0,2,1
1,2,0,0,0,0,0,0,0,0,0,0,6,6,15,6,6,6,0,0,0,0,0,0,0,0,0,2,1
1,2,0,0,0,0,0,0,0,0,0,40,44,0,0,0,43,41,0,0,0,0,0,0,0,0,0,2,1
1,2,0,0,0,10,0,0,0,0,0,40,44,0,0,0,43,41,0,0,0,0,0,10,0,0,0,2,1
1,2,0,0,10,0,10,0,0,0,0,0,0,0,0,0,0,0,0,0,0,0,10,0,10,0,0,2,1
1,2,0,0,0,10,0,10,0,0,0,0,0,0,0,0,0,0,0,0,0,10,0,10,0,0,0,2,1
1,2,0,0,0,0,10,0,0,0,0,0,0,0,0,0,0,0,0,0,0,0,10,0,0,0,0,2,1
1,2,0,0,0,0,0,0,0,0,0,0,0,0,0,0,0,0,0,0,0,0,0,0,0,0,0,2,1
1,2,0,0,0,0,0,0,0,0,0,0,0,0,0,0,0,0,0,0,0,0,0,0,0,0,0,2,1
1,2,2,2,2,2,2,2,2,2,2,2,2,2,2,2,2,2,2,2,2,2,2,2,2,2,2,2,1
1,2,2,2,2,2,2,2,2,2,2,2,2,2,2,2,2,2,2,2,2,2,2,2,2,2,2,2,1
1,1,1,1,1,1,1,1,1,1,1,1,1,1,1,1,1,1,1,1,1,1,1,1,1,1,1,1,1
endlayer

layer
1,1,1,1,1,1,1,1,1,1,1,1,1,1,1,1,1,1,1,1,1,1,1,1,1,1,1,1,1
1,2,2,2,2,2,2,2,2,2,2,2,2,2,2,2,2,2,2,2,2,2,2,2,2,2,2,2,1
1,2,0,0,0,0,0,0,0,0,0,0,0,0,0,0,0,0,0,0,0,0,0,0,0,0,0,2,1
1,2,0,0,0,0,0,0,0,0,0,0,0,0,0,0,0,0,0,0,0,0,0,0,0,0,0,2,1
1,2,0,0,0,6,10,0,9,0,0,0,0,0,0,0,0,0,0,0,9,0,7,6,0,0,0,2,1
1,2,8,9,0,10,5,10,0,12,0,0,0,0,0,0,0,0,0,12,0,7,0,7,0,9,8,2,1
1,2,9,0,10,5,10,0,0,0,9,0,0,0,0,0,0,0,9,0,0,0,7,0,7,0,9,2,1
1,2,0,0,0,10,0,0,0,0,0,15,0,0,0,0,0,15,0,0,0,0,0,7,0,0,0,2,1
1,2,0,0,0,0,0,0,0,0,0,0,9,0,0,0,9,0,0,0,0,0,0,0,0,0,0,2,1
1,2,0,0,0,0,0,0,0,0,0,0,0,7,0,7,0,0,0,0,0,0,0,0,0,0,0,2,1
1,2,0,0,0,0,0,0,0,0,0,0,0,0,0,0,0,0,0,0,0,0,0,0,0,0,0,2,1
1,2,0,0,0,0,0,0,0,0,0,0,0,0,0,0,0,0,0,0,0,0,0,0,0,0,0,2,1
1,2,0,0,0,45,0,0,0,0,0,0,0,0,0,0,0,0,0,0,0,0,0,45,0,0,0,2,1
1,2,0,0,0,0,0,0,0,0,0,0,0,0,0,0,0,0,0,0,0,0,0,0,0,0,0,2,1
1,2,0,0,0,0,0,0,0,0,0,0,0,0,0,0,0,0,0,0,0,0,0,0,0,0,0,2,1
1,2,0,0,0,0,0,0,0,0,0,0,0,0,0,0,0,0,0,0,0,0,0,0,0,0,0,2,1
1,2,0,0,0,0,0,0,0,0,0,0,0,0,0,0,0,0,0,0,0,0,0,0,0,0,0,2,1
1,2,38,0,0,0,0,0,0,0,0,0,0,0,0,0,0,0,0,0,0,0,0,0,0,0,38,2,1
1,2,24,9,0,0,0,0,0,0,0,0,0,0,0,0,0,0,0,0,0,0,0,0,0,9,24,2,1
1,2,38,0,0,0,0,0,0,0,0,0,0,0,0,0,0,0,0,0,0,0,0,0,0,0,38,2,1
1,2,0,0,0,0,0,0,0,0,0,0,0,0,0,0,0,0,0,0,0,0,0,0,0,0,0,2,1
1,2,0,0,0,0,0,0,0,0,0,0,0,0,0,0,0,0,0,0,0,0,0,0,0,0,0,2,1
1,2,0,0,0,0,0,0,0,0,0,0,0,0,0,0,0,0,0,0,0,0,0,0,0,0,0,2,1
1,2,0,0,0,0,0,0,0,0,0,0,0,0,32,0,0,0,0,0,0,0,0,0,0,0,0,2,1
1,2,0,0,0,0,0,0,0,0,0,0,0,0,0,0,0,0,0,0,0,0,0,0,0,0,0,2,1
1,2,0,0,0,0,0,0,0,0,0,0,0,0,0,0,0,0,0,0,0,0,0,0,0,0,0,2,1
1,2,0,0,0,0,0,0,0,0,0,0,0,0,0,0,0,0,0,0,0,0,0,0,0,0,0,2,1
1,2,38,0,0,0,0,0,0,0,0,0,0,0,0,0,0,0,0,0,0,0,0,0,0,0,38,2,1
1,2,24,9,0,0,0,0,0,0,0,0,0,0,0,0,0,0,0,0,0,0,0,0,0,9,24,2,1
1,2,38,0,0,0,0,0,0,0,0,0,0,0,0,0,0,0,0,0,0,0,0,0,0,0,38,2,1
1,2,0,0,0,0,0,0,0,0,0,0,0,0,0,0,0,0,0,0,0,0,0,0,0,0,0,2,1
1,2,0,0,0,0,0,0,0,0,0,0,0,0,0,0,0,0,0,0,0,0,0,0,0,0,0,2,1
1,2,0,0,0,0,0,0,0,0,0,0,0,0,0,0,0,0,0,0,0,0,0,0,0,0,0,2,1
1,2,0,0,0,0,0,0,0,0,0,0,0,0,0,0,0,0,0,0,0,0,0,0,0,0,0,2,1
1,2,0,0,0,0,39,27,27,0,0,0,0,0,0,0,0,0,0,27,27,39,0,0,0,0,0,2,1
1,2,0,0,0,0,27,27,27,0,0,0,0,0,0,0,0,0,0,27,27,39,0,0,0,0,0,2,1
1,2,0,0,0,0,39,27,39,0,0,0,0,0,0,0,0,0,0,27,27,39,0,0,0,0,0,2,1
1,2,0,0,0,0,0,0,0,0,0,0,0,0,0,0,0,0,0,0,0,0,0,0,0,0,0,2,1
1,2,0,0,0,0,0,0,0,0,0,6,6,6,15,6,6,6,0,0,0,0,0,0,0,0,0,2,1
1,2,0,0,0,0,0,0,0,0,36,47,0,0,0,0,0,46,3,0,0,0,0,0,0,0,0,2,1
1,2,0,0,0,10,0,0,0,0,36,47,0,0,0,0,0,46,3,0,0,0,0,10,0,0,0,2,1
1,2,0,0,10,5,10,0,0,0,0,0,0,0,0,0,0,0,0,0,0,0,10,5,10,0,0,2,1
1,2,0,0,0,10,5,10,0,0,0,0,0,0,0,0,0,0,0,0,0,10,5,10,0,0,0,2,1
1,2,0,0,0,0,10,0,0,0,0,0,0,0,0,0,0,0,0,0,0,0,10,0,0,0,0,2,1
1,2,0,0,0,0,0,0,0,0,0,0,0,0,0,0,0,0,0,0,0,0,0,0,0,0,0,2,1
1,2,0,0,0,0,0,0,0,0,0,0,0,0,0,0,0,0,0,0,0,0,0,0,0,0,0,2,1
1,2,2,2,2,2,2,2,2,2,2,2,2,2,2,2,2,2,2,2,2,2,2,2,2,2,2,2,1
1,2,2,2,2,2,2,2,2,2,2,2,2,2,2,2,2,2,2,2,2,2,2,2,2,2,2,2,1
1,1,1,1,1,1,1,1,1,1,1,1,1,1,1,1,1,1,1,1,1,1,1,1,1,1,1,1,1
endlayer

layer
1,1,1,1,1,1,1,1,1,1,1,1,1,1,1,1,1,1,1,1,1,1,1,1,1,1,1,1,1
1,2,2,2,2,2,2,2,2,2,2,2,2,2,2,2,2,2,2,2,2,2,2,2,2,2,2,2,1
1,2,0,0,0,0,0,0,0,0,0,0,0,0,0,0,0,0,0,0,0,0,0,0,0,0,0,2,1
1,2,0,0,0,0,0,0,0,0,0,0,0,0,0,0,0,0,0,0,0,0,0,0,0,0,0,2,1
1,2,0,0,0,6,10,0,9,0,0,0,0,0,0,0,0,0,0,0,9,0,7,6,0,0,0,2,1
1,2,8,9,0,10,0,10,0,12,0,0,0,0,0,0,0,0,0,12,0,7,0,7,0,9,8,2,1
1,2,9,0,10,0,10,0,0,0,9,0,0,0,0,0,0,0,9,0,0,0,7,0,7,0,9,2,1
1,2,0,0,0,10,0,0,0,0,0,15,0,0,0,0,0,15,0,0,0,0,0,7,0,0,0,2,1
1,2,0,0,0,0,0,0,0,0,0,0,9,0,0,0,9,0,0,0,0,0,0,0,0,0,0,2,1
1,2,0,0,0,0,0,0,0,0,0,0,0,7,15,7,0,0,0,0,0,0,0,0,0,0,0,2,1
1,2,0,0,0,0,0,0,0,0,0,0,0,0,0,0,0,0,0,0,0,0,0,0,0,0,0,2,1
1,2,0,0,0,0,0,0,0,0,0,0,0,0,0,0,0,0,0,0,0,0,0,0,0,0,0,2,1
1,2,0,0,0,45,0,0,0,0,0,0,0,0,0,0,0,0,0,0,0,0,0,45,0,0,0,2,1
1,2,0,0,0,0,0,0,0,0,0,0,0,0,0,0,0,0,0,0,0,0,0,0,0,0,0,2,1
1,2,0,0,0,0,0,0,0,0,0,0,0,0,0,0,0,0,0,0,0,0,0,0,0,0,0,2,1
1,2,0,0,0,0,0,0,0,0,0,0,0,0,0,0,0,0,0,0,0,0,0,0,0,0,0,2,1
1,2,0,0,0,0,0,0,0,0,0,0,0,0,0,0,0,0,0,0,0,0,0,0,0,0,0,2,1
1,2,38,0,0,0,0,0,0,0,0,0,0,0,0,0,0,0,0,0,0,0,0,0,0,0,38,2,1
1,2,24,48,0,0,0,0,0,0,0,0,0,0,0,0,0,0,0,0,0,0,0,0,0,48,24,2,1
1,2,38,0,0,0,0,0,0,0,0,0,0,0,0,0,0,0,0,0,0,0,0,0,0,0,38,2,1
1,2,0,0,0,0,0,0,0,0,0,0,0,0,0,0,0,0,0,0,0,0,0,0,0,0,0,2,1
1,2,0,0,0,0,0,0,0,0,0,0,27,27,27,27,27,0,0,0,0,0,0,0,0,0,0,2,1
1,2,0,0,0,0,0,0,0,0,0,0,27,27,27,27,27,0,0,0,0,0,0,0,0,0,0,2,1
1,2,0,0,0,0,0,0,0,0,0,0,27,27,5,27,27,0,0,0,0,0,0,0,0,0,0,2,1
1,2,0,0,0,0,0,0,0,0,0,0,27,27,27,27,27,0,0,0,0,0,0,0,0,0,0,2,1
1,2,0,0,0,0,0,0,0,0,0,0,0,27,27,27,0,0,0,0,0,0,0,0,0,0,0,2,1
1,2,0,0,0,0,0,0,0,0,0,0,0,0,0,0,0,0,0,0,0,0,0,0,0,0,0,2,1
1,2,38,0,0,0,0,0,0,0,0,0,0,0,0,0,0,0,0,0,0,0,0,0,0,0,38,2,1
1,2,24,48,0,0,0,0,0,0,0,0,0,0,0,0,0,0,0,0,0,0,0,0,0,48,24,2,1
1,2,38,0,0,0,0,0,0,0,0,0,0,0,0,0,0,0,0,0,0,0,0,0,0,0,38,2,1
1,2,0,0,0,0,0,0,0,0,0,0,0,0,0,0,0,0,0,0,0,0,0,0,0,0,0,2,1
1,2,0,0,0,0,0,0,0,0,0,0,0,0,0,0,0,0,0,0,0,0,0,0,0,0,0,2,1
1,2,0,0,0,0,0,0,0,0,0,0,0,0,0,0,0,0,0,0,0,0,0,0,0,0,0,2,1
1,2,0,0,0,0,0,0,0,0,0,0,0,0,0,0,0,0,0,0,0,0,0,0,0,0,0,2,1
1,2,0,0,0,0,0,0,0,0,0,0,0,0,0,0,0,0,0,0,0,0,0,0,0,0,0,2,1
1,2,0,0,0,0,0,0,0,0,0,0,0,0,0,0,0,0,0,0,0,0,0,0,0,0,0,2,1
1,2,0,0,0,0,0,0,0,0,0,0,0,0,0,0,0,0,0,0,0,0,0,0,0,0,0,2,1
1,2,0,0,0,0,0,0,0,0,0,0,0,0,0,0,0,0,0,0,0,0,0,0,0,0,0,2,1
1,2,0,0,0,0,0,0,6,6,6,6,6,6,15,6,6,6,6,6,6,0,0,0,0,0,0,2,1
1,2,0,0,0,0,0,0,6,3,44,0,0,0,0,0,0,0,43,3,6,0,0,0,0,0,0,2,1
1,2,0,0,0,10,0,0,6,3,44,0,0,0,0,0,0,0,43,3,6,0,0,10,0,0,0,2,1
1,2,0,0,10,0,10,0,6,3,3,0,0,0,0,0,0,0,3,3,6,0,10,0,10,0,0,2,1
1,2,0,0,0,10,0,10,6,3,3,0,0,0,0,0,0,0,3,3,6,10,0,10,0,0,0,2,1
1,2,0,0,0,0,10,0,0,0,0,0,0,0,0,0,0,0,0,0,0,0,10,0,0,0,0,2,1
1,2,0,0,0,0,0,0,0,0,0,0,0,0,0,0,0,0,0,0,0,0,0,0,0,0,0,2,1
1,2,0,0,0,0,0,0,0,0,0,0,0,0,5,0,0,0,0,0,0,0,0,0,0,0,0,2,1
1,2,2,2,2,2,2,2,2,2,2,2,2,2,2,2,2,2,2,2,2,2,2,2,2,2,2,2,1
1,2,2,2,2,2,2,2,2,2,2,2,2,2,2,2,2,2,2,2,2,2,2,2,2,2,2,2,1
1,1,1,1,1,1,1,1,1,1,1,1,1,1,1,1,1,1,1,1,1,1,1,1,1,1,1,1,1
endlayer

layer
1,1,1,1,1,1,1,1,1,1,1,1,1,1,1,1,1,1,1,1,1,1,1,1,1,1,1,1,1
1,2,2,2,2,2,2,2,2,2,2,2,2,2,2,2,2,2,2,2,2,2,2,2,2,2,2,2,1
1,2,0,0,0,0,0,0,0,0,0,8,0,0,0,0,0,8,0,0,0,0,0,0,0,0,0,2,1
1,2,0,0,0,0,0,0,0,0,8,5,8,0,0,0,8,5,8,0,0,0,0,0,0,0,0,2,1
1,2,0,0,0,0,10,0,9,0,0,8,0,0,0,0,0,8,0,0,9,0,7,0,0,0,0,2,1
1,2,8,9,0,8,49,10,0,12,0,0,0,0,0,0,0,0,0,12,0,7,49,8,0,9,8,2,1
1,2,9,0,10,49,10,0,0,0,9,0,0,0,0,0,0,0,9,0,0,0,7,49,7,0,9,2,1
1,2,0,0,0,10,0,0,0,0,0,15,0,0,0,0,0,15,0,0,0,0,0,7,0,0,0,2,1
1,2,0,0,0,0,0,0,0,0,0,0,9,15,15,15,9,0,0,0,0,0,0,0,0,0,0,2,1
1,2,0,0,0,0,0,0,0,0,0,0,0,7,7,7,0,0,0,0,0,0,0,0,0,0,0,2,1
1,2,0,0,0,0,0,0,0,0,0,0,0,0,0,0,0,0,0,0,0,0,0,0,0,0,0,2,1
1,2,0,0,0,0,0,0,0,0,0,0,0,0,0,0,0,0,0,0,0,0,0,0,0,0,0,2,1
1,2,0,0,0,45,0,0,0,0,0,0,0,0,0,0,0,0,0,0,0,0,0,45,0,0,0,2,1
1,2,0,0,0,0,0,0,0,0,0,0,0,0,0,0,0,0,0,0,0,0,0,0,0,0,0,2,1
1,2,0,0,0,0,0,0,0,0,0,0,0,0,0,0,0,0,0,0,0,0,0,0,0,0,0,2,1
1,2,0,0,0,0,0,0,0,0,0,0,0,0,0,0,0,0,0,0,0,0,0,0,0,0,0,2,1
1,2,0,0,0,0,0,0,0,0,0,0,0,0,0,0,0,0,0,0,0,0,0,0,0,0,0,2,1
1,2,38,0,0,0,0,0,0,0,0,0,0,0,0,0,0,0,0,0,0,0,0,0,0,0,38,2,1
1,2,24,9,0,0,0,0,0,0,0,0,0,0,0,0,0,0,0,0,0,0,0,0,0,9,24,2,1
1,2,38,0,0,0,0,0,0,0,0,0,0,0,0,0,0,0,0,0,0,0,0,0,0,0,38,2,1
1,2,0,0,0,0,0,0,0,0,0,0,0,0,0,0,0,0,0,0,0,0,0,0,0,0,0,2,1
1,2,0,0,0,0,0,0,0,0,0,0,0,0,0,0,0,0,0,0,0,0,0,0,0,0,0,2,1
1,2,0,0,0,0,0,0,0,0,0,0,0,27,27,27,0,0,0,0,0,0,0,0,0,0,0,2,1
1,2,0,0,0,0,0,0,0,0,0,0,0,27,27,27,0,0,0,0,0,0,0,0,0,0,0,2,1
1,2,0,0,0,0,0,0,0,0,0,0,0,27,27,27,0,0,0,0,0,0,0,0,0,0,0,2,1
1,2,0,0,0,0,0,0,0,0,0,0,0,0,0,0,0,0,0,0,0,0,0,0,0,0,0,2,1
1,2,0,0,0,0,0,0,0,0,0,0,0,0,0,0,0,0,0,0,0,0,0,0,0,0,0,2,1
1,2,38,0,0,0,0,0,0,0,0,0,0,0,0,0,0,0,0,0,0,0,0,0,0,0,38,2,1
1,2,24,9,0,0,0,0,0,0,0,0,0,0,0,0,0,0,0,0,0,0,0,0,0,9,24,2,1
1,2,38,0,0,0,0,0,0,0,0,0,0,0,0,0,0,0,0,0,0,0,0,0,0,0,38,2,1
1,2,0,0,0,0,0,0,0,0,0,0,0,0,0,0,0,0,0,0,0,0,0,0,0,0,0,2,1
1,2,0,0,0,0,0,0,0,0,0,0,0,0,0,0,0,0,0,0,0,0,0,0,0,0,0,2,1
1,2,0,0,0,0,0,0,0,0,0,0,0,0,0,0,0,0,0,0,0,0,0,0,0,0,0,2,1
1,2,0,0,0,0,0,0,0,0,0,0,0,0,0,0,0,0,0,0,0,0,0,0,0,0,0,2,1
1,2,0,0,0,0,0,0,0,0,0,0,0,0,0,0,0,0,0,0,0,0,0,0,0,0,0,2,1
1,2,0,0,0,0,0,0,0,0,0,0,0,0,0,0,0,0,0,0,0,0,0,0,0,0,0,2,1
1,2,0,0,0,0,0,0,0,0,0,0,0,0,0,0,0,0,0,0,0,0,0,0,0,0,0,2,1
1,2,0,0,0,0,0,0,0,0,0,0,0,0,0,0,0,0,0,0,0,0,0,0,0,0,0,2,1
1,2,0,0,0,0,0,0,6,6,6,6,6,6,15,6,6,6,6,6,6,0,0,0,0,0,0,2,1
1,2,0,0,0,0,0,0,6,0,0,0,0,0,0,0,0,0,0,0,6,0,0,0,0,0,0,2,1
1,2,0,0,0,10,0,0,6,0,0,0,0,0,0,0,0,0,0,0,6,0,0,10,0,0,0,2,1
1,2,0,0,10,0,10,0,6,51,51,0,0,0,0,0,0,0,50,50,6,0,10,0,10,0,0,2,1
1,2,0,0,0,8,0,10,6,3,3,0,0,0,0,0,0,0,3,3,6,10,0,8,0,0,0,2,1
1,2,0,0,0,0,10,0,6,3,3,0,0,0,0,0,0,0,3,3,6,0,10,0,0,0,0,2,1
1,2,0,0,0,0,0,0,6,3,3,0,0,0,0,0,0,0,0,0,0,0,0,0,0,0,0,2,1
1,2,0,0,0,0,0,0,0,0,0,0,0,0,45,0,0,0,0,0,0,0,0,0,0,0,0,2,1
1,2,2,2,2,2,2,2,2,2,2,2,2,2,2,2,2,2,2,2,2,2,2,2,2,2,2,2,1
1,2,2,2,2,2,2,2,2,2,2,2,2,2,2,2,2,2,2,2,2,2,2,2,2,2,2,2,1
1,1,1,1,1,1,1,1,1,1,1,1,1,1,1,1,1,1,1,1,1,1,1,1,1,1,1,1,1
endlayer

layer
1,1,1,1,1,1,1,1,1,1,1,1,1,1,1,1,1,1,1,1,1,1,1,1,1,1,1,1,1
1,2,2,2,2,2,2,2,2,2,2,2,2,2,2,2,2,2,2,2,2,2,2,2,2,2,2,2,1
1,2,0,0,0,0,0,0,0,0,0,0,15,48,15,48,15,0,0,0,0,0,0,0,0,0,0,2,1
1,2,0,0,0,0,0,0,0,0,0,45,15,48,15,48,15,45,0,0,0,0,0,0,0,0,0,2,1
1,2,0,0,0,0,10,0,9,0,0,0,15,48,15,48,15,0,0,0,9,0,7,0,0,0,0,2,1
1,2,8,9,0,0,0,10,0,12,0,0,15,48,15,48,15,0,0,12,0,7,0,0,0,9,8,2,1
1,2,9,0,10,0,10,0,0,0,9,0,15,48,15,48,15,0,9,0,0,0,7,0,7,0,9,2,1
1,2,0,0,0,10,0,0,0,0,0,15,15,48,15,48,15,15,0,0,0,0,0,7,0,0,0,2,1
1,2,0,0,0,0,0,0,0,0,0,0,9,42,5,42,9,0,0,0,0,0,0,0,0,0,0,2,1
1,2,0,0,0,0,0,0,0,0,0,0,0,7,48,7,0,0,0,0,0,0,0,0,0,0,0,2,1
1,2,0,0,0,0,0,0,0,0,0,0,0,0,0,0,0,0,0,0,0,0,0,0,0,0,0,2,1
1,2,0,0,0,0,0,0,0,0,0,0,0,0,0,0,0,0,0,0,0,0,0,0,0,0,0,2,1
1,2,0,0,0,45,0,0,0,0,0,0,0,0,0,0,0,0,0,0,0,0,0,45,0,0,0,2,1
1,2,0,0,0,0,0,0,0,0,0,0,0,0,0,0,0,0,0,0,0,0,0,0,0,0,0,2,1
1,2,0,0,0,0,0,0,0,0,0,0,0,0,0,0,0,0,0,0,0,0,0,0,0,0,0,2,1
1,2,0,0,0,0,0,0,0,0,0,0,0,0,0,0,0,0,0,0,0,0,0,0,0,0,0,2,1
1,2,0,0,0,0,0,0,0,0,0,0,0,0,0,0,0,0,0,0,0,0,0,0,0,0,0,2,1
1,2,38,0,0,0,0,0,0,0,0,0,0,0,0,0,0,0,0,0,0,0,0,0,0,0,38,2,1
1,2,24,9,0,0,0,0,0,0,0,0,0,0,0,0,0,0,0,0,0,0,0,0,0,9,24,2,1
1,2,38,0,0,0,0,0,0,0,0,0,0,0,0,0,0,0,0,0,0,0,0,0,0,0,38,2,1
1,2,0,0,0,0,0,0,0,0,0,0,0,0,0,0,0,0,0,0,0,0,0,0,0,0,0,2,1
1,2,0,0,0,0,0,0,0,0,0,0,0,0,0,0,0,0,0,0,0,0,0,0,0,0,0,2,1
1,2,0,0,0,0,0,0,0,0,0,0,0,0,0,0,0,0,0,0,0,0,0,0,0,0,0,2,1
1,2,0,0,0,0,0,0,0,0,0,0,0,0,0,0,0,0,0,0,0,0,0,0,0,0,0,2,1
1,2,0,0,0,0,0,0,0,0,0,0,0,0,0,0,0,0,0,0,0,0,0,0,0,0,0,2,1
1,2,0,0,0,0,0,0,0,0,0,0,0,0,0,0,0,0,0,0,0,0,0,0,0,0,0,2,1
1,2,0,0,0,0,0,0,0,0,0,0,0,0,0,0,0,0,0,0,0,0,0,0,0,0,0,2,1
1,2,38,0,0,0,0,0,0,0,0,0,0,0,0,0,0,0,0,0,0,0,0,0,0,0,38,2,1
1,2,24,9,0,0,0,0,0,0,0,0,0,0,0,0,0,0,0,0,0,0,0,0,0,9,24,2,1
1,2,38,0,0,0,0,0,0,0,0,0,0,0,0,0,0,0,0,0,0,0,0,0,0,0,38,2,1
1,2,0,0,0,0,0,0,0,0,0,0,0,0,0,0,0,0,0,0,0,0,0,0,0,0,0,2,1
1,2,0,0,0,0,0,0,0,0,0,0,0,0,0,0,0,0,0,0,0,0,0,0,0,0,0,2,1
1,2,0,0,0,0,0,0,0,0,0,0,0,0,0,0,0,0,0,0,0,0,0,0,0,0,0,2,1
1,2,0,0,0,0,0,0,0,0,0,0,0,0,0,0,0,0,0,0,0,0,0,0,0,0,0,2,1
1,2,0,0,0,0,0,0,0,0,0,0,0,0,0,0,0,0,0,0,0,0,0,0,0,0,0,2,1
1,2,0,0,0,0,0,0,0,0,0,0,0,0,0,0,0,0,0,0,0,0,0,0,0,0,0,2,1
1,2,0,0,0,0,0,0,0,0,0,0,0,0,0,0,0,0,0,0,0,0,0,0,0,0,0,2,1
1,2,0,0,0,0,0,0,0,0,0,0,0,0,0,0,0,0,0,0,0,0,0,0,0,0,0,2,1
1,2,0,0,0,0,0,0,6,6,6,6,6,6,15,6,6,6,6,6,6,0,0,0,0,0,0,2,1
1,2,0,0,0,0,0,0,6,0,0,0,0,0,0,0,0,0,0,0,6,0,0,0,0,0,0,2,1
1,2,0,0,0,10,0,0,6,0,0,0,0,0,0,0,0,0,0,0,6,0,0,10,0,0,0,2,1
1,2,0,0,10,0,10,0,6,0,0,0,0,0,0,0,0,0,0,0,6,0,10,0,10,0,0,2,1
1,2,0,0,0,0,0,10,6,51,51,0,0,0,0,0,0,0,50,50,6,10,0,0,0,0,0,2,1
1,2,0,0,0,0,10,0,6,3,3,0,0,0,0,0,0,0,3,3,6,0,10,0,0,0,0,2,1
1,2,0,0,0,0,0,0,6,3,3,0,0,0,0,0,0,0,3,3,6,0,0,0,0,0,0,2,1
1,2,0,0,0,0,0,0,6,3,3,0,0,0,45,0,0,0,3,3,6,0,0,0,0,0,0,2,1
1,2,2,2,2,2,2,2,2,2,2,2,2,2,2,2,2,2,2,2,2,2,2,2,2,2,2,2,1
1,2,2,2,2,2,2,2,2,2,2,2,2,2,2,2,2,2,2,2,2,2,2,2,2,2,2,2,1
1,1,1,1,1,1,1,1,1,1,1,1,1,1,1,1,1,1,1,1,1,1,1,1,1,1,1,1,1
endlayer

layer
1,1,1,1,1,1,1,1,1,1,1,1,1,1,1,1,1,1,1,1,1,1,1,1,1,1,1,1,1
1,2,2,2,2,2,2,2,2,2,2,2,2,2,2,2,2,2,2,2,2,2,2,2,2,2,2,2,1
1,2,15,15,15,15,15,15,15,15,15,15,41,0,42,0,40,15,15,15,15,15,15,15,15,15,15,2,1
1,2,15,15,15,15,15,15,15,15,15,15,41,0,0,0,40,15,15,15,15,15,15,15,15,15,15,2,1
1,2,15,15,15,15,8,15,9,15,15,15,41,0,0,0,40,15,15,15,9,15,8,15,15,15,15,2,1
1,2,15,9,15,15,15,10,0,12,15,15,41,0,0,0,40,15,15,12,0,7,15,15,15,9,15,2,1
1,2,9,0,8,15,10,0,0,0,9,15,41,0,0,0,40,15,9,0,0,0,7,15,8,0,9,2,1
1,2,0,0,0,10,0,0,0,0,0,15,50,48,0,48,50,15,0,0,0,0,0,7,0,0,0,2,1
1,2,0,0,0,0,0,0,0,0,0,0,40,0,19,0,41,0,0,0,0,0,0,0,0,0,0,2,1
1,2,0,0,0,0,0,0,0,0,0,0,0,7,7,7,0,0,0,0,0,0,0,0,0,0,0,2,1
1,2,0,0,0,0,0,0,0,0,0,0,0,0,0,0,0,0,0,0,0,0,0,0,0,0,0,2,1
1,2,0,0,0,0,0,0,0,0,0,0,0,0,0,0,0,0,0,0,0,0,0,0,0,0,0,2,1
1,2,0,0,0,45,0,0,0,0,0,0,0,0,0,0,0,0,0,0,0,0,0,45,0,0,0,2,1
1,2,0,0,0,0,0,0,0,0,0,0,0,0,0,0,0,0,0,0,0,0,0,0,0,0,0,2,1
1,2,0,0,0,0,0,0,0,0,0,0,0,0,0,0,0,0,0,0,0,0,0,0,0,0,0,2,1
1,2,0,0,0,0,0,0,0,0,0,0,0,0,0,0,0,0,0,0,0,0,0,0,0,0,0,2,1
1,2,0,0,0,0,0,0,0,0,0,0,0,0,0,0,0,0,0,0,0,0,0,0,0,0,0,2,1
1,2,38,0,0,0,0,0,0,0,0,0,0,0,0,0,0,0,0,0,0,0,0,0,0,0,38,2,1
1,2,24,9,0,0,0,0,0,0,0,0,0,0,0,0,0,0,0,0,0,0,0,0,0,9,24,2,1
1,2,38,0,0,0,0,0,0,0,0,0,0,0,0,0,0,0,0,0,0,0,0,0,0,0,38,2,1
1,2,0,0,0,0,0,0,0,0,0,0,0,0,0,0,0,0,0,0,0,0,0,0,0,0,0,2,1
1,2,0,0,0,0,0,0,0,0,0,0,0,0,0,0,0,0,0,0,0,0,0,0,0,0,0,2,1
1,2,0,0,0,0,0,0,0,0,0,0,0,0,0,0,0,0,0,0,0,0,0,0,0,0,0,2,1
1,2,0,0,0,0,0,0,0,0,0,0,0,0,0,0,0,0,0,0,0,0,0,0,0,0,0,2,1
1,2,0,0,0,0,0,0,0,0,0,0,0,0,0,0,0,0,0,0,0,0,0,0,0,0,0,2,1
1,2,0,0,0,0,0,0,0,0,0,0,0,0,0,0,0,0,0,0,0,0,0,0,0,0,0,2,1
1,2,0,0,0,0,0,0,0,0,0,0,0,0,0,0,0,0,0,0,0,0,0,0,0,0,0,2,1
1,2,38,0,0,0,0,0,0,0,0,0,0,0,0,0,0,0,0,0,0,0,0,0,0,0,38,2,1
1,2,24,9,0,0,0,0,0,0,0,0,0,0,0,0,0,0,0,0,0,0,0,0,0,9,24,2,1
1,2,38,0,0,0,0,0,0,0,0,0,0,0,0,0,0,0,0,0,0,0,0,0,0,0,38,2,1
1,2,0,0,0,0,0,0,0,0,0,0,0,0,0,0,0,0,0,0,0,0,0,0,0,0,0,2,1
1,2,0,0,0,0,0,0,0,0,0,0,0,0,0,0,0,0,0,0,0,0,0,0,0,0,0,2,1
1,2,0,0,0,0,0,0,0,0,0,0,0,0,0,0,0,0,0,0,0,0,0,0,0,0,0,2,1
1,2,0,0,0,0,0,0,0,0,0,0,0,0,0,0,0,0,0,0,0,0,0,0,0,0,0,2,1
1,2,0,0,0,0,0,0,0,0,0,0,0,0,0,0,0,0,0,0,0,0,0,0,0,0,0,2,1
1,2,0,0,0,0,0,0,0,0,0,0,0,0,0,0,0,0,0,0,0,0,0,0,0,0,0,2,1
1,2,0,0,0,0,0,0,0,0,0,0,0,0,0,0,0,0,0,0,0,0,0,0,0,0,0,2,1
1,2,0,0,0,0,0,0,0,0,0,0,0,0,0,0,0,0,0,0,0,0,0,0,0,0,0,2,1
1,2,0,0,0,0,0,0,6,6,6,6,6,6,15,6,6,6,6,6,6,0,0,0,0,0,0,2,1
1,2,0,0,0,0,0,0,6,0,0,0,0,0,0,0,0,0,0,0,6,0,0,0,0,0,0,2,1
1,2,0,0,0,10,0,0,6,0,0,0,0,0,0,0,0,0,0,0,6,0,0,10,0,0,0,2,1
1,2,0,0,8,0,10,0,6,0,0,0,0,0,0,0,0,0,0,0,6,0,10,0,8,0,0,2,1
1,2,0,0,0,0,0,10,6,0,0,0,0,0,0,0,0,0,0,0,6,10,0,0,0,0,0,2,1
1,2,0,0,0,0,8,0,6,0,0,0,0,0,0,0,0,0,0,0,6,0,8,0,0,0,0,2,1
1,2,0,0,0,0,0,0,6,0,51,3,0,0,0,0,0,3,51,0,6,0,0,0,0,0,0,2,1
1,2,0,0,0,0,0,0,6,0,40,3,3,0,45,0,3,3,41,0,6,0,0,0,0,0,0,2,1
1,2,2,2,2,2,2,2,2,2,2,2,2,2,2,2,2,2,2,2,2,2,2,2,2,2,2,2,1
1,2,2,2,2,2,2,2,2,2,2,2,2,2,2,2,2,2,2,2,2,2,2,2,2,2,2,2,1
1,1,1,1,1,1,1,1,1,1,1,1,1,1,1,1,1,1,1,1,1,1,1,1,1,1,1,1,1
endlayer

layer
1,1,1,1,1,1,1,1,1,1,1,1,1,1,1,1,1,1,1,1,1,1,1,1,1,1,1,1,1
1,2,2,2,2,2,2,2,2,2,2,2,2,2,2,2,2,2,2,2,2,2,2,2,2,2,2,2,1
1,2,0,0,24,0,0,48,0,40,48,41,0,48,33,48,0,40,48,41,0,48,0,0,24,0,0,2,1
1,2,0,5,24,0,0,0,0,40,48,41,0,0,0,0,0,40,48,41,0,0,0,0,24,5,0,2,1
1,2,48,42,0,0,0,0,9,50,48,41,0,0,0,0,0,40,48,50,9,0,0,0,0,42,48,2,1
1,2,0,9,0,0,0,8,0,7,48,41,0,0,0,0,0,40,48,7,0,8,0,0,0,9,0,2,1
1,2,9,0,0,0,10,0,0,0,9,41,0,0,0,0,0,40,9,0,0,0,7,0,0,0,9,2,1
1,2,0,0,0,8,0,0,0,0,0,7,0,0,0,0,0,7,0,0,0,0,0,8,0,0,0,2,1
1,2,0,0,0,0,0,0,0,0,0,0,0,0,0,0,0,0,0,0,0,0,0,0,0,0,0,2,1
1,2,0,0,0,0,0,0,0,0,0,0,0,40,7,41,0,0,0,0,0,0,0,0,0,0,0,2,1
1,2,0,0,0,0,0,0,0,0,0,0,0,0,0,0,0,0,0,0,0,0,0,0,0,0,0,2,1
1,2,0,0,0,0,0,0,0,0,0,0,0,0,0,0,0,0,0,0,0,0,0,0,0,0,0,2,1
1,2,0,0,0,45,0,0,0,0,0,0,0,0,0,0,0,0,0,0,0,0,0,45,0,0,0,2,1
1,2,0,0,0,0,0,0,0,0,0,0,0,0,0,0,0,0,0,0,0,0,0,0,0,0,0,2,1
1,2,0,0,0,0,0,0,0,0,0,0,0,0,0,0,0,0,0,0,0,0,0,0,0,0,0,2,1
1,2,0,0,0,0,0,0,0,0,0,0,0,0,0,0,0,0,0,0,0,0,0,0,0,0,0,2,1
1,2,0,0,0,0,0,0,0,0,0,0,0,0,0,0,0,0,0,0,0,0,0,0,0,0,0,2,1
1,2,38,0,0,0,0,0,0,0,0,0,0,0,0,0,0,0,0,0,0,0,0,0,0,0,38,2,1
1,2,24,48,0,0,0,0,0,0,0,0,0,0,0,0,0,0,0,0,0,0,0,0,0,48,24,2,1
1,2,38,0,0,0,0,0,0,0,0,0,0,0,0,0,0,0,0,0,0,0,0,0,0,0,38,2,1
1,2,0,0,0,0,0,0,0,0,0,0,0,0,0,0,0,0,0,0,0,0,0,0,0,0,0,2,1
1,2,0,0,0,0,0,0,0,0,0,0,0,0,0,0,0,0,0,0,0,0,0,0,0,0,0,2,1
1,2,0,0,0,0,0,0,0,0,0,0,0,0,0,0,0,0,0,0,0,0,0,0,0,0,0,2,1
1,2,0,0,0,0,0,0,0,0,0,0,0,0,0,0,0,0,0,0,0,0,0,0,0,0,0,2,1
1,2,0,0,0,0,0,0,0,0,0,0,0,0,0,0,0,0,0,0,0,0,0,0,0,0,0,2,1
1,2,0,0,0,0,0,0,0,0,0,0,0,0,0,0,0,0,0,0,0,0,0,0,0,0,0,2,1
1,2,0,0,0,0,0,0,0,0,0,0,0,0,0,0,0,0,0,0,0,0,0,0,0,0,0,2,1
1,2,38,0,0,0,0,0,0,0,0,0,0,0,0,0,0,0,0,0,0,0,0,0,0,0,38,2,1
1,2,24,48,0,0,0,0,0,0,0,0,0,0,0,0,0,0,0,0,0,0,0,0,0,48,24,2,1
1,2,38,0,0,0,0,0,0,0,0,0,0,0,0,0,0,0,0,0,0,0,0,0,0,0,38,2,1
1,2,0,0,0,0,0,0,0,0,0,0,0,0,0,0,0,0,0,0,0,0,0,0,0,0,0,2,1
1,2,0,0,0,0,0,0,0,0,0,0,0,0,0,0,0,0,0,0,0,0,0,0,0,0,0,2,1
1,2,0,0,0,0,0,0,0,0,0,0,0,0,0,0,0,0,0,0,0,0,0,0,0,0,0,2,1
1,2,0,0,0,0,0,0,0,0,0,0,0,0,0,0,0,0,0,0,0,0,0,0,0,0,0,2,1
1,2,0,0,0,0,0,0,0,0,0,0,0,0,0,0,0,0,0,0,0,0,0,0,0,0,0,2,1
1,2,0,0,0,0,0,0,0,0,0,0,0,0,0,0,0,0,0,0,0,0,0,0,0,0,0,2,1
1,2,0,0,0,0,0,0,0,0,0,0,0,0,0,0,0,0,0,0,0,0,0,0,0,0,0,2,1
1,2,0,0,0,0,0,0,0,0,0,0,0,0,0,0,0,0,0,0,0,0,0,0,0,0,0,2,1
1,2,0,0,0,0,0,0,6,6,6,6,6,6,15,6,6,6,6,6,6,0,0,0,0,0,0,2,1
1,2,0,0,0,0,0,0,6,0,0,0,3,3,3,3,3,0,0,0,6,0,0,0,0,0,0,2,1
1,2,0,0,0,8,0,0,6,0,0,0,0,3,3,3,0,0,0,0,6,0,0,8,0,0,0,2,1
1,2,0,0,0,0,10,0,6,0,0,0,0,3,3,3,0,0,0,0,6,0,10,0,0,0,0,2,1
1,2,0,0,0,0,0,8,6,0,0,0,0,3,3,3,0,0,0,0,6,8,0,0,0,0,0,2,1
1,2,0,0,0,0,0,0,6,0,0,0,3,3,3,3,3,0,0,0,6,0,0,0,0,0,0,2,1
1,2,0,0,0,0,0,0,6,0,0,40,3,3,48,3,3,41,0,0,6,0,0,0,0,0,0,2,1
1,2,0,0,0,0,0,0,6,0,0,40,37,3,52,3,37,37,0,0,6,0,0,0,0,0,0,2,1
1,2,2,2,2,2,2,2,2,2,2,2,2,2,2,2,2,2,2,2,2,2,2,2,2,2,2,2,1
1,2,2,2,2,2,2,2,2,2,2,2,2,2,2,2,2,2,2,2,2,2,2,2,2,2,2,2,1
1,1,1,1,1,1,1,1,1,1,1,1,1,1,1,1,1,1,1,1,1,1,1,1,1,1,1,1,1
endlayer

layer
1,1,1,1,1,1,1,1,1,1,1,1,1,1,1,1,1,1,1,1,1,1,1,1,1,1,1,1,1
1,2,2,2,2,2,2,2,2,2,2,2,2,2,2,2,2,2,2,2,2,2,2,2,2,2,2,2,1
1,2,0,0,0,0,48,31,48,0,53,0,48,31,0,30,48,0,53,0,48,30,48,0,0,0,0,2,1
1,2,0,0,0,0,0,0,0,0,53,0,0,0,0,0,0,0,53,0,0,0,0,0,0,0,0,2,1
1,2,30,48,42,0,0,0,9,0,53,0,0,0,0,0,0,0,53,0,9,0,0,0,42,48,31,2,1
1,2,0,9,0,0,0,0,0,0,53,0,0,0,0,0,0,0,53,0,0,0,0,0,0,9,0,2,1
1,2,9,0,0,0,10,0,0,0,9,0,0,0,0,0,0,0,9,0,0,0,7,0,0,0,9,2,1
1,2,0,0,0,0,0,0,0,0,0,0,0,0,0,0,0,0,0,0,0,0,0,0,0,0,0,2,1
1,2,0,0,0,0,0,0,0,0,0,0,0,0,0,0,0,0,0,0,0,0,0,0,0,0,0,2,1
1,2,0,0,0,0,0,0,0,0,0,0,0,0,7,0,0,0,0,0,0,0,0,0,0,0,0,2,1
1,2,0,0,0,0,0,0,0,0,0,0,0,0,0,0,0,0,0,0,0,0,0,0,0,0,0,2,1
1,2,0,0,0,0,0,0,0,0,0,0,0,0,0,0,0,0,0,0,0,0,0,0,0,0,0,2,1
1,2,0,0,0,42,0,0,0,0,0,0,0,0,0,0,0,0,0,0,0,0,0,42,0,0,0,2,1
1,2,0,0,0,0,0,0,0,0,0,0,0,0,0,0,0,0,0,0,0,0,0,0,0,0,0,2,1
1,2,0,0,0,0,0,0,0,0,0,0,0,0,0,0,0,0,0,0,0,0,0,0,0,0,0,2,1
1,2,0,0,0,0,0,0,0,0,0,0,0,0,0,0,0,0,0,0,0,0,0,0,0,0,0,2,1
1,2,0,0,0,0,0,0,0,0,0,0,0,0,0,0,0,0,0,0,0,0,0,0,0,0,0,2,1
1,2,38,0,0,0,0,0,0,0,0,0,0,0,0,0,0,0,0,0,0,0,0,0,0,0,38,2,1
1,2,24,48,0,0,0,0,0,0,0,0,0,0,0,0,0,0,0,0,0,0,0,0,0,48,24,2,1
1,2,38,0,0,0,0,0,0,0,0,0,0,0,0,0,0,0,0,0,0,0,0,0,0,0,38,2,1
1,2,0,0,0,0,0,0,0,0,0,0,0,0,0,0,0,0,0,0,0,0,0,0,0,0,0,2,1
1,2,0,0,0,0,0,0,0,0,0,0,0,0,0,0,0,0,0,0,0,0,0,0,0,0,0,2,1
1,2,0,0,0,0,0,0,0,0,0,0,0,0,0,0,0,0,0,0,0,0,0,0,0,0,0,2,1
1,2,0,0,0,0,0,0,0,0,0,0,0,0,0,0,0,0,0,0,0,0,0,0,0,0,0,2,1
1,2,0,0,0,0,0,0,0,0,0,0,0,0,0,0,0,0,0,0,0,0,0,0,0,0,0,2,1
1,2,0,0,0,0,0,0,0,0,0,0,0,0,0,0,0,0,0,0,0,0,0,0,0,0,0,2,1
1,2,0,0,0,0,0,0,0,0,0,0,0,0,0,0,0,0,0,0,0,0,0,0,0,0,0,2,1
1,2,38,0,0,0,0,0,0,0,0,0,0,0,0,0,0,0,0,0,0,0,0,0,0,0,38,2,1
1,2,24,48,0,0,0,0,0,0,0,0,0,0,0,0,0,0,0,0,0,0,0,0,0,48,24,2,1
1,2,38,0,0,0,0,0,0,0,0,0,0,0,0,0,0,0,0,0,0,0,0,0,0,0,38,2,1
1,2,0,0,0,0,0,0,0,0,0,0,0,0,0,0,0,0,0,0,0,0,0,0,0,0,0,2,1
1,2,0,0,0,0,0,0,0,0,0,0,0,0,0,0,0,0,0,0,0,0,0,0,0,0,0,2,1
1,2,0,0,0,0,0,0,0,0,0,0,0,0,0,0,0,0,0,0,0,0,0,0,0,0,0,2,1
1,2,0,0,0,0,0,0,0,0,0,0,0,0,0,0,0,0,0,0,0,0,0,0,0,0,0,2,1
1,2,0,0,0,0,0,0,0,0,0,0,0,0,0,0,0,0,0,0,0,0,0,0,0,0,0,2,1
1,2,0,0,0,0,0,0,0,0,0,27,27,39,39,39,39,39,0,0,0,0,0,0,0,0,0,2,1
1,2,0,0,0,0,0,0,0,0,0,39,39,39,39,39,39,39,0,0,0,0,0,0,0,0,0,2,1
1,2,0,0,0,0,0,0,0,0,0,39,39,39,39,39,39,39,0,0,0,0,0,0,0,0,0,2,1
1,2,0,0,0,0,0,0,6,6,6,6,3,3,3,3,3,6,6,6,6,0,0,0,0,0,0,2,1
1,2,0,0,0,0,0,0,6,0,0,0,40,37,37,37,41,0,0,0,6,0,0,0,0,0,0,2,1
1,2,0,0,0,0,0,0,6,0,0,0,0,0,0,0,0,0,0,0,6,0,0,0,0,0,0,2,1
1,2,0,0,0,0,10,0,6,0,0,0,0,0,0,0,0,0,0,0,6,0,10,0,0,0,0,2,1
1,2,0,0,0,0,0,0,6,0,0,0,0,0,0,0,0,0,0,0,6,0,0,0,0,0,0,2,1
1,2,0,0,0,0,0,0,6,0,0,0,0,0,0,0,0,0,0,0,6,0,0,0,0,0,0,2,1
1,2,0,0,0,0,0,0,6,0,0,0,0,0,0,0,0,0,0,0,6,0,0,0,0,0,0,2,1
1,2,0,0,0,0,0,0,6,0,0,0,0,6,6,6,0,0,0,0,6,0,0,0,0,0,0,2,1
1,2,2,2,2,2,2,2,2,2,2,2,2,2,2,2,2,2,2,2,2,2,2,2,2,2,2,2,1
1,2,2,2,2,2,2,2,2,2,2,2,2,2,2,2,2,2,2,2,2,2,2,2,2,2,2,2,1
1,1,1,1,1,1,1,1,1,1,1,1,1,1,1,1,1,1,1,1,1,1,1,1,1,1,1,1,1
endlayer

layer
1,1,1,1,1,1,1,1,1,1,1,1,1,1,1,1,1,1,1,1,1,1,1,1,1,1,1,1,1
1,2,2,2,2,2,2,2,2,2,2,2,2,2,2,2,2,2,2,2,2,2,2,2,2,2,2,2,1
1,2,0,0,0,48,31,0,0,42,31,42,31,0,0,0,30,42,30,42,0,0,30,48,0,0,0,2,1
1,2,0,0,0,0,0,0,0,0,0,0,0,0,0,0,0,0,0,0,0,0,0,0,0,0,0,2,1
1,2,0,30,48,42,0,0,0,0,0,0,0,0,0,0,0,0,0,0,0,0,0,42,48,31,0,2,1
1,2,0,9,0,0,0,0,0,0,0,0,0,0,0,0,0,0,0,0,0,0,0,0,0,9,0,2,1
1,2,9,0,0,0,10,0,0,0,9,0,0,0,0,0,0,0,9,0,0,0,7,0,0,0,9,2,1
1,2,0,0,0,0,0,0,0,0,0,0,0,0,0,0,0,0,0,0,0,0,0,0,0,0,0,2,1
1,2,0,0,0,0,0,0,0,0,0,0,0,0,0,0,0,0,0,0,0,0,0,0,0,0,0,2,1
1,2,0,0,0,0,0,0,0,0,0,0,0,0,0,0,0,0,0,0,0,0,0,0,0,0,0,2,1
1,2,0,0,0,0,0,0,0,0,0,0,0,0,0,0,0,0,0,0,0,0,0,0,0,0,0,2,1
1,2,0,0,0,0,0,0,0,0,0,0,0,0,0,0,0,0,0,0,0,0,0,0,0,0,0,2,1
1,2,0,0,0,54,0,0,0,0,0,0,0,0,0,0,0,0,0,0,0,0,0,54,0,0,0,2,1
1,2,0,0,0,0,0,0,0,0,0,0,0,0,0,0,0,0,0,0,0,0,0,0,0,0,0,2,1
1,2,0,0,0,0,0,0,0,0,0,0,0,0,0,0,0,0,0,0,0,0,0,0,0,0,0,2,1
1,2,0,0,0,0,0,0,0,0,0,0,0,0,0,0,0,0,0,0,0,0,0,0,0,0,0,2,1
1,2,0,0,0,0,0,0,0,0,0,0,0,0,0,0,0,0,0,0,0,0,0,0,0,0,0,2,1
1,2,38,0,0,0,0,0,0,0,0,0,0,0,0,0,0,0,0,0,0,0,0,0,0,0,38,2,1
1,2,24,9,0,0,0,0,0,0,0,0,0,0,0,0,0,0,0,0,0,0,0,0,0,9,24,2,1
1,2,38,0,0,0,0,0,0,0,0,0,0,0,0,0,0,0,0,0,0,0,0,0,0,0,38,2,1
1,2,0,0,0,0,0,0,0,0,0,0,0,0,0,0,0,0,0,0,0,0,0,0,0,0,0,2,1
1,2,0,0,0,0,0,0,0,0,0,0,0,0,0,0,0,0,0,0,0,0,0,0,0,0,0,2,1
1,2,0,0,0,0,0,0,0,0,0,0,0,0,0,0,0,0,0,0,0,0,0,0,0,0,0,2,1
1,2,0,0,0,0,0,0,0,0,0,0,0,0,0,0,0,0,0,0,0,0,0,0,0,0,0,2,1
1,2,0,0,0,0,0,0,0,0,0,0,0,0,0,0,0,0,0,0,0,0,0,0,0,0,0,2,1
1,2,0,0,0,0,0,0,0,0,0,0,0,0,0,0,0,0,0,0,0,0,0,0,0,0,0,2,1
1,2,0,0,0,0,0,0,0,0,0,0,0,0,0,0,0,0,0,0,0,0,0,0,0,0,0,2,1
1,2,38,0,0,0,0,0,0,0,0,0,0,0,0,0,0,0,0,0,0,0,0,0,0,0,38,2,1
1,2,24,9,0,0,0,0,0,0,0,0,0,0,0,0,0,0,0,0,0,0,0,0,0,9,24,2,1
1,2,38,0,0,0,0,0,0,0,0,0,0,0,0,0,0,0,0,0,0,0,0,0,0,0,38,2,1
1,2,0,0,0,0,0,0,0,0,0,0,0,0,0,0,0,0,0,0,0,0,0,0,0,0,0,2,1
1,2,0,0,0,0,0,0,0,55,55,55,55,0,0,0,55,55,55,55,0,0,0,0,0,0,0,2,1
1,2,0,0,0,0,0,0,0,0,0,0,0,0,0,0,0,0,0,0,0,0,0,0,0,0,0,2,1
1,2,0,0,0,0,0,0,0,0,0,0,0,0,0,0,0,0,0,0,0,0,0,0,0,0,0,2,1
1,2,0,0,0,0,0,27,39,39,39,0,0,0,0,0,0,0,39,39,27,27,0,0,0,0,0,2,1
1,2,0,0,0,0,0,39,6,6,6,3,3,3,3,3,3,3,6,6,6,39,0,0,0,0,0,2,1
1,2,0,0,0,0,0,27,6,6,6,3,3,3,3,3,3,3,6,6,6,39,0,0,0,0,0,2,1
1,2,0,0,0,0,0,27,6,6,6,3,3,3,3,3,3,3,6,6,6,27,0,0,0,0,0,2,1
1,2,0,0,0,0,0,27,6,6,6,6,40,37,37,37,41,6,6,6,6,27,0,0,0,0,0,2,1
1,2,0,0,0,0,0,27,6,0,0,0,0,0,0,0,0,0,0,0,6,39,0,0,0,0,0,2,1
1,2,0,0,0,0,0,27,6,0,0,0,0,0,0,0,0,0,0,0,6,27,0,0,0,0,0,2,1
1,2,0,0,0,0,10,27,6,0,0,0,0,0,0,0,0,0,0,0,6,27,10,0,0,0,0,2,1
1,2,0,0,0,0,0,39,6,0,0,0,0,0,0,0,0,0,0,0,6,39,0,0,0,0,0,2,1
1,2,0,0,0,0,0,39,6,0,0,0,0,0,0,0,0,0,0,0,6,39,0,0,0,0,0,2,1
1,2,0,0,0,0,0,39,6,0,0,0,0,0,0,0,0,0,0,0,6,27,0,0,0,0,0,2,1
1,2,0,0,0,0,0,39,6,0,0,0,0,6,6,6,0,0,0,0,6,39,0,0,0,0,0,2,1
1,2,2,2,2,2,2,2,2,2,2,2,2,2,2,2,2,2,2,2,2,2,2,2,2,2,2,2,1
1,2,2,2,2,2,2,2,2,2,2,2,2,2,2,2,2,2,2,2,2,2,2,2,2,2,2,2,1
1,1,1,1,1,1,1,1,1,1,1,1,1,1,1,1,1,1,1,1,1,1,1,1,1,1,1,1,1
endlayer

layer
1,1,1,1,1,1,1,1,1,1,1,1,1,1,1,1,1,1,1,1,1,1,1,1,1,1,1,1,1
1,2,2,2,2,2,2,2,2,2,2,2,2,2,2,2,2,2,2,2,2,2,2,2,2,2,2,2,1
1,2,0,0,48,31,0,0,0,0,0,31,0,0,56,0,0,30,0,0,0,0,0,30,48,0,0,2,1
1,2,0,0,0,0,0,0,0,0,0,0,0,0,0,0,0,0,0,0,0,0,0,0,0,0,0,2,1
1,2,0,0,30,48,42,0,0,0,0,0,0,0,0,0,0,0,0,0,0,0,42,48,31,0,0,2,1
1,2,0,9,0,0,0,0,0,0,0,0,0,0,0,0,0,0,0,0,0,0,0,0,0,9,0,2,1
1,2,0,0,0,0,10,0,0,0,0,0,0,0,0,0,0,0,0,0,0,0,7,0,0,0,0,2,1
1,2,0,0,0,0,0,0,0,0,0,0,0,0,0,0,0,0,0,0,0,0,0,0,0,0,0,2,1
1,2,0,0,0,0,0,0,0,0,0,0,0,0,0,0,0,0,0,0,0,0,0,0,0,0,0,2,1
1,2,0,0,0,0,0,0,0,0,0,0,0,0,0,0,0,0,0,0,0,0,0,0,0,0,0,2,1
1,2,0,0,0,0,0,0,0,0,0,0,0,0,0,0,0,0,0,0,0,0,0,0,0,0,0,2,1
1,2,0,0,0,0,0,0,0,0,0,0,0,0,0,0,0,0,0,0,0,0,0,0,0,0,0,2,1
1,2,0,0,0,54,0,0,0,0,0,0,0,0,0,0,0,0,0,0,0,0,0,54,0,0,0,2,1
1,2,0,0,0,0,0,0,0,0,0,0,0,0,0,0,0,0,0,0,0,0,0,0,0,0,0,2,1
1,2,0,0,0,0,0,0,0,0,0,0,0,0,0,0,0,0,0,0,0,0,0,0,0,0,0,2,1
1,2,0,0,0,0,0,0,0,0,0,0,0,0,0,0,0,0,0,0,0,0,0,0,0,0,0,2,1
1,2,0,0,0,0,0,0,0,0,0,0,0,0,0,0,0,0,0,0,0,0,0,0,0,0,0,2,1
1,2,38,0,0,0,0,0,0,0,0,0,0,0,0,0,0,0,0,0,0,0,0,0,0,0,38,2,1
1,2,24,9,0,0,0,0,0,0,0,0,0,0,0,0,0,0,0,0,0,0,0,0,0,9,24,2,1
1,2,38,0,0,0,0,0,0,0,0,0,0,0,0,0,0,0,0,0,0,0,0,0,0,0,38,2,1
1,2,0,0,0,0,0,0,0,0,0,0,0,0,0,0,0,0,0,0,0,0,0,0,0,0,0,2,1
1,2,0,0,0,0,0,0,0,0,0,0,0,0,0,0,0,0,0,0,0,0,0,0,0,0,0,2,1
1,2,0,0,0,0,0,0,0,0,0,0,0,0,0,0,0,0,0,0,0,0,0,0,0,0,0,2,1
1,2,0,0,0,0,0,0,0,0,0,0,0,0,0,0,0,0,0,0,0,0,0,0,0,0,0,2,1
1,2,0,0,0,0,0,0,0,0,0,0,0,0,0,0,0,0,0,0,0,0,0,0,0,0,0,2,1
1,2,0,0,0,0,0,0,0,0,0,0,0,0,0,0,0,0,0,0,0,0,0,0,0,0,0,2,1
1,2,0,0,0,0,0,0,0,0,0,0,0,0,0,0,0,0,0,0,0,0,0,0,0,0,0,2,1
1,2,38,0,0,0,0,0,0,0,0,0,0,0,0,0,0,0,0,0,0,0,0,0,0,0,38,2,1
1,2,24,9,0,0,0,0,0,0,0,0,0,0,0,0,0,0,0,0,0,0,0,0,0,9,24,2,1
1,2,38,0,0,0,0,0,0,0,0,0,0,0,0,0,0,0,0,0,0,0,0,0,0,0,38,2,1
1,2,0,0,0,0,0,0,57,57,57,57,57,57,0,57,57,57,57,57,57,0,0,0,0,0,0,2,1
1,2,0,0,0,0,0,0,60,59,59,59,59,58,0,60,59,59,59,59,58,0,0,0,0,0,0,2,1
1,2,0,0,0,0,0,0,60,61,61,61,61,58,0,60,61,61,61,61,58,0,0,0,0,0,0,2,1
1,2,0,0,0,0,0,0,0,15,15,48,15,48,15,48,15,48,15,15,0,0,0,0,0,0,0,2,1
1,2,0,0,0,0,0,39,0,15,15,3,48,3,48,3,48,3,15,15,27,27,0,0,0,0,0,2,1
1,2,0,0,0,0,0,39,0,3,3,3,15,3,15,3,15,3,3,3,0,39,0,0,0,0,0,2,1
1,2,0,0,0,0,0,39,62,0,0,40,37,37,37,37,37,41,0,0,62,39,0,0,0,0,0,2,1
1,2,0,0,0,0,0,39,6,0,0,0,0,0,0,0,0,0,0,0,6,39,0,0,0,0,0,2,1
1,2,0,0,0,0,0,39,62,0,0,0,0,0,0,0,0,0,0,0,62,39,0,0,0,0,0,2,1
1,2,0,0,0,0,0,39,6,0,0,0,0,0,0,0,0,0,0,0,6,39,0,0,0,0,0,2,1
1,2,0,0,0,0,0,39,62,0,0,0,0,0,0,0,0,0,0,0,62,39,0,0,0,0,0,2,1
1,2,0,0,0,0,10,39,6,0,0,0,0,0,0,0,0,0,0,0,6,39,10,0,0,0,0,2,1
1,2,0,0,0,0,0,39,62,0,0,0,0,0,0,0,0,0,0,0,62,39,0,0,0,0,0,2,1
1,2,0,0,0,0,0,39,6,0,0,0,0,0,0,0,0,0,0,0,6,39,0,0,0,0,0,2,1
1,2,0,0,0,0,0,39,62,0,0,0,0,0,0,0,0,0,0,0,62,39,0,0,0,0,0,2,1
1,2,0,0,0,0,0,39,6,0,0,0,0,6,6,6,0,0,0,0,6,39,0,0,0,0,0,2,1
1,2,2,2,2,2,2,2,2,2,2,2,2,2,2,2,2,2,2,2,2,2,2,2,2,2,2,2,1
1,2,2,2,2,2,2,2,2,2,2,2,2,2,2,2,2,2,2,2,2,2,2,2,2,2,2,2,1
1,1,1,1,1,1,1,1,1,1,1,1,1,1,1,1,1,1,1,1,1,1,1,1,1,1,1,1,1
endlayer

layer
1,1,1,1,1,1,1,1,1,1,1,1,1,1,1,1,1,1,1,1,1,1,1,1,1,1,1,1,1
1,2,2,2,2,2,2,2,2,2,2,2,2,2,2,2,2,2,2,2,2,2,2,2,2,2,2,2,1
1,2,0,48,31,0,0,0,0,0,0,0,0,56,24,56,0,0,0,0,0,0,0,0,30,48,0,2,1
1,2,0,0,0,0,42,0,0,0,0,0,0,0,0,0,0,0,0,0,0,0,42,0,0,0,0,2,1
1,2,0,0,0,30,48,0,0,0,0,0,0,0,0,0,0,0,0,0,0,0,48,31,0,0,0,2,1
1,2,0,9,0,0,0,0,0,0,0,0,0,0,0,0,0,0,0,0,0,0,0,0,0,9,0,2,1
1,2,0,0,0,0,10,0,0,0,0,0,0,0,0,0,0,0,0,0,0,0,7,0,0,0,0,2,1
1,2,0,0,0,0,0,0,0,0,0,0,0,0,0,0,0,0,0,0,0,0,0,0,0,0,0,2,1
1,2,0,0,0,0,0,0,0,0,0,0,0,0,0,0,0,0,0,0,0,0,0,0,0,0,0,2,1
1,2,0,0,0,0,0,0,0,0,0,0,0,0,0,0,0,0,0,0,0,0,0,0,0,0,0,2,1
1,2,0,0,0,0,0,0,0,0,0,0,0,0,0,0,0,0,0,0,0,0,0,0,0,0,0,2,1
1,2,0,0,0,0,0,0,0,0,0,0,0,0,0,0,0,0,0,0,0,0,0,0,0,0,0,2,1
1,2,0,0,0,54,0,0,0,0,0,0,0,0,0,0,0,0,0,0,0,0,0,54,0,0,0,2,1
1,2,0,0,0,0,0,0,0,0,0,0,0,0,0,0,0,0,0,0,0,0,0,0,0,0,0,2,1
1,2,0,0,0,0,0,0,0,0,0,0,0,0,0,0,0,0,0,0,0,0,0,0,0,0,0,2,1
1,2,0,0,0,0,0,0,0,0,0,0,0,0,0,0,0,0,0,0,0,0,0,0,0,0,0,2,1
1,2,0,0,0,0,0,0,0,0,0,0,0,0,0,0,0,0,0,0,0,0,0,0,0,0,0,2,1
1,2,38,0,0,0,0,0,0,0,0,0,0,0,0,0,0,0,0,0,0,0,0,0,0,0,38,2,1
1,2,24,48,0,0,0,0,0,0,0,0,0,0,0,0,0,0,0,0,0,0,0,0,0,48,24,2,1
1,2,38,0,0,0,0,0,0,0,0,0,0,0,0,0,0,0,0,0,0,0,0,0,0,0,38,2,1
1,2,0,0,0,0,0,0,0,0,0,0,0,0,0,0,0,0,0,0,0,0,0,0,0,0,0,2,1
1,2,0,0,0,0,0,0,0,0,0,0,0,0,0,0,0,0,0,0,0,0,0,0,0,0,0,2,1
1,2,0,0,0,0,0,0,0,0,0,0,0,0,0,0,0,0,0,0,0,0,0,0,0,0,0,2,1
1,2,0,0,0,0,0,0,0,0,0,0,0,0,0,0,0,0,0,0,0,0,0,0,0,0,0,2,1
1,2,0,0,0,0,0,0,0,0,0,0,0,0,0,0,0,0,0,0,0,0,0,0,0,0,0,2,1
1,2,0,0,0,0,0,0,0,0,0,0,0,0,0,0,0,0,0,0,0,0,0,0,0,0,0,2,1
1,2,0,0,0,0,0,0,0,0,0,0,0,0,0,0,0,0,0,0,0,0,0,0,0,0,0,2,1
1,2,38,0,0,0,0,0,0,0,0,0,0,0,0,0,0,0,0,0,0,0,0,0,0,0,38,2,1
1,2,24,48,0,0,0,0,0,0,0,0,0,0,0,0,0,0,0,0,0,0,0,0,0,48,24,2,1
1,2,38,0,0,0,0,0,0,0,0,0,0,0,0,0,0,0,0,0,0,0,0,0,0,0,38,2,1
1,2,0,0,0,0,0,0,0,63,63,63,63,0,0,0,63,63,63,63,0,0,0,0,0,0,0,2,1
1,2,0,0,0,0,0,0,66,65,65,65,65,64,0,66,65,65,65,65,64,0,0,0,0,0,0,2,1
1,2,0,0,0,0,0,0,48,3,48,3,48,3,48,3,48,3,48,3,48,0,0,0,0,0,0,2,1
1,2,0,0,0,0,0,0,52,0,0,0,0,0,0,0,0,0,0,0,52,0,0,0,0,0,0,2,1
1,2,0,0,0,0,0,39,40,0,0,0,0,0,0,0,0,0,0,0,41,27,0,0,0,0,0,2,1
1,2,0,0,0,0,0,39,67,68,68,0,0,0,0,0,0,0,68,68,67,39,0,0,0,0,0,2,1
1,2,0,0,0,0,0,27,6,3,3,0,0,0,0,0,0,0,3,3,6,39,0,0,0,0,0,2,1
1,2,0,0,0,0,0,27,3,69,69,0,0,0,0,0,0,0,69,69,3,39,0,0,0,0,0,2,1
1,2,0,0,0,0,0,27,6,34,0,0,0,0,0,0,0,0,0,36,6,39,0,0,0,0,0,2,1
1,2,0,0,0,0,0,27,3,0,0,0,0,0,0,0,0,0,0,0,3,39,0,0,0,0,0,2,1
1,2,0,0,0,0,0,27,6,0,0,0,0,0,0,0,0,0,0,0,6,39,0,0,0,0,0,2,1
1,2,0,0,0,0,10,39,3,0,0,0,0,0,0,0,0,0,0,0,3,39,10,0,0,0,0,2,1
1,2,0,0,0,0,0,39,6,0,0,0,0,0,0,0,0,0,0,0,6,39,0,0,0,0,0,2,1
1,2,0,0,0,0,0,39,3,0,0,0,0,0,0,0,0,0,0,0,3,39,0,0,0,0,0,2,1
1,2,0,0,0,0,0,39,6,0,0,0,0,0,0,0,0,0,0,0,6,39,0,0,0,0,0,2,1
1,2,0,0,0,0,0,39,3,0,0,0,0,6,6,6,0,0,0,0,3,39,0,0,0,0,0,2,1
1,2,2,2,2,2,2,2,2,2,2,2,2,2,2,2,2,2,2,2,2,2,2,2,2,2,2,2,1
1,2,2,2,2,2,2,2,2,2,2,2,2,2,2,2,2,2,2,2,2,2,2,2,2,2,2,2,1
1,1,1,1,1,1,1,1,1,1,1,1,1,1,1,1,1,1,1,1,1,1,1,1,1,1,1,1,1
endlayer

layer
1,1,1,1,1,1,1,1,1,1,1,1,1,1,1,1,1,1,1,1,1,1,1,1,1,1,1,1,1
1,2,2,2,2,2,2,2,2,2,2,2,2,2,2,2,2,2,2,2,2,2,2,2,2,2,2,2,1
1,2,48,31,0,0,42,0,0,0,0,0,56,24,48,24,56,0,0,0,0,0,42,0,0,30,48,2,1
1,2,0,0,0,0,48,0,0,0,0,0,0,0,0,0,0,0,0,0,0,0,48,0,0,0,0,2,1
1,2,0,0,0,0,33,0,0,0,0,0,0,0,0,0,0,0,0,0,0,0,33,0,0,0,0,2,1
1,2,0,0,0,0,0,0,0,0,0,0,0,0,0,0,0,0,0,0,0,0,0,0,0,0,0,2,1
1,2,0,0,0,0,10,0,0,0,0,0,0,0,0,0,0,0,0,0,0,0,7,0,0,0,0,2,1
1,2,0,0,0,0,0,0,0,0,0,0,0,0,0,0,0,0,0,0,0,0,0,0,0,0,0,2,1
1,2,0,0,0,0,0,0,0,0,0,0,0,0,0,0,0,0,0,0,0,0,0,0,0,0,0,2,1
1,2,0,0,0,0,0,0,0,0,0,0,0,0,0,0,0,0,0,0,0,0,0,0,0,0,0,2,1
1,2,0,0,0,0,0,0,0,0,0,0,0,0,0,0,0,0,0,0,0,0,0,0,0,0,0,2,1
1,2,0,0,0,0,0,0,0,0,0,0,0,0,0,0,0,0,0,0,0,0,0,0,0,0,0,2,1
1,2,0,0,0,54,0,0,0,0,0,0,0,0,0,0,0,0,0,0,0,0,0,54,0,0,0,2,1
1,2,0,0,0,0,0,0,0,0,0,0,0,0,0,0,0,0,0,0,0,0,0,0,0,0,0,2,1
1,2,0,0,0,0,0,0,0,0,0,0,0,0,0,0,0,0,0,0,0,0,0,0,0,0,0,2,1
1,2,0,0,0,0,0,0,0,0,0,0,0,0,0,0,0,0,0,0,0,0,0,0,0,0,0,2,1
1,2,0,0,0,0,0,0,0,0,0,0,0,0,0,0,0,0,0,0,0,0,0,0,0,0,0,2,1
1,2,38,0,0,0,0,0,0,0,0,0,0,0,0,0,0,0,0,0,0,0,0,0,0,0,38,2,1
1,2,24,48,0,0,0,0,0,0,0,0,0,0,0,0,0,0,0,0,0,0,0,0,0,48,24,2,1
1,2,38,0,0,0,0,0,0,0,0,0,0,0,0,0,0,0,0,0,0,0,0,0,0,0,38,2,1
1,2,0,0,0,0,0,0,0,0,0,0,0,0,0,0,0,0,0,0,0,0,0,0,0,0,0,2,1
1,2,0,0,0,0,0,0,0,0,0,0,0,0,0,0,0,0,0,0,0,0,0,0,0,0,0,2,1
1,2,0,0,0,0,0,0,0,0,0,0,0,0,0,0,0,0,0,0,0,0,0,0,0,0,0,2,1
1,2,0,0,0,0,0,0,0,0,0,0,0,0,0,0,0,0,0,0,0,0,0,0,0,0,0,2,1
1,2,0,0,0,0,0,0,0,0,0,0,0,0,0,0,0,0,0,0,0,0,0,0,0,0,0,2,1
1,2,0,0,0,0,0,0,0,0,0,0,0,0,0,0,0,0,0,0,0,0,0,0,0,0,0,2,1
1,2,0,0,0,0,0,0,0,0,0,0,0,0,0,0,0,0,0,0,0,0,0,0,0,0,0,2,1
1,2,38,0,0,0,0,0,0,0,0,0,0,0,0,0,0,0,0,0,0,0,0,0,0,0,38,2,1
1,2,24,48,0,0,0,0,0,0,0,0,0,0,0,0,0,0,0,0,0,0,0,0,0,48,24,2,1
1,2,38,0,0,0,0,0,0,0,0,0,0,0,0,0,0,0,0,0,0,0,0,0,0,0,38,2,1
1,2,0,0,0,0,0,0,0,0,0,0,0,0,0,0,0,0,0,0,0,0,0,0,0,0,0,2,1
1,2,0,0,0,0,0,0,0,70,71,71,70,0,0,0,70,71,71,70,0,0,0,0,0,0,0,2,1
1,2,0,0,0,0,0,0,48,0,0,0,0,0,0,0,0,0,0,0,48,0,0,0,0,0,0,2,1
1,2,0,0,0,0,0,0,0,0,0,0,0,0,0,0,0,0,0,0,0,0,0,0,0,0,0,2,1
1,2,0,0,0,0,0,27,15,0,0,0,0,0,0,0,0,0,0,0,15,27,0,0,0,0,0,2,1
1,2,0,0,0,0,0,27,40,0,0,0,0,0,0,0,0,0,0,0,41,27,0,0,0,0,0,2,1
1,2,0,0,0,0,0,27,72,68,68,0,0,0,0,0,0,0,68,68,72,27,0,0,0,0,0,2,1
1,2,0,0,0,0,0,27,73,3,3,0,0,0,0,0,0,0,3,3,73,27,0,0,0,0,0,2,1
1,2,0,0,0,0,0,27,72,3,0,0,0,0,0,0,0,0,0,3,72,27,0,0,0,0,0,2,1
1,2,0,0,0,0,0,27,73,15,0,0,0,0,0,0,0,0,0,15,73,27,0,0,0,0,0,2,1
1,2,0,0,0,0,0,27,72,15,0,0,0,0,0,0,0,0,0,15,72,27,0,0,0,0,0,2,1
1,2,0,0,0,0,10,27,73,0,0,0,0,0,5,0,0,0,0,0,73,27,10,0,0,0,0,2,1
1,2,0,0,0,0,0,27,72,0,0,0,0,0,0,0,0,0,0,0,72,27,0,0,0,0,0,2,1
1,2,0,0,0,0,0,27,73,0,0,0,0,0,0,0,0,0,0,0,73,27,0,0,0,0,0,2,1
1,2,0,0,0,0,0,27,72,0,0,0,0,0,0,0,0,0,0,0,72,27,0,0,0,0,0,2,1
1,2,0,0,0,0,0,27,73,15,15,0,0,15,15,15,0,0,15,15,73,27,0,0,0,0,0,2,1
1,2,2,2,2,2,2,2,2,2,2,2,2,2,2,2,2,2,2,2,2,2,2,2,2,2,2,2,1
1,2,2,2,2,2,2,2,2,2,2,2,2,2,2,2,2,2,2,2,2,2,2,2,2,2,2,2,1
1,1,1,1,1,1,1,1,1,1,1,1,1,1,1,1,1,1,1,1,1,1,1,1,1,1,1,1,1
endlayer

layer
1,1,1,1,1,1,1,1,1,1,1,1,1,1,1,1,1,1,1,1,1,1,1,1,1,1,1,1,1
1,2,2,2,2,2,2,2,2,2,2,2,2,2,2,2,2,2,2,2,2,2,2,2,2,2,2,2,1
1,2,0,0,0,42,48,0,0,0,0,56,24,48,42,48,24,56,0,0,0,0,48,42,0,0,0,2,1
1,2,0,0,0,0,33,0,0,0,0,0,0,0,0,0,0,0,0,0,0,0,33,0,0,0,0,2,1
1,2,0,0,0,0,0,0,0,0,0,0,0,0,0,0,0,0,0,0,0,0,0,0,0,0,0,2,1
1,2,0,0,0,0,0,0,0,0,0,0,0,0,0,0,0,0,0,0,0,0,0,0,0,0,0,2,1
1,2,0,0,0,0,8,0,0,0,0,0,0,0,0,0,0,0,0,0,0,0,8,0,0,0,0,2,1
1,2,0,0,0,0,0,0,0,0,0,0,0,0,0,0,0,0,0,0,0,0,0,0,0,0,0,2,1
1,2,0,0,0,0,0,0,0,0,0,0,0,0,0,0,0,0,0,0,0,0,0,0,0,0,0,2,1
1,2,0,0,0,0,0,0,0,0,0,0,0,0,0,0,0,0,0,0,0,0,0,0,0,0,0,2,1
1,2,0,0,0,0,0,0,0,0,0,0,0,0,0,0,0,0,0,0,0,0,0,0,0,0,0,2,1
1,2,0,0,0,0,0,0,0,0,0,0,0,0,0,0,0,0,0,0,0,0,0,0,0,0,0,2,1
1,2,0,0,0,54,0,0,0,0,0,0,0,0,0,0,0,0,0,0,0,0,0,54,0,0,0,2,1
1,2,0,0,0,0,0,0,0,0,0,0,0,0,0,0,0,0,0,0,0,0,0,0,0,0,0,2,1
1,2,0,0,0,0,0,0,0,0,0,0,0,0,0,0,0,0,0,0,0,0,0,0,0,0,0,2,1
1,2,0,0,0,0,0,0,0,0,0,0,0,0,0,0,0,0,0,0,0,0,0,0,0,0,0,2,1
1,2,0,0,0,0,0,0,0,0,0,0,0,0,0,0,0,0,0,0,0,0,0,0,0,0,0,2,1
1,2,38,0,0,0,0,0,0,0,0,0,0,0,0,0,0,0,0,0,0,0,0,0,0,0,38,2,1
1,2,24,9,0,0,0,0,0,0,0,0,0,0,0,0,0,0,0,0,0,0,0,0,0,9,24,2,1
1,2,38,0,0,0,0,0,0,0,0,0,0,0,0,0,0,0,0,0,0,0,0,0,0,0,38,2,1
1,2,0,0,0,0,0,0,0,0,0,0,0,0,0,0,0,0,0,0,0,0,0,0,0,0,0,2,1
1,2,0,0,0,0,0,0,0,0,0,0,0,0,0,0,0,0,0,0,0,0,0,0,0,0,0,2,1
1,2,74,0,0,0,0,0,0,0,0,0,0,0,0,0,0,0,0,0,0,0,0,0,0,0,74,2,1
1,2,35,0,0,0,0,0,0,0,0,0,0,0,0,0,0,0,0,0,0,0,0,0,0,0,35,2,1
1,2,56,0,0,0,0,0,0,0,0,0,0,0,0,0,0,0,0,0,0,0,0,0,0,0,56,2,1
1,2,0,0,0,0,0,0,0,0,0,0,0,0,0,0,0,0,0,0,0,0,0,0,0,0,0,2,1
1,2,0,0,0,0,0,0,0,0,0,0,0,0,0,0,0,0,0,0,0,0,0,0,0,0,0,2,1
1,2,38,0,0,0,0,0,0,0,0,0,0,0,0,0,0,0,0,0,0,0,0,0,0,0,38,2,1
1,2,24,9,0,0,0,0,0,0,0,0,0,0,0,0,0,0,0,0,0,0,0,0,0,9,24,2,1
1,2,38,0,0,0,0,0,0,0,0,0,0,0,0,0,0,0,0,0,0,0,0,0,0,0,38,2,1
1,2,0,0,0,0,0,0,0,0,0,0,0,0,0,0,0,0,0,0,0,0,0,0,0,0,0,2,1
1,2,0,0,0,0,0,0,0,0,0,0,0,0,0,0,0,0,0,0,0,0,0,0,0,0,0,2,1
1,2,0,0,0,0,0,0,0,0,0,0,0,0,0,0,0,0,0,0,0,0,0,0,0,0,0,2,1
1,2,0,0,0,0,0,0,0,0,0,0,0,0,0,0,0,0,0,0,0,0,0,0,0,0,0,2,1
1,2,0,0,0,0,0,0,0,0,0,0,0,0,0,0,0,0,0,0,0,0,0,0,0,0,0,2,1
1,2,0,0,0,0,0,0,52,0,0,0,0,0,0,0,0,0,0,0,52,0,0,0,0,0,0,2,1
1,2,0,0,0,0,0,0,6,0,0,0,0,0,0,0,0,0,0,0,6,0,0,0,0,0,0,2,1
1,2,0,0,0,0,0,0,6,43,68,0,0,0,0,0,0,0,68,68,6,0,0,0,0,0,0,2,1
1,2,0,0,0,0,0,0,6,43,3,3,0,0,0,0,0,3,3,44,6,0,0,0,0,0,0,2,1
1,2,0,0,0,0,0,0,6,48,3,0,0,0,0,0,0,0,3,48,6,0,0,0,0,0,0,2,1
1,2,0,0,0,0,0,0,6,15,0,0,0,0,0,0,0,0,0,15,6,0,0,0,0,0,0,2,1
1,2,0,0,0,0,8,0,6,0,0,0,0,0,45,0,0,0,0,0,6,0,8,0,0,0,0,2,1
1,2,0,0,0,0,0,0,6,0,0,0,0,0,0,0,0,0,0,0,6,0,0,0,0,0,0,2,1
1,2,0,0,0,0,0,0,6,0,0,0,0,0,0,0,0,0,0,0,6,0,0,0,0,0,0,2,1
1,2,0,0,0,0,0,0,6,0,0,0,0,0,0,0,0,0,0,0,6,0,0,0,0,0,0,2,1
1,2,0,0,0,0,0,0,6,0,0,15,15,0,0,0,15,15,0,0,6,0,0,0,0,0,0,2,1
1,2,2,2,2,2,2,2,2,2,2,2,2,2,2,2,2,2,2,2,2,2,2,2,2,2,2,2,1
1,2,2,2,2,2,2,2,2,2,2,2,2,2,2,2,2,2,2,2,2,2,2,2,2,2,2,2,1
1,1,1,1,1,1,1,1,1,1,1,1,1,1,1,1,1,1,1,1,1,1,1,1,1,1,1,1,1
endlayer

layer
1,1,1,1,1,1,1,1,1,1,1,1,1,1,1,1,1,1,1,1,1,1,1,1,1,1,1,1,1
1,2,2,2,2,2,2,2,2,2,2,2,2,2,2,2,2,2,2,2,2,2,2,2,2,2,2,2,1
1,2,0,0,0,48,31,0,0,24,76,24,48,42,5,42,48,24,75,24,0,0,30,48,0,0,0,2,1
1,2,0,0,42,0,0,0,0,0,0,0,0,0,0,0,0,0,0,0,0,0,0,0,42,0,0,2,1
1,2,0,0,0,0,0,0,0,0,0,0,0,0,0,0,0,0,0,0,0,0,0,0,0,0,0,2,1
1,2,0,0,0,0,0,0,0,0,0,0,0,0,0,0,0,0,0,0,0,0,0,0,0,0,0,2,1
1,2,0,0,0,0,0,0,0,0,0,0,0,0,0,0,0,0,0,0,0,0,0,0,0,0,0,2,1
1,2,0,0,0,0,0,0,0,0,0,0,0,0,0,0,0,0,0,0,0,0,0,0,0,0,0,2,1
1,2,0,0,0,0,0,0,0,0,0,0,0,0,0,0,0,0,0,0,0,0,0,0,0,0,0,2,1
1,2,0,0,0,0,0,0,0,0,0,0,0,0,0,0,0,0,0,0,0,0,0,0,0,0,0,2,1
1,2,0,0,0,0,0,0,0,0,0,0,0,0,0,0,0,0,0,0,0,0,0,0,0,0,0,2,1
1,2,0,0,0,0,0,0,0,0,0,0,0,0,0,0,0,0,0,0,0,0,0,0,0,0,0,2,1
1,2,0,0,0,54,0,0,0,0,0,0,0,0,0,0,0,0,0,0,0,0,0,54,0,0,0,2,1
1,2,0,0,0,0,0,0,0,0,0,0,0,0,0,0,0,0,0,0,0,0,0,0,0,0,0,2,1
1,2,0,0,0,0,0,0,0,0,0,0,0,0,0,0,0,0,0,0,0,0,0,0,0,0,0,2,1
1,2,0,0,0,0,0,0,0,0,0,0,0,0,0,0,0,0,0,0,0,0,0,0,0,0,0,2,1
1,2,0,0,0,0,0,0,0,0,0,0,0,0,0,0,0,0,0,0,0,0,0,0,0,0,0,2,1
1,2,38,0,0,0,0,0,0,0,0,0,0,0,0,0,0,0,0,0,0,0,0,0,0,0,38,2,1
1,2,24,9,0,0,0,0,0,0,0,0,0,0,0,0,0,0,0,0,0,0,0,0,0,9,24,2,1
1,2,38,0,0,0,0,0,0,0,0,0,0,0,0,0,0,0,0,0,0,0,0,0,0,0,38,2,1
1,2,0,0,0,0,0,0,0,0,0,0,0,0,0,0,0,0,0,0,0,0,0,0,0,0,0,2,1
1,2,74,0,0,0,0,0,0,0,0,0,0,0,0,0,0,0,0,0,0,0,0,0,0,0,74,2,1
1,2,35,0,0,0,0,0,0,0,0,0,0,0,0,0,0,0,0,0,0,0,0,0,0,0,35,2,1
1,5,77,0,0,0,0,0,0,0,0,0,0,0,0,0,0,0,0,0,0,0,0,0,0,0,77,5,1
1,2,35,0,0,0,0,0,0,0,0,0,0,0,0,0,0,0,0,0,0,0,0,0,0,0,35,2,1
1,2,56,0,0,0,0,0,0,0,0,0,0,0,0,0,0,0,0,0,0,0,0,0,0,0,56,2,1
1,2,0,0,0,0,0,0,0,0,0,0,0,0,0,0,0,0,0,0,0,0,0,0,0,0,0,2,1
1,2,38,0,0,0,0,0,0,0,0,0,0,0,0,0,0,0,0,0,0,0,0,0,0,0,38,2,1
1,2,24,9,0,0,0,0,0,0,0,0,0,0,0,0,0,0,0,0,0,0,0,0,0,9,24,2,1
1,2,38,0,0,0,0,0,0,0,0,0,0,0,0,0,0,0,0,0,0,0,0,0,0,0,38,2,1
1,2,0,0,0,0,0,0,0,0,0,0,0,0,0,0,0,0,0,0,0,0,0,0,0,0,0,2,1
1,2,0,0,0,0,0,0,0,0,0,0,0,0,0,0,0,0,0,0,0,0,0,0,0,0,0,2,1
1,2,0,0,0,0,0,0,0,0,0,0,0,0,0,0,0,0,0,0,0,0,0,0,0,0,0,2,1
1,2,0,0,0,0,0,0,0,0,0,0,0,0,0,0,0,0,0,0,0,0,0,0,0,0,0,2,1
1,2,0,0,0,0,0,0,0,0,0,0,0,0,0,0,0,0,0,0,0,0,0,0,0,0,0,2,1
1,2,0,0,0,0,0,0,0,0,0,0,0,0,0,0,0,0,0,0,0,0,0,0,0,0,0,2,1
1,2,0,0,0,0,0,0,15,0,0,0,62,6,6,6,62,0,0,0,15,0,0,0,0,0,0,2,1
1,2,0,0,0,0,0,0,15,0,0,0,6,0,0,0,6,0,0,0,15,0,0,0,0,0,0,2,1
1,2,0,0,0,0,0,0,15,0,43,68,6,0,0,0,6,68,68,0,15,0,0,0,0,0,0,2,1
1,2,0,0,0,0,0,0,15,0,43,3,3,0,0,0,3,3,44,0,15,0,0,0,0,0,0,2,1
1,2,0,0,0,0,0,0,15,15,0,3,0,0,55,0,0,3,0,15,15,0,0,0,0,0,0,2,1
1,2,0,0,0,0,0,0,15,0,0,0,0,55,45,55,0,0,0,0,15,0,0,0,0,0,0,2,1
1,2,0,0,0,0,0,0,15,0,0,0,0,0,55,0,0,0,0,0,15,0,0,0,0,0,0,2,1
1,2,0,0,0,0,0,0,15,0,0,0,0,0,0,0,0,0,0,0,15,0,0,0,0,0,0,2,1
1,2,0,0,0,0,0,0,15,0,0,0,0,0,0,0,0,0,0,0,15,0,0,0,0,0,0,2,1
1,2,0,0,0,0,0,0,15,0,15,0,0,15,15,15,0,0,15,0,15,0,0,0,0,0,0,2,1
1,2,2,2,2,2,2,2,2,2,2,2,2,2,2,2,2,2,2,2,2,2,2,2,2,2,2,2,1
1,2,2,2,2,2,2,2,2,2,2,2,2,2,2,2,2,2,2,2,2,2,2,2,2,2,2,2,1
1,1,1,1,1,1,1,1,1,1,1,1,1,1,1,1,1,1,1,1,1,1,1,1,1,1,1,0,1
endlayer

layer
1,1,1,1,1,1,1,1,1,1,1,1,1,1,1,1,1,1,1,1,1,1,1,1,1,1,1,1,1
1,2,2,2,2,2,2,2,2,2,2,2,2,2,2,2,2,2,2,2,2,2,2,2,2,2,2,2,1
1,2,0,0,0,31,0,0,24,48,42,33,24,48,42,48,24,33,42,48,24,0,0,30,0,0,0,2,1
1,2,0,0,48,0,0,0,0,0,0,0,0,0,0,0,0,0,0,0,0,0,0,0,48,0,0,2,1
1,2,0,42,0,0,0,0,0,0,0,0,0,0,0,0,0,0,0,0,0,0,0,0,0,42,0,2,1
1,2,0,0,0,0,0,0,0,0,0,0,0,0,0,0,0,0,0,0,0,0,0,0,0,0,0,2,1
1,2,0,0,0,0,0,0,0,0,0,0,0,0,0,0,0,0,0,0,0,0,0,0,0,0,0,2,1
1,2,0,0,0,0,0,0,0,0,0,0,0,0,0,0,0,0,0,0,0,0,0,0,0,0,0,2,1
1,2,0,0,0,0,0,0,0,0,0,0,0,0,0,0,0,0,0,0,0,0,0,0,0,0,0,2,1
1,2,0,0,0,0,0,0,0,0,0,0,0,0,0,0,0,0,0,0,0,0,0,0,0,0,0,2,1
1,2,0,0,0,0,0,0,0,0,0,0,0,0,0,0,0,0,0,0,0,0,0,0,0,0,0,2,1
1,2,0,0,0,0,0,0,0,0,0,0,0,0,0,0,0,0,0,0,0,0,0,0,0,0,0,2,1
1,2,0,0,0,54,0,0,0,0,0,0,0,0,0,0,0,0,0,0,0,0,0,54,0,0,0,2,1
1,2,0,0,0,0,0,0,0,0,0,0,0,0,0,0,0,0,0,0,0,0,0,0,0,0,0,2,1
1,2,0,0,0,0,0,0,0,0,0,0,0,0,0,0,0,0,0,0,0,0,0,0,0,0,0,2,1
1,2,0,0,0,0,0,0,0,0,0,0,0,0,0,0,0,0,0,0,0,0,0,0,0,0,0,2,1
1,2,0,0,0,0,0,0,0,0,0,0,0,0,0,0,0,0,0,0,0,0,0,0,0,0,0,2,1
1,2,38,0,0,0,0,0,0,0,0,0,0,0,0,0,0,0,0,0,0,0,0,0,0,0,38,2,1
1,2,24,9,0,0,0,0,0,0,0,0,0,0,0,0,0,0,0,0,0,0,0,0,0,9,24,2,1
1,2,38,0,0,0,0,0,0,0,0,0,0,0,0,0,0,0,0,0,0,0,0,0,0,0,38,2,1
1,2,74,0,0,0,0,0,0,0,0,0,0,0,0,0,0,0,0,0,0,0,0,0,0,0,74,2,1
1,2,48,0,0,0,0,0,0,0,0,0,0,0,0,0,0,0,0,0,0,0,0,0,0,0,48,2,1
1,2,24,0,0,0,0,0,0,0,0,0,0,0,0,0,0,0,0,0,0,0,0,0,0,0,24,2,1
1,2,35,0,0,0,0,0,0,0,0,0,0,0,0,0,0,0,0,0,0,0,0,0,0,0,35,2,1
1,2,24,0,0,0,0,0,0,0,0,0,0,0,0,0,0,0,0,0,0,0,0,0,0,0,24,2,1
1,2,48,0,0,0,0,0,0,0,0,0,0,0,0,0,0,0,0,0,0,0,0,0,0,0,48,2,1
1,2,56,0,0,0,0,0,0,0,0,0,0,0,0,0,0,0,0,0,0,0,0,0,0,0,56,2,1
1,2,38,0,0,0,0,0,0,0,0,0,0,0,0,0,0,0,0,0,0,0,0,0,0,0,38,2,1
1,2,24,9,0,0,0,0,0,0,0,0,0,0,0,0,0,0,0,0,0,0,0,0,0,9,24,2,1
1,2,38,0,0,0,0,0,0,0,0,0,0,0,0,0,0,0,0,0,0,0,0,0,0,0,38,2,1
1,2,0,0,0,0,0,0,0,0,0,0,0,0,0,0,0,0,0,0,0,0,0,0,0,0,0,2,1
1,2,0,0,0,0,0,0,0,0,0,0,0,0,0,0,0,0,0,0,0,0,0,0,0,0,0,2,1
1,2,0,0,0,0,0,0,0,0,0,0,0,0,0,0,0,0,0,0,0,0,0,0,0,0,0,2,1
1,2,0,0,0,0,0,0,0,0,0,0,0,0,0,0,0,0,0,0,0,0,0,0,0,0,0,2,1
1,2,0,0,0,0,0,0,0,0,0,0,0,0,0,0,0,0,0,0,0,0,0,0,0,0,0,2,1
1,2,0,0,0,0,0,0,0,0,0,0,0,0,0,0,0,0,0,0,0,0,0,0,0,0,0,2,1
1,2,0,0,0,0,0,0,15,0,0,0,9,0,0,0,9,0,0,0,15,0,0,0,0,0,0,2,1
1,2,0,0,0,0,0,0,0,0,0,0,3,78,78,78,3,0,0,0,0,0,0,0,0,0,0,2,1
1,2,0,0,0,0,0,0,0,0,0,0,3,3,3,3,3,0,0,0,0,0,0,0,0,0,0,2,1
1,2,0,0,0,0,0,0,0,0,0,68,68,3,3,3,68,68,0,0,0,0,0,0,0,0,0,2,1
1,2,0,0,0,0,0,0,0,15,0,43,3,3,3,3,3,44,0,15,0,0,0,0,0,0,0,2,1
1,2,0,0,0,0,0,0,0,15,0,0,3,3,3,3,3,0,0,15,0,0,0,0,0,0,0,2,1
1,2,0,0,0,0,0,0,0,15,0,0,3,3,3,3,3,0,0,15,0,0,0,0,0,0,0,2,1
1,2,0,0,0,0,0,0,0,15,0,0,3,3,3,3,3,0,0,15,0,0,0,0,0,0,0,2,1
1,2,0,0,0,0,0,0,0,15,0,0,0,0,0,0,0,0,0,15,0,0,0,0,0,0,0,2,1
1,2,0,0,0,0,0,0,0,15,6,6,6,6,6,6,6,6,6,15,0,0,0,0,0,0,0,2,1
1,2,2,2,2,2,2,2,2,2,2,2,2,2,2,2,2,2,2,2,2,2,2,2,2,2,2,2,1
1,2,2,2,2,2,2,2,2,2,2,2,2,2,2,2,2,2,2,2,2,2,2,2,2,2,2,2,1
1,1,1,1,1,1,1,1,1,1,1,1,1,1,1,1,1,1,1,1,1,1,1,1,1,1,1,1,1
endlayer

layer
1,1,1,1,1,1,1,1,1,1,1,1,1,1,1,1,1,1,1,1,1,1,1,1,1,1,1,1,1
1,2,2,2,2,2,2,2,2,2,2,2,2,2,2,2,2,2,2,2,2,2,2,2,2,2,2,2,1
1,2,0,0,0,0,0,24,48,42,0,0,33,24,48,24,33,0,0,42,48,24,0,0,0,0,0,2,1
1,2,0,0,31,0,0,0,0,0,0,0,0,0,0,0,0,0,0,0,0,0,0,0,30,0,0,2,1
1,2,0,48,0,0,0,0,0,0,0,0,0,0,0,0,0,0,0,0,0,0,0,0,0,48,0,2,1
1,2,0,42,0,0,0,0,0,0,0,0,0,0,0,0,0,0,0,0,0,0,0,0,0,42,0,2,1
1,2,0,0,0,0,0,0,0,0,0,0,0,0,0,0,0,0,0,0,0,0,0,0,0,0,0,2,1
1,2,0,0,0,0,0,0,0,0,0,0,0,0,0,0,0,0,0,0,0,0,0,0,0,0,0,2,1
1,2,0,0,0,0,0,0,0,0,0,0,0,0,0,0,0,0,0,0,0,0,0,0,0,0,0,2,1
1,2,0,0,0,0,0,0,0,0,0,0,0,0,0,0,0,0,0,0,0,0,0,0,0,0,0,2,1
1,2,0,0,0,0,0,0,0,0,0,0,0,0,0,0,0,0,0,0,0,0,0,0,0,0,0,2,1
1,2,0,0,0,0,0,0,0,0,0,0,0,0,0,0,0,0,0,0,0,0,0,0,0,0,0,2,1
1,2,0,0,0,54,0,0,0,0,0,0,0,0,0,0,0,0,0,0,0,0,0,54,0,0,0,2,1
1,2,0,0,0,0,0,0,0,0,0,0,0,0,0,0,0,0,0,0,0,0,0,0,0,0,0,2,1
1,2,0,0,0,0,0,0,0,0,0,0,0,0,0,0,0,0,0,0,0,0,0,0,0,0,0,2,1
1,2,0,0,0,0,0,0,0,0,0,0,0,0,0,0,0,0,0,0,0,0,0,0,0,0,0,2,1
1,2,0,0,0,0,0,0,0,0,0,0,0,0,0,0,0,0,0,0,0,0,0,0,0,0,0,2,1
1,2,38,0,0,0,0,0,0,0,0,0,0,0,0,0,0,0,0,0,0,0,0,0,0,0,38,2,1
1,2,24,48,0,0,0,0,0,0,0,0,0,0,0,0,0,0,0,0,0,0,0,0,0,48,24,2,1
1,2,38,0,0,0,0,0,0,0,0,0,0,0,0,0,0,0,0,0,0,0,0,0,0,0,38,2,1
1,2,48,0,0,0,0,0,0,0,0,0,0,0,0,0,0,0,0,0,0,0,0,0,0,0,48,2,1
1,2,33,0,0,0,0,0,0,0,0,0,0,0,0,0,0,0,0,0,0,0,0,0,0,0,33,2,1
1,2,0,0,0,0,0,0,0,0,0,0,0,0,0,0,0,0,0,0,0,0,0,0,0,0,0,2,1
1,2,24,0,0,0,0,0,0,0,0,0,0,0,0,0,0,0,0,0,0,0,0,0,0,0,24,2,1
1,2,0,0,0,0,0,0,0,0,0,0,0,0,0,0,0,0,0,0,0,0,0,0,0,0,0,2,1
1,2,29,0,0,0,0,0,0,0,0,0,0,0,0,0,0,0,0,0,0,0,0,0,0,0,29,2,1
1,2,48,0,0,0,0,0,0,0,0,0,0,0,0,0,0,0,0,0,0,0,0,0,0,0,48,2,1
1,2,38,0,0,0,0,0,0,0,0,0,0,0,0,0,0,0,0,0,0,0,0,0,0,0,38,2,1
1,2,24,48,0,0,0,0,0,0,0,0,0,0,0,0,0,0,0,0,0,0,0,0,0,48,24,2,1
1,2,38,0,0,0,0,0,0,0,0,0,0,0,0,0,0,0,0,0,0,0,0,0,0,0,38,2,1
1,2,0,0,0,0,0,0,0,0,0,0,0,0,0,0,0,0,0,0,0,0,0,0,0,0,0,2,1
1,2,0,0,0,0,0,0,0,0,0,0,0,0,0,0,0,0,0,0,0,0,0,0,0,0,0,2,1
1,2,0,0,0,0,0,0,0,0,0,0,0,0,0,0,0,0,0,0,0,0,0,0,0,0,0,2,1
1,2,0,0,0,0,0,0,0,0,0,0,0,0,0,0,0,0,0,0,0,0,0,0,0,0,0,2,1
1,2,0,0,0,0,0,0,0,0,0,0,0,0,0,0,0,0,0,0,0,0,0,0,0,0,0,2,1
1,2,0,0,0,0,0,0,0,0,0,0,0,0,0,0,0,0,0,0,0,0,0,0,0,0,0,2,1
1,2,0,0,0,0,0,0,15,34,0,36,9,41,37,40,9,34,0,36,15,0,0,0,0,0,0,2,1
1,2,0,0,0,0,0,0,0,0,0,0,0,0,0,0,0,0,0,0,0,0,0,0,0,0,0,2,1
1,2,0,0,0,0,0,0,0,0,0,0,0,0,0,0,0,0,0,0,0,0,0,0,0,0,0,2,1
1,2,0,0,0,0,0,0,0,0,0,0,0,0,0,0,0,0,0,0,0,0,0,0,0,0,0,2,1
1,2,0,0,0,0,0,0,0,0,52,0,0,0,0,0,0,0,52,0,0,0,0,0,0,0,0,2,1
1,2,0,0,0,0,0,0,0,0,52,0,0,0,0,0,0,0,52,0,0,0,0,0,0,0,0,2,1
1,2,0,0,0,0,0,0,0,0,52,0,79,79,79,79,79,0,52,0,0,0,0,0,0,0,0,2,1
1,2,0,0,0,0,0,0,0,0,52,0,3,3,3,3,3,0,52,0,0,0,0,0,0,0,0,2,1
1,2,0,0,0,0,0,0,0,0,52,0,3,3,3,3,3,0,52,0,0,0,0,0,0,0,0,2,1
1,2,0,0,0,0,0,0,0,0,52,6,3,3,3,3,3,6,52,0,0,0,0,0,0,0,0,2,1
1,2,2,2,2,2,2,2,2,2,2,2,2,2,2,2,2,2,2,2,2,2,2,2,2,2,2,2,1
1,2,2,2,2,2,2,2,2,2,2,2,2,2,2,2,2,2,2,2,2,2,2,2,2,2,2,2,1
1,1,1,1,1,1,1,1,1,1,1,1,1,1,1,1,1,1,1,1,1,1,1,1,1,1,1,1,1
endlayer

layer
1,1,1,1,1,1,1,1,1,1,1,1,1,1,1,1,1,1,1,1,1,1,1,1,1,1,1,1,1
1,2,2,2,2,2,2,2,2,2,2,2,2,2,2,2,2,2,2,2,2,2,2,2,2,2,2,2,1
1,2,0,0,0,0,24,48,42,0,0,0,0,33,24,33,0,0,0,0,42,48,24,0,0,0,0,2,1
1,2,0,0,0,0,0,0,0,0,0,0,0,0,0,0,0,0,0,0,0,0,0,0,0,0,0,2,1
1,2,0,29,0,0,0,0,0,0,0,0,0,0,0,0,0,0,0,0,0,0,0,0,0,29,0,2,1
1,2,0,48,42,0,0,0,0,0,0,0,0,0,0,0,0,0,0,0,0,0,0,0,42,48,0,2,1
1,2,0,0,0,0,0,0,0,0,0,0,0,0,0,0,0,0,0,0,0,0,0,0,0,0,0,2,1
1,2,0,0,0,0,0,0,0,0,0,0,0,0,0,0,0,0,0,0,0,0,0,0,0,0,0,2,1
1,2,0,0,0,0,0,0,0,0,0,0,0,0,0,0,0,0,0,0,0,0,0,0,0,0,0,2,1
1,2,0,0,0,0,0,0,0,0,0,0,0,0,0,0,0,0,0,0,0,0,0,0,0,0,0,2,1
1,2,0,0,0,0,0,0,0,0,0,0,0,0,0,0,0,0,0,0,0,0,0,0,0,0,0,2,1
1,2,0,0,0,0,0,0,0,0,0,0,0,0,0,0,0,0,0,0,0,0,0,0,0,0,0,2,1
1,2,0,0,0,54,0,0,0,0,0,0,0,0,0,0,0,0,0,0,0,0,0,54,0,0,0,2,1
1,2,0,0,0,0,0,0,0,0,0,0,0,0,0,0,0,0,0,0,0,0,0,0,0,0,0,2,1
1,2,0,0,0,0,0,0,0,0,0,0,0,0,0,0,0,0,0,0,0,0,0,0,0,0,0,2,1
1,2,0,0,0,0,0,0,0,0,0,0,0,0,0,0,0,0,0,0,0,0,0,0,0,0,0,2,1
1,2,0,0,0,0,0,0,0,0,0,0,0,0,0,0,0,0,0,0,0,0,0,0,0,0,0,2,1
1,2,38,0,0,0,0,0,0,0,0,0,0,0,0,0,0,0,0,0,0,0,0,0,0,0,38,2,1
1,2,24,9,0,0,0,0,0,0,0,0,0,0,0,0,0,0,0,0,0,0,0,0,0,9,24,2,1
1,2,38,0,0,0,0,0,0,0,0,0,0,0,0,0,0,0,0,0,0,0,0,0,0,0,38,2,1
1,2,54,0,0,0,0,0,0,0,0,0,0,0,0,0,0,0,0,0,0,0,0,0,0,0,54,2,1
1,2,0,0,0,0,0,0,0,0,0,0,0,0,0,0,0,0,0,0,0,0,0,0,0,0,0,2,1
1,2,0,0,0,0,0,0,0,0,0,0,0,0,0,0,0,0,0,0,0,0,0,0,0,0,0,2,1
1,2,54,0,0,0,0,0,0,0,0,0,0,0,0,0,0,0,0,0,0,0,0,0,0,0,54,2,1
1,2,0,0,0,0,0,0,0,0,0,0,0,0,0,0,0,0,0,0,0,0,0,0,0,0,0,2,1
1,2,0,0,0,0,0,0,0,0,0,0,0,0,0,0,0,0,0,0,0,0,0,0,0,0,0,2,1
1,2,54,0,0,0,0,0,0,0,0,0,0,0,0,0,0,0,0,0,0,0,0,0,0,0,54,2,1
1,2,38,0,0,0,0,0,0,0,0,0,0,0,0,0,0,0,0,0,0,0,0,0,0,0,38,2,1
1,2,24,9,0,0,0,0,0,0,0,0,0,0,0,0,0,0,0,0,0,0,0,0,0,9,24,2,1
1,2,38,0,0,0,0,0,0,0,0,0,0,0,0,0,0,0,0,0,0,0,0,0,0,0,38,2,1
1,2,0,0,0,0,0,0,0,0,0,0,0,0,0,0,0,0,0,0,0,0,0,0,0,0,0,2,1
1,2,0,0,0,0,0,0,0,0,0,0,0,0,0,0,0,0,0,0,0,0,0,0,0,0,0,2,1
1,2,0,0,0,0,0,0,0,0,0,0,0,0,0,0,0,0,0,0,0,0,0,0,0,0,0,2,1
1,2,0,0,0,0,0,0,0,0,0,0,0,0,0,0,0,0,0,0,0,0,0,0,0,0,0,2,1
1,2,0,0,0,0,0,0,0,0,0,0,0,0,0,0,0,0,0,0,0,0,0,0,0,0,0,2,1
1,2,0,0,0,0,0,0,0,0,0,0,0,0,0,0,0,0,0,0,0,0,0,0,0,0,0,2,1
1,2,0,0,0,0,0,0,62,15,62,15,62,6,6,6,62,15,62,15,62,0,0,0,0,0,0,2,1
1,2,0,0,0,0,0,0,0,0,0,0,0,0,0,0,0,0,0,0,0,0,0,0,0,0,0,2,1
1,2,0,0,0,0,0,0,0,0,0,0,0,0,0,0,0,0,0,0,0,0,0,0,0,0,0,2,1
1,2,0,0,0,0,0,0,0,0,0,0,0,0,0,0,0,0,0,0,0,0,0,0,0,0,0,2,1
1,2,0,0,0,0,0,0,0,0,0,0,0,0,0,0,0,0,0,0,0,0,0,0,0,0,0,2,1
1,2,0,0,0,0,0,0,0,0,0,0,0,0,0,0,0,0,0,0,0,0,0,0,0,0,0,2,1
1,2,0,0,0,0,0,0,0,0,0,0,0,0,0,0,0,0,0,0,0,0,0,0,0,0,0,2,1
1,2,0,0,0,0,0,0,0,0,0,3,50,0,0,0,50,3,0,0,0,0,0,0,0,0,0,2,1
1,2,0,0,0,0,0,0,0,0,0,3,41,0,0,0,40,3,0,0,0,0,0,0,0,0,0,2,1
1,2,0,0,0,0,0,0,0,0,0,3,37,0,0,0,37,3,0,0,0,0,0,0,0,0,0,2,1
1,2,2,2,2,2,2,2,2,2,2,2,2,2,2,2,2,2,2,2,2,2,2,2,2,2,2,2,1
1,2,2,2,2,2,2,2,2,2,2,2,2,2,2,2,2,2,2,2,2,2,2,2,2,2,2,2,1
1,1,1,1,1,1,1,1,1,1,1,1,1,1,1,1,1,1,1,1,1,1,1,1,1,1,1,1,1
endlayer

layer
1,1,1,1,1,1,1,1,1,1,1,1,1,1,1,1,1,1,1,1,1,1,1,1,1,1,1,1,1
1,2,2,2,2,2,2,2,2,2,2,2,2,2,2,2,2,2,2,2,2,2,2,2,2,2,2,2,1
1,2,0,0,0,24,48,42,0,0,0,0,0,0,33,0,0,0,0,0,0,42,48,24,0,0,0,2,1
1,2,0,0,0,0,0,0,0,0,0,0,0,0,0,0,0,0,0,0,0,0,0,0,0,0,0,2,1
1,2,0,0,42,0,0,0,0,0,0,0,0,0,0,0,0,0,0,0,0,0,0,0,42,0,0,2,1
1,2,0,30,48,0,0,0,0,0,0,0,0,0,0,0,0,0,0,0,0,0,0,0,48,31,0,2,1
1,2,0,0,0,0,0,0,0,0,0,0,0,0,0,0,0,0,0,0,0,0,0,0,0,0,0,2,1
1,2,0,0,0,0,0,0,0,0,0,0,0,0,0,0,0,0,0,0,0,0,0,0,0,0,0,2,1
1,2,0,0,0,0,0,0,0,0,0,0,0,0,0,0,0,0,0,0,0,0,0,0,0,0,0,2,1
1,2,0,0,0,0,0,0,0,0,0,0,0,0,0,0,0,0,0,0,0,0,0,0,0,0,0,2,1
1,2,0,0,0,0,0,0,0,0,0,0,0,0,0,0,0,0,0,0,0,0,0,0,0,0,0,2,1
1,2,0,0,0,0,0,0,0,0,0,0,0,0,0,0,0,0,0,0,0,0,0,0,0,0,0,2,1
1,2,0,0,0,54,0,0,0,0,0,0,0,0,0,0,0,0,0,0,0,0,0,54,0,0,0,2,1
1,2,0,0,0,0,0,0,0,0,0,0,0,0,0,0,0,0,0,0,0,0,0,0,0,0,0,2,1
1,2,0,0,0,0,0,0,0,0,0,0,0,0,0,0,0,0,0,0,0,0,0,0,0,0,0,2,1
1,2,0,0,0,0,0,0,0,0,0,0,0,0,0,0,0,0,0,0,0,0,0,0,0,0,0,2,1
1,2,0,0,0,0,0,0,0,0,0,0,0,0,0,0,0,0,0,0,0,0,0,0,0,0,0,2,1
1,2,38,0,0,0,0,0,0,0,0,0,0,0,0,0,0,0,0,0,0,0,0,0,0,0,38,2,1
1,2,24,9,0,0,0,0,0,0,0,0,0,0,0,0,0,0,0,0,0,0,0,0,0,9,24,2,1
1,2,38,0,0,0,0,0,0,0,0,0,0,0,0,0,0,0,0,0,0,0,0,0,0,0,38,2,1
1,2,54,0,0,0,0,0,0,0,0,0,0,0,0,0,0,0,0,0,0,0,0,0,0,0,54,2,1
1,2,0,0,0,0,0,0,0,0,0,0,0,0,0,0,0,0,0,0,0,0,0,0,0,0,0,2,1
1,2,0,0,0,0,0,0,0,0,0,0,0,0,0,0,0,0,0,0,0,0,0,0,0,0,0,2,1
1,2,54,0,0,0,0,0,0,0,0,0,0,0,0,0,0,0,0,0,0,0,0,0,0,0,54,2,1
1,2,0,0,0,0,0,0,0,0,0,0,0,0,0,0,0,0,0,0,0,0,0,0,0,0,0,2,1
1,2,0,0,0,0,0,0,0,0,0,0,0,0,0,0,0,0,0,0,0,0,0,0,0,0,0,2,1
1,2,54,0,0,0,0,0,0,0,0,0,0,0,0,0,0,0,0,0,0,0,0,0,0,0,54,2,1
1,2,38,0,0,0,0,0,0,0,0,0,0,0,0,0,0,0,0,0,0,0,0,0,0,0,38,2,1
1,2,24,9,0,0,0,0,0,0,0,0,0,0,0,0,0,0,0,0,0,0,0,0,0,9,24,2,1
1,2,38,0,0,0,0,0,0,0,0,0,0,0,0,0,0,0,0,0,0,0,0,0,0,0,38,2,1
1,2,0,0,0,0,0,0,0,0,0,0,0,0,0,0,0,0,0,0,0,0,0,0,0,0,0,2,1
1,2,0,0,0,0,0,0,0,0,0,0,0,0,0,0,0,0,0,0,0,0,0,0,0,0,0,2,1
1,2,0,0,0,0,0,0,0,0,0,0,0,0,0,0,0,0,0,0,0,0,0,0,0,0,0,2,1
1,2,0,0,0,0,0,0,0,0,0,0,0,0,0,0,0,0,0,0,0,0,0,0,0,0,0,2,1
1,2,0,0,0,0,0,0,0,0,0,0,0,0,0,0,0,0,0,0,0,0,0,0,0,0,0,2,1
1,2,0,0,0,0,0,0,0,0,0,0,0,0,0,0,0,0,0,0,0,0,0,0,0,0,0,2,1
1,2,0,0,0,0,0,0,0,0,0,0,0,0,0,0,0,0,0,0,0,0,0,0,0,0,0,2,1
1,2,0,0,0,0,0,0,0,0,0,0,0,0,0,0,0,0,0,0,0,0,0,0,0,0,0,2,1
1,2,0,0,0,0,0,0,0,0,0,0,0,0,0,0,0,0,0,0,0,0,0,0,0,0,0,2,1
1,2,0,0,0,0,0,0,0,0,0,0,0,0,0,0,0,0,0,0,0,0,0,0,0,0,0,2,1
1,2,0,0,0,0,0,0,0,0,0,0,0,0,0,0,0,0,0,0,0,0,0,0,0,0,0,2,1
1,2,0,0,0,0,0,0,0,0,0,0,0,0,0,0,0,0,0,0,0,0,0,0,0,0,0,2,1
1,2,0,0,0,0,0,0,0,0,0,0,0,0,0,0,0,0,0,0,0,0,0,0,0,0,0,2,1
1,2,0,0,0,0,0,0,0,0,3,50,0,0,0,0,0,50,3,0,0,0,0,0,0,0,0,2,1
1,2,0,0,0,0,0,0,0,0,3,41,0,0,0,0,0,40,3,0,0,0,0,0,0,0,0,2,1
1,2,0,0,0,0,0,0,0,0,3,37,0,0,0,0,0,37,3,0,0,0,0,0,0,0,0,2,1
1,2,2,2,2,2,2,2,2,2,2,2,2,2,2,2,2,2,2,2,2,2,2,2,2,2,2,2,1
1,2,2,2,2,2,2,2,2,2,2,2,2,2,2,2,2,2,2,2,2,2,2,2,2,2,2,2,1
1,1,1,1,1,1,1,1,1,1,1,1,1,1,1,1,1,1,1,1,1,1,1,1,1,1,1,1,1
endlayer

layer
1,1,1,1,1,1,1,1,1,1,1,1,1,1,1,1,1,1,1,1,1,1,1,1,1,1,1,1,1
1,2,2,2,2,2,2,2,2,2,2,2,2,2,2,2,2,2,2,2,2,2,2,2,2,2,2,2,1
1,2,80,80,24,48,42,81,81,81,81,81,81,81,81,81,81,81,81,81,81,81,42,48,24,80,80,2,1
1,2,83,81,81,81,81,81,81,81,81,81,81,81,81,81,81,81,81,81,81,81,81,81,81,81,82,2,1
1,2,83,81,48,81,81,81,81,81,81,81,81,81,81,81,81,81,81,81,81,81,81,81,48,81,82,2,1
1,2,83,81,33,81,81,81,81,81,81,81,81,81,81,81,81,81,81,81,81,81,81,81,33,81,82,2,1
1,2,83,81,81,81,81,81,81,81,81,81,81,81,81,81,81,81,81,81,81,81,81,81,81,81,82,2,1
1,2,83,81,81,81,81,81,81,81,81,81,81,81,81,81,81,81,81,81,81,81,81,81,81,81,82,2,1
1,2,83,81,81,81,81,81,81,81,81,81,81,81,81,81,81,81,81,81,81,81,81,81,81,81,82,2,1
1,2,83,81,81,81,81,81,81,81,81,81,81,81,81,81,81,81,81,81,81,81,81,81,81,81,82,2,1
1,2,83,81,81,81,81,81,81,81,81,81,81,81,81,81,81,81,81,81,81,81,81,81,81,81,82,2,1
1,2,83,81,81,81,81,81,81,81,81,81,81,81,81,81,81,81,81,81,81,81,81,81,81,81,82,2,1
1,2,83,81,81,84,81,81,81,81,81,81,81,81,81,81,81,81,81,81,81,81,81,84,81,81,82,2,1
1,2,83,81,81,81,81,81,81,81,81,81,81,81,81,81,81,81,81,81,81,81,81,81,81,81,82,2,1
1,2,83,81,81,81,81,81,81,81,81,81,81,81,81,81,81,81,81,81,81,81,81,81,81,81,82,2,1
1,2,83,81,81,81,81,81,81,81,81,81,81,81,81,81,81,81,81,81,81,81,81,81,81,81,82,2,1
1,2,83,81,81,81,81,81,81,81,81,81,81,81,81,81,81,81,81,81,81,81,81,81,81,81,82,2,1
1,2,9,81,81,81,81,81,81,81,81,81,81,81,81,81,81,81,81,81,81,81,81,81,81,81,9,2,1
1,2,24,9,81,81,81,81,81,81,81,81,81,81,81,81,81,81,81,81,81,81,81,81,81,9,24,2,1
1,2,9,81,81,81,81,81,81,81,81,81,81,81,81,81,81,81,81,81,81,81,81,81,81,81,9,2,1
1,2,83,81,81,81,81,81,81,81,81,81,81,81,81,81,81,81,81,81,81,81,81,81,81,81,82,2,1
1,2,83,81,81,81,81,81,81,81,81,81,81,81,81,81,81,81,81,81,81,81,81,81,81,81,82,2,1
1,2,83,81,81,81,81,81,81,81,81,81,81,81,81,81,81,81,81,81,81,81,81,81,81,81,82,2,1
1,2,83,81,81,81,81,81,81,81,81,81,81,81,81,81,81,81,81,81,81,81,81,81,81,81,82,2,1
1,2,83,81,81,81,81,81,81,81,81,81,81,81,81,81,81,81,81,81,81,81,81,81,81,81,82,2,1
1,2,83,81,81,81,81,81,81,81,81,81,81,81,81,81,81,81,81,81,81,81,81,81,81,81,82,2,1
1,2,83,81,81,81,81,81,81,81,81,81,81,81,81,81,81,81,81,81,81,81,81,81,81,81,82,2,1
1,2,9,81,81,81,81,81,81,81,81,81,81,81,81,81,81,81,81,81,81,81,81,81,81,81,9,2,1
1,2,24,9,81,81,81,81,81,81,81,81,81,81,81,81,81,81,81,81,81,81,81,81,81,9,24,2,1
1,2,9,81,81,81,81,81,81,81,81,81,81,81,81,81,81,81,81,81,81,81,81,81,81,81,9,2,1
1,2,83,81,81,81,81,81,81,81,81,81,81,81,81,81,81,81,81,81,81,81,81,81,81,81,82,2,1
1,2,83,81,81,81,81,81,81,81,81,81,81,81,81,81,81,81,81,81,81,81,81,81,81,81,82,2,1
1,2,83,81,81,81,81,81,81,81,81,81,81,81,81,81,81,81,81,81,81,81,81,81,81,81,82,2,1
1,2,83,81,81,81,81,81,81,81,81,81,81,81,81,81,81,81,81,81,81,81,81,81,81,81,82,2,1
1,2,83,81,81,81,81,81,81,81,81,81,81,81,81,81,81,81,81,81,81,81,81,81,81,81,82,2,1
1,2,83,81,81,81,81,81,81,81,81,81,81,81,81,81,81,81,81,81,81,81,81,81,81,81,82,2,1
1,2,83,81,81,81,81,81,81,81,81,81,81,81,81,81,81,81,81,81,81,81,81,81,81,81,82,2,1
1,2,83,81,81,81,81,81,81,81,81,81,81,81,81,81,81,81,81,81,81,81,81,81,81,81,82,2,1
1,2,83,81,81,81,81,81,81,81,81,81,81,81,81,81,81,81,81,81,81,81,81,81,81,81,82,2,1
1,2,83,81,81,81,81,81,81,81,81,81,81,81,81,81,81,81,81,81,81,81,81,81,81,81,82,2,1
1,2,83,81,81,81,81,81,81,81,81,81,81,81,81,81,81,81,81,81,81,81,81,81,81,81,82,2,1
1,2,83,81,81,81,81,81,81,81,81,81,81,81,81,81,81,81,81,81,81,81,81,81,81,81,82,2,1
1,2,83,81,81,81,81,81,81,81,81,81,81,81,81,81,81,81,81,81,81,81,81,81,81,81,82,2,1
1,2,83,81,81,81,81,81,81,3,50,0,0,0,0,0,0,0,50,3,81,81,81,81,81,81,82,2,1
1,2,83,81,81,81,81,81,81,3,41,0,0,0,0,0,0,0,40,3,81,81,81,81,81,81,82,2,1
1,2,85,85,85,85,85,85,85,3,37,0,0,0,0,0,0,0,37,3,85,85,85,85,85,85,85,2,1
1,2,2,2,2,2,2,2,2,2,2,2,2,2,2,2,2,2,2,2,2,2,2,2,2,2,2,2,1
1,2,2,2,2,2,2,2,2,2,2,2,2,2,2,2,2,2,2,2,2,2,2,2,2,2,2,2,1
1,1,1,1,1,1,1,1,1,1,1,1,1,1,1,1,1,1,1,1,1,1,1,1,1,1,1,1,1
endlayer

layer
0,0,0,0,0,0,0,0,0,0,0,0,0,0,0,0,0,0,0,0,0,0,0,0,0,0,0,0,0
0,86,86,86,86,86,86,86,86,86,86,86,86,86,86,86,86,86,86,86,86,86,86,86,86,86,86,86,0
0,86,86,86,86,86,86,86,86,86,86,86,86,86,86,86,86,86,86,86,86,86,86,86,86,86,86,86,0
0,86,86,65,65,65,65,65,65,86,86,65,65,65,65,65,65,65,86,86,65,65,65,65,65,65,86,86,0
0,86,86,65,65,65,65,65,86,86,65,65,65,65,65,65,65,65,65,86,86,65,65,65,65,65,86,86,0
0,86,86,65,65,59,65,86,86,65,65,86,65,65,65,65,65,86,65,65,86,86,65,59,65,65,86,86,0
0,86,86,65,65,65,86,86,86,65,86,86,86,65,65,65,86,86,86,65,86,86,86,65,65,65,86,86,0
0,86,86,65,65,86,86,86,65,86,86,86,86,86,65,86,86,86,86,86,65,86,86,86,65,65,86,86,0
0,86,86,65,86,86,86,86,86,86,86,86,86,86,86,86,86,86,86,86,86,86,86,86,86,65,86,86,0
0,86,86,86,86,86,86,86,86,86,86,87,87,87,87,87,87,87,86,86,86,86,86,86,86,86,86,86,0
0,86,86,86,86,86,86,86,86,86,87,87,65,65,65,65,65,87,87,86,86,86,86,86,86,86,86,86,0
0,86,86,86,86,86,86,86,86,87,87,65,65,59,65,59,65,65,87,87,86,86,86,86,86,86,86,86,0
0,86,86,86,86,86,86,86,86,87,65,65,59,59,65,65,59,65,65,87,86,86,86,86,86,86,86,86,0
0,86,86,86,86,86,86,86,86,87,65,59,65,59,65,59,65,59,65,87,86,86,86,86,86,86,86,86,0
0,86,86,86,86,86,86,86,86,87,65,59,59,59,59,59,65,59,65,87,86,86,86,86,86,86,86,86,0
0,86,86,86,86,86,86,86,86,87,65,59,65,59,59,59,65,59,65,87,86,86,86,86,86,86,86,86,0
0,86,86,86,86,86,86,86,86,87,65,59,65,65,65,59,65,59,65,87,86,86,86,86,86,86,86,86,0
0,86,86,86,86,86,86,86,86,87,65,65,59,65,65,65,59,65,65,87,86,86,86,86,86,86,86,86,0
0,86,86,86,86,86,86,86,86,87,87,65,65,59,65,65,65,65,87,87,86,86,86,86,86,86,86,86,0
0,86,86,86,86,86,86,86,86,86,87,87,65,65,65,65,65,88,88,86,86,86,86,86,86,86,86,86,0
0,86,86,65,86,86,86,86,86,86,86,87,87,87,65,87,87,88,86,86,86,86,86,86,86,65,86,86,0
0,86,86,65,65,86,86,86,86,86,86,86,86,87,65,87,86,86,86,86,86,86,86,86,65,65,86,86,0
0,86,86,65,65,65,86,86,86,86,86,86,86,87,65,87,86,86,86,86,86,86,86,65,65,65,86,86,0
0,86,86,65,65,65,65,86,86,86,86,86,86,87,65,87,86,86,86,86,86,86,65,65,65,65,86,86,0
0,86,86,65,65,65,65,65,86,86,86,86,86,87,65,87,86,86,86,86,86,65,65,65,65,65,86,86,0
0,86,86,65,65,65,65,86,86,86,86,86,86,87,65,87,86,86,86,86,86,86,65,65,65,65,86,86,0
0,86,86,65,65,65,86,86,86,86,86,86,86,87,65,87,86,86,86,86,86,86,86,65,65,65,86,86,0
0,86,86,65,65,86,86,86,86,86,86,86,86,87,65,87,86,86,86,86,86,86,86,86,65,65,86,86,0
0,86,86,65,86,86,86,86,86,86,86,86,86,87,65,87,86,86,86,86,86,86,86,86,86,65,86,86,0
0,86,86,86,86,86,86,86,86,86,86,86,86,87,65,87,86,86,86,86,86,86,86,86,86,86,86,86,0
0,86,86,86,86,86,86,86,86,86,86,86,86,87,65,87,86,86,86,86,86,86,86,86,86,86,86,86,0
0,86,86,86,86,86,86,86,86,86,86,86,86,87,65,87,86,86,86,86,86,86,86,86,86,86,86,86,0
0,86,86,86,86,86,86,59,86,86,86,86,86,87,65,87,86,86,86,86,86,59,86,86,86,86,86,86,0
0,86,86,86,86,86,86,86,86,86,86,86,86,87,65,87,86,86,86,86,86,86,86,86,86,86,86,86,0
0,86,86,86,86,86,86,86,86,86,86,86,86,87,65,87,86,86,86,86,86,86,86,86,86,86,86,86,0
0,86,86,86,86,86,86,86,86,86,86,86,86,87,65,87,86,86,86,86,86,86,86,86,86,86,86,86,0
0,86,86,86,86,86,86,86,86,86,86,86,86,87,65,87,86,86,86,86,86,86,86,86,86,86,86,86,0
0,86,86,86,86,86,86,86,86,86,86,86,86,87,65,87,86,86,86,86,86,86,86,86,86,86,86,86,0
0,86,86,86,86,86,86,86,86,86,59,59,65,87,65,87,65,59,59,86,86,86,86,86,86,86,86,86,0
0,86,86,86,86,86,86,86,86,86,89,89,89,89,89,89,89,89,89,59,86,86,86,86,86,86,86,86,0
0,86,86,86,86,86,86,86,59,89,89,89,89,89,89,89,89,89,89,89,59,86,86,86,86,86,86,86,0
0,86,86,86,86,86,59,59,89,89,89,89,89,89,89,89,89,89,89,89,89,59,59,86,86,86,86,86,0
0,86,86,86,86,86,59,89,89,89,89,89,89,89,89,89,89,89,89,89,89,89,59,86,86,86,86,86,0
0,86,86,86,86,86,86,89,89,50,0,0,0,0,0,0,0,0,0,50,89,89,86,86,86,86,86,86,0
0,86,86,86,86,86,86,89,89,41,0,0,0,0,0,0,0,0,0,40,89,89,86,86,86,86,86,86,0
0,86,86,86,86,86,86,89,89,37,0,0,0,0,0,0,0,0,0,90,89,89,86,86,86,86,86,86,0
0,86,86,86,86,86,86,86,2,2,2,2,2,2,2,2,2,2,2,2,2,86,86,86,86,86,86,86,0
0,86,86,86,86,86,86,86,86,86,86,86,86,86,86,86,86,86,86,86,86,86,86,86,86,86,86,86,0
0,0,0,0,0,0,0,0,0,0,0,0,0,0,0,0,0,0,0,0,0,0,0,0,0,0,0,0,0
endlayer

layer
0,0,0,0,0,0,0,0,0,0,0,0,0,0,0,0,0,0,0,0,0,0,0,0,0,0,0,0,0
0,91,91,91,91,0,0,0,0,0,0,0,0,0,0,0,0,0,0,0,0,0,0,0,91,91,91,91,0
0,91,0,0,0,0,0,0,0,0,0,0,0,0,0,0,0,0,0,0,0,0,0,0,0,0,0,91,0
0,91,0,0,0,0,0,0,0,0,0,0,0,0,0,0,0,0,0,0,0,0,0,0,0,0,0,91,0
0,91,0,0,0,0,0,0,0,0,0,0,0,0,0,0,0,0,0,0,0,0,0,0,0,0,0,91,0
0,91,0,0,0,92,0,0,0,0,0,0,0,0,0,0,0,0,0,0,0,0,0,92,0,0,0,91,0
0,91,0,0,0,0,0,0,0,0,0,0,0,0,0,0,0,0,0,0,0,0,0,0,0,0,0,91,0
0,91,0,0,0,0,0,0,0,0,0,0,0,0,0,0,0,0,0,0,0,0,0,0,0,0,0,91,0
0,91,0,0,0,0,0,0,0,0,0,48,87,0,0,0,87,48,0,0,0,0,0,0,0,0,0,91,0
0,91,0,0,0,0,0,0,0,0,26,0,0,0,0,0,0,0,26,0,0,0,0,0,0,0,0,91,0
0,91,0,0,0,0,0,0,0,48,0,0,93,93,93,93,93,0,0,48,0,0,0,0,0,0,0,91,0
0,91,0,0,0,0,0,0,26,0,0,93,93,26,26,26,93,93,0,0,26,0,0,0,0,0,0,91,0
0,91,0,0,0,0,0,48,0,0,93,93,26,48,48,48,26,93,93,0,0,48,0,0,0,0,0,91,0
0,91,0,0,0,0,0,26,0,0,93,26,48,48,48,48,48,26,93,0,0,26,0,0,0,0,0,91,0
0,91,0,0,0,0,0,48,0,0,93,26,48,48,48,48,48,26,93,0,0,48,0,0,0,0,0,91,0
0,91,0,0,0,0,0,26,0,0,93,26,48,48,48,48,48,26,93,0,0,26,0,0,0,0,0,91,0
0,91,0,0,0,0,0,48,0,0,93,26,48,48,48,48,48,26,93,0,0,48,0,0,0,0,0,91,0
0,91,0,0,0,0,0,26,0,0,93,93,26,48,48,48,26,93,93,0,0,26,0,0,0,0,0,91,0
0,91,0,0,0,0,0,48,0,0,0,93,93,26,26,26,93,93,0,0,0,48,0,0,0,0,0,91,0
0,91,0,0,0,0,0,0,26,0,0,0,93,93,93,93,0,0,0,0,26,0,0,0,0,0,0,91,0
0,91,0,0,0,0,0,0,0,48,0,0,0,0,0,0,0,0,0,48,0,0,0,0,0,0,0,91,0
0,91,0,0,0,0,0,0,0,0,26,0,0,0,0,0,0,0,26,0,0,0,0,0,0,0,0,91,0
0,91,0,0,0,0,0,0,0,0,0,26,0,0,0,0,0,26,0,0,0,0,0,0,0,0,0,91,0
0,91,0,0,0,0,0,0,0,0,0,48,0,0,0,0,0,48,0,0,0,0,0,0,0,0,0,91,0
0,91,0,0,0,0,0,0,0,0,0,26,0,0,0,0,0,26,0,0,0,0,0,0,0,0,0,91,0
0,91,0,0,0,0,0,0,0,0,0,48,0,0,0,0,0,48,0,0,0,0,0,0,0,0,0,91,0
0,91,0,0,0,0,0,0,0,0,26,0,0,0,0,0,0,0,26,0,0,0,0,0,0,0,0,91,0
0,91,0,0,0,0,0,0,0,0,48,0,0,0,0,0,0,0,48,0,0,0,0,0,0,0,0,91,0
0,91,0,0,0,0,0,0,0,0,26,0,0,0,0,0,0,0,26,0,0,0,0,0,0,0,0,91,0
0,91,0,0,0,0,0,0,0,0,48,0,0,0,0,0,0,0,48,0,0,0,0,0,0,0,0,91,0
0,91,0,0,0,0,0,0,0,0,26,0,0,0,0,0,0,0,26,0,0,0,0,0,0,0,0,91,0
0,91,0,0,0,0,0,0,0,0,26,0,0,0,0,0,0,0,26,0,0,0,0,0,0,0,0,91,0
0,91,0,0,0,0,0,92,0,26,0,0,0,0,0,0,0,0,0,26,0,92,0,0,0,0,0,91,0
0,91,0,0,0,0,0,0,26,0,0,0,0,0,0,0,0,0,0,0,26,0,0,0,0,0,0,91,0
0,91,0,0,0,0,0,26,0,0,0,0,0,0,0,0,0,0,0,0,0,26,0,0,0,0,0,91,0
0,91,0,0,0,0,26,0,0,0,0,0,0,0,0,0,0,0,0,0,0,0,26,0,0,0,0,91,0
0,91,0,0,0,26,0,0,0,0,0,0,0,0,0,0,0,0,0,0,0,0,0,26,0,0,0,91,0
0,91,0,0,26,0,0,0,0,0,0,0,0,0,0,0,0,0,0,0,0,0,0,0,26,0,0,91,0
0,91,0,26,0,0,0,0,0,0,89,89,31,0,0,0,30,89,89,0,0,0,0,0,0,26,0,91,0
0,91,0,26,0,0,0,0,0,89,0,0,0,0,0,0,0,0,0,89,0,0,0,0,0,26,0,91,0
0,91,0,26,0,0,0,0,89,0,0,0,0,0,0,0,0,0,0,0,89,0,0,0,0,26,0,91,0
0,91,0,26,0,0,89,89,0,0,0,0,0,0,0,0,0,0,0,0,0,89,89,0,0,26,0,91,0
0,91,0,26,0,0,89,0,0,0,88,88,87,87,88,88,88,87,87,0,0,0,89,0,0,26,0,91,0
0,91,0,0,26,0,89,0,0,0,0,0,0,87,87,87,0,0,0,0,0,0,89,0,26,0,0,91,0
0,91,0,0,0,26,89,0,0,0,0,0,0,87,87,87,0,0,0,0,0,0,89,26,0,0,0,91,0
0,91,0,0,0,0,89,0,0,0,0,0,0,87,87,87,0,0,0,0,0,0,89,0,0,0,0,91,0
0,91,0,0,0,91,89,89,89,89,89,89,89,89,89,89,89,89,89,89,89,89,89,91,0,0,0,91,0
0,91,91,91,91,91,91,91,91,91,91,91,91,91,91,91,91,91,91,91,91,91,91,91,91,91,91,91,0
0,0,0,0,0,0,0,0,0,0,0,0,0,0,0,0,0,0,0,0,0,0,0,0,0,0,0,0,0
endlayer

layer
0,0,0,0,0,0,0,0,0,0,0,0,0,0,0,0,0,0,0,0,0,0,0,0,0,0,0,0,0
0,0,0,0,0,0,0,0,0,0,0,0,0,0,0,0,0,0,0,0,0,0,0,0,0,0,0,0,0
0,0,0,0,0,0,0,0,0,0,0,0,0,0,0,0,0,0,0,0,0,0,0,0,0,0,0,0,0
0,0,0,0,0,0,0,0,0,0,0,0,0,0,0,0,0,0,0,0,0,0,0,0,0,0,0,0,0
0,0,0,0,0,0,0,0,0,0,0,0,0,0,0,0,0,0,0,0,0,0,0,0,0,0,0,0,0
0,0,0,0,0,92,0,0,0,0,0,0,0,0,0,0,0,0,0,0,0,0,0,92,0,0,0,0,0
0,0,0,0,0,0,0,0,0,0,0,0,0,0,0,0,0,0,0,0,0,0,0,0,0,0,0,0,0
0,0,0,0,0,0,0,0,0,0,0,0,0,0,0,0,0,0,0,0,0,0,0,0,0,0,0,0,0
0,0,0,0,0,0,0,0,0,0,0,87,87,0,0,0,87,87,0,0,0,0,0,0,0,0,0,0,0
0,0,0,0,0,0,0,0,0,0,87,0,0,0,0,0,0,0,87,0,0,0,0,0,0,0,0,0,0
0,0,0,0,0,0,0,0,0,87,0,0,0,0,0,0,0,0,0,87,0,0,0,0,0,0,0,0,0
0,0,0,0,0,0,0,0,87,0,0,0,0,0,0,0,0,0,0,0,87,0,0,0,0,0,0,0,0
0,0,0,0,0,0,0,87,0,0,0,0,0,0,0,0,0,0,0,0,0,87,0,0,0,0,0,0,0
0,0,0,0,0,0,0,87,0,0,0,0,17,17,17,17,17,0,0,0,0,87,0,0,0,0,0,0,0
0,0,0,0,0,0,0,87,0,0,0,0,18,26,26,26,16,0,0,0,0,87,0,0,0,0,0,0,0
0,0,0,0,0,0,0,87,0,0,0,0,18,26,26,26,16,0,0,0,0,87,0,0,0,0,0,0,0
0,0,0,0,0,0,0,87,0,0,0,0,18,20,20,20,20,0,0,0,0,87,0,0,0,0,0,0,0
0,0,0,0,0,0,0,87,0,0,0,0,0,0,0,0,0,0,0,0,0,87,0,0,0,0,0,0,0
0,0,0,0,0,0,0,87,0,0,0,0,0,0,0,0,0,0,0,0,0,87,0,0,0,0,0,0,0
0,0,0,0,0,0,0,0,87,0,0,0,0,0,0,0,0,0,0,0,87,0,0,0,0,0,0,0,0
0,0,0,0,0,0,0,0,0,87,0,0,0,0,0,0,0,0,0,87,0,0,0,0,0,0,0,0,0
0,0,0,0,0,0,0,0,0,0,87,0,0,0,0,0,0,0,87,0,0,0,0,0,0,0,0,0,0
0,0,0,0,0,0,0,0,0,0,0,87,0,0,0,0,0,87,0,0,0,0,0,0,0,0,0,0,0
0,0,0,0,0,0,0,0,0,0,0,87,0,0,0,0,0,87,0,0,0,0,0,0,0,0,0,0,0
0,0,0,0,0,0,0,0,0,0,0,87,0,0,0,0,0,87,0,0,0,0,0,0,0,0,0,0,0
0,0,0,0,0,0,0,0,0,0,0,87,0,0,0,0,0,87,0,0,0,0,0,0,0,0,0,0,0
0,0,0,0,0,0,0,0,0,0,87,0,0,0,0,0,0,0,87,0,0,0,0,0,0,0,0,0,0
0,0,0,0,0,0,0,0,0,0,87,0,0,0,0,0,0,0,87,0,0,0,0,0,0,0,0,0,0
0,0,0,0,0,0,0,0,0,0,87,0,0,0,0,0,0,0,87,0,0,0,0,0,0,0,0,0,0
0,0,0,0,0,0,0,0,0,0,87,0,0,0,0,0,0,0,87,0,0,0,0,0,0,0,0,0,0
0,0,0,0,0,0,0,0,0,0,87,0,0,0,0,0,0,0,87,0,0,0,0,0,0,0,0,0,0
0,0,0,0,0,0,0,0,0,0,87,0,0,0,0,0,0,0,87,0,0,0,0,0,0,0,0,0,0
0,0,0,0,0,0,0,92,0,87,0,0,0,0,0,0,0,0,0,87,0,92,0,0,0,0,0,0,0
0,0,0,0,0,0,0,0,87,0,0,0,0,0,0,0,0,0,0,0,87,0,0,0,0,0,0,0,0
0,0,0,0,0,0,0,87,0,0,0,0,0,0,0,0,0,0,0,0,0,87,0,0,0,0,0,0,0
0,0,0,0,0,0,87,0,0,0,0,0,0,0,0,0,0,0,0,0,0,0,87,0,0,0,0,0,0
0,0,0,0,0,87,0,0,0,0,0,0,0,0,0,0,0,0,0,0,0,0,0,87,0,0,0,0,0
0,0,0,0,87,0,0,0,0,0,0,0,0,0,0,0,0,0,0,0,0,0,0,0,87,0,0,0,0
0,0,0,87,0,0,0,0,0,0,48,47,0,0,0,0,0,46,48,0,0,0,0,0,0,87,0,0,0
0,0,0,87,0,0,0,0,0,48,0,0,0,0,0,0,0,0,0,48,0,0,0,0,0,87,0,0,0
0,0,0,87,0,0,0,0,48,0,0,0,0,0,0,0,0,0,0,0,48,0,0,0,0,87,0,0,0
0,0,0,87,0,0,12,12,0,0,0,0,0,0,0,0,0,0,0,0,0,12,12,0,0,87,0,0,0
0,0,0,87,0,0,12,0,0,0,88,88,88,88,88,88,88,87,87,0,0,0,12,0,0,87,0,0,0
0,0,0,0,87,0,12,0,0,0,0,0,87,87,87,87,87,0,0,0,0,0,12,0,87,0,0,0,0
0,0,0,0,0,87,12,0,0,0,0,0,87,87,87,87,87,0,0,0,0,0,12,87,0,0,0,0,0
0,0,0,0,0,0,12,0,0,0,0,0,87,87,87,87,87,0,0,0,0,0,12,0,0,0,0,0,0
0,0,0,0,0,91,12,12,12,12,12,12,12,12,12,12,12,12,12,12,12,12,12,91,0,0,0,0,0
0,0,0,0,0,91,91,91,91,91,91,91,91,91,91,91,91,91,91,91,91,91,91,91,0,0,0,0,0
0,0,0,0,0,0,0,0,0,0,0,0,0,0,0,0,0,0,0,0,0,0,0,0,0,0,0,0,0
endlayer

layer
0,0,0,0,0,0,0,0,0,0,0,0,0,0,0,0,0,0,0,0,0,0,0,0,0,0,0,0,0
0,0,0,0,0,0,0,0,0,0,0,0,0,0,0,0,0,0,0,0,0,0,0,0,0,0,0,0,0
0,0,0,0,0,0,0,0,0,0,0,0,0,0,0,0,0,0,0,0,0,0,0,0,0,0,0,0,0
0,0,0,0,0,0,0,0,0,0,0,0,0,0,0,0,0,0,0,0,0,0,0,0,0,0,0,0,0
0,0,0,0,0,0,0,0,0,0,0,0,0,0,0,0,0,0,0,0,0,0,0,0,0,0,0,0,0
0,0,0,0,0,92,0,0,0,0,0,0,0,0,0,0,0,0,0,0,0,0,0,92,0,0,0,0,0
0,0,0,0,0,0,0,0,0,0,0,0,0,0,0,0,0,0,0,0,0,0,0,0,0,0,0,0,0
0,0,0,0,0,0,0,0,0,0,0,0,0,0,0,0,0,0,0,0,0,0,0,0,0,0,0,0,0
0,0,0,0,0,0,0,0,0,0,0,0,0,0,0,0,0,0,0,0,0,0,0,0,0,0,0,0,0
0,0,0,0,0,0,0,0,0,0,0,0,0,0,0,0,0,0,0,0,0,0,0,0,0,0,0,0,0
0,0,0,0,0,0,0,0,0,0,0,0,0,0,0,0,0,0,0,0,0,0,0,0,0,0,0,0,0
0,0,0,0,0,0,0,0,0,0,0,0,0,0,0,0,0,0,0,0,0,0,0,0,0,0,0,0,0
0,0,0,0,0,0,0,0,0,0,0,0,0,0,0,0,0,0,0,0,0,0,0,0,0,0,0,0,0
0,0,0,0,0,0,0,0,0,0,0,0,0,0,0,0,0,0,0,0,0,0,0,0,0,0,0,0,0
0,0,0,0,0,0,0,0,0,0,0,0,0,0,48,0,0,0,0,0,0,0,0,0,0,0,0,0,0
0,0,0,0,0,0,0,0,0,0,0,0,0,0,48,0,0,0,0,0,0,0,0,0,0,0,0,0,0
0,0,0,0,0,0,0,0,0,0,0,0,0,0,0,0,0,0,0,0,0,0,0,0,0,0,0,0,0
0,0,0,0,0,0,0,0,0,0,0,0,0,0,0,0,0,0,0,0,0,0,0,0,0,0,0,0,0
0,0,0,0,0,0,0,0,0,0,0,0,0,0,0,0,0,0,0,0,0,0,0,0,0,0,0,0,0
0,0,0,0,0,0,0,0,0,0,0,0,0,0,0,0,0,0,0,0,0,0,0,0,0,0,0,0,0
0,0,0,0,0,0,0,0,0,0,0,0,0,0,0,0,0,0,0,0,0,0,0,0,0,0,0,0,0
0,0,0,0,0,0,0,0,0,0,0,0,0,0,0,0,0,0,0,0,0,0,0,0,0,0,0,0,0
0,0,0,0,0,0,0,0,0,0,0,0,0,0,0,0,0,0,0,0,0,0,0,0,0,0,0,0,0
0,0,0,0,0,0,0,0,0,0,0,0,0,0,0,0,0,0,0,0,0,0,0,0,0,0,0,0,0
0,0,0,0,0,0,0,0,0,0,0,0,0,0,0,0,0,0,0,0,0,0,0,0,0,0,0,0,0
0,0,0,0,0,0,0,0,0,0,0,0,0,0,0,0,0,0,0,0,0,0,0,0,0,0,0,0,0
0,0,0,0,0,0,0,0,0,0,0,0,0,0,0,0,0,0,0,0,0,0,0,0,0,0,0,0,0
0,0,0,0,0,0,0,0,0,0,0,0,0,0,0,0,0,0,0,0,0,0,0,0,0,0,0,0,0
0,0,0,0,0,0,0,0,0,0,0,0,0,0,0,0,0,0,0,0,0,0,0,0,0,0,0,0,0
0,0,0,0,0,0,0,0,0,0,0,0,0,0,0,0,0,0,0,0,0,0,0,0,0,0,0,0,0
0,0,0,0,0,0,94,94,94,0,0,0,0,0,0,0,0,0,0,0,0,0,0,0,0,0,0,0,0
0,0,0,0,0,94,94,94,94,94,0,0,0,0,0,0,0,0,0,0,0,94,0,0,0,0,0,0,0
0,0,0,0,0,94,94,92,94,94,0,0,0,0,0,0,0,0,0,0,94,92,94,0,0,0,0,0,0
0,0,0,0,0,94,94,94,94,94,0,0,0,0,0,0,0,0,0,0,0,94,0,0,0,0,0,0,0
0,0,0,0,0,0,94,94,94,0,0,0,0,0,0,0,0,0,0,0,0,0,0,0,0,0,0,0,0
0,0,0,0,0,0,0,0,0,0,0,0,0,0,0,0,0,0,0,0,0,0,0,0,0,0,0,0,0
0,0,0,0,0,0,0,0,0,0,0,0,0,0,0,0,0,0,0,0,0,0,0,0,0,0,0,0,0
0,0,0,0,0,0,0,0,0,0,0,0,0,0,0,0,0,0,0,0,0,0,0,0,0,0,0,0,0
0,0,0,0,0,0,0,0,0,0,15,15,75,0,0,0,76,15,15,0,0,0,0,0,0,0,0,0,0
0,0,0,0,0,0,0,0,0,12,0,0,0,0,0,0,0,0,0,12,0,0,0,0,0,0,0,0,0
0,0,0,0,0,0,0,0,15,0,0,0,0,0,0,0,0,0,0,0,15,0,0,0,0,0,0,0,0
0,0,0,0,0,0,15,15,0,0,0,0,0,0,49,0,0,0,0,0,0,15,15,0,0,0,0,0,0
0,0,0,0,0,0,15,0,0,0,0,0,0,49,5,49,0,0,0,0,0,0,15,0,0,0,0,0,0
0,0,0,0,0,0,15,0,0,0,0,0,0,0,49,0,0,0,0,0,0,0,15,0,0,0,0,0,0
0,0,0,0,0,0,15,0,0,0,0,0,0,0,0,0,0,0,0,0,0,0,15,0,0,0,0,0,0
0,0,0,0,0,0,15,0,0,0,0,0,0,0,0,0,0,0,0,0,0,0,15,0,0,0,0,0,0
0,0,0,0,0,0,15,15,15,15,15,15,15,15,15,15,15,15,15,15,15,15,15,0,0,0,0,0,0
0,0,0,0,0,0,0,0,0,0,0,0,0,0,0,0,0,0,0,0,0,0,0,0,0,0,0,0,0
0,0,0,0,0,0,0,0,0,0,0,0,0,0,0,0,0,0,0,0,0,0,0,0,0,0,0,0,0
endlayer

layer
0,0,0,0,0,0,0,0,0,0,0,0,0,0,0,0,0,0,0,0,0,0,0,0,0,0,0,0,0
0,0,0,0,0,0,0,0,0,0,0,0,0,0,0,0,0,0,0,0,0,0,0,0,0,0,0,0,0
0,0,94,94,94,94,94,94,94,0,0,0,0,0,0,0,0,0,0,0,94,94,94,94,94,0,0,0,0
0,0,94,94,94,94,94,94,94,0,0,0,0,0,0,0,0,0,0,0,94,94,94,94,94,94,0,0,0
0,0,94,94,94,94,94,94,94,0,0,0,0,0,0,0,0,0,0,0,94,94,94,94,94,94,94,0,0
0,0,94,94,94,92,94,94,94,0,0,0,0,0,0,0,0,0,0,0,94,94,94,92,94,94,94,0,0
0,0,94,94,94,94,94,94,94,0,0,0,0,0,0,0,0,0,0,0,94,94,94,94,94,94,94,0,0
0,0,94,94,94,94,94,94,94,0,0,0,0,0,0,0,0,0,0,0,0,94,94,94,94,94,94,0,0
0,0,0,94,94,94,94,94,0,0,0,0,0,0,0,0,0,0,0,0,0,0,94,94,94,94,0,0,0
0,0,0,0,0,0,0,0,0,0,0,0,0,0,0,0,0,0,0,0,0,0,0,0,0,0,0,0,0
0,0,0,0,0,0,0,0,0,0,0,0,0,0,0,0,0,0,0,0,0,0,0,0,0,0,0,0,0
0,0,0,0,0,0,0,0,0,0,0,0,0,0,0,0,0,0,0,0,0,0,0,0,0,0,0,0,0
0,0,0,0,0,0,0,0,0,0,0,0,0,0,0,0,0,0,0,0,0,0,0,0,0,0,0,0,0
0,0,0,0,0,0,0,0,0,0,0,0,0,0,0,0,0,0,0,0,0,0,0,0,0,0,0,0,0
0,0,0,0,0,0,0,0,0,0,0,0,0,48,0,48,0,0,0,0,0,0,0,0,0,0,0,0,0
0,0,0,0,0,0,0,0,0,0,0,0,0,48,0,48,0,0,0,0,0,0,0,0,0,0,0,0,0
0,0,0,0,0,0,0,0,0,0,0,0,0,0,0,0,0,0,0,0,0,0,0,0,0,0,0,0,0
0,0,0,0,0,0,0,0,0,0,0,0,0,0,0,0,0,0,0,0,0,0,0,0,0,0,0,0,0
0,0,0,0,0,0,0,0,0,0,0,0,0,0,0,0,0,0,0,0,0,0,0,0,0,0,0,0,0
0,0,0,0,0,0,0,0,0,0,0,0,0,0,0,0,0,0,0,0,0,0,0,0,0,0,0,0,0
0,0,0,0,0,0,0,0,0,0,0,0,0,0,0,0,0,0,0,0,0,0,0,0,0,0,0,0,0
0,0,0,0,0,0,0,0,0,0,0,0,0,0,0,0,0,0,0,0,0,0,0,0,0,0,0,0,0
0,0,0,0,0,0,0,0,0,0,0,0,0,0,0,0,0,0,0,0,0,0,0,0,0,0,0,0,0
0,0,0,0,0,0,0,0,0,0,0,0,0,0,0,0,0,0,0,0,0,0,0,0,0,0,0,0,0
0,0,0,0,0,0,0,0,0,0,0,0,0,0,0,0,0,0,0,0,0,0,0,0,0,0,0,0,0
0,0,0,0,0,0,0,0,0,0,0,0,0,0,0,0,0,0,0,0,0,0,0,0,0,0,0,0,0
0,0,0,0,0,0,0,0,0,0,0,0,0,0,0,0,0,0,0,0,0,0,0,0,0,0,0,0,0
0,0,0,0,0,0,0,0,0,0,0,0,0,0,0,0,0,0,0,0,0,0,0,0,0,0,0,0,0
0,0,0,0,0,0,0,0,0,0,0,0,0,0,0,0,0,0,0,0,0,0,0,0,0,0,0,0,0
0,0,0,0,0,0,0,0,0,0,0,0,0,0,0,0,0,0,0,0,0,0,0,0,0,0,0,0,0
0,0,0,0,0,0,94,94,94,94,0,0,0,0,0,0,0,0,0,0,94,94,94,0,0,0,0,0,0
0,0,0,0,0,0,94,94,94,94,94,0,0,0,0,0,0,0,0,94,94,94,94,94,0,0,0,0,0
0,0,0,0,0,94,94,92,94,0,0,0,0,0,0,0,0,0,0,94,94,92,94,94,0,0,0,0,0
0,0,0,0,0,94,94,94,94,94,0,0,0,0,0,0,0,0,0,94,94,94,94,94,0,0,0,0,0
0,0,0,0,0,0,94,94,94,0,0,0,0,0,0,0,0,0,0,0,94,94,94,0,0,0,0,0,0
0,0,0,0,0,0,0,0,0,0,0,0,0,0,0,0,0,0,0,0,0,0,0,0,0,0,0,0,0
0,0,0,0,0,0,0,0,0,0,0,0,0,0,0,0,0,0,0,0,0,0,0,0,0,0,0,0,0
0,0,0,0,0,0,0,0,0,97,96,96,96,96,96,96,96,96,96,95,0,0,0,0,0,0,0,0,0
0,0,0,0,0,0,0,0,96,96,12,15,15,15,12,15,15,15,12,95,95,0,0,0,0,0,0,0,0
0,0,0,0,0,0,0,96,97,12,100,99,99,99,12,99,99,99,98,12,95,96,0,0,0,0,0,0,0
0,0,0,0,0,96,96,97,12,100,100,101,101,101,12,101,101,101,99,98,12,95,96,96,0,0,0,0,0
0,0,0,0,0,97,12,12,100,99,101,101,101,101,12,101,101,101,101,99,98,12,12,95,0,0,0,0,0
0,0,0,0,0,97,12,99,100,101,101,101,101,101,12,101,101,101,101,101,98,99,12,95,0,0,0,0,0
0,0,0,0,0,97,12,100,101,101,101,101,101,101,12,101,101,101,101,101,101,98,12,95,0,0,0,0,0
0,0,0,0,0,97,12,100,101,101,101,101,101,101,12,101,101,101,101,101,101,98,12,95,0,0,0,0,0
0,0,0,0,0,97,12,102,102,102,102,102,102,102,12,102,102,102,102,102,102,98,12,95,0,0,0,0,0
0,0,0,0,0,97,12,12,12,12,12,12,12,12,12,12,12,12,12,12,12,12,12,95,0,0,0,0,0
0,0,0,0,0,97,103,103,103,103,103,103,103,103,103,103,103,103,103,103,103,103,103,103,0,0,0,0,0
0,0,0,0,0,0,0,0,0,0,0,0,0,0,0,0,0,0,0,0,0,0,0,0,0,0,0,0,0
endlayer

layer
0,0,0,0,0,0,0,0,0,0,0,0,0,0,0,0,0,0,0,0,0,0,0,0,0,0,0,0,0
0,0,0,0,0,0,0,0,0,0,0,0,0,0,0,0,0,0,0,0,0,0,0,0,0,0,0,0,0
0,0,94,94,94,94,94,94,94,0,0,0,0,0,0,0,0,0,0,0,94,94,94,94,94,0,88,0,0
0,0,94,94,94,94,94,94,94,0,0,0,0,0,0,0,0,0,0,0,94,94,94,94,94,94,0,0,0
0,0,94,94,94,94,94,94,94,0,0,0,0,0,0,0,0,0,0,0,94,94,94,94,94,94,94,0,0
0,0,94,94,94,92,94,94,94,0,0,0,0,0,0,0,0,0,0,0,94,94,94,92,94,94,94,0,0
0,0,94,94,94,94,94,94,94,0,0,0,0,0,0,0,0,0,0,0,94,94,94,94,94,94,94,0,0
0,0,94,94,94,94,94,94,94,0,0,0,0,0,0,0,0,0,0,0,0,94,94,94,94,94,94,0,0
0,0,94,94,94,94,94,94,0,0,0,0,0,0,0,0,0,0,0,0,0,0,94,94,94,94,94,0,0
0,0,0,0,0,0,0,0,0,0,0,0,0,0,0,0,0,0,0,0,0,0,0,0,0,0,0,0,0
0,0,0,0,0,0,0,0,0,0,0,0,0,0,0,0,0,0,0,0,0,0,0,0,0,0,0,0,0
0,0,0,0,0,0,0,0,0,0,0,0,0,0,0,0,0,0,0,0,0,0,0,0,0,0,0,0,0
0,0,0,0,0,0,0,0,0,0,0,0,0,0,0,0,0,0,0,0,0,0,0,0,0,0,0,0,0
0,0,0,0,0,0,0,0,0,0,0,0,0,0,0,0,0,0,0,0,0,0,0,0,0,0,0,0,0
0,0,0,0,0,0,0,0,0,0,0,0,48,0,0,30,75,0,0,0,0,0,0,0,0,0,0,0,0
0,0,0,0,0,0,0,0,0,0,0,0,48,0,0,30,75,0,0,0,0,0,0,0,0,0,0,0,0
0,0,0,0,0,0,0,0,0,0,0,0,0,0,0,0,0,0,0,0,0,0,0,0,0,0,0,0,0
0,0,0,0,0,0,0,0,0,0,0,0,0,0,0,0,0,0,0,0,0,0,0,0,0,0,0,0,0
0,0,0,0,0,0,0,0,0,0,0,0,0,0,0,0,0,0,0,0,0,0,0,0,0,0,0,0,0
0,0,0,0,0,0,0,0,0,0,0,0,0,0,0,0,0,0,0,0,0,0,0,0,0,0,0,0,0
0,0,0,0,0,0,0,0,0,0,0,0,0,0,0,0,0,0,0,0,0,0,0,0,0,0,0,0,0
0,0,0,0,0,0,0,0,0,0,0,0,0,0,0,0,0,0,0,0,0,0,0,0,0,0,0,0,0
0,0,0,0,0,0,0,0,0,0,0,0,0,0,0,0,0,0,0,0,0,0,0,0,0,0,0,0,0
0,0,0,0,0,0,0,0,0,0,0,0,0,0,0,0,0,0,0,0,0,0,0,0,0,0,0,0,0
0,0,0,0,0,0,0,0,0,0,0,0,0,0,0,0,0,0,0,0,0,0,0,0,0,0,0,0,0
0,0,0,0,0,0,0,0,0,0,0,0,0,0,0,0,0,0,0,0,0,0,0,0,0,0,0,0,0
0,0,0,0,0,0,0,0,0,0,0,0,0,0,0,0,0,0,0,0,0,0,0,0,0,0,0,0,0
0,0,0,0,0,0,0,0,0,0,0,0,0,0,0,0,0,0,0,0,0,0,0,0,0,0,0,0,0
0,0,0,0,0,0,0,0,0,0,0,0,0,0,0,0,0,0,0,0,0,0,0,0,0,0,0,0,0
0,0,0,0,0,0,0,0,0,0,0,0,0,0,0,0,0,0,0,0,0,0,0,0,0,0,0,0,0
0,0,0,0,0,0,94,94,94,0,0,0,0,0,0,0,0,0,0,0,0,0,0,0,0,0,0,0,0
0,0,0,0,0,94,94,94,94,94,0,0,0,0,0,0,0,0,0,0,0,94,0,0,0,0,0,0,0
0,0,0,0,0,0,94,92,94,94,0,0,0,0,0,0,0,0,0,0,94,92,94,0,0,0,0,0,0
0,0,0,0,0,94,94,94,94,94,0,0,0,0,0,0,0,0,0,0,0,94,0,0,0,0,0,0,0
0,0,0,0,0,94,94,94,94,0,0,0,0,0,0,0,0,0,0,0,0,0,0,0,0,0,0,0,0
0,0,0,0,0,0,94,94,0,0,0,0,0,0,0,0,0,0,0,0,0,0,0,0,0,0,0,0,0
0,0,0,0,0,0,0,0,0,0,0,0,0,0,0,0,0,0,0,0,0,0,0,0,0,0,0,0,0
0,0,0,0,0,0,0,0,0,0,87,104,87,104,87,104,87,104,87,0,0,0,0,0,0,0,0,0,0
0,0,0,0,0,0,0,0,0,87,87,104,87,105,88,105,87,104,88,88,0,0,0,0,0,0,0,0,0
0,0,0,0,0,0,0,0,87,87,104,87,105,88,106,88,105,87,104,87,87,0,0,0,0,0,0,0,0
0,0,0,0,0,87,105,87,87,104,87,105,88,106,88,106,88,105,87,104,87,87,105,87,0,0,0,0,0
0,0,0,0,0,105,105,87,104,87,105,88,106,88,106,88,106,88,105,87,104,87,105,105,0,0,0,0,0
0,0,0,0,0,87,87,104,87,104,88,106,88,106,107,106,88,106,88,104,87,104,87,87,0,0,0,0,0
0,0,0,0,0,104,104,87,104,87,105,88,106,88,106,88,106,88,105,87,104,87,104,104,0,0,0,0,0
0,0,0,0,0,87,87,104,87,104,87,105,88,106,88,106,88,105,87,104,87,104,87,87,0,0,0,0,0
0,0,0,0,0,104,104,87,104,87,104,88,105,88,106,88,105,87,104,87,104,87,104,104,0,0,0,0,0
0,0,0,0,0,88,88,105,88,105,87,104,87,105,88,105,87,104,87,104,87,104,88,88,0,0,0,0,0
0,0,0,0,0,104,88,104,87,104,87,104,87,104,87,104,87,104,87,104,87,104,88,104,0,0,0,0,0
0,0,0,0,0,0,0,0,0,0,0,0,0,0,0,0,0,0,0,0,0,0,0,0,0,0,0,0,0
endlayer

layer
0,0,0,0,0,0,0,0,0,0,0,0,0,0,0,0,0,0,0,0,0,0,0,0,0,0,0,0,0
0,0,0,0,0,0,0,0,0,0,0,0,0,0,0,0,0,0,0,0,0,0,0,0,0,0,0,0,0
0,0,0,0,0,0,0,0,0,0,0,0,0,0,0,0,0,0,0,0,0,0,0,0,0,0,0,0,0
0,0,0,94,94,94,94,0,0,0,0,0,0,0,0,0,0,0,0,0,0,94,94,94,94,0,0,0,0
0,0,0,94,94,94,94,94,0,0,0,0,0,0,0,0,0,0,0,0,0,94,94,94,94,94,0,0,0
0,0,0,94,94,92,94,94,0,0,0,0,0,0,0,0,0,0,0,0,0,94,94,92,94,94,0,0,0
0,0,0,94,94,94,94,94,0,0,0,0,0,0,0,0,0,0,0,0,0,0,94,94,94,94,0,0,0
0,0,0,94,94,94,94,0,0,0,0,0,0,0,0,0,0,0,0,0,0,0,94,94,94,94,0,0,0
0,0,0,0,0,0,0,0,0,0,0,0,0,0,0,0,0,0,0,0,0,0,0,0,0,0,0,0,0
0,0,0,0,0,0,0,0,0,0,0,0,0,0,0,0,0,0,0,0,0,0,0,0,0,0,0,0,0
0,0,0,0,0,0,0,0,0,0,0,0,0,0,0,0,0,0,0,0,0,0,0,0,0,0,0,0,0
0,0,0,0,0,0,0,0,0,0,0,0,0,0,0,0,0,0,0,0,0,0,0,0,0,0,0,0,0
0,0,0,0,0,0,0,0,0,0,0,0,0,0,0,0,0,0,0,0,0,0,0,0,0,0,0,0,0
0,0,0,0,0,0,0,0,0,0,0,0,0,0,0,0,0,0,0,0,0,0,0,0,0,0,0,0,0
0,0,0,0,0,0,0,0,0,0,0,0,30,75,0,0,0,0,0,0,0,0,0,0,0,0,0,0,0
0,0,0,0,0,0,0,0,0,0,0,0,30,75,0,0,0,0,0,0,0,0,0,0,0,0,0,0,0
0,0,0,0,0,0,0,0,0,0,0,0,0,0,0,0,0,0,0,0,0,0,0,0,0,0,0,0,0
0,0,0,0,0,0,0,0,0,0,0,0,0,0,0,0,0,0,0,0,0,0,0,0,0,0,0,0,0
0,0,0,0,0,0,0,0,0,0,0,0,0,0,0,0,0,0,0,0,0,0,0,0,0,0,0,0,0
0,0,0,0,0,0,0,0,0,0,0,0,0,0,0,0,0,0,0,0,0,0,0,0,0,0,0,0,0
0,0,0,0,0,0,0,0,0,0,0,0,0,0,0,0,0,0,0,0,0,0,0,0,0,0,0,0,0
0,0,0,0,0,0,0,0,0,0,0,0,0,0,0,0,0,0,0,0,0,0,0,0,0,0,0,0,0
0,0,0,0,0,0,0,0,0,0,0,0,0,0,0,0,0,0,0,0,0,0,0,0,0,0,0,0,0
0,0,0,0,0,0,0,0,0,0,0,0,0,0,0,0,0,0,0,0,0,0,0,0,0,0,0,0,0
0,0,0,0,0,0,0,0,0,0,0,0,0,0,0,0,0,0,0,0,0,0,0,0,0,0,0,0,0
0,0,0,0,0,0,0,0,0,0,0,0,0,0,0,0,0,0,0,0,0,0,0,0,0,0,0,0,0
0,0,0,0,0,0,0,0,0,0,0,0,0,0,0,0,0,0,0,0,0,0,0,0,0,0,0,0,0
0,0,0,0,0,0,0,0,0,0,0,0,0,0,0,0,0,0,0,0,0,0,0,0,0,0,0,0,0
0,0,0,0,0,0,0,0,0,0,0,0,0,0,0,0,0,0,0,0,0,0,0,0,0,0,0,0,0
0,0,0,0,0,0,0,0,0,0,0,0,0,0,0,0,0,0,0,0,0,0,0,0,0,0,0,0,0
0,0,0,0,0,0,0,94,0,0,0,0,0,0,0,0,0,0,0,0,94,94,94,0,0,0,0,0,0
0,0,0,0,0,0,0,94,0,0,0,0,0,0,0,0,0,0,0,94,94,94,94,94,0,0,0,0,0
0,0,0,0,0,0,94,92,94,0,0,0,0,0,0,0,0,0,0,94,94,92,94,94,0,0,0,0,0
0,0,0,0,0,0,0,94,0,0,0,0,0,0,0,0,0,0,0,94,94,94,94,94,0,0,0,0,0
0,0,0,0,0,0,0,0,0,0,0,0,0,0,0,0,0,0,0,0,94,94,94,0,0,0,0,0,0
0,0,0,0,0,0,0,0,0,0,0,0,0,0,0,0,0,0,0,0,0,0,0,0,0,0,0,0,0
0,0,0,0,0,0,0,0,0,0,0,0,0,0,0,0,0,0,0,0,0,0,0,0,0,0,0,0,0
0,0,0,0,0,0,0,0,0,0,0,0,0,0,0,0,0,0,0,0,0,0,0,0,0,0,0,0,0
0,0,0,0,0,0,0,0,0,0,0,0,0,0,0,0,0,0,0,0,0,0,0,0,0,0,0,0,0
0,0,0,0,0,0,0,0,0,0,0,0,0,0,0,0,0,0,0,0,0,0,0,0,0,0,0,0,0
0,0,0,0,0,0,0,0,0,0,0,0,0,0,0,0,0,0,0,0,0,0,0,0,0,0,0,0,0
0,0,0,0,0,0,0,0,0,0,0,0,0,0,0,0,0,0,0,0,0,0,0,0,0,0,0,0,0
0,0,0,0,0,0,0,0,0,0,0,0,0,0,0,0,0,0,0,0,0,0,0,0,0,0,0,0,0
0,0,0,0,0,0,0,0,0,0,0,0,0,0,0,0,0,0,0,0,0,0,0,0,0,0,0,0,0
0,0,0,0,0,0,0,0,0,0,0,0,0,0,0,0,0,0,0,0,0,0,0,0,0,0,0,0,0
0,0,0,0,0,0,0,0,0,0,0,0,0,0,0,0,0,0,0,0,0,0,0,0,0,0,0,0,0
0,0,0,0,0,0,0,0,0,0,0,0,0,0,0,0,0,0,0,0,0,0,0,0,0,0,0,0,0
0,0,0,0,0,0,0,0,0,0,0,0,0,0,0,0,0,0,0,0,0,0,0,0,0,0,0,0,0
0,0,0,0,0,0,0,0,0,0,0,0,0,0,0,0,0,0,0,0,0,0,0,0,0,0,0,0,0
endlayer

layer
0,0,0,0,0,0,0,0,0,0,0,0,0,0,0,0,0,0,0,0,0,0,0,0,0,0,0,0,0
0,0,0,0,0,0,0,0,0,0,0,0,0,0,0,0,0,0,0,0,0,0,0,0,0,0,0,0,0
0,0,0,0,0,0,0,0,0,0,0,0,0,0,0,0,0,0,0,0,0,0,0,0,0,0,0,0,0
0,0,0,0,94,94,94,0,0,0,0,0,0,0,0,0,0,0,0,0,0,0,94,94,94,0,0,0,0
0,0,0,94,94,94,94,94,0,0,0,0,0,0,0,0,0,0,0,0,0,94,94,94,94,94,0,0,0
0,0,0,94,94,94,94,94,0,0,0,0,0,0,0,0,0,0,0,0,0,94,94,94,94,94,0,0,0
0,0,0,94,94,94,94,94,0,0,0,0,0,0,0,0,0,0,0,0,0,94,94,94,94,94,0,0,0
0,0,0,0,94,94,94,0,0,0,0,0,0,0,0,0,0,0,0,0,0,0,94,94,94,0,0,0,0
0,0,0,0,0,0,0,0,0,0,0,0,0,0,0,0,0,0,0,0,0,0,0,0,0,0,0,0,0
0,0,0,0,0,0,0,0,0,0,0,0,0,0,0,0,0,0,0,0,0,0,0,0,0,0,0,0,0
0,0,0,0,0,0,0,0,0,0,0,0,0,0,0,0,0,0,0,0,0,0,0,0,0,0,0,0,0
0,0,0,0,0,0,0,0,0,0,0,0,0,0,0,0,0,0,0,0,0,0,0,0,0,0,0,0,0
0,0,0,0,0,0,0,0,0,0,0,0,0,0,0,0,0,0,0,0,0,0,0,0,0,0,0,0,0
0,0,0,0,0,0,0,0,0,0,0,0,0,0,0,0,0,0,0,0,0,0,0,0,0,0,0,0,0
0,0,0,0,0,0,0,0,0,0,0,0,0,48,0,0,0,0,0,0,0,0,0,0,0,0,0,0,0
0,0,0,0,0,0,0,0,0,0,0,0,0,48,0,0,0,0,0,0,0,0,0,0,0,0,0,0,0
0,0,0,0,0,0,0,0,0,0,0,0,0,0,0,0,0,0,0,0,0,0,0,0,0,0,0,0,0
0,0,0,0,0,0,0,0,0,0,0,0,0,0,0,0,0,0,0,0,0,0,0,0,0,0,0,0,0
0,0,0,0,0,0,0,0,0,0,0,0,0,0,0,0,0,0,0,0,0,0,0,0,0,0,0,0,0
0,0,0,0,0,0,0,0,0,0,0,0,0,0,0,0,0,0,0,0,0,0,0,0,0,0,0,0,0
0,0,0,0,0,0,0,0,0,0,0,0,0,0,0,0,0,0,0,0,0,0,0,0,0,0,0,0,0
0,0,0,0,0,0,0,0,0,0,0,0,0,0,0,0,0,0,0,0,0,0,0,0,0,0,0,0,0
0,0,0,0,0,0,0,0,0,0,0,0,0,0,0,0,0,0,0,0,0,0,0,0,0,0,0,0,0
0,0,0,0,0,0,0,0,0,0,0,0,0,0,0,0,0,0,0,0,0,0,0,0,0,0,0,0,0
0,0,0,0,0,0,0,0,0,0,0,0,0,0,0,0,0,0,0,0,0,0,0,0,0,0,0,0,0
0,0,0,0,0,0,0,0,0,0,0,0,0,0,0,0,0,0,0,0,0,0,0,0,0,0,0,0,0
0,0,0,0,0,0,0,0,0,0,0,0,0,0,0,0,0,0,0,0,0,0,0,0,0,0,0,0,0
0,0,0,0,0,0,0,0,0,0,0,0,0,0,0,0,0,0,0,0,0,0,0,0,0,0,0,0,0
0,0,0,0,0,0,0,0,0,0,0,0,0,0,0,0,0,0,0,0,0,0,0,0,0,0,0,0,0
0,0,0,0,0,0,0,0,0,0,0,0,0,0,0,0,0,0,0,0,0,0,0,0,0,0,0,0,0
0,0,0,0,0,0,94,94,94,0,0,0,0,0,0,0,0,0,0,0,0,0,0,0,0,0,0,0,0
0,0,0,0,0,94,94,94,94,94,0,0,0,0,0,0,0,0,0,0,0,94,0,0,0,0,0,0,0
0,0,0,0,0,0,94,92,94,94,0,0,0,0,0,0,0,0,0,0,94,92,94,0,0,0,0,0,0
0,0,0,0,0,0,94,94,94,94,0,0,0,0,0,0,0,0,0,0,0,94,0,0,0,0,0,0,0
0,0,0,0,0,0,94,94,94,0,0,0,0,0,0,0,0,0,0,0,0,0,0,0,0,0,0,0,0
0,0,0,0,0,0,0,0,0,0,0,0,0,0,0,0,0,0,0,0,0,0,0,0,0,0,0,0,0
0,0,0,0,0,0,0,0,0,0,0,0,0,0,0,0,0,0,0,0,0,0,0,0,0,0,0,0,0
0,0,0,0,0,0,0,0,0,0,0,0,0,0,0,0,0,0,0,0,0,0,0,0,0,0,0,0,0
0,0,0,0,0,0,0,0,0,0,0,0,0,0,0,0,0,0,0,0,0,0,0,0,0,0,0,0,0
0,0,0,0,0,0,0,0,0,0,0,0,0,0,0,0,0,0,0,0,0,0,0,0,0,0,0,0,0
0,0,0,0,0,0,0,0,0,0,0,0,0,0,0,0,0,0,0,0,0,0,0,0,0,0,0,0,0
0,0,0,0,0,0,0,0,0,0,0,0,0,0,0,0,0,0,0,0,0,0,0,0,0,0,0,0,0
0,0,0,0,0,0,0,0,0,0,0,0,0,0,0,0,0,0,0,0,0,0,0,0,0,0,0,0,0
0,0,0,0,0,0,0,0,0,0,0,0,0,0,0,0,0,0,0,0,0,0,0,0,0,0,0,0,0
0,0,0,0,0,0,0,0,0,0,0,0,0,0,0,0,0,0,0,0,0,0,0,0,0,0,0,0,0
0,0,0,0,0,0,0,0,0,0,0,0,0,0,0,0,0,0,0,0,0,0,0,0,0,0,0,0,0
0,0,0,0,0,0,0,0,0,0,0,0,0,0,0,0,0,0,0,0,0,0,0,0,0,0,0,0,0
0,0,0,0,0,0,0,0,0,0,0,0,0,0,0,0,0,0,0,0,0,0,0,0,0,0,0,0,0
0,0,0,0,0,0,0,0,0,0,0,0,0,0,0,0,0,0,0,0,0,0,0,0,0,0,0,0,0
endlayer

layer
0,0,0,0,0,0,0,0,0,0,0,0,0,0,0,0,0,0,0,0,0,0,0,0,0,0,0,0,0
0,0,0,0,0,0,0,0,0,0,0,0,0,0,0,0,0,0,0,0,0,0,0,0,0,0,0,0,0
0,0,0,0,0,0,0,0,0,0,0,0,0,0,0,0,0,0,0,0,0,0,0,0,0,0,0,0,0
0,0,0,0,0,0,0,0,0,0,0,0,0,0,0,0,0,0,0,0,0,0,0,0,0,0,0,0,0
0,0,0,0,0,0,0,0,0,0,0,0,0,0,0,0,0,0,0,0,0,0,0,0,0,0,0,0,0
0,0,0,0,0,0,0,0,0,0,0,0,0,0,0,0,0,0,0,0,0,0,0,0,0,0,0,0,0
0,0,0,0,0,0,0,0,0,0,0,0,0,0,0,0,0,0,0,0,0,0,0,0,0,0,0,0,0
0,0,0,0,0,0,0,0,0,0,0,0,0,0,0,0,0,0,0,0,0,0,0,0,0,0,0,0,0
0,0,0,0,0,0,0,0,0,0,0,0,0,0,0,0,0,0,0,0,0,0,0,0,0,0,0,0,0
0,0,0,0,0,0,0,0,0,0,0,0,0,0,0,0,0,0,0,0,0,0,0,0,0,0,0,0,0
0,0,0,0,0,0,0,0,0,0,0,0,0,0,0,0,0,0,0,0,0,0,0,0,0,0,0,0,0
0,0,0,0,0,0,0,0,0,0,0,0,0,0,0,0,0,0,0,0,0,0,0,0,0,0,0,0,0
0,0,0,0,0,0,0,0,0,0,0,0,0,0,0,0,0,0,0,0,0,0,0,0,0,0,0,0,0
0,0,0,0,0,0,0,0,0,0,0,0,0,0,0,0,0,0,0,0,0,0,0,0,0,0,0,0,0
0,0,0,0,0,0,0,0,0,0,0,30,0,48,0,0,0,0,0,0,0,0,0,0,0,0,0,0,0
0,0,0,0,0,0,0,0,0,0,0,30,0,48,0,0,0,0,0,0,0,0,0,0,0,0,0,0,0
0,0,0,0,0,0,0,0,0,0,0,0,0,0,0,0,0,0,0,0,0,0,0,0,0,0,0,0,0
0,0,0,0,0,0,0,0,0,0,0,0,0,0,0,0,0,0,0,0,0,0,0,0,0,0,0,0,0
0,0,0,0,0,0,0,0,0,0,0,0,0,0,0,0,0,0,0,0,0,0,0,0,0,0,0,0,0
0,0,0,0,0,0,0,0,0,0,0,0,0,0,0,0,0,0,0,0,0,0,0,0,0,0,0,0,0
0,0,0,0,0,0,0,0,0,0,0,0,0,0,0,0,0,0,0,0,0,0,0,0,0,0,0,0,0
0,0,0,0,0,0,0,0,0,0,0,0,0,0,0,0,0,0,0,0,0,0,0,0,0,0,0,0,0
0,0,0,0,0,0,0,0,0,0,0,0,0,0,0,0,0,0,0,0,0,0,0,0,0,0,0,0,0
0,0,0,0,0,0,0,0,0,0,0,0,0,0,0,0,0,0,0,0,0,0,0,0,0,0,0,0,0
0,0,0,0,0,0,0,0,0,0,0,0,0,0,0,0,0,0,0,0,0,0,0,0,0,0,0,0,0
0,0,0,0,0,0,0,0,0,0,0,0,0,0,0,0,0,0,0,0,0,0,0,0,0,0,0,0,0
0,0,0,0,0,0,0,0,0,0,0,0,0,0,0,0,0,0,0,0,0,0,0,0,0,0,0,0,0
0,0,0,0,0,0,0,0,0,0,0,0,0,0,0,0,0,0,0,0,0,0,0,0,0,0,0,0,0
0,0,0,0,0,0,0,0,0,0,0,0,0,0,0,0,0,0,0,0,0,0,0,0,0,0,0,0,0
0,0,0,0,0,0,0,0,0,0,0,0,0,0,0,0,0,0,0,0,0,0,0,0,0,0,0,0,0
0,0,0,0,0,0,0,0,0,0,0,0,0,0,0,0,0,0,0,0,94,94,94,0,0,0,0,0,0
0,0,0,0,0,0,0,94,0,0,0,0,0,0,0,0,0,0,0,94,94,94,94,94,0,0,0,0,0
0,0,0,0,0,0,94,92,94,0,0,0,0,0,0,0,0,0,0,94,94,92,94,94,0,0,0,0,0
0,0,0,0,0,0,0,94,0,0,0,0,0,0,0,0,0,0,0,94,94,94,94,94,0,0,0,0,0
0,0,0,0,0,0,0,0,0,0,0,0,0,0,0,0,0,0,0,0,94,94,94,0,0,0,0,0,0
0,0,0,0,0,0,0,0,0,0,0,0,0,0,0,0,0,0,0,0,0,0,0,0,0,0,0,0,0
0,0,0,0,0,0,0,0,0,0,0,0,0,0,0,0,0,0,0,0,0,0,0,0,0,0,0,0,0
0,0,0,0,0,0,0,0,0,0,0,0,0,0,0,0,0,0,0,0,0,0,0,0,0,0,0,0,0
0,0,0,0,0,0,0,0,0,0,0,0,0,0,0,0,0,0,0,0,0,0,0,0,0,0,0,0,0
0,0,0,0,0,0,0,0,0,0,0,0,0,0,0,0,0,0,0,0,0,0,0,0,0,0,0,0,0
0,0,0,0,0,0,0,0,0,0,0,0,0,0,0,0,0,0,0,0,0,0,0,0,0,0,0,0,0
0,0,0,0,0,0,0,0,0,0,0,0,0,0,0,0,0,0,0,0,0,0,0,0,0,0,0,0,0
0,0,0,0,0,0,0,0,0,0,0,0,0,0,0,0,0,0,0,0,0,0,0,0,0,0,0,0,0
0,0,0,0,0,0,0,0,0,0,0,0,0,0,0,0,0,0,0,0,0,0,0,0,0,0,0,0,0
0,0,0,0,0,0,0,0,0,0,0,0,0,0,0,0,0,0,0,0,0,0,0,0,0,0,0,0,0
0,0,0,0,0,0,0,0,0,0,0,0,0,0,0,0,0,0,0,0,0,0,0,0,0,0,0,0,0
0,0,0,0,0,0,0,0,0,0,0,0,0,0,0,0,0,0,0,0,0,0,0,0,0,0,0,0,0
0,0,0,0,0,0,0,0,0,0,0,0,0,0,0,0,0,0,0,0,0,0,0,0,0,0,0,0,0
0,0,0,0,0,0,0,0,0,0,0,0,0,0,0,0,0,0,0,0,0,0,0,0,0,0,0,0,0
endlayer

layer
0,0,0,0,0,0,0,0,0,0,0,0,0,0,0,0,0,0,0,0,0,0,0,0,0,0,0,0,0
