
# Created by Ruins mod version 14.9 Ingame Parser
# authoring Player: SunsOfOld

weight=100
embed_into_distance=1
acceptable_target_blocks=
unacceptable_target_blocks=flowing_water,water,flowing_lava,lava
dimensions=8,11,11
allowable_overhang=0
max_leveling=4
leveling_buffer=0
preserve_water=0
preserve_lava=0
uniqueMinDistance=1000000
preventRotation=1

rule1=0,100,chisel:sandstone-8
rule2=0,100,minecraft:sand-0
rule3=0,100,chisel:glowstone-4
rule4=0,100,BiomesOPlenty:plants-3
rule5=0,100,dendrology:leaves1-4
rule6=0,100,plantmegapack:desertBrittlebush-0
rule7=0,100,chisel:sandstone-7
rule8=0,100,dendrology:leaves1-12
rule9=0,100,chisel:sandstone-11
rule10=0,100,dendrology:ewcaly_planks-5
rule11=0,100,minecraft:sandstone_stairs-2
rule12=0,100,chisel:stained_glass_lightgray-7
rule13=0,100,minecraft:sandstone_stairs-3
rule14=0,100,chisel:sandstone-4
rule15=0,100,chisel:sandstone-10
rule16=0,100,IInventory;minecraft:chest;harvestcraft:datenutbreadItem#8#0#3+chisel:chisel#{chiselTarget:{},}#0#5+UndergroundBiomes:fossilPiece#1#6#7+BiomesOPlenty:gems#1#7#9+VeganOption:juteBundled#4#0#11+antiqueatlas:emptyAntiqueAtlas#1#0#13+dendrology:sapling0#1#4#15+VeganOption:rosin#1#0#17+BiomesOPlenty:jarEmpty#1#0#19+CarpentersBlocks:itemCarpentersHammer#1#0#21+harvestcraft:lambkebabItem#8#0#23-4
rule17=0,100,harvestcraft:pamcandleDeco2-5
rule18=0,100,chisel:sandstone-9
rule19=0,100,chisel:sandstone-13
rule20=0,100,chisel:sandstone-5
rule21=0,100,chisel:sandstone-3
rule22=0,100,dendrology:sslab0-4

layer
1,1,1,1,1,1,1,1,1,1,1
1,1,1,1,1,1,1,1,1,1,1
1,1,1,1,1,1,1,1,1,1,1
1,1,1,1,1,1,1,1,1,1,1
1,1,1,1,1,1,1,1,1,1,1
1,1,1,1,1,1,1,1,1,1,1
1,1,1,1,1,1,1,1,1,1,1
1,1,1,1,1,1,1,1,1,1,1
1,1,1,1,1,1,1,1,1,1,1
1,1,1,1,1,1,1,1,1,1,1
1,1,1,1,1,1,1,1,1,1,1
endlayer

layer
2,2,2,2,2,2,2,2,2,2,2
2,2,2,2,2,2,2,2,2,2,2
2,2,2,2,2,2,2,2,2,2,2
2,2,2,2,2,2,2,2,2,2,2
2,2,2,1,1,1,1,1,2,2,2
2,2,1,3,3,3,3,3,1,2,2
2,2,2,1,1,1,1,1,2,2,2
2,2,2,2,2,2,2,2,2,2,2
2,2,2,2,2,2,2,2,2,2,2
2,2,2,2,2,2,2,2,2,2,2
2,2,2,2,2,2,2,2,2,2,2
endlayer

layer
6,0,4,0,2,2,5,4,0,0,0
7,2,5,2,2,2,2,8,2,2,7
5,2,9,9,9,9,9,9,9,2,5
5,9,10,10,10,10,10,10,10,9,2
6,9,10,10,10,10,10,10,10,9,4
13,1,10,12,12,12,12,12,10,1,11
0,9,10,10,10,10,10,10,10,9,0
4,9,10,10,10,10,10,10,10,9,2
2,2,9,9,9,9,9,9,9,2,2
7,8,8,2,2,2,2,8,2,2,7
4,5,0,0,4,2,0,0,4,6,0
endlayer

layer
0,0,0,0,0,0,0,0,0,0,0
14,0,0,5,2,2,5,5,8,6,14
5,2,1,1,1,1,1,1,1,2,5
0,1,15,0,9,0,9,0,15,1,6
0,1,0,0,0,0,0,0,0,1,0
0,0,0,0,0,0,0,0,0,0,0
0,1,0,0,0,0,0,0,0,1,0
0,1,15,0,9,16,9,0,15,1,4
6,2,1,1,1,1,1,1,1,2,5
14,5,0,4,2,8,0,0,0,8,14
0,0,0,0,0,0,0,0,0,0,0
endlayer

layer
0,0,0,0,0,0,0,0,0,0,0
14,0,0,0,0,5,5,0,0,0,14
0,5,1,1,1,1,1,1,1,4,0
0,1,17,0,15,0,15,0,17,1,0
0,1,0,0,0,0,0,0,0,1,0
0,0,0,0,0,0,0,0,0,0,0
0,1,0,0,0,0,0,0,0,1,0
0,1,17,0,15,0,15,0,17,1,0
0,5,1,1,1,1,1,1,1,8,0
14,0,0,0,6,0,0,0,0,0,14
0,0,0,0,0,0,0,0,0,0,0
endlayer

layer
0,0,0,0,0,0,0,0,0,0,0
14,0,0,0,0,0,0,0,0,0,14
0,0,1,1,1,1,1,1,1,0,0
0,1,0,0,18,0,18,0,0,1,0
0,1,0,0,0,0,0,0,0,1,0
0,0,0,0,0,0,0,0,0,0,0
0,1,0,0,0,0,0,0,0,1,0
0,1,0,0,18,0,18,0,0,1,0
0,0,1,1,1,1,1,1,1,0,0
14,0,0,0,0,0,0,0,0,0,14
0,0,0,0,0,0,0,0,0,0,0
endlayer

layer
0,0,0,0,0,0,0,0,0,0,0
14,0,0,0,0,0,0,0,0,0,14
0,0,18,18,18,18,18,18,18,0,0
0,18,19,19,19,19,19,19,19,18,0
0,18,19,19,19,19,19,19,19,18,0
0,18,19,12,12,12,12,12,19,18,0
0,18,19,19,19,19,19,19,19,18,0
0,18,19,19,19,19,19,19,19,18,0
0,0,18,18,18,18,18,18,18,0,0
14,0,0,0,0,0,0,0,0,0,14
0,0,0,0,0,0,0,0,0,0,0
endlayer

layer
0,0,0,0,0,0,0,0,0,0,0
20,0,0,0,0,0,0,0,0,0,20
0,0,21,21,21,21,21,21,21,0,0
0,21,21,22,22,22,22,22,21,21,0
0,21,22,22,22,22,22,22,22,21,0
0,21,22,0,0,0,0,0,22,21,0
0,21,22,22,22,22,22,22,22,21,0
0,21,21,22,22,22,22,22,21,21,0
0,0,21,21,21,21,21,21,21,0,0
20,0,0,0,0,0,0,0,0,0,20
0,0,0,0,0,0,0,0,0,0,0
endlayer

