
# Created by Ruins mod version 14.9 Ingame Parser
# authoring Player: SunsOfOld

weight=100
embed_into_distance=2
acceptable_target_blocks=
unacceptable_target_blocks=flowing_water,water,flowing_lava,lava
dimensions=7,10,9
allowable_overhang=0
max_leveling=3
leveling_buffer=0
preserve_water=0
preserve_lava=0
uniqueMinDistance=1000000
preventRotation=1

rule1=0,100,preserveBlock
rule2=0,100,BiomesOPlenty:newBopDirt-2
rule3=0,100,minecraft:sand-0
rule4=0,100,BiomesOPlenty:newBopDirt-0
rule5=0,100,BiomesOPlenty:newBopDirt-1
rule6=0,100,BiomesOPlenty:newBopDirt-3
rule7=0,100,ExtrabiomesXL:grass-0
rule8=0,100,dendrology:hekur_planks-11
rule9=0,100,BiomesOPlenty:plants-3
rule10=0,100,plantmegapack:grassSeaOats-0
rule11=0,100,dendrology:hekur_planks-10
rule12=0,100,IInventory;minecraft:chest;harvestcraft:troutrawItem#5#0#2+harvestcraft:grouperrawItem#3#0#6+harvestcraft:fishtrapbaitItem#4#0#8+harvestcraft:fishtrap#1#0#10+BiomesOPlenty:flippers#1#0#13+harvestcraft:fishtrap#1#0#16+harvestcraft:fishtrapbaitItem#3#0#18+harvestcraft:charrrawItem#4#0#20+harvestcraft:bassrawItem#6#0#24-5
rule13=0,100,ExtrabiomesXL:stairs.cypress-4
rule14=0,100,ExtrabiomesXL:stairs.cypress-7
rule15=0,100,ExtrabiomesXL:stairs.cypress-6
rule16=0,100,ExtrabiomesXL:woodslab-3
rule17=0,100,plantmegapack:flowerMediterraneanSeaHolly-0
rule18=0,100,ExtrabiomesXL:stairs.cypress-5
rule19=0,100,ExtrabiomesXL:stairs.cypress-0
rule20=0,100,plantmegapack:leafyDustyMiller-0
rule21=0,100,plantmegapack:grassPrairie-0
rule22=0,100,GardenStuff:lattice-0
rule23=0,100,ExtrabiomesXL:woodslab-11
rule24=0,100,GardenStuff:lantern-8

layer
1,1,1,1,1,1,1,1,1
1,1,1,1,1,1,1,1,1
1,1,1,1,1,1,1,1,1
1,1,1,1,1,1,1,1,1
1,1,1,1,1,1,1,1,1
1,1,1,1,1,1,1,1,1
1,1,1,1,1,1,1,1,1
1,1,1,1,1,1,1,1,1
1,1,1,1,1,1,1,1,1
1,1,1,1,1,1,1,1,1
endlayer

layer
1,1,2,3,1,1,1,1,2
1,6,1,5,4,4,1,1,1
1,3,6,4,4,4,1,3,1
1,1,1,4,4,4,1,2,1
2,1,1,4,4,4,2,1,2
1,1,1,5,4,5,1,3,1
1,2,1,1,5,1,2,1,1
1,1,3,2,1,3,1,1,2
1,2,1,1,1,1,1,2,1
3,1,1,1,1,1,1,1,3
endlayer

layer
0,0,10,9,0,6,0,8,7
0,0,0,14,13,13,11,12,11
0,9,17,14,16,15,2,8,0
0,0,2,14,16,15,3,10,0
7,3,1,14,16,15,7,0,10
0,1,2,18,19,18,0,9,0
0,10,1,0,18,0,10,0,0
0,0,9,7,0,20,0,0,7
0,21,0,0,0,0,0,21,0
9,0,0,0,0,0,0,0,9
endlayer

layer
0,0,0,0,0,7,0,0,0
0,0,0,22,22,22,0,8,0
0,0,0,22,0,22,10,0,0
0,0,10,22,0,22,9,0,0
0,9,0,0,0,0,0,0,0
0,0,7,0,0,0,0,0,0
0,0,0,16,0,16,0,0,0
0,0,0,0,16,0,0,0,0
0,0,0,0,23,0,0,0,0
0,0,0,0,0,0,0,0,0
endlayer

layer
0,0,0,0,0,0,0,0,0
0,0,0,0,22,0,0,0,0
0,0,0,0,0,0,0,0,0
0,0,0,0,0,0,0,0,0
0,0,0,0,0,0,0,0,0
0,0,0,0,0,0,0,0,0
0,0,0,0,0,0,0,0,0
0,0,0,0,0,0,0,0,0
0,0,0,0,22,0,0,0,0
0,0,0,0,0,0,0,0,0
endlayer

layer
0,0,0,0,0,0,0,0,0
0,0,0,0,0,0,0,0,0
0,0,0,0,0,0,0,0,0
0,0,0,0,0,0,0,0,0
0,0,0,0,0,0,0,0,0
0,0,0,0,0,0,0,0,0
0,0,0,0,0,0,0,0,0
0,0,0,0,0,0,0,0,0
0,0,0,0,22,0,0,0,0
0,0,0,0,24,0,0,0,0
endlayer

layer
0,0,0,0,0,0,0,0,0
0,0,0,0,0,0,0,0,0
0,0,0,0,0,0,0,0,0
0,0,0,0,0,0,0,0,0
0,0,0,0,0,0,0,0,0
0,0,0,0,0,0,0,0,0
0,0,0,0,0,0,0,0,0
0,0,0,0,0,0,0,0,0
0,0,0,0,22,0,0,0,0
0,0,0,0,22,0,0,0,0
endlayer

