
# Created by Ruins mod version 15.0 Ingame Parser
# authoring Player: SunsOfOld

weight=100
embed_into_distance=4
acceptable_target_blocks=
unacceptable_target_blocks=flowing_water,water,flowing_lava,lava
dimensions=6,13,13
allowable_overhang=0
max_leveling=4
leveling_buffer=0
preserve_water=0
preserve_lava=0
uniqueMinDistance=1000000
preventRotation=1

rule1=0,100,preserveBlock
rule2=0,100,UndergroundBiomes:sedimentaryStone-14
rule3=0,100,BiomesOPlenty:newBopDirt-0
rule4=0,100,minecraft:dirt-0
rule5=0,100,minecraft:water-0
rule6=0,100,minecraft:water-8
rule7=0,100,minecraft:grass-0
rule8=0,100,MobSpawner:TropicalFish
rule9=0,100,BiomesOPlenty:foliage-11
rule10=0,100,minecraft:tallgrass-1
rule11=0,100,plantmegapack:groundcoverClover-0
rule12=0,100,minecraft:double_plant-2
rule13=0,100,ExtrabiomesXL:leaves_2-14
rule14=0,100,UndergroundBiomes:sedimentaryStoneHalfSlab-6
rule15=0,100,ExtrabiomesXL:flower3-0
rule16=0,100,ExtrabiomesXL:leaves_2-6
rule17=0,100,plantmegapack:wetlandsCattails-0
rule18=0,100,plantmegapack:cropSacredLotus-3
rule19=0,100,BiomesOPlenty:lilyBop-2
rule20=0,100,plantmegapack:cropSacredLotus-0
rule21=0,100,BiomesOPlenty:lilyBop-0
rule22=0,100,BiomesOPlenty:lilyBop-1
rule23=0,100,plantmegapack:cropSacredLotus-4
rule24=0,100,UndergroundBiomes:sedimentaryStoneFullSlab-6
rule25=0,100,ExtrabiomesXL:flower2-3
rule26=0,100,minecraft:double_plant-10
rule27=0,100,minecraft:double_plant-9
rule28=0,100,minecraft:double_plant-8
rule29=0,100,minecraft:double_plant-11

layer
1,1,1,1,1,1,1,1,1,1,1,1,1
1,1,1,1,1,1,1,1,1,1,1,1,1
1,1,1,1,1,1,1,1,1,1,1,1,1
1,1,1,1,1,1,1,1,1,1,1,1,1
1,1,1,1,1,3,2,1,1,1,1,1,1
1,1,1,1,1,3,4,2,2,1,1,1,1
1,1,1,1,2,4,2,4,2,1,1,1,1
1,1,1,1,1,2,2,2,2,1,1,1,1
1,1,1,1,1,1,2,2,1,1,1,1,1
1,1,1,1,1,1,1,1,1,1,1,1,1
1,1,1,1,1,1,1,1,1,1,1,1,1
1,1,1,1,1,1,1,1,1,1,1,1,1
1,1,1,1,1,1,1,1,1,1,1,1,1
endlayer

layer
1,1,1,1,1,1,1,1,1,1,1,1,1
1,1,1,1,1,1,1,1,1,1,1,1,1
1,1,1,1,1,1,1,1,1,1,1,1,1
1,1,1,1,1,2,2,1,1,1,1,1,1
1,1,1,1,2,5,5,2,1,1,1,1,1
1,1,1,1,2,5,5,5,2,1,1,1,1
1,1,1,2,6,5,5,5,6,2,1,1,1
1,1,1,1,2,5,5,5,6,4,1,1,1
1,1,1,1,1,2,6,6,2,1,1,1,1
1,1,1,1,1,3,2,2,1,1,1,1,1
1,1,1,1,1,1,1,1,1,1,1,1,1
1,1,1,1,1,1,1,1,1,1,1,1,1
1,1,1,1,1,1,1,1,1,1,1,1,1
endlayer

layer
1,1,1,1,1,1,1,1,1,1,1,1,1
1,1,1,1,1,1,1,1,1,1,1,1,1
1,1,1,1,1,1,2,1,1,1,1,1,1
1,1,1,1,1,2,5,3,1,1,1,1,1
1,1,1,2,2,5,5,5,3,2,1,1,1
1,1,2,2,5,5,5,5,5,3,1,1,1
1,1,1,3,5,5,5,5,5,2,2,1,1
1,1,1,3,5,5,5,5,5,5,2,1,1
1,1,1,1,2,5,5,5,5,2,1,1,1
1,1,1,1,4,5,5,2,2,2,1,1,1
1,1,1,1,1,3,3,1,1,1,1,1,1
1,1,1,1,1,1,1,1,1,1,1,1,1
1,1,1,1,1,1,1,1,1,1,1,1,1
endlayer

layer
1,7,1,1,1,1,1,1,1,1,7,1,7
1,7,7,1,3,3,1,1,3,1,1,7,7
7,1,1,1,2,2,2,2,3,3,1,7,7
1,1,3,2,2,5,5,5,2,1,3,1,7
7,1,1,2,5,5,5,5,5,2,1,1,1
7,1,2,5,5,5,5,5,5,5,2,3,1
1,1,2,5,5,5,5,5,5,5,5,3,1
1,3,2,5,5,5,5,5,5,5,2,1,1
1,3,1,2,5,5,5,5,5,2,2,3,1
1,1,3,2,5,5,5,5,2,8,2,1,1
7,1,1,3,2,5,5,2,2,3,1,7,7
7,1,3,3,1,2,2,3,1,1,1,7,7
7,1,1,1,1,7,1,1,1,7,7,7,1
endlayer

layer
0,10,0,0,0,0,0,0,0,0,9,0,9
0,12,15,0,13,13,14,0,13,0,13,12,11
9,0,13,14,14,0,0,0,17,13,16,13,12
0,13,16,2,0,0,0,18,0,14,13,14,9
12,13,14,14,0,0,19,0,0,0,14,13,0
9,0,0,0,21,0,0,0,0,20,0,17,0
0,0,0,23,0,22,0,22,0,0,0,13,0
0,17,0,0,21,0,0,0,21,0,0,14,0
0,13,14,0,0,0,19,0,0,14,24,16,13
0,14,13,0,20,0,0,0,0,2,14,13,0
9,0,14,13,0,18,0,0,14,13,13,25,9
12,0,13,13,14,0,0,13,13,0,0,12,10
9,0,0,13,0,15,0,0,0,9,12,10,0
endlayer

layer
0,0,0,0,0,0,0,0,0,0,0,0,0
0,27,0,0,0,0,0,0,0,0,0,26,0
0,0,0,0,0,0,0,0,0,0,13,0,26
0,0,13,14,0,0,0,0,0,0,0,0,0
28,0,0,0,0,0,0,0,0,0,0,0,0
0,0,0,0,0,0,0,0,0,0,0,0,0
0,0,0,0,0,0,0,0,0,0,0,0,0
0,0,0,0,0,0,0,0,0,0,0,0,0
0,0,0,0,0,0,0,0,0,0,0,13,0
0,0,0,0,0,0,0,0,0,14,0,0,0
0,0,0,0,0,0,0,0,0,0,0,0,0
29,0,0,13,0,0,0,0,0,0,0,26,0
0,0,0,0,0,0,0,0,0,0,29,0,0
endlayer

