
# Created by Ruins mod version 15.0 Ingame Parser
# authoring Player: SunsOfOld

weight=100
embed_into_distance=1
acceptable_target_blocks=
unacceptable_target_blocks=flowing_water,water,flowing_lava,lava
dimensions=6,14,14
allowable_overhang=0
max_leveling=2
leveling_buffer=0
preserve_water=0
preserve_lava=0
uniqueMinDistance=1000000
preventRotation=1

rule1=0,100,BiomesOPlenty:newBopGrass-0
rule2=0,100,preserveBlock
rule3=0,100,chisel:factoryblock-11
rule4=0,100,chisel:tyrian-3
rule5=0,100,chisel:tyrian-2
rule6=0,100,chisel:fantasyblock-14
rule7=0,100,chisel:factoryblock-5
rule8=0,100,BiomesOPlenty:newBopDirt-0
rule9=0,100,BiomesOPlenty:foliage-11
rule10=0,100,BiomesOPlenty:leaves2-5
rule11=0,100,plantmegapack:forestAustralianBugle-0
rule12=0,100,minecraft:double_plant-2
rule13=0,100,plantmegapack:plainsSmallPasqueFlower-0
rule14=0,100,plantmegapack:flowerStreamsideBluebells-0
rule15=0,100,BiomesOPlenty:leaves2-13
rule16=0,100,GardenTrees:thin_log-1
rule17=0,100,chisel:bookshelf-8
rule18=0,100,BiblioCraft:BiblioSeats-1
rule19=0,100,IInventory;harvestcraft:churn;harvestcraft:saltItem#9#0#1+harvestcraft:butterItem#3#0#2-3
rule20=0,100,IInventory;harvestcraft:oven;harvestcraft:oliveoilItem#2#0#1-5
rule21=0,100,IInventory;minecraft:furnace;minecraft:coal#3#1#1+minecraft:iron_ingot#{display:{Lore:[0:"Refined",],},}#0#2-5
rule22=0,100,EasyCrafting:table-0
rule23=0,100,plantmegapack:groundcoverFlowers-0
rule24=0,100,chisel:bookshelf-7
rule25=0,100,chisel:carpet-0
rule26=0,100,ExtrabiomesXL:door_baldcypress-5
rule27=0,100,minecraft:enchanting_table-0
rule28=0,100,ExtrabiomesXL:door_baldcypress-1
rule29=0,100,IInventory;minecraft:chest;minecraft:paper#1#0#1+VeganOption:burlap#4#0#2+minecraft:paper#2#0#5+minecraft:book#2#0#7+VeganOption:burlap#3#0#8+VeganOption:burlap#2#0#9+minecraft:writable_book#1#0#12+BiblioCraft:item.BiblioGlasses#1#0#14+minecraft:book#1#0#17+minecraft:book#2#0#18+minecraft:paper#2#0#20+minecraft:paper#2#0#25-3
rule30=0,100,harvestcraft:sink-0
rule31=0,100,IInventory;harvestcraft:quern;minecraft:wooden_pressure_plate#4#0#1-4
rule32=0,100,minecraft:anvil-10
rule33=0,100,IInventory;GardenStuff:bloomery_furnace;minecraft:coal#1#1#2-4
rule34=0,100,BiomesOPlenty:flowers-3
rule35=0,100,IInventory;BiblioCraft:BiblioTable;BiblioCraft:BiblioCase#1#1#0-1
rule36=0,100,minecraft:water-0
rule37=0,100,chisel:factoryblock-9
rule38=0,100,VeganOption:bedStraw-10
rule39=0,100,VeganOption:bedStraw-2
rule40=0,100,BiomesOPlenty:flowerVine-8
rule41=0,100,minecraft:double_plant-9
rule42=0,100,chisel:glass_pane-14
rule43=0,100,BiomesOPlenty:flowerVine-1
rule44=0,100,harvestcraft:pamcandleDeco2-5
rule45=0,100,harvestcraft:cuttingboard-0
rule46=0,100,ExtrabiomesXL:door_baldcypress-9
rule47=0,100,minecraft:double_plant-10
rule48=0,100,ExtrabiomesXL:door_baldcypress-8
rule49=0,100,minecraft:double_plant-8
rule50=0,100,minecraft:double_plant-11
rule51=0,100,BiomesOPlenty:flowerVine-2
rule52=0,100,BiomesOPlenty:woodenSingleSlab2-4
rule53=0,100,BiomesOPlenty:woodenSingleSlab2-12
rule54=0,100,BiomesOPlenty:woodenDoubleSlab2-4
rule55=0,100,chisel:glass-3

layer
2,1,1,1,1,1,1,1,1,1,1,1,1,1
2,2,2,2,2,2,2,2,2,2,2,2,2,1
1,2,4,4,4,4,2,3,3,3,3,3,2,1
6,5,4,4,4,4,5,3,3,3,3,3,2,1
6,5,4,4,4,4,5,3,3,3,3,3,2,1
1,2,4,4,4,4,2,3,3,3,3,3,2,1
6,2,2,2,2,2,2,3,3,3,3,3,2,1
1,6,1,6,1,1,2,2,2,5,5,2,2,1
6,6,6,1,6,6,1,2,4,4,4,4,2,1
1,6,2,2,6,6,6,5,4,4,4,4,2,1
2,8,7,7,2,6,6,5,4,4,4,4,2,2
1,2,7,7,2,6,1,2,4,4,4,4,2,1
1,6,2,2,6,1,1,2,2,2,2,2,2,1
2,1,1,1,1,2,1,1,2,1,1,1,1,2
endlayer

layer
0,9,12,9,13,10,14,10,13,12,11,9,10,9
15,5,5,5,5,5,5,5,5,5,5,5,5,10
23,5,22,21,20,19,5,16,18,17,17,16,5,10
0,26,0,25,25,0,0,0,0,0,0,24,5,14
0,28,0,25,25,0,0,0,0,27,0,17,5,12
9,5,33,32,31,30,5,0,0,0,0,29,5,10
0,5,5,5,5,5,5,16,0,0,0,16,5,10
9,0,14,0,10,15,5,5,5,0,0,5,5,34
0,0,0,9,0,0,13,5,0,0,0,35,5,10
12,16,4,4,16,0,0,28,0,25,25,18,5,12
0,4,36,36,4,0,0,28,0,25,25,0,5,0
9,4,36,36,4,0,9,5,37,39,38,37,5,15
13,16,4,4,16,12,9,5,5,5,5,5,5,15
0,12,9,13,9,0,9,12,10,15,10,12,10,0
endlayer

layer
0,40,41,40,0,0,10,40,0,41,0,40,40,0
0,16,6,42,42,6,16,6,42,42,42,6,16,10
0,6,45,44,0,0,6,16,0,0,17,16,6,43
0,46,0,0,0,0,0,0,0,0,0,24,42,0
0,48,0,0,0,0,0,0,0,0,0,44,42,47
0,6,0,0,0,0,6,0,0,0,0,0,42,0
0,16,6,42,42,6,6,16,0,0,0,16,6,10
0,0,0,0,0,15,16,6,6,0,0,6,16,0
0,0,0,0,0,0,0,6,0,0,0,0,6,0
49,16,0,0,16,0,0,46,0,0,0,0,42,47
0,0,0,0,0,0,0,48,0,0,0,0,42,0
0,0,0,0,0,0,0,6,0,0,0,44,6,10
0,16,0,0,16,50,0,16,6,42,42,6,16,0
0,49,0,0,0,0,0,50,51,15,0,49,0,0
endlayer

layer
0,40,40,40,0,0,40,40,0,0,0,40,40,0
0,6,6,6,6,6,16,6,42,42,42,6,16,43
52,6,0,0,0,0,6,16,0,0,0,16,6,43
53,6,0,0,0,0,0,0,0,0,0,0,42,0
53,6,0,0,0,0,0,0,0,0,0,0,42,0
52,6,0,0,0,0,6,0,0,0,0,0,42,0
0,6,6,6,6,6,6,16,0,0,0,16,6,0
0,0,0,0,0,10,16,6,6,0,0,6,16,0
0,0,0,0,0,0,52,6,0,0,0,0,6,0
0,16,0,0,16,0,53,6,0,0,0,0,6,0
0,0,0,0,0,0,53,6,0,0,0,0,6,0
0,0,0,0,0,0,52,6,0,0,0,0,6,43
0,16,0,0,16,0,0,6,6,6,6,6,6,0
0,0,0,0,0,0,0,0,51,0,0,0,0,0
endlayer

layer
0,0,0,0,0,0,40,40,0,0,0,40,40,0
0,0,52,52,52,52,6,6,6,6,6,6,6,43
0,52,54,54,54,54,6,16,0,0,0,16,6,43
0,52,54,55,55,54,6,0,0,0,0,0,6,0
0,52,54,55,55,54,6,0,0,0,0,0,6,0
0,52,54,54,54,54,6,0,0,0,0,0,6,0
0,0,52,52,52,52,6,16,0,0,0,16,6,0
0,0,0,0,0,0,6,6,6,6,6,6,6,0
0,0,0,0,0,0,0,52,54,54,54,54,52,0
0,54,53,53,54,0,0,52,54,55,55,54,52,0
0,53,0,0,53,0,0,52,54,55,55,54,52,0
0,53,0,0,53,0,0,52,54,54,54,54,52,0
0,54,53,53,54,0,0,0,52,52,52,52,0,0
0,0,0,0,0,0,0,0,0,0,0,0,0,0
endlayer

layer
0,0,0,0,0,0,0,0,0,0,0,0,0,0
0,0,0,0,0,0,0,52,52,52,52,52,0,0
0,0,0,0,0,0,52,54,54,54,54,54,52,0
0,0,0,0,0,0,52,54,55,55,55,54,52,0
0,0,0,0,0,0,52,54,55,55,55,54,52,0
0,0,0,0,0,0,52,54,55,55,55,54,52,0
0,0,0,0,0,0,52,54,54,54,54,54,52,0
0,0,0,0,0,0,0,52,52,52,52,52,0,0
0,0,0,0,0,0,0,0,0,0,0,0,0,0
0,0,52,52,0,0,0,0,0,0,0,0,0,0
0,52,15,15,52,0,0,0,0,0,0,0,0,0
0,52,15,15,52,0,0,0,0,0,0,0,0,0
0,0,52,52,0,0,0,0,0,0,0,0,0,0
0,0,0,0,0,0,0,0,0,0,0,0,0,0
endlayer

