
# Created by Ruins mod version 15.0 Ingame Parser
# authoring Player: SunsOfOld

weight=100
embed_into_distance=5
acceptable_target_blocks=
unacceptable_target_blocks=flowing_water,water,flowing_lava,lava
dimensions=9,9,7
allowable_overhang=0
max_leveling=2
leveling_buffer=0
preserve_water=0
preserve_lava=0
uniqueMinDistance=1000000
preventRotation=1

rule1=0,100,preserveBlock
rule2=0,100,chisel:factoryblock-1
rule3=0,100,chisel:factoryblock-5
rule4=0,100,chisel:tyrian-2
rule5=0,100,BiblioCraft:BiblioStuffs-2
rule6=0,100,chisel:carpet-0
rule7=0,100,minecraft:redstone_wire-0
rule8=0,100,plantmegapack:wallBracketIronCurl-3
rule9=0,100,plantmegapack:wallBracketIronCurl-2
rule10=0,100,CarpentersBlocks:blockCarpentersLadder-3
rule11=0,100,GardenStuff:heavy_chain-4
rule12=0,100,BiomesOPlenty:newBopGrass-0
rule13=0,100,chisel:factoryblock-11
rule14=0,100,chisel:fantasyblock-14
rule15=0,100,BiomesOPlenty:foliage-11
rule16=0,100,minecraft:double_plant-2
rule17=0,100,BiomesOPlenty:leaves2-13
rule18=0,100,BiomesOPlenty:leaves2-5
rule19=0,100,chisel:tyrian-3
rule20=0,100,plantmegapack:plainsSmallPasqueFlower-0
rule21=0,100,ExtrabiomesXL:door_baldcypress-3
rule22=0,100,VeganOption:bedStraw-0
rule23=0,100,VeganOption:bedStraw-8
rule24=0,100,BiomesOPlenty:flowers-3
rule25=0,100,minecraft:double_plant-10
rule26=0,100,minecraft:double_plant-9
rule27=0,100,BiomesOPlenty:flowerVine-8
rule28=0,100,GardenTrees:thin_log-1
rule29=0,100,chisel:glass_pane-14
rule30=0,100,BiomesOPlenty:flowerVine-4
rule31=0,100,minecraft:double_plant-8
rule32=0,100,ExtrabiomesXL:door_baldcypress-8
rule33=0,100,minecraft:double_plant-11
rule34=0,100,BiomesOPlenty:woodenSingleSlab2-4
rule35=0,100,BiomesOPlenty:woodenSingleSlab2-12
rule36=0,100,chisel:glass-3

layer
1,1,1,1,1,1,1
1,1,1,1,1,1,1
1,1,2,2,2,1,1
1,1,2,3,2,1,1
1,1,2,3,2,1,1
1,1,2,3,2,1,1
1,1,2,2,2,1,1
1,1,1,1,1,1,1
1,1,1,1,1,1,1
endlayer

layer
1,1,1,1,1,1,1
1,4,4,4,4,4,1
1,4,7,6,5,4,1
1,4,0,6,7,4,1
1,4,0,0,0,4,1
1,4,0,0,0,4,1
1,4,0,0,0,4,1
1,4,4,4,4,4,1
1,1,1,1,1,1,1
endlayer

layer
1,1,1,1,1,1,1
1,4,4,4,4,4,1
1,4,9,0,8,4,1
1,4,0,0,0,4,1
1,4,0,0,0,4,1
1,4,0,0,0,4,1
1,4,0,0,10,4,1
1,4,4,4,4,4,1
1,1,1,1,1,1,1
endlayer

layer
1,1,1,1,1,1,1
1,4,4,4,4,4,1
1,4,11,0,11,4,1
1,4,0,0,0,4,1
1,4,0,0,0,4,1
1,4,0,0,0,4,1
1,4,0,0,10,4,1
1,4,4,4,4,4,1
1,1,1,1,1,1,1
endlayer

layer
1,12,1,12,12,12,12
12,4,4,4,4,4,12
12,4,4,13,4,4,1
12,4,13,13,13,4,12
1,4,13,13,13,4,14
12,4,13,13,13,4,12
12,4,4,13,0,4,12
1,4,4,4,4,4,12
12,12,12,1,12,12,12
endlayer

layer
0,18,17,16,17,16,15
18,19,19,19,19,19,18
16,19,17,13,17,19,18
18,19,0,0,0,19,20
17,19,23,22,0,21,0
24,19,0,0,0,19,18
15,19,17,13,18,19,16
17,19,19,19,19,19,18
20,18,16,18,16,18,15
endlayer

layer
0,27,17,26,0,25,0
30,28,14,29,14,28,0
31,14,0,0,0,14,18
0,29,0,0,0,14,0
0,29,0,0,0,32,0
0,29,0,0,0,14,0
17,14,0,0,0,14,25
0,28,14,29,14,28,0
0,0,33,0,33,0,0
endlayer

layer
0,27,27,0,0,0,0
30,14,14,14,14,14,0
30,14,0,0,0,14,0
28,14,28,28,28,14,28
0,14,0,0,0,14,0
28,14,28,28,28,14,28
0,14,0,0,0,14,0
0,14,14,14,14,14,0
0,0,0,0,0,0,0
endlayer

layer
0,0,0,0,0,0,0
0,0,34,34,34,0,0
0,34,35,35,35,34,0
0,34,35,36,35,34,0
0,34,35,36,35,34,0
0,34,35,36,35,34,0
0,34,35,35,35,34,0
0,0,34,34,34,0,0
0,0,0,0,0,0,0
endlayer

