
# Created by Ruins mod version 15.0 Ingame Parser
# authoring Player: SunsOfOld

weight=100
embed_into_distance=0
acceptable_target_blocks=
unacceptable_target_blocks=flowing_water,water,flowing_lava,lava
dimensions=23,20,24
allowable_overhang=0
max_leveling=5
leveling_buffer=0
preserve_water=0
preserve_lava=0
uniqueMinDistance=1000000
preventRotation=1

rule1=0,100,chisel:marble_pillar-10
rule2=0,100,chisel:concrete-1
rule3=0,100,minecraft:planks-2
rule4=0,100,chisel:marble_stairs.2-2
rule5=0,100,minecraft:stained_hardened_clay-13
rule6=0,100,chisel:marble_stairs.0-0
rule7=0,100,chisel:marble_stairs.0-2
rule8=0,100,minecraft:wooden_slab-9
rule9=0,100,minecraft:bookshelf-0
rule10=0,100,IInventory;BiblioCraft:BiblioSeats;BiblioCraft:item.seatBack2#1#1#1-1
rule11=0,100,BiblioWoodsBoP:BiblioWoodtable-7
rule12=0,100,BiblioCraft:BiblioDesk-0
rule13=0,100,IInventory;BiblioWoodsBoP:BiblioWoodtable;BiblioCraft:item.BigBook#{author:"BradReligion1975",}#0#0-7
rule14=0,100,BiblioCraft:BiblioTable-1
rule15=0,100,minecraft:trapdoor-9
rule16=0,100,minecraft:spruce_stairs-5
rule17=0,100,chisel:marble_stairs.0-3
rule18=0,100,minecraft:stained_glass-15
rule19=0,100,minecraft:wooden_door-1
rule20=0,100,minecraft:stone-0
rule21=0,100,chisel:marble_stairs.0-1
rule22=0,100,minecraft:wooden_door-9
rule23=0,100,minecraft:wooden_door-8
rule24=0,100,chisel:marble_stairs.2-4
rule25=0,100,BiblioCraft:BiblioIronLantern-1
rule26=0,100,chisel:marble_stairs.2-5
rule27=0,100,chisel:marble_stairs.2-1
rule28=0,100,chisel:marble_stairs.2-0
rule29=0,100,chisel:marble_stairs.0-4
rule30=0,100,chisel:marble_stairs.0-6
rule31=0,100,chisel:marble_stairs.0-7
rule32=0,100,chisel:marble_stairs.0-5
rule33=0,100,GardenStuff:fence-0
rule34=0,100,chisel:marble-0
rule35=0,100,chisel:marble_slab_top-0
rule36=0,100,chisel:marble_slab-0

layer
0,0,0,0,0,0,0,0,0,0,0,0,0,0,0,0,0,0,0,0,0,0,0,0
0,1,0,0,0,0,0,0,0,0,0,0,0,0,0,0,0,0,0,0,0,1,0,0
0,0,2,2,2,2,2,2,2,2,2,2,2,2,2,2,2,2,2,2,2,0,0,0
0,0,2,3,3,3,3,3,3,3,3,3,3,3,3,3,3,3,3,3,2,0,0,0
0,0,2,3,3,3,3,3,3,3,3,3,3,3,3,3,3,3,3,3,2,0,0,0
0,0,2,3,3,3,3,3,3,3,3,3,3,3,3,3,3,3,3,3,2,0,0,0
0,0,2,3,3,3,3,3,3,3,3,3,3,3,3,3,3,3,3,3,2,1,0,0
0,0,2,3,3,3,3,3,3,3,3,3,3,3,3,3,3,3,3,3,2,0,0,0
0,0,2,3,3,3,3,3,3,3,3,3,3,3,3,3,3,3,3,3,2,2,0,0
0,0,2,3,3,3,3,3,3,3,3,3,3,3,3,3,3,3,3,3,2,4,0,0
0,0,2,3,3,3,3,3,3,3,3,3,3,3,3,3,3,3,3,3,2,4,0,0
0,0,2,3,3,3,3,3,3,3,3,3,3,3,3,3,3,3,3,3,2,2,0,0
0,0,2,3,3,3,3,3,3,3,3,3,3,3,3,3,3,3,3,3,2,0,0,0
0,0,2,3,3,3,3,3,3,3,3,3,3,3,3,3,3,3,3,3,2,1,0,0
0,0,2,3,3,3,3,3,3,3,3,3,3,3,3,3,3,3,3,3,2,0,0,0
0,0,2,3,3,3,3,3,3,3,3,3,3,3,3,3,3,3,3,3,2,0,0,0
0,0,2,3,3,3,3,3,3,3,3,3,3,3,3,3,3,3,3,3,2,0,0,0
0,0,2,2,2,2,2,2,2,2,2,2,2,2,2,2,2,2,2,2,2,0,0,0
0,1,0,0,0,0,0,0,0,0,0,0,0,0,0,0,0,0,0,0,0,1,0,0
0,0,0,0,0,0,0,0,0,0,0,0,0,0,0,0,0,0,0,0,0,0,0,0
endlayer

layer
0,0,0,0,0,0,0,0,0,0,0,0,0,0,0,0,0,0,0,0,0,0,0,0
0,1,0,0,0,0,0,0,0,0,0,0,0,0,0,0,0,0,0,0,0,1,0,0
0,0,5,5,5,6,6,6,5,5,6,6,6,5,5,6,6,6,5,5,5,0,0,0
0,0,5,9,9,12,12,12,9,9,10,11,10,9,9,8,0,0,0,0,7,0,0,0
0,0,5,14,0,0,0,0,0,0,10,13,10,0,0,8,0,0,0,0,7,0,0,0
0,0,17,14,0,0,0,0,0,0,0,0,0,0,0,16,8,8,16,15,5,0,0,0
0,0,17,14,0,0,0,0,0,0,0,0,0,0,0,0,0,0,0,0,5,1,0,0
0,0,5,14,0,0,0,0,0,0,0,0,0,0,0,0,0,0,0,0,5,0,0,0
0,0,5,9,0,0,0,0,0,2,2,2,2,0,0,0,0,0,0,0,18,0,0,0
0,0,5,9,0,0,0,0,0,20,20,20,4,0,0,0,0,0,0,0,19,0,0,0
0,0,5,9,0,0,0,0,0,20,20,20,4,0,0,0,0,0,0,0,19,0,0,0
0,0,5,9,0,0,0,0,0,2,2,2,2,0,0,0,0,0,0,0,18,0,0,0
0,0,5,14,0,0,0,0,0,0,0,0,0,0,0,0,0,0,0,0,5,0,0,0
0,0,17,14,0,0,0,0,0,0,0,0,0,0,0,0,0,0,0,0,5,1,0,0
0,0,17,14,0,0,0,0,0,0,0,0,0,0,0,0,0,0,0,0,5,0,0,0
0,0,5,14,0,0,0,0,0,0,0,11,0,0,0,0,0,0,0,0,7,0,0,0
0,0,5,9,9,0,0,0,9,9,0,11,0,9,9,0,0,0,0,0,7,0,0,0
0,0,5,5,5,21,21,21,5,5,21,21,21,5,5,21,21,21,5,5,5,0,0,0
0,1,0,0,0,0,0,0,0,0,0,0,0,0,0,0,0,0,0,0,0,1,0,0
0,0,0,0,0,0,0,0,0,0,0,0,0,0,0,0,0,0,0,0,0,0,0,0
endlayer

layer
0,0,0,0,0,0,0,0,0,0,0,0,0,0,0,0,0,0,0,0,0,0,0,0
0,1,0,0,0,0,0,0,0,0,0,0,0,0,0,0,0,0,0,0,0,1,0,0
0,0,5,5,5,18,18,0,5,5,18,18,0,5,5,18,18,18,5,5,5,0,0,0
0,0,5,9,9,0,0,0,9,9,0,0,0,9,9,0,0,0,0,0,18,0,0,0
0,0,5,0,0,0,0,0,0,0,0,0,0,0,0,0,0,0,0,0,18,0,0,0
0,0,0,0,0,0,0,0,0,0,0,0,0,0,0,0,0,0,0,0,5,0,0,0
0,0,18,0,0,0,0,0,0,0,0,0,0,0,0,0,0,0,0,0,5,1,0,0
0,0,5,0,0,0,0,0,0,0,0,0,0,0,0,0,0,0,0,0,5,0,0,0
0,0,5,9,0,0,0,0,0,2,2,2,0,0,0,0,0,0,0,0,18,0,0,0
0,0,5,9,0,0,0,0,0,20,20,4,0,0,0,0,0,0,0,0,22,0,0,0
0,0,5,9,0,0,0,0,0,20,20,4,0,0,0,0,0,0,0,0,23,0,0,0
0,0,5,9,0,0,0,0,0,2,2,2,0,0,0,0,0,0,0,0,18,0,0,0
0,0,5,0,0,0,0,0,0,0,0,0,0,0,0,0,0,0,0,0,5,0,0,0
0,0,18,0,0,0,0,0,0,0,0,0,0,0,0,0,0,0,0,0,5,1,0,0
0,0,18,0,0,0,0,0,0,0,0,0,0,0,0,0,0,0,0,0,5,0,0,0
0,0,5,0,0,0,0,0,0,0,0,0,0,0,0,0,0,0,0,0,18,0,0,0
0,0,5,9,9,0,0,0,9,9,0,0,0,9,9,0,0,0,0,0,18,0,0,0
0,0,5,5,5,18,18,18,5,5,18,0,18,5,5,18,18,18,5,5,5,0,0,0
0,1,0,0,0,0,0,0,0,0,0,0,0,0,0,0,0,0,0,0,0,1,0,0
0,0,0,0,0,0,0,0,0,0,0,0,0,0,0,0,0,0,0,0,0,0,0,0
endlayer

layer
0,0,0,0,0,0,0,0,0,0,0,0,0,0,0,0,0,0,0,0,0,0,0,0
0,1,0,0,0,0,0,0,0,0,0,0,0,0,0,0,0,0,0,0,0,1,0,0
0,0,5,5,5,18,18,0,5,5,18,0,0,5,5,18,0,18,5,5,5,0,0,0
0,0,5,9,9,0,0,0,9,9,0,0,0,9,9,0,0,0,0,0,18,0,0,0
0,0,5,0,0,0,0,0,0,0,0,0,0,0,0,0,0,0,0,0,0,0,0,0
0,0,0,0,0,0,0,0,0,0,0,0,0,0,0,0,0,0,0,0,5,0,0,0
0,0,18,0,0,0,0,0,0,0,0,0,0,0,0,0,0,0,0,0,5,1,0,0
0,0,5,0,0,0,0,0,0,0,0,0,0,0,0,0,0,0,0,0,5,0,0,0
0,0,5,9,0,0,0,0,0,2,2,0,0,0,0,0,0,0,0,0,18,0,0,0
0,0,5,9,0,0,0,0,0,20,4,0,0,0,0,0,0,0,0,0,5,0,0,0
0,0,5,9,0,0,0,0,0,20,4,0,0,0,0,0,0,0,0,0,5,0,0,0
0,0,5,9,0,0,0,0,0,2,2,0,0,0,0,0,0,0,0,0,18,0,0,0
0,0,5,0,0,0,0,0,0,0,0,0,0,0,0,0,0,0,0,0,5,0,0,0
0,0,18,0,0,0,0,0,0,0,0,0,0,0,0,0,0,0,0,0,5,1,0,0
0,0,0,0,0,0,0,0,0,0,0,0,0,0,0,0,0,0,0,0,5,0,0,0
0,0,5,0,0,0,0,0,0,0,0,0,0,0,0,0,0,0,0,0,18,0,0,0
0,0,5,9,9,0,0,0,9,9,0,0,0,9,9,0,0,0,0,0,0,0,0,0
0,0,5,5,5,18,0,18,5,5,0,18,18,5,5,0,18,18,5,5,5,0,0,0
0,1,0,0,0,0,0,0,0,0,0,0,0,0,0,0,0,0,0,0,0,1,0,0
0,0,0,0,0,0,0,0,0,0,0,0,0,0,0,0,0,0,0,0,0,0,0,0
endlayer

layer
0,0,0,0,0,0,0,0,0,0,0,0,0,0,0,0,0,0,0,0,0,0,0,0
0,1,0,0,0,0,0,0,0,0,0,0,0,0,0,0,0,0,0,0,0,1,0,0
0,0,5,5,5,18,0,0,5,5,18,18,18,5,5,18,0,0,5,5,5,0,0,0
0,0,5,9,9,0,0,0,9,9,0,0,0,9,9,0,0,0,0,0,18,0,0,0
0,0,5,0,0,0,0,0,0,0,0,0,0,0,0,0,0,0,0,0,18,0,0,0
0,0,18,0,0,0,0,0,0,0,0,0,0,0,0,0,0,0,0,0,5,0,0,0
0,0,18,0,0,0,0,0,0,0,0,0,0,0,0,0,0,0,0,0,5,1,0,0
0,0,5,0,0,0,0,0,0,0,0,0,0,0,0,0,0,0,0,0,5,0,0,0
0,0,5,9,0,0,0,24,24,2,0,0,0,0,0,0,0,0,0,0,18,0,0,0
0,0,5,9,0,0,0,3,3,4,0,0,0,0,0,0,0,0,0,0,5,25,0,0
0,0,5,9,0,0,0,3,3,4,0,0,0,0,0,0,0,0,0,0,5,25,0,0
0,0,5,9,0,0,0,26,26,2,0,0,0,0,0,0,0,0,0,0,0,0,0,0
0,0,5,0,0,0,0,0,0,0,0,0,0,0,0,0,0,0,0,0,5,0,0,0
0,0,18,0,0,0,0,0,0,0,0,0,0,0,0,0,0,0,0,0,5,1,0,0
0,0,18,0,0,0,0,0,0,0,0,0,0,0,0,0,0,0,0,0,5,0,0,0
0,0,5,0,0,0,0,0,0,0,0,0,0,0,0,0,0,0,0,0,18,0,0,0
0,0,5,9,9,0,0,0,9,9,0,0,0,9,9,0,0,0,0,0,0,0,0,0
0,0,5,5,5,0,18,18,5,5,18,0,18,5,5,0,0,18,5,5,5,0,0,0
0,1,0,0,0,0,0,0,0,0,0,0,0,0,0,0,0,0,0,0,0,1,0,0
0,0,0,0,0,0,0,0,0,0,0,0,0,0,0,0,0,0,0,0,0,0,0,0
endlayer

layer
0,0,0,0,0,0,0,0,0,0,0,0,0,0,0,0,0,0,0,0,0,0,0,0
0,1,0,0,0,0,0,0,0,0,0,0,0,0,0,0,0,0,0,0,0,1,0,0
0,0,5,5,5,18,0,18,5,5,18,18,18,5,5,18,0,18,5,5,5,0,0,0
0,0,5,9,9,0,0,0,9,9,0,0,0,9,9,0,0,0,0,0,18,0,0,0
0,0,5,0,0,0,0,0,0,0,0,0,0,0,0,0,0,0,0,0,18,0,0,0
0,0,18,0,0,0,0,0,0,0,0,0,0,0,0,0,0,0,0,0,5,0,0,0
0,0,18,0,0,0,0,0,0,0,0,0,0,0,0,0,0,0,0,0,5,1,0,0
0,0,5,0,0,0,0,24,24,0,0,0,0,0,0,0,0,0,0,0,5,0,0,0
0,0,5,9,0,0,3,27,27,2,0,0,0,0,0,0,0,0,0,0,18,0,0,0
0,0,5,9,0,0,3,0,0,0,0,0,0,0,0,0,0,0,0,0,5,0,0,0
0,0,5,9,0,0,3,0,0,0,0,0,0,0,0,0,0,0,0,0,5,0,0,0
0,0,5,9,0,0,3,28,28,2,0,0,0,0,0,0,0,0,0,0,18,0,0,0
0,0,5,0,0,0,0,26,26,0,0,0,0,0,0,0,0,0,0,0,5,0,0,0
0,0,0,0,0,0,0,0,0,0,0,0,0,0,0,0,0,0,0,0,5,1,0,0
0,0,18,0,0,0,0,0,0,0,0,0,0,0,0,0,0,0,0,0,5,0,0,0
0,0,5,0,0,0,0,0,0,0,0,0,0,0,0,0,0,0,0,0,18,0,0,0
0,0,5,9,9,0,0,0,9,9,0,0,0,9,9,0,0,0,0,0,18,0,0,0
0,0,5,5,5,18,18,18,5,5,18,0,18,5,5,0,0,18,5,5,5,0,0,0
0,1,0,0,0,0,0,0,0,0,0,0,0,0,0,0,0,0,0,0,0,1,0,0
0,0,0,0,0,0,0,0,0,0,0,0,0,0,0,0,0,0,0,0,0,0,0,0
endlayer

layer
0,0,0,0,0,0,0,0,0,0,0,0,0,0,0,0,0,0,0,0,0,0,0,0
0,1,0,0,0,0,0,0,0,0,0,0,0,0,0,0,0,0,0,0,0,1,0,0
0,0,5,5,5,29,29,29,5,5,29,29,29,5,5,29,29,29,5,5,5,0,0,0
0,0,5,3,3,3,3,3,3,3,3,3,3,3,3,3,3,3,3,3,30,0,0,0
0,0,5,3,3,3,3,3,3,3,3,3,3,3,3,3,3,3,3,3,30,0,0,0
0,0,31,3,3,3,3,3,3,3,3,3,3,3,3,3,3,3,3,3,5,0,0,0
0,0,31,3,3,3,3,3,3,3,3,3,3,3,3,3,3,3,3,3,5,1,0,0
0,0,5,3,3,3,3,27,27,2,0,0,0,0,0,0,0,0,0,0,5,0,0,0
0,0,5,3,3,3,3,0,0,0,0,0,0,0,0,0,0,0,0,0,5,0,0,0
0,0,5,3,3,3,3,0,0,0,0,0,0,0,0,0,0,0,0,0,5,0,0,0
0,0,5,3,3,3,3,0,0,0,0,0,0,0,0,0,0,0,0,0,5,0,0,0
0,0,5,3,3,3,3,0,0,0,0,0,0,0,0,0,0,0,0,0,5,0,0,0
0,0,5,3,3,3,3,28,28,2,0,0,0,0,0,0,0,0,0,0,5,0,0,0
0,0,31,3,3,3,3,3,3,3,3,3,3,3,3,3,3,3,3,3,5,1,0,0
0,0,31,3,3,3,3,3,3,3,3,3,3,3,3,3,3,3,3,3,5,0,0,0
0,0,5,3,3,3,3,3,3,3,3,3,3,3,3,3,3,3,3,3,30,0,0,0
0,0,5,3,3,3,3,3,3,3,3,3,3,3,3,3,3,3,3,3,30,0,0,0
0,0,5,5,5,32,32,32,5,5,32,32,32,5,5,32,32,32,5,5,5,0,0,0
0,1,0,0,0,0,0,0,0,0,0,0,0,0,0,0,0,0,0,0,0,1,0,0
0,0,0,0,0,0,0,0,0,0,0,0,0,0,0,0,0,0,0,0,0,0,0,0
endlayer

layer
0,0,0,0,0,0,0,0,0,0,0,0,0,0,0,0,0,0,0,0,0,0,0,0
0,1,0,0,0,0,0,0,0,0,0,0,0,0,0,0,0,0,0,0,0,1,0,0
0,0,5,5,5,6,6,6,5,5,6,6,6,5,5,6,6,6,5,5,5,0,0,0
0,0,5,9,9,0,0,0,9,9,0,0,0,9,9,0,0,0,0,11,7,0,0,0
0,0,5,0,9,0,0,0,9,0,0,0,0,0,0,0,0,0,0,0,7,0,0,0
0,0,17,0,0,0,0,0,0,0,0,0,0,0,0,0,0,0,0,0,5,0,0,0
0,0,17,0,0,0,0,0,0,33,33,33,33,33,33,33,33,33,33,33,5,1,0,0
0,0,5,0,0,0,33,0,0,0,0,0,0,0,0,0,0,0,0,0,5,0,0,0
0,0,5,9,0,0,33,0,0,0,0,0,0,0,0,0,0,0,0,0,18,0,0,0
0,0,5,9,9,0,33,0,0,0,0,0,0,0,0,0,0,0,0,0,18,0,0,0
0,0,5,9,0,0,33,0,0,0,0,0,0,0,0,0,0,0,0,0,18,0,0,0
0,0,5,9,0,0,33,0,0,0,0,0,0,0,0,0,0,0,0,0,18,0,0,0
0,0,5,0,0,0,33,0,0,0,0,0,0,0,0,0,0,0,0,0,5,0,0,0
0,0,17,0,0,0,0,0,0,33,33,33,33,33,33,33,33,33,33,33,5,1,0,0
0,0,17,0,0,0,0,0,0,0,0,0,0,0,0,0,0,0,0,0,5,0,0,0
0,0,5,0,0,0,0,0,9,0,0,0,0,9,0,0,0,0,0,0,7,0,0,0
0,0,5,9,9,9,0,0,9,9,0,0,0,9,9,0,0,0,0,11,7,0,0,0
0,0,5,5,5,21,21,21,5,5,21,21,21,5,5,21,21,21,5,5,5,0,0,0
0,1,0,0,0,0,0,0,0,0,0,0,0,0,0,0,0,0,0,0,0,1,0,0
0,0,0,0,0,0,0,0,0,0,0,0,0,0,0,0,0,0,0,0,0,0,0,0
endlayer

layer
0,0,0,0,0,0,0,0,0,0,0,0,0,0,0,0,0,0,0,0,0,0,0,0
0,1,0,0,0,0,0,0,0,0,0,0,0,0,0,0,0,0,0,0,0,1,0,0
0,0,5,5,5,18,18,18,5,5,18,18,0,5,5,0,18,18,5,5,5,0,0,0
0,0,5,9,0,0,0,0,0,9,0,0,0,9,9,0,0,0,0,0,18,0,0,0
0,0,5,0,0,0,0,0,0,0,0,0,0,0,0,0,0,0,0,0,18,0,0,0
0,0,18,0,0,0,0,0,0,0,0,0,0,0,0,0,0,0,0,0,5,0,0,0
0,0,18,0,0,0,0,0,0,0,0,0,0,0,0,0,0,0,0,0,5,1,0,0
0,0,5,0,0,0,0,0,0,0,0,0,0,0,0,0,0,0,0,0,5,0,0,0
0,0,5,9,0,0,0,0,0,0,0,0,0,0,0,0,0,0,0,0,18,0,0,0
0,0,5,0,0,0,0,0,0,0,0,0,0,0,0,0,0,0,0,0,18,0,0,0
0,0,5,9,0,0,0,0,0,0,0,0,0,0,0,0,0,0,0,0,18,0,0,0
0,0,5,9,0,0,0,0,0,0,0,0,0,0,0,0,0,0,0,0,18,0,0,0
0,0,5,0,0,0,0,0,0,0,0,0,0,0,0,0,0,0,0,0,5,0,0,0
0,0,18,0,0,0,0,0,0,0,0,0,0,0,0,0,0,0,0,0,5,1,0,0
0,0,18,0,0,0,0,0,0,0,0,0,0,0,0,0,0,0,0,0,5,0,0,0
0,0,5,0,0,0,0,0,0,0,0,0,0,0,0,0,0,0,0,0,18,0,0,0
0,0,5,9,9,0,0,0,9,9,0,0,0,9,9,0,0,0,0,0,18,0,0,0
0,0,5,5,5,18,18,18,5,5,0,0,18,5,5,18,18,18,5,5,5,0,0,0
0,1,0,0,0,0,0,0,0,0,0,0,0,0,0,0,0,0,0,0,0,1,0,0
0,0,0,0,0,0,0,0,0,0,0,0,0,0,0,0,0,0,0,0,0,0,0,0
endlayer

layer
0,0,0,0,0,0,0,0,0,0,0,0,0,0,0,0,0,0,0,0,0,0,0,0
0,1,0,0,0,0,0,0,0,0,0,0,0,0,0,0,0,0,0,0,0,1,0,0
0,0,5,5,5,18,0,18,5,5,18,0,0,5,5,0,0,18,5,5,5,0,0,0
0,0,5,9,9,0,0,0,9,9,0,0,0,9,9,0,0,0,0,0,0,0,0,0
0,0,5,0,0,0,0,0,0,0,0,0,0,0,0,0,0,0,0,0,18,0,0,0
0,0,0,0,0,0,0,0,0,0,0,0,0,0,0,0,0,0,0,0,5,0,0,0
0,0,18,0,0,0,0,0,0,0,0,0,0,0,0,0,0,0,0,0,5,1,0,0
0,0,5,0,0,0,0,0,0,0,0,0,0,0,0,0,0,0,0,0,5,0,0,0
0,0,5,9,0,0,0,0,0,0,0,0,0,0,0,0,0,0,0,0,18,0,0,0
0,0,5,0,0,0,0,0,0,0,0,0,0,0,0,0,0,0,0,0,0,0,0,0
0,0,5,0,0,0,0,0,0,0,0,0,0,0,0,0,0,0,0,0,18,0,0,0
0,0,5,9,0,0,0,0,0,0,0,0,0,0,0,0,0,0,0,0,18,0,0,0
0,0,5,0,0,0,0,0,0,0,0,0,0,0,0,0,0,0,0,0,5,0,0,0
0,0,18,0,0,0,0,0,0,0,0,0,0,0,0,0,0,0,0,0,5,1,0,0
0,0,18,0,0,0,0,0,0,0,0,0,0,0,0,0,0,0,0,0,5,0,0,0
0,0,5,0,0,0,0,0,0,0,0,0,0,0,0,0,0,0,0,0,18,0,0,0
0,0,5,9,9,0,0,0,9,9,0,0,0,9,9,0,0,0,0,0,0,0,0,0
0,0,5,5,5,18,0,0,5,5,0,18,18,5,5,0,18,18,5,5,5,0,0,0
0,1,0,0,0,0,0,0,0,0,0,0,0,0,0,0,0,0,0,0,0,1,0,0
0,0,0,0,0,0,0,0,0,0,0,0,0,0,0,0,0,0,0,0,0,0,0,0
endlayer

layer
0,0,0,0,0,0,0,0,0,0,0,0,0,0,0,0,0,0,0,0,0,0,0,0
0,1,0,0,0,0,0,0,0,0,0,0,0,0,0,0,0,0,0,0,0,1,0,0
0,0,5,5,5,0,0,18,5,5,18,0,0,5,5,18,18,18,5,5,5,0,0,0
0,0,5,0,9,0,0,0,9,0,0,0,0,9,9,0,0,0,0,0,0,0,0,0
0,0,5,0,0,0,0,0,0,0,0,0,0,0,0,0,0,0,0,0,18,0,0,0
0,0,0,0,0,0,0,0,0,0,0,0,0,0,0,0,0,0,0,0,5,0,0,0
0,0,0,0,0,0,0,0,0,0,0,0,0,0,0,0,0,0,0,0,5,1,0,0
0,0,5,0,0,0,0,0,0,0,0,0,0,0,0,0,0,0,0,0,5,0,0,0
0,0,5,9,0,0,0,0,0,0,0,0,0,0,0,0,0,0,0,0,18,0,0,0
0,0,5,9,0,0,0,0,0,0,0,0,0,0,0,0,0,0,0,0,18,0,0,0
0,0,5,9,0,0,0,0,0,0,0,0,0,0,0,0,0,0,0,0,18,0,0,0
0,0,5,9,0,0,0,0,0,0,0,0,0,0,0,0,0,0,0,0,18,0,0,0
0,0,5,0,0,0,0,0,0,0,0,0,0,0,0,0,0,0,0,0,5,0,0,0
0,0,0,0,0,0,0,0,0,0,0,0,0,0,0,0,0,0,0,0,5,1,0,0
0,0,0,0,0,0,0,0,0,0,0,0,0,0,0,0,0,0,0,0,5,0,0,0
0,0,5,0,0,0,0,0,0,0,0,0,0,0,0,0,0,0,0,0,18,0,0,0
0,0,5,9,9,0,0,0,9,0,0,0,0,9,9,0,0,0,0,0,18,0,0,0
0,0,5,5,5,0,0,0,5,5,0,0,18,5,5,18,0,0,5,5,5,0,0,0
0,1,0,0,0,0,0,0,0,0,0,0,0,0,0,0,0,0,0,0,0,1,0,0
0,0,0,0,0,0,0,0,0,0,0,0,0,0,0,0,0,0,0,0,0,0,0,0
endlayer

layer
0,0,0,0,0,0,0,0,0,0,0,0,0,0,0,0,0,0,0,0,0,0,0,0
0,1,0,0,0,0,0,0,0,0,0,0,0,0,0,0,0,0,0,0,0,1,0,0
0,0,5,5,5,0,0,18,5,5,18,18,18,5,5,18,18,18,5,5,5,0,0,0
0,0,5,9,9,0,0,0,9,9,0,0,0,9,9,0,0,0,0,0,18,0,0,0
0,0,5,0,0,0,0,0,0,0,0,0,0,0,0,0,0,0,0,0,18,0,0,0
0,0,18,0,0,0,0,0,0,0,0,0,0,0,0,0,0,0,0,0,5,0,0,0
0,0,18,0,0,0,0,0,0,0,0,0,0,0,0,0,0,0,0,0,5,1,0,0
0,0,5,0,0,0,0,0,0,0,0,0,0,0,0,0,0,0,0,0,5,0,0,0
0,0,5,9,0,0,0,0,0,0,0,0,0,0,0,0,0,0,0,0,5,0,0,0
0,0,5,9,0,0,0,0,0,0,0,0,0,0,0,0,0,0,0,0,18,0,0,0
0,0,5,9,0,0,0,0,0,0,0,0,0,0,0,0,0,0,0,0,18,0,0,0
0,0,5,9,0,0,0,0,0,0,0,0,0,0,0,0,0,0,0,0,5,0,0,0
0,0,5,0,0,0,0,0,0,0,0,0,0,0,0,0,0,0,0,0,5,0,0,0
0,0,18,0,0,0,0,0,0,0,0,0,0,0,0,0,0,0,0,0,5,1,0,0
0,0,0,0,0,0,0,0,0,0,0,0,0,0,0,0,0,0,0,0,5,0,0,0
0,0,5,0,0,0,0,0,0,0,0,0,0,0,0,0,0,0,0,0,18,0,0,0
0,0,5,9,9,0,0,0,9,9,0,0,0,9,0,0,0,0,0,0,18,0,0,0
0,0,5,5,5,18,18,18,5,5,18,18,18,5,5,18,18,0,5,5,5,0,0,0
0,1,0,0,0,0,0,0,0,0,0,0,0,0,0,0,0,0,0,0,0,1,0,0
0,0,0,0,0,0,0,0,0,0,0,0,0,0,0,0,0,0,0,0,0,0,0,0
endlayer

layer
32,32,32,32,32,32,32,32,32,32,32,32,32,32,32,32,32,32,32,32,32,32,32,0
0,1,0,0,0,0,0,0,0,0,0,0,0,0,0,0,0,0,0,0,0,1,0,0
0,0,5,5,5,29,29,29,5,5,29,29,29,5,5,29,29,29,5,5,5,0,0,0
0,0,5,9,9,0,0,0,9,9,0,0,0,9,9,0,0,0,0,0,30,0,0,0
0,0,5,0,0,0,0,0,0,0,0,0,0,0,0,0,0,0,0,0,30,0,0,0
0,0,31,0,0,0,0,0,0,0,0,0,0,0,0,0,0,0,0,0,5,0,0,0
0,0,31,0,0,0,0,0,0,0,0,0,0,0,0,0,0,0,0,0,5,1,0,0
0,0,5,0,0,0,0,0,0,0,0,0,0,0,0,0,0,0,0,0,5,0,0,0
0,0,5,9,0,0,0,0,0,0,0,0,0,0,0,0,0,0,0,0,5,0,0,0
0,0,5,9,0,0,0,0,0,0,0,0,0,0,0,0,0,0,0,0,5,0,0,0
0,0,5,9,0,0,0,0,0,0,0,0,0,0,0,0,0,0,0,0,5,0,0,0
0,0,5,9,0,0,0,0,0,0,0,0,0,0,0,0,0,0,0,0,5,0,0,0
0,0,5,0,0,0,0,0,0,0,0,0,0,0,0,0,0,0,0,0,5,0,0,0
0,0,31,0,0,0,0,0,0,0,0,0,0,0,0,0,0,0,0,0,5,1,0,0
0,0,31,0,0,0,0,0,0,0,0,0,0,0,0,0,0,0,0,0,5,0,0,0
0,0,5,0,0,0,0,0,0,0,0,0,0,0,0,0,0,0,0,0,30,0,0,0
0,0,5,9,0,0,0,0,9,9,0,0,0,9,9,0,0,0,0,0,30,0,0,0
0,0,5,5,5,32,32,32,5,5,32,32,32,5,5,32,32,32,5,5,5,0,0,0
0,1,0,0,0,0,0,0,0,0,0,0,0,0,0,0,0,0,0,0,0,1,0,0
29,29,29,29,29,29,29,29,29,29,29,29,29,29,29,29,29,29,29,29,29,29,29,0
endlayer

layer
6,6,6,6,6,6,6,6,6,6,6,6,6,6,6,6,6,6,6,6,6,6,6,0
32,34,34,34,34,34,34,34,34,34,34,34,34,34,34,34,34,34,34,34,34,34,32,0
0,34,34,34,34,34,34,34,34,34,34,34,34,34,34,34,34,34,34,34,34,34,0,0
0,34,0,0,0,0,0,0,0,0,0,0,0,0,0,0,0,0,0,0,34,34,0,0
0,34,0,0,0,0,0,0,0,0,0,0,0,0,0,0,0,0,0,0,0,34,0,0
0,34,0,0,0,0,0,0,0,0,0,0,0,0,0,0,0,0,0,0,0,34,0,0
0,34,0,0,0,0,0,0,0,0,0,0,0,0,0,0,0,0,0,0,0,34,0,0
0,34,0,0,0,0,0,0,0,0,0,0,0,0,0,0,0,0,0,0,0,34,0,0
0,34,0,0,0,0,0,0,0,0,0,0,0,0,0,0,0,0,0,0,0,34,0,0
0,34,0,0,0,0,0,0,0,0,0,0,0,0,0,0,0,0,0,0,0,34,0,0
0,34,0,0,0,0,0,0,0,0,0,0,0,0,0,0,0,0,0,0,0,34,0,0
0,34,0,0,0,0,0,0,0,0,0,0,0,0,0,0,0,0,0,0,0,34,0,0
0,34,0,0,0,0,0,0,0,0,0,0,0,0,0,0,0,0,0,0,0,34,0,0
0,34,0,0,0,0,0,0,0,0,0,0,0,0,0,0,0,0,0,0,0,34,0,0
0,34,0,0,0,0,0,0,0,0,0,0,0,0,0,0,0,0,0,0,0,34,0,0
0,34,0,0,0,0,0,0,0,0,0,0,0,0,0,0,0,0,0,0,0,34,0,0
0,34,0,0,0,0,0,0,0,0,0,0,0,0,0,0,0,0,0,0,0,34,0,0
0,34,34,34,34,34,34,34,34,34,34,34,34,34,34,34,34,34,34,34,34,34,0,0
29,34,34,34,34,34,34,34,34,34,34,34,34,34,34,34,34,34,34,34,34,34,29,0
21,21,21,21,21,21,21,21,21,21,21,21,21,21,21,21,21,21,21,21,21,21,21,0
endlayer

layer
0,0,0,0,0,0,0,0,0,0,0,0,0,0,0,0,0,0,0,0,0,0,0,0
6,6,6,6,6,6,6,6,6,6,6,6,6,6,6,6,6,6,6,6,6,6,6,0
32,34,34,34,34,34,34,34,34,34,34,34,34,34,34,34,34,34,34,34,34,34,32,0
0,34,0,0,0,0,0,0,0,0,0,0,0,0,0,0,0,0,0,0,34,34,0,0
0,34,0,0,0,0,0,0,0,0,0,0,0,0,0,0,0,0,0,0,0,34,0,0
0,34,0,0,0,0,0,0,0,0,0,0,0,0,0,0,0,0,0,0,0,34,0,0
0,34,0,0,0,0,0,0,0,0,0,0,0,0,0,0,0,0,0,0,0,34,0,0
0,34,0,0,0,0,0,0,0,0,0,0,0,0,0,0,0,0,0,0,0,34,0,0
0,34,0,0,0,0,0,0,0,0,0,0,0,0,0,0,0,0,0,0,0,34,0,0
0,34,0,0,0,0,0,0,0,0,0,0,0,0,0,0,0,0,0,0,0,34,0,0
0,34,0,0,0,0,0,0,0,0,0,0,0,0,0,0,0,0,0,0,0,34,0,0
0,34,0,0,0,0,0,0,0,0,0,0,0,0,0,0,0,0,0,0,0,34,0,0
0,34,0,0,0,0,0,0,0,0,0,0,0,0,0,0,0,0,0,0,0,34,0,0
0,34,0,0,0,0,0,0,0,0,0,0,0,0,0,0,0,0,0,0,0,34,0,0
0,34,0,0,0,0,0,0,0,0,0,0,0,0,0,0,0,0,0,0,0,34,0,0
0,34,0,0,0,0,0,0,0,0,0,0,0,0,0,0,0,0,0,0,0,34,0,0
0,34,0,0,0,0,0,0,0,0,0,0,0,0,0,0,0,0,0,0,0,34,0,0
29,34,34,34,34,34,34,34,34,34,34,34,34,34,34,34,34,34,34,34,34,34,29,0
21,21,21,21,21,21,21,21,21,21,21,21,21,21,21,21,21,21,21,21,21,21,21,0
0,0,0,0,0,0,0,0,0,0,0,0,0,0,0,0,0,0,0,0,0,0,0,0
endlayer

layer
0,0,0,0,0,0,0,0,0,0,0,0,0,0,0,0,0,0,0,0,0,0,0,0
0,0,0,0,0,0,0,0,0,0,0,0,0,0,0,0,0,0,0,0,0,0,0,0
6,6,6,6,6,6,6,6,6,6,6,6,6,6,6,6,6,6,6,6,6,6,6,0
32,34,34,34,34,34,34,34,34,34,34,34,34,34,34,34,34,34,34,34,34,34,32,0
0,34,0,0,0,0,0,0,0,0,0,0,0,0,0,0,0,0,0,0,0,34,0,0
0,34,0,0,0,0,0,0,0,0,0,0,0,0,0,0,0,0,0,0,0,34,0,0
0,34,0,0,0,0,0,0,0,0,0,0,0,0,0,0,0,0,0,0,0,34,0,0
0,34,0,0,0,0,0,0,0,0,0,0,0,0,0,0,0,0,0,0,0,34,0,0
0,34,0,0,0,0,0,0,0,0,0,0,0,0,0,0,0,0,0,0,0,34,0,0
0,34,0,0,0,0,0,0,0,0,0,0,0,0,0,0,0,0,0,0,0,34,0,0
0,34,0,0,0,0,0,0,0,0,0,0,0,0,0,0,0,0,0,0,0,34,0,0
0,34,0,0,0,0,0,0,0,0,0,0,0,0,0,0,0,0,0,0,0,34,0,0
0,34,0,0,0,0,0,0,0,0,0,0,0,0,0,0,0,0,0,0,0,34,0,0
0,34,0,0,0,0,0,0,0,0,0,0,0,0,0,0,0,0,0,0,0,34,0,0
0,34,0,0,0,0,0,0,0,0,0,0,0,0,0,0,0,0,0,0,0,34,0,0
0,34,0,0,0,0,0,0,0,0,0,0,0,0,0,0,0,0,0,0,0,34,0,0
29,34,34,34,34,34,34,34,34,34,34,34,34,34,34,34,34,34,34,34,34,34,29,0
21,21,21,21,21,21,21,21,21,21,21,21,21,21,21,21,21,21,21,21,21,21,21,0
0,0,0,0,0,0,0,0,0,0,0,0,0,0,0,0,0,0,0,0,0,0,0,0
0,0,0,0,0,0,0,0,0,0,0,0,0,0,0,0,0,0,0,0,0,0,0,0
endlayer

layer
0,0,0,0,0,0,0,0,0,0,0,0,0,0,0,0,0,0,0,0,0,0,0,0
0,0,0,0,0,0,0,0,0,0,0,0,0,0,0,0,0,0,0,0,0,0,0,0
0,0,0,0,0,0,0,0,0,0,0,0,0,0,0,0,0,0,0,0,0,0,0,0
6,6,6,6,6,6,6,6,6,6,6,6,6,6,6,6,6,6,6,6,6,6,6,0
32,34,34,34,34,34,34,34,34,34,34,34,34,34,34,34,34,34,34,34,34,34,32,0
0,34,0,0,0,0,0,0,0,0,0,0,0,0,0,0,0,0,0,0,0,34,0,0
0,34,0,0,0,0,0,0,0,0,0,0,0,0,0,0,0,0,0,0,0,34,0,0
0,34,0,0,0,0,0,0,0,0,0,0,0,0,0,0,0,0,0,0,0,34,0,0
0,34,0,0,0,0,0,0,0,0,0,0,0,0,0,0,0,0,0,0,0,34,0,0
0,34,0,0,0,0,0,0,0,0,0,0,0,0,0,0,0,0,0,0,0,34,0,0
0,34,0,0,0,0,0,0,0,0,0,0,0,0,0,0,0,0,0,0,0,34,0,0
0,34,0,0,0,0,0,0,0,0,0,0,0,0,0,0,0,0,0,0,0,34,0,0
0,34,0,0,0,0,0,0,0,0,0,0,0,0,0,0,0,0,0,0,0,34,0,0
0,34,0,0,0,0,0,0,0,0,0,0,0,0,0,0,0,0,0,0,0,34,0,0
0,34,0,0,0,0,0,0,0,0,0,0,0,0,0,0,0,0,0,0,0,34,0,0
29,34,34,34,34,34,34,34,34,34,34,34,34,34,34,34,34,34,34,34,34,34,29,0
21,21,21,21,21,21,21,21,21,21,21,21,21,21,21,21,21,21,21,21,21,21,21,0
0,0,0,0,0,0,0,0,0,0,0,0,0,0,0,0,0,0,0,0,0,0,0,0
0,0,0,0,0,0,0,0,0,0,0,0,0,0,0,0,0,0,0,0,0,0,0,0
0,0,0,0,0,0,0,0,0,0,0,0,0,0,0,0,0,0,0,0,0,0,0,0
endlayer

layer
0,0,0,0,0,0,0,0,0,0,0,0,0,0,0,0,0,0,0,0,0,0,0,0
0,0,0,0,0,0,0,0,0,0,0,0,0,0,0,0,0,0,0,0,0,0,0,0
0,0,0,0,0,0,0,0,0,0,0,0,0,0,0,0,0,0,0,0,0,0,0,0
0,0,0,0,0,0,0,0,0,0,0,0,0,0,0,0,0,0,0,0,0,0,0,0
6,6,6,6,6,6,6,6,6,6,6,6,6,6,6,6,6,6,6,6,6,6,6,0
32,34,34,34,34,34,34,34,34,34,34,34,34,34,34,34,34,34,34,34,34,34,32,0
0,34,0,0,0,0,0,0,0,0,0,0,0,0,0,0,0,0,0,0,0,34,0,0
0,34,0,0,0,0,0,0,0,0,0,0,0,0,0,0,0,0,0,0,0,34,0,0
0,34,0,0,0,0,0,0,0,0,0,0,0,0,0,0,0,0,0,0,0,34,0,0
0,34,0,0,0,0,0,0,0,0,0,0,0,0,0,0,0,0,0,0,0,34,0,0
0,34,0,0,0,0,0,0,0,0,0,0,0,0,0,0,0,0,0,0,0,34,0,0
0,34,0,0,0,0,0,0,0,0,0,0,0,0,0,0,0,0,0,0,0,34,0,0
0,34,0,0,0,0,0,0,0,0,0,0,0,0,0,0,0,0,0,0,0,34,0,0
0,34,0,0,0,0,0,0,0,0,0,0,0,0,0,0,0,0,0,0,0,34,0,0
29,34,34,34,34,34,34,34,34,34,34,34,34,34,34,34,34,34,34,34,34,34,29,0
21,21,21,21,21,21,21,21,21,21,21,21,21,21,21,21,21,21,21,21,21,21,21,0
0,0,0,0,0,0,0,0,0,0,0,0,0,0,0,0,0,0,0,0,0,0,0,0
0,0,0,0,0,0,0,0,0,0,0,0,0,0,0,0,0,0,0,0,0,0,0,0
0,0,0,0,0,0,0,0,0,0,0,0,0,0,0,0,0,0,0,0,0,0,0,0
0,0,0,0,0,0,0,0,0,0,0,0,0,0,0,0,0,0,0,0,0,0,0,0
endlayer

layer
0,0,0,0,0,0,0,0,0,0,0,0,0,0,0,0,0,0,0,0,0,0,0,0
0,0,0,0,0,0,0,0,0,0,0,0,0,0,0,0,0,0,0,0,0,0,0,0
0,0,0,0,0,0,0,0,0,0,0,0,0,0,0,0,0,0,0,0,0,0,0,0
0,0,0,0,0,0,0,0,0,0,0,0,0,0,0,0,0,0,0,0,0,0,0,0
0,0,0,0,0,0,0,0,0,0,0,0,0,0,0,0,0,0,0,0,0,0,0,0
6,6,6,6,6,6,6,6,6,6,6,6,6,6,6,6,6,6,6,6,6,6,6,0
32,34,34,34,34,34,34,34,34,34,34,34,34,34,34,34,34,34,34,34,34,34,32,0
0,34,0,0,0,0,0,0,0,0,0,0,0,0,0,0,0,0,0,0,0,34,0,0
0,34,0,0,0,0,0,0,0,0,0,0,0,0,0,0,0,0,0,0,0,34,0,0
0,34,0,0,0,0,0,0,0,0,0,0,0,0,0,0,0,0,0,0,0,34,0,0
0,34,0,0,0,0,0,0,0,0,0,0,0,0,0,0,0,0,0,0,0,34,0,0
0,34,0,0,0,0,0,0,0,0,0,0,0,0,0,0,0,0,0,0,0,34,0,0
0,34,0,0,0,0,0,0,0,0,0,0,0,0,0,0,0,0,0,0,0,34,0,0
29,34,34,34,34,34,34,34,34,34,34,34,34,34,34,34,34,34,34,34,34,34,29,0
21,21,21,21,21,21,21,21,21,21,21,21,21,21,21,21,21,21,21,21,21,21,21,0
0,0,0,0,0,0,0,0,0,0,0,0,0,0,0,0,0,0,0,0,0,0,0,0
0,0,0,0,0,0,0,0,0,0,0,0,0,0,0,0,0,0,0,0,0,0,0,0
0,0,0,0,0,0,0,0,0,0,0,0,0,0,0,0,0,0,0,0,0,0,0,0
0,0,0,0,0,0,0,0,0,0,0,0,0,0,0,0,0,0,0,0,0,0,0,0
0,0,0,0,0,0,0,0,0,0,0,0,0,0,0,0,0,0,0,0,0,0,0,0
endlayer

layer
0,0,0,0,0,0,0,0,0,0,0,0,0,0,0,0,0,0,0,0,0,0,0,0
0,0,0,0,0,0,0,0,0,0,0,0,0,0,0,0,0,0,0,0,0,0,0,0
0,0,0,0,0,0,0,0,0,0,0,0,0,0,0,0,0,0,0,0,0,0,0,0
0,0,0,0,0,0,0,0,0,0,0,0,0,0,0,0,0,0,0,0,0,0,0,0
0,0,0,0,0,0,0,0,0,0,0,0,0,0,0,0,0,0,0,0,0,0,0,0
0,0,0,0,0,0,0,0,0,0,0,0,0,0,0,0,0,0,0,0,0,0,0,0
6,6,6,6,6,6,6,6,6,6,6,6,6,6,6,6,6,6,6,6,6,6,6,0
32,34,34,34,34,34,34,34,34,34,34,34,34,34,34,34,34,34,34,34,34,34,32,0
0,34,0,0,0,0,0,0,0,0,0,0,0,0,0,0,0,0,0,0,0,34,0,0
0,34,0,0,0,0,0,0,0,0,0,0,0,0,0,0,0,0,0,0,0,34,0,0
0,34,0,0,0,0,0,0,0,0,0,0,0,0,0,0,0,0,0,0,0,34,0,0
0,34,0,0,0,0,0,0,0,0,0,0,0,0,0,0,0,0,0,0,0,34,0,0
29,34,34,34,34,34,34,34,34,34,34,34,34,34,34,34,34,34,34,34,34,34,29,0
21,21,21,21,21,21,21,21,21,21,21,21,21,21,21,21,21,21,21,21,21,21,21,0
0,0,0,0,0,0,0,0,0,0,0,0,0,0,0,0,0,0,0,0,0,0,0,0
0,0,0,0,0,0,0,0,0,0,0,0,0,0,0,0,0,0,0,0,0,0,0,0
0,0,0,0,0,0,0,0,0,0,0,0,0,0,0,0,0,0,0,0,0,0,0,0
0,0,0,0,0,0,0,0,0,0,0,0,0,0,0,0,0,0,0,0,0,0,0,0
0,0,0,0,0,0,0,0,0,0,0,0,0,0,0,0,0,0,0,0,0,0,0,0
0,0,0,0,0,0,0,0,0,0,0,0,0,0,0,0,0,0,0,0,0,0,0,0
endlayer

layer
0,0,0,0,0,0,0,0,0,0,0,0,0,0,0,0,0,0,0,0,0,0,0,0
0,0,0,0,0,0,0,0,0,0,0,0,0,0,0,0,0,0,0,0,0,0,0,0
0,0,0,0,0,0,0,0,0,0,0,0,0,0,0,0,0,0,0,0,0,0,0,0
0,0,0,0,0,0,0,0,0,0,0,0,0,0,0,0,0,0,0,0,0,0,0,0
0,0,0,0,0,0,0,0,0,0,0,0,0,0,0,0,0,0,0,0,0,0,0,0
0,0,0,0,0,0,0,0,0,0,0,0,0,0,0,0,0,0,0,0,0,0,0,0
0,0,0,0,0,0,0,0,0,0,0,0,0,0,0,0,0,0,0,0,0,0,0,0
6,6,6,6,6,6,6,6,6,6,6,6,6,6,6,6,6,6,6,6,6,6,6,0
32,34,34,34,34,34,34,34,34,34,34,34,34,34,34,34,34,34,34,34,34,34,32,0
0,34,0,0,0,0,0,0,0,0,0,0,0,0,0,0,0,0,0,0,0,34,0,0
0,34,0,0,0,0,0,0,0,0,0,0,0,0,0,0,0,0,0,0,0,34,0,0
29,34,34,34,34,34,34,34,34,34,34,34,34,34,34,34,34,34,34,34,34,34,29,0
21,21,21,21,21,21,21,21,21,21,21,21,21,21,21,21,21,21,21,21,21,21,21,0
0,0,0,0,0,0,0,0,0,0,0,0,0,0,0,0,0,0,0,0,0,0,0,0
0,0,0,0,0,0,0,0,0,0,0,0,0,0,0,0,0,0,0,0,0,0,0,0
0,0,0,0,0,0,0,0,0,0,0,0,0,0,0,0,0,0,0,0,0,0,0,0
0,0,0,0,0,0,0,0,0,0,0,0,0,0,0,0,0,0,0,0,0,0,0,0
0,0,0,0,0,0,0,0,0,0,0,0,0,0,0,0,0,0,0,0,0,0,0,0
0,0,0,0,0,0,0,0,0,0,0,0,0,0,0,0,0,0,0,0,0,0,0,0
0,0,0,0,0,0,0,0,0,0,0,0,0,0,0,0,0,0,0,0,0,0,0,0
endlayer

layer
0,0,0,0,0,0,0,0,0,0,0,0,0,0,0,0,0,0,0,0,0,0,0,0
0,0,0,0,0,0,0,0,0,0,0,0,0,0,0,0,0,0,0,0,0,0,0,0
0,0,0,0,0,0,0,0,0,0,0,0,0,0,0,0,0,0,0,0,0,0,0,0
0,0,0,0,0,0,0,0,0,0,0,0,0,0,0,0,0,0,0,0,0,0,0,0
0,0,0,0,0,0,0,0,0,0,0,0,0,0,0,0,0,0,0,0,0,0,0,0
0,0,0,0,0,0,0,0,0,0,0,0,0,0,0,0,0,0,0,0,0,0,0,0
0,0,0,0,0,0,0,0,0,0,0,0,0,0,0,0,0,0,0,0,0,0,0,0
0,0,0,0,0,0,0,0,0,0,0,0,0,0,0,0,0,0,0,0,0,0,0,0
6,6,6,6,6,6,6,6,6,6,6,6,6,6,6,6,6,6,6,6,6,6,6,0
35,34,34,34,34,34,34,34,34,34,34,34,34,34,34,34,34,34,34,34,34,34,35,0
29,34,34,34,34,34,34,34,34,34,34,34,34,34,34,34,34,34,34,34,34,34,35,0
21,21,21,21,21,21,21,21,21,21,21,21,21,21,21,21,21,21,21,21,21,21,21,0
0,0,0,0,0,0,0,0,0,0,0,0,0,0,0,0,0,0,0,0,0,0,0,0
0,0,0,0,0,0,0,0,0,0,0,0,0,0,0,0,0,0,0,0,0,0,0,0
0,0,0,0,0,0,0,0,0,0,0,0,0,0,0,0,0,0,0,0,0,0,0,0
0,0,0,0,0,0,0,0,0,0,0,0,0,0,0,0,0,0,0,0,0,0,0,0
0,0,0,0,0,0,0,0,0,0,0,0,0,0,0,0,0,0,0,0,0,0,0,0
0,0,0,0,0,0,0,0,0,0,0,0,0,0,0,0,0,0,0,0,0,0,0,0
0,0,0,0,0,0,0,0,0,0,0,0,0,0,0,0,0,0,0,0,0,0,0,0
0,0,0,0,0,0,0,0,0,0,0,0,0,0,0,0,0,0,0,0,0,0,0,0
endlayer

layer
0,0,0,0,0,0,0,0,0,0,0,0,0,0,0,0,0,0,0,0,0,0,0,0
0,0,0,0,0,0,0,0,0,0,0,0,0,0,0,0,0,0,0,0,0,0,0,0
0,0,0,0,0,0,0,0,0,0,0,0,0,0,0,0,0,0,0,0,0,0,0,0
0,0,0,0,0,0,0,0,0,0,0,0,0,0,0,0,0,0,0,0,0,0,0,0
0,0,0,0,0,0,0,0,0,0,0,0,0,0,0,0,0,0,0,0,0,0,0,0
0,0,0,0,0,0,0,0,0,0,0,0,0,0,0,0,0,0,0,0,0,0,0,0
0,0,0,0,0,0,0,0,0,0,0,0,0,0,0,0,0,0,0,0,0,0,0,0
0,0,0,0,0,0,0,0,0,0,0,0,0,0,0,0,0,0,0,0,0,0,0,0
0,0,0,0,0,0,0,0,0,0,0,0,0,0,0,0,0,0,0,0,0,0,0,0
36,36,36,36,36,36,36,36,36,36,36,36,36,36,36,36,36,36,36,36,36,36,36,36
36,36,36,36,36,36,36,36,36,36,36,36,36,36,36,36,36,36,36,36,36,36,36,36
0,0,0,0,0,0,0,0,0,0,0,0,0,0,0,0,0,0,0,0,0,0,0,0
0,0,0,0,0,0,0,0,0,0,0,0,0,0,0,0,0,0,0,0,0,0,0,0
0,0,0,0,0,0,0,0,0,0,0,0,0,0,0,0,0,0,0,0,0,0,0,0
0,0,0,0,0,0,0,0,0,0,0,0,0,0,0,0,0,0,0,0,0,0,0,0
0,0,0,0,0,0,0,0,0,0,0,0,0,0,0,0,0,0,0,0,0,0,0,0
0,0,0,0,0,0,0,0,0,0,0,0,0,0,0,0,0,0,0,0,0,0,0,0
0,0,0,0,0,0,0,0,0,0,0,0,0,0,0,0,0,0,0,0,0,0,0,0
0,0,0,0,0,0,0,0,0,0,0,0,0,0,0,0,0,0,0,0,0,0,0,0
0,0,0,0,0,0,0,0,0,0,0,0,0,0,0,0,0,0,0,0,0,0,0,0
endlayer

