
# Created by Ruins mod version 15.1 Ingame Parser
# authoring Player: SunsOfOld

weight=100
embed_into_distance=6
acceptable_target_blocks=
unacceptable_target_blocks=flowing_water,water,flowing_lava,lava
dimensions=35,27,30
allowable_overhang=0
max_leveling=6
leveling_buffer=0
preserve_water=0
preserve_lava=0
uniqueMinDistance=1000000
preventRotation=1

rule1=0,100,preserveBlock
rule2=0,100,minecraft:bedrock-0
rule3=0,100,minecraft:redstone_wire-15
rule4=0,100,minecraft:powered_repeater-0
rule5=2,100,minecraft:redstone_torch-2
rule6=0,100,minecraft:powered_repeater-2
rule7=0,100,CommandBlock:/testfor @p[r=16]:@
rule8=0,100,minecraft:redstone_wire-14
rule9=0,100,minecraft:unpowered_comparator-1
rule10=0,100,minecraft:redstone_wire-13
rule11=0,100,minecraft:unpowered_repeater-1
rule12=0,100,minecraft:redstone_wire-12
rule13=0,100,minecraft:unpowered_repeater-0
rule14=0,100,CommandBlock:/setblock ~ ~ ~ 152:@
rule15=0,100,CommandBlock:/summon Villager ~ ~24 ~ {CustomName:\"Do you know the power of the mushroom?\",CustomNameVisible:1,Profession:0,Offers:{Recipes:[{rewardExp:1b,maxUses:2147483647,uses:0,buy:{id:1289,Count:1},sell:{id:282,Count:1}},{rewardExp:1b,maxUses:2147483647,uses:0,buy:{id:1290,Count:2},sell:{id:4369,Count:4}},{rewardExp:1b,maxUses:2147483647,uses:0,buy:{id:1291,Count:3},sell:{id:5196,Count:1}},{rewardExp:1b,maxUses:2147483647,uses:0,buy:{id:1292,Count:2},sell:{id:5163,Count:1}},{rewardExp:1b,maxUses:2147483647,uses:0,buy:{id:1293,Count:32},sell:{id:110,Count:1}}]}}:@
rule16=0,100,minecraft:redstone_wire-0
rule17=0,100,minecraft:grass-0
rule18=0,100,minecraft:dirt-0
rule19=0,100,minecraft:snow_layer-0
rule20=0,100,harvestcraft:mushroomgarden-0
rule21=0,100,plantmegapack:fungusWeepingMilkCap-0
rule22=0,100,BiomesOPlenty:mushrooms-2
rule23=0,100,BiomesOPlenty:mushrooms-4
rule24=0,100,BiomesOPlenty:mushrooms-5
rule25=0,100,plantmegapack:fungusWoodBlewit-0
rule26=0,100,plantmegapack:fungusBlackPowderpuff-0
rule27=0,100,plantmegapack:fungusChanterelle-0
rule28=0,100,BiomesOPlenty:mushrooms-1
rule29=0,100,chisel:packedice-2
rule30=0,100,BiomesOPlenty:flowers-3
rule31=0,100,chisel:factoryblock-15
rule32=0,100,plantmegapack:fungusParasol-0
rule33=0,100,plantmegapack:bambooTropicalBlueLadder-5
rule34=0,100,BiomesOPlenty:treeMoss-4
rule35=0,100,BiomesOPlenty:treeMoss-2
rule36=0,100,BiomesOPlenty:treeMoss-8
rule37=0,100,BiomesOPlenty:treeMoss-9
rule38=0,100,BiomesOPlenty:treeMoss-1
rule39=0,100,plantmegapack:bambooTropicalBlueLadder-4
rule40=0,100,plantmegapack:vineSpanishMoss-8
rule41=0,100,BiomesOPlenty:treeMoss-6
rule42=0,100,plantmegapack:vineSpanishMoss-2
rule43=0,100,plantmegapack:vineSpanishMoss-1
rule44=0,100,plantmegapack:vineSpanishMoss-9
rule45=0,100,plantmegapack:vineSpanishMoss-4
rule46=0,100,plantmegapack:vineSpanishMoss-0
rule47=0,100,BiomesOPlenty:leaves1-6
rule48=0,100,BiomesOPlenty:logs2-5
rule49=0,100,BiomesOPlenty:leaves1-14
rule50=0,100,dendrology:logs2-6
rule51=0,100,dendrology:logs2-10
rule52=0,100,BiomesOPlenty:logs2-9
rule53=0,100,BiomesOPlenty:planks-5
rule54=0,100,BiomesOPlenty:magicStairs-2
rule55=0,100,BiomesOPlenty:magicStairs-7
rule56=0,100,BiomesOPlenty:magicStairs-6
rule57=0,100,BiomesOPlenty:magicStairs-3
rule58=0,100,BiomesOPlenty:magicStairs-4
rule59=0,100,BiomesOPlenty:magicStairs-1
rule60=0,100,BiomesOPlenty:magicStairs-0
rule61=0,100,BiomesOPlenty:magicStairs-5
rule62=0,100,BiomesOPlenty:woodenSingleSlab1-13
rule63=0,100,chisel:templeblock-15
rule64=0,100,chisel:glass2-0

layer
1,1,1,1,1,1,1,1,1,1,1,1,1,1,1,1,1,1,1,1,1,1,1,1,1,1,1,1,1,1
1,1,1,1,1,1,1,1,1,1,1,1,1,1,1,1,1,1,1,1,1,1,1,1,1,1,1,1,1,1
1,1,1,1,1,1,1,1,1,1,1,1,1,1,1,1,1,1,1,1,1,1,1,1,1,1,1,1,1,1
1,1,1,1,1,1,1,1,1,1,1,1,1,1,1,1,1,1,1,1,1,1,1,1,1,1,1,1,1,1
1,1,1,1,1,1,1,1,1,1,1,1,1,1,1,1,1,1,1,1,1,1,1,1,1,1,1,1,1,1
1,1,1,1,1,1,1,1,1,1,1,1,1,1,1,1,1,1,1,1,1,1,1,1,1,1,1,1,1,1
1,1,1,1,1,1,1,1,1,1,1,1,1,1,1,1,1,1,1,1,1,1,1,1,1,1,1,1,1,1
1,1,1,1,1,1,1,1,1,1,1,1,1,1,1,1,1,1,1,1,1,1,1,1,1,1,1,1,1,1
1,1,1,1,1,1,1,1,1,1,1,1,1,1,1,1,1,1,1,1,1,1,1,1,1,1,1,1,1,1
1,1,1,1,1,1,1,1,1,1,1,1,1,1,1,1,1,1,1,1,1,1,1,1,1,1,1,1,1,1
1,1,1,1,1,1,1,1,1,1,1,1,1,1,1,1,2,1,1,1,1,1,1,1,1,1,1,1,1,1
1,1,1,1,1,1,1,1,1,1,1,1,1,1,1,1,2,1,1,1,1,1,1,1,1,1,1,1,1,1
1,1,1,1,1,1,1,1,1,1,1,1,1,1,1,1,1,1,1,1,1,1,1,1,1,1,1,1,1,1
1,1,1,1,1,1,1,1,1,1,1,1,1,1,1,1,1,1,1,1,1,1,1,1,1,1,1,1,1,1
1,1,1,1,1,1,1,1,1,1,1,1,1,1,1,1,1,1,1,1,1,1,1,1,1,1,1,1,1,1
1,1,1,1,1,1,1,1,1,1,1,1,1,1,1,1,1,1,1,1,1,1,1,1,1,1,1,1,1,1
1,1,1,1,1,1,1,1,1,1,1,1,1,1,1,1,1,1,1,1,1,1,1,1,1,1,1,1,1,1
1,1,1,1,1,1,1,1,1,1,1,1,1,1,1,1,1,1,1,1,1,1,1,1,1,1,1,1,1,1
1,1,1,1,1,1,1,1,1,1,1,1,1,1,1,1,1,1,1,1,1,1,1,1,1,1,1,1,1,1
1,1,1,1,1,1,1,1,1,1,1,1,1,1,1,1,1,1,1,1,1,1,1,1,1,1,1,1,1,1
1,1,1,1,1,1,1,1,1,1,1,1,1,1,1,1,1,1,1,1,1,1,1,1,1,1,1,1,1,1
1,1,1,1,1,1,1,1,1,1,1,1,1,1,1,1,1,1,1,1,1,1,1,1,1,1,1,1,1,1
1,1,1,1,1,1,1,1,1,1,1,1,1,1,1,1,1,1,1,1,1,1,1,1,1,1,1,1,1,1
1,1,1,1,1,1,1,1,1,1,1,1,1,1,1,1,1,1,1,1,1,1,1,1,1,1,1,1,1,1
1,1,1,1,1,1,1,1,1,1,1,0,1,1,1,1,1,1,1,1,1,1,1,1,1,1,1,1,1,1
1,1,1,1,1,1,1,1,1,1,1,1,1,1,1,1,1,1,1,1,1,1,1,1,1,1,1,1,1,1
1,1,1,1,1,1,1,1,1,1,1,1,1,1,1,1,1,1,1,1,1,1,1,1,1,1,1,1,1,1
endlayer

layer
1,1,1,1,1,1,1,1,1,1,1,1,1,1,1,1,1,1,1,1,1,1,1,1,1,1,1,1,1,1
1,1,1,1,1,1,1,1,1,1,1,1,1,1,1,1,1,1,1,1,1,1,1,1,1,1,1,1,1,1
1,1,1,1,1,1,1,1,1,1,1,1,1,1,1,1,1,1,1,1,1,1,1,1,1,1,1,1,1,1
1,1,1,1,1,1,1,1,1,1,1,1,1,1,1,1,1,1,1,1,1,1,1,1,1,1,1,1,1,1
1,1,1,1,1,1,1,1,1,1,1,1,1,1,1,1,1,1,1,1,1,1,1,1,1,1,1,1,1,1
1,1,1,1,1,1,1,1,1,1,1,1,1,1,1,1,1,1,1,1,1,1,1,1,1,1,1,1,1,1
1,1,1,1,1,1,1,1,1,1,1,1,1,1,1,1,1,1,1,1,1,1,1,1,1,1,1,1,1,1
1,1,1,1,1,1,1,1,1,1,1,1,1,1,1,1,1,1,1,1,1,1,1,1,1,1,1,1,1,1
1,1,1,1,1,1,1,1,1,1,1,1,1,1,1,1,1,1,1,1,1,1,1,1,1,1,1,1,1,1
1,1,1,1,1,1,1,1,1,1,1,1,1,1,2,2,2,2,2,1,1,1,1,1,1,1,1,1,1,1
1,1,1,1,1,1,1,1,1,1,1,1,1,1,2,2,0,2,2,1,1,1,1,1,1,1,1,1,1,1
1,1,1,1,1,1,1,1,1,1,1,1,1,1,2,2,2,2,2,1,1,1,1,1,1,1,1,1,1,1
1,1,1,1,1,1,1,1,1,1,1,1,1,1,2,2,2,2,2,1,1,1,1,1,1,1,1,1,1,1
1,1,1,1,1,1,1,1,1,1,1,1,1,1,2,2,2,2,2,1,1,1,1,1,1,1,1,1,1,1
1,1,1,1,1,1,1,1,1,1,1,1,1,1,1,1,1,1,1,1,1,1,1,1,1,1,1,1,1,1
1,1,1,1,1,1,1,1,1,1,1,1,1,1,1,1,1,1,1,1,1,1,1,1,1,1,1,1,1,1
1,1,1,1,1,1,1,1,1,1,1,1,1,1,1,1,1,1,1,1,1,1,1,1,1,1,1,1,1,1
1,1,1,1,1,1,1,1,1,1,1,1,1,1,1,1,1,1,1,1,1,1,1,1,1,1,1,1,1,1
1,1,1,1,1,1,1,1,1,1,1,1,1,1,1,1,1,1,1,1,1,1,1,1,1,1,1,1,1,1
1,1,1,1,1,1,1,1,1,1,1,1,1,1,1,1,1,1,1,1,1,1,1,1,1,1,1,1,1,1
1,1,1,1,1,1,1,1,1,1,1,1,1,1,1,1,1,1,1,1,1,1,1,1,1,1,1,1,1,1
1,1,1,1,1,1,1,1,1,1,1,1,1,1,1,1,1,1,1,1,1,1,1,1,1,1,1,1,1,1
1,1,1,1,1,1,1,1,1,1,1,1,1,1,1,1,1,1,1,1,1,1,1,1,1,1,1,1,1,1
1,1,1,1,1,1,1,1,1,1,1,1,1,1,1,1,1,1,1,1,1,1,1,1,1,1,1,1,1,1
1,1,1,1,1,1,1,1,1,1,1,1,1,1,1,1,1,1,1,1,1,1,1,1,1,1,1,1,1,1
1,1,1,1,1,1,1,1,1,1,1,1,1,1,1,1,1,1,1,1,1,1,1,1,1,1,1,1,1,1
1,1,1,1,1,1,1,1,1,1,1,1,1,1,1,1,1,1,1,1,1,1,1,1,1,1,1,1,1,1
endlayer

layer
1,1,1,1,1,1,1,1,1,1,1,1,1,1,1,1,1,1,1,1,1,1,1,1,1,1,1,1,1,1
1,1,1,1,1,1,1,1,1,1,1,1,1,1,1,1,1,1,1,1,1,1,1,1,1,1,1,1,1,1
1,1,1,1,1,1,1,1,1,1,1,1,1,1,1,1,1,1,1,1,1,1,1,1,1,1,1,1,1,1
1,1,1,1,1,1,1,1,1,1,1,1,1,1,1,1,1,1,1,1,1,1,1,1,1,1,1,1,1,1
1,1,1,1,1,1,1,1,1,1,1,1,1,1,1,1,1,1,1,1,1,1,1,1,1,1,1,1,1,1
1,1,1,1,1,1,1,1,1,1,1,1,1,1,1,1,1,1,1,1,1,1,1,1,1,1,1,1,1,1
1,1,1,1,1,1,1,1,1,1,1,1,1,1,1,1,1,1,1,1,1,1,1,1,1,1,1,1,1,1
1,1,1,1,1,1,1,1,1,1,1,1,1,1,1,1,1,1,1,1,1,1,1,1,1,1,1,1,1,1
1,1,1,1,1,1,1,1,1,1,1,1,1,1,2,2,2,2,2,1,1,1,1,1,1,1,1,1,1,1
1,1,1,1,1,1,1,1,1,1,1,1,1,2,0,0,0,0,0,2,1,1,1,1,1,1,1,1,1,1
1,1,1,1,1,1,1,1,1,1,1,1,1,2,7,6,5,4,3,2,1,1,1,1,1,1,1,1,1,1
1,1,1,1,1,1,1,1,1,1,1,1,1,2,9,0,2,6,8,2,1,1,1,1,1,1,1,1,1,1
1,1,1,1,1,1,1,1,1,1,1,1,1,2,11,0,0,0,10,2,1,1,1,1,1,1,1,1,1,1
1,1,1,1,1,1,1,1,1,1,1,1,1,2,16,15,14,13,12,2,1,1,1,1,1,1,1,1,1,1
1,1,1,1,1,1,1,1,1,1,1,1,1,1,2,2,2,2,2,1,1,1,1,1,1,1,1,1,1,1
1,1,1,1,1,1,1,1,1,1,1,1,1,1,1,1,1,1,1,1,1,1,1,1,1,1,1,1,1,1
1,1,1,1,1,1,1,1,1,1,1,1,1,1,1,1,1,1,1,1,1,1,1,1,1,1,1,1,1,1
1,1,1,1,1,1,1,1,1,1,1,1,1,1,1,1,1,1,1,1,1,1,1,1,1,1,1,1,1,1
1,1,1,1,1,1,1,1,1,1,1,1,1,1,1,1,1,1,1,1,1,1,1,1,1,1,1,1,1,1
1,1,1,1,1,1,1,1,1,1,1,1,1,1,1,1,1,1,1,1,1,1,1,1,1,1,1,1,1,1
1,1,1,1,1,1,1,1,1,1,1,1,1,1,1,1,1,1,1,1,1,1,1,1,1,1,1,1,1,1
1,1,1,1,1,1,1,1,1,1,1,1,1,1,1,1,1,1,1,1,1,1,1,1,1,1,1,1,1,1
1,1,1,1,1,1,1,1,1,1,1,1,1,1,1,1,1,1,1,1,1,1,1,1,1,1,1,1,1,1
1,1,1,1,1,1,1,1,1,1,1,1,1,1,1,1,1,1,1,1,1,1,1,1,1,1,1,1,1,1
1,1,1,1,1,1,1,1,1,1,1,1,1,1,1,1,1,1,1,1,1,1,1,1,1,1,1,1,1,1
1,1,1,1,1,1,1,1,1,1,1,1,1,1,1,1,1,1,1,1,1,1,1,1,1,1,1,1,1,1
1,1,1,1,1,1,1,1,1,1,1,1,1,1,1,1,1,1,1,1,1,1,1,1,1,1,1,1,1,1
endlayer

layer
1,1,1,1,1,1,1,1,1,1,1,1,1,1,1,1,1,1,1,1,1,1,1,1,1,1,1,1,1,1
1,1,1,1,1,1,1,1,1,1,1,1,1,1,1,1,1,1,1,1,1,1,1,1,1,1,1,1,1,1
1,1,1,1,1,1,1,1,1,1,1,1,1,1,1,1,1,1,1,1,1,1,1,1,1,1,1,1,1,1
1,1,1,1,1,1,1,1,1,1,1,1,1,1,1,1,1,1,1,1,1,1,1,1,1,1,1,1,1,1
1,1,1,1,1,1,1,1,1,1,1,1,1,1,1,1,1,1,1,1,1,1,1,1,1,1,1,1,1,1
1,1,1,1,1,1,1,1,1,1,1,1,1,1,1,1,1,1,1,1,1,1,1,1,1,1,1,1,1,1
1,1,1,1,1,1,1,1,1,1,1,1,1,1,1,1,1,1,1,1,1,1,1,1,1,1,1,1,1,1
1,1,1,1,1,1,1,1,1,1,1,1,1,1,1,1,1,1,1,1,1,1,1,1,1,1,1,1,1,1
1,1,1,1,1,1,1,1,1,1,1,1,1,1,2,2,2,2,2,1,1,1,1,1,1,1,1,1,1,1
1,1,1,1,1,1,1,1,1,1,1,1,1,2,0,0,0,0,0,2,1,1,1,1,1,1,1,1,1,1
1,1,1,1,1,1,1,1,1,1,1,1,1,2,0,0,0,0,0,2,1,1,1,1,1,1,1,1,1,1
1,1,1,1,1,1,1,1,1,1,1,0,1,2,0,0,0,0,0,2,1,1,1,1,1,1,1,1,1,1
1,1,1,1,1,1,1,1,1,1,1,1,1,2,0,0,0,0,0,2,1,1,1,1,1,1,1,1,1,1
1,1,1,1,1,1,1,1,1,1,1,1,1,2,0,16,16,0,0,2,1,1,1,1,1,1,1,1,1,1
1,1,1,1,1,1,1,1,1,1,1,1,1,1,2,2,2,2,2,1,1,1,1,1,1,1,1,1,1,1
1,1,1,1,1,1,1,1,1,1,1,1,1,1,1,1,1,1,1,1,1,1,1,1,1,1,1,1,1,1
1,1,1,1,1,1,1,1,1,1,1,1,1,1,1,1,1,1,1,1,1,1,0,1,1,1,1,1,1,1
1,1,1,1,1,1,1,1,1,1,1,1,1,1,1,1,1,1,1,1,1,1,0,1,1,1,1,1,1,1
1,1,1,1,1,1,1,1,1,1,1,1,1,1,1,1,1,1,1,1,1,1,1,1,1,1,1,1,1,1
1,1,1,1,1,1,1,1,1,1,1,1,1,1,1,1,1,1,1,1,1,1,1,1,1,1,1,1,1,1
1,1,1,1,1,1,1,1,1,1,1,1,1,1,1,1,1,1,1,1,1,1,1,1,1,1,1,1,1,1
1,1,1,1,1,1,1,1,1,1,1,1,1,1,1,1,1,1,1,1,1,1,1,1,1,1,1,1,1,1
1,1,1,1,1,1,1,1,1,1,1,1,1,1,1,1,1,1,1,1,1,1,1,1,1,1,1,1,1,1
1,1,1,1,1,0,1,1,1,1,1,1,1,1,1,1,1,1,1,1,1,1,1,1,1,1,1,1,1,1
1,1,1,1,1,1,1,1,1,1,1,1,1,1,1,1,1,1,1,1,1,1,1,1,1,1,1,1,1,1
1,1,1,1,1,1,1,1,1,1,1,1,1,1,1,1,1,1,1,1,1,1,1,1,1,1,1,1,1,1
1,1,1,1,1,1,1,1,1,1,1,1,1,1,1,1,1,1,1,1,1,1,1,1,1,1,1,1,1,1
endlayer

layer
1,1,1,1,1,1,1,1,1,1,1,1,1,1,1,1,1,1,1,1,1,1,1,1,1,1,1,1,1,1
1,1,1,1,1,1,1,1,1,1,1,1,1,1,1,1,1,1,1,1,1,1,1,1,1,1,1,1,1,1
1,1,1,1,1,1,1,1,1,1,1,1,1,1,1,1,1,1,1,1,1,1,1,1,1,1,1,1,1,1
1,1,1,1,1,1,1,1,1,1,1,1,1,1,1,1,1,1,1,1,1,1,1,1,1,1,1,1,1,1
1,1,1,1,1,1,1,1,1,1,1,1,1,1,1,1,1,1,1,1,1,1,1,1,1,1,1,1,1,1
1,1,1,1,1,1,1,1,1,1,1,1,1,1,1,1,1,1,1,1,1,1,1,1,1,1,1,1,1,1
1,1,1,1,1,1,1,1,1,1,1,1,1,1,1,1,1,1,1,1,1,1,1,1,1,1,1,1,1,1
1,1,1,1,1,1,1,1,1,1,1,1,1,1,1,1,1,1,1,1,1,1,1,1,1,1,1,1,1,1
1,1,1,1,1,1,1,1,1,1,1,1,1,1,1,1,1,1,1,1,1,1,1,1,1,1,1,1,1,1
1,1,1,1,1,1,1,1,1,1,1,1,1,1,2,2,2,2,2,1,1,1,1,1,1,1,1,1,1,1
1,1,1,1,1,1,1,1,1,1,1,1,1,1,2,2,2,2,2,1,1,1,1,1,1,1,1,1,1,1
1,1,1,1,1,1,1,1,1,1,1,1,1,1,2,2,2,2,2,1,1,1,1,1,1,1,1,1,1,1
1,1,1,1,1,1,1,1,1,1,1,1,1,1,2,2,2,2,2,1,1,1,1,1,1,1,1,1,1,1
1,1,1,1,1,1,1,1,1,1,1,1,1,1,2,2,2,2,2,1,1,1,1,1,1,1,1,1,1,1
1,1,1,1,1,1,1,1,1,1,1,1,1,1,1,1,1,1,1,1,1,1,1,1,1,1,1,1,1,1
1,1,1,1,1,1,1,1,1,1,1,1,1,1,1,1,1,1,1,1,1,1,1,1,1,1,1,1,1,1
1,1,1,1,1,1,1,1,1,1,1,1,1,1,1,1,1,1,1,1,1,1,1,1,1,1,1,1,1,1
1,1,1,1,1,1,1,1,1,1,1,1,1,1,1,1,1,1,1,1,1,1,1,1,1,1,1,1,1,1
1,1,1,1,1,1,1,1,1,1,1,1,1,1,1,1,1,1,1,1,1,1,1,1,1,1,1,1,1,1
1,1,1,1,1,1,1,1,1,1,1,1,1,1,1,1,1,1,1,1,1,1,1,1,1,1,1,1,1,1
1,1,1,1,1,1,1,1,1,1,1,1,1,1,1,1,1,1,1,1,1,1,1,1,1,1,1,1,1,1
1,1,1,1,1,1,1,1,1,1,1,1,1,1,1,1,1,1,1,1,1,1,1,1,1,1,1,1,1,1
1,1,1,1,1,1,1,1,1,1,1,1,1,1,1,1,1,1,1,1,1,1,1,1,1,1,1,1,1,1
1,1,1,1,1,1,1,1,1,1,1,1,1,1,1,1,1,1,1,1,1,1,1,1,1,1,1,1,1,1
1,1,1,1,1,1,1,1,1,1,1,1,1,1,1,1,1,1,1,1,1,1,1,1,1,1,1,1,1,1
1,1,1,1,1,1,1,1,1,1,1,1,1,1,1,1,1,1,1,1,1,1,1,1,1,1,1,1,1,1
1,1,1,1,1,1,1,1,1,1,1,1,1,1,1,1,1,1,1,1,1,1,1,1,1,1,1,1,1,1
endlayer

layer
1,1,1,1,1,1,1,1,1,1,1,1,1,1,1,1,1,1,1,1,1,1,1,1,1,1,1,1,1,1
1,1,1,1,1,1,1,1,1,1,1,17,1,1,1,1,1,1,1,1,1,1,1,1,1,1,1,1,1,1
1,1,1,1,1,1,1,1,1,1,1,17,17,1,1,1,1,1,1,17,1,1,1,1,1,1,1,1,1,1
1,1,1,1,1,1,1,1,1,17,17,17,17,1,17,1,1,17,1,17,17,1,17,17,1,1,1,1,1,1
1,1,1,1,1,1,17,1,17,1,17,17,1,17,17,17,17,17,17,17,17,17,17,17,17,1,1,1,1,1
1,1,1,1,1,1,1,17,17,17,17,17,17,17,17,17,17,17,17,17,17,17,17,17,17,17,17,1,1,1
1,1,1,1,1,1,1,17,17,17,17,17,17,17,17,17,17,17,17,17,17,17,17,17,17,1,17,17,1,1
1,1,1,1,1,1,1,1,17,17,17,17,17,18,18,18,17,17,17,17,17,17,17,17,17,17,17,17,17,1
1,1,1,1,1,1,1,17,17,17,17,17,18,18,18,18,18,17,17,17,17,17,17,17,17,17,17,17,1,1
1,1,1,1,1,1,17,17,17,17,17,17,18,18,18,18,18,18,17,17,17,17,17,17,17,17,17,1,1,1
1,1,1,17,17,17,17,17,17,17,17,18,18,18,18,18,18,18,18,18,17,17,18,17,17,17,17,17,17,1
1,1,1,1,17,17,17,17,17,17,18,18,18,18,18,18,18,18,18,18,18,18,17,17,17,17,17,17,1,1
1,1,1,1,1,17,17,17,17,18,18,18,18,18,18,18,18,18,18,18,18,18,17,17,17,17,17,1,1,1
1,1,1,1,17,17,17,17,17,17,18,17,18,18,18,17,18,18,18,18,18,17,17,17,17,1,17,17,1,1
1,1,1,1,1,1,17,17,17,18,18,18,18,18,18,18,18,18,18,18,18,17,17,17,17,17,1,1,1,1
1,1,1,1,1,17,17,17,17,17,18,18,18,18,18,18,18,18,18,18,18,17,17,17,17,17,1,1,1,1
1,1,1,1,17,17,17,17,17,17,17,18,18,18,18,18,18,18,18,18,18,17,17,17,17,17,17,1,1,1
1,1,1,1,1,17,17,17,17,17,17,17,18,18,18,18,18,17,18,17,18,17,17,17,17,1,17,17,1,1
1,1,1,1,17,1,1,17,17,17,17,17,17,18,17,18,17,17,17,18,18,17,17,17,17,1,1,1,1,1
1,1,1,1,1,1,17,17,17,17,17,17,17,17,18,17,17,17,17,17,18,17,17,17,17,17,1,1,1,1
1,1,1,1,1,17,17,17,17,17,17,17,17,17,17,17,17,17,17,17,17,17,17,17,17,17,17,1,1,1
1,1,1,1,1,1,17,17,17,17,17,17,17,17,17,17,17,17,17,17,17,17,17,17,17,1,17,17,1,1
1,1,1,1,1,1,1,17,17,17,17,17,17,17,17,17,17,17,17,1,17,17,1,1,1,1,1,1,1,1
1,1,1,1,1,1,1,1,17,17,1,17,17,17,17,17,17,17,1,1,1,17,1,1,1,1,1,1,1,1
1,1,1,1,1,1,1,1,1,17,1,1,1,17,17,1,17,1,1,1,1,1,1,1,1,1,1,1,1,1
1,1,1,1,1,1,1,1,1,1,1,1,1,1,17,1,1,1,1,1,1,1,1,1,1,1,1,1,1,1
1,1,1,1,1,1,1,1,1,1,1,1,1,1,1,1,1,1,1,1,1,1,1,1,1,1,1,1,1,1
endlayer

layer
0,0,0,0,0,0,19,0,0,0,0,0,19,0,0,0,0,0,0,0,0,0,19,0,0,19,0,0,0,0
0,0,0,0,0,0,0,0,0,0,0,0,0,0,0,0,0,0,0,0,0,0,0,0,0,0,0,0,0,0
0,0,0,0,0,0,0,0,19,19,0,0,0,0,0,0,0,0,0,0,0,19,0,0,0,0,0,0,19,19
0,0,19,19,0,19,19,19,0,0,0,0,0,0,0,0,0,0,0,0,0,0,0,0,0,19,0,0,0,19
0,19,0,0,19,0,0,0,0,0,0,0,0,0,0,0,0,0,0,0,0,0,0,0,0,0,0,0,0,0
0,0,0,0,0,0,0,0,0,0,0,0,0,0,0,0,0,0,0,0,0,0,20,0,0,0,19,0,0,0
0,0,0,0,19,0,0,0,25,20,23,27,26,22,25,0,24,20,0,23,22,0,0,21,0,0,19,0,0,0
19,0,0,0,19,0,0,0,21,20,20,28,0,29,29,29,27,0,0,28,25,26,20,20,0,0,0,0,0,0
0,0,0,0,0,0,0,0,0,24,22,25,29,29,29,29,29,21,29,30,0,20,20,22,0,0,0,19,0,0
0,0,0,0,0,0,0,0,32,26,0,29,29,29,31,31,29,29,0,29,27,24,23,0,0,0,0,0,0,19
19,0,0,0,0,0,0,0,27,30,29,29,29,31,31,31,31,31,31,31,29,0,29,25,0,0,0,0,0,0
0,0,0,0,0,0,0,0,25,29,29,29,29,31,31,31,31,31,31,31,31,29,0,26,0,0,0,0,0,0
0,0,0,0,0,0,0,0,26,29,29,29,31,31,31,31,31,31,31,31,31,29,24,27,0,0,0,0,0,0
0,0,0,0,0,0,0,0,28,24,29,0,31,31,31,33,31,31,31,31,29,0,28,22,0,0,0,0,0,0
0,0,0,0,0,0,0,20,22,29,29,29,29,31,31,31,31,31,31,31,29,25,26,0,0,0,0,0,19,19
19,0,34,0,0,0,0,0,20,23,29,29,29,31,31,31,31,31,31,31,29,0,29,21,0,0,0,0,19,0
0,0,0,0,0,0,0,0,0,25,29,29,29,31,31,31,31,31,31,31,29,29,30,0,0,0,0,0,0,0
0,0,0,0,0,0,0,20,21,27,0,29,29,29,29,29,29,29,29,0,29,29,25,22,0,0,0,0,0,0
0,19,0,0,0,0,0,0,22,26,22,30,29,29,23,29,29,22,29,29,29,29,28,32,0,0,0,0,0,0
0,0,0,0,0,0,0,0,0,23,20,0,27,22,29,29,30,21,20,29,29,23,26,27,0,0,0,0,0,0
0,0,19,0,0,0,0,0,25,0,32,21,0,25,24,26,27,25,23,32,22,21,24,28,0,0,0,0,0,0
0,0,0,0,0,0,0,0,0,0,0,0,0,0,0,0,0,0,0,0,0,0,0,0,0,0,19,19,0,0
0,0,0,0,19,0,0,0,0,0,0,0,0,0,0,0,0,0,0,0,0,0,0,0,0,0,19,0,19,0
19,0,19,0,0,0,19,0,0,0,0,0,0,0,0,0,0,0,0,0,0,0,0,0,0,0,0,19,0,0
0,0,0,0,0,0,0,0,0,0,0,0,0,0,0,0,0,0,0,0,0,0,0,0,0,0,0,0,19,19
0,0,0,0,0,0,0,0,0,0,35,0,0,0,0,0,0,0,0,0,0,0,0,19,0,0,0,0,0,0
0,0,0,0,0,0,0,0,0,0,0,0,0,0,19,0,0,0,0,0,0,0,0,0,0,0,0,19,0,0
endlayer

layer
0,0,0,0,0,0,0,0,0,0,0,0,0,36,0,0,0,0,0,0,0,0,0,0,0,0,0,0,0,0
0,0,0,0,0,0,0,0,0,0,0,0,0,0,0,0,0,0,0,0,0,0,0,0,0,0,0,0,0,0
0,0,0,0,0,0,0,0,0,0,0,0,0,0,0,0,0,0,0,0,0,0,0,0,0,0,0,0,0,0
0,0,0,0,0,0,0,0,0,0,0,0,0,0,0,0,0,0,0,0,0,0,0,0,0,0,0,0,0,0
0,0,0,0,0,0,0,0,0,0,0,0,0,0,0,0,0,0,0,0,0,0,0,0,0,0,0,0,0,0
0,0,0,0,0,0,0,0,0,0,0,0,0,0,0,0,0,0,0,0,0,0,0,0,0,37,0,0,0,0
0,0,0,0,0,0,0,0,0,0,0,0,0,0,0,0,0,0,0,0,0,0,0,0,0,0,0,0,0,0
0,0,0,0,0,0,0,0,0,0,0,0,0,0,0,0,0,0,0,0,0,0,0,0,0,0,0,0,0,0
0,0,0,0,0,0,0,0,0,0,0,0,0,29,31,0,0,0,0,0,0,0,0,0,0,0,0,0,0,0
0,0,0,0,0,0,0,0,0,0,0,0,29,29,31,29,29,31,29,0,0,0,0,0,0,0,0,0,0,0
0,0,0,0,0,0,0,0,0,0,0,31,29,31,31,31,31,31,29,29,0,0,0,0,0,0,0,0,38,0
0,0,0,0,0,0,0,0,0,0,0,29,31,31,31,31,31,31,31,31,31,0,0,0,0,0,0,0,0,0
0,0,0,0,0,0,0,0,0,0,29,29,31,31,31,31,31,31,31,31,29,0,0,0,0,0,0,0,0,0
0,0,0,0,0,0,0,0,0,0,0,29,31,31,31,33,31,31,31,31,29,0,0,0,0,0,0,0,0,0
0,0,0,0,0,0,0,0,0,0,0,29,31,31,31,31,31,31,31,29,0,0,0,0,0,0,0,0,0,0
0,0,34,0,0,0,0,0,0,0,0,29,31,31,31,31,31,31,31,29,29,0,0,0,0,0,0,0,0,0
0,0,0,0,0,0,0,0,0,0,0,0,31,31,31,31,31,31,29,29,29,0,0,0,0,0,0,0,0,0
0,0,0,0,0,0,0,0,0,0,0,0,29,29,29,29,29,29,29,31,29,29,0,0,0,0,0,0,0,0
0,0,0,0,0,0,0,0,0,0,0,0,0,29,0,0,0,0,0,0,29,0,0,0,0,0,0,0,0,0
0,0,0,0,0,0,0,0,0,0,0,0,0,0,0,0,0,0,0,0,0,0,0,0,0,0,0,0,0,0
0,0,0,0,0,0,0,0,0,0,0,0,0,0,0,0,0,0,0,0,0,0,0,0,0,0,0,0,0,0
0,0,0,0,0,0,0,0,0,0,0,0,0,0,0,0,0,0,0,0,0,0,0,0,0,0,0,0,0,0
0,0,0,0,0,0,0,0,0,0,0,0,0,0,0,0,0,0,0,0,0,0,0,0,0,0,0,0,0,0
0,0,0,0,0,0,0,0,0,0,0,0,0,0,0,0,0,0,0,0,0,0,0,0,0,0,0,0,0,0
0,0,0,0,0,0,0,0,0,0,0,0,0,0,0,0,0,0,0,0,0,0,0,0,0,0,0,0,0,0
0,0,0,0,0,0,0,0,0,0,35,0,0,0,0,0,0,0,0,0,0,0,0,0,0,0,0,0,0,0
0,0,0,0,0,0,0,0,0,0,0,0,0,0,0,0,0,0,0,0,0,0,0,0,0,0,0,0,0,0
endlayer

layer
0,0,0,0,0,0,0,0,0,0,0,0,0,36,0,0,0,0,0,0,0,0,0,0,0,0,0,0,0,0
0,0,0,0,0,0,0,0,0,0,0,0,0,0,0,0,0,0,0,0,0,0,0,0,0,0,0,0,0,0
0,0,0,0,0,0,0,0,0,0,0,0,0,0,0,0,0,0,0,0,0,0,0,0,0,0,0,0,0,0
0,0,0,0,0,0,0,0,0,0,0,0,0,0,0,0,0,0,0,0,0,0,0,0,0,0,0,0,0,0
0,0,0,0,0,0,0,0,0,0,0,0,0,0,0,0,0,0,0,0,0,0,0,0,0,0,0,0,0,0
0,0,0,0,0,0,0,0,0,0,0,0,0,0,0,0,0,0,0,0,0,0,0,0,0,37,0,0,0,0
0,0,0,0,0,0,0,0,0,0,0,0,0,0,0,0,0,0,0,0,0,0,0,0,0,0,0,0,0,0
0,0,0,0,0,0,0,0,0,0,0,0,0,0,0,0,0,0,0,0,0,0,0,0,0,0,0,0,0,0
0,0,0,0,0,0,0,0,0,0,0,0,0,0,31,0,0,0,0,0,0,0,0,0,0,0,0,0,0,0
0,0,0,0,0,0,0,0,0,0,0,0,0,31,31,31,29,31,31,0,0,0,0,0,0,0,0,0,0,0
0,0,0,0,0,0,0,0,0,0,0,31,31,31,31,31,31,31,31,29,0,0,0,0,0,0,0,0,38,0
0,0,0,0,0,0,0,0,0,0,0,31,31,31,31,31,31,31,31,29,31,0,0,0,0,0,0,0,0,0
0,0,0,0,0,0,0,0,0,0,0,29,31,31,31,31,31,31,31,31,0,0,0,0,0,0,0,0,0,0
0,0,0,0,0,0,0,0,0,0,29,29,31,31,31,33,31,31,31,29,0,0,0,0,0,0,0,0,0,0
0,0,0,0,0,0,0,0,0,0,0,29,31,31,31,31,31,31,31,29,0,0,0,0,0,0,0,0,0,0
0,0,34,0,0,0,0,0,0,0,0,31,31,31,31,31,31,31,31,29,29,0,0,0,0,0,0,0,0,0
0,0,0,0,0,0,0,0,0,0,0,0,31,31,31,31,31,29,31,29,0,0,0,0,0,0,0,0,0,0
0,0,0,0,0,0,0,0,0,0,0,0,0,29,31,29,29,29,0,31,29,0,0,0,0,0,0,0,0,0
0,0,0,0,0,0,0,0,0,0,0,0,0,0,31,0,29,0,0,0,0,0,0,0,0,0,0,0,0,0
0,0,0,0,0,0,0,0,0,0,0,0,0,0,0,0,0,0,0,0,0,0,0,0,0,0,0,0,0,0
0,0,0,0,0,0,0,0,0,0,0,0,0,0,0,0,0,0,0,0,0,0,0,0,0,0,0,0,0,0
0,0,0,0,0,0,0,0,0,0,0,0,0,0,0,0,0,0,0,0,0,0,0,0,0,0,0,0,0,0
0,0,0,0,0,0,0,0,0,0,0,0,0,0,0,0,0,0,0,0,0,0,0,0,0,0,0,0,0,0
0,0,0,0,0,0,0,0,0,0,0,0,0,0,0,0,0,0,0,0,0,0,0,0,0,0,0,0,0,0
0,0,0,0,0,0,0,0,0,0,0,0,0,0,0,0,0,0,0,0,0,0,0,0,0,0,0,0,0,0
0,0,0,0,0,0,0,0,0,0,35,0,0,0,0,0,0,0,0,0,0,0,0,0,0,0,0,0,0,0
0,0,0,0,0,0,0,0,0,0,0,0,0,0,0,0,35,0,0,0,0,0,0,0,0,0,0,0,0,0
endlayer

layer
0,0,0,0,0,0,0,0,0,0,0,0,0,36,0,0,0,0,0,0,0,0,0,0,0,0,0,0,0,0
0,0,0,0,0,0,0,0,0,0,0,0,0,0,0,0,0,0,0,0,0,0,0,0,0,0,0,0,0,0
0,0,0,0,0,0,0,0,0,0,0,0,0,0,0,0,0,0,0,0,0,0,0,0,0,0,0,0,0,0
0,0,0,0,0,0,0,0,0,0,0,0,0,0,0,0,0,0,0,0,0,0,0,0,0,0,0,0,0,0
0,0,0,0,0,0,0,0,0,0,0,0,0,0,0,0,0,0,0,0,0,0,0,0,0,0,0,0,0,0
0,0,0,0,0,0,0,0,0,0,0,0,0,0,0,0,0,0,0,0,0,0,0,0,0,37,0,0,0,0
0,0,0,0,34,0,0,0,0,0,0,0,0,0,0,0,0,0,0,0,0,0,0,0,0,0,0,0,0,0
0,0,0,0,0,0,0,0,0,0,0,0,0,0,0,0,0,0,0,0,0,0,0,0,0,0,0,0,0,0
0,0,0,0,0,0,0,0,0,0,0,0,0,0,0,0,31,0,0,0,0,0,0,0,0,0,0,0,0,0
0,0,0,0,0,0,0,0,0,0,0,0,0,31,31,31,31,31,31,0,0,0,0,0,0,0,0,0,0,0
0,0,0,0,0,0,0,0,0,0,0,31,31,31,31,31,31,31,31,0,0,0,0,0,0,0,0,0,38,0
0,0,0,0,0,0,0,0,0,0,0,31,31,31,31,31,31,31,31,31,31,0,0,0,0,0,0,0,0,0
0,0,0,0,0,0,0,0,0,0,0,31,31,31,31,31,31,31,31,31,0,0,0,0,0,0,0,0,0,0
0,0,0,0,0,0,0,0,0,0,29,29,31,31,31,33,31,31,31,29,0,0,0,0,0,0,0,0,0,0
0,0,0,0,0,0,0,0,0,0,29,29,31,31,31,31,31,31,31,31,0,0,0,0,0,0,0,0,0,0
0,0,34,0,0,0,0,0,0,0,0,31,31,31,31,31,31,31,31,31,0,0,0,0,0,0,0,0,0,0
0,0,0,0,0,0,0,0,0,0,0,0,31,31,31,31,31,29,31,29,0,0,0,0,0,0,0,0,0,0
0,0,0,0,0,0,0,0,0,0,0,0,0,31,31,29,29,0,31,31,0,0,0,0,0,0,0,0,0,0
0,0,0,0,0,0,0,0,0,0,0,0,0,0,31,0,29,0,31,0,0,0,0,0,0,0,0,0,0,0
0,0,0,0,0,0,0,0,0,0,0,0,0,0,0,0,0,0,0,0,0,0,0,0,0,0,0,0,0,0
0,0,0,0,0,0,0,0,0,0,0,0,0,0,0,0,0,0,0,0,0,0,0,0,0,0,0,0,0,0
0,0,0,0,0,0,0,0,0,0,0,0,0,0,0,0,0,0,0,0,0,0,0,0,0,0,0,0,0,0
0,0,0,0,0,0,0,0,0,0,0,0,0,0,0,0,0,0,0,0,0,0,0,0,0,0,0,0,0,0
0,0,0,0,0,0,0,0,0,0,0,0,0,0,0,0,0,0,0,0,0,0,0,0,0,0,0,0,0,0
0,0,0,0,0,0,0,0,0,0,0,0,0,0,0,0,0,0,0,0,0,0,0,0,0,0,0,0,0,0
0,0,0,0,0,0,0,0,0,0,35,34,0,0,0,0,0,0,0,0,0,0,0,0,0,0,0,0,0,0
0,0,0,0,0,0,0,0,0,0,0,0,0,0,0,0,35,0,0,0,0,0,0,0,0,0,0,0,0,0
endlayer

layer
0,0,0,0,0,0,0,0,0,0,0,0,0,36,0,0,0,0,0,0,0,0,0,0,0,0,0,0,0,0
0,0,0,0,0,0,0,0,0,0,0,0,0,0,0,0,0,0,0,38,0,0,0,0,0,0,0,0,0,0
0,0,0,0,0,0,0,0,0,0,0,0,0,0,0,0,0,0,0,0,0,0,0,0,0,0,0,0,0,0
0,0,0,0,0,0,0,0,0,0,0,0,0,0,0,0,0,0,0,0,0,0,0,0,0,0,0,0,0,0
0,0,0,0,0,0,0,0,0,0,0,0,0,0,0,0,0,0,0,0,0,0,0,0,0,0,0,0,0,0
0,0,0,0,0,0,0,0,0,0,0,0,0,0,0,0,0,0,0,0,0,0,0,0,0,37,0,0,0,0
0,0,0,0,34,0,0,0,0,0,0,0,0,0,0,0,0,0,0,0,0,0,0,0,0,0,0,0,0,0
0,0,0,0,0,0,0,0,0,0,0,0,0,0,0,0,0,0,0,0,0,0,0,0,0,0,0,0,0,0
0,0,0,0,0,0,0,0,0,0,0,0,0,0,0,0,31,0,0,0,0,0,0,0,0,0,0,0,0,0
0,0,0,0,0,0,0,0,0,0,0,0,0,0,31,29,31,31,31,0,0,0,0,0,0,0,0,0,0,0
0,0,0,0,0,0,0,0,0,0,0,0,31,31,31,31,31,31,31,0,0,0,0,0,0,0,0,0,38,0
0,0,0,0,0,0,0,0,0,0,0,31,31,31,31,31,31,31,31,31,0,0,0,0,0,0,0,0,0,0
0,0,0,0,0,0,0,0,0,0,0,31,31,31,31,31,31,31,31,31,0,0,0,0,0,0,0,0,0,0
0,0,34,0,0,0,0,0,0,0,29,29,31,31,31,33,31,31,29,39,0,0,0,0,0,0,0,0,0,0
0,0,0,0,0,0,0,0,0,0,0,31,31,31,31,31,31,31,31,31,0,0,0,0,0,0,0,0,0,0
0,0,34,0,0,0,0,0,0,0,0,0,31,29,31,31,31,31,31,31,0,0,0,0,0,0,0,0,0,0
0,0,0,0,0,0,0,0,0,0,0,0,0,29,31,29,29,0,31,0,0,0,0,0,0,0,0,0,0,0
0,0,0,0,0,0,0,0,0,0,0,0,0,31,31,29,29,31,31,31,0,0,0,0,0,0,0,0,0,0
0,0,0,0,0,0,0,0,0,0,0,0,0,0,31,0,0,0,31,0,0,0,0,0,0,0,0,0,0,0
0,0,0,0,0,0,0,0,0,0,0,0,0,0,0,0,0,0,0,0,0,0,0,0,0,0,0,0,0,0
0,0,0,0,0,0,0,0,0,0,0,0,0,0,0,0,0,0,0,0,0,0,0,0,0,0,0,0,0,0
0,0,0,0,0,0,0,0,0,0,0,0,0,0,0,0,0,0,0,0,0,0,0,0,0,0,0,0,0,0
0,0,0,0,0,0,0,0,0,0,0,0,0,0,0,0,0,0,0,0,0,0,0,0,0,0,0,0,0,0
0,0,0,0,0,0,0,0,0,0,0,0,0,0,0,0,0,0,0,0,0,0,0,0,0,0,0,0,0,0
0,0,0,0,0,0,0,0,0,0,0,0,0,0,0,0,0,0,0,0,0,0,0,0,0,0,0,0,0,0
0,0,0,0,0,0,0,0,0,0,35,34,0,0,0,0,0,0,0,0,0,0,0,0,0,0,0,0,0,0
0,0,0,0,0,0,0,0,0,0,0,0,0,0,0,0,35,0,0,0,0,0,0,0,0,0,0,0,0,0
endlayer

layer
0,0,0,0,0,0,0,0,0,0,0,0,0,36,0,0,0,0,0,0,0,0,0,0,0,0,0,0,0,0
0,0,0,0,0,0,0,0,0,0,0,0,0,0,0,0,0,0,0,38,0,0,0,0,0,0,0,0,0,0
0,0,0,0,0,0,0,0,0,0,0,0,0,0,0,0,0,0,0,0,0,38,0,0,0,0,0,0,0,0
0,0,0,0,0,0,0,0,0,0,0,0,0,0,0,0,0,0,0,0,0,0,0,0,0,0,0,0,0,0
0,0,0,0,0,0,0,0,0,0,0,0,0,0,0,0,0,0,0,0,0,0,0,0,0,0,0,0,0,0
0,0,0,0,0,0,0,0,0,0,0,0,0,0,0,0,0,0,0,0,0,0,0,0,0,37,0,0,0,0
0,0,0,0,34,0,0,0,0,0,0,0,0,0,0,0,0,0,0,0,0,0,0,0,0,0,0,0,0,0
0,0,0,0,0,0,0,0,0,0,0,0,0,0,0,0,0,0,0,0,0,0,0,0,0,0,0,0,0,0
0,0,0,0,0,0,0,0,0,0,0,0,0,0,0,0,0,0,0,0,0,0,0,0,0,0,0,0,0,0
0,0,0,0,0,0,0,0,0,0,0,0,0,0,0,29,29,31,0,0,0,0,0,0,0,0,0,0,0,0
0,0,0,0,0,0,0,0,0,0,0,0,29,29,31,31,31,29,31,31,0,0,0,0,0,0,0,0,38,0
0,0,0,0,0,0,0,0,0,0,0,0,29,31,31,31,31,31,31,31,0,0,0,0,0,0,0,0,38,0
0,0,0,0,0,0,0,0,0,0,0,31,31,31,0,31,31,31,29,0,0,0,0,0,0,0,0,0,0,0
0,0,34,0,0,0,0,0,0,0,0,0,29,0,0,33,31,31,29,0,0,0,0,0,0,0,0,0,0,0
0,0,34,0,0,0,0,0,0,0,0,31,29,31,0,0,31,31,29,0,0,0,0,0,0,0,0,0,0,0
0,0,34,0,0,0,0,0,0,0,0,0,0,29,31,31,31,31,31,31,0,0,0,0,0,0,0,0,0,0
0,0,0,0,0,0,0,0,0,0,0,0,0,29,29,29,31,29,31,0,0,0,0,0,0,0,0,0,0,0
0,0,0,0,0,0,0,0,0,0,0,0,0,31,29,29,0,0,31,0,0,0,0,0,0,0,0,0,0,0
0,0,0,0,0,0,0,0,0,0,0,0,0,0,0,0,0,0,0,0,0,0,0,0,0,0,0,0,0,0
0,0,0,0,0,0,0,0,0,0,0,0,0,0,0,0,0,0,0,0,0,0,0,0,0,0,0,0,0,0
0,0,0,0,0,0,0,0,0,0,0,0,0,0,0,0,0,0,0,0,0,0,0,0,0,0,0,0,0,0
0,0,0,0,0,0,0,0,0,0,0,0,0,0,0,0,0,0,0,0,0,0,0,0,0,0,0,0,0,0
0,0,0,0,0,0,0,0,0,0,0,0,0,0,0,0,0,0,0,0,0,0,0,0,0,0,0,0,0,0
0,0,0,0,0,0,0,0,0,0,0,0,0,0,0,0,0,0,0,0,0,0,0,0,0,0,0,0,0,0
0,0,0,0,0,0,0,0,0,34,0,0,0,0,0,0,0,0,0,0,0,35,0,0,0,0,0,0,0,0
0,0,0,0,0,0,0,0,0,0,35,34,0,0,0,0,0,0,0,0,0,0,0,0,0,0,0,0,0,0
0,0,0,0,0,0,0,0,0,0,0,0,0,0,35,0,35,0,0,0,0,0,0,0,0,0,0,0,0,0
endlayer

layer
0,0,0,0,0,0,0,0,0,0,0,0,0,36,0,0,0,0,0,0,0,0,0,0,0,0,0,0,0,0
0,0,0,0,0,0,0,0,0,0,0,0,0,0,0,0,0,0,0,38,0,0,0,0,0,0,0,0,0,0
0,0,0,0,0,0,0,0,0,0,0,0,0,0,0,0,0,0,0,0,0,37,0,0,0,0,0,0,0,0
0,0,0,0,0,0,0,0,0,0,0,0,0,0,0,0,0,0,0,0,0,0,0,0,0,0,0,0,0,0
0,0,0,0,0,0,0,0,0,0,0,0,0,0,0,0,0,0,0,0,0,0,0,0,38,0,0,0,0,0
0,0,0,0,0,0,0,0,0,0,0,0,0,0,0,0,0,0,0,0,0,0,0,0,0,37,0,0,0,0
0,0,0,0,34,0,0,0,0,0,0,0,0,0,0,0,0,0,0,0,0,0,0,0,0,0,0,0,0,0
0,0,0,0,0,0,0,0,0,0,0,0,0,0,0,0,0,0,0,0,0,0,0,0,0,0,0,0,0,0
0,0,0,0,0,0,0,0,0,0,0,0,0,0,0,0,0,0,0,0,0,0,0,0,0,0,0,38,0,0
0,0,0,0,0,0,0,0,0,0,0,0,0,0,0,29,31,0,0,0,0,0,0,0,0,0,0,0,0,0
0,0,0,0,0,0,0,0,0,0,0,0,0,0,31,29,29,29,31,0,0,0,0,0,0,0,0,0,38,0
0,0,0,0,0,0,0,0,0,0,0,0,0,31,0,0,0,31,29,0,0,0,0,0,0,0,0,0,38,0
0,0,0,0,0,0,0,0,0,0,0,0,29,0,0,31,0,31,29,0,0,0,0,0,0,0,0,0,0,0
0,0,34,0,0,0,0,0,0,0,0,0,29,0,0,33,0,31,31,0,0,0,0,0,0,0,0,0,0,0
0,0,34,0,0,0,0,0,0,0,0,0,31,31,0,0,0,0,29,0,0,0,0,0,0,0,0,0,0,0
0,0,34,0,0,0,0,0,0,0,0,0,0,31,31,0,0,31,29,0,0,0,0,0,0,0,0,0,0,0
0,0,0,0,0,0,0,0,0,0,0,0,0,29,29,31,31,29,31,0,0,0,0,0,0,0,0,0,0,0
0,0,0,0,0,0,0,0,0,0,0,0,0,0,29,0,0,0,0,0,0,0,0,0,0,0,0,0,0,0
0,0,0,34,0,0,0,0,0,0,0,0,0,0,0,0,0,0,0,0,0,0,0,0,0,0,0,0,0,0
0,0,0,0,0,0,0,0,0,0,0,0,0,0,0,0,0,0,0,0,0,0,0,0,0,0,0,0,0,0
0,0,0,0,0,0,0,0,0,0,0,0,0,0,0,0,0,0,0,0,0,0,0,0,0,0,0,0,0,0
0,0,0,0,0,0,0,0,0,0,0,0,0,0,0,0,0,0,0,0,0,0,0,0,0,0,0,0,0,0
0,0,0,0,0,0,0,0,0,0,0,0,0,0,0,0,0,0,0,0,0,0,0,0,0,0,0,0,0,0
0,0,0,0,0,0,0,0,0,0,0,0,0,0,0,0,0,0,0,0,0,0,0,0,0,0,0,0,0,0
0,0,0,0,0,0,0,0,0,34,0,0,0,0,0,0,0,0,0,0,0,35,0,0,0,0,0,0,0,0
0,0,0,0,0,0,0,0,0,0,35,34,0,0,0,0,0,0,0,0,0,0,0,0,0,0,0,0,0,0
0,0,0,0,0,0,0,0,0,0,0,0,0,0,35,0,35,0,35,0,0,0,0,0,0,0,0,0,0,0
endlayer

layer
0,0,0,0,0,0,0,0,0,0,0,0,0,36,0,0,36,0,0,0,0,0,0,0,0,0,0,0,0,0
0,0,0,0,0,0,0,0,0,0,0,0,0,0,0,0,0,0,0,38,0,0,0,0,0,0,0,0,0,0
0,0,0,0,0,0,0,0,0,0,0,0,0,0,0,0,0,0,0,0,0,37,0,0,0,0,0,0,0,0
0,0,0,0,0,0,0,0,0,0,0,0,0,0,0,0,0,0,0,0,0,0,0,38,0,0,0,0,0,0
0,0,0,0,0,0,0,0,0,0,0,0,0,0,0,0,0,0,0,0,0,0,0,0,38,0,0,0,0,0
0,0,0,0,0,0,0,0,0,0,0,0,0,0,0,0,0,0,0,0,0,0,0,0,0,37,0,0,0,0
0,0,0,0,34,0,0,0,0,0,0,0,0,0,0,0,0,0,0,0,0,0,0,0,0,0,0,0,0,0
0,0,0,0,0,0,0,0,0,0,0,0,0,0,0,0,0,0,0,0,0,0,0,0,0,0,0,0,0,0
0,0,0,0,0,0,0,0,0,0,0,0,0,0,0,0,0,0,0,0,0,0,0,0,0,0,0,38,0,0
0,0,0,0,0,0,0,0,0,0,0,0,0,0,0,0,0,0,0,0,0,0,0,0,0,0,0,0,0,0
0,0,0,0,0,0,0,0,0,0,0,0,0,0,31,31,29,0,0,0,0,0,0,0,0,0,0,0,38,0
0,0,0,0,0,0,0,0,0,0,0,0,0,31,0,0,0,31,29,0,0,0,0,0,0,0,0,0,38,0
0,0,0,0,0,0,0,0,0,0,0,0,29,0,0,31,0,0,31,0,0,0,0,0,0,0,0,0,0,0
0,0,34,0,0,0,0,0,0,0,0,0,31,0,0,33,0,0,31,0,0,0,0,0,0,0,0,0,38,0
0,0,34,0,0,0,0,0,0,0,0,0,31,0,0,0,0,0,29,0,0,0,0,0,0,0,0,0,0,0
0,0,34,0,0,0,0,0,0,0,0,0,0,31,0,0,0,0,29,0,0,0,0,0,0,0,0,0,0,0
0,0,0,0,0,0,0,0,0,0,0,0,0,0,31,31,31,31,29,0,0,0,0,0,0,0,0,0,0,0
0,0,0,0,0,0,0,0,0,0,0,0,0,0,0,0,0,0,0,0,0,0,0,0,0,0,0,0,0,0
0,0,0,34,0,0,0,0,0,0,0,0,0,0,0,0,0,0,0,0,0,0,0,0,0,0,0,0,0,0
0,0,0,0,0,0,0,0,0,0,0,0,0,0,0,0,0,0,0,0,0,0,0,0,0,0,0,0,0,0
0,0,0,0,0,0,0,0,0,0,0,0,0,0,0,0,0,0,0,0,0,0,0,0,0,0,0,0,0,0
0,0,0,0,0,0,0,0,0,0,0,0,0,0,0,0,0,0,0,0,0,0,0,0,0,0,0,0,0,0
0,0,0,0,0,0,0,0,0,0,0,0,0,0,0,0,0,0,0,0,0,0,0,0,0,0,0,0,0,0
0,0,0,0,0,0,0,0,0,0,0,0,0,0,0,0,0,0,0,0,0,0,0,35,0,0,0,0,0,0
0,0,0,0,0,0,0,0,0,34,0,0,0,0,0,0,0,0,0,0,0,35,0,0,0,0,0,0,0,0
0,0,0,0,0,0,0,0,0,0,35,34,0,0,0,0,0,0,0,0,0,0,0,0,0,0,0,0,0,0
0,0,0,0,0,0,0,0,0,0,0,0,0,0,35,0,35,0,35,0,0,0,0,0,0,0,0,0,0,0
endlayer

layer
0,0,0,0,0,0,0,0,0,0,0,0,0,36,0,0,36,0,0,0,0,0,0,0,0,0,0,0,0,0
0,0,0,0,0,0,0,0,0,0,36,0,0,0,0,0,0,0,0,38,0,0,0,0,0,0,0,0,0,0
0,0,0,0,0,0,0,0,0,0,0,0,0,0,0,0,0,0,0,0,0,37,0,0,0,0,0,0,0,0
0,0,0,0,0,0,0,0,0,0,0,0,0,0,0,0,0,0,0,0,0,0,0,38,0,0,0,0,0,0
0,0,0,0,0,0,0,0,0,0,0,0,0,0,0,0,0,0,0,0,0,0,0,0,38,0,0,0,0,0
0,0,0,0,0,0,0,0,0,0,0,0,0,0,0,0,0,0,0,0,0,0,0,0,0,37,0,0,0,0
0,0,0,0,34,0,0,0,0,0,0,0,0,0,0,0,0,0,0,0,0,0,0,0,0,0,0,0,0,0
0,0,0,0,0,0,0,0,0,0,0,0,0,0,0,0,0,0,0,0,0,0,0,0,0,0,0,0,0,0
0,0,0,34,0,0,0,0,0,0,0,0,0,0,0,0,0,0,0,0,0,0,0,0,0,0,0,38,0,0
0,0,0,0,0,0,0,0,0,0,0,0,0,0,0,0,0,0,0,0,0,0,0,0,0,0,0,0,0,0
0,0,34,0,0,0,0,0,0,0,0,0,0,0,29,31,29,0,0,0,0,0,0,0,0,0,0,0,38,0
0,0,0,0,0,0,0,0,0,0,0,0,0,31,0,0,0,31,0,0,0,0,0,0,0,0,0,0,38,0
0,0,0,0,0,0,0,0,0,0,0,0,31,0,0,31,0,0,31,0,0,0,0,0,0,0,0,0,38,0
0,0,34,0,0,0,0,0,0,0,0,0,31,0,0,33,0,0,31,0,0,0,0,0,0,0,0,0,38,0
0,0,34,0,0,0,0,0,0,0,0,0,31,0,0,0,0,0,31,0,0,0,0,0,0,0,0,0,0,0
0,0,34,0,0,0,0,0,0,0,0,0,0,31,0,0,0,0,29,0,0,0,0,0,0,0,0,0,0,0
0,0,0,0,0,0,0,0,0,0,0,0,0,0,31,31,29,29,29,0,0,0,0,0,0,0,0,0,0,0
0,0,0,0,0,0,0,0,0,0,0,0,0,0,0,0,0,0,0,0,0,0,0,0,0,0,0,0,0,0
0,0,0,34,0,0,0,0,0,0,0,0,0,0,0,0,0,0,0,0,0,0,0,0,0,0,0,0,0,0
0,0,0,0,0,0,0,0,0,0,0,0,0,0,0,0,0,0,0,0,0,0,0,0,0,0,0,0,0,0
0,0,0,0,0,0,0,0,0,0,0,0,0,0,0,0,0,0,0,0,0,0,0,0,0,0,0,0,0,0
0,0,0,0,0,0,0,0,0,0,0,0,0,0,0,0,0,0,0,0,0,0,0,0,0,0,0,0,0,0
0,0,0,0,0,0,0,0,0,0,0,0,0,0,0,0,0,0,0,0,0,0,0,0,0,0,0,0,0,0
0,0,0,0,0,0,0,0,0,0,0,0,0,0,0,0,0,0,0,0,0,0,0,35,0,0,0,0,0,0
0,0,0,0,0,0,0,0,0,34,0,0,0,0,0,0,0,0,0,0,0,35,35,0,0,0,0,0,0,0
0,0,0,0,0,0,0,0,0,0,35,34,0,0,0,0,0,0,0,0,0,0,0,0,0,0,0,0,0,0
0,0,0,0,0,0,0,0,0,0,0,0,0,0,35,0,35,0,35,0,0,0,0,0,0,0,0,0,0,0
endlayer

layer
0,0,0,0,0,0,0,0,0,0,0,0,0,36,0,0,36,36,0,0,0,0,0,0,0,0,0,0,0,0
0,0,0,0,0,0,0,0,0,0,36,40,0,0,0,0,0,0,0,38,0,0,0,0,0,0,0,0,0,0
0,0,0,0,0,0,0,0,0,0,0,0,0,0,0,0,0,0,0,0,0,37,0,0,0,0,0,0,0,0
0,0,0,0,0,0,0,0,0,0,0,0,0,0,0,0,0,0,0,0,0,0,0,38,0,0,0,0,0,0
0,0,0,0,0,0,36,0,0,0,0,0,0,0,0,0,0,0,0,0,0,0,0,0,38,0,0,0,0,0
0,0,0,0,0,0,0,0,0,0,0,0,0,0,0,0,0,0,0,0,0,0,0,0,0,37,0,0,0,0
0,0,0,0,34,0,0,0,0,0,0,0,0,0,0,0,0,0,0,0,0,0,0,0,0,0,38,0,0,0
0,0,0,0,0,0,0,0,0,0,0,0,0,0,0,0,0,0,0,0,0,0,0,0,0,0,0,0,0,0
0,0,0,34,0,0,0,0,0,0,0,0,0,0,0,0,0,0,0,0,0,0,0,0,0,0,0,38,0,0
0,0,0,0,0,0,0,0,0,0,0,0,0,0,0,0,0,0,0,0,0,0,0,0,0,0,0,0,0,0
0,0,34,0,0,0,0,0,0,0,0,0,0,0,29,31,31,0,0,0,0,0,0,0,0,0,0,0,38,0
0,0,0,0,0,0,0,0,0,0,0,0,0,29,0,0,0,31,0,0,0,0,0,0,0,0,0,0,38,0
0,0,0,0,0,0,0,0,0,0,0,0,31,0,0,31,0,0,29,0,0,0,0,0,0,0,0,0,38,0
0,0,34,0,0,0,0,0,0,0,0,0,31,0,0,33,0,0,29,0,0,0,0,0,0,0,0,0,38,0
0,0,34,0,0,0,0,0,0,0,0,0,31,0,0,0,0,0,31,0,0,0,0,0,0,0,0,0,38,0
0,0,34,0,0,0,0,0,0,0,0,0,0,29,0,0,0,0,31,0,0,0,0,0,0,0,0,0,0,0
0,0,0,0,0,0,0,0,0,0,0,0,0,0,29,29,29,29,0,0,0,0,0,0,0,0,0,0,0,0
0,0,0,0,0,0,0,0,0,0,0,0,0,0,0,0,0,0,0,0,0,0,0,0,0,0,0,0,0,0
0,0,0,34,0,0,0,0,0,0,0,0,0,0,0,0,0,0,0,0,0,0,0,0,0,0,0,0,0,0
0,0,0,0,0,0,0,0,0,0,0,0,0,0,0,0,0,0,0,0,0,0,0,0,0,0,38,0,0,0
0,0,0,0,0,0,0,0,0,0,0,0,0,0,0,0,0,0,0,0,0,0,0,0,0,0,38,0,0,0
0,0,0,0,0,0,0,0,0,0,0,0,0,0,0,0,0,0,0,0,0,0,0,0,0,0,0,0,0,0
0,0,0,0,0,0,0,0,0,0,0,0,0,0,0,0,0,0,0,0,0,0,0,0,0,0,0,0,0,0
0,0,0,0,0,0,0,0,0,0,0,0,0,0,0,0,0,0,0,0,0,0,0,35,0,0,0,0,0,0
0,0,0,0,0,0,0,0,0,34,0,0,0,0,0,0,0,0,0,0,0,35,35,0,0,0,0,0,0,0
0,0,0,0,0,0,0,0,0,0,35,41,0,0,0,0,0,0,0,0,0,0,0,0,0,0,0,0,0,0
0,0,0,0,0,0,0,0,0,0,0,0,0,0,35,0,35,0,35,0,0,0,0,0,0,0,0,0,0,0
endlayer

layer
0,0,0,0,0,0,0,0,0,0,0,0,0,36,0,0,36,36,0,0,0,0,0,0,0,0,0,0,0,0
0,0,0,0,0,0,0,0,0,0,36,40,0,0,0,0,0,0,0,38,0,0,0,0,0,0,0,0,0,0
0,0,0,0,0,0,0,0,0,0,0,0,0,0,0,0,0,0,0,0,0,37,0,0,0,0,0,0,0,0
0,0,0,0,0,0,0,0,0,0,0,0,0,0,0,0,0,0,0,0,0,0,0,38,0,0,0,0,0,0
0,0,0,0,0,0,36,0,0,0,0,0,0,0,0,0,0,0,0,0,0,0,0,0,38,0,0,0,0,0
0,0,0,0,0,0,0,0,0,0,0,0,0,0,0,0,0,0,0,0,0,0,0,0,0,37,0,0,0,0
0,0,0,0,34,0,0,0,0,0,0,0,0,0,0,0,0,0,0,0,0,0,0,0,0,0,38,0,0,0
0,0,0,0,0,0,0,0,0,0,0,0,0,0,0,0,0,0,0,0,0,0,0,0,0,0,0,0,0,0
0,0,0,34,0,0,0,0,0,0,0,0,0,0,0,0,0,0,0,0,0,0,0,0,0,0,0,38,0,0
0,0,0,0,0,0,0,0,0,0,0,0,0,0,0,0,0,0,0,0,0,0,0,0,0,0,0,0,0,0
0,0,34,0,0,0,0,0,0,0,0,0,0,0,29,31,31,0,0,0,0,0,0,0,0,0,0,0,38,0
0,0,34,0,0,0,0,0,0,0,0,0,0,29,0,0,0,29,0,0,0,0,0,0,0,0,0,0,38,0
0,0,0,0,0,0,0,0,0,0,0,0,29,0,0,31,0,31,0,0,0,0,0,0,0,0,0,0,38,0
0,0,34,0,0,0,0,0,0,0,0,0,31,0,0,33,0,0,29,0,0,0,0,0,0,0,0,0,38,0
0,0,34,0,0,0,0,0,0,0,0,0,31,0,0,0,0,0,29,0,0,0,0,0,0,0,0,0,38,0
0,0,34,0,0,0,0,0,0,0,0,0,0,29,31,0,0,0,31,0,0,0,0,0,0,0,0,0,0,0
0,0,0,0,0,0,0,0,0,0,0,0,0,0,0,29,29,29,0,0,0,0,0,0,0,0,0,0,0,0
0,0,0,0,0,0,0,0,0,0,0,0,0,0,0,0,0,0,0,0,0,0,0,0,0,0,0,0,0,0
0,0,0,34,0,0,0,0,0,0,0,0,0,0,0,0,0,0,0,0,0,0,0,0,0,0,0,0,0,0
0,0,0,0,0,0,0,0,0,0,0,0,0,0,0,0,0,0,0,0,0,0,0,0,0,0,38,0,0,0
0,0,0,0,0,0,0,0,0,0,0,0,0,0,0,0,0,0,0,0,0,0,0,0,0,0,38,0,0,0
0,0,0,0,0,0,0,0,0,0,0,0,0,0,0,0,0,0,0,0,0,0,0,0,0,0,0,0,0,0
0,0,0,0,0,0,0,0,0,0,0,0,0,0,0,0,0,0,0,0,0,0,0,0,0,0,0,0,0,0
0,0,0,0,0,0,0,0,0,0,0,0,0,0,0,0,0,0,0,0,0,0,0,35,0,0,0,0,0,0
0,0,0,0,0,0,0,0,0,34,0,0,0,0,0,0,0,0,0,0,0,35,35,0,0,0,0,0,0,0
0,0,0,0,0,0,0,0,0,0,35,41,0,0,0,0,0,0,0,0,0,0,0,0,0,0,0,0,0,0
0,0,0,0,0,0,0,0,0,0,0,0,0,0,35,0,35,0,35,0,0,0,0,0,0,0,0,0,0,0
endlayer

layer
0,0,0,0,0,0,0,0,0,0,0,0,36,36,0,36,36,36,0,0,0,0,0,0,0,0,0,0,0,0
0,0,0,0,0,0,0,0,0,0,36,40,0,0,0,0,0,0,0,38,0,0,0,0,0,0,0,0,0,0
0,0,0,0,0,0,0,0,0,0,0,0,0,0,0,0,0,0,0,0,0,37,0,0,0,0,0,0,0,0
0,0,0,0,0,0,0,0,0,0,0,0,0,0,0,0,0,0,0,0,0,0,0,38,0,0,0,0,0,0
0,0,0,0,0,0,36,0,0,0,0,0,0,0,0,0,0,0,0,0,0,0,0,0,38,0,0,0,0,0
0,0,0,0,0,0,0,0,0,0,0,0,0,0,0,0,0,0,0,0,0,0,0,0,0,37,0,0,0,0
0,0,0,0,34,0,0,0,0,0,0,0,0,0,0,0,0,0,0,0,0,0,0,0,0,0,38,0,0,0
0,0,0,0,0,0,0,0,0,0,0,0,0,0,0,0,0,0,0,0,0,0,0,0,0,0,0,0,0,0
0,0,0,34,0,0,0,0,0,0,0,0,0,0,0,0,0,0,0,0,0,0,0,0,0,0,0,38,0,0
0,0,0,0,0,0,0,0,0,0,0,0,0,0,0,0,0,0,0,0,0,0,0,0,0,0,0,0,0,0
0,0,34,0,0,0,0,0,0,0,0,0,0,0,29,0,29,0,0,0,0,0,0,0,0,0,0,0,38,0
0,0,34,0,0,0,0,0,0,0,0,0,0,29,29,31,29,29,0,0,0,0,0,0,0,0,0,0,38,0
0,0,0,0,0,0,0,0,0,0,0,0,29,29,0,31,0,29,0,0,0,0,0,0,0,0,0,0,38,0
0,0,34,0,0,0,0,0,0,0,0,0,29,31,0,33,0,31,0,0,0,0,0,0,0,0,0,0,38,0
0,0,34,0,0,0,0,0,0,0,0,0,31,29,0,0,0,29,29,0,0,0,0,0,0,0,0,0,38,0
0,0,34,0,0,0,0,0,0,0,0,0,0,29,29,31,29,29,29,0,0,0,0,0,0,0,0,0,0,0
0,0,0,0,0,0,0,0,0,0,0,0,0,0,29,0,29,29,0,0,0,0,0,0,0,0,0,0,0,0
0,0,0,0,0,0,0,0,0,0,0,0,0,0,0,0,0,0,0,0,0,0,0,0,0,0,0,0,0,0
0,0,0,34,0,0,0,0,0,0,0,0,0,0,0,0,0,0,0,0,0,0,0,0,0,0,0,0,0,0
0,0,0,0,0,0,0,0,0,0,0,0,0,0,0,0,0,0,0,0,0,0,0,0,0,0,38,0,0,0
0,0,0,0,0,0,0,0,0,0,0,0,0,0,0,0,0,0,0,0,0,0,0,0,0,0,38,0,0,0
0,0,0,0,0,0,0,0,0,0,0,0,0,0,0,0,0,0,0,0,0,0,0,0,0,0,0,0,0,0
0,0,0,0,0,0,0,0,0,0,0,0,0,0,0,0,0,0,0,0,0,0,0,0,0,0,0,0,0,0
0,0,0,0,0,0,0,0,0,0,0,0,0,0,0,0,0,0,0,0,0,0,0,35,0,0,0,0,0,0
0,0,0,0,0,0,0,0,0,34,0,0,0,0,0,0,0,0,0,0,0,35,35,0,0,0,0,0,0,0
0,0,0,0,0,0,0,0,0,0,35,41,0,0,0,0,0,0,0,42,0,0,0,0,0,0,0,0,0,0
0,0,0,0,0,0,0,0,0,0,0,0,0,0,35,0,35,0,35,0,0,0,0,0,0,0,0,0,0,0
endlayer

layer
0,0,0,0,0,0,0,0,0,0,0,0,36,36,36,36,36,36,0,0,0,0,0,0,0,0,0,0,0,0
0,0,0,0,0,0,0,0,0,0,36,40,0,0,0,0,0,0,0,38,0,0,0,0,0,0,0,0,0,0
0,0,0,0,0,0,0,0,0,0,0,0,0,0,0,0,0,0,0,0,0,37,36,0,0,0,0,0,0,0
0,0,0,0,0,0,0,0,0,0,0,0,0,0,0,0,0,0,0,0,0,0,0,38,0,0,0,0,0,0
0,0,0,0,0,0,36,0,0,0,0,0,0,0,0,0,0,0,0,0,0,0,0,0,38,0,0,0,0,0
0,0,0,0,0,0,0,0,0,0,0,0,0,0,0,0,0,0,0,0,0,0,0,0,0,37,0,0,0,0
0,0,0,0,34,0,0,0,0,0,0,0,0,0,0,0,0,0,0,0,0,0,0,0,0,0,38,0,0,0
0,0,0,0,36,0,0,0,0,0,0,0,0,0,0,0,0,0,0,0,0,0,0,0,0,0,43,0,0,0
0,0,0,34,0,0,0,0,0,0,0,0,0,0,0,0,0,0,0,0,0,0,0,0,0,0,0,38,0,0
0,0,0,0,0,0,0,0,0,0,0,0,0,0,0,0,0,0,0,0,0,0,0,0,0,0,0,0,0,0
0,0,34,0,0,0,0,0,0,0,0,0,0,0,0,0,0,0,0,0,0,0,0,0,0,0,0,0,38,0
0,0,34,0,0,0,0,0,0,0,0,0,0,29,31,31,31,29,0,0,0,0,0,0,0,0,0,0,38,0
0,0,0,0,0,0,0,0,0,0,0,0,0,31,0,31,0,31,0,0,0,0,0,0,0,0,0,0,38,0
0,0,34,0,0,0,0,0,0,0,0,0,0,31,0,33,0,31,0,0,0,0,0,0,0,0,0,0,38,0
0,0,34,0,0,0,0,0,0,0,0,0,29,31,0,0,0,31,0,0,0,0,0,0,0,0,0,0,38,0
0,0,34,0,0,0,0,0,0,0,0,0,0,0,29,31,31,29,29,0,0,0,0,0,0,0,0,0,38,0
0,0,0,0,0,0,0,0,0,0,0,0,0,0,29,0,0,29,0,0,0,0,0,0,0,0,0,0,0,0
0,0,0,0,0,0,0,0,0,0,0,0,0,0,0,0,0,0,0,0,0,0,0,0,0,0,0,0,0,0
0,0,0,34,0,0,0,0,0,0,0,0,0,0,0,0,0,0,0,0,0,0,0,0,0,0,0,0,0,0
0,0,0,0,0,0,0,0,0,0,0,0,0,0,0,0,0,0,0,0,0,0,0,0,0,0,38,0,0,0
0,0,0,0,34,0,0,0,0,0,0,0,0,0,0,0,0,0,0,0,0,0,0,0,0,0,38,0,0,0
0,0,0,0,0,0,0,0,0,0,0,0,0,0,0,0,0,0,0,0,0,0,0,0,0,0,0,0,0,0
0,0,0,0,0,0,0,0,0,0,0,0,0,0,0,0,0,0,0,0,0,0,0,0,0,0,0,0,0,0
0,0,0,0,0,0,0,35,0,0,0,0,0,0,0,0,0,0,0,0,0,0,0,35,0,0,0,0,0,0
0,0,0,0,0,0,0,0,0,34,0,0,0,0,0,0,0,0,0,0,0,35,35,0,0,0,0,0,0,0
0,0,0,0,0,0,0,0,0,0,35,41,0,0,0,0,0,0,0,42,0,0,0,0,0,0,0,0,0,0
0,0,0,0,0,0,0,0,0,0,0,0,0,0,35,0,35,0,35,0,0,0,0,0,0,0,0,0,0,0
endlayer

layer
0,0,0,0,0,0,0,0,0,0,0,0,36,36,36,36,36,36,0,0,0,0,0,0,0,0,0,0,0,0
0,0,0,0,0,0,0,0,0,0,36,40,0,0,0,0,0,0,0,38,0,0,0,0,0,0,0,0,0,0
0,0,0,0,0,0,0,0,0,0,0,0,0,0,0,0,0,0,0,0,0,37,36,0,0,0,0,0,0,0
0,0,0,0,0,0,0,0,0,0,0,0,0,0,0,0,0,0,0,0,0,0,0,38,0,0,0,0,0,0
0,0,0,0,0,0,36,0,0,0,0,0,0,0,0,0,0,0,0,0,0,0,0,0,38,0,0,0,0,0
0,0,0,0,0,0,0,0,0,0,0,0,0,0,0,0,0,0,0,0,0,0,0,0,0,37,0,0,0,0
0,0,0,0,34,0,0,0,0,0,0,0,0,0,0,0,0,0,0,0,0,0,0,0,0,0,38,0,0,0
0,0,0,0,36,0,0,0,0,0,0,0,0,0,0,0,0,0,0,0,0,0,0,0,0,0,43,0,0,0
0,0,0,34,0,0,0,0,0,0,0,0,0,0,0,0,0,0,0,0,0,0,0,0,0,0,0,38,0,0
0,0,0,0,0,0,0,0,0,0,0,0,0,0,0,0,0,0,0,0,0,0,0,0,0,0,0,0,0,0
0,0,34,0,0,0,0,0,0,0,0,0,0,0,0,29,0,0,0,0,0,0,0,0,0,0,0,0,38,0
0,0,34,0,0,0,0,0,0,0,0,0,0,0,31,31,31,0,0,0,0,0,0,0,0,0,0,0,38,0
0,0,0,0,0,0,0,0,0,0,0,0,0,31,0,31,0,31,0,0,0,0,0,0,0,0,0,0,38,0
0,0,34,0,0,0,0,0,0,0,0,0,29,31,0,33,0,31,29,0,0,0,0,0,0,0,0,0,38,0
0,0,34,0,0,0,0,0,0,0,0,0,0,31,0,0,0,31,0,0,0,0,0,0,0,0,0,0,38,0
0,0,34,0,0,0,0,0,0,0,0,0,0,0,31,31,31,31,0,0,0,0,0,0,0,0,0,0,38,0
0,0,34,0,0,0,0,0,0,0,0,0,0,0,0,29,0,0,0,0,0,0,0,0,0,0,0,0,0,0
0,0,0,0,0,0,0,0,0,0,0,0,0,0,0,0,0,0,0,0,0,0,0,0,0,0,0,42,0,0
0,0,0,34,0,0,0,0,0,0,0,0,0,0,0,0,0,0,0,0,0,0,0,0,0,0,0,0,0,0
0,0,0,0,0,0,0,0,0,0,0,0,0,0,0,0,0,0,0,0,0,0,0,0,0,0,38,0,0,0
0,0,0,0,34,0,0,0,0,0,0,0,0,0,0,0,0,0,0,0,0,0,0,0,0,0,38,0,0,0
0,0,0,0,0,0,0,0,0,0,0,0,0,0,0,0,0,0,0,0,0,0,0,0,0,0,0,0,0,0
0,0,0,0,0,0,0,0,0,0,0,0,0,0,0,0,0,0,0,0,0,0,0,0,0,0,0,0,0,0
0,0,0,0,0,0,0,41,0,0,0,0,0,0,0,0,0,0,0,0,0,0,0,35,0,0,0,0,0,0
0,0,0,0,0,0,0,0,42,34,0,0,0,0,0,0,0,0,0,0,0,35,35,0,0,0,0,0,0,0
0,0,0,0,0,0,0,0,0,0,35,41,0,0,0,0,0,0,0,42,0,0,0,0,0,0,0,0,0,0
0,0,0,0,0,0,0,0,0,0,0,0,0,0,35,0,35,0,35,0,0,0,0,0,0,0,0,0,0,0
endlayer

layer
0,0,0,0,0,0,0,0,0,0,0,0,36,36,36,36,36,36,0,0,0,0,0,0,0,0,0,0,0,0
0,0,0,0,0,0,0,0,0,0,36,40,0,0,0,0,0,0,0,38,40,0,0,0,0,0,0,0,0,0
0,0,0,0,0,0,0,0,0,0,0,0,0,0,0,0,0,0,0,0,0,37,36,0,0,0,0,0,0,0
0,0,0,0,0,0,0,36,0,0,0,0,0,0,0,0,0,0,0,0,0,0,0,38,0,0,0,0,0,0
0,0,0,0,0,0,36,0,0,0,0,0,0,0,0,0,0,0,0,0,0,0,0,0,38,0,0,0,0,0
0,0,0,0,0,40,0,0,0,0,0,0,0,0,0,0,0,0,0,0,0,0,0,0,0,37,0,0,0,0
0,0,0,0,34,0,0,0,0,0,0,0,0,0,0,0,0,0,0,0,0,0,0,0,0,0,38,0,0,0
0,0,0,0,36,0,0,0,0,0,0,0,0,0,0,0,0,0,0,0,0,0,0,0,0,0,44,0,0,0
0,0,0,34,0,0,0,0,0,0,0,0,0,0,0,0,0,0,0,0,0,0,0,0,0,0,0,38,0,0
0,0,0,34,0,0,0,0,0,0,0,0,0,0,0,0,0,0,0,0,0,0,0,0,0,0,0,0,0,0
0,0,34,0,0,0,0,0,0,0,0,0,0,0,0,29,0,0,0,0,0,0,0,0,0,0,0,0,38,0
0,0,34,0,0,0,0,0,0,0,0,0,0,31,31,29,31,0,0,0,0,0,0,0,0,0,0,0,38,0
0,0,0,0,0,0,0,0,0,0,0,0,0,31,0,31,0,31,0,0,0,0,0,0,0,0,0,0,38,0
0,0,34,0,0,0,0,0,0,0,0,0,29,29,0,33,0,29,29,0,0,0,0,0,0,0,0,0,38,0
0,0,34,0,0,0,0,0,0,0,0,0,0,31,0,0,0,31,0,0,0,0,0,0,0,0,0,0,38,0
0,0,34,0,0,0,0,0,0,0,0,0,0,0,31,29,31,31,0,0,0,0,0,0,0,0,0,0,38,0
0,0,34,0,0,0,0,0,0,0,0,0,0,0,0,29,0,0,0,0,0,0,0,0,0,0,0,0,0,0
0,0,0,0,0,0,0,0,0,0,0,0,0,0,0,0,0,0,0,0,0,0,0,0,0,0,0,42,0,0
0,0,0,34,0,0,0,0,0,0,0,0,0,0,0,0,0,0,0,0,0,0,0,0,0,0,0,38,0,0
0,0,0,0,0,0,0,0,0,0,0,0,0,0,0,0,0,0,0,0,0,0,0,0,0,0,38,0,0,0
0,0,0,0,34,0,0,0,0,0,0,0,0,0,0,0,0,0,0,0,0,0,0,0,0,0,38,0,0,0
0,0,0,0,0,34,0,0,0,0,0,0,0,0,0,0,0,0,0,0,0,0,0,0,0,0,0,0,0,0
0,0,0,0,0,0,0,0,0,0,0,0,0,0,0,0,0,0,0,0,0,0,0,0,0,0,0,0,0,0
0,0,0,0,0,0,0,41,0,0,0,0,0,0,0,0,0,0,0,0,0,0,0,35,0,0,0,0,0,0
0,0,0,0,0,0,0,0,42,34,0,0,0,0,0,0,0,0,0,0,0,35,35,0,0,0,0,0,0,0
0,0,0,0,0,0,0,0,0,0,35,41,0,0,0,0,0,0,0,42,35,0,0,0,0,0,0,0,0,0
0,0,0,0,0,0,0,0,0,0,0,0,35,35,35,0,35,35,35,0,0,0,0,0,0,0,0,0,0,0
endlayer

layer
0,0,0,0,0,0,0,0,0,0,0,0,36,36,36,36,36,36,0,0,0,0,0,0,0,0,0,0,0,0
0,0,0,0,0,0,0,0,0,0,36,40,0,0,0,0,0,0,0,38,40,0,0,0,0,0,0,0,0,0
0,0,0,0,0,0,0,0,0,0,0,0,0,0,0,0,0,0,0,0,0,37,36,0,0,0,0,0,0,0
0,0,0,0,0,0,0,36,0,0,0,0,0,0,0,0,0,0,0,0,0,0,0,38,0,0,0,0,0,0
0,0,0,0,0,0,36,0,0,0,0,0,0,0,0,0,0,0,0,0,0,0,0,0,38,0,0,0,0,0
0,0,0,0,0,40,0,0,0,0,0,0,0,0,0,0,0,0,0,0,0,0,0,0,0,37,0,0,0,0
0,0,0,0,34,0,0,0,0,0,0,0,0,0,0,0,0,0,0,0,0,0,0,0,0,0,38,0,0,0
0,0,0,0,36,0,0,0,0,0,0,0,0,0,0,0,0,0,0,0,0,0,0,0,0,0,44,0,0,0
0,0,0,34,0,0,0,0,0,0,0,0,0,0,0,0,0,0,0,0,0,0,0,0,0,0,0,38,0,0
0,0,0,34,0,0,0,0,0,0,0,0,0,0,0,0,0,0,0,0,0,0,0,0,0,0,0,43,0,0
0,0,34,0,0,0,0,0,0,0,0,0,0,0,0,29,29,0,0,0,0,0,0,0,0,0,0,0,38,0
0,0,34,0,0,0,0,0,0,0,0,0,0,31,31,29,29,31,0,0,0,0,0,0,0,0,0,0,38,0
0,0,0,0,0,0,0,0,0,0,0,0,29,29,0,31,0,31,0,0,0,0,0,0,0,0,0,0,38,0
0,0,34,0,0,0,0,0,0,0,0,0,29,29,0,33,0,29,29,0,0,0,0,0,0,0,0,0,38,0
0,0,34,0,0,0,0,0,0,0,0,0,0,31,0,0,0,29,29,0,0,0,0,0,0,0,0,0,38,0
0,0,34,0,0,0,0,0,0,0,0,0,0,31,29,29,31,31,0,0,0,0,0,0,0,0,0,0,38,0
0,0,34,0,0,0,0,0,0,0,0,0,0,0,29,29,0,0,0,0,0,0,0,0,0,0,0,0,43,0
0,0,0,0,0,0,0,0,0,0,0,0,0,0,0,0,0,0,0,0,0,0,0,0,0,0,0,42,0,0
0,0,0,34,0,0,0,0,0,0,0,0,0,0,0,0,0,0,0,0,0,0,0,0,0,0,0,38,0,0
0,0,0,0,0,0,0,0,0,0,0,0,0,0,0,0,0,0,0,0,0,0,0,0,0,0,38,0,0,0
0,0,0,0,34,0,0,0,0,0,0,0,0,0,0,0,0,0,0,0,0,0,0,0,0,0,38,0,0,0
0,0,0,0,0,34,0,0,0,0,0,0,0,0,0,0,0,0,0,0,0,0,0,0,0,0,0,0,0,0
0,0,0,0,0,0,0,0,0,0,0,0,0,0,0,0,0,0,0,0,0,0,0,0,0,0,0,0,0,0
0,0,0,0,0,0,0,41,0,0,0,0,0,0,0,0,0,0,0,0,0,0,0,35,0,0,0,0,0,0
0,0,0,0,0,0,0,0,42,34,0,0,0,0,0,0,0,0,0,0,0,35,35,0,0,0,0,0,0,0
0,0,0,0,0,0,0,0,0,0,35,41,0,0,0,0,0,0,0,42,35,0,0,0,0,0,0,0,0,0
0,0,0,0,0,0,0,0,0,0,0,0,35,35,35,35,35,35,35,0,0,0,0,0,0,0,0,0,0,0
endlayer

layer
0,0,0,0,0,0,0,0,0,0,0,0,36,36,36,36,36,36,0,0,0,0,0,0,0,0,0,0,0,0
0,0,0,0,0,0,0,0,0,0,36,40,0,0,0,0,0,0,0,38,40,0,0,0,0,0,0,0,0,0
0,0,0,0,0,0,0,0,0,0,0,0,0,0,0,0,0,0,0,0,0,37,36,0,0,0,0,0,0,0
0,0,0,0,0,0,0,36,0,0,0,0,0,0,0,0,0,0,0,0,0,0,0,38,0,0,0,0,0,0
0,0,0,0,0,0,36,0,0,0,0,0,0,0,0,0,0,0,0,0,0,0,0,0,38,0,0,0,0,0
0,0,0,0,0,40,0,0,0,0,0,0,0,0,0,0,0,0,0,0,0,0,0,0,0,37,0,0,0,0
0,0,0,0,34,0,0,0,0,0,0,0,0,0,0,0,0,0,0,0,0,0,0,0,0,0,38,0,0,0
0,0,0,0,36,0,0,0,0,0,0,0,0,0,0,0,0,0,0,0,0,0,0,0,0,0,44,0,0,0
0,0,0,34,0,0,0,0,0,0,0,0,0,0,0,0,0,0,0,0,0,0,0,0,0,0,0,38,0,0
0,0,0,34,0,0,0,0,0,0,0,0,0,0,0,0,0,0,0,0,0,0,0,0,0,0,0,43,0,0
0,0,34,0,0,0,0,0,0,0,0,0,0,0,29,31,29,0,0,0,0,0,0,0,0,0,0,0,38,0
0,0,34,0,0,0,0,0,0,0,0,0,0,31,29,31,29,31,0,0,0,0,0,0,0,0,0,0,38,0
0,0,45,0,0,0,0,0,0,0,0,0,29,29,31,31,31,29,29,0,0,0,0,0,0,0,0,0,38,0
0,0,34,0,0,0,0,0,0,0,0,0,31,31,0,33,0,31,31,0,0,0,0,0,0,0,0,0,38,0
0,0,34,0,0,0,0,0,0,0,0,0,29,29,31,0,31,29,29,0,0,0,0,0,0,0,0,0,38,0
0,0,34,0,0,0,0,0,0,0,0,0,0,31,29,31,29,31,0,0,0,0,0,0,0,0,0,0,38,0
0,0,34,0,0,0,0,0,0,0,0,0,0,0,29,31,29,0,0,0,0,0,0,0,0,0,0,0,43,0
0,0,0,0,0,0,0,0,0,0,0,0,0,0,0,0,0,0,0,0,0,0,0,0,0,0,0,42,0,0
0,0,0,34,0,0,0,0,0,0,0,0,0,0,0,0,0,0,0,0,0,0,0,0,0,0,0,38,0,0
0,0,0,0,45,0,0,0,0,0,0,0,0,0,0,0,0,0,0,0,0,0,0,0,0,0,38,0,0,0
0,0,0,0,34,0,0,0,0,0,0,0,0,0,0,0,0,0,0,0,0,0,0,0,0,0,38,0,0,0
0,0,0,0,0,34,0,0,0,0,0,0,0,0,0,0,0,0,0,0,0,0,0,0,0,0,0,0,0,0
0,0,0,0,0,0,0,0,0,0,0,0,0,0,0,0,0,0,0,0,0,0,0,0,0,0,0,0,0,0
0,0,0,0,0,0,0,41,0,0,0,0,0,0,0,0,0,0,0,0,0,0,0,35,0,0,0,0,0,0
0,0,0,0,0,0,0,0,42,34,0,0,0,0,0,0,0,0,0,0,0,35,35,0,0,0,0,0,0,0
0,0,0,0,0,0,0,0,0,0,35,41,0,0,0,0,0,0,0,42,35,0,0,0,0,0,0,0,0,0
0,0,0,0,0,0,0,0,0,0,0,0,35,35,35,35,35,35,35,0,0,0,0,0,0,0,0,0,0,0
endlayer

layer
0,0,0,0,0,0,0,0,0,0,0,0,36,36,36,36,36,36,0,0,0,0,0,0,0,0,0,0,0,0
0,0,0,0,0,0,0,0,0,0,36,40,0,0,0,0,0,0,0,38,40,0,0,0,0,0,0,0,0,0
0,0,0,0,0,0,0,0,0,0,0,0,0,0,0,0,0,0,0,0,0,37,36,0,0,0,0,0,0,0
0,0,0,0,0,0,0,36,0,0,0,0,0,0,0,0,0,0,0,0,0,0,0,38,0,0,0,0,0,0
0,0,0,0,0,0,36,0,0,0,0,0,0,0,0,0,0,0,0,0,0,0,0,0,38,0,0,0,0,0
0,0,0,0,0,40,0,0,0,0,0,0,0,0,0,0,0,0,0,0,0,0,0,0,0,37,0,0,0,0
0,0,0,0,34,0,0,0,0,0,0,0,0,0,0,0,0,0,0,0,0,0,0,0,0,0,38,0,0,0
0,0,0,0,36,0,0,0,0,0,0,0,0,0,0,0,0,0,0,0,0,0,0,0,0,0,44,0,0,0
0,0,0,34,0,0,0,0,0,0,0,0,0,0,0,0,0,0,0,0,0,0,0,0,0,0,0,38,0,0
0,0,0,34,0,0,0,0,0,0,0,0,0,0,0,0,0,0,0,0,0,0,0,0,0,0,0,43,0,0
0,0,34,0,0,0,0,0,0,0,0,0,0,0,29,31,31,0,0,0,0,0,0,0,0,0,0,0,38,0
0,0,34,0,0,0,0,0,0,0,0,0,0,29,29,31,31,29,0,0,0,0,0,0,0,0,0,0,38,0
0,0,45,0,0,0,0,0,0,0,0,0,31,31,31,31,31,29,29,0,0,0,0,0,0,0,0,0,38,0
0,0,34,0,0,0,0,0,0,0,0,0,31,31,31,33,31,31,31,0,0,0,0,0,0,0,0,0,38,0
0,0,34,0,0,0,0,0,0,0,0,0,29,29,31,31,31,31,31,0,0,0,0,0,0,0,0,0,38,0
0,0,34,0,0,0,0,0,0,0,0,0,0,29,31,31,29,29,0,0,0,0,0,0,0,0,0,0,38,0
0,0,34,0,0,0,0,0,0,0,0,0,0,0,31,31,29,0,0,0,0,0,0,0,0,0,0,0,43,0
0,0,0,45,0,0,0,0,0,0,0,0,0,0,0,0,0,0,0,0,0,0,0,0,0,0,0,42,0,0
0,0,0,34,0,0,0,0,0,0,0,0,0,0,0,0,0,0,0,0,0,0,0,0,0,0,0,38,0,0
0,0,0,0,45,0,0,0,0,0,0,0,0,0,0,0,0,0,0,0,0,0,0,0,0,0,38,0,0,0
0,0,0,0,34,0,0,0,0,0,0,0,0,0,0,0,0,0,0,0,0,0,0,0,0,0,38,0,0,0
0,0,0,0,0,34,0,0,0,0,0,0,0,0,0,0,0,0,0,0,0,0,0,0,0,0,0,0,0,0
0,0,0,0,0,0,0,0,0,0,0,0,0,0,0,0,0,0,0,0,0,0,0,0,0,0,0,0,0,0
0,0,0,0,0,0,0,41,0,0,0,0,0,0,0,0,0,0,0,0,0,0,0,35,0,0,0,0,0,0
0,0,0,0,0,0,0,0,42,34,0,0,0,0,0,0,0,0,0,0,0,35,35,0,0,0,0,0,0,0
0,0,0,0,0,0,0,0,0,0,35,41,0,0,0,0,0,0,0,42,35,0,0,0,0,0,0,0,0,0
0,0,0,0,0,0,0,0,0,0,0,0,35,35,35,35,35,35,35,0,0,0,0,0,0,0,0,0,0,0
endlayer

layer
0,0,0,0,0,0,0,0,0,0,0,0,36,36,36,36,36,36,40,0,0,0,0,0,0,0,0,0,0,0
0,0,0,0,0,0,0,0,0,0,36,40,0,0,0,0,0,0,0,38,40,0,0,0,0,0,0,0,0,0
0,0,0,0,0,0,0,0,40,0,0,0,0,0,0,0,0,0,0,0,0,37,36,0,0,0,0,0,0,0
0,0,0,0,0,0,0,36,0,0,0,0,0,0,0,0,0,0,0,0,0,0,0,38,0,0,0,0,0,0
0,0,0,0,0,0,36,0,0,0,0,0,0,0,0,0,0,0,0,0,0,0,0,0,38,0,0,0,0,0
0,0,0,0,0,40,0,0,0,0,0,0,0,0,0,0,0,0,0,0,0,0,0,0,0,37,0,0,0,0
0,0,0,0,34,0,0,0,0,0,0,0,0,0,0,0,0,0,0,0,0,0,0,0,0,0,38,0,0,0
0,0,0,0,36,0,0,0,0,0,0,0,0,0,0,0,0,0,0,0,0,0,0,0,0,0,44,0,0,0
0,0,0,34,0,0,0,0,0,0,0,0,0,0,0,0,0,0,0,0,0,0,0,0,0,0,0,38,0,0
0,0,0,34,0,0,0,0,0,0,0,0,0,0,0,0,0,0,0,0,0,0,0,0,0,0,0,43,0,0
0,0,34,0,0,0,0,0,0,0,0,0,0,0,31,31,31,0,0,0,0,0,0,0,0,0,0,0,38,0
0,0,34,0,0,0,0,0,0,0,0,0,0,31,31,31,31,31,0,0,0,0,0,0,0,0,0,0,38,0
0,0,45,0,0,0,0,0,0,0,0,0,31,31,31,31,31,31,31,0,0,0,0,0,0,0,0,0,38,0
0,0,34,0,0,0,0,0,0,0,0,0,31,31,31,33,31,31,31,0,0,0,0,0,0,0,0,0,38,0
0,0,34,0,0,0,0,0,0,0,0,0,31,31,31,31,31,31,31,0,0,0,0,0,0,0,0,0,38,0
0,0,34,0,0,0,0,0,0,0,0,0,0,31,31,31,31,31,0,0,0,0,0,0,0,0,0,0,38,0
0,0,34,0,0,0,0,0,0,0,0,0,0,0,31,31,31,0,0,0,0,0,0,0,0,0,0,0,43,0
0,0,0,45,0,0,0,0,0,0,0,0,0,0,0,0,0,0,0,0,0,0,0,0,0,0,46,42,0,0
0,0,0,34,46,46,0,0,0,0,0,0,0,0,0,0,0,0,0,0,0,0,0,0,0,0,0,38,0,0
0,0,0,0,45,0,0,0,0,0,0,0,0,0,0,0,0,0,0,0,0,0,0,0,0,0,38,0,0,0
0,0,0,0,34,0,0,0,0,0,0,0,0,0,0,0,0,0,0,0,0,0,0,0,0,0,38,0,0,0
0,0,0,0,0,34,0,0,0,0,0,0,0,0,0,0,0,0,0,0,0,0,0,0,0,43,0,0,0,0
0,0,0,0,0,0,0,0,0,0,0,0,0,0,0,0,0,0,0,0,0,0,0,0,0,0,0,0,0,0
0,0,0,0,0,0,0,41,0,0,0,0,0,0,0,0,0,0,0,0,0,0,0,35,0,0,0,0,0,0
0,0,0,0,0,0,0,0,42,34,0,0,0,0,0,0,0,0,46,0,0,35,35,0,0,0,0,0,0,0
0,0,0,0,0,0,0,0,0,0,35,41,0,0,0,0,0,0,46,42,35,0,0,0,0,0,0,0,0,0
0,0,0,0,0,0,0,0,0,0,0,0,35,35,35,35,35,35,35,0,0,0,0,0,0,0,0,0,0,0
endlayer

layer
0,0,0,0,0,0,0,0,0,0,0,0,36,36,36,36,36,36,40,0,0,0,0,0,0,0,0,0,0,0
0,0,0,0,0,0,0,0,0,0,36,40,47,47,47,47,47,47,47,38,40,0,0,0,0,0,0,0,0,0
0,0,0,0,0,0,0,0,40,40,47,47,48,48,48,48,48,48,48,47,47,37,36,0,0,0,0,0,0,0
0,0,0,0,0,0,0,36,47,47,48,48,48,48,48,48,48,48,48,48,48,47,47,38,0,0,0,0,0,0
0,0,0,0,0,0,36,47,48,48,48,48,48,48,48,48,48,48,48,48,48,48,48,47,38,0,0,0,0,0
0,0,0,0,0,40,47,51,48,48,48,48,48,48,48,48,48,48,48,48,48,48,48,50,49,37,0,0,0,0
0,0,0,0,34,47,52,52,50,48,48,48,48,48,48,48,48,48,48,48,48,48,51,52,52,49,38,0,0,0
0,0,0,0,36,47,52,52,52,51,48,48,48,48,48,48,48,48,48,48,48,50,52,52,52,49,44,0,0,0
0,0,0,34,47,52,52,52,52,52,50,48,48,48,48,48,48,48,48,48,51,52,52,52,52,52,47,38,0,0
0,0,0,34,47,52,52,52,52,52,52,51,48,48,48,48,48,48,48,50,52,52,52,52,52,52,47,43,0,0
0,0,34,47,52,52,52,52,52,52,52,52,50,48,48,48,48,48,51,52,52,52,52,52,52,52,52,47,38,0
0,0,34,47,52,52,52,52,52,52,52,52,52,51,48,48,48,50,52,52,52,52,52,52,52,52,52,47,38,0
0,0,45,47,52,52,52,52,52,52,52,52,52,52,50,48,51,52,52,52,52,52,52,52,52,52,52,47,38,0
0,0,34,47,52,52,52,52,52,52,52,52,52,52,52,31,52,52,52,52,52,52,52,52,52,52,52,47,38,0
0,0,34,47,52,52,52,52,52,52,52,52,52,52,51,48,50,52,52,52,52,52,52,52,52,52,52,47,38,0
0,0,34,47,52,52,52,52,52,52,52,52,52,50,48,48,48,51,52,52,52,52,52,52,52,52,52,47,38,0
0,0,34,47,52,52,52,52,52,52,52,52,51,48,48,48,48,48,50,52,52,52,52,52,52,52,52,47,43,0
0,0,0,45,47,52,52,52,52,52,52,50,48,48,48,48,48,48,48,51,52,52,52,52,52,52,47,42,0,0
0,0,0,34,47,52,52,52,52,52,51,48,48,48,48,48,48,48,48,48,50,52,52,52,52,52,47,38,0,0
0,0,0,0,45,47,52,52,52,50,48,48,48,48,48,48,48,48,48,48,48,51,52,52,52,47,38,0,0,0
0,0,0,0,34,47,52,52,51,48,48,48,48,48,48,48,48,48,48,48,48,48,50,52,52,47,38,0,0,0
0,0,0,0,0,34,47,50,48,48,48,48,48,48,48,48,48,48,48,48,48,48,48,51,47,43,0,0,0,0
0,0,0,0,0,0,0,47,48,48,48,48,48,48,48,48,48,48,48,48,48,48,48,49,0,0,0,0,0,0
0,0,0,0,0,0,0,41,47,47,48,48,48,48,48,48,48,48,48,48,48,47,47,35,0,0,0,0,0,0
0,0,0,0,0,0,0,0,42,34,47,47,48,48,48,48,48,48,48,47,47,35,35,0,0,0,0,0,0,0
0,0,0,0,0,0,0,0,0,0,35,41,47,47,47,47,47,47,47,42,35,0,0,0,0,0,0,0,0,0
0,0,0,0,0,0,0,0,0,0,0,0,35,35,35,35,35,35,35,0,0,0,0,0,0,0,0,0,0,0
endlayer

layer
0,0,0,0,0,0,0,0,0,0,0,0,36,36,36,40,36,36,40,0,0,0,0,0,0,0,0,0,0,0
0,0,0,0,0,0,0,0,0,0,36,40,0,0,0,0,0,0,0,38,40,0,0,0,0,0,0,0,0,0
0,0,0,0,0,0,0,0,36,40,0,0,47,47,47,47,47,47,47,0,0,38,36,0,0,0,0,0,0,0
0,0,0,0,0,0,0,36,0,0,47,47,53,0,0,0,0,0,53,47,47,0,0,38,0,0,0,0,0,0
0,0,0,0,0,0,0,0,47,47,53,53,0,0,0,0,0,0,0,53,53,47,47,0,0,0,0,0,0,0
0,0,0,0,0,40,0,47,0,0,0,0,0,0,0,0,0,0,0,0,0,0,0,47,0,38,0,0,0,0
0,0,0,0,34,0,47,0,0,0,0,0,0,0,0,0,0,0,0,0,0,0,0,0,47,0,38,0,0,0
0,0,0,0,36,0,47,0,0,0,0,0,0,0,0,0,0,0,0,0,0,0,0,0,47,0,44,0,0,0
0,0,0,45,0,47,53,0,0,0,0,0,0,0,0,0,0,0,0,0,0,0,0,0,53,47,43,38,0,0
0,0,0,34,0,47,53,0,0,0,0,0,0,0,0,0,0,0,0,0,0,0,0,0,53,47,0,43,0,0
0,0,34,0,47,53,0,0,0,0,0,0,0,0,0,0,0,0,0,0,0,0,0,0,0,53,47,0,38,0
0,0,34,0,47,0,0,0,0,0,0,0,0,0,0,0,0,0,0,0,0,0,0,0,0,0,47,0,38,0
0,0,45,0,47,0,0,0,0,0,0,0,0,0,0,0,0,0,0,0,0,0,0,0,0,0,47,0,38,0
0,0,34,0,47,0,0,0,0,0,0,0,0,0,0,0,0,0,0,0,0,0,0,0,0,0,47,0,43,0
0,0,45,0,47,0,0,0,0,0,0,0,0,0,0,0,0,0,0,0,0,0,0,0,0,0,47,0,38,0
0,0,45,0,47,0,0,0,0,0,0,0,0,0,0,0,0,0,0,0,0,0,0,0,0,0,47,0,38,0
0,0,34,0,47,53,0,0,0,0,0,0,0,0,0,0,0,0,0,0,0,0,0,0,0,53,47,0,43,0
0,0,0,45,0,47,53,0,0,0,0,0,0,0,0,0,0,0,0,0,0,0,0,0,53,47,0,42,0,0
0,0,0,34,0,47,53,0,0,0,0,0,0,0,0,0,0,0,0,0,0,0,0,0,53,47,0,38,0,0
0,0,0,0,45,0,47,0,0,0,0,0,0,0,0,0,0,0,0,0,0,0,0,0,47,0,43,0,0,0
0,0,0,0,34,45,47,0,0,0,0,0,0,0,0,0,0,0,0,0,0,0,0,0,47,0,38,0,0,0
0,0,0,0,0,45,0,47,0,0,0,0,0,0,0,0,0,0,0,0,0,0,0,47,0,43,0,0,0,0
0,0,0,0,0,0,0,0,47,47,53,53,0,0,0,0,0,0,0,53,53,47,47,0,0,0,0,0,0,0
0,0,0,0,0,0,0,35,0,0,47,47,53,0,0,0,0,0,53,47,47,0,0,35,0,0,0,0,0,0
0,0,0,0,0,0,0,0,42,45,0,0,47,47,47,47,47,47,47,0,0,35,42,0,0,0,0,0,0,0
0,0,0,0,0,0,0,0,0,0,42,35,0,0,0,0,0,0,42,42,35,0,0,0,0,0,0,0,0,0
0,0,0,0,0,0,0,0,0,0,0,0,35,35,42,35,42,35,42,0,0,0,0,0,0,0,0,0,0,0
endlayer

layer
0,0,0,0,0,0,0,0,0,0,0,0,36,36,36,40,36,36,40,0,0,0,0,0,0,0,0,0,0,0
0,0,0,0,0,0,0,0,0,0,36,40,0,0,0,0,0,0,0,38,40,0,0,0,0,0,0,0,0,0
0,0,0,0,0,0,0,0,36,40,0,0,0,0,0,0,0,0,0,0,0,38,36,0,0,0,0,0,0,0
0,0,0,0,0,0,0,36,0,0,0,0,53,0,0,0,0,0,53,0,0,0,0,38,0,0,0,0,0,0
0,0,0,0,0,0,0,0,0,0,53,53,0,0,0,0,0,0,0,53,53,0,0,0,0,0,0,0,0,0
0,0,0,0,0,40,0,0,0,0,0,0,0,0,0,0,0,0,0,0,0,0,0,0,0,38,0,0,0,0
0,0,0,0,34,0,0,0,0,0,0,0,0,0,0,0,0,0,0,0,0,0,0,0,0,0,38,0,0,0
0,0,0,0,36,0,0,0,0,0,0,0,0,0,0,0,0,0,0,0,0,0,0,0,0,0,44,0,0,0
0,0,0,45,0,0,53,0,0,0,0,0,0,0,0,0,0,0,0,0,0,0,0,0,53,0,0,38,0,0
0,0,0,34,0,0,53,0,0,0,0,0,0,0,0,0,0,0,0,0,0,0,0,0,53,0,0,43,0,0
0,0,34,0,0,53,0,0,0,0,0,0,0,0,0,0,0,0,0,0,0,0,0,0,0,53,0,0,38,0
0,0,34,0,0,0,0,0,0,0,0,0,0,0,0,0,0,0,0,0,0,0,0,0,0,0,0,0,38,0
0,0,45,0,0,0,0,0,0,0,0,0,0,0,0,0,0,0,0,0,0,0,0,0,0,0,0,0,38,0
0,0,34,0,0,0,0,0,0,0,0,0,0,0,0,0,0,0,0,0,0,0,0,0,0,0,0,0,43,0
0,0,45,0,0,0,0,0,0,0,0,0,0,0,0,0,0,0,0,0,0,0,0,0,0,0,0,0,38,0
0,0,45,0,0,0,0,0,0,0,0,0,0,0,0,0,0,0,0,0,0,0,0,0,0,0,0,0,38,0
0,0,34,0,0,53,0,0,0,0,0,0,0,0,0,0,0,0,0,0,0,0,0,0,0,53,0,0,43,0
0,0,0,45,0,0,53,0,0,0,0,0,0,0,0,0,0,0,0,0,0,0,0,0,53,0,0,42,0,0
0,0,0,34,0,0,53,0,0,0,0,0,0,0,0,0,0,0,0,0,0,0,0,0,53,0,0,38,0,0
0,0,0,0,45,0,0,0,0,0,0,0,0,0,0,0,0,0,0,0,0,0,0,0,0,0,43,0,0,0
0,0,0,0,34,0,0,0,0,0,0,0,0,0,0,0,0,0,0,0,0,0,0,0,0,0,38,0,0,0
0,0,0,0,0,45,0,0,0,0,0,0,0,0,0,0,0,0,0,0,0,0,0,0,0,43,0,0,0,0
0,0,0,0,0,0,0,0,0,0,53,53,0,0,0,0,0,0,0,53,53,0,0,0,0,0,0,0,0,0
0,0,0,0,0,0,0,35,0,0,0,0,53,0,0,0,0,0,53,0,0,0,0,35,0,0,0,0,0,0
0,0,0,0,0,0,0,0,42,45,0,0,0,0,0,0,0,0,0,0,0,35,42,0,0,0,0,0,0,0
0,0,0,0,0,0,0,0,0,0,42,35,0,0,0,0,0,0,0,42,35,0,0,0,0,0,0,0,0,0
0,0,0,0,0,0,0,0,0,0,0,0,35,35,42,35,42,35,42,0,0,0,0,0,0,0,0,0,0,0
endlayer

layer
0,0,0,0,0,0,0,0,0,0,0,0,36,36,36,40,36,36,40,0,0,0,0,0,0,0,0,0,0,0
0,0,0,0,0,0,0,0,0,0,36,40,0,0,0,0,0,0,0,38,40,0,0,0,0,0,0,0,0,0
0,0,0,0,0,0,0,0,36,40,0,0,0,0,0,0,0,0,0,0,0,38,36,0,0,0,0,0,0,0
0,0,0,0,0,0,0,36,0,0,0,0,57,56,0,0,0,55,54,0,0,0,0,38,0,0,0,0,0,0
0,0,0,0,0,0,0,0,0,55,54,0,0,0,0,0,0,0,0,0,57,56,0,0,0,0,0,0,0,0
0,0,0,0,0,40,0,0,0,0,0,0,0,0,0,0,0,0,0,0,0,0,0,0,0,38,0,0,0,0
0,0,0,0,34,0,0,0,0,0,0,0,0,0,0,0,0,0,0,0,0,0,0,0,0,0,38,0,0,0
0,0,0,0,36,0,58,0,0,0,0,0,0,0,0,0,0,0,0,0,0,0,0,0,58,0,44,0,0,0
0,0,0,45,0,0,59,0,0,0,0,0,0,0,0,0,0,0,0,0,0,0,0,0,59,0,0,38,0,0
0,0,0,34,0,0,0,0,0,0,0,0,0,0,0,0,0,0,0,0,0,0,0,0,0,0,0,43,0,0
0,0,34,0,0,60,0,0,0,0,0,0,0,0,0,0,0,0,0,0,0,0,0,0,0,60,0,0,38,0
0,0,34,0,0,61,0,0,0,0,0,0,0,0,0,0,0,0,0,0,0,0,0,0,0,61,0,0,38,0
0,0,45,0,0,0,0,0,0,0,0,0,0,0,0,0,0,0,0,0,0,0,0,0,0,0,0,0,38,0
0,0,34,0,0,0,0,0,0,0,0,0,0,0,0,0,0,0,0,0,0,0,0,0,0,0,0,0,43,0
0,0,45,0,0,0,0,0,0,0,0,0,0,0,0,0,0,0,0,0,0,0,0,0,0,0,0,0,38,0
0,0,45,0,0,58,0,0,0,0,0,0,0,0,0,0,0,0,0,0,0,0,0,0,0,58,0,0,38,0
0,0,34,0,0,59,0,0,0,0,0,0,0,0,0,0,0,0,0,0,0,0,0,0,0,59,0,0,43,0
0,0,0,45,0,0,0,0,0,0,0,0,0,0,0,0,0,0,0,0,0,0,0,0,0,0,0,42,0,0
0,0,0,34,0,0,60,0,0,0,0,0,0,0,0,0,0,0,0,0,0,0,0,0,60,0,0,38,0,0
0,0,0,0,45,0,61,0,0,0,0,0,0,0,0,0,0,0,0,0,0,0,0,0,61,0,43,0,0,0
0,0,0,0,34,0,0,0,0,0,0,0,0,0,0,0,0,0,0,0,0,0,0,0,0,0,38,0,0,0
0,0,0,0,0,45,0,0,0,0,0,0,0,0,0,0,0,0,0,0,0,0,0,0,0,43,0,0,0,0
0,0,0,0,0,0,0,0,0,55,54,0,0,0,0,0,0,0,0,0,57,56,0,0,0,0,0,0,0,0
0,0,0,0,0,0,0,35,0,0,0,0,57,56,0,0,0,55,54,0,0,0,0,35,0,0,0,0,0,0
0,0,0,0,0,0,0,0,42,45,0,0,0,0,0,0,0,0,0,0,0,35,42,0,0,0,0,0,0,0
0,0,0,0,0,0,0,0,0,0,42,35,0,0,0,0,0,0,0,42,35,0,0,0,0,0,0,0,0,0
0,0,0,0,0,0,0,0,0,0,0,0,35,35,42,35,42,35,42,0,0,0,0,0,0,0,0,0,0,0
endlayer

layer
0,0,0,0,0,0,0,0,0,0,0,0,36,36,36,40,36,36,40,0,0,0,0,0,0,0,0,0,0,0
0,0,0,0,0,0,0,0,0,0,36,40,0,0,0,62,0,0,0,38,40,0,0,0,0,0,0,0,0,0
0,0,0,0,0,0,0,0,36,40,0,0,0,0,62,62,62,0,0,0,0,38,36,0,0,0,0,0,0,0
0,0,0,0,0,0,0,36,0,0,0,0,0,57,56,62,55,54,0,0,0,0,0,38,0,0,0,0,0,0
0,0,0,0,0,0,62,62,55,54,0,0,0,0,0,0,0,0,0,0,0,57,56,62,62,0,0,0,0,0
0,0,0,0,0,40,62,0,0,0,0,0,0,0,0,0,0,0,0,0,0,0,0,0,62,38,0,0,0,0
0,0,0,0,34,0,58,0,0,0,0,0,0,0,0,0,0,0,0,0,0,0,0,0,58,0,38,0,0,0
0,0,0,0,36,0,59,0,0,0,0,0,0,0,0,0,0,0,0,0,0,0,0,0,59,0,44,0,0,0
0,0,0,45,0,0,0,0,0,0,0,0,0,0,0,0,0,0,0,0,0,0,0,0,0,0,0,38,0,0
0,0,0,34,0,0,0,0,0,0,0,0,0,0,0,0,0,0,0,0,0,0,0,0,0,0,0,43,0,0
0,0,34,0,0,0,0,0,0,0,0,0,0,0,0,0,0,0,0,0,0,0,0,0,0,0,0,0,38,0
0,0,34,0,0,60,0,0,0,0,0,0,0,0,0,0,0,0,0,0,0,0,0,0,0,60,0,0,38,0
0,0,45,0,62,61,0,0,0,0,0,0,0,0,0,0,0,0,0,0,0,0,0,0,0,61,62,0,38,0
0,0,34,62,62,62,0,0,0,0,0,0,0,0,0,0,0,0,0,0,0,0,0,0,0,62,62,62,43,0
0,0,45,0,62,58,0,0,0,0,0,0,0,0,0,0,0,0,0,0,0,0,0,0,0,58,62,0,38,0
0,0,45,0,0,59,0,0,0,0,0,0,0,0,0,0,0,0,0,0,0,0,0,0,0,59,0,0,38,0
0,0,34,0,0,0,0,0,0,0,0,0,0,0,0,0,0,0,0,0,0,0,0,0,0,0,0,0,43,0
0,0,0,45,0,0,0,0,0,0,0,0,0,0,0,0,0,0,0,0,0,0,0,0,0,0,0,42,0,0
0,0,0,34,0,0,0,0,0,0,0,0,0,0,0,0,0,0,0,0,0,0,0,0,0,0,0,38,0,0
0,0,0,0,45,0,60,0,0,0,0,0,0,0,0,0,0,0,0,0,0,0,0,0,60,0,43,0,0,0
0,0,0,0,34,0,61,0,0,0,0,0,0,0,0,0,0,0,0,0,0,0,0,0,61,0,38,0,0,0
0,0,0,0,0,45,62,0,0,0,0,0,0,0,0,0,0,0,0,0,0,0,0,0,62,43,0,0,0,0
0,0,0,0,0,0,62,62,55,54,0,0,0,0,0,0,0,0,0,0,0,57,56,62,62,0,0,0,0,0
0,0,0,0,0,0,0,35,0,0,0,0,0,57,62,62,55,54,0,0,0,0,0,35,0,0,0,0,0,0
0,0,0,0,0,0,0,0,42,45,0,0,0,0,62,62,62,0,0,0,0,35,42,0,0,0,0,0,0,0
0,0,0,0,0,0,0,0,0,0,42,35,0,0,0,62,0,0,0,42,35,0,0,0,0,0,0,0,0,0
0,0,0,0,0,0,0,0,0,0,0,0,35,35,42,35,42,35,42,0,0,0,0,0,0,0,0,0,0,0
endlayer

layer
0,0,0,0,0,0,0,0,0,0,0,0,36,36,36,40,36,36,40,0,0,0,0,0,0,0,0,0,0,0
0,0,0,0,0,0,0,0,0,0,36,40,47,47,47,47,47,47,47,38,40,0,0,0,0,0,0,0,0,0
0,0,0,0,0,0,0,0,36,40,47,47,0,0,0,0,0,0,0,47,47,38,36,0,0,0,0,0,0,0
0,0,0,0,0,0,0,36,47,47,0,0,0,0,0,0,0,0,0,0,0,47,47,38,0,0,0,0,0,0
0,0,0,0,0,0,36,47,0,0,0,0,0,0,0,0,0,0,0,0,0,0,0,47,38,0,0,0,0,0
0,0,0,0,0,40,47,0,0,0,0,0,0,0,0,0,0,0,0,0,0,0,0,0,47,38,0,0,0,0
0,0,0,0,34,47,0,0,0,0,0,0,0,0,0,0,0,0,0,0,0,0,0,0,0,47,38,0,0,0
0,0,0,0,36,47,0,0,0,0,0,0,0,0,0,0,0,0,0,0,0,0,0,0,0,47,44,0,0,0
0,0,0,45,47,0,0,0,0,0,0,0,0,0,0,0,0,0,0,0,0,0,0,0,0,0,47,38,0,0
0,0,0,34,47,0,0,0,0,0,0,0,0,0,0,0,0,0,0,0,0,0,0,0,0,0,47,43,0,0
0,0,34,47,0,0,0,0,0,0,0,0,0,0,0,0,0,0,0,0,0,0,0,0,0,0,0,47,38,0
0,0,34,47,0,0,0,0,0,0,0,0,0,0,0,0,0,0,0,0,0,0,0,0,0,0,0,47,38,0
0,0,45,47,0,0,0,0,0,0,0,0,0,0,0,0,0,0,0,0,0,0,0,0,0,0,0,47,38,0
0,0,34,47,0,0,0,0,0,0,0,0,0,0,0,0,0,0,0,0,0,0,0,0,0,0,0,47,43,0
0,0,45,47,0,0,0,0,0,0,0,0,0,0,0,0,0,0,0,0,0,0,0,0,0,0,0,47,38,0
0,0,45,47,0,0,0,0,0,0,0,0,0,0,0,0,0,0,0,0,0,0,0,0,0,0,0,47,38,0
0,0,34,47,0,0,0,0,0,0,0,0,0,0,0,0,0,0,0,0,0,0,0,0,0,0,0,47,43,0
0,0,0,45,47,0,0,0,0,0,0,0,0,0,0,0,0,0,0,0,0,0,0,0,0,0,47,42,0,0
0,0,0,34,47,0,0,0,0,0,0,0,0,0,0,0,0,0,0,0,0,0,0,0,0,0,47,38,0,0
0,0,0,0,45,47,0,0,0,0,0,0,0,0,0,0,0,0,0,0,0,0,0,0,0,47,43,0,0,0
0,0,0,0,34,47,0,0,0,0,0,0,0,0,0,0,0,0,0,0,0,0,0,0,0,47,38,0,0,0
0,0,0,0,0,45,47,0,0,0,0,0,0,0,0,0,0,0,0,0,0,0,0,0,47,43,0,0,0,0
0,0,0,0,0,0,35,47,0,0,0,0,0,0,0,0,0,0,0,0,0,0,0,47,35,0,0,0,0,0
0,0,0,0,0,0,0,35,47,47,0,0,0,0,0,0,0,0,0,0,0,47,47,35,0,0,0,0,0,0
0,0,0,0,0,0,0,0,42,45,47,47,0,0,0,0,0,0,0,47,47,35,42,0,0,0,0,0,0,0
0,0,0,0,0,0,0,0,0,0,42,35,47,47,47,47,47,47,47,42,35,0,0,0,0,0,0,0,0,0
0,0,0,0,0,0,0,0,0,0,0,0,35,35,42,35,42,35,42,0,0,0,0,0,0,0,0,0,0,0
endlayer

layer
0,0,0,0,0,0,0,0,0,0,0,0,36,36,36,40,0,36,40,0,0,0,0,0,0,0,0,0,0,0
0,0,0,0,0,0,0,0,0,0,36,0,53,53,53,53,53,53,53,38,40,0,0,0,0,0,0,0,0,0
0,0,0,0,0,0,0,0,36,40,53,53,0,0,0,0,0,0,0,53,53,38,36,0,0,0,0,0,0,0
0,0,0,0,0,0,0,36,53,53,0,0,0,0,0,0,0,0,0,0,0,53,53,38,0,0,0,0,0,0
0,0,0,0,0,0,36,53,0,0,0,0,0,0,0,0,0,0,0,0,0,0,0,53,38,0,0,0,0,0
0,0,0,0,0,40,53,0,0,0,0,0,0,0,0,0,0,0,0,0,0,0,0,0,53,38,0,0,0,0
0,0,0,0,34,53,0,0,0,0,0,0,0,0,0,0,0,0,0,0,0,0,0,0,0,53,38,0,0,0
0,0,0,0,36,53,0,0,0,0,0,0,0,0,0,0,0,0,0,0,0,0,0,0,0,53,44,0,0,0
0,0,0,45,53,0,0,0,0,0,0,0,0,0,0,0,0,0,0,0,0,0,0,0,0,0,53,38,0,0
0,0,0,34,53,0,0,0,0,0,0,0,0,0,0,0,0,0,0,0,0,0,0,0,0,0,53,43,0,0
0,0,34,53,0,0,0,0,0,0,0,0,0,0,0,0,0,0,0,0,0,0,0,0,0,0,0,53,38,0
0,0,34,53,0,0,0,0,0,0,0,0,0,0,0,0,0,0,0,0,0,0,0,0,0,0,0,53,38,0
0,0,0,53,0,0,0,0,0,0,0,0,0,0,0,0,0,0,0,0,0,0,0,0,0,0,0,53,38,0
0,0,34,53,0,0,0,0,0,0,0,0,0,0,0,0,0,0,0,0,0,0,0,0,0,0,0,53,43,0
0,0,45,53,0,0,0,0,0,0,0,0,0,0,0,0,0,0,0,0,0,0,0,0,0,0,0,53,38,0
0,0,0,53,0,0,0,0,0,0,0,0,0,0,0,0,0,0,0,0,0,0,0,0,0,0,0,53,38,0
0,0,34,53,0,0,0,0,0,0,0,0,0,0,0,0,0,0,0,0,0,0,0,0,0,0,0,53,0,0
0,0,0,35,53,0,0,0,0,0,0,0,0,0,0,0,0,0,0,0,0,0,0,0,0,0,53,42,0,0
0,0,0,34,53,0,0,0,0,0,0,0,0,0,0,0,0,0,0,0,0,0,0,0,0,0,53,38,0,0
0,0,0,0,45,53,0,0,0,0,0,0,0,0,0,0,0,0,0,0,0,0,0,0,0,53,43,0,0,0
0,0,0,0,34,53,0,0,0,0,0,0,0,0,0,0,0,0,0,0,0,0,0,0,0,53,38,0,0,0
0,0,0,0,0,45,53,0,0,0,0,0,0,0,0,0,0,0,0,0,0,0,0,0,53,0,0,0,0,0
0,0,0,0,0,0,35,53,0,0,0,0,0,0,0,0,0,0,0,0,0,0,0,53,35,0,0,0,0,0
0,0,0,0,0,0,0,35,53,53,0,0,0,0,0,0,0,0,0,0,0,53,53,35,0,0,0,0,0,0
0,0,0,0,0,0,0,0,42,45,53,53,0,0,0,0,0,0,0,53,53,35,42,0,0,0,0,0,0,0
0,0,0,0,0,0,0,0,0,0,42,35,53,53,53,53,53,53,53,0,35,0,0,0,0,0,0,0,0,0
0,0,0,0,0,0,0,0,0,0,0,0,35,35,0,35,42,35,0,0,0,0,0,0,0,0,0,0,0,0
endlayer

layer
0,0,0,0,0,0,0,0,0,0,0,0,0,0,0,0,0,0,0,0,0,0,0,0,0,0,0,0,0,0
0,0,0,0,0,0,0,0,0,0,0,0,60,60,60,60,60,60,60,0,0,0,0,0,0,0,0,0,0,0
0,0,0,0,0,0,0,0,0,0,60,60,61,61,61,61,61,61,61,60,60,0,0,0,0,0,0,0,0,0
0,0,0,0,0,0,0,0,60,60,61,61,0,0,0,0,0,0,0,61,61,60,60,0,0,0,0,0,0,0
0,0,0,0,0,0,0,60,61,61,0,0,0,0,0,0,0,0,0,0,0,61,61,60,0,0,0,0,0,0
0,0,0,0,0,0,57,62,0,0,0,0,0,0,0,0,0,0,0,0,0,0,0,62,54,0,0,0,0,0
0,0,0,0,0,57,56,0,0,0,0,0,0,0,0,0,0,0,0,0,0,0,0,0,55,54,0,0,0,0
0,0,0,0,0,57,56,0,0,0,0,0,0,0,0,0,0,0,0,0,0,0,0,0,55,54,0,0,0,0
0,0,0,0,57,56,0,0,0,0,0,0,0,0,0,0,0,0,0,0,0,0,0,0,0,55,54,0,0,0
0,0,0,0,57,56,0,0,0,0,0,0,0,0,0,0,0,0,0,0,0,0,0,0,0,55,54,0,0,0
0,0,0,57,56,0,0,0,0,0,0,0,0,0,0,0,0,0,0,0,0,0,0,0,0,0,55,54,0,0
0,0,0,57,56,0,0,0,0,0,0,0,0,0,0,0,0,0,0,0,0,0,0,0,0,0,55,54,0,0
0,0,0,57,56,0,0,0,0,0,0,0,0,0,0,0,0,0,0,0,0,0,0,0,0,0,55,54,0,0
0,0,0,57,56,0,0,0,0,0,0,0,0,0,0,0,0,0,0,0,0,0,0,0,0,0,55,54,0,0
0,0,0,57,56,0,0,0,0,0,0,0,0,0,0,0,0,0,0,0,0,0,0,0,0,0,55,54,0,0
0,0,0,57,56,0,0,0,0,0,0,0,0,0,0,0,0,0,0,0,0,0,0,0,0,0,55,54,0,0
0,0,0,57,56,0,0,0,0,0,0,0,0,0,0,0,0,0,0,0,0,0,0,0,0,0,55,54,0,0
0,0,0,0,57,56,0,0,0,0,0,0,0,0,0,0,0,0,0,0,0,0,0,0,0,55,54,0,0,0
0,0,0,0,57,56,0,0,0,0,0,0,0,0,0,0,0,0,0,0,0,0,0,0,0,55,54,0,0,0
0,0,0,0,0,57,56,0,0,0,0,0,0,0,0,0,0,0,0,0,0,0,0,0,55,54,0,0,0,0
0,0,0,0,0,57,56,0,0,0,0,0,0,0,0,0,0,0,0,0,0,0,0,0,55,54,0,0,0,0
0,0,0,0,0,0,57,62,0,0,0,0,0,0,0,0,0,0,0,0,0,0,0,62,54,0,0,0,0,0
0,0,0,0,0,0,0,59,58,58,0,0,0,0,0,0,0,0,0,0,0,58,58,59,0,0,0,0,0,0
0,0,0,0,0,0,0,0,59,59,58,58,0,0,0,0,0,0,0,58,58,59,59,0,0,0,0,0,0,0
0,0,0,0,0,0,0,0,0,0,59,59,58,58,58,58,58,58,58,59,59,0,0,0,0,0,0,0,0,0
0,0,0,0,0,0,0,0,0,0,0,0,59,59,59,59,59,59,59,0,0,0,0,0,0,0,0,0,0,0
0,0,0,0,0,0,0,0,0,0,0,0,0,0,0,0,0,0,0,0,0,0,0,0,0,0,0,0,0,0
endlayer

layer
0,0,0,0,0,0,0,0,0,0,0,0,0,0,0,0,0,0,0,0,0,0,0,0,0,0,0,0,0,0
0,0,0,0,0,0,0,0,0,0,0,0,0,0,0,0,0,0,0,0,0,0,0,0,0,0,0,0,0,0
0,0,0,0,0,0,0,0,0,0,0,0,60,60,60,60,60,60,60,0,0,0,0,0,0,0,0,0,0,0
0,0,0,0,0,0,0,0,0,0,60,60,53,53,53,53,53,53,53,60,60,0,0,0,0,0,0,0,0,0
0,0,0,0,0,0,0,0,60,60,53,53,63,63,63,63,63,63,63,53,53,60,60,0,0,0,0,0,0,0
0,0,0,0,0,0,0,53,53,53,63,63,64,63,64,63,64,63,64,63,63,53,53,53,0,0,0,0,0,0
0,0,0,0,0,0,57,53,63,63,64,63,63,64,63,63,63,64,63,63,64,63,63,53,54,0,0,0,0,0
0,0,0,0,0,0,57,53,63,64,63,63,64,63,63,64,63,63,64,63,63,64,63,53,54,0,0,0,0,0
0,0,0,0,0,57,53,63,64,63,63,64,63,63,64,63,64,63,63,64,63,63,64,63,53,54,0,0,0,0
0,0,0,0,0,57,53,63,63,63,64,63,63,64,63,63,63,64,63,63,64,63,63,63,53,54,0,0,0,0
0,0,0,0,57,53,63,64,63,64,63,63,64,63,63,64,63,63,64,63,63,64,63,64,63,53,54,0,0,0
0,0,0,0,57,53,63,63,64,63,63,64,63,63,64,63,64,63,63,64,63,63,64,63,63,53,54,0,0,0
0,0,0,0,57,53,63,64,63,63,64,63,63,64,63,63,63,64,63,63,64,63,63,64,63,53,54,0,0,0
0,0,0,0,57,53,63,63,63,64,63,63,64,63,63,64,63,63,64,63,63,64,63,63,63,53,54,0,0,0
0,0,0,0,57,53,63,64,63,63,64,63,63,64,63,63,63,64,63,63,64,63,63,64,63,53,54,0,0,0
0,0,0,0,57,53,63,63,64,63,63,64,63,63,64,63,64,63,63,64,63,63,64,63,63,53,54,0,0,0
0,0,0,0,57,53,63,64,63,64,63,63,64,63,63,64,63,63,64,63,63,64,63,64,63,53,54,0,0,0
0,0,0,0,0,57,53,63,63,63,64,63,63,64,63,63,63,64,63,63,64,63,63,63,53,54,0,0,0,0
0,0,0,0,0,57,53,63,64,63,63,64,63,63,64,63,64,63,63,64,63,63,64,63,53,54,0,0,0,0
0,0,0,0,0,0,57,53,63,64,63,63,64,63,63,64,63,63,64,63,63,64,63,53,54,0,0,0,0,0
0,0,0,0,0,0,57,53,63,63,64,63,63,64,63,63,63,64,63,63,64,63,63,53,54,0,0,0,0,0
0,0,0,0,0,0,0,53,53,53,63,63,64,63,64,63,64,63,64,63,63,53,53,53,0,0,0,0,0,0
0,0,0,0,0,0,0,0,59,59,53,53,63,63,63,63,63,63,63,53,53,59,59,0,0,0,0,0,0,0
0,0,0,0,0,0,0,0,0,0,59,59,53,53,53,53,53,53,53,59,59,0,0,0,0,0,0,0,0,0
0,0,0,0,0,0,0,0,0,0,0,0,59,59,59,59,59,59,59,0,0,0,0,0,0,0,0,0,0,0
0,0,0,0,0,0,0,0,0,0,0,0,0,0,0,0,0,0,0,0,0,0,0,0,0,0,0,0,0,0
0,0,0,0,0,0,0,0,0,0,0,0,0,0,0,0,0,0,0,0,0,0,0,0,0,0,0,0,0,0
endlayer

layer
0,0,0,0,0,0,0,0,0,0,0,0,0,0,0,0,0,0,0,0,0,0,0,0,0,0,0,0,0,0
0,0,0,0,0,0,0,0,0,0,0,0,0,0,0,0,0,0,0,0,0,0,0,0,0,0,0,0,0,0
0,0,0,0,0,0,0,0,0,0,0,0,0,0,0,0,0,0,0,0,0,0,0,0,0,0,0,0,0,0
0,0,0,0,0,0,0,0,0,0,0,0,19,19,19,0,0,0,0,0,0,0,0,0,0,0,0,0,0,0
0,0,0,0,0,0,0,0,0,0,0,0,0,0,0,0,0,0,0,0,19,0,0,0,0,0,0,0,0,0
0,0,0,0,0,0,0,0,19,0,0,0,0,0,0,0,0,19,0,0,0,0,0,0,0,0,0,0,0,0
0,0,0,0,0,0,0,0,0,0,0,19,0,0,0,0,0,0,0,0,0,0,0,0,0,0,0,0,0,0
0,0,0,0,0,0,0,0,0,0,0,0,0,0,0,0,0,0,0,0,0,0,0,19,0,0,0,0,0,0
0,0,0,0,0,0,0,0,0,0,0,0,0,0,0,0,0,0,0,0,0,0,0,0,0,0,0,0,0,0
0,0,0,0,0,0,0,0,0,0,0,19,19,0,0,0,0,0,0,0,0,0,0,0,0,0,0,0,0,0
0,0,0,0,0,0,19,0,19,0,0,19,0,0,0,0,0,0,0,0,0,0,0,0,0,0,0,0,0,0
0,0,0,0,0,0,0,0,0,0,0,0,19,0,0,0,0,19,0,0,19,0,0,0,0,0,0,0,0,0
0,0,0,0,0,0,19,0,0,0,0,0,0,0,0,0,0,0,0,19,0,0,0,0,0,0,0,0,0,0
0,0,0,0,0,0,0,0,0,0,0,0,0,0,0,0,0,0,0,0,0,0,0,0,0,0,0,0,0,0
0,0,0,0,0,19,0,0,0,0,0,0,19,0,0,0,0,0,0,0,0,19,0,0,0,0,0,0,0,0
0,0,0,0,0,0,0,0,0,0,0,0,0,0,0,0,0,0,19,0,0,19,0,0,0,0,0,0,0,0
0,0,0,0,0,0,0,0,0,0,0,0,0,0,0,0,0,0,0,0,0,0,0,0,0,0,0,0,0,0
0,0,0,0,0,0,0,0,0,19,0,0,0,0,0,0,0,0,0,0,0,0,0,0,0,0,0,0,0,0
0,0,0,0,0,0,0,0,0,0,19,0,0,0,0,0,0,0,0,0,0,19,0,0,0,0,0,0,0,0
0,0,0,0,0,0,0,0,0,0,0,19,0,0,0,0,0,0,0,0,0,0,0,19,0,0,0,0,0,0
0,0,0,0,0,0,0,0,0,0,0,0,19,0,0,0,0,0,19,0,0,0,0,0,0,0,0,0,0,0
0,0,0,0,0,0,0,0,19,19,0,0,0,0,0,0,0,0,0,0,0,0,0,0,0,0,0,0,0,0
0,0,0,0,0,0,0,0,0,0,0,0,0,0,0,19,0,0,0,0,0,0,0,0,0,0,0,0,0,0
0,0,0,0,0,0,0,0,0,0,0,0,0,0,0,0,19,0,0,0,0,0,0,0,0,0,0,0,0,0
0,0,0,0,0,0,0,0,0,0,0,0,0,0,0,0,0,0,0,0,0,0,0,0,0,0,0,0,0,0
0,0,0,0,0,0,0,0,0,0,0,0,0,0,0,0,0,0,0,0,0,0,0,0,0,0,0,0,0,0
0,0,0,0,0,0,0,0,0,0,0,0,0,0,0,0,0,0,0,0,0,0,0,0,0,0,0,0,0,0
endlayer

