
# Created by Ruins mod version 15.0 Ingame Parser
# authoring Player: SunsOfOld

weight=100
embed_into_distance=1
acceptable_target_blocks=
unacceptable_target_blocks=flowing_water,water,flowing_lava,lava
dimensions=5,19,19
allowable_overhang=0
max_leveling=5
leveling_buffer=0
preserve_water=0
preserve_lava=0
uniqueMinDistance=1000000
preventRotation=1

rule1=0,100,minecraft:grass-0
rule2=0,100,preserveBlock
rule3=0,100,minecraft:dirt-0
rule4=0,100,GardenStuff:moss_brick-4
rule5=0,100,GardenStuff:moss_brick-6
rule6=0,100,ExtrabiomesXL:leaves_2-15
rule7=0,100,ExtrabiomesXL:leaves_2-7
rule8=0,100,minecraft:glowstone-0
rule9=0,100,IInventory;minecraft:chest;harvestcraft:pammangoSapling#1#0#3+harvestcraft:pamlimeSapling#1#0#4+harvestcraft:pamlemonSapling#1#0#5+ExtrabiomesXL:extrabiomes.scarecrow#1#0#13+harvestcraft:stuffedpepperItem#4#0#21+harvestcraft:stuffedpepperItem#4#0#23-5
rule10=0,100,GardenStuff:moss_brick-1

layer
1,1,1,1,1,1,1,1,1,1,1,1,1,1,1,1,1,1,1
1,1,1,2,1,1,1,1,3,1,3,2,2,1,1,1,2,2,1
1,1,1,2,2,2,1,2,4,2,2,2,2,1,2,2,1,2,1
1,1,2,1,2,2,2,2,4,1,1,1,1,2,2,4,1,1,1
1,1,1,1,2,2,1,1,2,2,1,1,1,2,2,2,2,2,1
1,1,2,1,1,1,1,1,2,2,2,1,1,2,2,2,1,1,1
1,1,2,2,1,1,1,1,2,2,1,1,1,2,4,3,4,1,1
1,2,2,2,1,1,1,2,2,2,1,2,2,1,4,4,2,2,1
1,2,1,1,1,2,1,1,1,1,1,2,2,1,1,2,2,2,1
1,1,2,1,2,2,2,1,1,1,1,1,1,2,2,1,1,2,1
1,2,2,1,2,2,2,1,1,2,2,2,2,2,1,1,2,2,1
1,1,2,1,1,2,2,2,1,2,2,1,2,1,1,2,2,2,1
1,2,2,1,1,1,1,1,2,1,1,2,1,1,1,1,2,2,1
1,2,2,2,1,1,1,1,2,2,2,2,2,1,1,2,2,2,1
1,1,2,2,2,1,1,1,2,2,1,1,2,2,2,1,1,2,2
1,1,1,2,2,2,2,2,1,1,1,1,1,2,2,1,1,2,1
1,1,1,1,2,2,2,2,4,1,1,1,1,1,2,2,2,1,1
1,1,1,1,1,2,2,2,5,1,2,2,2,2,2,1,1,1,1
1,1,1,1,1,1,1,1,1,1,1,1,1,1,1,1,1,1,1
endlayer

layer
0,0,0,0,0,0,0,0,0,0,0,0,7,0,0,0,0,6,0
0,0,0,0,0,0,0,0,4,0,4,0,4,0,0,0,6,8,6
0,0,0,0,6,7,0,0,0,0,0,0,0,0,4,0,0,6,0
0,0,0,0,4,0,0,0,0,0,0,0,0,0,0,0,0,0,0
0,0,0,0,0,0,0,0,7,6,0,0,0,6,6,0,4,0,0
0,0,4,0,0,0,0,0,4,9,4,0,0,0,6,0,0,0,0
0,0,0,0,0,0,0,0,7,6,0,0,0,0,0,4,0,0,0
0,7,6,0,0,0,0,0,0,0,0,0,0,0,0,0,4,6,0
0,4,0,0,0,0,0,0,0,0,0,0,4,0,0,0,6,4,0
0,0,0,0,0,7,4,0,0,0,0,0,0,0,0,0,0,0,0
0,4,0,0,6,7,0,0,0,6,6,0,4,0,0,0,0,4,0
0,0,0,0,0,0,4,0,0,6,0,0,0,0,0,0,6,0,0
0,0,0,0,0,0,0,0,0,0,0,0,0,0,0,0,0,0,0
0,0,4,0,0,0,0,0,0,5,0,5,0,0,0,0,5,6,0
0,0,6,6,0,0,0,0,0,0,0,0,6,0,0,0,0,7,0
0,0,0,7,4,0,0,0,0,0,0,0,0,0,4,0,0,0,0
0,0,0,0,0,0,4,0,0,0,0,0,0,0,6,4,0,0,0
0,0,0,0,0,0,6,0,0,0,6,4,4,0,0,0,0,0,0
0,0,0,0,0,0,0,0,0,0,0,0,0,0,0,0,0,0,0
endlayer

layer
0,0,0,0,0,0,0,0,0,0,0,0,6,0,0,0,0,0,0
0,0,0,0,0,0,0,0,0,0,0,0,0,0,0,0,0,6,0
0,0,0,0,0,6,0,0,0,0,0,0,0,0,0,0,0,0,0
0,0,0,0,5,0,0,0,0,0,0,0,0,0,0,0,0,0,0
0,0,0,0,0,0,0,0,6,0,0,0,0,0,0,0,0,0,0
0,0,4,0,0,0,0,0,10,0,5,0,0,0,0,0,0,0,0
0,0,0,0,0,0,0,0,6,0,0,0,0,0,0,0,0,0,0
0,7,0,0,0,0,0,0,0,0,0,0,0,0,0,0,6,0,0
0,5,0,0,0,0,0,0,0,0,0,0,4,0,0,0,0,4,0
0,0,0,0,0,0,10,0,0,0,0,0,0,0,0,0,0,0,0
0,5,0,0,0,0,0,0,0,0,0,0,4,0,0,0,0,0,0
0,0,0,0,0,0,10,0,0,0,0,0,0,0,0,0,0,0,0
0,0,0,0,0,0,0,0,0,0,0,0,0,0,0,0,0,0,0
0,0,10,0,0,0,0,0,0,10,0,10,0,0,0,0,10,0,0
0,0,0,0,0,0,0,0,0,0,0,0,0,0,0,0,0,6,0
0,0,0,0,10,0,0,0,0,0,0,0,0,0,0,0,0,0,0
0,0,0,0,0,0,10,0,0,0,0,0,0,0,0,0,0,0,0
0,0,0,0,0,0,0,0,0,0,0,6,0,0,0,0,0,0,0
0,0,0,0,0,0,0,0,0,0,0,0,0,0,0,0,0,0,0
endlayer

layer
0,0,0,0,0,0,0,0,0,0,0,0,0,0,0,0,0,0,0
0,0,0,0,0,0,0,0,0,0,0,0,0,0,0,0,0,0,0
0,0,0,0,0,0,0,0,0,0,0,0,0,0,0,0,0,0,0
0,0,0,0,10,0,0,0,0,0,0,0,0,0,0,0,0,0,0
0,0,0,0,0,0,0,0,0,0,0,0,0,0,0,0,0,0,0
0,0,10,0,0,0,0,0,10,0,5,0,0,0,0,0,0,0,0
0,0,0,0,0,0,0,0,0,0,0,0,0,0,0,0,0,0,0
0,0,0,0,0,0,0,0,0,0,0,0,0,0,0,0,0,0,0
0,4,0,0,0,0,0,0,0,0,0,0,4,0,0,0,0,0,0
0,0,0,0,0,0,5,0,0,0,0,0,0,0,0,0,0,0,0
0,4,0,0,0,0,0,0,0,0,0,0,0,0,0,0,0,0,0
0,0,0,0,0,0,5,0,0,0,0,0,0,0,0,0,0,0,0
0,0,0,0,0,0,0,0,0,0,0,0,0,0,0,0,0,0,0
0,0,10,0,0,0,0,0,0,10,0,4,0,0,0,0,0,0,0
0,0,0,0,0,0,0,0,0,0,0,0,0,0,0,0,0,0,0
0,0,0,0,5,0,0,0,0,0,0,0,0,0,0,0,0,0,0
0,0,0,0,0,0,0,0,0,0,0,0,0,0,0,0,0,0,0
0,0,0,0,0,0,0,0,0,0,0,0,0,0,0,0,0,0,0
0,0,0,0,0,0,0,0,0,0,0,0,0,0,0,0,0,0,0
endlayer

layer
0,0,0,0,0,0,0,0,0,0,0,0,0,0,0,0,0,0,0
0,0,0,0,0,0,0,0,0,0,0,0,0,0,0,0,0,0,0
0,0,0,0,0,0,0,0,0,0,0,0,0,0,0,0,0,0,0
0,0,0,0,4,0,0,0,0,0,0,0,0,0,0,0,0,0,0
0,0,0,4,0,0,0,0,0,0,0,0,0,0,0,0,0,0,0
0,0,10,0,0,0,0,0,5,5,5,0,0,0,0,0,0,0,0
0,0,0,0,0,0,0,0,0,0,0,0,0,0,0,0,0,0,0
0,0,0,0,0,0,0,0,0,0,0,0,0,0,0,0,0,0,0
0,10,0,0,0,0,0,0,0,0,0,0,0,0,0,0,0,0,0
0,10,0,0,0,0,4,0,0,0,0,0,0,0,0,0,0,0,0
0,5,0,0,0,0,4,0,0,0,0,0,0,0,0,0,0,0,0
0,0,0,0,0,0,4,0,0,0,0,0,0,0,0,0,0,0,0
0,0,0,0,0,0,0,0,0,0,0,0,0,0,0,0,0,0,0
0,0,5,0,0,0,0,0,0,10,10,10,0,0,0,0,0,0,0
0,0,0,4,0,0,0,0,0,0,0,0,0,0,0,0,0,0,0
0,0,0,0,4,0,0,0,0,0,0,0,0,0,0,0,0,0,0
0,0,0,0,0,0,0,0,0,0,0,0,0,0,0,0,0,0,0
0,0,0,0,0,0,0,0,0,0,0,0,0,0,0,0,0,0,0
0,0,0,0,0,0,0,0,0,0,0,0,0,0,0,0,0,0,0
endlayer

