
# Created by Ruins mod version 15.0 Ingame Parser
# authoring Player: SunsOfOld

weight=100
embed_into_distance=2
acceptable_target_blocks=
unacceptable_target_blocks=flowing_water,water,flowing_lava,lava
dimensions=13,22,20
allowable_overhang=0
max_leveling=5
leveling_buffer=0
preserve_water=0
preserve_lava=0
uniqueMinDistance=1000000
preventRotation=1

rule1=0,100,minecraft:grass-0
rule2=0,100,minecraft:dirt-0
rule3=0,100,minecraft:water-9
rule4=0,100,preserveBlock
rule5=0,100,minecraft:water-0
rule6=0,100,dendrology:logs0-0
rule7=0,100,dendrology:logs0-4
rule8=0,100,dendrology:logs0-8
rule9=0,100,ExtrabiomesXL:flower3-7
rule10=0,100,plantmegapack:groundcoverLeavesBRN-0
rule11=0,100,plantmegapack:groundcoverMoss-0
rule12=1,100,StandingSign:Athena:"Overgrown:Greenhouse":Completed-4
rule13=0,100,ExtrabiomesXL:flower2-9
rule14=0,100,plantmegapack:epiphyteSulphurShelf-4
rule15=0,100,plantmegapack:vineSilverveinCreeper-8
rule16=0,100,plantmegapack:vineSilverveinCreeper-1
rule17=0,100,minecraft:double_plant-3
rule18=0,100,ExtrabiomesXL:log2-1
rule19=0,100,ExtrabiomesXL:leaves_2-12
rule20=0,100,BiomesOPlenty:woodenSingleSlab2-0
rule21=0,100,plantmegapack:vineSilverveinCreeper-4
rule22=0,100,minecraft:double_plant-2
rule23=0,100,minecraft:tallgrass-1
rule24=0,100,BiomesOPlenty:mushrooms-4
rule25=0,100,plantmegapack:fungusParasol-0
rule26=0,100,plantmegapack:fungusWeepingMilkCap-0
rule27=0,100,plantmegapack:flowerRose-12
rule28=0,100,plantmegapack:flowerBell-2
rule29=0,100,plantmegapack:jungleLollipopPlant-0
rule30=0,100,plantmegapack:floatingWaterChestnut-0
rule31=0,100,plantmegapack:floatingRedRootFloater-0
rule32=0,100,plantmegapack:riverWrightsWaternymph-0
rule33=0,100,plantmegapack:fungusBlackPowderpuff-0
rule34=0,100,plantmegapack:riverAmazonSword-0
rule35=0,100,plantmegapack:oceanTangle-0
rule36=0,100,harvestcraft:mushroomgarden-0
rule37=0,100,minecraft:log-4
rule38=0,100,plantmegapack:vineSilverveinCreeper-2
rule39=0,100,IInventory;minecraft:chest;minecraft:water_bucket#1#0#0+BiomesOPlenty:flowerBand#1#2#4+plantmegapack:wallBracketWoodDarkOak#1#0#8+dendrology:sapling1#1#3#12+minecraft:enchanted_book#{StoredEnchantments:[0:{id:7s,lvl:3s,},],}#0#13+dendrology:sapling0#1#0#14+VeganOption:seedSunflower#5#0#22-4
rule40=0,100,plantmegapack:epiphyteSulphurShelf-2
rule41=0,100,minecraft:double_plant-10
rule42=0,100,dendrology:salyx_planks-14
rule43=0,100,dendrology:leaves0-4
rule44=0,100,dendrology:leaves0-12
rule45=0,100,chisel:glass_pane-14
rule46=0,100,minecraft:double_plant-8
rule47=0,100,minecraft:double_plant-11
rule48=0,100,plantmegapack:hangingBambooMoso-1
rule49=0,100,plantmegapack:hangingFoliageLGRED-1
rule50=0,100,minecraft:double_plant-9
rule51=0,100,minecraft:water-1
rule52=0,100,plantmegapack:hangingPhilodendron-1
rule53=0,100,plantmegapack:hangingBambooAsper-1
rule54=0,100,plantmegapack:hangingScalyTree-1
rule55=0,100,GardenTrees:thin_log-0
rule56=0,100,plantmegapack:hangingFoliageLGGRN-1
rule57=0,100,GardenStuff:lantern-13
rule58=0,100,plantmegapack:hangingBambooMoso-0
rule59=0,100,plantmegapack:hangingFoliageLGRED-0
rule60=0,100,plantmegapack:hangingPhilodendron-0
rule61=0,100,plantmegapack:hangingBambooAsper-0
rule62=0,100,plantmegapack:floatingWaterLily-0
rule63=0,100,plantmegapack:hangingScalyTree-0
rule64=0,100,plantmegapack:epiphyteSulphurShelf-5
rule65=0,100,plantmegapack:hangingFoliageLGGRN-0
rule66=0,100,plantmegapack:epiphyteArtistsConk-5
rule67=0,100,plantmegapack:epiphyteLargeFootDendrobium-4
rule68=0,100,GardenTrees:thin_log_fence-0
rule69=0,100,BiomesOPlenty:redwoodStairs-7
rule70=0,100,BiomesOPlenty:woodenSingleSlab2-8
rule71=0,100,BiomesOPlenty:redwoodStairs-6
rule72=0,100,GardenStuff:lattice_wood-2
rule73=0,100,plantmegapack:epiphyteKingOrchid-5
rule74=0,100,plantmegapack:wallBracketWoodDarkOak-3
rule75=0,100,plantmegapack:wallBracketWoodDarkOak-2
rule76=0,100,plantmegapack:epiphyteLargeFootDendrobium-3
rule77=0,100,plantmegapack:wallBracketWoodDarkOak-4
rule78=0,100,BiomesOPlenty:logs2-2
rule79=0,100,plantmegapack:epiphyteTurkeyTail-2
rule80=0,100,plantmegapack:epiphyteKingOrchid-2
rule81=0,100,plantmegapack:epiphyteTurkeyTail-3
rule82=0,100,plantmegapack:epiphyteArtistsConk-2
rule83=0,100,plantmegapack:epiphyteSulphurShelf-3
rule84=0,100,plantmegapack:epiphyteArtistsConk-4
rule85=0,100,plantmegapack:epiphyteLargeFootDendrobium-5
rule86=0,100,chisel:glass-3
rule87=0,100,chisel:glass-5
rule88=0,100,chisel:stained_glass_yellow-7

layer
2,2,2,2,2,2,2,2,2,2,2,2,2,2,2,2,2,2,2,1
2,2,2,2,2,2,2,2,2,2,2,2,2,2,2,2,2,2,1,1
2,2,2,2,2,2,2,2,2,2,2,2,2,2,2,1,2,2,1,2
2,2,2,1,2,2,2,2,2,2,1,2,2,2,2,1,1,2,1,1
2,2,2,2,2,2,2,2,2,2,2,2,2,2,2,2,2,2,2,2
2,2,2,2,2,2,2,2,2,2,2,2,2,2,0,2,1,1,2,1
2,2,2,2,2,2,2,2,2,2,2,2,2,2,2,2,2,2,1,2
2,2,2,2,2,2,1,2,2,2,2,2,2,2,2,2,2,1,2,2
2,2,2,2,2,2,2,2,2,2,2,2,2,2,1,1,2,2,2,2
2,2,2,2,2,2,0,0,2,2,2,2,2,2,2,2,2,1,2,2
2,2,2,2,2,2,0,0,2,2,2,2,2,2,2,2,2,2,2,2
2,2,2,2,2,2,3,2,2,2,2,2,2,2,2,2,2,2,2,2
2,2,2,2,2,2,2,2,2,2,2,2,2,2,2,2,2,2,2,2
2,2,2,2,2,2,2,2,2,2,2,2,1,2,2,2,2,2,2,2
2,2,2,2,2,2,2,2,2,2,2,2,2,2,2,2,2,2,2,2
2,2,2,2,2,2,2,2,2,2,2,2,2,2,2,2,1,2,2,2
2,2,2,2,2,2,2,2,2,2,2,2,2,2,2,2,2,1,2,2
2,2,2,2,2,2,2,2,2,2,2,2,2,2,2,2,2,1,2,2
2,2,2,2,2,2,2,2,2,2,2,2,2,2,2,2,2,2,1,2
2,2,2,1,2,2,2,2,2,2,2,2,2,2,2,1,2,2,2,2
2,2,2,2,2,2,2,2,2,2,1,2,2,2,2,2,2,2,2,2
2,2,2,2,2,2,2,2,2,2,2,2,2,2,2,2,2,2,1,2
endlayer

layer
1,4,4,1,1,1,4,4,1,1,1,4,1,4,1,1,1,1,1,1
4,1,1,1,1,4,1,4,4,1,4,1,1,4,1,1,1,1,1,1
1,1,2,1,1,1,1,1,1,1,1,2,1,4,1,1,1,1,1,1
1,4,1,1,1,1,1,1,1,1,1,1,1,1,1,1,1,1,1,1
4,1,1,1,1,1,1,1,1,1,1,1,1,1,1,1,1,1,1,1
1,4,1,1,1,1,1,1,1,1,1,1,4,1,1,1,1,1,1,1
1,4,1,1,1,1,1,1,1,1,1,1,1,4,1,1,1,1,1,1
1,1,1,1,1,1,1,1,1,1,1,1,1,1,1,1,1,1,1,1
1,1,1,1,1,5,3,3,5,1,1,1,4,1,1,1,1,1,1,1
1,1,1,1,1,3,1,2,3,1,1,1,1,4,1,1,1,1,1,1
1,1,1,1,1,3,1,1,3,1,1,1,1,1,1,1,1,1,1,1
4,1,1,1,1,5,3,3,5,1,1,1,1,4,4,1,6,1,4,4
4,4,1,1,1,1,1,1,1,1,1,1,4,1,6,2,1,1,7,1
1,1,1,1,2,1,1,1,1,1,1,1,1,1,1,2,2,2,7,1
1,4,1,1,2,1,1,1,1,1,1,1,1,1,8,8,2,2,4,1
4,1,1,1,2,1,1,1,1,1,1,1,1,1,7,2,1,1,2,4
1,1,1,1,1,1,1,1,1,1,1,1,1,1,1,1,1,4,4,1
1,1,1,1,1,1,1,1,1,1,1,1,1,1,1,1,1,1,1,1
1,4,1,1,1,1,1,1,1,1,1,1,1,4,1,1,1,1,1,1
1,1,2,1,1,1,1,1,1,1,1,2,1,4,1,1,1,1,1,1
4,1,1,4,1,1,1,4,1,1,1,1,1,1,1,1,1,1,1,1
1,4,4,1,1,1,1,1,1,4,1,1,1,1,1,1,1,1,1,1
endlayer

layer
0,0,0,13,0,10,0,11,0,11,10,0,9,0,0,0,0,0,0,0
0,10,10,11,9,0,11,0,15,10,15,14,0,0,0,0,0,0,0,0
21,0,18,19,19,20,20,20,20,19,19,18,17,16,0,0,0,0,0,0
11,0,19,11,24,10,23,0,22,13,17,19,10,10,0,0,0,0,0,0
21,10,19,9,23,26,0,0,25,22,22,19,11,0,0,0,0,0,0,0
28,0,19,22,11,0,0,23,0,0,27,19,0,16,0,0,0,0,0,0
0,0,19,25,29,10,0,24,10,11,23,19,0,16,0,0,0,0,0,0
21,17,19,0,0,0,0,0,28,25,0,19,10,0,0,0,0,0,0,0
0,10,19,16,13,31,3,3,30,22,13,19,0,29,0,0,0,0,0,0
29,9,19,0,17,3,32,5,3,0,26,19,17,0,0,0,0,0,0,0
0,11,19,0,0,3,35,34,3,33,21,19,29,11,0,0,0,0,0,0
0,10,19,0,10,30,3,3,30,0,9,19,0,16,15,10,0,25,0,0
0,0,19,36,0,0,17,10,0,21,22,19,0,0,0,7,36,9,0,15
0,28,19,36,37,0,13,0,26,10,28,19,0,10,36,7,6,6,0,10
10,0,19,0,37,22,24,0,0,0,21,19,0,11,0,0,6,6,0,26
21,0,19,36,37,25,0,10,25,0,29,19,0,0,0,6,10,26,6,0
21,0,19,16,23,10,28,0,0,0,24,19,10,28,26,10,0,0,0,10
0,11,19,25,10,0,22,23,33,23,23,19,27,11,0,0,0,0,0,0
10,0,19,22,28,22,0,13,23,22,39,19,10,0,0,0,0,0,38,38
21,17,18,19,19,19,19,19,19,19,19,18,40,16,0,38,0,0,0,0
0,27,10,38,28,0,10,0,29,10,26,11,25,0,0,0,0,0,0,0
11,0,0,0,10,0,11,0,0,0,0,29,10,0,0,0,0,0,0,0
endlayer

layer
0,0,0,0,0,0,0,0,0,0,0,0,0,0,0,0,0,0,0,0
0,0,15,0,0,0,0,0,15,15,15,15,0,0,0,0,0,0,0,0
21,0,42,19,44,0,0,0,0,19,43,42,41,16,0,0,0,0,0,0
0,0,45,0,0,0,38,0,47,38,46,45,0,0,0,0,0,0,0,0
21,0,45,0,0,0,0,0,0,46,46,45,0,0,0,0,0,0,0,0
0,0,0,41,0,0,0,0,0,0,48,45,0,16,0,0,0,0,0,0
0,0,45,49,0,0,0,0,0,0,21,45,0,16,0,0,0,0,0,0
21,50,45,0,0,0,0,0,0,0,0,45,0,0,0,0,0,0,0,0
0,0,45,16,0,0,51,51,0,47,0,45,0,0,0,0,0,0,0,0
0,0,45,53,50,51,5,5,51,0,52,45,41,0,0,0,21,0,0,0
0,0,45,0,0,51,5,5,51,0,21,45,0,0,0,0,0,0,0,0
0,0,45,0,0,0,51,51,0,0,21,0,0,16,15,0,0,0,0,0
0,0,45,0,0,0,47,0,0,21,46,45,0,0,0,0,14,0,0,15
0,0,45,0,0,0,0,0,0,0,21,45,0,0,0,0,6,6,0,0
0,0,45,54,36,41,0,0,0,0,21,45,0,0,0,0,6,6,0,0
21,0,45,0,36,0,0,0,0,0,0,0,0,0,0,0,0,0,55,0
21,0,0,16,0,0,0,0,0,0,56,45,0,0,0,0,0,0,0,0
0,0,45,16,0,0,50,0,0,0,0,45,0,21,0,0,0,0,0,0
0,0,45,50,15,50,56,15,15,50,15,45,0,0,0,0,0,0,38,38
21,46,42,0,0,0,45,45,45,0,45,42,0,16,0,38,0,0,0,0
0,0,0,38,38,0,0,0,0,0,0,0,38,0,0,0,0,0,0,0
0,0,0,0,0,0,0,0,0,0,0,0,0,0,0,0,0,0,0,0
endlayer

layer
0,0,0,0,0,0,0,0,0,0,0,0,0,0,0,0,0,0,0,0
0,0,15,0,0,0,0,0,15,15,15,15,0,0,0,0,0,0,0,0
21,0,42,43,19,0,0,0,0,19,19,42,0,16,0,0,0,0,0,0
0,0,45,0,0,0,38,0,0,38,0,45,0,0,0,0,0,0,0,0
21,57,45,0,0,0,0,0,0,0,0,45,57,0,0,0,0,0,0,0
0,0,45,16,0,0,0,0,0,0,58,45,0,16,0,0,0,0,0,0
0,0,45,59,0,0,0,0,0,0,21,0,0,16,0,0,0,0,0,0
21,0,45,0,0,0,0,0,0,0,0,45,0,0,0,0,0,0,0,0
0,57,0,16,0,0,0,0,0,0,0,45,57,0,0,0,0,0,0,0
0,0,45,61,0,0,30,30,0,0,60,45,0,0,0,0,21,0,0,0
0,0,45,0,0,0,62,31,0,0,21,45,0,0,0,0,0,0,0,0
0,0,45,0,0,0,0,0,0,0,21,45,0,16,15,0,0,0,0,0
0,0,45,0,0,0,0,0,0,21,21,45,0,0,0,0,0,0,0,15
0,57,45,0,0,0,0,0,0,0,21,45,57,0,0,0,6,6,0,0
0,0,45,63,0,0,0,0,0,0,21,45,0,0,0,0,6,6,44,0
21,0,45,0,0,0,0,0,0,0,0,45,0,0,0,0,0,64,44,44
21,0,45,16,0,0,0,0,0,0,65,45,0,0,0,0,0,0,44,0
0,57,45,16,0,0,0,0,0,0,0,45,57,21,0,0,0,0,0,0
0,0,45,0,15,0,65,15,15,15,15,45,0,0,0,0,0,0,38,38
21,0,42,45,45,45,0,45,45,45,0,42,0,16,0,38,0,0,0,0
0,0,66,38,38,0,0,0,0,0,0,0,38,0,0,0,0,0,0,0
0,0,0,0,0,0,0,0,0,0,0,0,0,0,0,0,0,0,0,0
endlayer

layer
0,0,0,0,0,0,0,0,0,0,0,0,0,0,0,0,0,0,0,0
0,0,15,0,0,67,0,0,15,15,15,15,0,0,0,0,0,0,0,0
21,68,18,19,19,71,70,70,69,19,43,18,68,16,0,0,0,0,0,0
0,72,19,0,0,73,38,0,0,38,0,19,72,0,0,0,0,0,0,0
21,72,43,0,0,0,0,0,0,0,0,19,72,0,0,0,0,0,0,0
0,72,43,16,0,0,0,0,0,0,74,43,72,16,0,0,0,0,0,0
0,72,19,75,0,0,0,0,0,0,21,43,72,16,0,0,0,0,0,0
21,72,19,0,0,0,0,0,0,0,0,19,72,0,0,0,0,0,0,0
0,72,19,16,0,0,0,0,0,0,0,19,72,0,0,0,0,0,0,0
0,72,19,75,0,0,0,0,0,0,74,19,72,0,0,0,21,0,0,0
0,72,44,0,0,0,0,0,0,0,21,44,72,0,0,0,0,0,0,0
0,72,19,0,0,0,0,0,0,0,21,19,72,16,15,0,0,0,44,0
0,72,19,0,0,0,0,0,0,21,21,19,72,0,0,0,0,0,0,15
0,72,44,0,0,0,0,0,0,0,21,19,72,0,0,0,6,6,0,0
0,72,19,75,0,0,0,0,0,0,21,19,72,0,76,6,6,6,55,55
21,72,19,0,0,0,0,0,0,0,0,19,72,0,0,0,0,44,44,0
21,72,19,16,0,0,0,0,0,0,74,44,72,0,0,0,0,0,0,0
0,72,44,16,0,0,0,0,0,0,0,44,72,21,0,0,0,0,0,0
0,72,44,0,15,0,77,15,15,15,15,19,72,0,0,0,0,0,38,38
21,68,18,19,19,44,44,19,19,19,43,18,68,16,0,38,0,0,0,0
0,0,38,38,38,0,0,0,0,0,0,0,38,0,0,0,0,0,0,0
0,0,0,0,0,0,0,0,0,0,0,0,0,0,0,0,0,0,0,0
endlayer

layer
0,0,0,0,0,0,0,0,0,0,0,0,0,0,0,0,0,0,0,0
0,0,15,0,0,0,0,0,15,0,15,15,0,0,0,0,0,0,0,0
21,78,42,42,42,42,42,42,42,42,42,42,78,16,0,0,0,0,0,0
0,78,0,0,66,38,38,0,0,38,0,0,78,0,0,0,0,0,0,0
21,78,0,0,0,0,0,0,0,0,0,0,78,0,0,0,0,0,0,0
0,78,0,0,0,0,0,0,0,0,0,0,78,16,0,0,0,0,0,0
0,78,0,0,0,0,0,0,0,0,0,0,78,16,0,0,0,0,0,0
21,78,0,0,0,0,0,0,0,0,0,0,78,0,0,0,0,0,0,0
0,78,0,0,0,0,0,0,0,0,0,0,78,0,0,0,0,0,0,0
0,78,0,0,0,0,0,0,0,0,0,0,78,0,0,0,21,44,0,0
0,78,79,0,0,0,0,0,0,0,0,76,78,0,0,0,0,0,0,0
0,78,0,0,0,0,0,0,0,0,0,21,78,16,15,0,0,55,44,0
0,78,0,0,0,0,0,0,0,21,0,0,78,0,44,0,0,6,0,15
0,78,40,0,0,0,0,0,0,0,0,81,78,80,0,0,6,6,40,0
0,78,40,0,0,0,0,0,0,0,0,21,78,0,0,6,6,6,0,55
21,78,0,0,0,0,0,0,0,0,0,0,78,0,0,0,0,0,44,44
21,78,82,0,0,0,0,0,0,0,0,0,78,0,0,0,0,0,0,0
83,78,0,0,0,0,0,0,0,0,0,0,78,21,0,0,0,0,0,0
0,78,0,67,0,0,0,0,0,84,15,0,78,0,0,0,0,0,38,38
21,78,42,42,42,42,42,42,42,42,42,42,78,16,0,38,0,0,0,0
0,0,38,38,38,0,0,0,85,0,0,0,38,0,0,0,0,0,0,0
0,0,0,0,0,0,0,0,0,0,0,0,0,0,0,0,0,0,0,0
endlayer

layer
0,0,0,0,0,0,0,0,0,0,0,0,0,0,0,0,0,0,0,0
0,0,0,0,0,0,0,0,0,0,0,0,0,0,0,0,0,0,0,0
0,0,0,0,0,0,0,0,0,0,0,0,0,0,0,0,0,0,0,0
0,0,86,87,87,87,87,87,0,87,87,86,0,0,0,0,0,0,0,0
0,0,87,0,0,0,0,0,0,0,0,87,0,0,0,0,0,0,0,0
0,0,87,0,0,0,0,0,0,0,0,87,0,0,0,0,0,0,0,0
0,0,87,0,0,0,0,0,0,0,0,87,0,0,0,0,0,0,0,0
0,0,87,0,0,0,0,0,0,0,0,87,0,0,0,0,0,0,0,0
0,0,87,0,0,0,0,0,0,0,0,87,0,0,0,0,0,0,0,0
0,0,87,0,0,0,0,0,0,0,0,87,0,0,0,0,21,44,0,0
0,0,87,0,0,0,0,0,0,0,0,87,0,0,0,0,0,44,0,0
0,0,87,0,0,0,0,0,0,0,0,21,0,16,15,0,44,55,44,0
0,0,87,0,0,0,0,0,0,21,0,87,55,55,55,55,0,44,44,15
0,0,87,0,0,0,0,0,0,0,0,87,44,0,0,55,6,6,0,43
0,0,87,0,0,0,0,0,0,0,0,21,44,44,44,6,6,6,44,43
0,0,87,0,0,0,0,0,0,0,0,87,44,44,44,0,0,6,44,44
0,0,87,0,0,0,0,0,0,0,0,87,0,0,0,0,0,0,0,0
0,0,87,0,0,0,0,0,0,0,0,87,0,21,0,0,0,0,43,0
0,0,86,87,87,87,87,87,87,87,87,86,0,0,0,0,0,0,38,38
0,0,0,0,0,0,0,0,0,0,0,0,0,0,0,38,0,0,0,0
0,0,0,0,0,0,0,0,0,0,0,0,0,0,0,0,0,0,0,0
0,0,0,0,0,0,0,0,0,0,0,0,0,0,0,0,0,0,0,0
endlayer

layer
0,0,0,0,0,0,0,0,0,0,0,0,0,0,0,0,0,0,0,0
0,0,0,0,0,0,0,0,0,0,0,0,0,0,0,0,0,0,0,0
0,0,0,0,0,0,0,0,0,0,0,0,0,0,0,0,0,0,0,0
0,0,0,86,86,86,0,86,86,86,86,0,0,0,0,0,0,0,0,0
0,0,0,88,0,0,0,0,0,0,88,0,0,0,0,0,0,0,0,0
0,0,0,88,0,0,0,0,0,0,88,0,0,0,0,0,0,0,0,0
0,0,0,0,0,0,0,0,0,0,88,0,0,0,0,0,0,0,0,0
0,0,0,0,0,0,0,0,0,0,88,0,0,0,0,0,0,0,0,0
0,0,0,88,0,0,0,0,0,0,88,0,0,0,0,0,0,0,0,0
0,0,0,88,0,0,0,0,0,0,88,0,0,0,0,0,21,44,44,0
0,0,0,88,0,0,0,0,0,0,88,15,0,0,0,0,44,44,44,43
0,0,0,88,0,0,0,0,0,0,88,21,43,16,15,44,44,55,44,43
0,0,0,88,0,0,0,0,0,21,88,55,55,0,44,55,44,0,0,0
0,0,0,88,0,0,0,0,0,0,88,0,15,0,0,44,6,6,6,0
0,0,0,88,0,0,0,0,0,0,88,21,44,44,44,44,6,6,44,43
0,0,0,88,0,0,0,0,0,0,88,0,0,44,44,6,0,76,6,0
0,0,0,88,0,0,0,0,0,0,88,0,0,0,0,55,0,0,0,0
0,0,0,88,0,0,0,0,0,0,88,0,0,21,0,55,0,0,44,0
0,0,0,86,86,86,86,0,0,86,86,0,0,0,0,0,0,0,38,38
0,0,0,0,0,0,0,0,0,0,0,0,0,0,0,38,0,0,0,0
0,0,0,0,0,0,0,0,0,0,0,0,0,0,0,0,0,0,0,0
0,0,0,0,0,0,0,0,0,0,0,0,0,0,0,0,0,0,0,0
endlayer

layer
0,0,0,0,0,0,0,0,0,0,0,0,0,0,0,0,0,0,0,0
0,0,0,0,0,0,0,0,0,0,0,0,0,0,0,0,0,0,0,0
0,0,0,0,0,0,0,0,0,0,0,0,0,0,0,0,0,0,0,0
0,0,0,0,86,86,86,86,86,86,0,0,0,0,0,0,0,0,0,0
0,0,0,0,86,88,88,88,88,86,0,0,0,0,0,0,0,0,0,0
0,0,0,0,86,88,88,88,88,86,0,0,0,0,0,0,0,0,0,0
0,0,0,0,86,88,88,88,88,86,0,0,0,0,0,0,0,0,0,0
0,0,0,0,86,88,88,88,88,86,0,0,0,0,0,0,0,0,0,0
0,0,0,0,86,88,88,88,88,86,0,0,0,0,0,0,0,0,0,0
0,0,0,0,86,88,88,88,88,86,0,0,0,0,0,0,0,0,0,0
0,0,0,0,0,88,88,88,88,86,0,15,0,0,0,0,0,44,44,0
0,0,0,0,86,88,88,88,88,86,44,44,0,0,0,0,0,44,44,0
0,0,0,0,86,88,88,88,88,21,44,44,44,0,0,44,0,44,44,43
0,0,0,0,86,88,88,88,88,86,44,44,44,0,0,44,44,44,6,0
0,0,0,0,86,88,88,88,88,86,44,44,0,0,44,44,0,0,0,0
0,0,0,0,86,88,88,88,88,86,0,0,0,44,44,6,0,0,44,0
0,0,0,0,86,88,88,88,88,86,0,0,0,0,0,0,0,0,6,0
0,0,0,0,86,88,88,88,88,86,0,0,0,21,0,55,0,0,44,0
0,0,0,0,86,86,86,86,86,86,0,0,0,0,0,43,0,0,38,38
0,0,0,0,0,0,0,0,0,0,0,0,0,0,0,38,0,0,0,0
0,0,0,0,0,0,0,0,0,0,0,0,0,0,0,0,0,0,0,0
0,0,0,0,0,0,0,0,0,0,0,0,0,0,0,0,0,0,0,0
endlayer

layer
0,0,0,0,0,0,0,0,0,0,0,0,0,0,0,0,0,0,0,0
0,0,0,0,0,0,0,0,0,0,0,0,0,0,0,0,0,0,0,0
0,0,0,0,0,0,0,0,0,0,0,0,0,0,0,0,0,0,0,0
0,0,0,0,0,0,0,0,0,0,0,0,0,0,0,0,0,0,0,0
0,0,0,0,0,0,0,0,0,0,0,0,0,0,0,0,0,0,0,0
0,0,0,0,0,0,0,0,0,0,0,0,0,0,0,0,0,0,0,0
0,0,0,0,0,0,0,0,0,0,0,0,0,0,0,0,0,0,0,0
0,0,0,0,0,0,0,0,0,0,0,0,0,0,0,0,0,0,0,0
0,0,0,0,0,0,0,0,0,0,0,0,0,0,0,0,0,0,0,0
0,0,0,0,0,0,0,0,0,0,0,0,0,0,0,0,0,0,0,0
0,0,0,0,0,0,0,0,0,0,0,0,0,0,0,0,0,0,0,0
0,0,0,0,0,0,0,0,0,0,15,0,0,0,0,0,0,0,0,0
0,0,0,0,0,0,0,0,0,21,44,44,0,0,0,0,0,0,44,0
0,0,0,0,0,0,0,0,0,21,44,44,0,0,0,0,0,44,44,43
0,0,0,0,0,0,0,0,0,0,0,0,0,0,0,44,0,0,44,0
0,0,0,0,0,0,0,0,0,0,0,0,0,0,44,44,44,44,44,43
0,0,0,0,0,0,0,0,0,0,0,0,0,0,0,44,0,44,44,43
0,0,0,0,0,0,0,0,0,0,0,0,0,21,0,55,0,43,43,43
0,0,0,0,0,0,0,0,0,0,0,0,0,0,0,43,0,0,38,38
0,0,0,0,0,0,0,0,0,0,0,0,0,0,0,38,0,0,0,0
0,0,0,0,0,0,0,0,0,0,0,0,0,0,0,0,0,0,0,0
0,0,0,0,0,0,0,0,0,0,0,0,0,0,0,0,0,0,0,0
endlayer

layer
0,0,0,0,0,0,0,0,0,0,0,0,0,0,0,0,0,0,0,0
0,0,0,0,0,0,0,0,0,0,0,0,0,0,0,0,0,0,0,0
0,0,0,0,0,0,0,0,0,0,0,0,0,0,0,0,0,0,0,0
0,0,0,0,0,0,0,0,0,0,0,0,0,0,0,0,0,0,0,0
0,0,0,0,0,0,0,0,0,0,0,0,0,0,0,0,0,0,0,0
0,0,0,0,0,0,0,0,0,0,0,0,0,0,0,0,0,0,0,0
0,0,0,0,0,0,0,0,0,0,0,0,0,0,0,0,0,0,0,0
0,0,0,0,0,0,0,0,0,0,0,0,0,0,0,0,0,0,0,0
0,0,0,0,0,0,0,0,0,0,0,0,0,0,0,0,0,0,0,0
0,0,0,0,0,0,0,0,0,0,0,0,0,0,0,0,0,0,0,0
0,0,0,0,0,0,0,0,0,0,0,0,0,0,0,0,0,0,0,0
0,0,0,0,0,0,0,0,0,0,0,0,0,0,0,0,0,0,0,0
0,0,0,0,0,0,0,0,0,0,0,0,0,0,0,0,0,0,0,0
0,0,0,0,0,0,0,0,0,0,0,0,0,0,0,0,0,0,44,0
0,0,0,0,0,0,0,0,0,0,0,0,0,0,0,0,0,0,0,0
0,0,0,0,0,0,0,0,0,0,0,0,0,0,0,44,15,0,44,0
0,0,0,0,0,0,0,0,0,0,0,0,0,0,44,44,44,44,44,43
0,0,0,0,0,0,0,0,0,0,0,0,0,21,43,43,43,0,43,0
0,0,0,0,0,0,0,0,0,0,0,0,0,0,43,43,43,0,0,0
0,0,0,0,0,0,0,0,0,0,0,0,0,0,0,0,0,0,0,0
0,0,0,0,0,0,0,0,0,0,0,0,0,0,0,0,0,0,0,0
0,0,0,0,0,0,0,0,0,0,0,0,0,0,0,0,0,0,0,0
endlayer

layer
0,0,0,0,0,0,0,0,0,0,0,0,0,0,0,0,0,0,0,0
0,0,0,0,0,0,0,0,0,0,0,0,0,0,0,0,0,0,0,0
0,0,0,0,0,0,0,0,0,0,0,0,0,0,0,0,0,0,0,0
0,0,0,0,0,0,0,0,0,0,0,0,0,0,0,0,0,0,0,0
0,0,0,0,0,0,0,0,0,0,0,0,0,0,0,0,0,0,0,0
0,0,0,0,0,0,0,0,0,0,0,0,0,0,0,0,0,0,0,0
0,0,0,0,0,0,0,0,0,0,0,0,0,0,0,0,0,0,0,0
0,0,0,0,0,0,0,0,0,0,0,0,0,0,0,0,0,0,0,0
0,0,0,0,0,0,0,0,0,0,0,0,0,0,0,0,0,0,0,0
0,0,0,0,0,0,0,0,0,0,0,0,0,0,0,0,0,0,0,0
0,0,0,0,0,0,0,0,0,0,0,0,0,0,0,0,0,0,0,0
0,0,0,0,0,0,0,0,0,0,0,0,0,0,0,0,0,0,0,0
0,0,0,0,0,0,0,0,0,0,0,0,0,0,0,0,0,0,0,0
0,0,0,0,0,0,0,0,0,0,0,0,0,0,0,0,0,0,0,0
0,0,0,0,0,0,0,0,0,0,0,0,0,0,0,0,0,0,0,0
0,0,0,0,0,0,0,0,0,0,0,0,0,0,0,0,0,0,0,0
0,0,0,0,0,0,0,0,0,0,0,0,0,0,15,44,0,0,43,0
0,0,0,0,0,0,0,0,0,0,0,0,0,21,43,43,43,0,0,0
0,0,0,0,0,0,0,0,0,0,0,0,0,0,38,43,0,0,0,0
0,0,0,0,0,0,0,0,0,0,0,0,0,0,0,0,0,0,0,0
0,0,0,0,0,0,0,0,0,0,0,0,0,0,0,0,0,0,0,0
0,0,0,0,0,0,0,0,0,0,0,0,0,0,0,0,0,0,0,0
endlayer

