
# Created by Ruins mod version 14.9 Ingame Parser
# authoring Player: SunsOfOld

weight=100
embed_into_distance=2
acceptable_target_blocks=
unacceptable_target_blocks=flowing_water,water,flowing_lava,lava
dimensions=12,10,11
allowable_overhang=0
max_leveling=4
leveling_buffer=0
preserve_water=0
preserve_lava=0
uniqueMinDistance=1000000
preventRotation=1

rule1=0,100,preserveBlock
rule2=0,100,minecraft:grass-0
rule3=0,100,chisel:fantasyblock2-14
rule4=0,100,minecraft:dirt-0
rule5=0,100,BiomesOPlenty:foliage-11
rule6=0,100,BiomesOPlenty:foliage-10
rule7=0,100,plantmegapack:groundcoverClover-0
rule8=0,100,minecraft:tallgrass-1
rule9=0,100,ExtrabiomesXL:flower2-3
rule10=0,100,BiomesOPlenty:cherryStairs-2
rule11=0,100,BiomesOPlenty:planks-1
rule12=0,100,BiomesOPlenty:cherryStairs-3
rule13=0,100,ExtrabiomesXL:flower3-0
rule14=0,100,plantmegapack:fungusBlackPowderpuff-0
rule15=0,100,plantmegapack:bambooTropicalBlue-0
rule16=0,100,BiomesOPlenty:foliage-1
rule17=0,100,BiomesOPlenty:foliage-2
rule18=0,100,chisel:torch4-5
rule19=0,100,BiomesOPlenty:foliage-14
rule20=0,100,BiomesOPlenty:foliage-5
rule21=0,100,ExtrabiomesXL:mini_log_1-0
rule22=0,100,plantmegapack:bambooTropicalBlue-1
rule23=0,100,BiomesOPlenty:cherryStairs-7
rule24=0,100,BiomesOPlenty:cherryStairs-6
rule25=0,100,plantmegapack:bambooTropicalBlue-2
rule26=0,100,ExtrabiomesXL:leaves_3-0
rule27=0,100,ExtrabiomesXL:leaves_3-12
rule28=0,100,ExtrabiomesXL:leaves_3-4
rule29=0,100,BiomesOPlenty:woodenSingleSlab1-1
rule30=0,100,plantmegapack:bambooTropicalBlue-3
rule31=0,100,ExtrabiomesXL:mini_log_1-4
rule32=0,100,ExtrabiomesXL:mini_log_1-8
rule33=0,100,plantmegapack:bambooTropicalBlue-4

layer
1,1,1,1,1,1,1,1,1,1,1
1,1,1,1,1,1,1,1,1,1,1
1,1,1,1,1,1,1,1,1,1,1
1,1,1,1,1,1,1,1,1,1,1
1,1,1,1,1,1,1,1,1,1,1
1,1,1,1,1,1,1,1,1,1,1
1,1,1,1,1,1,1,1,1,1,1
1,1,1,1,1,1,1,1,1,1,1
1,1,1,1,1,1,1,1,1,1,1
1,1,1,1,1,1,1,1,1,1,1
endlayer

layer
1,1,1,1,1,1,1,1,1,1,1
1,1,2,2,3,1,1,2,2,1,1
1,2,2,2,2,3,2,2,2,2,1
1,2,4,4,4,3,4,4,4,2,1
1,1,2,2,2,3,2,2,2,2,1
1,2,2,2,2,3,2,2,2,2,1
1,2,2,2,2,2,3,2,2,1,1
1,2,2,2,2,2,2,2,2,2,1
1,1,2,2,2,2,3,1,2,1,1
1,1,1,1,1,1,1,1,1,1,1
endlayer

layer
0,0,0,0,0,0,0,0,0,0,0
0,0,5,7,0,0,0,6,5,0,0
0,8,8,6,7,0,5,8,9,8,0
0,12,11,11,10,0,12,11,11,10,0
0,0,14,13,5,0,5,6,6,8,0
0,7,5,17,7,0,16,15,15,6,0
0,6,8,8,20,19,0,18,15,0,0
0,7,8,21,8,7,19,19,8,5,0
0,0,6,8,7,6,0,0,8,0,0
0,0,0,0,0,0,0,0,0,0,0
endlayer

layer
0,0,0,0,0,0,0,0,0,0,0
0,0,0,0,0,0,0,0,0,0,0
0,0,0,0,0,0,0,0,0,0,0
0,0,11,11,0,0,0,11,11,0,0
0,0,0,0,0,0,0,0,0,0,0
0,0,0,0,0,0,0,22,22,0,0
0,0,0,0,0,0,0,0,22,0,0
0,0,0,21,0,0,0,0,0,0,0
0,0,0,0,0,0,0,0,0,0,0
0,0,0,0,0,0,0,0,0,0,0
endlayer

layer
0,0,0,0,0,0,0,0,0,0,0
0,0,0,0,0,0,0,0,0,0,0
0,0,0,0,0,0,0,0,0,0,0
0,0,11,11,24,0,23,11,11,0,0
0,0,0,0,0,0,0,0,0,0,0
0,0,26,26,0,0,0,25,25,0,0
0,28,27,0,0,0,0,0,25,0,0
0,0,27,21,0,27,0,0,0,0,0
0,0,27,0,0,0,0,0,0,0,0
0,0,0,27,0,0,0,0,0,0,0
endlayer

layer
0,0,0,0,0,0,0,0,0,0,0
0,0,0,0,0,0,0,0,0,0,0
0,0,0,0,0,0,0,0,0,0,0
0,0,29,29,12,11,10,29,29,0,0
0,0,27,27,0,0,0,0,0,0,0
0,28,26,26,26,0,0,30,30,0,0
0,27,32,31,26,26,0,0,30,0,0
0,26,27,21,26,26,27,0,0,0,0
0,0,27,31,26,26,0,0,0,0,0
0,0,27,26,26,0,0,0,0,0,0
endlayer

layer
0,0,0,0,0,0,0,0,0,0,0
0,0,0,0,0,0,0,0,0,0,0
0,0,0,0,0,0,0,0,0,0,0
0,0,0,0,0,0,0,0,0,0,0
0,0,27,27,27,0,0,0,0,0,0
0,26,26,26,27,27,0,30,30,0,0
0,27,26,26,26,27,27,0,30,0,0
0,26,26,26,26,26,27,0,0,0,0
0,27,26,26,26,26,27,0,0,0,0
0,0,0,26,26,27,0,0,0,0,0
endlayer

layer
0,0,0,0,0,0,0,0,0,0,0
0,0,0,0,0,0,0,0,0,0,0
0,0,0,0,0,0,0,0,0,0,0
0,0,0,0,0,0,0,0,0,0,0
0,0,0,27,0,0,0,0,0,0,0
0,0,26,27,27,0,0,30,30,0,0
0,0,26,27,27,27,0,0,30,0,0
0,26,26,26,27,27,27,0,0,0,0
0,0,26,26,26,27,0,0,0,0,0
0,0,0,26,26,0,0,0,0,0,0
endlayer

layer
0,0,0,0,0,0,0,0,0,0,0
0,0,0,0,0,0,0,0,0,0,0
0,0,0,0,0,0,0,0,0,0,0
0,0,0,0,0,0,0,0,0,0,0
0,0,0,0,0,0,0,0,0,0,0
0,0,0,0,0,0,0,30,30,0,0
0,0,0,27,27,0,0,0,30,0,0
0,0,0,27,27,27,0,0,0,0,0
0,0,0,0,27,0,0,0,0,0,0
0,0,0,0,0,0,0,0,0,0,0
endlayer

layer
0,0,0,0,0,0,0,0,0,0,0
0,0,0,0,0,0,0,0,0,0,0
0,0,0,0,0,0,0,0,0,0,0
0,0,0,0,0,0,0,0,0,0,0
0,0,0,0,0,0,0,0,0,0,0
0,0,0,0,0,0,0,30,30,0,0
0,0,0,0,0,0,0,0,30,0,0
0,0,0,0,0,0,0,0,0,0,0
0,0,0,0,0,0,0,0,0,0,0
0,0,0,0,0,0,0,0,0,0,0
endlayer

layer
0,0,0,0,0,0,0,0,0,0,0
0,0,0,0,0,0,0,0,0,0,0
0,0,0,0,0,0,0,0,0,0,0
0,0,0,0,0,0,0,0,0,0,0
0,0,0,0,0,0,0,0,0,0,0
0,0,0,0,0,0,0,30,30,0,0
0,0,0,0,0,0,0,0,30,0,0
0,0,0,0,0,0,0,0,0,0,0
0,0,0,0,0,0,0,0,0,0,0
0,0,0,0,0,0,0,0,0,0,0
endlayer

layer
0,0,0,0,0,0,0,0,0,0,0
0,0,0,0,0,0,0,0,0,0,0
0,0,0,0,0,0,0,0,0,0,0
0,0,0,0,0,0,0,0,0,0,0
0,0,0,0,0,0,0,0,0,0,0
0,0,0,0,0,0,0,33,33,0,0
0,0,0,0,0,0,0,0,33,0,0
0,0,0,0,0,0,0,0,0,0,0
0,0,0,0,0,0,0,0,0,0,0
0,0,0,0,0,0,0,0,0,0,0
endlayer

