
# Created by Ruins mod version 15.0 Ingame Parser
# authoring Player: SunsOfOld

weight=100
embed_into_distance=1
acceptable_target_blocks=
unacceptable_target_blocks=flowing_water,water,flowing_lava,lava
dimensions=9,31,13
allowable_overhang=0
max_leveling=6
leveling_buffer=0
preserve_water=0
preserve_lava=0
uniqueMinDistance=1000000
preventRotation=1

rule1=0,100,chisel:nether_brick-15
rule2=0,100,chisel:nether_brick-11
rule3=0,100,chisel:netherrack-2
rule4=0,100,chisel:grimstone-12
rule5=0,100,chisel:lavastone-7
rule6=0,100,chisel:nether_brick-8
rule7=0,100,chisel:grimstone-9
rule8=0,100,chisel:grimstone-1
rule9=0,100,minecraft:log2-1
rule10=0,100,GardenStuff:fence-2
rule11=0,100,UndergroundBiomes:igneousStoneBrick-5
rule12=0,100,chisel:grimstone-11
rule13=0,100,GardenTrees:thin_log-5
rule14=0,100,minecraft:stone_slab-0
rule15=0,100,UndergroundBiomes:stairs-2
rule16=0,100,UndergroundBiomes:stairs-3
rule17=0,100,minecraft:stone_slab-8
rule18=0,100,GardenStuff:heavy_chain-4
rule19=0,100,UndergroundBiomes:stairs-7
rule20=0,100,UndergroundBiomes:stairs-6
rule21=0,100,GardenStuff:light_chain-4
rule22=0,100,minecraft:cobblestone-0
rule23=0,100,minecraft:stone_stairs-2
rule24=0,100,UndergroundBiomes:stairs-4
rule25=0,100,minecraft:stone_stairs-3
rule26=0,100,chisel:nether_brick-2
rule27=0,100,GardenStuff:lattice-2
rule28=0,100,UndergroundBiomes:stairs-5
rule29=0,100,UndergroundBiomes:stairs-0
rule30=0,100,minecraft:stone_stairs-0
rule31=0,100,minecraft:stone_stairs-1
rule32=0,100,UndergroundBiomes:stairs-1

layer
0,0,0,0,0,0,0,0,0,0,0,0,0
0,1,1,1,1,1,1,1,1,1,1,1,0
0,1,2,2,2,2,2,2,2,2,2,1,0
0,1,2,3,3,3,3,3,3,3,2,1,0
0,1,2,3,4,4,4,4,4,3,2,1,0
0,1,2,3,4,5,6,5,4,3,2,1,0
0,1,2,3,4,4,6,4,4,3,2,1,0
0,1,2,3,3,4,6,4,3,3,2,1,0
0,1,2,3,3,4,6,4,3,3,2,1,0
0,1,2,3,4,4,6,4,4,3,2,1,0
0,1,2,3,4,5,6,5,4,3,2,1,0
0,1,2,3,4,4,4,4,4,3,2,1,0
0,1,2,7,7,7,7,7,7,7,2,1,0
0,1,2,7,8,8,4,8,8,7,2,1,0
0,1,2,7,8,4,4,4,8,7,2,1,0
0,1,2,7,4,4,4,4,4,7,2,1,0
0,1,2,7,8,4,4,4,8,7,2,1,0
0,1,2,7,8,8,4,8,8,7,2,1,0
0,1,2,7,7,7,7,7,7,7,2,1,0
0,1,2,3,4,4,4,4,4,3,2,1,0
0,1,2,3,4,5,6,5,4,3,2,1,0
0,1,2,3,4,4,6,4,4,3,2,1,0
0,1,2,3,3,4,6,4,3,3,2,1,0
0,1,2,3,3,4,6,4,3,3,2,1,0
0,1,2,3,4,4,6,4,4,3,2,1,0
0,1,2,3,4,5,6,5,4,3,2,1,0
0,1,2,3,4,4,4,4,4,3,2,1,0
0,1,2,3,3,3,3,3,3,3,2,1,0
0,1,2,2,2,2,2,2,2,2,2,1,0
0,1,1,1,1,1,1,1,1,1,1,1,0
0,0,0,0,0,0,0,0,0,0,0,0,0
endlayer

layer
0,0,0,0,0,0,0,0,0,0,0,0,0
0,9,10,10,11,0,0,0,11,10,10,9,0
0,10,0,0,0,0,0,0,0,0,0,10,0
0,10,0,0,0,0,0,0,0,0,0,10,0
0,10,0,0,0,0,0,0,0,0,0,10,0
0,10,0,0,0,0,0,0,0,0,0,10,0
0,10,0,0,0,0,0,0,0,0,0,10,0
0,10,0,0,0,0,0,0,0,0,0,10,0
0,10,0,0,0,0,0,0,0,0,0,10,0
0,10,0,0,0,0,0,0,0,0,0,10,0
0,10,0,0,0,0,0,0,0,0,0,10,0
0,10,0,0,0,0,0,0,0,0,0,10,0
0,10,0,0,0,0,0,0,0,0,0,10,0
0,10,0,0,0,0,4,0,0,0,0,10,0
0,10,0,0,0,4,4,4,0,0,0,10,0
0,10,0,0,4,4,12,4,4,0,0,10,0
0,10,0,0,0,4,4,4,0,0,0,10,0
0,10,0,0,0,0,4,0,0,0,0,10,0
0,10,0,0,0,0,0,0,0,0,0,10,0
0,10,0,0,0,0,0,0,0,0,0,10,0
0,10,0,0,0,0,0,0,0,0,0,10,0
0,10,0,0,0,0,0,0,0,0,0,10,0
0,10,0,0,0,0,0,0,0,0,0,10,0
0,10,0,0,0,0,0,0,0,0,0,10,0
0,10,0,0,0,0,0,0,0,0,0,10,0
0,10,0,0,0,0,0,0,0,0,0,10,0
0,10,0,0,0,0,0,0,0,0,0,10,0
0,10,0,0,0,0,0,0,0,0,0,10,0
0,10,0,0,0,0,0,0,0,0,0,10,0
0,9,10,10,11,0,0,0,11,10,10,9,0
0,0,0,0,0,0,0,0,0,0,0,0,0
endlayer

layer
0,0,0,0,0,0,0,0,0,0,0,0,0
0,13,10,10,11,0,0,0,11,10,10,13,0
0,10,0,0,0,0,0,0,0,0,0,10,0
0,10,0,0,0,0,0,0,0,0,0,10,0
0,10,0,0,0,0,0,0,0,0,0,10,0
0,10,0,0,0,0,0,0,0,0,0,10,0
0,10,0,0,0,0,0,0,0,0,0,10,0
0,10,0,0,0,0,0,0,0,0,0,10,0
0,10,0,0,0,0,0,0,0,0,0,10,0
0,10,0,0,0,0,0,0,0,0,0,10,0
0,10,0,0,0,0,0,0,0,0,0,10,0
0,10,0,0,0,0,0,0,0,0,0,10,0
0,10,0,0,0,0,0,0,0,0,0,10,0
0,10,0,0,0,0,0,0,0,0,0,10,0
0,10,0,0,0,0,0,0,0,0,0,10,0
0,10,0,0,0,0,0,0,0,0,0,10,0
0,10,0,0,0,0,0,0,0,0,0,10,0
0,10,0,0,0,0,0,0,0,0,0,10,0
0,10,0,0,0,0,0,0,0,0,0,10,0
0,10,0,0,0,0,0,0,0,0,0,10,0
0,10,0,0,0,0,0,0,0,0,0,10,0
0,10,0,0,0,0,0,0,0,0,0,10,0
0,10,0,0,0,0,0,0,0,0,0,10,0
0,10,0,0,0,0,0,0,0,0,0,10,0
0,10,0,0,0,0,0,0,0,0,0,10,0
0,10,0,0,0,0,0,0,0,0,0,10,0
0,10,0,0,0,0,0,0,0,0,0,10,0
0,10,0,0,0,0,0,0,0,0,0,10,0
0,10,0,0,0,0,0,0,0,0,0,10,0
0,13,10,10,11,0,0,0,11,10,10,13,0
0,0,0,0,0,0,0,0,0,0,0,0,0
endlayer

layer
0,0,0,0,0,0,0,0,0,0,0,0,0
0,13,14,16,11,0,0,0,11,15,14,13,0
0,14,0,0,0,0,0,0,0,0,0,14,0
0,14,0,0,0,0,0,0,0,0,0,14,0
0,14,0,0,0,0,0,0,0,0,0,14,0
0,14,0,0,0,0,0,0,0,0,0,14,0
0,14,0,0,0,0,0,0,0,0,0,14,0
0,14,0,0,0,0,0,0,0,0,0,14,0
0,14,0,0,0,0,0,0,0,0,0,14,0
0,14,0,0,0,0,0,0,0,0,0,14,0
0,14,0,0,0,0,0,0,0,0,0,14,0
0,14,0,0,0,0,0,0,0,0,0,14,0
0,14,0,0,0,0,0,0,0,0,0,14,0
0,14,0,0,0,0,0,0,0,0,0,14,0
0,14,0,0,0,0,0,0,0,0,0,14,0
0,14,0,0,0,0,0,0,0,0,0,14,0
0,14,0,0,0,0,0,0,0,0,0,14,0
0,14,0,0,0,0,0,0,0,0,0,14,0
0,14,0,0,0,0,0,0,0,0,0,14,0
0,14,0,0,0,0,0,0,0,0,0,14,0
0,14,0,0,0,0,0,0,0,0,0,14,0
0,14,0,0,0,0,0,0,0,0,0,14,0
0,14,0,0,0,0,0,0,0,0,0,14,0
0,14,0,0,0,0,0,0,0,0,0,14,0
0,14,0,0,0,0,0,0,0,0,0,14,0
0,14,0,0,0,0,0,0,0,0,0,14,0
0,14,0,0,0,0,0,0,0,0,0,14,0
0,14,0,0,0,0,0,0,0,0,0,14,0
0,14,0,0,0,0,0,0,0,0,0,14,0
0,13,14,16,11,0,0,0,11,15,14,13,0
0,0,0,0,0,0,0,0,0,0,0,0,0
endlayer

layer
0,0,0,0,0,0,0,0,0,0,0,0,0
17,13,18,0,11,20,0,19,11,0,18,13,17
17,18,0,0,0,0,21,0,0,0,0,18,17
17,21,0,0,0,0,21,0,0,0,0,21,17
17,18,0,0,0,0,21,0,0,0,0,18,17
17,21,0,0,0,0,21,0,0,0,0,21,17
17,18,0,0,0,0,21,0,0,0,0,18,17
17,21,0,0,0,0,21,0,0,0,0,21,17
17,18,0,0,0,0,21,0,0,0,0,18,17
17,21,0,0,0,0,21,0,0,0,0,21,17
17,18,0,0,0,0,18,0,0,0,0,18,17
17,21,0,0,0,0,18,0,0,0,0,21,17
17,18,0,0,0,0,21,0,0,0,0,18,17
17,21,0,0,0,0,21,0,0,0,0,21,17
17,18,0,0,0,0,21,0,0,0,0,18,17
17,21,0,0,0,0,21,0,0,0,0,21,17
17,18,0,0,0,0,21,0,0,0,0,18,17
17,21,0,0,0,0,21,0,0,0,0,21,17
17,18,0,0,0,0,21,0,0,0,0,18,17
17,21,0,0,0,0,21,0,0,0,0,21,17
17,18,0,0,0,0,21,0,0,0,0,18,17
17,21,0,0,0,0,21,0,0,0,0,21,17
17,18,0,0,0,0,21,0,0,0,0,18,17
17,21,0,0,0,0,21,0,0,0,0,21,17
17,18,0,0,0,0,21,0,0,0,0,18,17
17,21,0,0,0,0,21,0,0,0,0,21,17
17,18,0,0,0,0,21,0,0,0,0,18,17
17,21,0,0,0,0,21,0,0,0,0,21,17
17,18,0,0,0,0,21,0,0,0,0,18,17
17,13,18,0,22,20,0,19,22,0,18,13,17
0,0,0,0,0,0,0,0,0,0,0,0,0
endlayer

layer
0,0,0,0,0,0,0,0,0,0,0,0,0
0,14,17,14,25,11,24,11,23,14,17,14,0
0,14,17,14,16,26,27,26,15,14,17,14,0
0,14,17,14,25,26,27,26,23,14,17,14,0
0,14,17,14,16,26,27,26,15,14,17,14,0
0,14,17,14,25,26,27,26,23,14,17,14,0
0,14,17,14,16,26,27,26,15,14,17,14,0
0,14,17,14,25,26,27,26,23,14,17,14,0
0,14,17,14,16,26,27,26,15,14,17,14,0
0,14,17,14,25,26,27,26,23,14,17,14,0
0,14,17,14,16,26,27,26,15,14,17,14,0
0,14,17,14,25,26,27,26,23,14,17,14,0
0,14,17,14,16,26,27,26,15,14,17,14,0
0,14,17,14,25,26,27,26,23,14,17,14,0
0,14,17,14,16,26,27,26,15,14,17,14,0
0,14,17,14,25,26,27,26,23,14,17,14,0
0,14,17,14,16,26,27,26,15,14,17,14,0
0,14,17,14,25,26,27,26,23,14,17,14,0
0,14,17,14,16,26,27,26,15,14,17,14,0
0,14,17,14,25,26,27,26,23,14,17,14,0
0,14,17,14,16,26,27,26,15,14,17,14,0
0,14,17,14,25,26,27,26,23,14,17,14,0
0,14,17,14,16,26,27,26,15,14,17,14,0
0,14,17,14,25,26,27,26,23,14,17,14,0
0,14,17,14,16,26,27,26,15,14,17,14,0
0,14,17,14,25,26,27,26,23,14,17,14,0
0,14,17,14,16,26,27,26,15,14,17,14,0
0,14,17,14,25,26,27,26,23,14,17,14,0
0,14,17,14,16,26,27,26,15,14,17,14,0
0,14,17,14,25,22,28,22,23,14,17,14,0
0,0,0,0,0,0,0,0,0,0,0,0,0
endlayer

layer
0,0,0,0,0,0,0,0,0,0,0,0,0
0,0,27,0,0,29,30,29,0,0,27,0,0
0,0,27,0,0,25,3,23,0,0,27,0,0
0,0,27,0,0,16,3,15,0,0,27,0,0
0,0,27,0,0,25,3,23,0,0,27,0,0
0,0,27,0,0,16,3,15,0,0,27,0,0
0,0,27,0,0,25,3,23,0,0,27,0,0
0,0,27,0,0,16,3,15,0,0,27,0,0
0,0,27,0,0,25,3,23,0,0,27,0,0
0,0,27,0,0,16,3,15,0,0,27,0,0
0,0,27,0,0,25,3,23,0,0,27,0,0
0,0,27,0,0,16,3,15,0,0,27,0,0
0,0,27,0,0,25,3,23,0,0,27,0,0
0,0,27,0,0,16,3,15,0,0,27,0,0
0,0,27,0,0,25,3,23,0,0,27,0,0
0,0,27,0,0,16,3,15,0,0,27,0,0
0,0,27,0,0,25,3,23,0,0,27,0,0
0,0,27,0,0,16,3,15,0,0,27,0,0
0,0,27,0,0,25,3,23,0,0,27,0,0
0,0,27,0,0,16,3,15,0,0,27,0,0
0,0,27,0,0,25,3,23,0,0,27,0,0
0,0,27,0,0,16,3,15,0,0,27,0,0
0,0,27,0,0,25,3,23,0,0,27,0,0
0,0,27,0,0,16,3,15,0,0,27,0,0
0,0,27,0,0,25,3,23,0,0,27,0,0
0,0,27,0,0,16,3,15,0,0,27,0,0
0,0,27,0,0,25,3,23,0,0,27,0,0
0,0,27,0,0,16,3,15,0,0,27,0,0
0,0,27,0,0,25,3,23,0,0,27,0,0
0,0,27,0,0,32,31,15,0,0,27,0,0
0,0,0,0,0,0,0,0,0,0,0,0,0
endlayer

layer
0,0,0,0,0,0,0,0,0,0,0,0,0
0,0,0,0,0,0,0,0,0,0,0,0,0
0,0,0,0,0,14,14,14,0,0,0,0,0
0,0,0,0,0,14,4,14,0,0,0,0,0
0,0,0,0,0,14,14,14,0,0,0,0,0
0,0,0,0,0,14,14,14,0,0,0,0,0
0,0,0,0,0,14,14,14,0,0,0,0,0
0,0,0,0,0,14,14,14,0,0,0,0,0
0,0,0,0,0,14,14,14,0,0,0,0,0
0,0,0,0,0,14,14,14,0,0,0,0,0
0,0,0,0,0,14,14,14,0,0,0,0,0
0,0,0,0,0,14,14,14,0,0,0,0,0
0,0,0,0,0,14,14,14,0,0,0,0,0
0,0,0,0,0,14,14,14,0,0,0,0,0
0,0,0,0,0,14,14,14,0,0,0,0,0
0,0,0,0,0,14,14,14,0,0,0,0,0
0,0,0,0,0,14,14,14,0,0,0,0,0
0,0,0,0,0,14,14,14,0,0,0,0,0
0,0,0,0,0,14,14,14,0,0,0,0,0
0,0,0,0,0,14,14,14,0,0,0,0,0
0,0,0,0,0,14,14,14,0,0,0,0,0
0,0,0,0,0,14,14,14,0,0,0,0,0
0,0,0,0,0,14,14,14,0,0,0,0,0
0,0,0,0,0,14,14,14,0,0,0,0,0
0,0,0,0,0,14,14,14,0,0,0,0,0
0,0,0,0,0,14,14,14,0,0,0,0,0
0,0,0,0,0,14,14,14,0,0,0,0,0
0,0,0,0,0,14,4,14,0,0,0,0,0
0,0,0,0,0,14,14,14,0,0,0,0,0
0,0,0,0,0,0,0,0,0,0,0,0,0
0,0,0,0,0,0,0,0,0,0,0,0,0
endlayer

layer
0,0,0,0,0,0,0,0,0,0,0,0,0
0,0,0,0,0,0,0,0,0,0,0,0,0
0,0,0,0,0,0,0,0,0,0,0,0,0
0,0,0,0,0,0,27,0,0,0,0,0,0
0,0,0,0,0,0,27,0,0,0,0,0,0
0,0,0,0,0,0,27,0,0,0,0,0,0
0,0,0,0,0,0,27,0,0,0,0,0,0
0,0,0,0,0,0,27,0,0,0,0,0,0
0,0,0,0,0,0,27,0,0,0,0,0,0
0,0,0,0,0,0,27,0,0,0,0,0,0
0,0,0,0,0,0,27,0,0,0,0,0,0
0,0,0,0,0,0,27,0,0,0,0,0,0
0,0,0,0,0,0,27,0,0,0,0,0,0
0,0,0,0,0,0,27,0,0,0,0,0,0
0,0,0,0,0,0,27,0,0,0,0,0,0
0,0,0,0,0,0,27,0,0,0,0,0,0
0,0,0,0,0,0,27,0,0,0,0,0,0
0,0,0,0,0,0,27,0,0,0,0,0,0
0,0,0,0,0,0,27,0,0,0,0,0,0
0,0,0,0,0,0,27,0,0,0,0,0,0
0,0,0,0,0,0,27,0,0,0,0,0,0
0,0,0,0,0,0,27,0,0,0,0,0,0
0,0,0,0,0,0,27,0,0,0,0,0,0
0,0,0,0,0,0,27,0,0,0,0,0,0
0,0,0,0,0,0,27,0,0,0,0,0,0
0,0,0,0,0,0,27,0,0,0,0,0,0
0,0,0,0,0,0,27,0,0,0,0,0,0
0,0,0,0,0,0,27,0,0,0,0,0,0
0,0,0,0,0,0,0,0,0,0,0,0,0
0,0,0,0,0,0,0,0,0,0,0,0,0
0,0,0,0,0,0,0,0,0,0,0,0,0
endlayer

