
# Created by Ruins mod version 15.0 Ingame Parser
# authoring Player: SunsOfOld

weight=100
embed_into_distance=1
acceptable_target_blocks=
unacceptable_target_blocks=flowing_water,water,flowing_lava,lava
dimensions=25,25,24
allowable_overhang=0
max_leveling=5
leveling_buffer=0
preserve_water=0
preserve_lava=0
uniqueMinDistance=1000000
preventRotation=1

rule1=0,100,preserveBlock
rule2=0,100,minecraft:grass-0
rule3=0,100,minecraft:dirt-0
rule4=0,100,UndergroundBiomes:igneousStone-12
rule5=0,100,plantmegapack:epiphyteFragrantFern-2
rule6=0,100,minecraft:log-5
rule7=0,100,plantmegapack:groundcoverLeavesBRN-0
rule8=0,100,minecraft:tallgrass-1
rule9=0,100,plantmegapack:fungusWoollyGomphus-0
rule10=0,100,plantmegapack:groundcoverGrassGRNDK-0
rule11=0,100,minecraft:red_flower-0
rule12=0,100,plantmegapack:groundcoverLeavesGRN-0
rule13=0,100,minecraft:crafting_table-0
rule14=0,100,GardenCore:compost_bin-0
rule15=0,100,IInventory;GardenCore:compost_bin;GardenCore:compost_pile#8#0#9-0
rule16=0,100,IInventory;GardenCore:compost_bin;GardenCore:compost_pile#2#0#9-0
rule17=0,100,IInventory;BiblioCraft:BiblioTable;BiblioCraft:item.FramingSaw#1#0#0-0
rule18=0,100,GardenTrees:thin_log_fence-0
rule19=0,100,ExtrabiomesXL:flower3-8
rule20=0,100,ExtrabiomesXL:flower2-2
rule21=0,100,ExtrabiomesXL:flower2-14
rule22=0,100,ExtrabiomesXL:leaves_1-14
rule23=0,100,chisel:leaves-6
rule24=0,100,ExtrabiomesXL:flower2-4
rule25=0,100,ExtrabiomesXL:flower1-7
rule26=0,100,ExtrabiomesXL:leaves_1-5
rule27=0,100,ExtrabiomesXL:flower3-6
rule28=0,100,ExtrabiomesXL:leaves_1-13
rule29=0,100,dendrology:leaves0-12
rule30=0,100,dendrology:logs1-0
rule31=0,100,plantmegapack:bambooGiantTimberLadder-3
rule32=0,100,minecraft:yellow_flower-0
rule33=0,100,plantmegapack:epiphyteArtistsConk-5
rule34=0,100,ExtrabiomesXL:flower2-11
rule35=0,100,plantmegapack:epiphyteFragrantFern-3
rule36=0,100,dendrology:leaves0-4
rule37=0,100,plantmegapack:hangingWolfWillow-1
rule38=0,100,plantmegapack:hangingFoliageLGRED-1
rule39=0,100,plantmegapack:hangingBambooGolden-1
rule40=0,100,plantmegapack:hangingPhilodendron-1
rule41=0,100,plantmegapack:epiphyteTurkeyTail-2
rule42=0,100,plantmegapack:hangingWolfWillow-0
rule43=0,100,plantmegapack:hangingFoliageLGRED-0
rule44=0,100,plantmegapack:hangingBambooGolden-0
rule45=0,100,plantmegapack:hangingPhilodendron-0
rule46=0,100,dendrology:leaves1-0
rule47=0,100,dendrology:logs1-4
rule48=0,100,minecraft:fence-0
rule49=0,100,plantmegapack:wallBracketIronCurl-4
rule50=0,100,plantmegapack:wallBracketIronCurl-2
rule51=0,100,chisel:oak_planks-11
rule52=0,100,plantmegapack:wallBracketIronCurl-3
rule53=0,100,GardenStuff:lattice_wood-0
rule54=0,100,minecraft:log-8
rule55=0,100,GardenTrees:thin_log-0
rule56=0,100,minecraft:log-4
rule57=0,100,chisel:oak_planks-7
rule58=0,100,minecraft:trapdoor-12
rule59=0,100,dendrology:logs1-8
rule60=0,100,chisel:oak_planks-1
rule61=0,100,IInventory;minecraft:chest;harvestcraft:snickersbarItem#4#0#2+minecraft:painting#1#0#9+BiomesOPlenty:jarEmpty#3#0#13+GardenTrees:strange_plant#3#0#17+harvestcraft:snickersbarItem#1#0#20+harvestcraft:snickersbarItem#2#0#24-3
rule62=0,100,chisel:oak_planks-12
rule63=0,100,IInventory;BiblioCraft:BiblioTable;minecraft:wooden_sword#{RepairCost:2,display:{Name:"Wood Scepter",},}#0#0-1
rule64=0,100,minecraft:oak_stairs-1
rule65=0,100,minecraft:jukebox-0
rule66=0,100,BiblioCraft:BiblioSeats-1
rule67=0,100,IInventory;BiblioCraft:BiblioTable;BiblioCraft:BiblioStuffs#1#2#0-1
rule68=0,100,minecraft:wooden_slab-8
rule69=0,100,plantmegapack:epiphyteFishBoneCactus-4
rule70=0,100,minecraft:oak_stairs-7
rule71=0,100,IInventory;BiblioCraft:BiblioCase;BiblioCraft:item.BigBook#{author:"Polyphaga",RepairCost:2,display:{Name:"Entomology 101",},}#0#0-1
rule72=0,100,chisel:glass-6
rule73=0,100,harvestcraft:beehive-0
rule74=0,100,plantmegapack:hangingFlowersGRN-1
rule75=0,100,plantmegapack:hangingWildfire-1
rule76=0,100,dendrology:leaves1-12
rule77=0,100,plantmegapack:hangingFlowersGRN-0
rule78=0,100,plantmegapack:hangingWildfire-0
rule79=0,100,GardenContainers:large_pot_colored-14
rule80=0,100,plantmegapack:hangingLavender-1
rule81=0,100,minecraft:carpet-12
rule82=0,100,plantmegapack:bambooGiantTimberLadder-5
rule83=0,100,GardenStuff:light_chain-0
rule84=0,100,plantmegapack:hangingLavender-0
rule85=0,100,minecraft:flower_pot-2
rule86=0,100,plantmegapack:wallBracketWoodDarkOak-2
rule87=0,100,chisel:oak_planks-4
rule88=0,100,plantmegapack:epiphyteKingOrchid-3
rule89=0,100,plantmegapack:epiphyteCreepingMistletoe-2
rule90=0,100,dendrology:leaves1-4
rule91=0,100,IInventory;minecraft:chest;harvestcraft:snickersbarItem#2#0#1+BiomesOPlenty:gems#1#7#4+harvestcraft:snickersbarItem#1#0#8+BiomesOPlenty:gems#1#7#12+dendrology:sapling0#1#4#13+BiomesOPlenty:gems#1#7#14+BiomesOPlenty:jarEmpty#2#0#18+BiomesOPlenty:gems#1#7#22-4

layer
1,1,1,1,1,1,1,1,1,1,1,1,1,1,1,1,1,1,1,1,1,1,1,1
1,1,1,1,1,1,1,1,1,1,1,1,1,1,1,1,1,1,1,1,1,1,1,1
1,1,1,1,1,1,1,1,1,1,1,1,1,1,1,1,1,1,1,1,1,1,1,1
1,1,1,1,2,1,1,1,1,1,2,1,2,1,1,1,1,1,2,1,1,1,1,1
1,1,1,1,1,1,1,2,2,1,1,2,2,2,1,2,1,2,2,1,1,1,1,1
1,1,1,1,2,2,2,2,2,2,2,2,2,2,2,2,2,2,2,1,1,1,1,1
1,1,1,2,2,2,2,2,2,2,2,2,3,3,3,2,2,2,1,1,1,1,1,1
1,1,1,1,1,2,2,2,2,2,2,2,2,3,2,2,2,2,2,1,1,2,1,1
1,1,1,1,2,2,4,2,3,2,2,2,2,2,2,2,2,2,2,2,2,1,1,1
1,1,1,1,2,2,4,3,4,2,2,2,2,2,2,2,2,2,2,2,1,1,1,1
1,1,1,2,2,2,2,3,3,2,2,2,2,2,2,2,2,2,2,1,1,1,1,1
1,1,1,1,1,2,2,2,2,2,2,2,2,2,2,2,2,2,2,1,1,1,1,1
1,1,1,1,1,2,2,2,2,2,2,2,3,2,2,2,2,2,2,1,2,1,1,1
1,1,1,1,1,2,2,2,2,2,2,2,2,2,2,2,2,2,2,1,1,1,1,1
1,1,1,1,2,2,2,2,2,2,2,2,2,2,2,2,2,2,2,2,1,1,1,1
1,1,1,1,2,2,2,2,2,2,2,2,2,2,2,2,2,2,2,2,2,1,1,1
1,1,1,2,2,2,2,2,3,2,2,2,2,2,2,2,2,2,2,1,1,1,1,1
1,1,1,1,2,2,2,3,3,2,2,2,2,3,2,2,2,2,2,1,1,1,1,1
1,1,1,1,1,2,2,2,2,3,2,2,2,3,4,2,2,2,2,1,1,1,1,1
1,1,1,1,2,1,1,1,2,2,2,2,2,2,4,2,2,2,2,1,1,1,1,1
1,1,1,1,1,1,2,1,2,2,1,1,1,2,2,1,2,1,1,2,2,1,1,1
1,1,1,1,1,1,1,1,2,1,1,1,1,2,1,1,1,1,1,1,1,1,1,1
1,1,1,1,1,1,1,1,1,1,1,1,1,1,1,1,1,1,1,1,1,1,1,1
1,1,1,1,1,1,1,1,1,1,1,1,1,1,1,1,1,1,1,1,1,1,1,1
1,1,1,1,1,1,1,1,1,1,1,1,1,1,1,1,1,1,1,1,1,1,1,1
endlayer

layer
0,0,0,0,0,0,0,0,0,0,0,0,0,0,0,0,0,0,0,0,0,0,0,0
0,0,0,0,0,0,0,0,0,0,0,0,0,0,0,0,0,0,0,0,6,0,6,5
0,0,0,0,0,0,0,0,0,0,0,0,0,0,0,0,0,0,0,0,6,6,6,0
0,0,0,0,9,0,0,0,0,0,8,0,0,0,0,0,0,0,7,0,6,6,6,0
0,0,0,0,0,0,0,8,8,0,0,8,0,9,0,0,0,8,10,0,6,6,6,0
0,0,0,0,9,8,8,8,12,0,0,8,0,0,8,8,8,11,0,0,6,6,0,0
0,0,0,0,12,8,8,8,8,8,8,0,4,4,4,0,8,8,0,0,0,0,0,0
0,0,0,0,0,8,8,10,8,0,0,7,0,4,8,8,0,0,0,0,0,0,0,0
0,0,0,0,8,8,0,0,4,0,10,0,0,0,8,8,12,0,17,16,15,14,13,0
0,0,0,0,8,8,0,4,0,0,0,21,12,8,20,0,19,0,18,18,18,18,18,18
0,0,0,0,0,8,25,4,4,0,12,0,0,8,7,24,10,0,18,0,23,0,22,18
0,0,0,0,0,10,0,0,0,0,0,27,0,0,0,8,0,0,18,22,26,22,23,18
0,0,0,0,0,0,0,8,7,12,0,31,30,8,0,7,8,0,18,29,28,22,26,18
0,0,0,0,0,0,0,8,0,8,8,8,0,0,8,0,0,0,18,29,28,29,29,18
0,0,0,0,0,0,8,8,8,0,0,8,7,0,12,8,7,0,18,29,22,23,28,18
0,0,0,0,0,0,8,8,8,8,0,10,8,8,8,32,32,32,0,23,23,28,0,18
0,0,0,0,0,10,0,8,4,0,12,0,0,8,8,11,0,8,18,18,18,18,18,18
0,0,0,0,0,0,0,4,4,0,8,0,0,4,8,8,8,7,24,0,0,33,0,0
0,0,0,0,0,0,0,0,0,4,0,0,12,4,0,8,12,8,8,0,0,0,0,0
0,0,0,0,0,0,0,0,7,0,0,0,0,0,0,34,32,8,12,0,0,0,0,0
0,0,0,0,0,0,0,0,0,0,0,0,0,0,8,0,32,0,0,0,0,0,0,0
0,0,0,0,0,0,0,0,0,0,0,0,0,7,0,0,0,0,0,0,0,0,0,0
0,0,0,0,0,0,0,0,0,0,0,0,0,0,0,0,0,0,0,0,0,0,0,0
0,0,0,0,0,0,0,0,0,0,0,0,0,0,0,0,0,0,0,0,0,0,0,0
0,0,0,0,0,0,0,0,0,0,0,0,0,0,0,0,0,0,0,0,0,0,0,0
endlayer

layer
0,0,0,0,0,0,0,0,0,0,0,0,0,0,0,0,0,0,0,0,0,0,0,0
0,0,0,0,0,0,0,0,0,0,0,0,0,0,0,0,0,0,0,0,0,0,0,0
0,0,0,0,0,0,0,0,0,0,0,0,0,0,0,0,0,0,0,0,0,0,0,0
0,0,0,0,0,0,0,0,0,0,0,0,0,0,0,0,0,0,0,0,0,6,0,0
0,0,0,0,0,0,0,0,0,0,0,0,0,0,0,0,0,0,0,0,35,6,0,0
0,0,0,0,0,0,0,0,0,0,0,0,0,0,0,0,0,0,0,0,0,0,0,0
0,0,0,0,0,0,0,0,0,0,0,0,0,4,0,0,0,0,0,0,0,0,0,0
0,0,0,0,0,0,0,0,0,0,0,0,0,0,0,0,0,0,0,0,0,0,0,0
0,0,0,0,0,0,0,0,0,0,0,0,0,0,0,0,0,0,0,0,0,0,0,0
0,0,0,0,0,0,0,0,0,0,0,0,0,0,0,0,0,0,0,0,0,0,0,0
0,0,0,0,0,0,0,0,4,0,0,0,0,0,0,0,0,0,0,0,0,0,0,0
0,0,0,0,0,0,0,0,0,0,0,0,0,0,0,0,0,0,0,0,23,0,0,0
0,0,0,0,0,0,0,0,0,0,0,31,30,0,0,0,0,0,0,0,36,23,0,0
0,0,0,0,0,0,0,0,0,0,0,0,0,0,0,0,0,0,0,0,0,28,0,0
0,0,0,0,0,0,0,0,0,0,0,0,0,0,0,0,0,0,0,28,0,0,28,0
0,0,0,0,0,0,0,0,0,0,0,0,0,0,0,0,0,0,0,0,0,0,0,0
0,0,0,0,0,0,0,0,0,0,0,0,0,0,0,0,0,0,0,0,0,0,0,0
0,0,0,0,0,0,0,0,0,0,0,0,0,0,0,0,0,0,0,0,0,0,0,0
0,0,0,0,0,0,0,0,0,0,0,0,0,0,0,0,0,0,0,0,0,0,0,0
0,0,0,0,0,0,0,0,0,0,0,0,0,0,0,0,0,0,0,0,0,0,0,0
0,0,0,0,0,0,0,0,0,0,0,0,0,0,0,0,0,0,0,0,0,0,0,0
0,0,0,0,0,0,0,0,0,0,0,0,0,0,0,0,0,0,0,0,0,0,0,0
0,0,0,0,0,0,0,0,0,0,0,0,0,0,0,0,0,0,0,0,0,0,0,0
0,0,0,0,0,0,0,0,0,0,0,0,0,0,0,0,0,0,0,0,0,0,0,0
0,0,0,0,0,0,0,0,0,0,0,0,0,0,0,0,0,0,0,0,0,0,0,0
endlayer

layer
0,0,0,0,0,0,0,0,0,0,0,0,0,0,0,0,0,0,0,0,0,0,0,0
0,0,0,0,0,0,0,0,0,0,0,0,0,0,0,0,0,0,0,0,0,0,0,0
0,0,0,0,0,0,0,0,0,0,0,0,0,0,0,0,0,0,0,0,0,0,0,0
0,0,0,0,0,0,0,0,0,0,0,0,0,0,0,0,0,0,0,0,0,0,0,0
0,0,0,0,0,0,0,0,0,0,0,0,0,0,0,0,0,0,0,0,0,0,0,0
0,0,0,0,0,0,0,0,0,0,0,0,0,0,0,0,0,0,0,0,0,0,0,0
0,0,0,0,0,0,0,0,0,0,0,0,0,0,0,0,0,0,0,0,0,0,0,0
0,0,0,0,0,0,0,0,0,0,0,0,0,0,0,0,0,0,0,0,0,0,0,0
0,0,0,0,0,0,0,0,0,0,0,0,0,0,0,0,0,0,0,0,0,0,0,0
0,0,0,0,0,0,0,0,0,0,0,0,0,0,0,0,0,0,0,0,0,0,0,0
0,0,0,0,0,0,0,0,0,0,0,0,0,0,0,0,0,0,0,0,0,0,0,0
0,0,0,0,0,0,0,0,0,0,0,0,0,0,0,0,0,0,0,0,0,0,0,0
0,0,0,0,0,0,0,0,0,0,0,31,30,0,0,0,0,0,0,0,0,0,0,0
0,0,0,0,0,0,0,0,0,0,0,0,0,0,0,0,0,0,0,0,0,0,0,0
0,0,0,0,0,0,0,0,0,0,0,0,0,0,0,0,0,0,0,0,0,0,0,0
0,0,0,0,0,0,0,0,0,0,0,0,0,0,0,0,0,0,0,0,0,0,0,0
0,0,0,0,0,0,0,0,0,0,0,0,0,0,0,0,0,0,0,0,0,0,0,0
0,0,0,0,0,0,0,0,0,0,0,0,0,0,0,0,0,0,0,0,0,0,0,0
0,0,0,0,0,0,0,0,0,0,0,0,0,0,0,0,0,0,0,0,0,0,0,0
0,0,0,0,0,0,0,0,0,0,0,0,0,0,0,0,0,0,0,0,0,0,0,0
0,0,0,0,0,0,0,0,0,0,0,0,0,0,0,0,0,0,0,0,0,0,0,0
0,0,0,0,0,0,0,0,0,0,0,0,0,0,0,0,0,0,0,0,0,0,0,0
0,0,0,0,0,0,0,0,0,0,0,0,0,0,0,0,0,0,0,0,0,0,0,0
0,0,0,0,0,0,0,0,0,0,0,0,0,0,0,0,0,0,0,0,0,0,0,0
0,0,0,0,0,0,0,0,0,0,0,0,0,0,0,0,0,0,0,0,0,0,0,0
endlayer

layer
0,0,0,0,0,0,0,0,0,0,0,0,0,0,0,0,0,0,0,0,0,0,0,0
0,0,0,0,0,0,0,0,0,0,0,0,0,0,0,0,0,0,0,0,0,0,0,0
0,0,0,0,0,0,0,0,0,0,0,0,0,0,0,0,0,0,0,0,0,0,0,0
0,0,0,0,0,0,0,0,0,0,0,0,0,0,0,0,0,0,0,0,0,0,0,0
0,0,0,0,0,0,0,0,0,0,0,0,0,0,0,0,0,0,0,0,0,0,0,0
0,0,0,0,0,0,0,0,0,0,0,0,0,0,0,0,0,0,0,0,0,0,0,0
0,0,0,0,0,0,0,0,0,0,0,0,0,0,0,0,0,0,0,0,0,0,0,0
0,0,0,0,0,0,0,0,0,0,0,0,0,0,0,0,0,0,0,0,0,0,0,0
0,0,0,0,0,0,0,0,0,0,0,0,0,0,0,0,0,0,0,0,0,0,0,0
0,0,0,0,0,0,0,0,0,0,0,0,0,0,0,0,0,0,0,0,0,0,0,0
0,0,0,0,0,0,0,0,0,0,0,0,0,0,0,0,0,0,0,0,0,0,0,0
0,0,0,0,0,0,0,0,0,0,0,0,0,0,0,0,0,0,0,0,0,0,0,0
0,0,0,0,0,0,0,0,0,0,0,31,30,0,0,0,0,0,0,0,0,0,0,0
0,0,0,0,0,0,0,0,0,0,0,0,0,0,0,0,0,0,0,0,0,0,0,0
0,0,0,0,0,0,0,0,0,0,0,0,0,0,0,0,0,0,0,0,0,0,0,0
0,0,0,0,0,0,0,0,0,0,0,0,0,0,0,0,0,0,0,0,0,0,0,0
0,0,0,0,0,0,0,0,0,0,0,0,0,0,0,0,0,0,0,0,0,0,0,0
0,0,0,0,0,0,0,0,0,0,0,0,0,0,0,0,0,0,0,0,0,0,0,0
0,0,0,0,0,0,0,0,0,0,0,0,0,0,0,0,0,0,0,0,0,0,0,0
0,0,0,0,0,0,0,0,0,0,0,0,0,0,0,0,0,0,0,0,0,0,0,0
0,0,0,0,0,0,0,0,0,0,0,0,0,0,0,0,0,0,0,0,0,0,0,0
0,0,0,0,0,0,0,0,0,0,0,0,0,0,0,0,0,0,0,0,0,0,0,0
0,0,0,0,0,0,0,0,0,0,0,0,0,0,0,0,0,0,0,0,0,0,0,0
0,0,0,0,0,0,0,0,0,0,0,0,0,0,0,0,0,0,0,0,0,0,0,0
0,0,0,0,0,0,0,0,0,0,0,0,0,0,0,0,0,0,0,0,0,0,0,0
endlayer

layer
0,0,0,0,0,0,0,0,0,0,0,0,0,0,0,0,0,0,0,0,0,0,0,0
0,0,0,0,0,0,0,0,0,0,0,0,0,0,0,0,0,0,0,0,0,0,0,0
0,0,0,0,0,0,0,0,0,0,0,0,0,0,0,0,0,0,0,0,0,0,0,0
0,0,0,0,0,0,0,0,0,0,0,0,0,0,0,0,0,0,0,0,0,0,0,0
0,0,0,0,0,0,0,0,0,0,0,0,0,0,0,0,0,0,0,0,0,0,0,0
0,0,0,0,0,0,0,0,0,0,0,0,0,0,0,0,0,0,0,0,0,0,0,0
0,0,0,0,0,0,0,0,0,0,0,0,0,0,0,0,0,0,0,0,0,0,0,0
0,0,0,0,0,0,0,0,0,0,0,0,0,0,0,0,0,0,0,0,0,0,0,0
0,0,0,0,0,0,0,0,0,0,0,0,0,0,0,0,0,0,0,0,0,0,0,0
0,0,0,0,0,0,0,0,0,0,0,0,0,0,0,0,0,0,0,0,0,0,0,0
0,0,0,0,0,0,0,0,0,0,0,0,0,0,0,0,0,0,0,0,0,0,0,0
0,0,0,0,0,0,0,0,0,0,0,0,0,0,0,0,0,0,0,0,0,0,0,0
0,0,0,0,0,0,0,0,0,0,0,31,30,0,0,0,0,0,0,0,0,0,0,0
0,0,0,0,0,0,0,0,0,0,0,0,0,0,0,0,0,0,0,0,0,0,0,0
0,0,0,0,0,0,0,0,0,0,0,0,0,0,0,0,0,0,0,0,0,0,0,0
0,0,0,0,0,0,0,0,0,0,0,0,0,0,0,0,0,0,0,0,0,0,0,0
0,0,0,0,0,0,0,0,0,0,0,0,0,0,0,0,0,0,0,0,0,0,0,0
0,0,0,0,0,0,0,0,0,0,0,0,0,0,0,0,0,0,0,0,0,0,0,0
0,0,0,0,0,0,0,0,0,0,0,0,0,0,0,0,0,0,0,0,0,0,0,0
0,0,0,0,0,0,0,0,0,0,0,0,0,0,0,0,0,0,0,0,0,0,0,0
0,0,0,0,0,0,0,0,0,0,0,0,0,0,0,0,0,0,0,0,0,0,0,0
0,0,0,0,0,0,0,0,0,0,0,0,0,0,0,0,0,0,0,0,0,0,0,0
0,0,0,0,0,0,0,0,0,0,0,0,0,0,0,0,0,0,0,0,0,0,0,0
0,0,0,0,0,0,0,0,0,0,0,0,0,0,0,0,0,0,0,0,0,0,0,0
0,0,0,0,0,0,0,0,0,0,0,0,0,0,0,0,0,0,0,0,0,0,0,0
endlayer

layer
0,0,0,0,0,0,0,0,0,0,0,0,0,0,0,0,0,0,0,0,0,0,0,0
0,0,0,0,0,0,0,0,0,0,0,0,0,0,0,0,0,0,0,0,0,0,0,0
0,0,0,0,0,0,0,0,0,0,0,0,0,0,0,0,0,0,0,0,0,0,0,0
0,0,0,0,0,0,0,0,0,0,0,0,0,0,0,0,0,0,0,0,0,0,0,0
0,0,0,0,0,0,0,0,0,0,0,0,0,0,0,0,0,0,0,0,0,0,0,0
0,0,0,0,0,0,0,0,0,0,0,0,0,0,0,0,0,0,0,0,0,0,0,0
0,0,0,0,0,0,0,0,0,0,0,0,0,0,0,0,0,0,0,0,0,0,0,0
0,0,0,0,0,0,0,0,0,0,0,0,0,0,0,0,0,0,0,0,0,0,0,0
0,0,0,0,0,0,0,0,0,0,0,0,0,0,0,0,0,0,0,0,0,0,0,0
0,0,0,0,0,0,0,0,0,0,0,0,0,0,0,0,0,0,0,0,0,0,0,0
0,0,0,0,0,0,0,0,0,0,0,0,0,0,0,0,0,0,0,0,0,0,0,0
0,0,0,0,0,0,0,0,0,0,0,0,0,0,0,0,0,0,0,0,0,0,0,0
0,0,0,0,0,0,0,0,0,0,0,31,30,0,0,0,0,0,0,0,0,0,0,0
0,0,0,0,0,0,0,0,0,0,0,0,0,0,0,0,0,0,0,0,0,0,0,0
0,0,0,0,0,0,0,0,0,0,0,0,0,0,0,0,0,0,0,0,0,0,0,0
0,0,0,0,0,0,0,0,0,0,0,0,0,0,0,0,0,0,0,0,0,0,0,0
0,0,0,0,0,0,0,0,0,0,0,0,0,0,0,0,0,0,0,0,0,0,0,0
0,0,0,0,0,0,0,0,0,0,0,0,0,0,0,0,0,0,0,0,0,0,0,0
0,0,0,0,0,0,0,0,0,0,0,0,0,0,0,0,0,0,0,0,0,0,0,0
0,0,0,0,0,0,0,0,0,0,0,0,0,0,0,0,0,0,0,0,0,0,0,0
0,0,0,0,0,0,0,0,0,0,0,0,0,0,0,0,0,0,0,0,0,0,0,0
0,0,0,0,0,0,0,0,0,0,0,0,0,0,0,0,0,0,0,0,0,0,0,0
0,0,0,0,0,0,0,0,0,0,0,0,0,0,0,0,0,0,0,0,0,0,0,0
0,0,0,0,0,0,0,0,0,0,0,0,0,0,0,0,0,0,0,0,0,0,0,0
0,0,0,0,0,0,0,0,0,0,0,0,0,0,0,0,0,0,0,0,0,0,0,0
endlayer

layer
0,0,0,0,0,0,0,0,0,0,0,0,0,0,0,0,0,0,0,0,0,0,0,0
0,0,0,0,0,0,0,0,0,0,0,0,0,0,0,0,0,0,0,0,0,0,0,0
0,0,0,0,0,0,0,0,0,0,0,0,0,0,0,0,0,0,0,0,0,0,0,0
0,0,0,0,0,0,0,0,0,0,0,0,0,0,0,0,0,0,0,0,0,0,0,0
0,0,0,0,0,0,0,0,0,0,0,0,0,0,0,0,0,0,0,0,0,0,0,0
0,0,0,0,0,0,0,0,0,0,0,0,0,0,0,0,0,0,0,0,0,0,0,0
0,0,0,0,0,0,0,0,0,0,38,0,37,0,0,0,0,0,0,0,0,0,0,0
0,0,0,0,0,0,0,0,0,40,0,0,0,39,0,0,0,0,0,0,0,0,0,0
0,0,0,0,0,0,0,0,0,0,0,0,0,0,0,0,0,0,0,0,0,0,0,0
0,0,0,0,0,0,0,0,0,0,0,0,0,0,0,0,0,0,0,0,0,0,0,0
0,0,0,0,0,0,0,0,0,0,0,0,0,0,0,0,0,0,0,0,0,0,0,0
0,0,0,0,0,0,0,0,0,0,0,0,0,0,0,0,0,0,0,0,0,0,0,0
0,0,0,0,0,0,0,0,0,0,0,31,30,41,0,0,0,0,0,0,0,0,0,0
0,0,0,0,0,0,0,0,0,0,0,0,0,0,0,0,0,0,0,0,0,0,0,0
0,0,0,0,0,0,0,0,0,0,0,0,0,0,0,0,0,0,0,0,0,0,0,0
0,0,0,0,0,0,0,0,0,0,0,0,0,0,0,0,0,0,0,0,0,0,0,0
0,0,0,0,0,0,0,0,0,0,0,0,0,0,0,0,0,0,0,0,0,0,0,0
0,0,0,0,0,0,0,0,0,0,0,0,0,0,0,0,0,0,0,0,0,0,0,0
0,0,0,0,0,0,0,0,0,0,0,0,0,0,0,0,0,0,0,0,0,0,0,0
0,0,0,0,0,0,0,0,0,0,0,0,0,0,0,0,0,0,0,0,0,0,0,0
0,0,0,0,0,0,0,0,0,0,0,0,0,0,0,0,0,0,0,0,0,0,0,0
0,0,0,0,0,0,0,0,0,0,0,0,0,0,0,0,0,0,0,0,0,0,0,0
0,0,0,0,0,0,0,0,0,0,0,0,0,0,0,0,0,0,0,0,0,0,0,0
0,0,0,0,0,0,0,0,0,0,0,0,0,0,0,0,0,0,0,0,0,0,0,0
0,0,0,0,0,0,0,0,0,0,0,0,0,0,0,0,0,0,0,0,0,0,0,0
endlayer

layer
0,0,0,0,0,0,0,0,0,0,0,0,0,0,0,0,0,0,0,0,0,0,0,0
0,0,0,0,0,0,0,0,0,0,0,0,0,0,0,0,0,0,0,0,0,0,0,0
0,0,0,0,0,0,0,0,0,0,0,0,0,0,0,0,0,0,0,0,0,0,0,0
0,0,0,0,0,0,0,0,0,0,0,0,0,0,0,0,0,0,0,0,0,0,0,0
0,0,0,0,0,0,0,0,0,0,0,0,0,0,0,0,0,0,0,0,0,0,0,0
0,0,0,0,0,0,0,0,0,0,0,0,0,0,0,0,0,0,0,0,0,0,0,0
0,0,0,0,0,0,0,0,0,0,43,0,42,0,0,0,0,0,0,0,0,0,0,0
0,0,0,0,0,0,0,0,0,45,0,0,0,44,0,0,0,0,0,0,0,0,0,0
0,0,0,0,0,0,0,0,0,0,0,0,0,0,0,0,0,0,0,0,0,0,0,0
0,0,0,0,0,0,0,0,0,0,0,0,0,0,0,0,0,0,0,0,0,0,0,0
0,0,0,0,0,0,0,0,0,0,0,0,0,0,0,0,0,0,0,0,0,0,0,0
0,0,0,0,0,0,0,0,0,0,48,48,47,46,0,0,0,0,0,0,0,0,0,0
0,0,0,0,0,0,0,0,0,0,48,31,30,46,0,0,0,0,0,0,0,0,0,0
0,0,0,0,0,0,0,0,0,0,48,46,46,46,0,0,0,0,0,0,0,0,0,0
0,0,0,0,0,0,0,0,0,0,0,0,0,0,0,0,0,0,0,0,0,0,0,0
0,0,0,0,0,0,0,0,0,0,0,0,0,0,0,0,0,0,0,0,0,0,0,0
0,0,0,0,0,0,0,0,0,0,0,0,0,0,0,0,0,0,0,0,0,0,0,0
0,0,0,0,0,0,0,0,0,0,0,0,0,0,0,0,0,0,0,0,0,0,0,0
0,0,0,0,0,0,0,0,0,0,0,0,0,0,0,0,0,0,0,0,0,0,0,0
0,0,0,0,0,0,0,0,0,0,0,0,0,0,0,0,0,0,0,0,0,0,0,0
0,0,0,0,0,0,0,0,0,0,0,0,0,0,0,0,0,0,0,0,0,0,0,0
0,0,0,0,0,0,0,0,0,0,0,0,0,0,0,0,0,0,0,0,0,0,0,0
0,0,0,0,0,0,0,0,0,0,0,0,0,0,0,0,0,0,0,0,0,0,0,0
0,0,0,0,0,0,0,0,0,0,0,0,0,0,0,0,0,0,0,0,0,0,0,0
0,0,0,0,0,0,0,0,0,0,0,0,0,0,0,0,0,0,0,0,0,0,0,0
endlayer

layer
0,0,0,0,0,0,0,0,0,0,0,0,0,0,0,0,0,0,0,0,0,0,0,0
0,0,0,0,0,0,0,0,0,0,0,0,0,0,0,0,0,0,0,0,0,0,0,0
0,0,0,0,0,0,0,0,0,0,0,0,0,0,0,0,0,0,0,0,0,0,0,0
0,0,0,0,0,0,0,0,0,0,0,0,0,0,0,0,0,0,0,0,0,0,0,0
0,0,0,0,0,0,0,0,0,0,0,0,0,0,0,0,0,0,0,0,0,0,0,0
0,0,0,0,0,0,0,0,0,0,0,0,0,0,0,0,0,0,0,0,0,0,0,0
0,0,0,0,0,0,0,0,0,0,49,0,49,0,0,0,0,0,0,0,0,0,0,0
0,0,0,0,0,0,0,0,0,52,51,51,51,50,0,0,0,0,0,0,0,0,0,0
0,0,0,0,0,55,55,55,55,54,54,54,54,54,54,53,0,0,0,0,0,0,0,0
0,0,0,0,55,55,51,51,56,57,57,57,57,57,57,56,55,55,0,0,0,0,0,0
0,0,0,0,55,51,51,51,56,57,57,57,47,57,57,56,51,55,55,0,0,0,0,0
0,0,0,0,55,51,51,51,56,57,57,57,57,57,57,56,51,51,55,0,0,0,0,0
0,0,0,0,55,51,51,51,56,57,57,58,30,57,57,56,51,51,55,0,0,0,0,0
0,0,0,0,55,51,51,51,56,57,57,59,57,59,57,56,51,51,55,55,0,0,0,0
0,0,0,0,55,51,51,51,56,57,57,57,57,57,57,56,51,55,55,0,0,0,0,0
0,0,0,0,55,55,51,51,56,57,57,57,57,57,57,56,55,55,0,0,0,0,0,0
0,0,0,0,0,55,55,55,55,54,54,54,54,54,54,53,0,0,0,0,0,0,0,0
0,0,0,0,0,0,0,0,0,0,0,0,0,0,0,0,0,0,0,0,0,0,0,0
0,0,0,0,0,0,0,0,0,0,0,0,0,0,0,0,0,0,0,0,0,0,0,0
0,0,0,0,0,0,0,0,0,0,0,0,0,0,0,0,0,0,0,0,0,0,0,0
0,0,0,0,0,0,0,0,0,0,0,0,0,0,0,0,0,0,0,0,0,0,0,0
0,0,0,0,0,0,0,0,0,0,0,0,0,0,0,0,0,0,0,0,0,0,0,0
0,0,0,0,0,0,0,0,0,0,0,0,0,0,0,0,0,0,0,0,0,0,0,0
0,0,0,0,0,0,0,0,0,0,0,0,0,0,0,0,0,0,0,0,0,0,0,0
0,0,0,0,0,0,0,0,0,0,0,0,0,0,0,0,0,0,0,0,0,0,0,0
endlayer

layer
0,0,0,0,0,0,0,0,0,0,0,0,0,0,0,0,0,0,0,0,0,0,0,0
0,0,0,0,0,0,0,0,0,0,0,0,0,0,0,0,0,0,0,0,0,0,0,0
0,0,0,0,0,0,0,0,0,0,0,0,0,0,0,0,0,0,0,0,0,0,0,0
0,0,0,0,0,0,0,0,0,0,0,0,0,0,0,0,0,0,0,0,0,0,0,0
0,0,0,0,0,0,0,0,0,0,0,0,0,0,0,0,0,0,0,0,0,0,0,0
0,0,0,0,0,0,0,0,0,0,0,0,0,0,0,0,0,0,0,0,0,0,0,0
0,0,0,0,0,0,0,0,0,53,53,53,53,53,0,0,0,0,0,0,0,0,0,0
0,0,0,0,0,0,0,0,0,53,0,0,0,53,0,0,0,0,0,0,0,0,0,0
0,0,0,0,0,18,18,18,18,60,60,0,60,60,60,53,0,0,0,0,0,0,0,0
0,0,0,0,18,18,0,62,60,0,0,0,0,0,61,60,18,18,0,0,0,0,0,0
0,0,0,0,18,0,62,62,60,0,0,0,0,0,62,60,63,18,18,0,0,0,0,0
0,0,0,0,18,0,0,0,53,0,0,0,65,0,64,60,0,0,18,0,0,0,0,0
0,0,0,0,18,0,0,0,0,0,0,0,30,0,0,0,0,0,18,0,0,0,0,0
0,0,0,0,18,0,0,0,53,0,0,0,0,0,0,60,0,0,0,0,0,0,0,0
0,0,0,0,18,67,66,0,60,66,0,0,0,66,0,60,0,18,18,0,0,0,0,0
0,0,0,0,18,18,0,0,60,68,68,68,68,68,68,60,18,18,0,0,0,0,0,0
0,0,0,0,0,18,18,18,18,60,60,60,60,60,60,53,0,0,0,0,0,0,0,0
0,0,0,0,0,0,0,0,0,0,0,0,0,0,0,0,0,0,0,0,0,0,0,0
0,0,0,0,0,0,0,0,0,0,0,0,0,0,0,0,0,0,0,0,0,0,0,0
0,0,0,0,0,0,0,0,0,0,0,0,0,0,0,0,0,0,0,0,0,0,0,0
0,0,0,0,0,0,0,0,0,0,0,0,0,0,0,0,0,0,0,0,0,0,0,0
0,0,0,0,0,0,0,0,0,0,0,0,0,0,0,0,0,0,0,0,0,0,0,0
0,0,0,0,0,0,0,0,0,0,0,0,0,0,0,0,0,0,0,0,0,0,0,0
0,0,0,0,0,0,0,0,0,0,0,0,0,0,0,0,0,0,0,0,0,0,0,0
0,0,0,0,0,0,0,0,0,0,0,0,0,0,0,0,0,0,0,0,0,0,0,0
endlayer

layer
0,0,0,0,0,0,0,0,0,0,0,0,0,0,0,0,0,0,0,0,0,0,0,0
0,0,0,0,0,0,0,0,0,0,0,0,0,0,0,0,0,0,0,0,0,0,0,0
0,0,0,0,0,0,0,0,0,0,0,0,0,0,0,0,0,0,0,0,0,0,0,0
0,0,0,0,0,0,0,0,0,0,0,0,0,0,0,0,0,0,0,0,0,0,0,0
0,0,0,0,0,0,0,0,0,0,0,0,0,0,0,0,0,0,0,0,0,0,0,0
0,0,0,0,0,0,46,46,46,0,0,46,46,46,0,0,0,0,0,0,0,0,0,0
0,0,0,0,0,46,46,46,46,46,0,0,0,46,46,0,0,0,0,0,0,0,0,0
0,0,0,0,0,46,46,46,46,46,0,0,69,46,46,0,0,0,0,0,0,0,0,0
0,0,0,0,0,46,46,46,59,60,60,0,47,60,60,53,0,0,0,0,0,0,0,0
0,0,0,0,0,0,46,46,60,0,0,0,0,0,70,60,0,0,0,0,0,0,0,0
0,0,0,0,0,0,0,62,60,0,0,0,0,0,64,60,0,0,0,0,0,0,0,0
0,0,0,0,0,0,0,0,53,0,0,0,0,0,0,60,0,0,0,0,0,0,0,0
0,0,0,0,0,0,0,0,0,0,0,0,30,0,0,0,0,0,0,0,0,0,0,0
0,0,0,0,0,0,0,0,53,0,0,0,0,0,0,60,0,0,0,0,0,0,0,0
0,0,0,0,0,0,0,0,60,0,0,0,0,0,0,60,0,0,0,0,0,0,0,0
0,0,0,0,0,0,0,0,60,0,71,0,0,0,0,59,0,0,0,0,0,0,0,0
0,0,0,0,0,0,0,0,53,72,72,60,60,72,72,53,0,0,0,0,0,0,0,0
0,0,0,0,0,0,0,0,0,0,0,0,0,0,0,0,0,0,0,0,0,0,0,0
0,0,0,0,0,0,0,0,0,0,0,0,0,0,0,0,0,0,0,0,0,0,0,0
0,0,0,0,0,0,0,0,0,0,0,0,0,0,0,0,73,0,0,0,0,0,0,0
0,0,0,0,0,0,0,0,0,0,0,0,0,0,0,0,0,0,0,0,0,0,0,0
0,0,0,0,0,0,0,0,0,0,0,0,0,0,0,0,0,0,0,0,0,0,0,0
0,0,0,0,0,0,0,0,0,0,0,0,0,0,0,0,0,0,0,0,0,0,0,0
0,0,0,0,0,0,0,0,0,0,0,0,0,0,0,0,0,0,0,0,0,0,0,0
0,0,0,0,0,0,0,0,0,0,0,0,0,0,0,0,0,0,0,0,0,0,0,0
endlayer

layer
0,0,0,0,0,0,0,0,0,0,0,0,0,0,0,0,0,0,0,0,0,0,0,0
0,0,0,0,0,0,0,0,0,0,0,0,0,0,0,0,0,0,0,0,0,0,0,0
0,0,0,0,0,0,0,0,0,0,0,0,0,0,0,0,0,0,0,0,0,0,0,0
0,0,0,0,0,0,0,0,0,0,0,0,0,0,0,0,0,0,0,0,0,0,0,0
0,0,0,0,0,0,46,46,46,0,0,46,46,46,0,0,0,0,0,0,0,0,0,0
0,0,0,0,0,46,46,46,46,46,46,46,46,46,46,0,0,0,0,0,0,0,0,0
0,0,0,0,46,46,46,46,46,46,46,46,46,46,46,46,0,0,0,0,0,0,0,0
0,0,0,0,46,46,46,59,46,46,46,46,47,46,46,46,0,0,0,0,0,0,0,0
0,0,0,0,46,46,46,46,46,60,60,60,60,60,60,46,0,0,0,0,0,0,0,0
0,0,0,0,0,46,46,46,60,0,0,0,0,0,64,60,0,0,0,0,0,0,0,0
0,0,0,0,0,0,46,46,60,0,0,0,0,0,0,60,0,0,0,0,0,0,0,0
0,0,0,0,0,74,0,55,60,0,0,59,53,0,0,60,0,0,0,0,0,0,0,0
0,0,0,0,0,0,0,0,53,0,0,53,30,53,0,53,0,0,0,0,0,0,0,0
0,0,0,0,0,75,0,55,60,0,0,0,53,0,0,60,0,0,0,0,0,0,0,0
0,0,0,0,0,0,0,0,60,0,0,0,0,0,0,60,0,0,0,0,0,0,0,0
0,0,0,0,0,0,46,46,60,0,0,0,0,0,0,60,46,46,0,0,0,0,0,0
0,0,0,0,0,46,46,46,59,72,72,60,60,72,72,76,59,46,46,46,0,0,0,0
0,0,0,0,0,46,46,46,46,46,0,55,55,0,0,46,46,46,46,0,0,0,0,0
0,0,0,0,0,46,46,46,46,46,0,0,0,0,0,46,46,46,46,46,0,0,0,0
0,0,0,0,0,0,46,46,46,0,0,0,0,0,0,0,46,46,0,0,0,0,0,0
0,0,0,0,0,0,0,0,0,0,0,0,0,0,0,0,0,0,0,0,0,0,0,0
0,0,0,0,0,0,0,0,0,0,0,0,0,0,0,0,0,0,0,0,0,0,0,0
0,0,0,0,0,0,0,0,0,0,0,0,0,0,0,0,0,0,0,0,0,0,0,0
0,0,0,0,0,0,0,0,0,0,0,0,0,0,0,0,0,0,0,0,0,0,0,0
0,0,0,0,0,0,0,0,0,0,0,0,0,0,0,0,0,0,0,0,0,0,0,0
endlayer

layer
0,0,0,0,0,0,0,0,0,0,0,0,0,0,0,0,0,0,0,0,0,0,0,0
0,0,0,0,0,0,0,0,0,0,0,0,0,0,0,0,0,0,0,0,0,0,0,0
0,0,0,0,0,0,0,0,0,0,0,0,0,0,0,0,0,0,0,0,0,0,0,0
0,0,0,0,0,0,0,0,0,0,0,0,0,0,0,0,0,0,0,0,0,0,0,0
0,0,0,0,0,0,0,0,0,0,0,0,0,0,0,0,0,0,0,0,0,0,0,0
0,0,0,0,0,0,46,46,46,0,0,46,46,46,0,0,0,0,0,0,0,0,0,0
0,0,0,0,0,46,59,46,46,46,46,46,47,46,46,0,0,0,0,0,0,0,0,0
0,0,0,0,0,46,46,46,46,46,51,51,51,46,46,0,0,0,0,0,0,0,0,0
0,0,0,0,0,46,46,46,46,60,60,51,60,60,60,53,0,0,0,0,0,0,0,0
0,0,0,0,0,0,46,46,60,57,57,57,57,57,0,60,0,0,0,0,0,0,0,0
0,0,0,0,0,0,55,55,60,57,59,57,57,57,0,60,55,55,55,0,0,0,0,0
0,0,0,0,0,77,55,51,51,57,57,57,57,57,0,60,51,51,55,0,0,0,0,0
0,0,0,0,0,0,55,51,51,57,57,57,30,57,57,60,51,51,55,0,0,0,0,0
0,0,0,0,0,78,55,51,51,57,57,57,57,57,57,51,51,51,55,0,0,0,0,0
0,0,0,0,0,0,46,46,60,57,57,57,57,57,57,60,46,46,46,0,0,0,0,0
0,0,0,0,0,46,46,46,60,57,57,57,57,57,57,60,46,46,46,46,0,0,0,0
0,0,0,0,46,46,46,46,76,60,60,60,60,60,60,46,46,46,46,46,46,0,0,0
0,0,0,0,46,46,46,59,46,46,46,51,51,0,46,46,46,59,46,46,46,0,0,0
0,0,0,0,46,46,46,46,46,46,46,79,79,0,46,46,46,46,46,46,46,0,0,0
0,0,0,0,0,46,46,46,46,46,0,0,0,0,0,46,46,46,46,46,0,0,0,0
0,0,0,0,0,0,46,46,46,0,0,0,0,0,0,0,46,46,46,0,0,0,0,0
0,0,0,0,0,0,0,0,0,0,0,0,0,0,0,0,0,0,0,0,0,0,0,0
0,0,0,0,0,0,0,0,0,0,0,0,0,0,0,0,0,0,0,0,0,0,0,0
0,0,0,0,0,0,0,0,0,0,0,0,0,0,0,0,0,0,0,0,0,0,0,0
0,0,0,0,0,0,0,0,0,0,0,0,0,0,0,0,0,0,0,0,0,0,0,0
endlayer

layer
0,0,0,0,0,0,0,0,0,0,0,0,0,0,0,0,0,0,0,0,0,0,0,0
0,0,0,0,0,0,0,0,0,0,0,0,0,0,0,0,0,0,0,0,0,0,0,0
0,0,0,46,46,46,0,0,0,0,0,46,46,46,0,0,0,0,0,0,0,0,0,0
0,0,46,46,46,46,46,0,0,0,46,46,46,46,46,0,0,0,0,0,0,0,0,0
0,0,46,46,46,46,46,0,0,0,46,46,46,46,46,0,0,0,0,0,0,0,0,0
0,0,46,46,46,59,46,0,0,0,46,46,47,46,46,0,0,0,0,0,0,0,0,0
0,0,0,46,46,46,0,0,0,0,0,0,0,0,0,0,0,0,0,0,0,0,0,0
0,0,0,0,0,0,0,0,0,0,0,0,0,0,0,0,0,0,0,0,0,0,0,0
0,0,0,0,0,73,0,0,0,60,60,0,60,60,60,53,0,0,0,0,0,0,0,0
0,0,0,0,0,0,0,0,60,59,81,81,81,81,0,60,80,0,0,0,0,0,0,0
0,0,0,0,0,0,18,18,60,81,81,81,81,81,0,60,18,18,18,0,0,0,0,0
0,0,0,0,0,52,18,0,53,81,81,81,81,81,0,60,0,66,18,0,0,0,0,0
0,0,0,0,0,0,18,0,0,81,81,81,30,81,81,60,0,0,18,0,0,0,0,0
0,0,0,0,0,52,18,0,53,81,81,81,81,81,81,0,0,0,18,0,0,0,0,0
0,0,0,0,0,0,18,18,60,81,81,81,81,81,81,60,18,18,18,0,0,0,0,0
0,0,0,0,0,0,46,46,60,81,81,81,81,81,53,60,46,46,46,0,0,0,0,0
0,0,0,0,0,46,46,46,76,60,60,0,60,60,60,46,46,46,46,46,0,0,0,0
0,0,0,0,0,46,46,46,46,46,0,0,82,0,0,46,46,46,46,46,0,0,0,0
0,0,0,0,0,46,59,46,46,46,0,83,83,0,0,46,46,46,59,46,0,0,0,0
0,0,0,0,0,0,46,46,46,0,0,0,0,0,0,0,46,46,46,0,0,0,0,0
0,0,0,0,0,0,0,0,0,0,0,0,0,0,0,0,0,0,0,0,0,0,0,0
0,0,0,0,0,0,0,0,0,0,0,0,0,0,0,0,0,0,0,0,0,0,0,0
0,0,0,0,0,0,0,0,0,0,0,0,0,0,0,0,0,0,0,0,0,0,0,0
0,0,0,0,0,0,0,0,0,0,0,0,0,0,0,0,0,0,0,0,0,0,0,0
0,0,0,0,0,0,0,0,0,0,0,0,0,0,0,0,0,0,0,0,0,0,0,0
endlayer

layer
0,0,0,0,0,0,0,0,0,0,0,0,0,0,0,0,0,0,0,0,0,0,0,0
0,0,0,46,46,46,0,0,0,0,0,46,46,46,0,0,0,0,0,0,0,0,0,0
0,0,46,46,46,46,46,0,0,0,46,46,46,46,46,0,0,0,0,0,0,0,0,0
0,46,46,46,46,46,46,46,0,46,46,46,46,46,46,46,0,0,0,0,0,0,0,0
0,46,46,46,59,46,46,46,0,46,46,46,47,46,46,46,0,0,0,0,0,0,0,0
0,46,46,46,46,46,46,46,46,46,46,46,46,46,46,46,0,0,0,0,0,0,0,0
0,0,46,46,46,46,46,46,0,55,55,55,55,55,46,0,0,0,0,0,0,0,0,0
0,0,0,46,46,46,46,0,0,55,0,0,0,55,0,0,0,0,0,0,0,0,0,0
0,0,0,0,0,46,46,46,59,60,60,0,60,60,60,53,0,0,0,0,0,0,0,0
0,0,0,0,0,0,46,46,60,85,0,0,0,0,0,60,84,0,0,0,0,0,0,0
0,0,0,0,0,0,0,0,60,0,0,0,0,0,0,60,0,0,0,0,0,0,0,0
0,0,0,0,0,0,0,0,53,0,0,59,0,0,0,60,0,0,0,0,0,0,0,0
0,0,0,0,0,0,0,0,0,0,0,0,30,59,0,60,0,0,0,0,0,0,0,0
0,0,0,0,0,0,0,0,53,0,0,0,0,0,0,0,0,0,0,0,0,0,0,0
0,0,0,0,0,0,0,0,60,0,0,0,0,0,0,60,0,0,0,0,0,0,0,0
0,0,0,0,0,0,0,0,60,0,0,0,0,0,53,60,0,0,0,0,0,0,0,0
0,0,0,0,0,0,0,0,53,60,60,0,60,60,60,53,0,0,0,0,0,0,0,0
0,0,0,0,0,0,0,0,0,0,55,0,82,55,0,0,0,0,0,0,0,0,0,0
0,0,0,46,46,46,0,0,0,0,55,55,55,55,0,0,0,0,0,46,46,46,0,0
0,0,46,46,46,59,46,0,0,0,0,0,0,0,0,0,0,0,46,59,46,46,0,0
0,0,46,46,46,46,46,0,0,0,0,0,0,0,0,0,0,0,46,46,46,0,0,0
0,0,46,46,46,46,46,0,0,0,0,0,0,0,0,0,0,0,46,46,46,46,0,0
0,0,0,46,46,46,0,0,0,0,0,0,0,0,0,0,0,0,0,46,46,46,0,0
0,0,0,0,0,0,0,0,0,0,0,0,0,0,0,0,0,0,0,0,0,0,0,0
0,0,0,0,0,0,0,0,0,0,0,0,0,0,0,0,0,0,0,0,0,0,0,0
endlayer

layer
0,0,0,0,0,0,0,0,0,0,0,0,0,0,0,0,0,0,0,0,0,0,0,0
0,0,0,0,0,0,0,0,0,0,0,0,0,0,0,0,0,0,0,0,0,0,0,0
0,0,0,46,46,46,0,0,0,0,0,46,46,46,0,0,0,0,0,0,0,0,0,0
0,0,46,46,46,46,46,0,0,0,46,46,46,46,46,0,0,0,0,0,0,0,0,0
0,0,46,46,46,46,46,46,46,0,46,46,46,46,46,0,0,0,0,0,0,0,0,0
0,0,46,46,46,46,46,46,46,46,46,46,46,46,46,0,0,0,0,0,0,0,0,0
0,0,0,46,46,46,46,46,46,0,0,0,0,0,0,0,0,0,0,0,0,0,0,0
0,0,0,0,46,46,46,59,46,0,0,0,0,0,0,0,0,0,0,0,0,0,0,0
0,0,0,0,46,46,46,46,46,54,54,54,54,54,54,53,0,0,0,0,0,0,0,0
0,0,0,0,0,46,46,46,56,87,87,87,87,87,87,56,86,0,0,0,0,0,0,0
0,0,0,0,0,0,46,46,56,87,59,87,87,87,87,56,0,0,0,0,0,0,0,0
0,0,0,0,0,0,0,88,56,87,87,87,87,87,87,56,0,0,0,0,0,0,0,0
0,0,0,0,0,0,0,88,56,87,87,87,30,59,59,56,0,0,0,0,0,0,0,0
0,0,0,0,0,0,0,88,56,87,87,87,87,87,87,56,89,0,0,0,0,0,0,0
0,0,0,0,0,0,0,0,56,87,87,87,87,87,87,56,0,0,0,0,0,0,0,0
0,0,0,0,0,0,0,0,56,87,87,87,87,87,87,56,0,0,0,0,0,0,0,0
0,0,0,0,0,0,0,0,53,54,54,54,54,54,54,53,0,0,0,0,0,0,0,0
0,0,0,46,46,46,0,0,0,0,0,0,82,0,0,0,0,0,0,46,46,46,0,0
0,0,46,46,46,46,46,0,0,0,0,0,0,0,0,0,0,0,46,46,46,46,46,0
0,46,46,46,46,46,46,46,0,0,0,0,0,0,0,0,0,46,46,46,46,46,46,0
0,46,46,46,59,46,46,46,0,0,0,0,0,0,0,0,0,46,46,46,59,46,46,46
0,46,46,46,46,46,46,46,0,0,0,0,0,0,0,0,0,46,46,46,46,46,46,46
0,0,46,46,46,46,46,0,0,0,0,0,0,0,0,0,0,0,46,46,46,46,46,0
0,0,0,46,46,46,0,0,0,0,0,0,0,0,0,0,0,0,0,46,46,46,0,0
0,0,0,0,0,0,0,0,0,0,0,0,0,0,0,0,0,0,0,0,0,0,0,0
endlayer

layer
0,0,0,0,0,0,0,0,0,0,0,0,0,0,0,0,0,0,0,0,0,0,0,0
0,0,0,0,0,0,0,0,0,0,0,0,0,0,0,0,0,0,0,0,0,0,0,0
0,0,0,0,0,0,0,0,0,0,0,0,0,0,0,0,0,0,0,0,0,0,0,0
0,0,0,0,0,0,0,0,0,0,0,0,0,0,0,0,0,0,0,0,0,0,0,0
0,0,0,0,0,0,0,0,0,0,0,0,0,0,0,0,0,0,0,0,0,0,0,0
0,0,0,0,0,0,46,46,46,0,0,0,0,0,0,0,0,0,0,0,0,0,0,0
0,0,0,0,0,46,59,46,46,46,0,0,0,0,0,0,0,0,0,0,0,0,0,0
0,0,0,0,0,46,46,46,46,46,0,0,0,0,0,0,0,0,0,0,0,0,0,0
0,0,0,0,0,46,46,46,46,46,0,0,0,0,0,0,0,0,0,0,0,0,0,0
0,0,0,0,0,0,46,46,46,59,0,90,90,90,0,0,0,0,0,0,0,0,0,0
0,0,0,0,0,0,0,0,0,0,76,0,0,0,76,0,0,0,0,0,0,0,0,0
0,0,0,0,0,0,0,0,0,76,0,0,91,0,0,46,0,0,0,0,0,0,0,0
0,0,0,0,0,0,0,0,0,76,0,0,30,0,59,59,0,0,0,0,0,0,0,0
0,0,0,0,0,0,0,0,0,76,0,0,0,0,0,46,0,0,0,0,0,0,0,0
0,0,0,0,0,0,0,0,0,0,76,0,0,0,90,0,0,0,0,0,0,0,0,0
0,0,0,0,0,0,0,0,0,0,0,76,0,76,0,0,0,0,0,0,0,0,0,0
0,0,0,0,0,0,0,0,0,0,0,0,0,0,0,0,0,0,0,0,0,0,0,0
0,0,0,0,0,0,0,0,0,0,0,0,0,0,0,0,0,0,0,0,0,0,0,0
0,0,0,46,46,46,0,0,0,0,0,0,0,0,0,0,0,0,0,46,46,46,0,0
0,0,46,46,46,46,46,0,0,0,0,0,0,0,0,0,0,0,46,46,46,46,46,0
0,0,46,46,46,46,46,0,0,0,0,0,0,0,0,0,0,0,46,46,46,46,46,0
0,0,46,46,46,46,46,0,0,0,0,0,0,0,0,0,0,0,46,46,46,46,46,0
0,0,0,46,46,46,0,0,0,0,0,0,0,0,0,0,0,0,0,46,46,46,0,0
0,0,0,0,0,0,0,0,0,0,0,0,0,0,0,0,0,0,0,0,0,0,0,0
0,0,0,0,0,0,0,0,0,0,0,0,0,0,0,0,0,0,0,0,0,0,0,0
endlayer

layer
0,0,0,0,0,0,0,0,0,0,0,0,0,0,0,0,0,0,0,0,0,0,0,0
0,0,0,0,0,0,0,0,0,0,0,0,0,0,0,0,0,0,0,0,0,0,0,0
0,0,0,46,46,46,0,0,0,0,0,0,0,0,0,0,0,0,0,0,0,0,0,0
0,0,46,46,46,46,46,0,0,0,0,0,0,0,0,0,0,0,0,0,0,0,0,0
0,0,46,46,46,46,46,0,0,0,0,0,0,0,0,0,0,0,0,0,0,0,0,0
0,0,46,46,46,59,46,46,46,0,0,0,0,0,0,0,0,0,0,0,0,0,0,0
0,0,0,46,46,46,46,46,46,46,0,0,0,0,0,0,0,0,0,0,0,0,0,0
0,0,0,0,0,46,46,46,46,46,0,0,0,0,0,0,0,0,0,0,0,0,0,0
0,0,0,0,0,46,46,46,59,46,0,0,0,0,0,0,0,0,0,0,0,0,0,0
0,0,0,0,0,0,46,46,46,46,0,90,46,90,0,0,0,0,0,0,0,0,0,0
0,0,0,0,0,0,0,0,0,0,76,0,0,0,76,0,46,46,46,0,0,0,0,0
0,0,0,0,0,0,0,0,0,76,0,0,0,0,0,46,46,46,46,46,0,0,0,0
0,0,0,0,0,0,0,0,0,76,0,0,30,0,0,59,59,46,46,46,0,0,0,0
0,0,0,0,0,0,0,0,0,76,0,0,0,0,0,46,46,46,46,46,0,0,0,0
0,0,0,0,0,0,0,0,0,0,76,0,0,0,76,0,46,46,46,0,0,0,0,0
0,0,0,0,0,0,0,0,0,0,0,90,0,76,0,0,0,0,0,0,0,0,0,0
0,0,0,0,0,0,0,0,0,0,0,0,0,0,0,0,0,0,0,0,0,0,0,0
0,0,0,0,0,0,0,0,0,0,0,0,0,0,0,0,0,0,0,0,0,0,0,0
0,0,0,0,0,0,0,0,0,0,0,0,0,0,0,0,0,0,0,0,0,0,0,0
0,0,0,0,0,0,0,0,0,0,0,0,0,0,0,0,0,0,0,0,0,0,0,0
0,0,0,0,0,0,0,0,0,0,0,0,0,0,0,0,0,0,0,0,0,0,0,0
0,0,0,0,0,0,0,0,0,0,0,0,0,0,0,0,0,0,0,0,0,0,0,0
0,0,0,0,0,0,0,0,0,0,0,0,0,0,0,0,0,0,0,0,0,0,0,0
0,0,0,0,0,0,0,0,0,0,0,0,0,0,0,0,0,0,0,0,0,0,0,0
0,0,0,0,0,0,0,0,0,0,0,0,0,0,0,0,0,0,0,0,0,0,0,0
endlayer

layer
0,0,0,0,0,0,0,0,0,0,0,0,0,0,0,0,0,0,0,0,0,0,0,0
0,0,0,46,46,46,0,0,0,0,0,0,0,0,0,0,0,0,0,0,0,0,0,0
0,0,46,46,46,46,46,0,0,0,0,0,0,0,0,0,0,0,0,0,0,0,0,0
0,46,46,46,46,46,46,46,0,0,0,0,0,0,0,0,0,0,0,0,0,0,0,0
0,46,46,46,59,46,46,46,46,0,0,0,0,0,0,0,0,0,0,0,0,0,0,0
0,46,46,46,46,46,46,46,46,46,0,0,0,0,0,0,0,0,0,0,0,0,0,0
0,0,46,46,46,46,46,46,46,46,46,0,0,0,0,0,0,0,0,0,0,0,0,0
0,0,0,46,46,46,46,59,46,46,46,0,0,0,0,0,0,0,0,0,0,0,0,0
0,0,0,0,46,46,46,46,46,46,46,0,0,0,0,0,0,0,0,0,0,0,0,0
0,0,0,0,0,46,46,46,46,46,0,46,46,46,0,46,46,46,46,0,0,0,0,0
0,0,0,0,0,0,46,46,46,0,46,46,46,46,46,46,46,46,46,46,0,0,0,0
0,0,0,0,0,0,0,0,0,46,46,46,46,46,46,46,46,46,46,46,46,0,0,0
0,0,0,0,0,0,0,0,0,46,46,46,30,46,46,46,59,59,46,46,46,0,0,0
0,0,0,0,0,0,0,0,0,46,46,46,46,46,46,46,46,46,46,46,46,0,0,0
0,0,0,0,0,0,0,0,0,0,46,46,46,46,46,46,46,46,46,46,0,0,0,0
0,0,0,0,0,0,0,0,0,0,0,46,46,46,0,46,46,46,46,0,0,0,0,0
0,0,0,0,0,0,0,0,0,0,0,0,0,0,0,0,0,0,0,0,0,0,0,0
0,0,0,0,0,0,0,0,0,0,0,0,0,0,0,0,0,0,0,0,0,0,0,0
0,0,0,0,0,0,0,0,0,0,0,0,0,0,0,0,0,0,0,0,0,0,0,0
0,0,0,0,0,0,0,0,0,0,0,0,0,0,0,0,0,0,0,0,0,0,0,0
0,0,0,0,0,0,0,0,0,0,0,0,0,0,0,0,0,0,0,0,0,0,0,0
0,0,0,0,0,0,0,0,0,0,0,0,0,0,0,0,0,0,0,0,0,0,0,0
0,0,0,0,0,0,0,0,0,0,0,0,0,0,0,0,0,0,0,0,0,0,0,0
0,0,0,0,0,0,0,0,0,0,0,0,0,0,0,0,0,0,0,0,0,0,0,0
0,0,0,0,0,0,0,0,0,0,0,0,0,0,0,0,0,0,0,0,0,0,0,0
endlayer

layer
0,0,0,0,0,0,0,0,0,0,0,0,0,0,0,0,0,0,0,0,0,0,0,0
0,0,0,0,0,0,0,0,0,0,0,0,0,0,0,0,0,0,0,0,0,0,0,0
0,0,0,46,46,46,0,0,0,0,0,0,0,0,0,0,0,0,0,0,0,0,0,0
0,0,46,46,46,46,46,0,0,0,0,0,0,0,0,0,0,0,0,0,0,0,0,0
0,0,46,46,46,46,46,0,0,0,0,0,0,0,0,0,0,0,0,0,0,0,0,0
0,0,46,46,46,46,46,46,46,0,0,0,0,0,0,0,0,0,0,0,0,0,0,0
0,0,0,46,46,46,59,46,46,46,0,0,0,0,0,0,0,0,0,0,0,0,0,0
0,0,0,0,0,46,46,46,46,46,0,0,0,0,0,0,0,0,0,0,0,0,0,0
0,0,0,0,0,46,46,46,46,46,0,0,0,0,0,0,0,0,0,0,0,0,0,0
0,0,0,0,0,0,46,46,46,0,0,0,0,0,0,0,46,46,46,0,0,0,0,0
0,0,0,0,0,0,0,0,0,0,0,0,0,0,0,46,46,46,46,46,0,0,0,0
0,0,0,0,0,0,0,0,0,0,0,0,0,0,46,46,46,46,46,46,46,0,0,0
0,0,0,0,0,0,0,0,0,0,0,0,30,0,46,46,46,59,59,46,46,0,0,0
0,0,0,0,0,0,0,0,0,0,0,0,0,0,46,46,46,46,46,46,46,0,0,0
0,0,0,0,0,0,0,0,0,0,0,0,0,0,0,46,46,46,46,46,0,0,0,0
0,0,0,0,0,0,0,0,0,0,0,0,0,0,0,0,46,46,46,0,0,0,0,0
0,0,0,0,0,0,0,0,0,0,0,0,0,0,0,0,0,0,0,0,0,0,0,0
0,0,0,0,0,0,0,0,0,0,0,0,0,0,0,0,0,0,0,0,0,0,0,0
0,0,0,0,0,0,0,0,0,0,0,0,0,0,0,0,0,0,0,0,0,0,0,0
0,0,0,0,0,0,0,0,0,0,0,0,0,0,0,0,0,0,0,0,0,0,0,0
0,0,0,0,0,0,0,0,0,0,0,0,0,0,0,0,0,0,0,0,0,0,0,0
0,0,0,0,0,0,0,0,0,0,0,0,0,0,0,0,0,0,0,0,0,0,0,0
0,0,0,0,0,0,0,0,0,0,0,0,0,0,0,0,0,0,0,0,0,0,0,0
0,0,0,0,0,0,0,0,0,0,0,0,0,0,0,0,0,0,0,0,0,0,0,0
0,0,0,0,0,0,0,0,0,0,0,0,0,0,0,0,0,0,0,0,0,0,0,0
endlayer

layer
0,0,0,0,0,0,0,0,0,0,0,0,0,0,0,0,0,0,0,0,0,0,0,0
0,0,0,0,73,0,0,0,0,0,0,0,0,0,0,0,0,0,0,0,0,0,0,0
0,0,0,46,46,46,0,0,0,0,0,0,0,0,0,0,0,0,0,0,0,0,0,0
0,0,46,46,46,46,46,0,0,0,0,0,0,0,0,0,0,0,0,0,0,0,0,0
0,0,46,46,46,46,46,0,0,0,0,0,0,0,0,0,0,0,0,0,0,0,0,0
0,0,46,46,46,59,46,0,0,0,0,0,0,0,0,0,0,0,0,0,0,0,0,0
0,0,0,46,46,46,0,0,0,0,0,0,0,0,0,0,0,0,0,0,0,0,0,0
0,0,0,0,0,0,0,0,0,0,0,0,0,0,0,0,0,0,0,0,0,0,0,0
0,0,0,0,0,0,0,0,0,0,0,0,0,0,0,0,0,0,0,0,0,0,0,0
0,0,0,0,0,0,0,0,0,0,0,0,0,0,0,0,0,0,0,0,0,0,0,0
0,0,0,0,0,0,0,0,0,0,0,0,0,0,0,0,46,46,46,46,46,46,0,0
0,0,0,0,0,0,0,0,0,0,0,0,0,0,0,46,46,46,46,46,46,46,46,73
0,0,0,0,0,0,0,0,0,0,0,0,30,0,0,46,46,46,59,59,46,46,46,0
0,0,0,0,0,0,0,0,0,0,0,0,0,0,0,46,46,46,46,46,46,46,46,0
0,0,0,0,0,0,0,0,0,0,0,0,0,0,0,0,46,46,46,46,46,46,0,0
0,0,0,0,0,0,0,0,0,0,0,0,0,0,0,0,0,0,0,0,0,0,0,0
0,0,0,0,0,0,0,0,0,0,0,0,0,0,0,0,0,0,0,0,0,0,0,0
0,0,0,0,0,0,0,0,0,0,0,0,0,0,0,0,0,0,0,0,0,0,0,0
0,0,0,0,0,0,0,0,0,0,0,0,0,0,0,0,0,0,0,0,0,0,0,0
0,0,0,0,0,0,0,0,0,0,0,0,0,0,0,0,0,0,0,0,0,0,0,0
0,0,0,0,0,0,0,0,0,0,0,0,0,0,0,0,0,0,0,0,0,0,0,0
0,0,0,0,0,0,0,0,0,0,0,0,0,0,0,0,0,0,0,0,0,0,0,0
0,0,0,0,0,0,0,0,0,0,0,0,0,0,0,0,0,0,0,0,0,0,0,0
0,0,0,0,0,0,0,0,0,0,0,0,0,0,0,0,0,0,0,0,0,0,0,0
0,0,0,0,0,0,0,0,0,0,0,0,0,0,0,0,0,0,0,0,0,0,0,0
endlayer

layer
0,0,0,0,0,0,0,0,0,0,0,0,0,0,0,0,0,0,0,0,0,0,0,0
0,0,0,46,46,46,0,0,0,0,0,0,0,0,0,0,0,0,0,0,0,0,0,0
0,0,46,46,46,46,46,0,0,0,0,0,0,0,0,0,0,0,0,0,0,0,0,0
0,46,46,46,46,46,46,46,0,0,0,0,0,0,0,0,0,0,0,0,0,0,0,0
0,46,46,46,59,46,46,46,0,0,0,0,0,0,0,0,0,0,0,0,0,0,0,0
0,46,46,46,46,46,46,46,0,0,0,0,0,0,0,0,0,0,0,0,0,0,0,0
0,0,46,46,46,46,46,0,0,0,0,0,0,0,0,0,0,0,0,0,0,0,0,0
0,0,0,46,46,46,0,0,0,0,0,0,0,0,0,0,0,0,0,0,0,0,0,0
0,0,0,0,0,0,0,0,0,0,0,0,0,0,0,0,0,0,0,0,0,0,0,0
0,0,0,0,0,0,0,0,0,0,0,0,0,0,0,0,0,0,0,46,46,46,0,0
0,0,0,0,0,0,0,0,0,0,0,0,0,0,0,0,0,0,46,46,46,46,46,0
0,0,0,0,0,0,0,0,0,0,0,0,0,0,0,0,0,46,46,46,46,46,46,46
0,0,0,0,0,0,0,0,0,0,0,0,30,0,0,0,0,46,46,59,59,46,46,46
0,0,0,0,0,0,0,0,0,0,0,0,0,0,0,0,0,46,46,46,46,46,46,46
0,0,0,0,0,0,0,0,0,0,0,0,0,0,0,0,0,0,46,46,46,46,46,0
0,0,0,0,0,0,0,0,0,0,0,0,0,0,0,0,0,0,0,46,46,46,0,0
0,0,0,0,0,0,0,0,0,0,0,0,0,0,0,0,0,0,0,0,0,0,0,0
0,0,0,0,0,0,0,0,0,0,0,0,0,0,0,0,0,0,0,0,0,0,0,0
0,0,0,0,0,0,0,0,0,0,0,0,0,0,0,0,0,0,0,0,0,0,0,0
0,0,0,0,0,0,0,0,0,0,0,0,0,0,0,0,0,0,0,0,0,0,0,0
0,0,0,0,0,0,0,0,0,0,0,0,0,0,0,0,0,0,0,0,0,0,0,0
0,0,0,0,0,0,0,0,0,0,0,0,0,0,0,0,0,0,0,0,0,0,0,0
0,0,0,0,0,0,0,0,0,0,0,0,0,0,0,0,0,0,0,0,0,0,0,0
0,0,0,0,0,0,0,0,0,0,0,0,0,0,0,0,0,0,0,0,0,0,0,0
0,0,0,0,0,0,0,0,0,0,0,0,0,0,0,0,0,0,0,0,0,0,0,0
endlayer

layer
0,0,0,0,0,0,0,0,0,0,0,0,0,0,0,0,0,0,0,0,0,0,0,0
0,0,0,0,0,0,0,0,0,0,0,0,0,0,0,0,0,0,0,0,0,0,0,0
0,0,0,46,46,46,0,0,0,0,0,0,0,0,0,0,0,0,0,0,0,0,0,0
0,0,46,46,46,46,46,0,0,0,0,0,0,0,0,0,0,0,0,0,0,0,0,0
0,0,46,46,46,46,46,0,0,0,0,0,0,0,0,0,0,0,0,0,0,0,0,0
0,0,46,46,46,46,46,0,0,0,0,0,0,0,0,0,0,0,0,0,0,0,0,0
0,0,0,46,46,46,0,0,0,0,0,0,0,0,0,0,0,0,0,0,0,0,0,0
0,0,0,0,0,0,0,0,0,0,0,0,0,0,0,0,0,0,0,0,0,0,0,0
0,0,0,0,0,0,0,0,0,0,0,0,0,0,0,0,0,0,0,0,0,0,0,0
0,0,0,0,0,0,0,0,0,0,0,46,46,46,0,0,0,0,0,46,46,46,0,0
0,0,0,0,0,0,0,0,0,0,46,46,46,46,46,0,0,0,46,46,46,46,46,0
0,0,0,0,0,0,0,0,0,46,46,46,46,46,46,46,0,46,46,46,46,46,46,46
0,0,0,0,0,0,0,0,0,46,46,46,30,46,46,46,0,46,46,46,59,46,46,46
0,0,0,0,0,0,0,0,0,46,46,46,46,46,46,46,0,46,46,46,46,46,46,46
0,0,0,0,0,0,0,0,0,0,46,46,46,46,46,0,0,0,46,46,46,46,46,0
0,0,0,0,0,0,0,0,0,46,0,46,46,46,0,0,0,0,0,46,46,46,0,0
0,0,0,0,0,0,0,0,0,0,0,0,0,0,0,0,0,0,0,0,0,0,0,0
0,0,0,0,0,0,0,0,0,0,0,0,0,0,0,0,0,0,0,0,0,0,0,0
0,0,0,0,0,0,0,0,0,0,0,0,0,0,0,0,0,0,0,0,0,0,0,0
0,0,0,0,0,0,0,0,0,0,0,0,0,0,0,0,0,0,0,0,0,0,0,0
0,0,0,0,0,0,0,0,0,0,0,0,0,0,0,0,0,0,0,0,0,0,0,0
0,0,0,0,0,0,0,0,0,0,0,0,0,0,0,0,0,0,0,0,0,0,0,0
0,0,0,0,0,0,0,0,0,0,0,0,0,0,0,0,0,0,0,0,0,0,0,0
0,0,0,0,0,0,0,0,0,0,0,0,0,0,0,0,0,0,0,0,0,0,0,0
0,0,0,0,0,0,0,0,0,0,0,0,0,0,0,0,0,0,0,0,0,0,0,0
endlayer

layer
0,0,0,0,0,0,0,0,0,0,0,0,0,0,0,0,0,0,0,0,0,0,0,0
0,0,0,0,0,0,0,0,0,0,0,0,0,0,0,0,0,0,0,0,0,0,0,0
0,0,0,0,0,0,0,0,0,0,0,0,0,0,0,0,0,0,0,0,0,0,0,0
0,0,0,0,0,0,0,0,0,0,0,0,0,0,0,0,0,0,0,0,0,0,0,0
0,0,0,0,0,0,0,0,0,0,0,0,0,0,0,0,0,0,0,0,0,0,0,0
0,0,0,0,0,0,0,0,0,0,0,0,0,0,0,0,0,0,0,0,0,0,0,0
0,0,0,0,0,0,0,0,0,0,0,0,0,0,0,0,0,0,0,0,0,0,0,0
0,0,0,0,0,0,0,0,0,0,0,0,0,0,0,0,0,0,0,0,0,0,0,0
0,0,0,0,0,0,0,0,0,0,0,0,0,0,0,0,0,0,0,0,0,0,0,0
0,0,0,0,0,0,0,0,0,0,0,0,0,0,0,0,0,0,0,0,0,0,0,0
0,0,0,0,0,0,0,0,0,0,0,46,46,46,0,0,0,0,0,46,46,46,0,0
0,0,0,0,0,0,0,0,0,0,46,46,46,46,46,0,0,0,46,46,46,46,46,0
0,0,0,0,0,0,0,0,0,0,46,46,46,46,46,0,0,0,46,46,46,46,46,0
0,0,0,0,0,0,0,0,0,0,46,46,46,46,46,0,0,0,46,46,46,46,46,0
0,0,0,0,0,0,0,0,0,0,0,46,46,46,0,0,0,0,0,46,46,46,0,0
0,0,0,0,0,0,0,0,0,0,0,0,0,0,0,0,0,0,0,0,0,0,0,0
0,0,0,0,0,0,0,0,0,0,0,0,0,0,0,0,0,0,0,0,0,0,0,0
0,0,0,0,0,0,0,0,0,0,0,0,0,0,0,0,0,0,0,0,0,0,0,0
0,0,0,0,0,0,0,0,0,0,0,0,0,0,0,0,0,0,0,0,0,0,0,0
0,0,0,0,0,0,0,0,0,0,0,0,0,0,0,0,0,0,0,0,0,0,0,0
0,0,0,0,0,0,0,0,0,0,0,0,0,0,0,0,0,0,0,0,0,0,0,0
0,0,0,0,0,0,0,0,0,0,0,0,0,0,0,0,0,0,0,0,0,0,0,0
0,0,0,0,0,0,0,0,0,0,0,0,0,0,0,0,0,0,0,0,0,0,0,0
0,0,0,0,0,0,0,0,0,0,0,0,0,0,0,0,0,0,0,0,0,0,0,0
0,0,0,0,0,0,0,0,0,0,0,0,0,0,0,0,0,0,0,0,0,0,0,0
endlayer

