
# Created by Ruins mod version 15.0 Ingame Parser
# authoring Player: SunsOfOld

weight=100
embed_into_distance=2
acceptable_target_blocks=
unacceptable_target_blocks=flowing_water,water,flowing_lava,lava
dimensions=11,12,14
allowable_overhang=0
max_leveling=4
leveling_buffer=0
preserve_water=0
preserve_lava=0
uniqueMinDistance=1000000
preventRotation=1

rule1=0,100,preserveBlock
rule2=0,100,minecraft:dirt-0
rule3=0,100,minecraft:gravel-0
rule4=0,100,minecraft:grass-0
rule5=0,100,BiomesOPlenty:planks-2
rule6=0,100,minecraft:dirt-2
rule7=0,100,BiomesOPlenty:ivy-8
rule8=0,100,IInventory;GardenContainers:stone_window_box;plantmegapack:grassMeadowFoxtail#1#0#2+plantmegapack:grassMeadowFoxtail#1#0#4-2
rule9=0,100,chisel:mossy_cobblestone-12
rule10=0,100,chisel:mossy_cobblestone-13
rule11=0,100,chisel:cobblestone-12
rule12=0,100,ExtrabiomesXL:door_fir-6
rule13=0,100,BiomesOPlenty:darkStairs-4
rule14=0,100,BiomesOPlenty:ivy-1
rule15=0,100,IInventory;minecraft:chest;minecraft:fishing_rod#1#0#0+minecraft:fishing_rod#1#0#1+minecraft:fishing_rod#1#0#2+harvestcraft:fishtrap#7#0#3+harvestcraft:fishtrapbaitItem#8#0#4+minecraft:fish#3#0#5+minecraft:boat#1#0#6+minecraft:boat#1#0#7+minecraft:boat#1#0#8+minecraft:boat#1#0#9+minecraft:boat#1#0#10+minecraft:stick#3#0#24+minecraft:string#2#0#25-5
rule16=0,100,BiblioCraft:BiblioWorkbench-4
rule17=0,100,BiomesOPlenty:darkStairs-6
rule18=0,100,BiomesOPlenty:woodenSingleSlab1-2
rule19=0,100,BiomesOPlenty:darkStairs-7
rule20=0,100,minecraft:furnace-4
rule21=0,100,BiomesOPlenty:ivy-4
rule22=0,100,BiomesOPlenty:darkStairs-5
rule23=0,100,BiomesOPlenty:ivy-2
rule24=0,100,dendrology:stairs12-4
rule25=0,100,GardenCore:garden_proxy-0
rule26=0,100,dendrology:stairs12-6
rule27=0,100,dendrology:salyx_planks-2
rule28=0,100,chisel:iron_bars-7
rule29=0,100,ExtrabiomesXL:door_fir-8
rule30=0,100,dendrology:stairs12-7
rule31=2,100,minecraft:torch-3
rule32=0,100,minecraft:ladder-3
rule33=0,100,UndergroundBiomes:wall-0
rule34=0,100,dendrology:stairs12-5
rule35=0,100,GardenTrees:thin_log-0
rule36=0,100,BiomesOPlenty:ivy-12
rule37=0,100,dendrology:stairs12-0
rule38=0,100,BiomesOPlenty:woodenSingleSlab1-10
rule39=0,100,dendrology:sslab1-12
rule40=0,100,BiomesOPlenty:darkStairs-2
rule41=0,100,BiomesOPlenty:darkStairs-3
rule42=0,100,VeganOption:bedStraw-10
rule43=0,100,VeganOption:bedStraw-2
rule44=0,100,ChestGenHook:dungeonChest:5-2
rule45=0,100,ExtrabiomesXL:door_fir-4
rule46=0,100,GardenTrees:thin_log_fence-0
rule47=0,100,ExtrabiomesXL:door_fir-9
rule48=1,100,minecraft:torch-5
rule49=2,100,minecraft:torch-4

layer
1,1,2,1,2,1,2,2,2,2,2,2,1,1
2,2,2,2,2,2,2,2,2,2,2,2,2,2
2,2,2,2,2,2,2,2,2,2,2,2,2,2
2,2,2,2,2,2,2,2,2,2,2,2,2,2
1,2,2,2,2,2,2,2,2,2,2,2,2,2
1,2,2,2,2,2,2,2,2,2,2,2,2,2
1,2,2,2,2,2,2,2,2,2,2,2,2,2
2,2,2,2,2,2,2,2,2,2,2,2,2,2
2,2,2,2,2,2,2,2,2,2,2,2,2,2
2,2,2,2,2,2,2,2,2,2,2,2,2,2
1,2,2,2,2,2,2,2,2,2,2,2,2,2
1,2,2,2,2,1,1,2,1,1,2,1,2,1
endlayer

layer
1,1,4,1,3,1,4,4,3,3,3,3,1,1
1,4,4,4,3,4,4,4,3,3,3,4,4,1
4,4,4,4,3,4,4,4,3,4,4,4,4,4
4,1,4,6,3,6,4,2,5,2,2,2,2,4
1,4,4,6,4,6,4,2,5,5,5,5,2,4
1,4,4,6,4,6,4,2,5,5,5,5,2,4
1,4,4,6,4,6,4,2,5,5,5,5,2,4
4,1,4,6,6,6,4,2,2,2,2,2,2,4
4,4,4,4,4,4,4,4,4,4,4,4,4,4
1,4,4,4,4,4,4,4,4,4,4,4,4,4
1,1,4,4,4,4,4,4,4,4,4,4,1,1
1,1,1,4,4,1,1,4,1,1,4,1,4,1
endlayer

layer
0,0,0,0,0,0,0,0,0,0,0,0,0,0
0,0,0,0,0,0,0,0,0,0,0,0,7,0
0,0,0,0,0,0,0,0,0,7,8,8,0,0
0,0,0,0,13,0,0,11,12,9,11,10,9,0
0,0,0,19,18,17,0,9,0,0,16,15,9,14
0,0,0,19,18,17,0,11,0,0,0,0,9,0
0,0,0,19,18,17,0,11,20,0,0,0,9,14
0,0,0,19,22,22,21,9,11,9,9,11,11,14
0,0,0,0,0,0,0,23,23,0,0,0,23,0
0,0,0,0,0,0,0,0,0,0,0,0,23,0
0,0,0,0,0,0,0,0,0,0,0,0,0,0
0,0,0,0,0,0,0,0,0,0,0,0,0,0
endlayer

layer
0,0,0,0,0,0,0,0,0,0,0,0,0,0
0,0,0,0,0,0,0,0,0,0,0,0,7,0
0,0,0,0,0,0,0,24,0,7,25,25,24,0
0,0,0,0,0,0,30,27,29,27,28,28,27,26
0,0,0,0,0,0,0,28,0,0,0,31,27,14
0,0,0,0,0,0,0,28,0,0,0,0,28,0
0,0,0,0,0,0,30,27,33,0,0,32,27,26
0,0,0,0,0,0,21,27,27,28,28,27,27,0
0,0,0,0,0,0,0,23,34,0,0,34,23,0
0,0,0,0,0,0,0,0,0,0,0,0,23,0
0,0,0,0,0,0,0,0,0,0,0,0,0,0
0,0,0,0,0,0,0,0,0,0,0,0,0,0
endlayer

layer
0,0,0,0,0,0,0,0,0,0,0,0,0,0
0,0,0,0,0,0,0,0,0,0,0,0,7,0
0,0,0,0,0,0,0,35,0,7,0,36,35,0
0,0,0,0,0,0,35,27,37,27,24,24,27,35
0,0,0,0,0,0,0,30,38,38,38,38,27,14
0,0,0,0,0,0,0,30,38,38,38,38,26,0
0,0,0,0,0,0,35,27,33,38,38,32,27,35
0,0,0,0,0,0,21,27,27,34,34,27,27,0
0,0,0,0,0,0,0,23,35,39,39,35,23,0
0,0,0,0,0,0,0,0,34,39,39,34,23,0
0,0,0,0,0,0,0,0,39,39,39,39,0,0
0,0,0,0,0,0,0,0,0,0,0,0,0,0
endlayer

layer
0,0,0,0,0,0,0,0,0,0,0,0,0,0
0,0,0,0,0,0,0,0,0,0,0,0,7,0
0,0,0,0,0,0,41,35,0,0,0,36,35,40
0,0,0,0,0,0,41,24,24,24,24,24,24,40
0,0,0,0,0,0,41,5,0,0,43,42,5,40
0,0,0,0,0,0,41,5,44,0,0,0,5,40
0,0,0,0,0,0,41,5,33,0,0,0,5,40
0,0,0,0,0,0,41,27,27,45,45,27,27,40
0,0,0,0,0,0,41,23,46,0,0,46,0,40
0,0,0,0,0,0,0,0,46,0,0,46,23,0
0,0,0,0,0,0,0,0,46,46,46,46,0,0
0,0,0,0,0,0,0,0,0,0,0,0,0,0
endlayer

layer
0,0,0,0,0,0,0,0,0,0,0,0,0,0
0,0,0,0,0,0,0,0,0,0,0,0,7,0
0,0,0,0,0,0,0,5,0,0,0,36,5,14
0,0,0,0,0,0,0,5,27,28,28,27,5,0
0,0,0,0,0,0,0,5,0,0,0,0,5,0
0,0,0,0,0,0,0,5,0,0,0,0,5,0
0,0,0,0,0,0,0,5,33,0,0,0,5,14
0,0,0,0,0,0,0,5,27,47,29,27,5,14
0,0,0,0,0,0,0,5,35,0,0,35,5,14
0,0,0,0,0,0,0,0,0,0,0,0,23,0
0,0,0,0,0,0,0,0,48,0,0,48,0,0
0,0,0,0,0,0,0,0,0,0,0,0,0,0
endlayer

layer
0,0,0,0,0,0,0,0,0,0,0,0,0,0
0,0,0,0,0,0,0,0,0,0,0,0,0,0
0,0,0,0,0,0,0,41,17,0,0,19,40,0
0,0,0,0,0,0,0,41,27,28,28,27,40,0
0,0,0,0,0,0,0,41,0,0,0,0,40,0
0,0,0,0,0,0,0,41,49,0,0,31,40,0
0,0,0,0,0,0,0,41,33,0,0,0,40,0
0,0,0,0,0,0,0,41,27,34,34,27,40,0
0,0,0,0,0,0,0,41,35,0,0,35,40,0
0,0,0,0,0,0,0,0,0,0,0,0,0,0
0,0,0,0,0,0,0,0,0,0,0,0,0,0
0,0,0,0,0,0,0,0,0,0,0,0,0,0
endlayer

layer
0,0,0,0,0,0,0,0,0,0,0,0,0,0
0,0,0,0,0,0,0,0,0,0,0,0,0,0
0,0,0,0,0,0,0,0,41,38,38,40,0,0
0,0,0,0,0,0,0,0,41,24,24,40,0,0
0,0,0,0,0,0,0,0,41,0,0,40,0,0
0,0,0,0,0,0,0,0,41,0,0,40,0,0
0,0,0,0,0,0,0,0,33,0,0,40,0,0
0,0,0,0,0,0,0,0,41,27,27,40,0,0
0,0,0,0,0,0,0,0,41,38,38,40,0,0
0,0,0,0,0,0,0,0,0,0,0,0,0,0
0,0,0,0,0,0,0,0,0,0,0,0,0,0
0,0,0,0,0,0,0,0,0,0,0,0,0,0
endlayer

layer
0,0,0,0,0,0,0,0,0,0,0,0,0,0
0,0,0,0,0,0,0,0,0,0,0,0,0,0
0,0,0,0,0,0,0,0,0,41,40,0,0,0
0,0,0,0,0,0,0,0,0,41,40,0,0,0
0,0,0,0,0,0,0,0,0,41,40,0,0,0
0,0,0,0,0,0,0,0,0,41,40,0,0,0
0,0,0,0,0,0,0,0,33,41,40,0,0,0
0,0,0,0,0,0,0,0,0,41,40,0,0,0
0,0,0,0,0,0,0,0,0,41,40,0,0,0
0,0,0,0,0,0,0,0,0,0,0,0,0,0
0,0,0,0,0,0,0,0,0,0,0,0,0,0
0,0,0,0,0,0,0,0,0,0,0,0,0,0
endlayer

layer
0,0,0,0,0,0,0,0,0,0,0,0,0,0
0,0,0,0,0,0,0,0,0,0,0,0,0,0
0,0,0,0,0,0,0,0,0,0,0,0,0,0
0,0,0,0,0,0,0,0,0,0,0,0,0,0
0,0,0,0,0,0,0,0,0,0,0,0,0,0
0,0,0,0,0,0,0,0,0,0,0,0,0,0
0,0,0,0,0,0,0,0,33,0,0,0,0,0
0,0,0,0,0,0,0,0,0,0,0,0,0,0
0,0,0,0,0,0,0,0,0,0,0,0,0,0
0,0,0,0,0,0,0,0,0,0,0,0,0,0
0,0,0,0,0,0,0,0,0,0,0,0,0,0
0,0,0,0,0,0,0,0,0,0,0,0,0,0
endlayer

