
# Created by Ruins mod version 15.1 Ingame Parser
# authoring Player: VikingWarlock

weight=100
embed_into_distance=1
acceptable_target_blocks=
unacceptable_target_blocks=flowing_water,water,flowing_lava,lava
dimensions=35,19,20
allowable_overhang=0
max_leveling=2
leveling_buffer=0
preserve_water=0
preserve_lava=0
uniqueMinDistance=1000000
preventRotation=1

rule1=0,100,minecraft:grass-0
rule2=0,100,minecraft:dirt-0
rule3=0,100,ExtrabiomesXL:log_elbow_rainbow_eucalyptus-5
rule4=0,100,ExtrabiomesXL:cornerlog_rainboweucalyptus-0
rule5=0,100,ExtrabiomesXL:cornerlog_rainboweucalyptus-3
rule6=0,100,ExtrabiomesXL:log_elbow_rainbow_eucalyptus-8
rule7=0,100,ExtrabiomesXL:cornerlog_rainboweucalyptus-1
rule8=0,100,ExtrabiomesXL:cornerlog_rainboweucalyptus-2
rule9=0,100,ExtrabiomesXL:log2-0
rule10=0,100,ExtrabiomesXL:log_elbow_rainbow_eucalyptus-4
rule11=0,100,ExtrabiomesXL:log_elbow_rainbow_eucalyptus-9
rule12=0,100,minecraft:ladder-5
rule13=0,100,BiomesOPlenty:magicStairs-4
rule14=0,100,BiomesOPlenty:magicStairs-6
rule15=0,100,minecraft:coal_block-0
rule16=0,100,minecraft:lapis_block-0
rule17=0,100,BiomesOPlenty:magicStairs-7
rule18=0,100,BiomesOPlenty:magicStairs-5
rule19=0,100,chisel:waterstone-1
rule20=0,100,ExtrabiomesXL:leaves_2-3
rule21=0,100,IInventory;minecraft:trapped_chest;harvestcraft:randomtacoItem#1#0#0+harvestcraft:randomtacoItem#1#0#1+harvestcraft:randomtacoItem#1#0#3+harvestcraft:randomtacoItem#2#0#5+harvestcraft:randomtacoItem#1#0#7+BiblioCraft:BiblioIronLantern#1#11#8+minecraft:golden_shovel#{RepairCost:2,display:{Name:\"Latrine Tool\",},}#0#10+BiblioCraft:BiblioIronLantern#1#11#11+BiblioCraft:BiblioIronLantern#2#11#13+BiblioCraft:BiblioIronLantern#1#11#15+antiqueatlas:emptyAntiqueAtlas#1#0#16+harvestcraft:randomtacoItem#1#0#17+BiblioCraft:BiblioIronLantern#1#11#18+harvestcraft:randomtacoItem#1#0#19+harvestcraft:randomtacoItem#1#0#22+minecraft:compass#{RepairCost:2,display:{Name:\"Explorer's Compass\",},}#0#23+harvestcraft:randomtacoItem#1#0#25+BiblioCraft:BiblioIronLantern#1#11#26-4
rule22=0,100,minecraft:stained_glass_pane-11
rule23=0,100,chisel:stained_glass_pane_purple-11
rule24=0,100,ExtrabiomesXL:leaves_2-7
rule25=0,100,IInventory;minecraft:trapped_chest;minecraft:lapis_block#{RepairCost:2,display:{Name:\"Merrik's Secret Supply\",},}#0#0+minecraft:lapis_block#{RepairCost:2,display:{Name:\"Merrik's Secret Supply\",},}#0#2+minecraft:lapis_block#{RepairCost:2,display:{Name:\"Merrik's Secret Supply\",},}#0#4+minecraft:lapis_block#{RepairCost:2,display:{Name:\"Merrik's Secret Supply\",},}#0#8+minecraft:lapis_block#{RepairCost:2,display:{Name:\"Merrik's Secret Supply\",},}#0#15+minecraft:lapis_block#{RepairCost:2,display:{Name:\"Merrik's Secret Supply\",},}#0#19+minecraft:lapis_block#{RepairCost:2,display:{Name:\"Merrik's Secret Supply\",},}#0#22+minecraft:lapis_block#{RepairCost:2,display:{Name:\"Merrik's Secret Supply\",},}#0#26-4
rule26=0,100,BiblioCraft:BiblioIronLantern-11
rule27=0,100,BiomesOPlenty:magicStairs-2
rule28=0,100,BiomesOPlenty:magicStairs-0
rule29=0,100,BiomesOPlenty:magicStairs-3
rule30=0,100,ExtrabiomesXL:leaves_2-15
rule31=0,100,BiomesOPlenty:magicStairs-1
rule32=0,100,BiomesOPlenty:woodenSingleSlab1-5
rule33=0,100,ExtrabiomesXL:leaves_2-11

layer
1,1,1,1,1,1,1,1,1,1,1,1,1,1,1,1,1,1,1,1
1,1,1,1,1,1,1,1,1,1,1,1,1,1,1,1,1,1,1,1
1,1,1,1,1,1,1,1,1,1,1,1,1,1,1,1,1,1,1,1
1,1,1,1,1,1,1,1,1,1,1,1,1,1,1,1,1,1,1,1
1,1,1,1,1,1,1,1,1,1,1,1,1,1,1,1,1,1,1,1
1,1,1,1,1,1,1,1,1,1,1,1,1,1,1,1,1,1,1,1
1,1,1,1,1,1,1,1,1,1,1,1,1,1,1,1,1,1,1,1
1,1,1,1,1,1,1,1,1,1,2,1,1,1,1,1,1,1,1,1
1,1,1,1,1,1,1,1,1,2,2,1,1,1,1,1,1,1,1,1
1,1,1,1,1,1,1,1,2,2,2,2,1,1,1,1,1,1,1,1
1,1,1,1,1,1,1,1,1,2,1,1,1,1,1,1,1,1,1,1
1,1,1,1,1,1,1,1,1,1,1,1,1,1,1,1,1,1,1,1
1,1,1,1,1,1,1,1,1,1,1,1,1,1,1,1,1,1,1,1
1,1,1,1,1,1,1,1,1,1,1,1,1,1,1,1,1,1,1,1
1,1,1,1,1,1,1,1,1,1,1,1,1,1,1,1,1,1,1,1
1,1,1,1,1,1,1,1,1,1,1,1,1,1,1,1,1,1,1,1
1,1,1,1,1,1,1,1,1,1,1,1,1,1,1,1,1,1,1,1
1,1,1,1,1,1,1,1,1,1,1,1,1,1,1,1,1,1,1,1
1,1,1,1,1,1,1,1,1,1,1,1,1,1,1,1,1,1,1,1
endlayer

layer
0,0,0,0,0,0,0,0,0,0,0,0,0,0,0,0,0,0,0,0
0,0,0,0,0,0,0,0,0,0,0,0,0,0,0,0,0,0,0,0
0,0,0,0,0,0,0,0,0,0,0,0,0,0,0,0,0,0,0,0
0,0,0,0,0,0,0,0,0,0,0,0,0,0,0,0,0,0,0,0
0,0,0,0,0,0,0,0,0,0,0,0,0,0,0,0,0,0,0,0
0,0,0,0,0,0,0,0,0,0,0,0,0,0,0,0,0,0,0,0
0,0,0,0,0,0,0,0,0,0,0,0,0,0,0,0,0,0,0,0
0,0,0,0,0,0,0,0,0,0,3,0,0,0,0,0,0,0,0,0
0,0,0,0,0,0,0,0,0,5,4,0,0,0,0,0,0,0,0,0
0,0,0,0,0,0,0,0,9,8,7,6,0,0,0,0,0,0,0,0
0,0,0,0,0,0,0,0,0,10,0,0,0,0,0,0,0,0,0,0
0,0,0,0,0,0,0,0,0,0,0,0,0,0,0,0,0,0,0,0
0,0,0,0,0,0,0,0,0,0,0,0,0,0,0,0,0,0,0,0
0,0,0,0,0,0,0,0,0,0,0,0,0,0,0,0,0,0,0,0
0,0,0,0,0,0,0,0,0,0,0,0,0,0,0,0,0,0,0,0
0,0,0,0,0,0,0,0,0,0,0,0,0,0,0,0,0,0,0,0
0,0,0,0,0,0,0,0,0,0,0,0,0,0,0,0,0,0,0,0
0,0,0,0,0,0,0,0,0,0,0,0,0,0,0,0,0,0,0,0
0,0,0,0,0,0,0,0,0,0,0,0,0,0,0,0,0,0,0,0
endlayer

layer
0,0,0,0,0,0,0,0,0,0,0,0,0,0,0,0,0,0,0,0
0,0,0,0,0,0,0,0,0,0,0,0,0,0,0,0,0,0,0,0
0,0,0,0,0,0,0,0,0,0,0,0,0,0,0,0,0,0,0,0
0,0,0,0,0,0,0,0,0,0,0,0,0,0,0,0,0,0,0,0
0,0,0,0,0,0,0,0,0,0,0,0,0,0,0,0,0,0,0,0
0,0,0,0,0,0,0,0,0,0,0,0,0,0,0,0,0,0,0,0
0,0,0,0,0,0,0,0,0,0,0,0,0,0,0,0,0,0,0,0
0,0,0,0,0,0,0,0,0,0,0,0,0,0,0,0,0,0,0,0
0,0,0,0,0,0,0,0,0,5,4,0,0,0,0,0,0,0,0,0
0,0,0,0,0,0,0,0,11,8,7,0,0,0,0,0,0,0,0,0
0,0,0,0,0,0,0,0,0,0,12,0,0,0,0,0,0,0,0,0
0,0,0,0,0,0,0,0,0,0,0,0,0,0,0,0,0,0,0,0
0,0,0,0,0,0,0,0,0,0,0,0,0,0,0,0,0,0,0,0
0,0,0,0,0,0,0,0,0,0,0,0,0,0,0,0,0,0,0,0
0,0,0,0,0,0,0,0,0,0,0,0,0,0,0,0,0,0,0,0
0,0,0,0,0,0,0,0,0,0,0,0,0,0,0,0,0,0,0,0
0,0,0,0,0,0,0,0,0,0,0,0,0,0,0,0,0,0,0,0
0,0,0,0,0,0,0,0,0,0,0,0,0,0,0,0,0,0,0,0
0,0,0,0,0,0,0,0,0,0,0,0,0,0,0,0,0,0,0,0
endlayer

layer
0,0,0,0,0,0,0,0,0,0,0,0,0,0,0,0,0,0,0,0
0,0,0,0,0,0,0,0,0,0,0,0,0,0,0,0,0,0,0,0
0,0,0,0,0,0,0,0,0,0,0,0,0,0,0,0,0,0,0,0
0,0,0,0,0,0,0,0,0,0,0,0,0,0,0,0,0,0,0,0
0,0,0,0,0,0,0,0,0,0,0,0,0,0,0,0,0,0,0,0
0,0,0,0,0,0,0,0,0,0,0,0,0,0,0,0,0,0,0,0
0,0,0,0,0,0,0,0,0,0,0,0,0,0,0,0,0,0,0,0
0,0,0,0,0,0,0,0,0,0,0,0,0,0,0,0,0,0,0,0
0,0,0,0,0,0,0,0,0,5,4,0,0,0,0,0,0,0,0,0
0,0,0,0,0,0,0,0,0,8,7,0,0,0,0,0,0,0,0,0
0,0,0,0,0,0,0,0,0,0,12,0,0,0,0,0,0,0,0,0
0,0,0,0,0,0,0,0,0,0,0,0,0,0,0,0,0,0,0,0
0,0,0,0,0,0,0,0,0,0,0,0,0,0,0,0,0,0,0,0
0,0,0,0,0,0,0,0,0,0,0,0,0,0,0,0,0,0,0,0
0,0,0,0,0,0,0,0,0,0,0,0,0,0,0,0,0,0,0,0
0,0,0,0,0,0,0,0,0,0,0,0,0,0,0,0,0,0,0,0
0,0,0,0,0,0,0,0,0,0,0,0,0,0,0,0,0,0,0,0
0,0,0,0,0,0,0,0,0,0,0,0,0,0,0,0,0,0,0,0
0,0,0,0,0,0,0,0,0,0,0,0,0,0,0,0,0,0,0,0
endlayer

layer
0,0,0,0,0,0,0,0,0,0,0,0,0,0,0,0,0,0,0,0
0,0,0,0,0,0,0,0,0,0,0,0,0,0,0,0,0,0,0,0
0,0,0,0,0,0,0,0,0,0,0,0,0,0,0,0,0,0,0,0
0,0,0,0,0,0,0,0,0,0,0,0,0,0,0,0,0,0,0,0
0,0,0,0,0,0,0,0,0,0,0,0,0,0,0,0,0,0,0,0
0,0,0,0,0,0,0,0,0,0,0,0,0,0,0,0,0,0,0,0
0,0,0,0,0,0,0,0,0,0,0,0,0,0,0,0,0,0,0,0
0,0,0,0,0,0,0,0,0,0,0,0,0,0,0,0,0,0,0,0
0,0,0,0,0,0,0,0,0,5,4,0,0,0,0,0,0,0,0,0
0,0,0,0,0,0,0,0,0,8,7,0,0,0,0,0,0,0,0,0
0,0,0,0,0,0,0,0,0,0,12,0,0,0,0,0,0,0,0,0
0,0,0,0,0,0,0,0,0,0,0,0,0,0,0,0,0,0,0,0
0,0,0,0,0,0,0,0,0,0,0,0,0,0,0,0,0,0,0,0
0,0,0,0,0,0,0,0,0,0,0,0,0,0,0,0,0,0,0,0
0,0,0,0,0,0,0,0,0,0,0,0,0,0,0,0,0,0,0,0
0,0,0,0,0,0,0,0,0,0,0,0,0,0,0,0,0,0,0,0
0,0,0,0,0,0,0,0,0,0,0,0,0,0,0,0,0,0,0,0
0,0,0,0,0,0,0,0,0,0,0,0,0,0,0,0,0,0,0,0
0,0,0,0,0,0,0,0,0,0,0,0,0,0,0,0,0,0,0,0
endlayer

layer
0,0,0,0,0,0,0,0,0,0,0,0,0,0,0,0,0,0,0,0
0,0,0,0,0,0,0,0,0,0,0,0,0,0,0,0,0,0,0,0
0,0,0,0,0,0,0,0,0,0,0,0,0,0,0,0,0,0,0,0
0,0,0,0,0,0,0,0,0,0,0,0,0,0,0,0,0,0,0,0
0,0,0,0,0,0,0,0,0,0,0,0,0,0,0,0,0,0,0,0
0,0,0,0,0,0,0,0,0,0,0,0,0,0,0,0,0,0,0,0
0,0,0,0,0,0,0,0,0,0,0,0,0,0,0,0,0,0,0,0
0,0,0,0,0,0,0,0,0,0,0,0,0,0,0,0,0,0,0,0
0,0,0,0,0,0,0,0,0,5,4,0,0,0,0,0,0,0,0,0
0,0,0,0,0,0,0,0,0,8,7,0,0,0,0,0,0,0,0,0
0,0,0,0,0,0,0,0,0,0,12,0,0,0,0,0,0,0,0,0
0,0,0,0,0,0,0,0,0,0,0,0,0,0,0,0,0,0,0,0
0,0,0,0,0,0,0,0,0,0,0,0,0,0,0,0,0,0,0,0
0,0,0,0,0,0,0,0,0,0,0,0,0,0,0,0,0,0,0,0
0,0,0,0,0,0,0,0,0,0,0,0,0,0,0,0,0,0,0,0
0,0,0,0,0,0,0,0,0,0,0,0,0,0,0,0,0,0,0,0
0,0,0,0,0,0,0,0,0,0,0,0,0,0,0,0,0,0,0,0
0,0,0,0,0,0,0,0,0,0,0,0,0,0,0,0,0,0,0,0
0,0,0,0,0,0,0,0,0,0,0,0,0,0,0,0,0,0,0,0
endlayer

layer
0,0,0,0,0,0,0,0,0,0,0,0,0,0,0,0,0,0,0,0
0,0,0,0,0,0,0,0,0,0,0,0,0,0,0,0,0,0,0,0
0,0,0,0,0,0,0,0,0,0,0,0,0,0,0,0,0,0,0,0
0,0,0,0,0,0,0,0,0,0,0,0,0,0,0,0,0,0,0,0
0,0,0,0,0,0,0,0,0,0,0,0,0,0,0,0,0,0,0,0
0,0,0,0,0,0,0,0,0,0,0,0,0,0,0,0,0,0,0,0
0,0,0,0,0,0,0,0,0,0,0,0,0,0,0,0,0,0,0,0
0,0,0,0,0,0,0,0,0,0,0,0,0,0,0,0,0,0,0,0
0,0,0,0,0,0,0,0,0,5,4,9,0,0,0,0,0,0,0,0
0,0,0,0,0,0,0,0,0,8,7,0,0,0,0,0,0,0,0,0
0,0,0,0,0,0,0,0,0,9,12,9,0,0,0,0,0,0,0,0
0,0,0,0,0,0,0,0,0,0,0,0,0,0,0,0,0,0,0,0
0,0,0,0,0,0,0,0,0,0,0,0,0,0,0,0,0,0,0,0
0,0,0,0,0,0,0,0,0,0,0,0,0,0,0,0,0,0,0,0
0,0,0,0,0,0,0,0,0,0,0,0,0,0,0,0,0,0,0,0
0,0,0,0,0,0,0,0,0,0,0,0,0,0,0,0,0,0,0,0
0,0,0,0,0,0,0,0,0,0,0,0,0,0,0,0,0,0,0,0
0,0,0,0,0,0,0,0,0,0,0,0,0,0,0,0,0,0,0,0
0,0,0,0,0,0,0,0,0,0,0,0,0,0,0,0,0,0,0,0
endlayer

layer
0,0,0,0,0,0,0,0,0,0,0,0,0,0,0,0,0,0,0,0
0,0,0,0,0,0,0,0,0,0,0,0,0,0,0,0,0,0,0,0
0,0,0,0,0,0,0,0,0,0,0,0,0,0,0,0,0,0,0,0
0,0,0,0,0,0,0,0,0,0,0,0,0,0,0,0,0,0,0,0
0,0,0,0,0,0,0,0,0,0,0,0,0,0,0,0,0,0,0,0
0,0,0,0,0,0,0,0,0,0,0,0,0,0,0,0,0,0,0,0
0,0,0,0,0,0,0,0,0,0,0,0,0,0,0,0,0,0,0,0
0,0,0,0,0,0,0,0,0,9,0,0,0,0,0,0,0,0,0,0
0,0,0,0,0,0,0,0,9,5,4,9,0,0,0,0,0,0,0,0
0,0,0,0,0,0,0,0,0,8,7,0,0,0,0,0,0,0,0,0
0,0,0,0,0,0,0,0,0,9,12,0,9,0,0,0,0,0,0,0
0,0,0,0,0,0,0,0,0,0,0,0,0,0,0,0,0,0,0,0
0,0,0,0,0,0,0,0,0,0,0,0,0,0,0,0,0,0,0,0
0,0,0,0,0,0,0,0,0,0,0,0,0,0,0,0,0,0,0,0
0,0,0,0,0,0,0,0,0,0,0,0,0,0,0,0,0,0,0,0
0,0,0,0,0,0,0,0,0,0,0,0,0,0,0,0,0,0,0,0
0,0,0,0,0,0,0,0,0,0,0,0,0,0,0,0,0,0,0,0
0,0,0,0,0,0,0,0,0,0,0,0,0,0,0,0,0,0,0,0
0,0,0,0,0,0,0,0,0,0,0,0,0,0,0,0,0,0,0,0
endlayer

layer
0,0,0,0,0,0,0,0,0,0,0,0,0,0,0,0,0,0,0,0
0,0,0,0,0,0,0,0,0,0,0,0,0,0,0,0,0,0,0,0
0,0,0,0,0,0,0,0,0,0,0,0,0,0,0,0,0,0,0,0
0,0,0,0,0,0,0,0,0,0,0,0,0,0,0,0,0,0,0,0
0,0,0,0,0,0,0,0,0,0,0,0,0,0,0,0,0,0,0,0
0,0,0,0,0,0,0,0,0,0,0,0,0,0,0,0,0,0,0,0
0,0,0,0,0,0,0,0,0,9,0,0,0,0,0,0,0,0,0,0
0,0,0,0,0,0,0,0,0,0,0,0,9,0,0,0,0,0,0,0
0,0,0,0,0,0,0,0,9,5,4,9,0,0,0,0,0,0,0,0
0,0,0,0,0,0,0,0,0,8,7,0,0,0,0,0,0,0,0,0
0,0,0,0,0,0,0,0,0,9,12,0,9,0,0,0,0,0,0,0
0,0,0,0,0,0,0,0,0,0,0,0,0,0,0,0,0,0,0,0
0,0,0,0,0,0,0,0,0,0,0,0,0,0,0,0,0,0,0,0
0,0,0,0,0,0,0,0,0,0,0,0,0,0,0,0,0,0,0,0
0,0,0,0,0,0,0,0,0,0,0,0,0,0,0,0,0,0,0,0
0,0,0,0,0,0,0,0,0,0,0,0,0,0,0,0,0,0,0,0
0,0,0,0,0,0,0,0,0,0,0,0,0,0,0,0,0,0,0,0
0,0,0,0,0,0,0,0,0,0,0,0,0,0,0,0,0,0,0,0
0,0,0,0,0,0,0,0,0,0,0,0,0,0,0,0,0,0,0,0
endlayer

layer
0,0,0,0,0,0,0,0,0,0,0,0,0,0,0,0,0,0,0,0
0,0,0,0,0,0,0,0,0,0,0,0,0,0,0,0,0,0,0,0
0,0,0,0,0,0,0,0,0,0,0,0,0,0,0,0,0,0,0,0
0,0,0,0,0,0,0,0,0,0,0,0,0,0,0,0,0,0,0,0
0,0,0,0,0,13,13,13,13,13,13,13,13,13,13,13,0,0,0,0
0,0,0,0,0,17,15,16,15,16,15,16,15,16,15,14,0,0,0,0
0,0,0,0,0,17,16,15,16,9,16,15,16,15,16,14,0,0,0,0
0,0,0,0,0,17,15,9,9,9,15,16,9,16,15,14,0,0,0,0
0,0,0,0,0,17,16,15,9,5,4,9,16,15,16,14,0,0,0,0
0,0,0,0,0,17,15,16,15,8,7,16,15,16,15,14,0,0,0,0
0,0,0,0,0,17,16,15,16,9,12,15,16,9,16,14,0,0,0,0
0,0,0,0,0,17,15,16,15,9,15,16,15,16,15,14,0,0,0,0
0,0,0,0,0,18,18,18,18,18,18,18,18,18,18,18,0,0,0,0
0,0,0,0,0,0,0,0,0,0,0,0,0,0,0,0,0,0,0,0
0,0,0,0,0,0,0,0,0,0,0,0,0,0,0,0,0,0,0,0
0,0,0,0,0,0,0,0,0,0,0,0,0,0,0,0,0,0,0,0
0,0,0,0,0,0,0,0,0,0,0,0,0,0,0,0,0,0,0,0
0,0,0,0,0,0,0,0,0,0,0,0,0,0,0,0,0,0,0,0
0,0,0,0,0,0,0,0,0,0,0,0,0,0,0,0,0,0,0,0
endlayer

layer
0,0,0,0,0,0,0,0,0,0,0,0,0,0,0,0,0,0,0,0
0,0,0,0,0,0,0,0,0,0,0,0,0,0,0,0,0,0,0,0
0,0,0,0,0,0,0,0,0,0,0,0,0,0,0,0,0,0,0,0
0,0,0,0,0,0,0,0,0,0,0,0,0,0,0,0,0,0,0,0
0,0,0,0,0,9,19,19,19,19,19,19,19,19,19,9,0,0,0,0
0,0,0,0,0,19,0,0,0,9,0,0,0,0,0,19,0,0,0,0
0,0,0,0,0,19,0,0,0,0,0,0,0,0,0,19,0,0,0,0
0,0,0,0,0,19,0,9,9,9,20,0,9,0,0,19,0,0,0,0
0,0,0,0,0,19,0,0,9,5,4,20,9,0,0,19,0,0,0,0
0,0,0,0,0,19,0,0,0,8,7,0,0,0,0,19,0,0,0,0
0,0,0,0,0,19,0,0,0,0,0,0,0,0,9,19,0,0,0,0
0,0,0,0,0,19,21,0,9,9,0,0,0,0,0,19,0,0,0,0
0,0,0,0,0,9,19,19,19,19,19,19,19,19,19,9,0,0,0,0
0,0,0,0,0,0,0,0,0,0,0,0,0,0,0,0,0,0,0,0
0,0,0,0,0,0,0,0,0,0,0,0,0,0,0,0,0,0,0,0
0,0,0,0,0,0,0,0,0,0,0,0,0,0,0,0,0,0,0,0
0,0,0,0,0,0,0,0,0,0,0,0,0,0,0,0,0,0,0,0
0,0,0,0,0,0,0,0,0,0,0,0,0,0,0,0,0,0,0,0
0,0,0,0,0,0,0,0,0,0,0,0,0,0,0,0,0,0,0,0
endlayer

layer
0,0,0,0,0,0,0,0,0,0,0,0,0,0,0,0,0,0,0,0
0,0,0,0,0,0,0,0,0,0,0,0,0,0,0,0,0,0,0,0
0,0,0,0,0,0,0,0,0,0,0,0,0,0,0,0,0,0,0,0
0,0,0,0,0,0,0,0,0,0,0,0,0,0,0,0,0,0,0,0
0,0,0,0,0,9,19,22,22,9,22,22,22,22,19,9,0,0,0,0
0,0,0,0,0,19,0,0,0,0,0,0,0,0,0,19,0,0,0,0
0,0,0,0,0,23,0,0,0,0,0,0,0,9,0,23,0,0,0,0
0,0,0,0,0,23,9,0,9,20,24,20,20,0,0,23,0,0,0,0
0,0,0,0,0,23,0,0,9,5,25,20,9,0,0,23,0,0,0,0
0,0,0,0,0,23,0,0,20,8,7,20,20,0,0,23,0,0,0,0
0,0,0,0,0,23,0,0,0,20,0,0,0,0,9,23,0,0,0,0
0,0,0,0,0,19,0,0,9,9,0,0,0,0,0,19,0,0,0,0
0,0,0,0,0,9,19,23,23,23,23,23,23,23,19,9,0,0,0,0
0,0,0,0,0,0,0,0,0,0,0,0,0,0,0,0,0,0,0,0
0,0,0,0,0,0,0,0,0,0,0,0,0,0,0,0,0,0,0,0
0,0,0,0,0,0,0,0,0,0,0,0,0,0,0,0,0,0,0,0
0,0,0,0,0,0,0,0,0,0,0,0,0,0,0,0,0,0,0,0
0,0,0,0,0,0,0,0,0,0,0,0,0,0,0,0,0,0,0,0
0,0,0,0,0,0,0,0,0,0,0,0,0,0,0,0,0,0,0,0
endlayer

layer
0,0,0,0,0,0,0,0,0,0,0,0,0,0,0,0,0,0,0,0
0,0,0,0,0,0,0,0,0,0,0,0,0,0,0,0,0,0,0,0
0,0,0,0,0,0,0,0,0,20,0,0,0,0,0,0,0,0,0,0
0,0,0,0,0,0,0,0,0,0,0,0,0,0,0,0,0,0,0,0
0,0,0,0,0,9,19,19,19,9,19,19,19,19,19,9,0,0,0,0
0,0,0,0,0,19,26,0,0,20,20,20,0,0,26,19,0,0,0,0
0,0,0,0,0,19,9,0,20,20,20,20,20,9,0,19,0,0,0,0
0,0,0,0,0,19,0,20,9,20,20,20,20,20,0,19,0,0,0,0
0,0,0,0,0,19,0,20,9,5,24,20,9,20,0,19,0,0,0,0
0,0,0,0,0,19,0,20,20,8,7,20,20,20,0,19,0,0,0,0
0,0,0,0,0,19,0,0,20,20,20,20,20,0,0,9,20,0,0,0
0,0,0,0,0,19,26,0,9,20,20,20,0,0,26,19,0,0,0,0
0,0,0,0,0,9,19,19,9,19,19,19,19,19,19,9,0,0,0,0
0,0,0,0,0,0,0,0,0,0,0,0,0,0,0,0,0,0,0,0
0,0,0,0,0,0,0,0,0,0,0,0,0,0,0,0,0,0,0,0
0,0,0,0,0,0,0,0,0,0,0,0,0,0,0,0,0,0,0,0
0,0,0,0,0,0,0,0,0,0,0,0,0,0,0,0,0,0,0,0
0,0,0,0,0,0,0,0,0,0,0,0,0,0,0,0,0,0,0,0
0,0,0,0,0,0,0,0,0,0,0,0,0,0,0,0,0,0,0,0
endlayer

layer
0,0,0,0,0,0,0,0,0,0,0,0,0,0,0,0,0,0,0,0
0,0,0,0,0,0,0,0,20,20,20,0,0,0,0,0,0,0,0,0
0,0,0,0,0,0,0,0,20,20,20,0,0,0,0,0,0,0,0,0
0,0,0,0,29,28,28,28,20,9,20,28,28,28,28,28,27,0,0,0
0,0,0,0,20,0,0,0,0,0,0,0,0,0,0,9,27,0,0,0
0,0,0,20,20,20,30,30,20,20,20,20,20,30,30,0,27,0,0,0
0,0,0,0,20,9,0,9,9,20,20,20,20,9,30,0,27,0,0,0
0,0,0,0,29,0,0,20,20,20,20,20,20,20,30,24,27,0,0,0
0,0,0,0,29,0,0,9,20,5,4,20,9,20,30,20,20,20,0,0
0,0,0,0,29,0,0,20,20,8,7,20,20,20,20,20,20,20,20,0
0,0,0,0,29,0,0,20,20,20,20,20,20,20,20,20,9,20,20,0
0,0,0,0,29,0,0,0,9,20,20,20,20,30,20,20,20,20,20,0
0,0,0,0,29,9,0,0,9,0,0,0,0,0,0,9,27,0,0,0
0,0,0,0,29,31,31,31,31,31,31,31,31,31,31,31,27,0,0,0
0,0,0,0,0,0,0,0,0,0,0,0,0,0,0,0,0,0,0,0
0,0,0,0,0,0,0,0,0,0,0,0,0,0,0,0,0,0,0,0
0,0,0,0,0,0,0,0,0,0,0,0,0,0,0,0,0,0,0,0
0,0,0,0,0,0,0,0,0,0,0,0,0,0,0,0,0,0,0,0
0,0,0,0,0,0,0,0,0,0,0,0,0,0,0,0,0,0,0,0
endlayer

layer
0,0,0,0,0,0,0,0,0,20,0,0,0,0,0,0,0,0,0,0
0,0,0,0,0,0,0,0,20,20,20,0,0,0,0,0,0,0,0,0
0,0,0,0,20,20,20,20,20,9,20,20,0,0,0,0,0,0,0,0
0,0,0,20,20,20,20,20,20,20,20,0,0,0,0,0,0,0,0,0
0,0,20,20,20,20,20,20,0,20,20,32,32,32,32,32,0,0,0,0
0,20,20,20,20,20,20,20,20,20,33,20,20,32,9,32,0,0,0,0
0,20,20,20,20,9,20,9,9,20,33,20,20,20,32,32,0,0,0,0
0,0,20,20,20,20,20,20,20,20,20,20,20,20,32,32,20,0,0,0
0,0,0,20,20,20,20,9,20,20,20,20,9,20,20,20,20,20,20,0
0,0,0,0,0,32,32,20,20,20,20,20,20,20,20,20,20,20,20,0
0,0,0,0,0,32,32,20,20,20,20,20,20,20,20,20,9,20,20,20
0,0,0,0,0,32,32,32,9,20,20,20,20,32,20,20,20,20,20,0
0,0,0,0,0,32,32,32,9,32,20,32,32,32,20,20,20,20,20,0
0,0,0,0,0,0,0,0,0,0,0,0,0,0,0,0,20,0,0,0
0,0,0,0,0,0,0,0,0,0,0,0,0,0,0,0,0,0,0,0
0,0,0,0,0,0,0,0,0,0,0,0,0,0,0,0,0,0,0,0
0,0,0,0,0,0,0,0,0,0,0,0,0,0,0,0,0,0,0,0
0,0,0,0,0,0,0,0,0,0,0,0,0,0,0,0,0,0,0,0
0,0,0,0,0,0,0,0,0,0,0,0,0,0,0,0,0,0,0,0
endlayer

layer
0,0,0,0,0,0,0,0,0,0,0,0,0,0,0,0,0,0,0,0
0,0,0,0,20,0,0,20,20,20,20,0,0,0,0,0,0,0,0,0
0,0,0,20,20,20,20,20,20,20,20,0,0,0,0,0,0,0,0,0
0,0,20,20,20,20,20,20,20,20,20,0,0,0,0,0,0,0,0,0
0,20,20,20,20,20,20,20,20,20,0,0,0,0,0,0,0,0,0,0
20,20,20,20,9,20,20,20,20,20,20,20,20,0,9,0,0,0,0,0
0,20,20,20,20,20,20,9,9,20,20,20,20,20,0,0,0,0,0,0
0,0,20,20,20,20,20,20,20,20,20,20,20,20,0,0,0,0,0,0
0,0,0,20,20,20,20,9,20,20,20,20,20,9,0,20,20,20,0,0
0,0,0,0,20,20,20,20,20,20,20,20,20,20,20,20,20,20,20,0
0,0,0,0,0,0,0,20,20,20,20,20,20,20,20,20,20,20,20,0
0,0,0,0,0,0,0,0,20,20,20,20,20,0,20,20,20,20,20,0
0,0,0,0,0,0,0,9,0,0,0,0,0,0,0,20,20,20,0,0
0,0,0,0,0,0,0,0,9,0,0,0,0,0,0,0,0,0,0,0
0,0,0,0,0,0,0,0,0,0,0,0,0,0,0,0,0,0,0,0
0,0,0,0,0,0,0,0,0,0,0,0,0,0,0,0,0,0,0,0
0,0,0,0,0,0,0,0,0,0,0,0,0,0,0,0,0,0,0,0
0,0,0,0,0,0,0,0,0,0,0,0,0,0,0,0,0,0,0,0
0,0,0,0,0,0,0,0,0,0,0,0,0,0,0,0,0,0,0,0
endlayer

layer
0,0,0,0,0,0,0,0,0,0,0,0,0,0,0,0,0,0,0,0
0,0,0,0,0,0,0,0,0,0,0,0,0,0,0,0,0,0,0,0
0,0,0,0,20,0,20,20,0,20,0,0,0,0,0,0,0,0,0,0
0,0,0,20,20,20,20,20,20,20,0,0,0,0,0,0,0,0,0,0
0,0,20,20,20,20,20,20,20,20,0,0,0,0,0,0,0,0,0,0
0,20,20,20,20,20,20,9,20,20,20,20,0,0,9,0,0,0,0,0
0,0,20,20,20,20,20,9,20,20,20,20,20,0,0,0,0,0,0,0
0,0,0,20,20,20,20,20,20,20,20,20,20,20,0,0,0,0,0,0
0,0,0,20,20,20,20,9,20,20,20,20,20,9,0,0,0,0,0,0
0,0,0,0,0,0,0,20,20,20,20,20,20,20,0,0,0,0,0,0
0,0,0,0,0,0,0,0,20,20,20,33,20,0,0,0,20,0,0,0
0,0,0,0,0,0,0,0,0,20,20,0,0,0,0,0,0,0,0,0
0,0,0,0,0,0,0,9,0,0,0,0,0,0,0,0,0,0,0,0
0,0,0,0,0,0,20,20,9,0,0,0,0,0,0,0,0,0,0,0
0,0,0,0,0,0,0,20,0,0,0,0,0,0,0,0,0,0,0,0
0,0,0,0,0,0,0,0,0,0,0,0,0,0,0,0,0,0,0,0
0,0,0,0,0,0,0,0,0,0,0,0,0,0,0,0,0,0,0,0
0,0,0,0,0,0,0,0,0,0,0,0,0,0,0,0,0,0,0,0
0,0,0,0,0,0,0,0,0,0,0,0,0,0,0,0,0,0,0,0
endlayer

layer
0,0,0,0,0,0,0,0,0,0,0,0,0,0,0,0,0,0,0,0
0,0,0,0,0,0,0,0,0,0,0,0,0,0,0,0,0,0,0,0
0,0,0,0,0,0,0,0,0,0,0,0,0,0,0,0,0,0,0,0
0,0,0,0,0,0,20,20,20,0,0,0,0,0,0,20,0,0,0,0
0,0,0,0,20,20,20,20,20,20,0,0,0,0,0,9,0,0,0,0
0,0,0,20,20,20,9,20,20,20,0,0,0,0,0,0,0,0,0,0
0,0,0,0,20,20,20,20,20,20,20,20,0,0,0,0,0,0,0,0
0,0,0,0,0,0,20,20,20,20,20,20,20,0,0,0,0,0,0,0
0,0,0,0,0,0,9,0,20,20,20,20,20,9,0,0,0,0,0,0
0,0,0,0,0,0,0,0,20,20,20,20,20,0,0,0,0,0,0,0
0,0,0,0,0,20,20,20,20,20,0,20,0,0,0,0,0,0,0,0
0,0,0,0,20,20,20,20,20,20,20,0,0,0,0,0,0,0,0,0
0,0,0,0,20,20,20,9,20,20,20,0,0,0,0,0,0,0,0,0
0,0,0,0,20,20,20,20,9,20,20,0,0,0,0,0,0,0,0,0
0,0,0,0,0,20,20,20,20,20,20,0,0,0,0,0,0,0,0,0
0,0,0,0,0,0,20,20,20,20,20,0,0,0,0,0,0,0,0,0
0,0,0,0,0,0,0,20,20,20,0,0,0,0,0,0,0,0,0,0
0,0,0,0,0,0,0,0,0,0,0,0,0,0,0,0,0,0,0,0
0,0,0,0,0,0,0,0,0,0,0,0,0,0,0,0,0,0,0,0
endlayer

layer
0,0,0,0,0,0,0,0,0,0,0,0,0,0,0,0,0,0,0,0
0,0,0,0,0,0,0,0,0,0,0,0,0,0,0,0,0,0,0,0
0,0,0,0,0,0,0,0,0,0,0,0,0,0,20,20,20,0,0,0
0,0,0,0,0,0,0,0,0,0,0,0,0,0,20,20,20,0,0,0
0,0,0,0,0,20,0,0,0,0,0,0,0,0,20,9,20,0,0,0
0,0,0,0,0,0,9,20,0,0,0,0,0,0,0,0,0,0,0,0
0,0,0,0,0,0,0,0,0,0,0,0,0,0,0,0,0,0,0,0
0,0,0,0,0,0,0,0,0,0,20,0,0,0,0,0,0,0,0,0
0,0,0,0,0,0,9,20,0,20,20,20,0,9,0,0,0,0,0,0
0,0,0,0,20,20,20,20,20,20,0,0,0,0,0,0,0,0,0,0
0,0,0,0,20,20,20,20,20,20,0,0,0,0,0,0,0,0,0,0
0,0,0,0,20,20,20,20,20,20,20,0,0,0,0,0,0,0,0,0
0,0,0,20,20,20,20,9,20,20,20,20,0,0,0,0,0,0,0,0
0,0,0,20,20,20,20,9,20,20,20,20,0,0,0,0,0,0,0,0
0,0,0,0,20,20,20,20,20,20,20,0,0,0,0,0,0,0,0,0
0,0,0,0,0,20,20,20,20,20,0,0,0,0,0,0,0,0,0,0
0,0,0,0,0,0,20,20,20,0,0,0,0,0,0,0,0,0,0,0
0,0,0,0,0,0,0,20,0,0,0,0,0,0,0,0,0,0,0,0
0,0,0,0,0,0,0,0,0,0,0,0,0,0,0,0,0,0,0,0
endlayer

layer
0,0,0,0,0,0,0,0,0,0,0,0,0,0,0,0,0,0,0,0
0,0,0,0,0,0,0,0,0,0,0,0,0,0,0,20,0,0,0,0
0,0,0,0,0,0,0,0,0,0,0,0,0,0,20,20,20,0,0,0
0,0,0,0,20,20,20,0,0,0,0,0,0,20,20,9,20,20,0,0
0,0,0,0,20,20,20,0,0,0,0,0,0,0,20,20,20,0,0,0
0,0,0,0,20,20,9,0,0,0,0,0,0,0,0,20,0,0,0,0
0,0,0,0,0,0,0,0,0,0,0,0,0,0,0,0,0,0,0,0
0,0,0,0,0,0,0,0,0,0,0,0,0,0,0,0,0,0,0,0
0,0,0,0,0,0,9,0,0,0,0,0,0,0,9,0,0,0,0,0
0,0,0,0,0,0,0,0,0,0,0,0,0,0,0,0,0,0,0,0
0,0,0,0,0,20,20,20,20,0,0,0,0,0,0,0,0,0,0,0
0,0,0,0,20,20,20,20,20,20,0,0,0,0,0,0,0,0,0,0
0,0,0,0,20,20,20,20,20,20,20,0,0,0,0,0,0,0,0,0
0,0,0,0,20,20,9,20,20,20,20,0,0,0,0,0,0,0,0,0
0,0,0,0,20,20,20,20,20,20,0,0,0,0,0,0,0,0,0,0
0,0,0,0,20,20,20,20,20,0,0,0,0,0,0,0,0,0,0,0
0,0,0,0,0,20,20,20,0,0,0,0,0,0,0,0,0,0,0,0
0,0,0,0,0,0,0,0,0,0,0,0,0,0,0,0,0,0,0,0
0,0,0,0,0,0,0,0,0,0,0,0,0,0,0,0,0,0,0,0
endlayer

layer
0,0,0,0,0,0,0,0,0,0,0,0,0,0,0,0,0,0,0,0
0,0,0,0,0,0,0,0,0,0,0,0,0,0,0,0,0,0,0,0
0,0,0,0,0,20,0,0,0,0,0,0,0,0,20,20,20,0,0,0
0,0,0,0,20,20,20,0,0,0,0,0,0,0,20,20,20,0,0,0
0,0,0,20,20,9,20,20,0,0,0,0,0,0,20,20,20,0,0,0
0,0,0,0,20,20,20,0,0,0,0,0,0,0,0,0,0,0,0,0
0,0,0,0,0,20,0,0,0,0,0,0,0,0,0,0,0,0,0,0
0,0,0,0,0,0,0,0,0,0,0,0,0,0,0,0,0,0,0,0
0,0,0,0,0,0,9,0,0,0,0,0,0,0,9,0,0,0,0,0
0,0,0,0,0,0,0,0,0,0,0,0,0,0,0,0,0,0,0,0
0,0,0,0,0,0,0,0,0,0,0,0,0,0,0,0,0,0,0,0
0,0,0,0,0,0,0,0,0,0,0,0,0,0,0,0,0,0,0,0
0,0,0,0,0,0,0,20,0,0,0,0,0,0,0,0,0,0,0,0
0,0,0,0,0,0,9,20,20,0,0,0,0,0,0,0,0,0,0,0
0,0,0,0,0,0,0,20,0,0,0,0,0,0,0,0,0,0,0,0
0,0,0,0,0,0,0,0,0,0,0,0,0,0,0,0,0,0,0,0
0,0,0,0,0,0,0,0,0,0,0,0,0,0,0,0,0,0,0,0
0,0,0,0,0,0,0,0,0,0,0,0,0,0,0,0,0,0,0,0
0,0,0,0,0,0,0,0,0,0,0,0,0,0,0,0,0,0,0,0
endlayer

layer
0,0,0,0,0,0,0,0,0,0,0,0,0,0,0,0,0,0,0,0
0,0,0,0,0,0,0,0,0,0,0,0,0,0,0,0,0,0,0,0
0,0,0,0,0,0,0,0,0,0,0,0,0,0,0,0,0,0,0,0
0,0,0,0,20,20,20,0,0,0,0,0,0,0,0,20,0,0,0,0
0,0,0,0,20,20,20,0,0,0,0,0,0,0,0,0,0,0,0,0
0,0,0,0,20,20,20,0,0,0,0,0,0,0,0,0,0,0,0,0
0,0,0,0,0,0,0,0,0,0,0,0,0,0,0,0,0,0,0,0
0,0,0,0,0,0,0,0,0,0,0,0,0,0,0,0,0,0,0,0
0,0,0,0,0,9,0,0,0,0,0,0,0,0,9,0,0,0,0,0
0,0,0,0,0,0,0,0,0,0,0,0,0,0,0,0,0,0,0,0
0,0,0,0,0,0,0,0,0,0,0,0,0,0,0,0,0,0,0,0
0,0,0,0,0,0,0,0,0,0,0,0,0,0,0,0,0,0,0,0
0,0,0,0,0,0,0,0,0,0,0,0,0,0,0,0,0,0,0,0
0,0,0,0,0,0,9,0,0,0,0,0,0,0,0,0,0,0,0,0
0,0,0,0,0,0,0,0,0,0,0,0,0,0,0,0,0,0,0,0
0,0,0,0,0,0,0,0,0,0,0,0,0,0,0,0,0,0,0,0
0,0,0,0,0,0,0,0,0,0,0,0,0,0,0,0,0,0,0,0
0,0,0,0,0,0,0,0,0,0,0,0,0,0,0,0,0,0,0,0
0,0,0,0,0,0,0,0,0,0,0,0,0,0,0,0,0,0,0,0
endlayer

layer
0,0,0,0,0,0,0,0,0,0,0,0,0,0,0,0,0,0,0,0
0,0,0,0,0,0,0,0,0,0,0,0,0,0,0,0,0,0,0,0
0,0,0,0,0,0,0,0,0,0,0,0,0,0,0,0,0,0,0,0
0,0,0,0,0,0,0,0,0,0,0,0,0,0,0,0,0,0,0,0
0,0,0,0,0,20,0,0,0,0,0,0,0,0,0,0,0,0,0,0
0,0,0,0,0,0,0,0,0,0,0,0,0,0,0,0,0,0,0,0
0,0,0,0,0,0,0,0,0,0,0,0,0,0,0,0,0,0,0,0
0,0,0,0,0,0,0,0,0,0,0,0,0,0,0,0,0,0,0,0
0,0,0,0,0,9,0,0,0,0,0,0,0,0,9,0,0,0,0,0
0,0,0,0,0,0,0,0,0,0,0,0,0,0,0,0,0,0,0,0
0,0,0,0,0,0,0,0,0,0,0,0,0,0,0,0,0,0,0,0
0,0,0,0,0,0,0,0,0,0,0,0,0,0,0,0,0,0,0,0
0,0,0,0,0,0,0,0,0,0,0,0,0,0,0,0,0,0,0,0
0,0,0,0,0,0,9,0,0,0,0,0,0,0,0,0,0,0,0,0
0,0,0,0,0,0,0,0,0,0,0,0,0,0,0,0,0,0,0,0
0,0,0,0,0,0,0,0,0,0,0,0,0,0,0,0,0,0,0,0
0,0,0,0,0,0,0,0,0,0,0,0,0,0,0,0,0,0,0,0
0,0,0,0,0,0,0,0,0,0,0,0,0,0,0,0,0,0,0,0
0,0,0,0,0,0,0,0,0,0,0,0,0,0,0,0,0,0,0,0
endlayer

layer
0,0,0,0,0,0,0,0,0,0,0,0,0,0,0,0,0,0,0,0
0,0,0,0,0,0,0,0,0,0,0,0,0,0,0,0,0,0,0,0
0,0,0,0,0,0,0,0,0,0,0,0,0,0,0,0,0,0,0,0
0,0,0,0,0,0,0,0,0,0,0,0,0,0,0,0,0,0,0,0
0,0,0,0,0,0,0,0,0,0,0,0,0,0,0,0,0,0,0,0
0,0,0,0,0,0,0,0,0,0,0,0,0,0,0,0,0,0,0,0
0,0,0,0,0,0,0,0,0,0,0,0,0,0,0,0,0,0,0,0
0,0,0,0,20,0,0,0,0,0,0,0,0,0,0,0,0,0,0,0
0,0,0,0,0,9,0,0,0,0,0,0,0,0,9,0,0,0,0,0
0,0,0,0,0,0,0,0,0,0,0,0,0,0,0,0,0,0,0,0
0,0,0,0,0,0,0,0,0,0,0,0,0,0,0,0,0,0,0,0
0,0,0,0,0,0,0,0,0,0,0,0,0,0,0,0,0,0,0,0
0,0,0,0,0,0,0,0,0,0,0,0,0,0,0,0,0,0,0,0
0,0,0,0,0,0,9,0,0,0,0,0,0,0,0,0,0,0,0,0
0,0,0,0,0,0,0,0,0,0,0,0,0,0,0,0,0,0,0,0
0,0,0,0,0,0,0,0,0,0,0,0,0,0,0,0,0,0,0,0
0,0,0,0,0,0,0,0,0,0,0,0,0,0,0,0,0,0,0,0
0,0,0,0,0,0,0,0,0,0,0,0,0,0,0,0,0,0,0,0
0,0,0,0,0,0,0,0,0,0,0,0,0,0,0,0,0,0,0,0
endlayer

layer
0,0,0,0,0,0,0,0,0,0,0,0,0,0,0,0,0,0,0,0
0,0,0,0,0,0,0,0,0,0,0,0,0,0,0,0,0,0,0,0
0,0,0,0,0,0,0,0,0,0,0,0,0,0,0,0,0,0,0,0
0,0,0,0,0,0,0,0,0,0,0,0,0,0,0,0,0,0,0,0
0,0,0,0,0,0,0,0,0,0,0,0,0,0,0,0,0,0,0,0
0,0,0,20,20,20,0,0,0,0,0,0,0,0,0,0,0,0,0,0
0,0,20,20,20,20,20,0,0,0,0,0,0,0,0,0,0,0,0,0
0,0,20,20,20,20,20,0,0,0,0,0,0,0,0,0,0,0,0,0
0,0,20,20,20,9,20,0,0,0,0,0,0,0,0,9,0,0,0,0
0,0,0,20,20,20,0,0,0,0,0,0,0,0,0,0,0,0,0,0
0,0,0,0,0,0,0,0,0,0,0,0,0,0,0,0,0,0,0,0
0,0,0,0,0,0,0,0,0,0,0,0,0,0,0,0,0,0,0,0
0,0,0,0,0,0,0,0,0,0,0,0,0,0,0,0,0,0,0,0
0,0,0,0,0,0,0,0,0,0,0,0,0,0,0,0,0,0,0,0
0,0,0,0,0,9,0,0,0,0,0,0,0,0,0,0,0,0,0,0
0,0,0,0,0,0,0,0,0,0,0,0,0,0,0,0,0,0,0,0
0,0,0,0,0,0,0,0,0,0,0,0,0,0,0,0,0,0,0,0
0,0,0,0,0,0,0,0,0,0,0,0,0,0,0,0,0,0,0,0
0,0,0,0,0,0,0,0,0,0,0,0,0,0,0,0,0,0,0,0
endlayer

layer
0,0,0,0,0,0,0,0,0,0,0,0,0,0,0,0,0,0,0,0
0,0,0,0,0,0,0,0,0,0,0,0,0,0,0,0,0,0,0,0
0,0,0,0,0,0,0,0,0,0,0,0,0,0,0,0,0,0,0,0
0,0,0,0,0,0,0,0,0,0,0,0,0,0,0,0,0,0,0,0
0,0,0,0,20,0,0,0,0,0,0,0,0,0,0,0,0,0,0,0
0,0,20,20,20,20,20,0,0,0,0,0,0,0,0,0,0,0,0,0
0,0,20,20,20,20,20,0,0,0,0,0,0,0,0,0,0,0,0,0
0,20,20,20,9,20,20,20,0,0,0,0,0,0,0,0,0,0,0,0
0,0,20,20,20,20,20,0,0,0,0,0,0,0,0,9,0,0,0,0
0,0,20,20,20,20,20,0,0,0,0,0,0,0,0,0,0,0,0,0
0,0,0,0,20,0,0,0,0,0,0,0,0,0,0,0,0,0,0,0
0,0,0,0,0,0,0,0,0,0,0,0,0,0,0,0,0,0,0,0
0,0,0,0,0,0,0,0,0,0,0,0,0,0,0,0,0,0,0,0
0,0,0,0,0,0,0,0,0,0,0,0,0,0,0,0,0,0,0,0
0,0,0,0,0,9,0,0,0,0,0,0,0,0,0,0,0,0,0,0
0,0,0,0,0,0,0,0,0,0,0,0,0,0,0,0,0,0,0,0
0,0,0,0,0,0,0,0,0,0,0,0,0,0,0,0,0,0,0,0
0,0,0,0,0,0,0,0,0,0,0,0,0,0,0,0,0,0,0,0
0,0,0,0,0,0,0,0,0,0,0,0,0,0,0,0,0,0,0,0
endlayer

layer
0,0,0,0,0,0,0,0,0,0,0,0,0,0,0,0,0,0,0,0
0,0,0,0,0,0,0,0,0,0,0,0,0,0,0,0,0,0,0,0
0,0,0,0,0,0,0,0,0,0,0,0,0,0,0,0,0,0,0,0
0,0,0,0,0,0,0,0,0,0,0,0,0,0,0,0,0,0,0,0
0,0,0,0,0,0,0,0,0,0,0,0,0,0,0,0,0,0,0,0
0,0,0,20,20,20,0,0,0,0,0,0,0,0,0,0,0,0,0,0
0,0,20,20,20,20,20,0,0,0,0,0,0,0,0,0,0,0,0,0
0,0,20,20,20,20,20,0,0,0,0,0,0,0,0,0,0,0,0,0
0,0,20,20,20,20,20,0,0,0,0,0,0,0,0,9,0,0,0,0
0,0,0,20,20,20,0,0,0,0,0,0,0,0,0,0,0,0,0,0
0,0,0,0,0,0,0,0,0,0,0,0,0,0,0,0,0,0,0,0
0,0,0,0,0,0,0,0,0,0,0,0,0,0,0,0,0,0,0,0
0,0,0,0,0,0,0,0,0,0,0,0,0,0,0,0,0,0,0,0
0,0,0,0,0,0,0,0,0,0,0,0,0,0,0,0,0,0,0,0
0,0,0,0,20,9,0,0,0,0,0,0,0,0,0,0,0,0,0,0
0,0,0,0,0,0,0,0,0,0,0,0,0,0,0,0,0,0,0,0
0,0,0,0,0,0,0,0,0,0,0,0,0,0,0,0,0,0,0,0
0,0,0,0,0,0,0,0,0,0,0,0,0,0,0,0,0,0,0,0
0,0,0,0,0,0,0,0,0,0,0,0,0,0,0,0,0,0,0,0
endlayer

layer
0,0,0,0,0,0,0,0,0,0,0,0,0,0,0,0,0,0,0,0
0,0,0,0,0,0,0,0,0,0,0,0,0,0,0,0,0,0,0,0
0,0,0,0,0,0,0,0,0,0,0,0,0,0,0,0,0,0,0,0
0,0,0,0,0,0,0,0,0,0,0,0,0,0,0,0,0,0,0,0
0,0,0,0,0,0,0,0,0,0,0,0,0,0,0,0,0,0,0,0
0,0,0,0,0,0,0,0,0,0,0,0,0,0,0,0,0,0,0,0
0,0,0,0,0,0,0,0,0,0,0,0,0,0,0,0,0,0,0,0
0,0,0,0,20,0,0,0,0,0,0,0,0,0,0,0,0,0,0,0
0,0,0,0,0,0,0,0,0,0,0,0,0,0,0,9,0,0,0,0
0,0,0,0,0,0,0,0,0,0,0,0,0,0,0,0,0,0,0,0
0,0,0,0,0,0,0,0,0,0,0,0,0,0,0,0,0,0,0,0
0,0,0,0,0,0,0,0,0,0,0,0,0,0,0,0,0,0,0,0
0,0,0,20,20,20,0,0,0,0,0,0,0,0,0,0,0,0,0,0
0,0,20,20,20,20,20,0,0,0,0,0,0,0,0,0,0,0,0,0
0,0,20,20,20,9,20,0,0,0,0,0,0,0,0,0,0,0,0,0
0,0,20,20,20,20,20,0,0,0,0,0,0,0,0,0,0,0,0,0
0,0,0,20,20,20,0,0,0,0,0,0,0,0,0,0,0,0,0,0
0,0,0,0,0,0,0,0,0,0,0,0,0,0,0,0,0,0,0,0
0,0,0,0,0,0,0,0,0,0,0,0,0,0,0,0,0,0,0,0
endlayer

layer
0,0,0,0,0,0,0,0,0,0,0,0,0,0,0,0,0,0,0,0
0,0,0,0,0,0,0,0,0,0,0,0,0,0,0,0,0,0,0,0
0,0,0,0,0,0,0,0,0,0,0,0,0,0,0,0,0,0,0,0
0,0,0,0,0,0,0,0,0,0,0,0,0,0,0,0,0,0,0,0
0,0,0,0,0,0,0,0,0,0,0,0,0,0,0,0,0,0,0,0
0,0,0,0,0,0,0,0,0,0,0,0,0,0,0,0,0,0,0,0
0,0,0,0,0,0,0,0,0,0,0,0,0,0,0,0,0,0,0,0
0,0,0,0,0,0,0,0,0,0,0,0,0,0,0,0,0,0,0,0
0,0,0,0,0,0,0,0,0,0,0,0,0,0,0,0,9,0,0,0
0,0,0,0,0,0,0,0,0,0,0,0,0,0,0,0,0,0,0,0
0,0,0,0,0,0,0,0,0,0,0,0,0,0,0,0,0,0,0,0
0,0,0,0,20,0,0,0,0,0,0,0,0,0,0,0,0,0,0,0
0,0,20,20,20,20,20,0,0,0,0,0,0,0,0,0,0,0,0,0
0,0,20,20,20,20,20,0,0,0,0,0,0,0,0,0,0,0,0,0
0,20,20,20,9,20,20,20,0,0,0,0,0,0,0,0,0,0,0,0
0,0,20,20,20,20,20,0,0,0,0,0,0,0,0,0,0,0,0,0
0,0,20,20,20,20,20,0,0,0,0,0,0,0,0,0,0,0,0,0
0,0,0,0,20,0,0,0,0,0,0,0,0,0,0,0,0,0,0,0
0,0,0,0,0,0,0,0,0,0,0,0,0,0,0,0,0,0,0,0
endlayer

layer
0,0,0,0,0,0,0,0,0,0,0,0,0,0,0,0,0,0,0,0
0,0,0,0,0,0,0,0,0,0,0,0,0,0,0,0,0,0,0,0
0,0,0,0,0,0,0,0,0,0,0,0,0,0,0,0,0,0,0,0
0,0,0,0,0,0,0,0,0,0,0,0,0,0,0,0,0,0,0,0
0,0,0,0,0,0,0,0,0,0,0,0,0,0,0,0,0,0,0,0
0,0,0,0,0,0,0,0,0,0,0,0,0,0,0,0,0,0,0,0
0,0,0,0,0,0,0,0,0,0,0,0,0,0,0,0,0,0,0,0
0,0,0,0,0,0,0,0,0,0,0,0,0,0,0,0,0,0,0,0
0,0,0,0,0,0,0,0,0,0,0,0,0,0,0,0,9,0,0,0
0,0,0,0,0,0,0,0,0,0,0,0,0,0,0,0,0,0,0,0
0,0,0,0,0,0,0,0,0,0,0,0,0,0,0,0,0,0,0,0
0,0,0,0,0,0,0,0,0,0,0,0,0,0,0,0,0,0,0,0
0,0,0,20,20,20,0,0,0,0,0,0,0,0,0,0,0,0,0,0
0,0,20,20,20,20,20,0,0,0,0,0,0,0,0,0,0,0,0,0
0,0,20,20,20,20,20,0,0,0,0,0,0,0,0,0,0,0,0,0
0,0,20,20,20,20,20,0,0,0,0,0,0,0,0,0,0,0,0,0
0,0,0,20,20,20,0,0,0,0,0,0,0,0,0,0,0,0,0,0
0,0,0,0,0,0,0,0,0,0,0,0,0,0,0,0,0,0,0,0
0,0,0,0,0,0,0,0,0,0,0,0,0,0,0,0,0,0,0,0
endlayer

layer
0,0,0,0,0,0,0,0,0,0,0,0,0,0,0,0,0,0,0,0
0,0,0,0,0,0,0,0,0,0,0,0,0,0,0,0,0,0,0,0
0,0,0,0,0,0,0,0,0,0,0,0,0,0,0,0,0,0,0,0
0,0,0,0,0,0,0,0,0,0,0,0,0,0,0,0,0,0,0,0
0,0,0,0,0,0,0,0,0,0,0,0,0,0,0,0,0,0,0,0
0,0,0,0,0,0,0,0,0,0,0,0,0,0,0,0,0,0,0,0
0,0,0,0,0,0,0,0,0,0,0,0,0,0,0,0,20,0,0,0
0,0,0,0,0,0,0,0,0,0,0,0,0,0,0,20,20,20,0,0
0,0,0,0,0,0,0,0,0,0,0,0,0,0,0,0,9,0,0,0
0,0,0,0,0,0,0,0,0,0,0,0,0,0,0,0,0,0,0,0
0,0,0,0,0,0,0,0,0,0,0,0,0,0,0,0,0,0,0,0
0,0,0,0,0,0,0,0,0,0,0,0,0,0,0,0,0,0,0,0
0,0,0,0,0,0,0,0,0,0,0,0,0,0,0,0,0,0,0,0
0,0,0,0,0,0,0,0,0,0,0,0,0,0,0,0,0,0,0,0
0,0,0,0,20,0,0,0,0,0,0,0,0,0,0,0,0,0,0,0
0,0,0,0,0,0,0,0,0,0,0,0,0,0,0,0,0,0,0,0
0,0,0,0,0,0,0,0,0,0,0,0,0,0,0,0,0,0,0,0
0,0,0,0,0,0,0,0,0,0,0,0,0,0,0,0,0,0,0,0
0,0,0,0,0,0,0,0,0,0,0,0,0,0,0,0,0,0,0,0
endlayer

layer
0,0,0,0,0,0,0,0,0,0,0,0,0,0,0,0,0,0,0,0
0,0,0,0,0,0,0,0,0,0,0,0,0,0,0,0,0,0,0,0
0,0,0,0,0,0,0,0,0,0,0,0,0,0,0,0,0,0,0,0
0,0,0,0,0,0,0,0,0,0,0,0,0,0,0,0,0,0,0,0
0,0,0,0,0,0,0,0,0,0,0,0,0,0,0,0,20,0,0,0
0,0,0,0,0,0,0,0,0,0,0,0,0,0,0,20,20,20,0,0
0,0,0,0,0,0,0,0,0,0,0,0,0,0,20,20,20,20,20,0
0,0,0,0,0,0,0,0,0,0,0,0,0,20,20,20,20,20,20,20
0,0,0,0,0,0,0,0,0,0,0,0,0,20,20,20,9,20,20,20
0,0,0,0,0,0,0,0,0,0,0,0,0,20,20,20,20,20,20,20
0,0,0,0,0,0,0,0,0,0,0,0,0,0,20,20,20,20,20,0
0,0,0,0,0,0,0,0,0,0,0,0,0,0,0,0,0,0,0,0
0,0,0,0,0,0,0,0,0,0,0,0,0,0,0,0,0,0,0,0
0,0,0,0,0,0,0,0,0,0,0,0,0,0,0,0,0,0,0,0
0,0,0,0,0,0,0,0,0,0,0,0,0,0,0,0,0,0,0,0
0,0,0,0,0,0,0,0,0,0,0,0,0,0,0,0,0,0,0,0
0,0,0,0,0,0,0,0,0,0,0,0,0,0,0,0,0,0,0,0
0,0,0,0,0,0,0,0,0,0,0,0,0,0,0,0,0,0,0,0
0,0,0,0,0,0,0,0,0,0,0,0,0,0,0,0,0,0,0,0
endlayer

layer
0,0,0,0,0,0,0,0,0,0,0,0,0,0,0,0,0,0,0,0
0,0,0,0,0,0,0,0,0,0,0,0,0,0,0,0,0,0,0,0
0,0,0,0,0,0,0,0,0,0,0,0,0,0,0,0,0,0,0,0
0,0,0,0,0,0,0,0,0,0,0,0,0,0,0,0,20,0,0,0
0,0,0,0,0,0,0,0,0,0,0,0,0,0,0,20,20,20,0,0
0,0,0,0,0,0,0,0,0,0,0,0,0,0,20,20,20,20,20,0
0,0,0,0,0,0,0,0,0,0,0,0,0,20,20,20,20,20,20,20
0,0,0,0,0,0,0,0,0,0,0,0,20,20,20,20,9,20,20,20
0,0,0,0,0,0,0,0,0,0,0,0,0,20,20,20,20,20,20,20
0,0,0,0,0,0,0,0,0,0,0,0,0,0,20,20,20,20,20,0
0,0,0,0,0,0,0,0,0,0,0,0,0,0,0,20,20,20,0,0
0,0,0,0,0,0,0,0,0,0,0,0,0,0,0,0,20,0,0,0
0,0,0,0,0,0,0,0,0,0,0,0,0,0,0,0,0,0,0,0
0,0,0,0,0,0,0,0,0,0,0,0,0,0,0,0,0,0,0,0
0,0,0,0,0,0,0,0,0,0,0,0,0,0,0,0,0,0,0,0
0,0,0,0,0,0,0,0,0,0,0,0,0,0,0,0,0,0,0,0
0,0,0,0,0,0,0,0,0,0,0,0,0,0,0,0,0,0,0,0
0,0,0,0,0,0,0,0,0,0,0,0,0,0,0,0,0,0,0,0
0,0,0,0,0,0,0,0,0,0,0,0,0,0,0,0,0,0,0,0
endlayer

layer
0,0,0,0,0,0,0,0,0,0,0,0,0,0,0,0,0,0,0,0
0,0,0,0,0,0,0,0,0,0,0,0,0,0,0,0,0,0,0,0
0,0,0,0,0,0,0,0,0,0,0,0,0,0,0,0,0,0,0,0
0,0,0,0,0,0,0,0,0,0,0,0,0,0,0,0,0,0,0,0
0,0,0,0,0,0,0,0,0,0,0,0,0,0,0,0,20,0,0,0
0,0,0,0,0,0,0,0,0,0,0,0,0,0,0,20,20,20,0,0
0,0,0,0,0,0,0,0,0,0,0,0,0,0,20,20,20,20,20,0
0,0,0,0,0,0,0,0,0,0,0,0,0,20,20,20,20,20,20,20
0,0,0,0,0,0,0,0,0,0,0,0,0,0,20,20,20,20,20,0
0,0,0,0,0,0,0,0,0,0,0,0,0,0,0,20,20,20,0,0
0,0,0,0,0,0,0,0,0,0,0,0,0,0,0,0,20,0,0,0
0,0,0,0,0,0,0,0,0,0,0,0,0,0,0,0,0,0,0,0
0,0,0,0,0,0,0,0,0,0,0,0,0,0,0,0,0,0,0,0
0,0,0,0,0,0,0,0,0,0,0,0,0,0,0,0,0,0,0,0
0,0,0,0,0,0,0,0,0,0,0,0,0,0,0,0,0,0,0,0
0,0,0,0,0,0,0,0,0,0,0,0,0,0,0,0,0,0,0,0
0,0,0,0,0,0,0,0,0,0,0,0,0,0,0,0,0,0,0,0
0,0,0,0,0,0,0,0,0,0,0,0,0,0,0,0,0,0,0,0
0,0,0,0,0,0,0,0,0,0,0,0,0,0,0,0,0,0,0,0
endlayer

layer
0,0,0,0,0,0,0,0,0,0,0,0,0,0,0,0,0,0,0,0
0,0,0,0,0,0,0,0,0,0,0,0,0,0,0,0,0,0,0,0
0,0,0,0,0,0,0,0,0,0,0,0,0,0,0,0,0,0,0,0
0,0,0,0,0,0,0,0,0,0,0,0,0,0,0,0,0,0,0,0
0,0,0,0,0,0,0,0,0,0,0,0,0,0,0,0,0,0,0,0
0,0,0,0,0,0,0,0,0,0,0,0,0,0,0,0,0,0,0,0
0,0,0,0,0,0,0,0,0,0,0,0,0,0,0,0,20,0,0,0
0,0,0,0,0,0,0,0,0,0,0,0,0,0,0,20,20,20,0,0
0,0,0,0,0,0,0,0,0,0,0,0,0,0,0,0,20,0,0,0
0,0,0,0,0,0,0,0,0,0,0,0,0,0,0,0,0,0,0,0
0,0,0,0,0,0,0,0,0,0,0,0,0,0,0,0,0,0,0,0
0,0,0,0,0,0,0,0,0,0,0,0,0,0,0,0,0,0,0,0
0,0,0,0,0,0,0,0,0,0,0,0,0,0,0,0,0,0,0,0
0,0,0,0,0,0,0,0,0,0,0,0,0,0,0,0,0,0,0,0
0,0,0,0,0,0,0,0,0,0,0,0,0,0,0,0,0,0,0,0
0,0,0,0,0,0,0,0,0,0,0,0,0,0,0,0,0,0,0,0
0,0,0,0,0,0,0,0,0,0,0,0,0,0,0,0,0,0,0,0
0,0,0,0,0,0,0,0,0,0,0,0,0,0,0,0,0,0,0,0
0,0,0,0,0,0,0,0,0,0,0,0,0,0,0,0,0,0,0,0
endlayer

