
# Created by Ruins mod version 15.0 Ingame Parser
# authoring Player: SunsOfOld

weight=100
embed_into_distance=1
acceptable_target_blocks=
unacceptable_target_blocks=flowing_water,water,flowing_lava,lava
dimensions=7,22,20
allowable_overhang=0
max_leveling=5
leveling_buffer=0
preserve_water=0
preserve_lava=0
uniqueMinDistance=1000000
preventRotation=1

rule1=0,100,preserveBlock
rule2=0,100,minecraft:grass-0
rule3=0,100,dendrology:hekur_planks-4
rule4=0,100,minecraft:farmland-7
rule5=0,100,minecraft:water-0
rule6=0,100,minecraft:dirt-0
rule7=0,100,chisel:dirt-10
rule8=0,100,chisel:dirt-12
rule9=0,100,chisel:dirt-2
rule10=0,100,GardenStuff:fence-3
rule11=0,100,minecraft:tallgrass-1
rule12=0,100,minecraft:double_plant-2
rule13=0,100,minecraft:anvil-10
rule14=0,100,ExtrabiomesXL:flower1-7
rule15=0,100,VeganOption:composter-5
rule16=0,100,GardenCore:compost_bin-0
rule17=0,100,GardenStuff:lattice-2
rule18=0,100,ExtrabiomesXL:flower3-0
rule19=0,100,dendrology:hekur_planks-1
rule20=0,100,plantmegapack:cropGreenBeans-1
rule21=0,100,plantmegapack:cropGreenBeans-0
rule22=0,100,IInventory;minecraft:chest;ExtrabiomesXL:saplings_1#4#4#12+dendrology:sapling0#4#5#13-3
rule23=0,100,GardenContainers:large_pot_colored-6
rule24=0,100,harvestcraft:pamsoybeanCrop-1
rule25=0,100,harvestcraft:pamtomatoCrop-7
rule26=0,100,plantmegapack:floatingWaterLettuce-0
rule27=0,100,harvestcraft:pamasparagusCrop-0
rule28=0,100,harvestcraft:pameggplantCrop-0
rule29=0,100,harvestcraft:pamrhubarbCrop-0
rule30=0,100,ExtrabiomesXL:tile.extrabiomes.crop.strawberry-1
rule31=0,100,dendrology:hekur_planks-12
rule32=0,100,harvestcraft:pamsoybeanCrop-7
rule33=0,100,harvestcraft:pamtomatoCrop-1
rule34=0,100,harvestcraft:pamlettuceCrop-0
rule35=0,100,harvestcraft:pameggplantCrop-7
rule36=0,100,harvestcraft:pamrhubarbCrop-1
rule37=0,100,plantmegapack:cropLettuce-4
rule38=0,100,ExtrabiomesXL:tile.extrabiomes.crop.strawberry-0
rule39=0,100,GardenContainers:medium_pot_colored-1
rule40=0,100,plantmegapack:cropGreenBeans-2
rule41=0,100,harvestcraft:pamsoybeanCrop-6
rule42=0,100,harvestcraft:pameggplantCrop-1
rule43=0,100,ExtrabiomesXL:tile.extrabiomes.crop.strawberry-7
rule44=0,100,GardenStuff:root_cover-0
rule45=0,100,minecraft:web-0
rule46=0,100,harvestcraft:pamsoybeanCrop-4
rule47=0,100,harvestcraft:pamtomatoCrop-0
rule48=0,100,harvestcraft:pameggplantCrop-5
rule49=0,100,ExtrabiomesXL:flower2-0
rule50=0,100,dendrology:wood0-5
rule51=0,100,minecraft:wooden_door-4
rule52=0,100,harvestcraft:pamtomatoCrop-5
rule53=0,100,harvestcraft:pamasparagusCrop-2
rule54=0,100,harvestcraft:pameggplantCrop-3
rule55=0,100,GardenContainers:medium_pot_colored-15
rule56=0,100,harvestcraft:pamsoybeanCrop-0
rule57=0,100,harvestcraft:pamasparagusCrop-1
rule58=0,100,harvestcraft:pameggplantCrop-4
rule59=0,100,ExtrabiomesXL:tile.extrabiomes.crop.strawberry-3
rule60=0,100,harvestcraft:pamlettuceCrop-6
rule61=0,100,harvestcraft:pamasparagusCrop-6
rule62=0,100,harvestcraft:pamrhubarbCrop-5
rule63=0,100,harvestcraft:pamlettuceCrop-5
rule64=0,100,harvestcraft:pamasparagusCrop-5
rule65=0,100,GardenTrees:thin_log-5
rule66=0,100,ExtrabiomesXL:flower2-14
rule67=0,100,harvestcraft:pamasparagusCrop-3
rule68=0,100,harvestcraft:pamrhubarbCrop-4
rule69=0,100,ExtrabiomesXL:flower3-13
rule70=0,100,harvestcraft:pamrhubarbCrop-3
rule71=0,100,harvestcraft:pamtomatoCrop-2
rule72=0,100,harvestcraft:pamlettuceCrop-2
rule73=0,100,harvestcraft:pameggplantCrop-6
rule74=0,100,GardenContainers:medium_pot_colored-6
rule75=0,100,harvestcraft:pamrhubarbCrop-7
rule76=0,100,ExtrabiomesXL:flower3-1
rule77=0,100,GardenTrees:thin_log-1
rule78=0,100,ExtrabiomesXL:flower1-1
rule79=0,100,harvestcraft:pamsoybeanCrop-2
rule80=0,100,harvestcraft:pamasparagusCrop-4
rule81=0,100,ExtrabiomesXL:tile.extrabiomes.crop.strawberry-2
rule82=1,100,StandingSign:null:Soy Beans:null:null-12
rule83=1,100,StandingSign:null:Tomatoes:null:null-12
rule84=1,100,StandingSign:null:Lettuce:null:null-12
rule85=1,100,StandingSign:null:Asparagus:null:null-12
rule86=1,100,StandingSign:null:Eggplant:null:null-12
rule87=1,100,StandingSign:null:Rhubarb:null:null-12
rule88=1,100,StandingSign:null:Strawberries:null:null-12
rule89=0,100,GardenTrees:thin_log-0
rule90=0,100,minecraft:double_plant-8
rule91=0,100,GardenStuff:light_chain-4
rule92=0,100,minecraft:wooden_door-8
rule93=2,100,WallSign:null:Green Beans:null:null-5
rule94=0,100,BiomesOPlenty:darkStairs-2
rule95=0,100,BiomesOPlenty:darkStairs-7
rule96=0,100,BiomesOPlenty:darkStairs-6
rule97=0,100,BiomesOPlenty:darkStairs-3
rule98=0,100,chisel:torch5-1
rule99=0,100,BiomesOPlenty:leaves3-2
rule100=0,100,BiomesOPlenty:leaves3-3
rule101=0,100,BiomesOPlenty:leaves3-1
rule102=0,100,BiomesOPlenty:darkStairs-4
rule103=0,100,BiomesOPlenty:darkStairs-5
rule104=0,100,BiomesOPlenty:woodenSingleSlab1-2

layer
2,2,1,2,1,1,2,1,2,2,1,1,1,2,1,1,2,1,2,1
1,2,2,2,2,2,2,2,2,2,1,2,2,1,2,2,1,2,1,2
1,1,2,2,2,2,2,2,1,2,2,2,2,2,1,2,2,2,2,1
2,2,2,3,3,3,3,3,2,2,2,2,2,2,2,2,2,2,2,1
1,2,2,3,3,3,3,3,2,4,4,4,4,4,4,4,4,4,2,2
2,1,6,3,3,3,3,3,2,4,5,4,4,4,5,4,4,4,1,2
2,2,6,3,3,3,3,3,2,4,4,4,4,4,4,4,4,4,2,1
2,2,6,3,3,3,3,3,2,4,4,4,4,4,4,4,4,4,2,2
1,2,2,6,6,3,6,6,2,4,4,4,4,4,4,4,4,4,1,1
2,2,2,6,2,8,7,2,2,4,5,4,4,4,5,4,4,4,2,2
1,2,2,2,8,7,8,2,2,4,4,4,4,4,4,4,4,4,1,2
1,2,2,2,9,2,2,2,2,4,4,4,4,4,4,4,4,4,2,1
2,2,2,2,2,7,2,2,2,4,4,4,4,4,4,4,4,4,2,2
1,2,2,2,2,9,8,2,2,4,5,4,4,4,5,4,4,4,2,1
2,2,2,2,8,2,9,2,2,4,4,4,4,4,4,4,4,4,1,2
1,2,2,2,2,2,7,2,2,4,4,4,4,4,4,4,4,4,2,1
2,2,2,2,2,9,2,2,2,4,4,4,4,4,4,4,4,4,2,2
1,2,2,2,2,8,9,2,2,4,5,4,4,4,5,4,4,4,2,1
2,2,2,2,7,2,2,9,2,4,4,4,4,4,4,4,4,4,1,1
1,2,2,2,2,7,7,8,2,2,2,2,2,2,2,2,2,2,2,2
1,2,2,2,2,2,9,2,1,7,1,9,8,2,7,1,9,1,9,1
2,2,1,1,2,1,2,9,1,1,2,1,1,1,2,1,2,2,1,1
endlayer

layer
10,10,10,10,10,10,10,10,10,10,10,10,10,10,10,10,10,10,10,10
10,12,12,11,12,12,11,12,12,12,0,12,11,0,0,11,0,11,0,10
10,0,11,16,15,11,14,13,0,0,12,12,11,12,0,12,12,12,11,10
10,12,16,19,19,19,19,19,11,17,11,11,11,11,18,11,11,17,12,10
10,12,0,19,16,23,22,19,11,21,21,21,21,21,21,21,21,20,11,10
10,0,31,19,16,0,31,19,0,30,26,29,28,27,26,25,24,21,0,10
10,11,31,19,16,0,39,19,0,38,37,36,35,27,34,33,32,21,12,10
10,12,31,19,45,0,44,19,0,43,37,36,42,27,34,33,41,40,11,10
10,11,11,19,19,51,50,19,49,30,37,36,48,27,34,47,46,20,0,10
10,12,0,31,55,0,23,16,0,30,26,29,54,53,26,52,46,20,11,10
10,11,12,11,0,0,0,11,11,59,37,36,58,57,34,47,56,21,0,10
10,0,11,11,0,11,11,11,11,30,37,62,54,61,60,47,32,21,11,10
10,11,65,12,11,0,11,11,11,38,37,29,54,64,63,52,41,21,11,10
10,11,69,12,11,0,0,11,11,38,26,68,42,67,26,25,41,21,66,10
10,11,0,11,0,11,0,11,0,30,37,70,28,53,34,52,32,21,0,10
10,0,74,12,12,12,0,0,0,30,37,62,73,27,72,71,32,21,12,10
10,11,77,76,12,0,11,11,11,30,37,75,28,27,63,47,24,21,11,10
10,11,49,11,0,0,0,11,11,81,26,70,28,80,26,33,79,21,78,10
10,11,12,11,0,0,12,0,11,38,37,29,28,27,63,47,56,20,0,10
10,16,11,11,11,0,0,0,12,88,84,87,86,85,84,83,82,17,11,10
10,12,89,49,12,11,0,11,0,0,0,0,0,11,0,0,0,0,0,10
10,10,10,10,10,10,11,0,10,10,10,10,10,10,10,10,10,10,10,10
endlayer

layer
0,0,0,0,0,0,0,0,0,0,0,0,0,0,0,0,0,0,0,0
0,90,90,0,90,90,0,90,90,90,0,90,0,0,0,0,0,0,0,0
0,0,0,0,0,0,0,0,0,0,90,90,0,90,0,90,90,90,0,0
0,90,0,19,19,17,19,19,0,17,0,0,0,0,0,0,0,17,90,0
0,90,0,19,16,0,31,19,0,91,91,91,91,91,91,91,91,91,0,0
0,0,0,17,0,0,31,17,0,0,0,0,0,0,0,0,0,91,0,0
0,0,0,17,0,0,0,17,0,0,0,0,0,0,0,0,0,91,90,0
0,90,0,19,0,0,44,50,0,0,0,0,0,0,0,0,0,91,0,0
0,0,0,19,19,92,19,19,0,0,0,0,0,0,0,0,0,91,0,0
0,90,0,31,0,0,0,0,0,0,0,0,0,0,0,0,0,91,0,0
0,0,90,0,0,0,0,0,0,0,0,0,0,0,0,0,0,91,0,0
0,0,0,0,0,0,0,0,0,0,0,0,0,0,0,0,0,91,0,0
0,0,65,90,0,0,0,0,0,0,0,0,0,0,0,0,0,91,0,0
0,0,0,90,0,0,0,0,0,0,0,0,0,0,0,0,0,91,0,0
0,0,0,0,0,0,0,0,0,0,0,0,0,0,0,0,0,91,0,0
0,0,0,90,90,90,0,0,0,0,0,0,0,0,0,0,0,91,90,0
0,0,77,0,90,0,0,0,0,0,0,0,0,0,0,0,0,91,0,0
0,0,0,0,0,0,0,0,0,0,0,0,0,0,0,0,0,91,0,0
0,0,90,0,0,0,90,0,0,0,0,0,0,0,0,0,0,91,0,0
0,0,0,0,0,0,0,0,90,0,0,0,0,0,0,0,0,17,0,0
0,90,89,0,90,0,0,0,0,0,0,0,0,0,0,0,0,93,0,0
0,0,0,0,0,10,0,0,10,0,0,0,0,0,0,0,0,0,0,0
endlayer

layer
0,0,0,0,0,0,0,0,0,0,0,0,0,0,0,0,0,0,0,0
0,0,0,0,0,0,0,0,0,0,0,0,0,0,0,0,0,0,0,0
0,0,97,96,0,0,0,95,94,0,0,0,0,0,0,0,0,0,0,0
0,0,97,19,19,17,19,19,94,17,0,0,0,0,0,0,0,17,0,0
0,0,97,19,45,0,31,19,94,17,17,17,17,17,17,17,17,17,0,0
0,0,97,19,0,0,39,19,94,0,0,0,0,0,0,0,0,17,0,0
0,0,97,19,0,0,0,19,94,0,0,0,0,0,0,0,0,17,0,0
0,0,97,19,0,0,44,19,94,0,0,0,0,0,0,0,0,17,0,0
0,0,97,19,19,19,19,19,94,0,0,0,0,0,0,0,0,17,0,0
0,0,97,96,0,98,0,95,94,0,0,0,0,0,0,0,0,17,0,0
0,0,0,0,0,0,0,0,0,0,0,0,0,0,0,0,0,17,0,0
0,0,99,0,0,0,0,0,0,0,0,0,0,0,0,0,0,17,0,0
0,99,65,99,0,0,0,0,0,0,0,0,0,0,0,0,0,17,0,0
0,0,99,0,0,0,0,0,0,0,0,0,0,0,0,0,0,17,0,0
0,0,0,0,0,0,0,0,0,0,0,0,0,0,0,0,0,17,0,0
0,0,100,0,0,0,0,0,0,0,0,0,0,0,0,0,0,17,0,0
0,100,77,100,0,0,0,0,0,0,0,0,0,0,0,0,0,17,0,0
0,0,100,0,0,0,0,0,0,0,0,0,0,0,0,0,0,17,0,0
0,0,0,0,0,0,0,0,0,0,0,0,0,0,0,0,0,17,0,0
0,0,101,0,0,0,0,0,0,0,0,0,0,0,0,0,0,17,0,0
0,101,89,101,0,0,0,0,0,0,0,0,0,0,0,0,0,0,0,0
0,0,101,0,0,17,17,17,17,0,0,0,0,0,0,0,0,0,0,0
endlayer

layer
0,0,0,0,0,0,0,0,0,0,0,0,0,0,0,0,0,0,0,0
0,0,0,0,0,0,0,0,0,0,0,0,0,0,0,0,0,0,0,0
0,0,0,97,96,0,95,94,0,0,0,0,0,0,0,0,0,0,0,0
0,0,0,97,19,19,19,94,0,0,0,0,0,0,0,0,0,0,0,0
0,0,0,97,17,17,17,94,0,0,0,0,0,0,0,0,0,0,0,0
0,0,0,97,17,17,17,94,0,0,0,0,0,0,0,0,0,0,0,0
0,0,0,97,17,17,17,94,0,0,0,0,0,0,0,0,0,0,0,0
0,0,0,97,17,17,17,94,0,0,0,0,0,0,0,0,0,0,0,0
0,0,0,97,19,17,19,94,0,0,0,0,0,0,0,0,0,0,0,0
0,0,0,97,96,0,95,94,0,0,0,0,0,0,0,0,0,0,0,0
0,0,0,0,0,0,0,0,0,0,0,0,0,0,0,0,0,0,0,0
0,99,99,99,0,0,0,0,0,0,0,0,0,0,0,0,0,0,0,0
0,99,65,99,0,0,0,0,0,0,0,0,0,0,0,0,0,0,0,0
0,99,99,99,0,0,0,0,0,0,0,0,0,0,0,0,0,0,0,0
0,0,0,0,0,0,0,0,0,0,0,0,0,0,0,0,0,0,0,0
0,100,100,100,0,0,0,0,0,0,0,0,0,0,0,0,0,0,0,0
0,100,77,100,0,0,0,0,0,0,0,0,0,0,0,0,0,0,0,0
0,100,100,100,0,0,0,0,0,0,0,0,0,0,0,0,0,0,0,0
0,0,0,0,0,0,0,0,0,0,0,0,0,0,0,0,0,0,0,0
0,101,101,101,0,0,0,0,0,0,0,0,0,0,0,0,0,0,0,0
0,101,89,101,0,0,0,0,0,0,0,0,0,0,0,0,0,0,0,0
0,101,101,101,0,0,0,0,0,0,0,0,0,0,0,0,0,0,0,0
endlayer

layer
0,0,0,0,0,0,0,0,0,0,0,0,0,0,0,0,0,0,0,0
0,0,0,0,0,0,0,0,0,0,0,0,0,0,0,0,0,0,0,0
0,0,0,0,97,102,94,0,0,0,0,0,0,0,0,0,0,0,0,0
0,0,0,0,97,19,94,0,0,0,0,0,0,0,0,0,0,0,0,0
0,0,0,0,97,0,94,0,0,0,0,0,0,0,0,0,0,0,0,0
0,0,0,0,97,45,94,0,0,0,0,0,0,0,0,0,0,0,0,0
0,0,0,0,97,0,94,0,0,0,0,0,0,0,0,0,0,0,0,0
0,0,0,0,97,39,94,0,0,0,0,0,0,0,0,0,0,0,0,0
0,0,0,0,97,19,94,0,0,0,0,0,0,0,0,0,0,0,0,0
0,0,0,0,97,103,94,0,0,0,0,0,0,0,0,0,0,0,0,0
0,0,0,0,0,0,0,0,0,0,0,0,0,0,0,0,0,0,0,0
0,0,99,0,0,0,0,0,0,0,0,0,0,0,0,0,0,0,0,0
0,99,99,99,0,0,0,0,0,0,0,0,0,0,0,0,0,0,0,0
0,0,99,0,0,0,0,0,0,0,0,0,0,0,0,0,0,0,0,0
0,0,0,0,0,0,0,0,0,0,0,0,0,0,0,0,0,0,0,0
0,0,100,0,0,0,0,0,0,0,0,0,0,0,0,0,0,0,0,0
0,100,100,100,0,0,0,0,0,0,0,0,0,0,0,0,0,0,0,0
0,0,100,0,0,0,0,0,0,0,0,0,0,0,0,0,0,0,0,0
0,0,0,0,0,0,0,0,0,0,0,0,0,0,0,0,0,0,0,0
0,0,101,0,0,0,0,0,0,0,0,0,0,0,0,0,0,0,0,0
0,101,101,101,0,0,0,0,0,0,0,0,0,0,0,0,0,0,0,0
0,0,101,0,0,0,0,0,0,0,0,0,0,0,0,0,0,0,0,0
endlayer

layer
0,0,0,0,0,0,0,0,0,0,0,0,0,0,0,0,0,0,0,0
0,0,0,0,0,0,0,0,0,0,0,0,0,0,0,0,0,0,0,0
0,0,0,0,0,104,0,0,0,0,0,0,0,0,0,0,0,0,0,0
0,0,0,0,0,104,0,0,0,0,0,0,0,0,0,0,0,0,0,0
0,0,0,0,0,104,0,0,0,0,0,0,0,0,0,0,0,0,0,0
0,0,0,0,0,104,0,0,0,0,0,0,0,0,0,0,0,0,0,0
0,0,0,0,0,104,0,0,0,0,0,0,0,0,0,0,0,0,0,0
0,0,0,0,0,104,0,0,0,0,0,0,0,0,0,0,0,0,0,0
0,0,0,0,0,104,0,0,0,0,0,0,0,0,0,0,0,0,0,0
0,0,0,0,0,104,0,0,0,0,0,0,0,0,0,0,0,0,0,0
0,0,0,0,0,0,0,0,0,0,0,0,0,0,0,0,0,0,0,0
0,0,0,0,0,0,0,0,0,0,0,0,0,0,0,0,0,0,0,0
0,0,99,0,0,0,0,0,0,0,0,0,0,0,0,0,0,0,0,0
0,0,0,0,0,0,0,0,0,0,0,0,0,0,0,0,0,0,0,0
0,0,0,0,0,0,0,0,0,0,0,0,0,0,0,0,0,0,0,0
0,0,0,0,0,0,0,0,0,0,0,0,0,0,0,0,0,0,0,0
0,0,100,0,0,0,0,0,0,0,0,0,0,0,0,0,0,0,0,0
0,0,0,0,0,0,0,0,0,0,0,0,0,0,0,0,0,0,0,0
0,0,0,0,0,0,0,0,0,0,0,0,0,0,0,0,0,0,0,0
0,0,0,0,0,0,0,0,0,0,0,0,0,0,0,0,0,0,0,0
0,0,101,0,0,0,0,0,0,0,0,0,0,0,0,0,0,0,0,0
0,0,0,0,0,0,0,0,0,0,0,0,0,0,0,0,0,0,0,0
endlayer

