
# Created by Ruins mod version 15.0 Ingame Parser
# authoring Player: SunsOfOld

weight=1
embed_into_distance=5
acceptable_target_blocks=
unacceptable_target_blocks=flowing_water,water,flowing_lava,lava
dimensions=33,13,12
allowable_overhang=0
max_leveling=4
leveling_buffer=0
preserve_water=0
preserve_lava=0
uniqueMinDistance=1000000
preventRotation=1

rule1=0,100,preserveBlock
rule2=0,100,UndergroundBiomes:metamorphicCobblestone-1
rule3=0,100,MobSpawner:CaveSpider
rule4=0,100,minecraft:fence-0
rule5=0,100,minecraft:web-0
rule6=0,100,minecraft:bookshelf-0
rule7=0,100,IInventory;minecraft:chest;harvestcraft:pamnutmegSapling#1#0#0+harvestcraft:pampaperbarkSapling#1#0#1+harvestcraft:pamdurianSapling#1#0#2+harvestcraft:pampeachSapling#1#0#3+harvestcraft:pamlimeSapling#1#0#4+harvestcraft:pamdateSapling#1#0#5+harvestcraft:pamcherrySapling#1#0#6+harvestcraft:pamplumSapling#1#0#7+harvestcraft:pamfigSapling#1#0#8+harvestcraft:pampersimmonSapling#1#0#9+harvestcraft:pammapleSapling#1#0#10+harvestcraft:pamavocadoSapling#1#0#11+harvestcraft:pamlemonSapling#1#0#12+harvestcraft:pamalmondSapling#1#0#13+harvestcraft:pamvanillabeanSapling#1#0#14+harvestcraft:pampomegranateSapling#1#0#15+harvestcraft:pampapayaSapling#1#0#16+harvestcraft:pamstarfruitSapling#1#0#17+harvestcraft:pamcashewSapling#1#0#18+harvestcraft:pampeppercornSapling#1#0#19+harvestcraft:pamdragonfruitSapling#1#0#20+harvestcraft:pamorangeSapling#1#0#21+harvestcraft:pamapricotSapling#1#0#22+harvestcraft:pampistachioSapling#1#0#23+harvestcraft:pambananaSapling#1#0#24+harvestcraft:pampecanSapling#1#0#25+harvestcraft:pamgrapefruitSapling#1#0#26-5
rule8=0,100,IInventory;minecraft:chest;harvestcraft:pamcoconutSapling#1#0#0+harvestcraft:pamcinnamonSapling#1#0#1+harvestcraft:pampearSapling#1#0#2+harvestcraft:pamoliveSapling#1#0#3+harvestcraft:pamappleSapling#1#0#4+harvestcraft:pamappleSapling#1#0#5+harvestcraft:pamchestnutSapling#1#0#6+harvestcraft:pampistachioSapling#1#0#7+harvestcraft:pammangoSapling#1#0#8+GardenCore:compost_bin#1#0#9+minecraft:iron_shovel#1#0#10+GardenCore:compost_bin#1#0#11+minecraft:iron_shovel#1#0#12+GardenCore:compost_bin#1#0#13+minecraft:iron_shovel#1#0#14+GardenCore:compost_bin#1#0#15+minecraft:iron_shovel#1#0#16+GardenCore:compost_bin#1#0#17+minecraft:iron_shovel#1#0#18+GardenCore:compost_bin#1#0#19+minecraft:iron_shovel#1#0#20+GardenCore:compost_bin#1#0#21+minecraft:iron_shovel#1#0#22+GardenCore:compost_bin#1#0#23+minecraft:iron_shovel#1#0#24+GardenCore:compost_bin#1#0#25+minecraft:iron_shovel#1#0#26-5
rule9=0,100,minecraft:bed-10
rule10=0,100,minecraft:bed-2
rule11=0,100,minecraft:log-0
rule12=0,100,IInventory;minecraft:chest;minecraft:cooked_porkchop#3#0#0+minecraft:cooked_porkchop#3#0#1+minecraft:cooked_porkchop#3#0#2+minecraft:cooked_porkchop#4#0#3+minecraft:cooked_porkchop#2#0#4+minecraft:cooked_porkchop#3#0#5+minecraft:cooked_porkchop#3#0#6+minecraft:cooked_porkchop#3#0#7+minecraft:cooked_porkchop#2#0#8+minecraft:cooked_porkchop#2#0#9+minecraft:cooked_porkchop#2#0#10+minecraft:cooked_porkchop#2#0#11+minecraft:cooked_porkchop#2#0#12+harvestcraft:maplesyrupItem#16#0#13+minecraft:cooked_porkchop#2#0#14+minecraft:cooked_porkchop#2#0#15+minecraft:cooked_porkchop#2#0#16+minecraft:cooked_porkchop#2#0#17+minecraft:cooked_porkchop#2#0#18+minecraft:cooked_porkchop#3#0#19+minecraft:cooked_porkchop#3#0#20+minecraft:cooked_porkchop#3#0#21+harvestcraft:apiary#1#0#22+minecraft:cooked_porkchop#3#0#23+minecraft:cooked_porkchop#3#0#24+minecraft:cooked_porkchop#3#0#25+minecraft:cooked_porkchop#2#0#26-3
rule13=0,100,minecraft:anvil-1
rule14=0,100,IInventory;minecraft:chest;harvestcraft:almondItem#1#0#0+harvestcraft:almondItem#1#0#1+harvestcraft:almondItem#1#0#2+harvestcraft:almondItem#1#0#3+harvestcraft:almondItem#1#0#4+harvestcraft:almondItem#1#0#5+harvestcraft:almondItem#1#0#6+harvestcraft:almondItem#1#0#7+harvestcraft:almondItem#1#0#8+harvestcraft:chestnutItem#5#0#9+harvestcraft:chestnutItem#5#0#10+harvestcraft:chestnutItem#6#0#11+harvestcraft:almondItem#7#0#12+antiqueatlas:emptyAntiqueAtlas#1#0#13+harvestcraft:almondItem#7#0#14+harvestcraft:chestnutItem#6#0#15+harvestcraft:chestnutItem#5#0#16+harvestcraft:chestnutItem#5#0#17+harvestcraft:almondItem#1#0#18+harvestcraft:almondItem#1#0#19+harvestcraft:almondItem#1#0#20+harvestcraft:almondItem#1#0#21+harvestcraft:almondItem#1#0#22+harvestcraft:almondItem#1#0#23+harvestcraft:almondItem#1#0#24+harvestcraft:almondItem#1#0#25+harvestcraft:almondItem#1#0#26-3
rule15=0,100,minecraft:crafting_table-0
rule16=0,100,minecraft:furnace-4
rule17=2,100,minecraft:torch-1
rule18=0,100,minecraft:wooden_pressure_plate-0
rule19=0,100,IInventory;minecraft:chest;ExtrabiomesXL:saplings_2#1#4#0+minecraft:sapling#1#2#1+minecraft:sapling#1#0#2+harvestcraft:animaltrap#1#0#3+Backpack:backpack#{backpack-UID:"f8665de2-8631-4195-bf15-b85b5fab4b95",name:"item.backpack.big_green.name",}#203#4+harvestcraft:animaltrap#1#0#5+ExtrabiomesXL:saplings_1#1#2#6+ExtrabiomesXL:saplings_1#1#1#7+dendrology:sapling0#1#2#8+dendrology:sapling0#1#0#9+dendrology:sapling0#1#7#10+dendrology:sapling0#1#3#11+dendrology:sapling0#1#6#12+dendrology:sapling0#1#1#13+dendrology:sapling0#1#5#14+ExtrabiomesXL:saplings_1#1#3#15+ExtrabiomesXL:saplings_2#1#2#16+ExtrabiomesXL:saplings_2#1#1#17+minecraft:sapling#1#1#18+ExtrabiomesXL:saplings_1#1#6#19+ExtrabiomesXL:saplings_1#1#7#20+ExtrabiomesXL:saplings_2#1#0#21+ExtrabiomesXL:saplings_2#1#0#22+dendrology:sapling0#1#4#23+dendrology:sapling1#1#3#24+dendrology:sapling1#1#1#25+dendrology:sapling1#1#2#26-5
rule20=0,100,IInventory;minecraft:chest;ExtrabiomesXL:saplings_1#1#5#0+minecraft:sapling#1#4#1+dendrology:sapling1#1#0#2+ExtrabiomesXL:saplings_2#1#0#3+ExtrabiomesXL:saplings_2#1#0#4+minecraft:sapling#1#5#5+minecraft:sapling#1#5#6+minecraft:sapling#1#5#7+minecraft:sapling#1#5#8+ExtrabiomesXL:saplings_1#1#5#9+ExtrabiomesXL:saplings_1#1#5#10+ExtrabiomesXL:saplings_1#1#5#11+ExtrabiomesXL:saplings_1#1#4#12+ExtrabiomesXL:saplings_1#1#4#13+ExtrabiomesXL:saplings_1#1#4#14+ExtrabiomesXL:saplings_1#1#4#15+ExtrabiomesXL:saplings_1#1#4#16+ExtrabiomesXL:saplings_1#1#4#17+minecraft:sapling#1#3#18+minecraft:sapling#1#3#19+minecraft:sapling#1#3#20+minecraft:sapling#1#3#21+minecraft:sapling#1#3#22+ExtrabiomesXL:saplings_2#1#3#23+ExtrabiomesXL:saplings_2#1#3#24+ExtrabiomesXL:saplings_2#1#3#26-5
rule21=0,100,minecraft:ladder-5
rule22=0,100,harvestcraft:cuttingboard-0
rule23=0,100,minecraft:dirt-7
rule24=0,100,minecraft:dirt-0
rule25=0,100,minecraft:leaves-12
rule26=0,100,minecraft:wooden_door-0
rule27=0,100,minecraft:planks-0
rule28=0,100,minecraft:trapdoor-3
rule29=0,100,IInventory;GardenCore:compost_bin;GardenCore:compost_pile#24#0#9-0
rule30=0,100,minecraft:oak_stairs-2
rule31=0,100,minecraft:leaves-4
rule32=2,100,WallSign:null:Elzeard:Bouffier:null-4
rule33=0,100,minecraft:wooden_door-8
rule34=0,100,minecraft:flower_pot-1
rule35=0,100,minecraft:leaves-0
rule36=0,100,harvestcraft:beehive-0
rule37=0,100,minecraft:log-4
rule38=0,100,minecraft:log-8
rule39=0,100,minecraft:vine-1

layer
1,1,1,1,1,1,1,1,1,1,1,1
1,1,1,1,1,1,1,1,1,1,1,1
1,1,2,2,2,2,2,2,2,2,1,1
1,1,2,2,2,2,2,2,2,2,1,1
1,1,2,2,2,2,2,2,2,2,1,1
1,1,2,2,2,2,2,2,2,2,1,1
1,1,2,2,2,2,2,2,2,2,1,1
1,1,2,2,2,2,2,2,2,2,1,1
1,1,2,2,2,2,2,2,2,2,1,1
1,1,2,2,2,2,2,2,2,2,1,1
1,1,2,2,2,3,2,2,2,2,1,1
1,1,1,1,1,1,1,1,1,1,1,1
1,1,1,1,1,1,1,1,1,1,1,1
endlayer

layer
1,1,1,1,1,1,1,1,1,1,1,1
1,1,1,1,1,1,1,1,1,1,1,1
1,1,2,2,2,2,2,2,2,2,1,1
1,1,2,8,7,6,5,5,4,2,1,1
1,1,2,5,5,11,0,10,9,2,1,1
1,1,2,0,0,0,0,0,12,2,1,1
1,1,2,0,0,0,0,5,13,2,1,1
1,1,2,5,0,0,0,0,14,2,1,1
1,1,2,4,5,0,5,5,4,2,1,1
1,1,2,4,4,16,15,4,4,2,1,1
1,1,2,2,2,2,2,2,2,2,1,1
1,1,1,1,1,1,1,1,1,1,1,1
1,1,1,1,1,1,1,1,1,1,1,1
endlayer

layer
1,1,1,1,1,1,1,1,1,1,1,1
1,1,1,1,1,1,17,1,1,1,1,1
1,1,2,2,2,2,2,2,2,2,1,1
1,1,2,20,19,6,5,5,18,2,1,1
1,1,2,5,5,11,0,0,5,2,1,1
1,1,2,5,0,21,0,0,5,2,1,1
1,1,2,0,0,0,0,0,5,2,1,1
1,1,2,0,0,0,0,0,5,2,1,1
1,1,2,18,0,5,0,0,18,2,1,1
1,1,2,18,18,5,22,18,18,2,1,1
1,1,2,2,2,2,2,2,2,2,1,1
1,1,1,1,1,1,1,1,1,1,1,1
1,1,1,1,1,1,1,1,1,1,1,1
endlayer

layer
1,1,1,1,1,1,1,1,1,1,1,1
1,1,1,1,1,1,1,1,1,1,1,1
1,1,2,2,2,2,2,2,2,2,1,1
1,1,2,5,5,6,5,0,5,2,1,1
1,1,2,5,5,11,5,5,5,2,1,1
1,1,2,5,0,21,0,0,5,2,1,1
1,1,2,0,0,0,0,0,5,2,1,1
1,1,2,5,0,0,0,0,5,2,1,1
1,1,2,0,0,5,0,0,5,2,1,1
1,1,2,5,0,0,5,0,5,2,1,1
1,1,2,2,2,2,2,2,2,2,1,1
1,1,1,1,1,1,1,1,1,1,1,1
1,1,1,1,1,1,1,1,1,1,1,1
endlayer

layer
1,1,1,1,1,1,1,1,1,1,1,1
1,1,1,1,1,1,1,1,1,1,1,1
1,1,1,24,1,1,1,1,23,1,1,1
1,1,1,2,2,2,2,2,2,1,1,1
1,1,1,2,2,2,2,2,2,1,1,1
1,1,1,2,2,5,2,2,2,1,1,1
1,1,24,2,2,2,2,2,2,1,1,1
1,1,1,2,2,2,2,2,2,23,1,1
1,1,1,2,2,2,2,2,2,1,1,1
1,1,1,2,2,2,2,2,2,1,1,1
1,1,1,1,1,24,1,1,1,1,1,1
1,1,1,1,1,1,1,1,1,1,1,1
1,1,1,1,1,1,1,1,1,1,1,1
endlayer

layer
0,0,0,0,0,0,0,0,0,0,0,0
0,0,0,0,0,0,0,0,0,0,0,0
0,0,0,11,0,0,0,0,11,0,0,0
0,0,0,0,0,0,0,5,25,0,0,0
0,0,0,5,11,27,26,11,0,0,0,0
0,0,0,0,27,28,0,27,0,0,0,0
0,0,11,29,27,0,0,27,0,0,0,0
0,0,0,25,27,30,4,27,0,11,0,0
0,0,0,5,11,27,27,11,25,0,0,0
0,0,0,0,0,0,0,31,25,25,0,0
0,0,0,0,0,11,0,0,25,0,0,0
0,0,0,0,0,0,0,0,0,0,0,0
0,0,0,0,0,0,0,0,0,0,0,0
endlayer

layer
0,0,0,0,0,0,0,0,0,0,0,0
0,0,0,0,0,0,0,0,0,0,0,0
0,0,0,11,0,0,0,0,11,31,0,0
0,0,0,0,31,32,5,25,31,0,0,0
0,0,0,31,11,27,33,11,31,0,0,0
0,0,0,0,27,0,0,27,0,0,0,0
0,31,11,0,5,0,0,34,0,31,0,0
0,0,0,0,27,0,18,27,0,11,25,0
0,0,31,35,11,27,27,11,31,25,0,0
0,0,0,35,35,35,35,35,5,0,0,0
0,0,0,35,35,11,35,35,0,25,0,0
0,0,0,35,35,35,35,35,0,0,0,0
0,0,0,35,35,35,35,35,0,0,0,0
endlayer

layer
0,0,0,0,0,0,0,0,0,0,0,0
0,0,0,31,0,0,0,0,31,0,0,0
0,0,31,11,31,0,0,25,11,25,0,0
0,0,31,5,31,25,25,25,25,0,0,0
0,35,35,35,11,27,27,11,5,0,0,0
35,35,35,35,27,5,5,27,35,35,35,0
35,35,11,35,27,0,0,27,35,35,35,35
35,35,35,35,27,5,5,27,35,11,35,35
35,35,35,35,11,27,27,11,35,35,36,35
0,0,0,35,35,35,35,35,35,35,35,0
0,0,0,35,35,11,35,35,0,0,0,0
0,0,0,35,35,35,35,35,0,0,0,0
0,0,0,35,35,35,35,0,0,0,0,0
endlayer

layer
0,0,35,35,35,0,35,35,35,35,0,0
0,35,35,35,35,35,35,35,35,35,35,0
0,35,35,11,35,35,35,35,11,35,35,0
0,35,35,35,35,35,35,35,35,36,35,0
0,35,35,35,11,11,11,11,35,35,0,0
35,35,35,35,11,37,37,11,35,35,35,0
35,35,11,35,11,37,37,11,35,35,35,35
35,35,35,35,11,37,37,11,35,11,35,35
35,35,36,35,11,11,11,11,35,35,35,35
0,0,0,5,35,35,5,0,36,35,35,35
0,0,0,0,35,11,35,0,0,0,0,0
0,0,0,0,35,35,35,0,0,0,0,0
0,0,0,0,0,0,0,0,0,0,0,0
endlayer

layer
0,35,35,35,35,0,35,35,35,35,0,0
0,35,35,35,35,35,35,35,35,35,35,0
0,35,35,11,35,35,35,35,11,35,35,0
0,35,35,35,35,35,35,35,35,35,35,0
0,35,35,35,11,0,0,11,35,35,35,0
0,0,35,0,0,11,11,0,0,0,0,0
0,35,11,35,35,11,11,35,35,35,0,0
0,35,35,35,35,11,11,35,35,11,35,0
0,0,35,35,11,35,35,11,35,35,35,0
0,0,35,35,35,35,35,35,35,35,0,0
0,0,35,35,35,35,35,35,35,35,0,0
0,0,0,0,0,35,0,0,0,0,0,0
0,0,0,0,0,0,0,0,0,0,0,0
endlayer

layer
0,0,0,0,0,0,0,0,0,0,0,0
0,0,0,35,0,0,0,0,35,0,0,0
0,0,35,11,35,35,35,35,11,35,0,0
0,0,35,35,35,35,35,35,35,35,0,0
0,0,35,35,11,35,35,11,0,0,0,0
0,0,35,35,35,35,35,0,0,0,0,0
0,35,35,35,35,35,35,35,35,35,0,0
0,0,35,35,35,35,35,35,35,35,35,0
0,0,35,35,11,35,35,11,35,35,0,0
0,0,35,35,35,35,35,35,35,35,0,0
0,0,0,35,35,35,35,35,35,35,0,0
0,0,0,0,0,0,0,0,0,0,0,0
0,0,0,0,0,0,0,0,0,0,0,0
endlayer

layer
0,0,0,0,0,0,0,0,0,0,0,0
0,0,0,35,0,0,0,0,35,0,0,0
0,0,35,35,35,35,0,35,35,35,0,0
0,0,35,35,35,35,35,0,35,35,35,0
0,0,35,35,11,35,35,11,0,35,0,0
0,0,35,35,35,35,35,0,0,0,0,0
0,0,35,35,35,35,35,0,0,0,0,0
0,0,0,35,35,35,0,35,35,0,0,0
0,0,0,35,11,35,35,11,35,0,0,0
0,0,0,0,35,35,0,35,0,0,0,0
0,0,0,0,0,0,0,0,0,0,0,0
0,0,0,0,0,0,0,0,0,0,0,0
0,0,0,0,0,0,0,0,0,0,0,0
endlayer

layer
0,0,0,0,0,0,35,0,0,0,0,0
0,0,0,0,0,35,35,35,35,35,35,0
0,0,0,0,0,0,35,35,35,35,35,35
0,0,0,35,35,35,35,35,35,35,35,35
0,0,0,35,11,35,38,11,35,35,35,35
0,0,0,35,35,38,37,35,35,35,35,0
0,0,0,35,35,35,35,35,0,0,0,0
0,0,0,35,35,35,35,35,0,0,0,0
0,0,0,35,35,35,35,35,35,0,0,0
0,0,0,0,35,0,0,35,0,0,0,0
0,0,0,0,0,0,0,0,0,0,0,0
0,0,0,0,0,0,0,0,0,0,0,0
0,0,0,0,0,0,0,0,0,0,0,0
endlayer

layer
0,0,0,0,35,35,35,35,35,0,0,0
0,0,0,0,35,35,35,35,35,35,35,0
0,0,0,0,35,35,35,35,35,35,35,35
0,0,0,0,35,35,35,35,35,35,35,35
0,0,0,35,35,35,35,11,35,35,35,35
0,0,0,35,35,35,35,35,37,38,35,0
0,0,0,35,38,35,35,35,0,35,0,0
0,0,0,35,35,35,35,35,0,0,0,0
0,0,0,0,35,35,35,0,0,0,0,0
0,0,0,0,0,0,0,0,0,0,0,0
0,0,0,0,0,0,0,0,0,0,0,0
0,0,0,0,0,0,0,0,0,0,0,0
0,0,0,0,0,0,0,0,0,0,0,0
endlayer

layer
0,0,0,0,35,35,35,35,35,0,0,0
0,0,0,0,35,35,35,35,35,0,0,0
0,0,0,0,35,35,35,35,35,36,0,0
0,0,0,0,35,35,35,35,37,38,35,0
0,0,0,35,35,35,35,11,38,35,35,35
0,0,35,35,35,35,35,37,35,35,35,35
0,0,35,35,35,35,35,35,37,35,35,35
0,0,35,35,35,35,35,0,35,35,35,0
0,0,0,35,35,35,0,0,0,0,0,0
0,0,0,0,0,0,0,0,0,0,0,0
0,0,0,0,0,0,0,0,0,0,0,0
0,0,0,0,0,0,0,0,0,0,0,0
0,0,0,0,0,0,0,0,0,0,0,0
endlayer

layer
0,0,0,0,0,0,35,0,0,0,0,0
0,0,0,0,0,35,35,35,35,35,35,0
0,0,0,0,0,35,35,35,35,37,35,35
0,0,0,0,36,38,35,35,35,35,35,35
0,0,0,35,35,35,38,11,38,35,35,35
0,0,35,35,35,35,35,35,35,38,35,35
0,0,35,35,35,35,35,35,35,35,35,35
0,0,35,35,35,35,35,35,35,35,35,0
0,0,0,35,35,35,0,35,35,35,0,0
0,0,0,0,0,0,0,0,0,0,0,0
0,0,0,0,0,0,0,0,0,0,0,0
0,0,0,0,0,0,0,0,0,0,0,0
0,0,0,0,0,0,0,0,0,0,0,0
endlayer

layer
0,0,0,0,0,0,0,0,35,35,35,0
0,0,0,0,35,35,35,35,35,35,35,35
0,0,0,35,35,35,35,35,35,35,35,35
0,0,0,35,35,35,35,35,35,35,35,35
0,0,0,35,35,35,35,11,38,38,35,35
0,0,0,0,35,35,35,35,35,35,38,35
0,0,0,35,35,35,35,35,35,35,35,0
0,0,0,0,35,0,35,35,35,35,35,0
0,0,0,0,0,0,0,35,35,35,0,0
0,0,0,0,0,0,0,0,0,0,0,0
0,0,0,0,0,0,0,0,0,0,0,0
0,0,0,0,0,0,0,0,0,0,0,0
0,0,0,0,0,0,0,0,0,0,0,0
endlayer

layer
0,0,0,0,0,0,0,0,35,35,35,0
0,0,0,0,35,35,35,35,35,35,35,35
0,0,0,35,35,35,35,35,35,35,35,35
0,0,0,35,35,35,35,35,35,35,35,35
0,0,0,35,35,35,35,11,35,35,35,35
0,0,0,0,35,35,35,35,35,35,35,35
0,0,0,0,0,0,0,35,35,35,35,35
0,0,0,0,0,0,0,0,35,35,35,35
0,0,0,0,0,0,0,0,0,0,0,0
0,0,0,0,0,0,0,0,0,0,0,0
0,0,0,0,0,0,0,0,0,0,0,0
0,0,0,0,0,0,0,0,0,0,0,0
0,0,0,0,0,0,0,0,0,0,0,0
endlayer

layer
0,0,0,0,0,0,0,0,0,0,0,0
0,0,0,0,0,0,0,0,0,35,0,0
0,0,0,0,0,35,35,35,35,35,35,0
0,0,0,0,35,35,35,35,35,35,35,35
0,0,0,0,0,35,35,35,35,35,35,35
0,0,0,0,0,35,35,35,35,35,35,35
0,0,0,0,0,0,35,35,35,35,35,35
0,0,0,0,0,0,0,0,0,0,35,0
0,0,0,0,0,0,0,0,0,0,0,0
0,0,0,0,0,0,0,0,0,0,0,0
0,0,0,0,0,0,0,0,0,0,0,0
0,0,0,0,0,0,0,0,0,0,0,0
0,0,0,0,0,0,0,0,0,0,0,0
endlayer

layer
0,0,0,0,0,0,0,0,0,0,0,0
0,0,0,0,0,0,0,0,0,0,0,0
0,0,0,0,0,0,35,35,35,0,0,0
0,0,0,0,0,35,35,35,35,35,0,0
0,0,0,0,0,35,35,35,35,35,35,0
0,0,0,0,0,35,35,35,35,35,35,35
0,0,0,0,0,0,35,35,0,0,0,0
0,0,0,0,0,0,0,0,0,0,0,0
0,0,0,0,0,0,0,0,0,0,0,0
0,0,0,0,0,0,0,0,0,0,0,0
0,0,0,0,0,0,0,0,0,0,0,0
0,0,0,0,0,0,0,0,0,0,0,0
0,0,0,0,0,0,0,0,0,0,0,0
endlayer

layer
0,0,0,0,0,0,0,0,0,0,0,0
0,0,0,0,0,0,0,0,0,0,0,0
0,0,0,0,0,0,0,0,0,0,0,0
0,0,0,0,0,0,0,35,0,0,0,0
0,0,0,0,0,0,35,35,35,0,0,0
0,0,0,0,0,0,0,35,0,0,0,0
0,0,0,0,0,0,0,0,0,0,0,0
0,0,0,0,0,0,0,0,0,0,0,0
0,0,0,0,0,0,0,0,0,0,0,0
0,0,0,0,0,0,0,0,0,0,0,0
0,0,0,0,0,0,0,0,0,0,0,0
0,0,0,0,0,0,0,0,0,0,0,0
0,0,0,0,0,0,0,0,0,0,0,0
endlayer

layer
0,0,0,0,0,0,0,0,0,0,0,0
0,0,0,0,0,0,0,0,0,0,0,0
0,0,0,0,0,0,0,0,0,0,0,0
0,0,0,0,0,0,0,0,0,0,0,0
0,0,0,0,0,0,0,0,0,0,0,0
0,0,0,0,0,0,0,0,0,0,0,0
0,0,0,0,0,0,0,0,0,0,0,0
0,0,0,0,0,0,0,0,0,0,0,0
0,0,0,0,0,0,0,0,0,0,0,0
0,0,0,0,0,0,0,0,0,0,0,0
0,0,0,0,0,0,0,0,0,0,0,0
0,0,0,0,0,0,0,0,0,0,0,0
0,0,0,0,0,0,0,0,0,0,0,0
endlayer

layer
0,0,0,0,0,0,0,0,0,0,0,0
0,0,0,0,0,0,0,0,0,0,0,0
0,0,0,0,0,0,0,0,0,0,0,0
0,0,0,0,0,0,0,0,0,0,0,0
0,0,0,0,0,0,0,0,0,0,0,0
0,0,0,0,0,0,0,0,0,0,0,0
0,0,0,0,0,0,0,0,0,0,0,0
0,0,0,0,0,0,0,0,0,0,0,0
0,0,0,0,0,0,0,0,0,0,0,0
0,0,0,0,0,0,0,0,0,0,0,0
0,0,0,0,0,0,0,0,0,0,0,0
0,0,0,0,0,0,0,0,0,0,0,0
0,0,0,0,0,0,0,0,0,0,0,0
endlayer

layer
0,0,0,0,0,0,0,0,0,0,0,0
0,0,0,0,0,0,0,0,0,0,0,0
0,0,0,0,0,0,0,0,0,0,0,0
0,0,0,0,0,0,0,0,0,0,0,0
0,0,0,0,0,0,0,0,0,0,0,0
0,0,0,0,0,0,0,0,0,0,0,0
0,0,0,0,0,0,0,0,0,0,0,0
0,0,0,0,0,0,0,0,0,0,0,0
0,0,0,0,0,0,0,0,0,0,0,0
0,0,0,0,0,0,0,0,0,0,0,0
0,0,0,0,0,0,0,0,0,0,0,0
0,0,0,0,0,0,0,0,0,0,0,0
0,0,0,0,0,0,0,0,0,0,0,0
endlayer

layer
0,0,0,0,0,0,0,0,0,0,0,0
0,0,0,0,0,0,0,0,0,0,0,0
0,0,0,0,0,0,0,0,0,0,0,0
0,0,0,0,0,0,0,0,0,0,0,0
0,0,0,0,0,0,0,0,0,0,0,0
0,0,0,0,0,0,0,0,0,0,0,0
0,0,0,0,0,0,0,0,0,0,0,0
0,0,0,0,0,0,0,0,0,0,0,0
0,0,0,0,0,0,0,0,0,0,0,0
0,0,0,0,0,0,0,0,0,0,0,0
0,0,0,0,0,0,0,0,0,0,0,0
0,0,0,0,0,0,0,0,0,0,0,0
0,0,0,0,0,0,0,0,0,0,0,0
endlayer

layer
0,0,0,0,0,0,0,0,0,0,0,0
0,0,0,0,0,0,0,0,0,0,0,0
0,0,0,0,0,0,0,0,0,0,0,0
0,0,0,0,0,0,0,0,0,0,0,0
0,0,0,0,0,0,0,0,0,0,0,0
0,0,0,0,0,0,0,0,0,0,0,0
0,0,0,0,0,0,0,0,0,0,0,0
0,0,0,0,0,0,0,0,0,0,0,0
0,0,0,0,0,0,0,0,0,0,0,0
0,0,0,0,0,0,0,0,0,0,0,0
0,0,0,0,0,0,0,0,0,0,0,0
0,0,0,0,0,0,0,0,0,0,0,0
0,0,0,0,0,0,0,0,0,0,0,0
endlayer

layer
0,0,0,0,0,0,0,0,0,0,0,0
0,0,0,0,0,0,0,0,0,0,0,0
0,0,0,0,0,0,0,0,0,0,0,0
0,0,0,0,0,0,0,0,0,0,0,0
0,0,0,0,0,0,0,0,0,0,0,0
0,0,0,0,0,0,0,0,0,0,0,0
0,0,0,0,0,0,0,0,0,0,0,0
0,0,0,0,0,0,0,0,0,0,0,0
0,0,0,0,0,0,0,0,0,0,0,0
0,0,0,0,0,0,0,0,0,0,0,0
0,0,0,0,0,0,0,0,0,0,0,0
0,0,0,0,0,0,0,0,0,0,0,0
0,0,0,0,0,0,0,0,0,0,0,0
endlayer

layer
0,0,0,0,0,0,0,0,0,0,0,0
0,0,0,0,0,0,0,0,0,0,0,0
0,0,0,0,0,0,0,0,0,0,0,0
0,0,0,0,0,0,0,0,0,0,0,0
0,0,0,0,0,0,0,0,0,0,0,0
0,0,0,0,0,0,0,0,0,0,0,0
0,0,0,0,0,0,0,0,0,0,0,0
0,0,0,0,0,0,0,0,0,0,0,0
0,0,0,0,0,0,0,0,0,0,0,0
0,0,0,0,0,0,0,0,0,0,0,0
0,0,0,0,0,0,0,0,0,0,0,0
0,0,0,0,0,0,0,0,0,0,0,0
0,0,0,0,0,0,0,0,0,0,0,0
endlayer

layer
0,0,0,0,0,0,0,0,0,0,0,0
0,0,0,0,0,0,0,0,0,0,0,0
0,0,0,0,0,0,0,0,0,0,0,0
0,0,0,0,0,0,0,0,0,0,0,0
0,0,0,0,0,0,0,0,0,0,0,0
0,0,0,0,0,0,0,0,0,0,0,0
0,0,0,0,0,0,0,0,0,0,0,0
0,0,0,0,0,0,0,0,0,0,0,0
0,0,0,0,0,0,0,0,0,0,0,0
0,0,0,0,0,0,0,0,0,0,0,0
0,0,0,0,0,0,0,0,0,0,0,0
0,0,0,0,0,0,0,0,0,0,0,0
0,0,0,0,0,0,0,0,0,0,0,0
endlayer

layer
0,0,0,0,0,0,0,0,0,0,0,0
0,0,0,0,0,0,0,0,0,0,0,0
0,0,0,0,0,0,0,0,0,0,0,0
0,0,0,0,0,0,0,0,0,0,0,0
0,0,0,0,0,0,0,0,0,0,0,0
0,0,0,0,0,0,0,0,0,0,0,0
0,0,0,0,0,0,0,0,0,0,0,0
0,0,0,0,0,0,0,0,0,0,0,0
0,0,0,0,0,0,0,0,0,0,0,0
0,0,0,0,0,0,0,0,0,0,0,0
0,0,0,0,0,0,0,0,0,0,0,0
0,0,0,0,0,0,0,0,0,0,0,0
0,0,0,0,0,0,0,0,0,0,0,0
endlayer

layer
0,0,0,0,0,0,0,0,0,0,0,0
0,0,0,0,0,0,0,0,0,0,0,0
0,0,0,0,0,0,0,0,0,0,0,0
0,0,0,0,0,0,0,0,0,0,0,0
0,0,0,0,0,0,0,0,0,0,0,0
0,0,0,0,0,0,0,0,0,0,0,0
0,0,0,0,0,0,0,0,0,0,0,0
0,0,0,0,0,0,0,0,0,0,0,0
0,0,0,0,0,0,0,0,0,0,0,0
0,0,0,0,0,0,0,0,0,0,0,0
0,0,0,0,0,0,0,0,0,0,0,0
0,0,0,0,0,0,0,0,0,0,0,0
0,0,0,0,0,0,0,0,0,0,0,0
endlayer

layer
0,0,0,0,0,0,0,0,0,0,0,0
0,0,0,0,0,0,0,0,0,0,0,0
0,0,0,0,0,0,0,0,0,0,0,0
0,0,0,0,0,0,0,0,0,0,0,0
0,0,0,0,0,0,0,0,0,0,0,0
0,0,0,0,0,0,0,0,0,0,0,0
0,0,0,0,0,0,0,0,0,0,0,0
0,0,0,0,0,0,0,0,0,0,0,0
0,0,0,0,0,0,0,0,0,0,0,0
0,0,0,0,0,0,0,0,0,0,0,0
0,0,0,0,0,0,0,0,0,0,0,0
0,0,0,0,0,0,0,0,0,0,0,0
0,0,0,0,0,0,0,0,0,0,0,0
endlayer

layer
0,0,0,0,0,0,0,0,0,0,0,0
0,0,0,0,0,0,0,0,0,0,0,0
0,0,0,0,0,0,0,0,0,0,0,0
0,0,0,0,0,0,0,0,0,0,0,0
0,0,0,0,0,0,0,0,0,0,0,0
0,0,0,0,0,0,0,0,0,0,0,0
0,0,0,0,0,0,0,0,0,0,0,0
0,0,0,0,0,0,0,0,0,0,0,0
0,0,0,0,0,0,0,0,0,0,0,0
0,0,0,0,0,0,0,0,0,0,0,0
0,0,0,0,0,0,0,0,0,0,0,0
0,0,0,0,0,0,0,0,0,0,0,0
0,0,0,0,0,0,0,0,0,0,0,0
endlayer

