
# Created by Ruins mod version 15.0 Ingame Parser
# authoring Player: SunsOfOld

weight=100
embed_into_distance=2
acceptable_target_blocks=
unacceptable_target_blocks=flowing_water,water,flowing_lava,lava
dimensions=4,11,13
allowable_overhang=0
max_leveling=4
leveling_buffer=0
preserve_water=0
preserve_lava=0
uniqueMinDistance=1000000
preventRotation=1

rule1=0,100,preserveBlock
rule2=0,100,minecraft:water-0
rule3=0,100,BiomesOPlenty:mud-0
rule4=0,100,harvestcraft:pamriceCrop-7

layer
1,1,1,1,1,1,1,1,1,1,1,1,1
1,1,1,1,1,1,1,1,1,1,1,1,1
1,1,1,1,1,1,1,1,1,1,1,1,1
1,1,1,1,1,1,1,1,1,1,1,1,1
1,1,1,1,1,1,1,1,1,1,1,1,1
1,1,1,1,1,1,1,1,1,1,1,1,1
1,1,1,1,1,1,1,1,1,1,1,1,1
1,1,1,1,1,1,1,1,1,1,1,1,1
1,1,1,1,1,1,1,1,1,1,1,1,1
1,1,1,1,1,1,1,1,1,1,1,1,1
1,1,1,1,1,1,1,1,1,1,1,1,1
endlayer

layer
1,1,1,1,1,1,1,1,1,1,1,1,0
1,1,1,1,1,1,1,1,1,1,1,1,1
1,1,1,1,1,1,1,2,2,2,2,1,1
1,1,1,1,1,1,1,2,2,2,2,1,1
1,1,1,1,1,1,1,2,2,2,2,1,1
1,1,1,1,1,1,1,2,2,2,2,1,1
1,1,1,1,1,1,1,2,2,2,2,1,0
1,1,1,1,1,1,1,2,2,2,2,1,1
1,1,1,1,1,1,1,2,2,2,2,1,0
1,1,1,1,1,1,1,1,1,1,1,1,0
1,1,1,1,1,1,1,1,1,1,1,1,0
endlayer

layer
0,0,3,0,3,3,0,3,3,0,0,0,0
0,3,3,3,3,3,3,3,0,0,3,0,0
3,3,2,2,2,2,3,4,4,4,4,3,0
3,3,2,2,2,2,3,4,4,4,4,0,0
0,3,2,2,2,2,3,4,4,4,4,0,0
3,3,2,2,2,2,3,4,4,4,4,0,0
0,3,2,2,2,2,3,4,4,4,4,0,0
0,3,2,2,2,2,3,4,4,4,4,0,0
3,3,2,2,2,2,3,4,4,4,4,0,0
3,3,3,3,3,3,3,3,0,0,0,3,0
0,3,3,3,3,0,0,0,0,0,3,0,0
endlayer

layer
0,0,0,0,0,0,0,0,0,0,0,0,0
0,0,3,0,0,0,0,0,0,0,0,0,0
0,3,4,4,4,4,0,0,0,0,0,0,0
0,0,4,4,4,4,0,0,0,0,0,0,0
0,0,4,4,4,4,0,0,0,0,0,0,0
0,0,4,4,4,4,0,0,0,0,0,0,0
0,0,4,4,4,4,0,0,0,0,0,0,0
0,0,4,4,4,4,0,0,0,0,0,0,0
0,3,4,4,4,4,0,0,0,0,0,0,0
0,0,3,3,3,0,0,0,0,0,0,0,0
0,0,0,3,0,0,0,0,0,0,0,0,0
endlayer

