
# Created by Ruins mod version 15.0 Ingame Parser
# authoring Player: SunsOfOld

weight=100
embed_into_distance=5
acceptable_target_blocks=
unacceptable_target_blocks=flowing_water,water,flowing_lava,lava,sand
dimensions=20,8,16
allowable_overhang=0
max_leveling=4
leveling_buffer=0
preserve_water=0
preserve_lava=0
uniqueMinDistance=1000000
preventRotation=1

rule1=0,100,preserveBlock
rule2=0,100,minecraft:grass-0
rule3=0,100,minecraft:dirt-0
rule4=0,100,minecraft:clay-0
rule5=0,100,minecraft:sand-0
rule6=0,100,minecraft:water-0
rule7=0,100,minecraft:stone-0
rule8=0,100,BiomesOPlenty:woodenSingleSlab2-10
rule9=0,100,BiomesOPlenty:planks-11
rule10=0,100,minecraft:double_plant-2
rule11=0,100,minecraft:tallgrass-1
rule12=0,100,GardenTrees:thin_log-0
rule13=0,100,IInventory;minecraft:chest;minecraft:speckled_melon#1#0#0+minecraft:potion#1#8269#1+minecraft:potion#1#8269#2+minecraft:fishing_rod#{RepairCost:4,ench:[0:{id:62s,lvl:3s,},1:{id:34s,lvl:3s,},],}#0#3+harvestcraft:snapperrawItem#1#0#4+minecraft:fish#2#0#5+minecraft:fish#1#1#6+harvestcraft:catfishrawItem#2#0#7+harvestcraft:eelrawItem#1#0#8+harvestcraft:anchovyrawItem#3#0#9+harvestcraft:jellyfishrawItem#2#0#10+harvestcraft:walleyerawItem#1#0#11+harvestcraft:grouperrawItem#1#0#12+harvestcraft:octopusrawItem#1#0#13-3
rule14=0,100,BiomesOPlenty:logs4-0
rule15=0,100,minecraft:rail-0
rule16=0,100,minecraft:double_plant-8
rule17=0,100,chisel:torch6-5
rule18=0,100,BiomesOPlenty:woodenSingleSlab2-2
rule19=0,100,BiomesOPlenty:colorizedLeaves2-1

layer
1,1,1,1,1,1,1,1,1,1,1,1,1,1,1,1
1,1,1,1,1,1,1,1,1,1,1,1,1,1,1,1
1,1,1,1,1,1,1,1,1,1,1,1,1,1,1,1
1,1,1,1,1,1,1,1,1,1,1,1,1,1,1,1
1,1,1,1,1,1,1,1,1,1,1,1,1,1,1,1
1,1,1,1,1,1,1,1,1,1,1,1,1,1,1,1
1,1,1,1,1,1,1,1,1,1,1,1,1,1,1,1
1,1,1,1,1,1,1,1,1,1,1,1,1,1,1,1
endlayer

layer
1,1,1,1,1,1,1,1,1,1,1,1,1,1,1,1
1,1,1,1,1,1,1,1,1,1,1,1,1,1,1,1
1,1,1,1,1,1,1,1,1,1,1,1,1,1,1,1
1,1,1,1,1,1,1,1,1,1,1,1,1,1,1,1
1,1,1,1,1,1,1,1,1,1,1,1,1,1,1,1
1,1,1,1,1,1,1,1,1,1,1,1,1,1,1,1
1,1,1,1,1,1,1,1,1,1,1,1,1,1,1,1
1,1,1,1,1,1,1,1,1,1,1,1,1,1,1,1
endlayer

layer
1,1,1,1,1,1,1,1,1,1,1,1,1,1,1,1
1,1,1,1,1,1,1,1,1,1,1,1,1,1,1,1
1,1,4,4,3,2,1,1,1,1,1,1,1,1,1,1
1,4,4,5,5,5,2,1,1,1,1,1,1,1,1,1
1,1,1,4,5,5,1,1,1,1,1,1,1,1,1,1
1,1,1,1,1,1,1,1,1,1,1,1,1,1,1,1
1,1,1,1,1,1,1,1,1,1,1,1,1,1,1,1
1,1,1,1,1,1,1,1,1,1,1,1,1,1,1,1
endlayer

layer
1,1,1,1,1,1,1,1,1,1,1,1,1,1,1,1
1,1,3,5,5,2,1,1,1,3,3,1,1,1,1,1
1,5,6,6,6,6,2,1,1,1,1,3,3,1,1,1
1,3,6,6,6,6,6,5,2,1,1,1,3,1,1,3
3,3,2,6,6,6,5,2,1,1,1,1,1,1,3,1
3,3,3,3,3,3,3,3,1,1,1,1,3,3,1,1
1,1,1,1,1,1,1,1,1,1,1,1,1,1,1,1
1,1,1,1,1,1,1,1,1,1,1,1,1,1,1,1
endlayer

layer
2,2,2,1,1,1,1,2,2,1,1,1,1,7,1,1
1,5,6,6,6,6,5,2,2,2,2,1,1,1,1,1
1,6,6,6,6,6,6,5,2,2,2,2,2,7,7,1
2,6,6,6,6,6,6,6,8,8,8,2,2,1,1,1
2,2,6,6,6,6,6,6,5,2,2,2,1,3,2,1
2,2,2,2,2,2,2,7,7,1,1,1,1,1,1,1
9,9,9,9,9,9,9,9,9,9,9,9,9,9,9,9
1,1,2,1,1,1,2,1,2,2,1,1,2,1,1,1
endlayer

layer
11,11,11,0,0,0,0,11,10,0,0,0,0,0,0,0
0,0,0,0,0,0,0,0,11,11,11,0,0,7,7,0
0,0,0,0,0,0,0,0,0,12,11,12,11,0,0,0
11,0,0,0,0,0,0,0,0,0,0,13,12,0,0,0
11,11,0,0,0,0,0,0,0,12,0,12,0,14,0,0
11,11,10,11,11,11,11,12,0,0,0,0,0,0,0,0
15,15,0,0,15,15,15,0,15,15,15,15,15,0,15,15
0,0,0,0,0,0,0,0,0,0,0,0,0,0,0,0
endlayer

layer
0,0,0,0,0,0,0,0,16,0,0,0,0,0,0,0
0,0,0,0,0,0,0,0,0,0,0,0,0,7,0,0
0,0,0,0,0,0,0,0,0,12,12,12,0,0,0,0
0,0,0,0,0,0,0,0,0,0,0,12,17,0,0,0
0,0,0,0,0,0,0,0,0,12,12,12,0,14,0,0
0,0,16,0,0,0,0,17,0,0,0,0,0,0,0,0
0,0,0,0,0,0,0,0,0,0,0,0,0,0,0,0
0,0,0,0,0,0,0,0,0,0,0,0,0,0,0,0
endlayer

layer
0,0,0,0,0,0,0,0,0,0,0,0,0,0,0,0
0,0,0,0,0,0,0,0,0,0,0,0,0,0,0,0
0,0,0,0,0,0,0,0,0,12,0,18,0,0,0,0
0,0,0,0,0,0,0,0,0,0,8,18,0,0,0,0
0,0,0,0,0,0,0,0,0,12,8,18,0,14,0,0
0,0,0,0,0,0,0,0,0,0,0,0,0,0,0,0
0,0,0,0,0,0,0,0,0,0,0,0,0,0,0,0
0,0,0,0,0,0,0,0,0,0,0,0,0,0,0,0
endlayer

layer
0,0,0,0,0,0,0,0,0,0,0,0,0,0,0,0
0,0,0,0,0,0,0,0,0,0,0,0,0,0,0,0
0,0,0,0,0,0,0,0,0,18,0,0,0,0,0,0
0,0,0,0,0,0,0,0,0,18,0,0,0,0,0,0
0,0,0,0,0,0,0,0,0,18,0,0,0,14,0,0
0,0,0,0,0,0,0,0,0,0,0,0,0,0,0,0
0,0,0,0,0,0,0,0,0,0,0,0,0,0,0,0
0,0,0,0,0,0,0,0,0,0,0,0,0,0,0,0
endlayer

layer
0,0,0,0,0,0,0,0,0,0,0,0,0,0,0,0
0,0,0,0,0,0,0,0,0,0,0,0,0,0,0,0
0,0,0,0,0,0,0,0,0,0,0,0,0,0,0,19
0,0,0,0,0,0,0,0,0,0,0,0,0,0,0,0
0,0,0,0,0,0,0,0,0,0,0,0,0,14,0,0
0,0,0,0,0,0,0,0,0,0,0,0,0,0,0,0
0,0,0,0,0,0,0,0,0,0,0,0,0,0,0,0
0,0,0,0,0,0,0,0,0,0,0,0,0,0,0,0
endlayer

layer
0,0,0,0,0,0,0,0,0,0,0,0,0,0,0,0
0,0,0,0,0,0,0,0,0,0,0,0,0,0,0,0
0,0,0,0,0,0,0,0,0,0,0,0,0,0,19,0
0,0,0,0,0,0,0,0,0,0,0,0,0,0,0,19
0,0,0,0,0,0,0,0,0,0,0,0,0,14,0,0
0,0,0,0,0,0,0,0,0,0,0,0,0,0,0,0
0,0,0,0,0,0,0,0,0,0,0,0,0,0,0,0
0,0,0,0,0,0,0,0,0,0,0,0,0,0,0,0
endlayer

layer
0,0,0,0,0,0,0,0,0,0,0,0,0,0,0,0
0,0,0,0,0,0,0,0,0,0,0,0,0,0,0,0
0,0,0,0,0,0,0,0,0,0,0,0,0,0,0,0
0,0,0,0,0,0,0,0,0,0,0,0,19,19,19,0
0,0,0,0,0,0,0,0,0,0,0,0,19,14,19,0
0,0,0,0,0,0,0,0,0,0,0,19,19,19,19,0
0,0,0,0,0,0,0,0,0,0,0,19,19,0,0,0
0,0,0,0,0,0,0,0,0,0,0,0,0,0,0,0
endlayer

layer
0,0,0,0,0,0,0,0,0,0,0,0,0,0,0,0
0,0,0,0,0,0,0,0,0,0,0,0,0,0,0,0
0,0,0,0,0,0,0,0,0,0,0,19,19,0,0,0
0,0,0,0,0,0,0,0,0,0,0,19,0,0,0,0
0,0,0,0,0,0,0,0,0,0,0,0,0,14,0,0
0,0,0,0,0,0,0,0,0,0,0,0,0,0,0,0
0,0,0,0,0,0,0,0,0,0,0,0,0,0,0,0
0,0,0,0,0,0,0,0,0,0,0,0,0,0,0,0
endlayer

layer
0,0,0,0,0,0,0,0,0,0,0,0,0,0,0,0
0,0,0,0,0,0,0,0,0,0,0,0,0,0,0,0
0,0,0,0,0,0,0,0,0,0,0,0,0,0,0,19
0,0,0,0,0,0,0,0,0,0,0,0,19,19,19,0
0,0,0,0,0,0,0,0,0,0,0,0,19,14,19,0
0,0,0,0,0,0,0,0,0,0,0,0,19,19,19,19
0,0,0,0,0,0,0,0,0,0,0,19,0,0,19,19
0,0,0,0,0,0,0,0,0,0,0,0,0,0,0,0
endlayer

layer
0,0,0,0,0,0,0,0,0,0,0,0,0,0,0,0
0,0,0,0,0,0,0,0,0,0,0,0,0,0,0,0
0,0,0,0,0,0,0,0,0,0,0,0,0,0,19,0
0,0,0,0,0,0,0,0,0,0,0,0,0,0,0,19
0,0,0,0,0,0,0,0,0,0,0,0,0,14,0,0
0,0,0,0,0,0,0,0,0,0,0,19,0,0,0,0
0,0,0,0,0,0,0,0,0,0,0,0,19,0,0,0
0,0,0,0,0,0,0,0,0,0,0,0,0,0,0,0
endlayer

layer
0,0,0,0,0,0,0,0,0,0,0,0,0,0,0,0
0,0,0,0,0,0,0,0,0,0,0,0,0,0,0,0
0,0,0,0,0,0,0,0,0,0,0,0,0,0,0,0
0,0,0,0,0,0,0,0,0,0,0,0,19,19,19,0
0,0,0,0,0,0,0,0,0,0,0,0,19,14,19,0
0,0,0,0,0,0,0,0,0,0,0,0,19,19,19,0
0,0,0,0,0,0,0,0,0,0,0,0,0,0,0,0
0,0,0,0,0,0,0,0,0,0,0,0,0,0,0,0
endlayer

layer
0,0,0,0,0,0,0,0,0,0,0,0,0,0,0,0
0,0,0,0,0,0,0,0,0,0,0,0,0,0,0,0
0,0,0,0,0,0,0,0,0,0,0,0,0,0,0,0
0,0,0,0,0,0,0,0,0,0,0,0,0,0,0,0
0,0,0,0,0,0,0,0,0,0,0,0,0,14,0,0
0,0,0,0,0,0,0,0,0,0,0,0,0,0,0,0
0,0,0,0,0,0,0,0,0,0,0,0,0,0,0,0
0,0,0,0,0,0,0,0,0,0,0,0,0,0,0,0
endlayer

layer
0,0,0,0,0,0,0,0,0,0,0,0,0,0,0,0
0,0,0,0,0,0,0,0,0,0,0,0,0,0,0,0
0,0,0,0,0,0,0,0,0,0,0,0,0,0,0,0
0,0,0,0,0,0,0,0,0,0,0,0,19,19,19,0
0,0,0,0,0,0,0,0,0,0,0,0,19,14,19,0
0,0,0,0,0,0,0,0,0,0,0,0,19,19,19,0
0,0,0,0,0,0,0,0,0,0,0,0,0,0,0,0
0,0,0,0,0,0,0,0,0,0,0,0,0,0,0,0
endlayer

layer
0,0,0,0,0,0,0,0,0,0,0,0,0,0,0,0
0,0,0,0,0,0,0,0,0,0,0,0,0,0,0,0
0,0,0,0,0,0,0,0,0,0,0,0,0,0,0,0
0,0,0,0,0,0,0,0,0,0,0,0,0,19,0,0
0,0,0,0,0,0,0,0,0,0,0,0,19,0,19,0
0,0,0,0,0,0,0,0,0,0,0,0,0,19,0,0
0,0,0,0,0,0,0,0,0,0,0,0,0,0,0,0
0,0,0,0,0,0,0,0,0,0,0,0,0,0,0,0
endlayer

layer
0,0,0,0,0,0,0,0,0,0,0,0,0,0,0,0
0,0,0,0,0,0,0,0,0,0,0,0,0,0,0,0
0,0,0,0,0,0,0,0,0,0,0,0,0,0,0,0
0,0,0,0,0,0,0,0,0,0,0,0,0,0,0,0
0,0,0,0,0,0,0,0,0,0,0,0,0,19,0,0
0,0,0,0,0,0,0,0,0,0,0,0,0,0,0,0
0,0,0,0,0,0,0,0,0,0,0,0,0,0,0,0
0,0,0,0,0,0,0,0,0,0,0,0,0,0,0,0
endlayer

