
# Created by Ruins mod version 14.9 Ingame Parser
# authoring Player: SunsOfOld

weight=100
embed_into_distance=1
acceptable_target_blocks=
unacceptable_target_blocks=flowing_water,water,flowing_lava,lava
dimensions=13,10,10
allowable_overhang=0
max_leveling=3
leveling_buffer=0
preserve_water=0
preserve_lava=0
uniqueMinDistance=1000000
preventRotation=1

rule1=0,100,BiomesOPlenty:newBopDirt-0
rule2=0,100,preserveBlock
rule3=0,100,dendrology:sslab0-5
rule4=0,100,BiomesOPlenty:mud-0
rule5=0,100,BiomesOPlenty:newBopDirt-1
rule6=0,100,GardenStuff:moss_brick-2
rule7=0,100,GardenStuff:moss_brick-0
rule8=0,100,IInventory;minecraft:dispenser;harvestcraft:freshwaterItem#32#0#0+harvestcraft:freshwaterItem#32#0#1+harvestcraft:freshwaterItem#32#0#2+harvestcraft:freshwaterItem#32#0#3+harvestcraft:sink#1#3#4+harvestcraft:freshwaterItem#32#0#5+harvestcraft:freshwaterItem#32#0#6+harvestcraft:freshwaterItem#32#0#7+harvestcraft:freshwaterItem#32#0#8-1
rule9=0,100,GardenStuff:moss_brick-1
rule10=0,100,dendrology:dslab0-5
rule11=0,100,BiomesOPlenty:foliage-11
rule12=0,100,plantmegapack:wetlandsCattails-0
rule13=0,100,plantmegapack:vineSilverveinCreeper-12
rule14=0,100,dendrology:leaves2-15
rule15=0,100,plantmegapack:vineSilverveinCreeper-9
rule16=0,100,minecraft:water-0
rule17=0,100,GardenStuff:moss_brick-6
rule18=0,100,plantmegapack:wetlandsClubrush-0
rule19=0,100,GardenStuff:moss_brick-4
rule20=0,100,dendrology:logs2-3
rule21=0,100,plantmegapack:vineSilverveinCreeper-1
rule22=0,100,BiomesOPlenty:colorizedLeaves2-12
rule23=0,100,plantmegapack:wetlandsReedMannagrass-0
rule24=0,100,plantmegapack:wetlandsCommonRush-0
rule25=0,100,plantmegapack:vineSilverveinCreeper-2
rule26=0,100,plantmegapack:vineSilverveinCreeper-8
rule27=0,100,plantmegapack:wetlandsFloweringRush-0
rule28=0,100,GardenStuff:lattice-3
rule29=0,100,plantmegapack:vineSilverveinCreeper-0
rule30=0,100,plantmegapack:vineSilverveinCreeper-4
rule31=0,100,dendrology:logs2-7
rule32=0,100,dendrology:leaves2-7
rule33=0,100,dendrology:logs2-11

layer
2,4,2,1,2,3,1,1,2,1
5,2,2,2,2,5,2,2,2,1
2,2,2,2,2,2,2,4,1,2
1,2,2,7,6,2,2,2,2,1
2,2,2,9,9,8,2,1,1,2
1,2,2,2,2,2,2,2,2,1
2,2,2,2,2,2,1,4,2,2
2,1,2,5,10,1,5,2,1,2
1,2,1,2,10,2,2,4,2,1
2,1,2,2,1,3,1,2,1,2
endlayer

layer
0,0,0,11,0,0,11,12,0,11
11,14,1,2,3,13,5,0,0,12
0,5,2,7,9,5,14,0,11,0
18,4,17,16,16,9,5,0,15,11
0,5,6,16,16,16,19,1,18,0
12,4,1,17,7,1,20,5,0,11
0,22,4,1,5,3,1,0,0,21
0,24,1,11,0,24,11,0,23,0
11,0,18,0,0,25,0,0,0,11
0,11,0,0,11,0,11,0,12,0
endlayer

layer
0,0,0,0,0,0,26,0,0,0
0,22,14,3,26,26,11,0,0,0
0,14,0,6,9,27,14,0,0,0
0,0,17,0,0,17,22,0,15,0
0,22,7,0,0,9,1,11,0,0
0,14,14,9,6,27,20,24,0,0
0,0,14,3,11,0,18,0,0,21
0,0,11,0,0,0,0,0,21,0
0,0,0,0,0,25,0,0,0,0
0,0,0,0,0,0,0,0,0,0
endlayer

layer
0,0,0,0,0,0,26,0,0,0
0,0,26,0,0,26,0,0,0,0
0,22,0,0,0,14,22,0,0,0
0,29,28,0,0,28,0,0,15,0
0,30,28,0,0,28,27,0,0,0
0,30,14,25,0,0,20,0,0,0
0,0,0,0,0,0,0,0,0,21
0,0,30,0,0,0,0,0,21,0
0,0,0,0,0,25,0,0,0,0
0,0,0,0,0,0,0,0,0,0
endlayer

layer
0,0,0,0,0,0,26,0,0,0
0,0,26,0,0,26,0,0,0,0
0,14,0,0,0,22,0,0,0,0
0,22,28,0,0,28,0,0,15,0
0,30,28,0,0,28,0,0,0,0
0,30,14,25,0,0,20,0,0,0
0,0,0,0,0,0,0,0,0,21
0,0,30,0,0,0,0,0,21,0
0,0,0,0,0,25,0,0,0,0
0,0,0,0,0,0,0,0,0,0
endlayer

layer
0,0,0,0,0,0,26,0,0,0
0,0,26,0,0,26,0,0,0,0
0,30,14,0,0,14,0,0,0,0
0,0,28,28,28,28,0,0,15,0
0,30,28,28,28,28,0,0,0,0
0,30,14,25,0,0,20,0,0,0
0,0,0,0,0,0,31,0,0,21
0,0,30,0,0,0,32,0,21,0
0,0,0,0,0,25,0,0,0,0
0,0,0,0,0,0,0,0,0,0
endlayer

layer
0,0,0,0,0,0,26,0,0,0
0,0,26,0,0,0,0,0,0,0
0,30,0,0,0,0,0,0,0,0
0,0,14,22,14,22,0,32,15,0
0,30,22,14,32,32,31,32,32,0
0,0,0,25,0,32,20,14,32,14
0,0,0,0,0,32,0,32,32,21
0,0,30,0,32,14,31,14,21,0
0,0,0,0,0,25,14,32,0,0
0,0,0,0,0,0,0,0,0,0
endlayer

layer
0,0,0,0,0,0,26,0,0,0
0,0,26,0,0,0,0,0,0,0
0,30,0,0,0,0,0,0,0,0
0,0,0,0,0,0,31,0,21,0
0,0,0,32,32,32,0,32,0,0
0,0,0,0,33,33,20,14,32,0
0,32,32,0,0,32,32,14,0,0
0,0,30,32,32,14,14,14,14,0
0,0,0,0,32,32,32,0,0,0
0,0,0,0,0,0,0,0,0,0
endlayer

layer
0,0,0,32,32,14,26,0,0,0
0,0,26,32,31,14,14,14,0,0
0,30,0,0,0,33,32,32,32,0
0,0,0,0,32,32,0,0,21,0
0,0,0,32,32,32,0,32,32,0
0,14,14,33,32,32,20,33,14,14
0,14,33,32,32,32,32,14,14,0
0,14,14,0,32,25,14,0,0,0
0,0,0,0,0,0,0,0,0,0
0,0,0,0,0,0,0,0,0,0
endlayer

layer
0,0,0,0,32,14,14,0,0,0
0,0,26,32,32,14,0,0,0,0
0,30,14,32,32,32,32,32,0,0
0,14,14,32,32,32,32,32,21,0
0,14,14,32,32,32,32,32,0,0
0,0,14,32,32,32,20,14,14,0
0,14,14,32,32,32,14,14,0,0
0,0,14,32,32,25,25,0,0,0
0,0,0,0,0,0,0,0,0,0
0,0,0,0,0,0,0,0,0,0
endlayer

layer
0,0,0,0,0,0,0,0,0,0
0,0,0,0,32,32,32,0,0,0
0,0,0,32,32,32,32,26,0,0
0,0,14,32,32,32,32,32,21,0
0,0,14,32,32,32,32,32,0,0
0,0,0,32,32,32,20,14,0,0
0,0,14,0,32,32,14,0,0,0
0,0,0,32,32,25,32,0,0,0
0,0,0,0,0,0,0,0,0,0
0,0,0,0,0,0,0,0,0,0
endlayer

layer
0,0,0,0,0,0,0,0,0,0
0,0,0,0,0,0,0,0,0,0
0,0,0,0,0,32,0,0,0,0
0,0,0,32,0,32,32,0,0,0
0,0,0,32,32,32,32,32,0,0
0,0,0,0,0,32,20,32,0,0
0,0,0,0,0,32,32,32,0,0
0,0,0,0,0,0,0,0,0,0
0,0,0,0,0,0,0,0,0,0
0,0,0,0,0,0,0,0,0,0
endlayer

layer
0,0,0,0,0,0,0,0,0,0
0,0,0,0,0,0,0,0,0,0
0,0,0,0,0,0,0,0,0,0
0,0,0,0,0,0,0,0,0,0
0,0,0,0,0,0,32,0,0,0
0,0,0,0,0,32,32,0,0,0
0,0,0,0,0,0,32,0,0,0
0,0,0,0,0,0,0,0,0,0
0,0,0,0,0,0,0,0,0,0
0,0,0,0,0,0,0,0,0,0
endlayer

