
# Created by Ruins mod version 15.0 Ingame Parser
# authoring Player: MillicentOak

weight=100
embed_into_distance=0
acceptable_target_blocks=
unacceptable_target_blocks=flowing_water,water,flowing_lava,lava
dimensions=38,13,13
allowable_overhang=0
max_leveling=4
leveling_buffer=0
preserve_water=0
preserve_lava=0
uniqueMinDistance=1000000
preventRotation=1

rule1=0,100,ExtrabiomesXL:stairs.cypress-0
rule2=0,100,ExtrabiomesXL:stairs.cypress-3
rule3=0,100,ExtrabiomesXL:stairs.cypress-2
rule4=0,100,ExtrabiomesXL:planks-3
rule5=0,100,ExtrabiomesXL:log1-2
rule6=0,100,ExtrabiomesXL:log1-10
rule7=0,100,ExtrabiomesXL:log1-6
rule8=0,100,minecraft:dirt-0
rule9=0,100,ExtrabiomesXL:planks-7
rule10=0,100,IInventory;CarpentersBlocks:blockCarpentersSafe;harvestcraft:turnipsoupItem#3#0#1+harvestcraft:beansandriceItem#1#0#3+harvestcraft:turnipsoupItem#2#0#6+harvestcraft:meatystewItem#2#0#11+harvestcraft:meatystewItem#1#0#14+harvestcraft:turnipsoupItem#2#0#17+harvestcraft:beansandriceItem#1#0#18+harvestcraft:turnipsoupItem#1#0#20+harvestcraft:beansandriceItem#2#0#23-6
rule11=0,100,ExtrabiomesXL:door_cypress-6
rule12=0,100,chisel:glass_pane-15
rule13=0,100,ExtrabiomesXL:woodslab-15
rule14=0,100,harvestcraft:pamcandleDeco9-2
rule15=0,100,ExtrabiomesXL:door_cypress-8
rule16=0,100,ExtrabiomesXL:woodslab-7
rule17=0,100,ExtrabiomesXL:stairs.cypress-4
rule18=0,100,ExtrabiomesXL:stairs.cypress-1
rule19=0,100,ExtrabiomesXL:woodslab-11
rule20=0,100,ExtrabiomesXL:stairs.baldcypress-4
rule21=0,100,ExtrabiomesXL:stairs.baldcypress-7
rule22=0,100,ExtrabiomesXL:stairs.baldcypress-6
rule23=0,100,ExtrabiomesXL:stairs.cypress-6
rule24=0,100,ExtrabiomesXL:stairs.cypress-7
rule25=0,100,ExtrabiomesXL:stairs.baldcypress-5
rule26=0,100,ExtrabiomesXL:stairs.cypress-5
rule27=0,100,ExtrabiomesXL:fence-3
rule28=0,100,harvestcraft:pamcandleDeco9-5
rule29=0,100,ExtrabiomesXL:woodslab-3
rule30=0,100,ExtrabiomesXL:stairs.baldcypress-2
rule31=0,100,ExtrabiomesXL:stairs.baldcypress-0
rule32=0,100,ExtrabiomesXL:stairs.baldcypress-3
rule33=0,100,ExtrabiomesXL:stairs.baldcypress-1
rule34=0,100,IInventory;CarpentersBlocks:blockCarpentersSafe;minecraft:arrow#3#0#0+minecraft:arrow#4#0#3+minecraft:arrow#2#0#5+minecraft:arrow#2#0#8+minecraft:arrow#2#0#11+minecraft:arrow#1#0#15+minecraft:arrow#1#0#18+minecraft:arrow#2#0#20+minecraft:arrow#2#0#23+minecraft:arrow#3#0#26-6

layer
0,0,0,0,0,0,0,0,0,0,0,0,0
0,0,0,0,0,0,0,0,0,0,0,0,0
0,0,0,0,2,1,1,1,1,0,0,0,0
0,0,0,0,2,4,4,4,3,0,0,0,0
0,0,0,0,5,6,6,6,5,0,0,0,0
0,0,0,0,7,8,8,8,7,0,0,0,0
0,0,0,0,7,8,8,8,7,0,0,0,0
0,0,0,0,7,8,8,8,7,0,0,0,0
0,0,0,0,5,6,6,6,5,0,0,0,0
0,0,0,0,0,0,0,0,0,0,0,0,0
0,0,0,0,0,0,0,0,0,0,0,0,0
0,0,0,0,0,0,0,0,0,0,0,0,0
0,0,0,0,0,0,0,0,0,0,0,0,0
endlayer

layer
0,0,0,0,0,0,0,0,0,0,0,0,0
0,0,0,0,0,0,0,0,0,0,0,0,0
0,0,0,0,0,0,0,0,0,0,0,0,0
0,0,0,0,0,2,1,3,0,0,0,0,0
0,0,0,0,5,6,6,6,5,0,0,0,0
0,0,0,0,9,9,4,9,9,0,0,0,0
0,0,0,0,4,4,4,4,4,0,0,0,0
0,0,0,0,9,9,4,10,9,0,0,0,0
0,0,0,0,5,9,4,9,5,0,0,0,0
0,0,0,0,0,0,0,0,0,0,0,0,0
0,0,0,0,0,0,0,0,0,0,0,0,0
0,0,0,0,0,0,0,0,0,0,0,0,0
0,0,0,0,0,0,0,0,0,0,0,0,0
endlayer

layer
0,0,0,0,0,0,0,0,0,0,0,0,0
0,0,0,0,0,0,0,0,0,0,0,0,0
0,0,0,0,0,0,0,0,0,0,0,0,0
0,0,0,0,0,0,0,0,0,0,0,0,0
0,0,0,0,5,9,11,9,5,0,0,0,0
0,0,0,0,9,0,0,0,9,0,0,0,0
0,0,0,0,12,0,0,1,12,0,0,0,0
0,0,0,0,9,0,0,13,9,0,0,0,0
0,0,0,0,5,9,12,9,5,0,0,0,0
0,0,0,0,0,0,0,0,0,0,0,0,0
0,0,0,0,0,0,0,0,0,0,0,0,0
0,0,0,0,0,0,0,0,0,0,0,0,0
0,0,0,0,0,0,0,0,0,0,0,0,0
endlayer

layer
0,0,0,0,0,0,0,0,0,0,0,0,0
0,0,0,0,0,0,0,0,0,0,0,0,0
0,0,0,0,0,0,0,0,0,0,0,0,0
0,0,0,0,0,14,0,14,0,0,0,0,0
0,0,0,0,5,9,15,9,5,0,0,0,0
0,0,0,0,9,0,0,0,9,0,0,0,0
0,0,0,0,12,0,0,0,12,0,0,0,0
0,0,0,0,9,13,3,16,9,0,0,0,0
0,0,0,0,5,9,12,9,5,0,0,0,0
0,0,0,0,0,0,0,0,0,0,0,0,0
0,0,0,0,0,0,0,0,0,0,0,0,0
0,0,0,0,0,0,0,0,0,0,0,0,0
0,0,0,0,0,0,0,0,0,0,0,0,0
endlayer

layer
0,0,0,0,0,0,0,0,0,0,0,0,0
0,0,0,0,0,0,0,0,0,0,0,0,0
0,0,0,0,0,0,0,0,0,0,0,0,0
0,0,0,0,0,0,0,0,0,0,0,0,0
0,0,0,0,5,9,17,9,5,0,0,0,0
0,0,0,0,9,13,0,0,9,0,0,0,0
0,0,0,0,4,18,0,0,4,0,0,0,0
0,0,0,0,9,16,0,0,9,0,0,0,0
0,0,0,0,5,9,4,9,5,0,0,0,0
0,0,0,0,0,0,0,0,0,0,0,0,0
0,0,0,0,0,0,0,0,0,0,0,0,0
0,0,0,0,0,0,0,0,0,0,0,0,0
0,0,0,0,0,0,0,0,0,0,0,0,0
endlayer

layer
0,0,0,0,0,0,0,0,0,0,0,0,0
0,0,0,0,0,0,0,0,0,0,0,0,0
0,0,0,0,0,0,0,0,0,0,0,0,0
0,0,0,0,0,0,0,0,0,0,0,0,0
0,0,0,0,5,6,6,6,5,0,0,0,0
0,0,0,0,7,16,2,13,7,0,0,0,0
0,0,0,0,7,0,0,0,7,0,0,0,0
0,0,0,0,7,0,0,14,7,0,0,0,0
0,0,0,0,5,6,6,6,5,0,0,0,0
0,0,0,0,0,0,0,0,0,0,0,0,0
0,0,0,0,0,0,0,0,0,0,0,0,0
0,0,0,0,0,0,0,0,0,0,0,0,0
0,0,0,0,0,0,0,0,0,0,0,0,0
endlayer

layer
0,0,0,0,0,0,0,0,0,0,0,0,0
0,0,0,0,0,0,0,0,0,0,0,0,0
0,0,0,0,0,0,0,0,0,0,0,0,0
0,0,0,0,0,0,0,0,0,0,0,0,0
0,0,0,0,5,9,4,9,5,0,0,0,0
0,0,0,0,9,0,0,16,9,0,0,0,0
0,0,0,0,4,0,0,1,4,0,0,0,0
0,0,0,0,9,0,0,13,9,0,0,0,0
0,0,0,0,5,9,4,9,5,0,0,0,0
0,0,0,0,0,0,0,0,0,0,0,0,0
0,0,0,0,0,0,0,0,0,0,0,0,0
0,0,0,0,0,0,0,0,0,0,0,0,0
0,0,0,0,0,0,0,0,0,0,0,0,0
endlayer

layer
0,0,0,0,0,0,0,0,0,0,0,0,0
0,0,0,0,0,0,0,0,0,0,0,0,0
0,0,0,0,0,0,0,0,0,0,0,0,0
0,0,0,0,0,0,0,0,0,0,0,0,0
0,0,0,0,5,9,12,9,5,0,0,0,0
0,0,0,0,9,0,0,0,9,0,0,0,0
0,0,0,0,12,0,0,0,12,0,0,0,0
0,0,0,0,9,13,3,16,9,0,0,0,0
0,0,0,0,5,9,12,9,5,0,0,0,0
0,0,0,0,0,0,0,0,0,0,0,0,0
0,0,0,0,0,0,0,0,0,0,0,0,0
0,0,0,0,0,0,0,0,0,0,0,0,0
0,0,0,0,0,0,0,0,0,0,0,0,0
endlayer

layer
0,0,0,0,0,0,0,0,0,0,0,0,0
0,0,0,0,0,0,0,0,0,0,0,0,0
0,0,0,0,0,0,0,0,0,0,0,0,0
0,0,0,0,0,0,0,0,0,0,0,0,0
0,0,0,0,5,9,12,9,5,0,0,0,0
0,0,0,0,9,13,0,0,9,0,0,0,0
0,0,0,0,12,18,0,0,12,0,0,0,0
0,0,0,0,9,16,0,0,9,0,0,0,0
0,0,0,0,5,9,12,9,5,0,0,0,0
0,0,0,0,0,0,0,0,0,0,0,0,0
0,0,0,0,0,0,0,0,0,0,0,0,0
0,0,0,0,0,0,0,0,0,0,0,0,0
0,0,0,0,0,0,0,0,0,0,0,0,0
endlayer

layer
0,0,0,0,0,0,0,0,0,0,0,0,0
0,0,0,0,0,0,0,0,0,0,0,0,0
0,0,0,0,0,0,0,0,0,0,0,0,0
0,0,0,0,0,0,0,0,0,0,0,0,0
0,0,0,0,5,9,4,9,5,0,0,0,0
0,0,0,0,9,16,2,13,9,0,0,0,0
0,0,0,0,9,0,0,0,4,0,0,0,0
0,0,0,0,9,0,0,14,9,0,0,0,0
0,0,0,0,5,9,4,9,5,0,0,0,0
0,0,0,0,0,0,0,0,0,0,0,0,0
0,0,0,0,0,0,0,0,0,0,0,0,0
0,0,0,0,0,0,0,0,0,0,0,0,0
0,0,0,0,0,0,0,0,0,0,0,0,0
endlayer

layer
0,0,0,0,0,0,0,0,0,0,0,0,0
0,0,0,0,0,0,0,0,0,0,0,0,0
0,0,0,0,0,0,0,0,0,0,0,0,0
0,0,0,0,0,0,0,0,0,0,0,0,0
0,0,0,0,5,6,6,6,5,0,0,0,0
0,0,0,0,7,0,0,16,7,0,0,0,0
0,0,0,0,7,0,0,1,7,0,0,0,0
0,0,0,0,7,0,0,13,7,0,0,0,0
0,0,0,0,5,6,6,6,5,0,0,0,0
0,0,0,0,0,0,0,0,0,0,0,0,0
0,0,0,0,0,0,0,0,0,0,0,0,0
0,0,0,0,0,0,0,0,0,0,0,0,0
0,0,0,0,0,0,0,0,0,0,0,0,0
endlayer

layer
0,0,0,0,0,0,0,0,0,0,0,0,0
0,0,0,0,0,0,0,0,0,0,0,0,0
0,0,0,0,0,0,0,0,0,0,0,0,0
0,0,0,0,0,0,0,0,0,0,0,0,0
0,0,0,0,5,9,4,9,5,0,0,0,0
0,0,0,0,9,0,0,0,9,0,0,0,0
0,0,0,0,4,0,0,0,4,0,0,0,0
0,0,0,0,9,13,3,16,9,0,0,0,0
0,0,0,0,5,9,4,9,5,0,0,0,0
0,0,0,0,0,0,0,0,0,0,0,0,0
0,0,0,0,0,0,0,0,0,0,0,0,0
0,0,0,0,0,0,0,0,0,0,0,0,0
0,0,0,0,0,0,0,0,0,0,0,0,0
endlayer

layer
0,0,0,0,0,0,0,0,0,0,0,0,0
0,0,0,0,0,0,0,0,0,0,0,0,0
0,0,0,0,0,0,0,0,0,0,0,0,0
0,0,0,0,0,0,0,0,0,0,0,0,0
0,0,0,0,5,9,12,9,5,0,0,0,0
0,0,0,0,9,13,0,0,9,0,0,0,0
0,0,0,0,12,18,0,0,12,0,0,0,0
0,0,0,0,9,16,0,0,9,0,0,0,0
0,0,0,0,5,9,12,9,5,0,0,0,0
0,0,0,0,0,0,0,0,0,0,0,0,0
0,0,0,0,0,0,0,0,0,0,0,0,0
0,0,0,0,0,0,0,0,0,0,0,0,0
0,0,0,0,0,0,0,0,0,0,0,0,0
endlayer

layer
0,0,0,0,0,0,0,0,0,0,0,0,0
0,0,0,0,0,0,0,0,0,0,0,0,0
0,0,0,0,0,0,0,0,0,0,0,0,0
0,0,0,0,0,0,0,0,0,0,0,0,0
0,0,0,0,5,9,12,9,5,0,0,0,0
0,0,0,0,9,16,2,13,9,0,0,0,0
0,0,0,0,12,0,0,0,12,0,0,0,0
0,0,0,0,9,0,0,14,9,0,0,0,0
0,0,0,0,5,9,12,9,5,0,0,0,0
0,0,0,0,0,0,0,0,0,0,0,0,0
0,0,0,0,0,0,0,0,0,0,0,0,0
0,0,0,0,0,0,0,0,0,0,0,0,0
0,0,0,0,0,0,0,0,0,0,0,0,0
endlayer

layer
0,0,0,0,0,0,0,0,0,0,0,0,0
0,0,0,0,0,0,0,0,0,0,0,0,0
0,0,0,0,0,0,0,0,0,0,0,0,0
0,0,0,0,0,0,0,0,0,0,0,0,0
0,0,0,0,5,9,4,9,5,0,0,0,0
0,0,0,0,9,0,0,16,9,0,0,0,0
0,0,0,0,4,0,0,1,4,0,0,0,0
0,0,0,0,9,0,0,13,9,0,0,0,0
0,0,0,0,5,9,4,9,5,0,0,0,0
0,0,0,0,0,0,0,0,0,0,0,0,0
0,0,0,0,0,0,0,0,0,0,0,0,0
0,0,0,0,0,0,0,0,0,0,0,0,0
0,0,0,0,0,0,0,0,0,0,0,0,0
endlayer

layer
0,0,0,0,0,0,0,0,0,0,0,0,0
0,0,0,0,0,0,0,0,0,0,0,0,0
0,0,0,0,0,0,0,0,0,0,0,0,0
0,0,0,0,0,0,0,0,0,0,0,0,0
0,0,0,0,5,6,6,6,5,0,0,0,0
0,0,0,0,7,0,0,0,7,0,0,0,0
0,0,0,0,7,0,0,0,7,0,0,0,0
0,0,0,0,7,13,3,16,7,0,0,0,0
0,0,0,0,5,6,6,6,5,0,0,0,0
0,0,0,0,0,0,0,0,0,0,0,0,0
0,0,0,0,0,0,0,0,0,0,0,0,0
0,0,0,0,0,0,0,0,0,0,0,0,0
0,0,0,0,0,0,0,0,0,0,0,0,0
endlayer

layer
0,0,0,0,0,0,0,0,0,0,0,0,0
0,0,0,0,0,0,0,0,0,0,0,0,0
0,0,0,0,0,0,0,0,0,0,0,0,0
0,0,0,0,0,0,0,0,0,0,0,0,0
0,0,0,0,5,9,4,9,5,0,0,0,0
0,0,0,0,9,13,0,0,9,0,0,0,0
0,0,0,0,4,18,0,0,4,0,0,0,0
0,0,0,0,9,16,0,0,9,0,0,0,0
0,0,0,0,5,9,4,9,5,0,0,0,0
0,0,0,0,0,0,0,0,0,0,0,0,0
0,0,0,0,0,0,0,0,0,0,0,0,0
0,0,0,0,0,0,0,0,0,0,0,0,0
0,0,0,0,0,0,0,0,0,0,0,0,0
endlayer

layer
0,0,0,0,0,0,0,0,0,0,0,0,0
0,0,0,0,0,0,0,0,0,0,0,0,0
0,0,0,0,0,0,0,0,0,0,0,0,0
0,0,0,0,0,0,0,0,0,0,0,0,0
0,0,0,0,5,9,12,9,5,0,0,0,0
0,0,0,0,9,16,2,13,9,0,0,0,0
0,0,0,0,12,0,0,0,12,0,0,0,0
0,0,0,0,9,0,0,14,9,0,0,0,0
0,0,0,0,5,9,12,9,5,0,0,0,0
0,0,0,0,0,0,0,0,0,0,0,0,0
0,0,0,0,0,0,0,0,0,0,0,0,0
0,0,0,0,0,0,0,0,0,0,0,0,0
0,0,0,0,0,0,0,0,0,0,0,0,0
endlayer

layer
0,0,0,0,0,0,0,0,0,0,0,0,0
0,0,0,0,0,0,0,0,0,0,0,0,0
0,0,0,0,0,0,0,0,0,0,0,0,0
0,0,0,0,0,0,0,0,0,0,0,0,0
0,0,0,0,5,9,12,9,5,0,0,0,0
0,0,0,0,9,0,0,16,9,0,0,0,0
0,0,0,0,12,0,0,1,12,0,0,0,0
0,0,0,0,9,0,0,13,9,0,0,0,0
0,0,0,0,5,9,12,9,5,0,0,0,0
0,0,0,0,0,0,0,0,0,0,0,0,0
0,0,0,0,0,0,0,0,0,0,0,0,0
0,0,0,0,0,0,0,0,0,0,0,0,0
0,0,0,0,0,0,0,0,0,0,0,0,0
endlayer

layer
0,0,0,0,0,0,0,0,0,0,0,0,0
0,0,0,0,0,0,0,0,0,0,0,0,0
0,0,0,0,0,0,0,0,0,0,0,0,0
0,0,0,0,0,0,0,0,0,0,0,0,0
0,0,0,0,5,9,4,9,5,0,0,0,0
0,0,0,0,9,0,0,0,9,0,0,0,0
0,0,0,0,4,0,0,0,4,0,0,0,0
0,0,0,0,9,13,3,16,9,0,0,0,0
0,0,0,0,5,9,4,9,5,0,0,0,0
0,0,0,0,0,0,0,0,0,0,0,0,0
0,0,0,0,0,0,0,0,0,0,0,0,0
0,0,0,0,0,0,0,0,0,0,0,0,0
0,0,0,0,0,0,0,0,0,0,0,0,0
endlayer

layer
0,0,0,0,0,0,0,0,0,0,0,0,0
0,0,0,0,0,0,0,0,0,0,0,0,0
0,0,0,0,0,0,0,0,0,0,0,0,0
0,0,0,0,0,0,0,0,0,0,0,0,0
0,0,0,0,5,6,6,6,5,0,0,0,0
0,0,0,0,7,13,0,0,7,0,0,0,0
0,0,0,0,7,18,0,0,7,0,0,0,0
0,0,0,0,7,16,0,0,7,0,0,0,0
0,0,0,0,5,6,6,6,5,0,0,0,0
0,0,0,0,0,0,0,0,0,0,0,0,0
0,0,0,0,0,0,0,0,0,0,0,0,0
0,0,0,0,0,0,0,0,0,0,0,0,0
0,0,0,0,0,0,0,0,0,0,0,0,0
endlayer

layer
0,0,0,0,0,0,0,0,0,0,0,0,0
0,0,0,0,13,13,19,13,13,0,0,0,0
0,0,13,13,19,19,17,19,19,13,13,0,0
0,0,13,21,20,9,4,9,20,20,13,0,0
0,13,19,21,5,6,6,6,5,22,19,13,0
0,13,19,9,7,16,2,13,7,9,19,13,0
0,19,24,4,7,0,0,0,7,4,23,19,0
0,13,19,9,7,0,0,14,7,9,19,13,0
0,13,19,21,5,6,6,6,5,22,19,13,0
0,0,13,25,25,9,4,9,25,22,13,0,0
0,0,13,13,19,19,26,19,19,13,13,0,0
0,0,0,0,13,13,19,13,13,0,0,0,0
0,0,0,0,0,0,0,0,0,0,0,0,0
endlayer

layer
0,0,0,0,0,0,0,0,0,0,0,0,0
0,0,0,0,27,27,27,27,27,0,0,0,0
0,0,27,27,27,0,0,0,27,27,27,0,0
0,0,27,0,0,0,0,0,0,0,27,0,0
0,27,27,0,5,0,0,0,5,0,27,27,0
0,27,0,0,0,0,0,0,0,0,0,27,0
0,27,0,0,0,0,0,0,0,0,0,27,0
0,27,0,0,0,0,0,0,0,0,0,27,0
0,27,27,0,5,0,0,0,5,0,27,27,0
0,0,27,0,0,0,0,0,0,0,27,0,0
0,0,27,27,27,0,0,0,27,27,27,0,0
0,0,0,0,27,27,27,27,27,0,0,0,0
0,0,0,0,0,0,0,0,0,0,0,0,0
endlayer

layer
0,0,0,0,0,0,0,0,0,0,0,0,0
0,0,0,0,0,0,0,0,0,0,0,0,0
0,0,28,0,27,0,0,0,27,0,28,0,0
0,0,0,0,0,0,0,0,0,0,0,0,0
0,0,27,0,5,0,0,0,5,0,27,0,0
0,0,0,0,0,0,0,0,0,0,0,0,0
0,0,0,0,0,0,0,0,0,0,0,0,0
0,0,0,0,0,0,0,0,0,0,0,0,0
0,0,27,0,5,0,0,0,5,0,27,0,0
0,0,0,0,0,0,0,0,0,0,0,0,0
0,0,28,0,27,0,0,0,27,0,28,0,0
0,0,0,0,0,0,0,0,0,0,0,0,0
0,0,0,0,0,0,0,0,0,0,0,0,0
endlayer

layer
0,0,0,0,0,0,0,0,0,0,0,0,0
0,0,0,0,0,0,0,0,0,0,0,0,0
0,0,0,0,27,0,0,0,27,0,0,0,0
0,0,0,0,0,0,0,0,0,0,0,0,0
0,0,27,0,5,0,0,0,5,0,27,0,0
0,0,0,0,0,0,0,0,0,0,0,0,0
0,0,0,0,0,0,0,0,0,0,0,0,0
0,0,0,0,0,0,0,0,0,0,0,0,0
0,0,27,0,5,0,0,0,5,0,27,0,0
0,0,0,0,0,0,0,0,0,0,0,0,0
0,0,0,0,27,0,0,0,27,0,0,0,0
0,0,0,0,0,0,0,0,0,0,0,0,0
0,0,0,0,0,0,0,0,0,0,0,0,0
endlayer

layer
0,0,0,0,16,29,29,29,16,0,0,0,0
0,0,16,16,2,1,4,1,3,16,16,0,0
0,16,2,1,2,13,13,13,3,1,3,16,0
0,16,2,13,13,0,0,0,13,13,3,16,0
16,1,1,13,5,0,0,0,5,13,1,1,16
29,2,13,0,0,0,0,0,0,0,13,3,29
29,4,13,0,0,0,0,0,0,0,13,4,29
29,2,13,0,0,0,0,0,0,0,13,3,29
16,18,18,13,5,0,0,0,5,13,18,3,16
0,16,2,13,13,0,0,0,13,13,3,16,0
0,16,2,18,2,13,13,13,3,18,18,16,0
0,0,16,16,2,18,4,18,3,16,16,0,0
0,0,0,0,16,29,29,29,16,0,0,0,0
endlayer

layer
0,0,0,0,0,0,0,0,0,0,0,0,0
0,0,0,0,0,0,0,0,0,0,0,0,0
0,0,0,0,0,0,16,0,0,0,0,0,0
0,0,0,0,16,32,31,30,16,0,0,0,0
0,0,0,16,31,31,26,30,31,16,0,0,0
0,0,0,31,32,0,0,0,30,31,0,0,0
0,0,16,32,23,0,0,0,24,30,16,0,0
0,0,0,33,32,0,0,0,30,33,0,0,0
0,0,0,16,32,33,17,33,33,16,0,0,0
0,0,0,0,16,32,33,30,16,0,0,0,0
0,0,0,0,0,0,16,0,0,0,0,0,0
0,0,0,0,0,0,0,0,0,0,0,0,0
0,0,0,0,0,0,0,0,0,0,0,0,0
endlayer

layer
0,0,0,0,0,0,0,0,0,0,0,0,0
0,0,0,0,0,0,0,0,0,0,0,0,0
0,0,0,0,0,0,0,0,0,0,0,0,0
0,0,0,0,0,0,0,0,0,0,0,0,0
0,0,0,0,0,0,1,0,0,0,0,0,0
0,0,0,0,0,29,19,29,0,0,0,0,0
0,0,0,0,2,19,0,19,3,0,0,0,0
0,0,0,0,0,29,19,29,0,0,0,0,0
0,0,0,0,0,0,29,0,0,0,0,0,0
0,0,0,0,0,0,0,0,0,0,0,0,0
0,0,0,0,0,0,0,0,0,0,0,0,0
0,0,0,0,0,0,0,0,0,0,0,0,0
0,0,0,0,0,0,0,0,0,0,0,0,0
endlayer

layer
0,0,0,0,0,0,0,0,0,0,0,0,0
0,0,0,0,0,0,0,0,0,0,0,0,0
0,0,0,0,0,0,0,0,0,0,0,0,0
0,0,0,0,0,0,0,0,0,0,0,0,0
0,0,0,0,0,0,0,0,0,0,0,0,0
0,0,0,0,0,0,4,0,0,0,0,0,0
0,0,0,0,0,4,34,4,0,0,0,0,0
0,0,0,0,0,0,4,0,0,0,0,0,0
0,0,0,0,0,0,0,0,0,0,0,0,0
0,0,0,0,0,0,0,0,0,0,0,0,0
0,0,0,0,0,0,0,0,0,0,0,0,0
0,0,0,0,0,0,0,0,0,0,0,0,0
0,0,0,0,0,0,0,0,0,0,0,0,0
endlayer

layer
0,0,0,0,0,0,0,0,0,0,0,0,0
0,0,0,0,0,0,0,0,0,0,0,0,0
0,0,0,0,0,0,0,0,0,0,0,0,0
0,0,0,0,0,0,0,0,0,0,0,0,0
0,0,0,0,0,0,0,0,0,0,0,0,0
0,0,0,0,0,0,1,0,0,0,0,0,0
0,0,0,0,0,2,4,3,0,0,0,0,0
0,0,0,0,0,0,18,0,0,0,0,0,0
0,0,0,0,0,0,0,0,0,0,0,0,0
0,0,0,0,0,0,0,0,0,0,0,0,0
0,0,0,0,0,0,0,0,0,0,0,0,0
0,0,0,0,0,0,0,0,0,0,0,0,0
0,0,0,0,0,0,0,0,0,0,0,0,0
endlayer

layer
0,0,0,0,0,0,0,0,0,0,0,0,0
0,0,0,0,0,0,0,0,0,0,0,0,0
0,0,0,0,0,0,0,0,0,0,0,0,0
0,0,0,0,0,0,0,0,0,0,0,0,0
0,0,0,0,0,0,0,0,0,0,0,0,0
0,0,0,0,0,0,0,0,0,0,0,0,0
0,0,0,0,0,0,4,0,0,0,0,0,0
0,0,0,0,0,0,0,0,0,0,0,0,0
0,0,0,0,0,0,0,0,0,0,0,0,0
0,0,0,0,0,0,0,0,0,0,0,0,0
0,0,0,0,0,0,0,0,0,0,0,0,0
0,0,0,0,0,0,0,0,0,0,0,0,0
0,0,0,0,0,0,0,0,0,0,0,0,0
endlayer

layer
0,0,0,0,0,0,0,0,0,0,0,0,0
0,0,0,0,0,0,0,0,0,0,0,0,0
0,0,0,0,0,0,0,0,0,0,0,0,0
0,0,0,0,0,0,0,0,0,0,0,0,0
0,0,0,0,0,0,0,0,0,0,0,0,0
0,0,0,0,0,0,0,0,0,0,0,0,0
0,0,0,0,0,0,4,0,0,0,0,0,0
0,0,0,0,0,0,0,0,0,0,0,0,0
0,0,0,0,0,0,0,0,0,0,0,0,0
0,0,0,0,0,0,0,0,0,0,0,0,0
0,0,0,0,0,0,0,0,0,0,0,0,0
0,0,0,0,0,0,0,0,0,0,0,0,0
0,0,0,0,0,0,0,0,0,0,0,0,0
endlayer

layer
0,0,0,0,0,0,0,0,0,0,0,0,0
0,0,0,0,0,0,0,0,0,0,0,0,0
0,0,0,0,0,0,0,0,0,0,0,0,0
0,0,0,0,0,0,0,0,0,0,0,0,0
0,0,0,0,0,0,0,0,0,0,0,0,0
0,0,0,0,0,0,0,0,0,0,0,0,0
0,0,0,0,0,0,4,0,0,0,0,0,0
0,0,0,0,0,0,0,0,0,0,0,0,0
0,0,0,0,0,0,0,0,0,0,0,0,0
0,0,0,0,0,0,0,0,0,0,0,0,0
0,0,0,0,0,0,0,0,0,0,0,0,0
0,0,0,0,0,0,0,0,0,0,0,0,0
0,0,0,0,0,0,0,0,0,0,0,0,0
endlayer

layer
0,0,0,0,0,0,0,0,0,0,0,0,0
0,0,0,0,0,0,0,0,0,0,0,0,0
0,0,0,0,0,0,0,0,0,0,0,0,0
0,0,0,0,0,0,0,0,0,0,0,0,0
0,0,0,0,0,0,0,0,0,0,0,0,0
0,0,0,0,0,0,0,0,0,0,0,0,0
0,0,0,0,0,0,4,0,0,0,0,0,0
0,0,0,0,0,0,0,0,0,0,0,0,0
0,0,0,0,0,0,0,0,0,0,0,0,0
0,0,0,0,0,0,0,0,0,0,0,0,0
0,0,0,0,0,0,0,0,0,0,0,0,0
0,0,0,0,0,0,0,0,0,0,0,0,0
0,0,0,0,0,0,0,0,0,0,0,0,0
endlayer

layer
0,0,0,0,0,0,0,0,0,0,0,0,0
0,0,0,0,0,0,0,0,0,0,0,0,0
0,0,0,0,0,0,0,0,0,0,0,0,0
0,0,0,0,0,0,0,0,0,0,0,0,0
0,0,0,0,0,0,0,0,0,0,0,0,0
0,0,0,0,0,0,0,0,0,0,0,0,0
0,0,0,0,0,0,27,0,0,0,0,0,0
0,0,0,0,0,0,0,0,0,0,0,0,0
0,0,0,0,0,0,0,0,0,0,0,0,0
0,0,0,0,0,0,0,0,0,0,0,0,0
0,0,0,0,0,0,0,0,0,0,0,0,0
0,0,0,0,0,0,0,0,0,0,0,0,0
0,0,0,0,0,0,0,0,0,0,0,0,0
endlayer

layer
0,0,0,0,0,0,0,0,0,0,0,0,0
0,0,0,0,0,0,0,0,0,0,0,0,0
0,0,0,0,0,0,0,0,0,0,0,0,0
0,0,0,0,0,0,0,0,0,0,0,0,0
0,0,0,0,0,0,0,0,0,0,0,0,0
0,0,0,0,0,0,0,0,0,0,0,0,0
0,0,0,0,0,0,27,0,0,0,0,0,0
0,0,0,0,0,0,0,0,0,0,0,0,0
0,0,0,0,0,0,0,0,0,0,0,0,0
0,0,0,0,0,0,0,0,0,0,0,0,0
0,0,0,0,0,0,0,0,0,0,0,0,0
0,0,0,0,0,0,0,0,0,0,0,0,0
0,0,0,0,0,0,0,0,0,0,0,0,0
endlayer

layer
0,0,0,0,0,0,0,0,0,0,0,0,0
0,0,0,0,0,0,0,0,0,0,0,0,0
0,0,0,0,0,0,0,0,0,0,0,0,0
0,0,0,0,0,0,0,0,0,0,0,0,0
0,0,0,0,0,0,0,0,0,0,0,0,0
0,0,0,0,0,0,0,0,0,0,0,0,0
0,0,0,0,0,0,27,0,0,0,0,0,0
0,0,0,0,0,0,0,0,0,0,0,0,0
0,0,0,0,0,0,0,0,0,0,0,0,0
0,0,0,0,0,0,0,0,0,0,0,0,0
0,0,0,0,0,0,0,0,0,0,0,0,0
0,0,0,0,0,0,0,0,0,0,0,0,0
0,0,0,0,0,0,0,0,0,0,0,0,0
endlayer

layer
0,0,0,0,0,0,0,0,0,0,0,0,0
0,0,0,0,0,0,0,0,0,0,0,0,0
0,0,0,0,0,0,0,0,0,0,0,0,0
0,0,0,0,0,0,0,0,0,0,0,0,0
0,0,0,0,0,0,0,0,0,0,0,0,0
0,0,0,0,0,0,0,0,0,0,0,0,0
0,0,0,0,0,0,27,0,0,0,0,0,0
0,0,0,0,0,0,0,0,0,0,0,0,0
0,0,0,0,0,0,0,0,0,0,0,0,0
0,0,0,0,0,0,0,0,0,0,0,0,0
0,0,0,0,0,0,0,0,0,0,0,0,0
0,0,0,0,0,0,0,0,0,0,0,0,0
0,0,0,0,0,0,0,0,0,0,0,0,0
endlayer

